Workbook
Name _1B.05.M.010.0010: #REF!
Name _1B.05.M.010.0050: #REF!
Name _1B.05.M.0100.0010: #REF!
Name _1B.05.M.020.0010: #REF!
Name _1B.05.M.020.0020: #REF!
Name _1B.05.M.020.0030: #REF!
Name _1B.05.M.020.0040: #REF!
Name _1B.05.M.030.0010: #REF!
Name _1B.05.M.030.0020: #REF!
Name _1B.05.M.040.0010: #REF!
Name _1B.05.M.050.0010: #REF!
Name _1B.05.M.050.0020: #REF!
Name _1B.05.M.050.0030: #REF!
Name _1B.05.M.060.0020: #REF!
Name _1B.05.M.060.0100: #REF!
Name _1B.05.M.070.0010: #REF!
Name _1B.05.M.070.0020: #REF!
Name _1B.05.M.070.0030: #REF!
Name _1B.05.M.070.0040: #REF!
Name _1B.05.M.070.0050: #REF!
Name _1B.05.M.080.0010: #REF!
Name _1B.05.M.090.0010: #REF!
Name _1B.09.P.010.0010: #REF!
Name _1B.09.P.010.0020: #REF!
Name _1B.09.P.010.0030: #REF!
Name _1B.09.P.010.0040: #REF!
Name _1B.09.P.010.0050: #REF!
Name _1B.09.P.010.0060: #REF!
Name _1B.09.P.010.0070: #REF!
Name _1B.09.P.020.0010: #REF!
Name _1B.09.P.020.0020: #REF!
Name _1B.09.P.020.0030: #REF!
Name _1B.09.P.020.0040: #REF!
Name _1B.09.P.020.0050: #REF!
Name _1B.09.P.020.0060: #REF!
Name _1B.09.P.020.0070: #REF!
Name _1B.09.P.020.0080: #REF!
Name _1B.09.P.020.0090: #REF!
Name _1B.09.P.020.0100: #REF!
Name _1B.09.P.020.0110: #REF!
Name _1B.09.P.020.0120: #REF!
Name _1B.09.P.020.0130: #REF!
Name _1B.09.P.020.0140: #REF!
Name _1B.09.P.020.0150: #REF!
Name _1B.09.P.030.0010: #REF!
Name _1B.09.P.030.0020: #REF!
Name _1B.09.P.030.0030: #REF!
Name _1B.09.P.030.0040: #REF!
Name _1B.09.P.030.0050: #REF!
Name _1B.09.P.030.0060: #REF!
Name _1B.09.P.040.0010: #REF!
Name _1B.09.P.040.0020: #REF!
Name _1B.09.P.040.0030: #REF!
Name _1B.09.P.050.0010: #REF!
Name _1B.09.P.050.0020: #REF!
Name _1B.09.P.060.0010: #REF!
Name _1B.09.P.060.0020: #REF!
Name _1B.09.P.060.0030: #REF!
Name _1B.09.P.060.0040: #REF!
Name _1B.09.P.060.0050: #REF!

Sheet Weekly Progress Report
A1: MODON - Weekly Progress Report - Construction Projects | M1: Dashboard 20-Oct-2026 | AB1: Report No. | AC1: ='General Information'!L2 -> 47.857143 | AF1: Data Date | AG1: ='General Information'!L1 -> 46315
A2: Contract General Information | G2: Key Dates | M2: Cost Summary (SR) | U2: Performance Summary | AA2: Project Scope
A3: Project Name | B3: ='General Information'!C3 -> INFRASTRUCTURE DEVELOPMENT FOR INDUSTRIAL CITY 1 IN JEDDAH | G3: Contract Award | H3: ='General Information'!C12 -> 45963 | I3: Contract Award (Hijri) | J3: ='General Information'!C16 -> 45963 | K3: Revised Completion | L3: ='General Information'!C20 -> 46709 | M3: Original Contract Value | O3: ='Invoice Log'!E3 -> 86782345 | Q3: O&M Value (if any) | S3: ='[36]Invoice Log'!I3 -> 0 | T3: EAC | U3: Plan Value | V3: =K28 -> 0.53183049 | W3: Phys. Plan Value | X3: =W28 -> 0.4698619 | Y3: Quality Score | Z3: ='Quality '!AC11 -> 0.85206897 | AA3: The Scope of Works for the INFRASTRUCTURE DEVELOPMENT FOR INDUSTRIAL CITY 1 IN JEDDAH. This construction works includes but not limited to the followings: (Road works - Storm network - Sewer Network - Potable water network - TSE network - Electrical works - Fence - Bridge - Landscape works)
A4: Project ID | B4: ='General Information'!C4 -> JDH1-02-003 | D4: Stage | E4: ='General Information'!C7 -> Construction | G4: Contract Sign | H4: ='General Information'!C13 -> 45974 | I4: Contract Sign (Hijri) | J4: ='General Information'!C17 -> 45974 | K4: Committed Completion | L4: ='General Information'!C21 -> 46709 | M4: Revised Contract Value | O4: ='Invoice Log'!E4 -> 86782345 | P4: EAC | Q4: Submitted Invoices (Gross Value) | S4: ='Invoice Log'!F33 -> 44851849 | U4: Earn Value | V4: =L28 -> 0.78721045 | W4: Phys. Earn Value | X4: =X28 -> 0.72612176 | Z4: =REPT("¢",IF(INT(+Z3*10)>5,5,INT(+Z3*10)))&REPT("£",IF(INT(+Z3*10)>5,0,5-INT(+Z3*10)))&CHAR(10)&REPT("¢",+IF(INT(+Z3*10)>5,-5+INT(+Z3*10),0))&REPT("£",IF(INT(+Z3*10)>5,10-INT(+Z3*10),5)) -> ¢¢¢¢¢ ¢¢¢££
A5: Contractor | B5: ='General Information'!C5 -> Al Enjaz Company for Trading and Contracting | D5: Status | E5: ='General Information'!C8 -> Active | G5: Site Handover | H5: ='General Information'!C14 -> 45980 | I5: Site Handover (Hijri) | J5: ='General Information'!C18 -> 45980 | K5: Forecast Completion | L5: ='General Information'!C22 -> 46893 | M5: Estimate At Completion Value | O5: ='Invoice Log'!E5 -> 86782345 | P5: =+#REF!+#REF!+O5 -> #REF! | Q5: Penalities | S5: ='Invoice Log'!M6 -> 0 | U5: Variance | V5: =V4-V3 -> 0.25537996 | W5: Variance | X5: =X4-X3 -> 0.25625986 | Y5: Safety Score | Z5: =HSE!AE6 -> 0.77173913
A6: Consultant | B6: ='General Information'!C6 -> Saudi Arabia Consulting Engineering Company "EGIS" | D6: Modon PM | E6: ='General Information'!C9 -> Engr.Abdallah Aljulayfi | G6: Original Completion | H6: ='General Information'!C15 -> 46709 | I6: Original Completion (Hijri) | J6: ='General Information'!C19 -> 46709 | K6: Variance | L6: ='General Information'!C23 -> -184 | M6: Potential Changes | O6: =O4-O5 -> 0 | Q6: FIR Value (Todate) | S6: =MAX('Invoice Ammount FIR'!C3:C46) -> 57162747 | U6: FIR % | V6: =S6/O4 -> 0.65869097 | W6: Invoiced % | X6: =S4/O4 -> 0.5168315 | Z6: =REPT("¢",IF(INT(+Z5*10)>5,5,INT(+Z5*10)))&REPT("£",IF(INT(+Z5*10)>5,0,5-INT(+Z5*10)))&CHAR(10)&REPT("¢",+IF(INT(+Z5*10)>5,-5+INT(+Z5*10),0))&REPT("£",IF(INT(+Z5*10)>5,10-INT(+Z5*10),5)) -> ¢¢¢¢¢ ¢¢£££
A8: Progress Overview
A9: Earned Value Progress (SAR) | O9: Physical Progress (Effort) | AA9: Earned Value Progress (%)
A10: WBS | C10: BOQ Value (SAR) | D10: % Wt. | E10: Weekly (SAR) | G10: To Date (SAR) | O10: Budgeted | P10: % Wt. | Q10: Weekly Physical Progress | U10: To Date Physical Progress
E11: Planned | F11: Earned | G11: Original Plan | H11: Revised Planned | I11: Earned | J11: Original Plan % | K11: Revised Planned % | L11: Earned % | M11: Variance | N11: SPI | O11: (Manhours) | Q11: Planned | R11: Earned | S11: Plan % | T11: Earned % | U11: Planned | V11: Earned | W11: Plan % | X11: Earned % | Y11: Variance | Z11: SPI
C12: =Progress!C7 -> 0 | D12: =Progress!D7 -> 0 | E12: =Progress!E18 -> 88958.71 | F12: =Progress!F18 -> 0 | G12: =Progress!G18 -> 2119815.9 | H12: =Progress!H18 -> 2208774.6 | I12: =Progress!I18 -> 5352415.6 | J12: =IFERROR(IF(ISBLANK(G12),"",G12/C12),0) -> 0 | K12: =IFERROR(IF(ISBLANK(H12),"",H12/C12),0) -> 0 | L12: =IFERROR(IF(ISBLANK(I12),"",I12/C12),0) -> 0 | M12: =IFERROR(L12-K12,"") -> 0 | N12: =IFERROR(L12/K12,"") | P12: =IF(ISBLANK(O12),"",O12/$O$28)
A13: =Progress!A7 -> Mobilization | C13: =Progress!C7 -> 0 | D13: =Progress!D7 -> 0 | E13: =Progress!E7 -> 0 | F13: =Progress!F7 -> 0 | G13: =Progress!G7 -> 0 | H13: =Progress!H7 -> 0 | I13: =Progress!I7 -> 0 | J13: =IFERROR(IF(ISBLANK(G13),"",G13/C13),0) -> 0 | K13: =IFERROR(IF(ISBLANK(H13),"",H13/C13),0) -> 0 | L13: =IFERROR(IF(ISBLANK(I13),"",I13/C13),0) -> 0 | M13: =IFERROR(L13-K13,"") -> 0 | N13: =IFERROR(L13/K13,"") | O13: =Progress!L7 -> 20050 | P13: =IF(ISBLANK(O13),"",O13/$O$28) -> 0.028059176 | Q13: =Progress!N7 -> 0 | R13: =Progress!O7 -> 0 | S13: =IFERROR(IF(ISBLANK(Q13),"",Q13/O13),0) -> 0 | T13: =IFERROR(IF(ISBLANK(R13),"",R13/O13),0) -> 0 | U13: =Progress!P7 -> 20050 | V13: =Progress!Q7 -> 20050 | W13: =IFERROR(IF(ISBLANK(U13),"",U13/O13),0) -> 1 | X13: =IFERROR(IF(ISBLANK(V13),"",V13/O13),0) -> 1 | Y13: =IFERROR(X13-W13,"") -> 0 | Z13: =IFERROR(X13/W13,"") -> 1
A14: =Progress!A8 -> Engineering | C14: =Progress!C8 -> 2601460.4 | D14: =Progress!D8 -> 0.029976839 | E14: =Progress!E8 -> 0 | F14: =Progress!F8 -> 0 | G14: =Progress!G8 -> 2601460.4 | H14: =Progress!H8 -> 2601460.4 | I14: =Progress!I8 -> 2579200.4 | J14: =IFERROR(IF(ISBLANK(G14),"",G14/C14),0) -> 1 | K14: =IFERROR(IF(ISBLANK(H14),"",H14/C14),0) -> 1 | L14: =IFERROR(IF(ISBLANK(I14),"",I14/C14),0) -> 0.99144327 | M14: =IFERROR(L14-K14,"") -> -0.0085567322 | N14: =IFERROR(L14/K14,"") -> 0.99144327 | O14: =Progress!L8 -> 33415 | P14: =IF(ISBLANK(O14),"",O14/$O$28) -> 0.046762961 | Q14: =Progress!N8 -> 0 | R14: =Progress!O8 -> 0 | S14: =IFERROR(IF(ISBLANK(Q14),"",Q14/O14),0) -> 0 | T14: =IFERROR(IF(ISBLANK(R14),"",R14/O14),0) -> 0 | U14: =Progress!P8 -> 33415 | V14: =Progress!Q8 -> 33009.2 | W14: =IFERROR(IF(ISBLANK(U14),"",U14/O14),0) -> 1 | X14: =IFERROR(IF(ISBLANK(V14),"",V14/O14),0) -> 0.98785575 | Y14: =IFERROR(X14-W14,"") -> -0.012144247 | Z14: =IFERROR(X14/W14,"") -> 0.98785575
A15: =Progress!A9 -> Procurement | C15: =Progress!C9 -> 17355662 | D15: =Progress!D9 -> 0.1999907 | E15: =Progress!E9 -> 26504 | F15: =Progress!F9 -> 208500 | G15: =Progress!G9 -> 13492073 | H15: =Progress!H9 -> 13518577 | I15: =Progress!I9 -> 15737880 | J15: =IFERROR(IF(ISBLANK(G15),"",G15/C15),0) -> 0.7773874 | K15: =IFERROR(IF(ISBLANK(H15),"",H15/C15),0) -> 0.77891451 | L15: =IFERROR(IF(ISBLANK(I15),"",I15/C15),0) -> 0.9067865 | M15: =IFERROR(L15-K15,"") -> 0.12787199 | N15: =IFERROR(L15/K15,"") -> 1.1641669 | O15: =Progress!L9 -> 82413.81 | P15: =IF(ISBLANK(O15),"",O15/$O$28) -> 0.11533484 | Q15: =Progress!N9 -> 0 | R15: =Progress!O9 -> 0 | S15: =IFERROR(IF(ISBLANK(Q15),"",Q15/O15),0) -> 0 | T15: =IFERROR(IF(ISBLANK(R15),"",R15/O15),0) -> 0 | U15: =Progress!P9 -> 35843.52 | V15: =Progress!Q9 -> 65032.49 | W15: =IFERROR(IF(ISBLANK(U15),"",U15/O15),0) -> 0.43492128 | X15: =IFERROR(IF(ISBLANK(V15),"",V15/O15),0) -> 0.789097 | Y15: =IFERROR(X15-W15,"") -> 0.35417571 | Z15: =IFERROR(X15/W15,"") -> 1.8143444
A16: =Progress!A10 -> Construction | C16: =Progress!C10 -> 58147531 | D16: =Progress!D10 -> 0.67003872 | E16: =Progress!E10 -> 394580.51 | F16: =Progress!F10 -> 190111.17 | G16: =Progress!G10 -> 29638879 | H16: =Progress!H10 -> 30033459 | I16: =Progress!I10 -> 44572325 | J16: =IFERROR(IF(ISBLANK(G16),"",G16/C16),0) -> 0.50971861 | K16: =IFERROR(IF(ISBLANK(H16),"",H16/C16),0) -> 0.51650446 | L16: =IFERROR(IF(ISBLANK(I16),"",I16/C16),0) -> 0.76653857 | M16: =IFERROR(L16-K16,"") -> 0.2500341 | N16: =IFERROR(L16/K16,"") -> 1.4840889 | O16: =Progress!L10 -> 545268.46 | P16: =IF(ISBLANK(O16),"",O16/$O$28) -> 0.76308147 | Q16: =Progress!N10 -> 5590.01 | R16: =Progress!O10 -> 1907.14 | S16: =IFERROR(IF(ISBLANK(Q16),"",Q16/O16),0) -> 0.010251849 | T16: =IFERROR(IF(ISBLANK(R16),"",R16/O16),0) -> 0.0034976166 | U16: =Progress!P10 -> 246436.59 | V16: =Progress!Q10 -> 390120.29 | W16: =IFERROR(IF(ISBLANK(U16),"",U16/O16),0) -> 0.4519546 | X16: =IFERROR(IF(ISBLANK(V16),"",V16/O16),0) -> 0.71546462 | Y16: =IFERROR(X16-W16,"") -> 0.26351001 | Z16: =IFERROR(X16/W16,"") -> 1.5830453
A17: =Progress!A11 -> Site Demolition | C17: =Progress!C11 -> 279942.75 | D17: =Progress!D11 -> 0.003225803 | E17: =Progress!E11 -> 0 | F17: =Progress!F11 -> 0 | G17: =Progress!G11 -> 279942.75 | H17: =Progress!H11 -> 279942.75 | I17: =Progress!I11 -> 279942.75 | J17: =IFERROR(IF(ISBLANK(G17),"",G17/C17),0) -> 1 | K17: =IFERROR(IF(ISBLANK(H17),"",H17/C17),0) -> 1 | L17: =IFERROR(IF(ISBLANK(I17),"",I17/C17),0) -> 1 | M17: =IFERROR(L17-K17,"") -> 0 | N17: =IFERROR(L17/K17,"") -> 1 | O17: =Progress!L11 -> 7350 | P17: =IF(ISBLANK(O17),"",O17/$O$28) -> 0.010286032 | Q17: =Progress!N11 -> 0 | R17: =Progress!O11 -> 0 | S17: =IFERROR(IF(ISBLANK(Q17),"",Q17/O17),0) -> 0 | T17: =IFERROR(IF(ISBLANK(R17),"",R17/O17),0) -> 0 | U17: =Progress!P11 -> 7350 | V17: =Progress!Q11 -> 7350 | W17: =IFERROR(IF(ISBLANK(U17),"",U17/O17),0) -> 1 | X17: =IFERROR(IF(ISBLANK(V17),"",V17/O17),0) -> 1 | Y17: =IFERROR(X17-W17,"") -> 0 | Z17: =IFERROR(X17/W17,"") -> 1
A18: =Progress!A12 -> Roads & Meduim Voltage | C18: =Progress!C12 -> 11810039 | D18: =Progress!D12 -> 0.13608803 | E18: =Progress!E12 -> 0 | F18: =Progress!F12 -> 0 | G18: =Progress!G12 -> 11810039 | H18: =Progress!H12 -> 11810039 | I18: =Progress!I12 -> 8650438.8 | J18: =IFERROR(IF(ISBLANK(G18),"",G18/C18),0) -> 1 | K18: =IFERROR(IF(ISBLANK(H18),"",H18/C18),0) -> 1 | L18: =IFERROR(IF(ISBLANK(I18),"",I18/C18),0) -> 0.7324649 | M18: =IFERROR(L18-K18,"") -> -0.2675351 | N18: =IFERROR(L18/K18,"") -> 0.7324649 | O18: =Progress!L12 -> 100175 | P18: =IF(ISBLANK(O18),"",O18/$O$28) -> 0.14019092 | Q18: =Progress!N12 -> 0 | R18: =Progress!O12 -> 0 | S18: =IFERROR(IF(ISBLANK(Q18),"",Q18/O18),0) -> 0 | T18: =IFERROR(IF(ISBLANK(R18),"",R18/O18),0) -> 0 | U18: =Progress!P12 -> 100175 | V18: =Progress!Q12 -> 73591 | W18: =IFERROR(IF(ISBLANK(U18),"",U18/O18),0) -> 1 | X18: =IFERROR(IF(ISBLANK(V18),"",V18/O18),0) -> 0.73462441 | Y18: =IFERROR(X18-W18,"") -> -0.26537559 | Z18: =IFERROR(X18/W18,"") -> 0.73462441
A19: =Progress!A13 -> Deep Infrastructure network | C19: =Progress!C13 -> 10009830 | D19: =Progress!D13 -> 0.11534409 | E19: =Progress!E13 -> 10082.82 | F19: =Progress!F13 -> 7209.5 | G19: =Progress!G13 -> 9958787.2 | H19: =Progress!H13 -> 9968870 | I19: =Progress!I13 -> 9750710.5 | J19: =IFERROR(IF(ISBLANK(G19),"",G19/C19),0) -> 0.99490071 | K19: =IFERROR(IF(ISBLANK(H19),"",H19/C19),0) -> 0.99590801 | L19: =IFERROR(IF(ISBLANK(I19),"",I19/C19),0) -> 0.97411348 | M19: =IFERROR(L19-K19,"") -> -0.021794529 | N19: =IFERROR(L19/K19,"") -> 0.97811592 | O19: =Progress!L13 -> 54025 | P19: =IF(ISBLANK(O19),"",O19/$O$28) -> 0.075605834 | Q19: =Progress!N13 -> 0 | R19: =Progress!O13 -> 0 | S19: =IFERROR(IF(ISBLANK(Q19),"",Q19/O19),0) -> 0 | T19: =IFERROR(IF(ISBLANK(R19),"",R19/O19),0) -> 0 | U19: =Progress!P13 -> 54025 | V19: =Progress!Q13 -> 51820.5 | W19: =IFERROR(IF(ISBLANK(U19),"",U19/O19),0) -> 1 | X19: =IFERROR(IF(ISBLANK(V19),"",V19/O19),0) -> 0.95919482 | Y19: =IFERROR(X19-W19,"") -> -0.040805183 | Z19: =IFERROR(X19/W19,"") -> 0.95919482
A20: =Progress!A14 -> Shallow infrastructure network | C20: =Progress!C14 -> 12539076 | D20: =Progress!D14 -> 0.14448879 | E20: =Progress!E14 -> 209087.15 | F20: =Progress!F14 -> 99253.79 | G20: =Progress!G14 -> 2810927.8 | H20: =Progress!H14 -> 3020015 | I20: =Progress!I14 -> 10453768 | J20: =IFERROR(IF(ISBLANK(G20),"",G20/C20),0) -> 0.22417344 | K20: =IFERROR(IF(ISBLANK(H20),"",H20/C20),0) -> 0.24084828 | L20: =IFERROR(IF(ISBLANK(I20),"",I20/C20),0) -> 0.83369524 | M20: =IFERROR(L20-K20,"") -> 0.59284696 | N20: =IFERROR(L20/K20,"") -> 3.4614955 | O20: =Progress!L14 -> 198577.38 | P20: =IF(ISBLANK(O20),"",O20/$O$28) -> 0.27790113 | Q20: =Progress!N14 -> 4687.15 | R20: =Progress!O14 -> 1717.15 | S20: =IFERROR(IF(ISBLANK(Q20),"",Q20/O20),0) -> 0.023603645 | T20: =IFERROR(IF(ISBLANK(R20),"",R20/O20),0) -> 0.0086472588 | U20: =Progress!P14 -> 43207.03 | V20: =Progress!Q14 -> 154727.25 | W20: =IFERROR(IF(ISBLANK(U20),"",U20/O20),0) -> 0.21758284 | X20: =IFERROR(IF(ISBLANK(V20),"",V20/O20),0) -> 0.77917863 | Y20: =IFERROR(X20-W20,"") -> 0.56159579 | Z20: =IFERROR(X20/W20,"") -> 3.5810666
A21: =Progress!A15 -> Bridge | C21: =Progress!C15 -> 2513307 | D21: =Progress!D15 -> 0.02896104 | E21: =Progress!E15 -> 15291.43 | F21: =Progress!F15 -> 0 | G21: =Progress!G15 -> 1320006.9 | H21: =Progress!H15 -> 1335298.3 | I21: =Progress!I15 -> 1830342.9 | J21: =IFERROR(IF(ISBLANK(G21),"",G21/C21),0) -> 0.52520718 | K21: =IFERROR(IF(ISBLANK(H21),"",H21/C21),0) -> 0.53129137 | L21: =IFERROR(IF(ISBLANK(I21),"",I21/C21),0) -> 0.72826077 | M21: =IFERROR(L21-K21,"") -> 0.1969694 | N21: =IFERROR(L21/K21,"") -> 1.3707371 | O21: =Progress!L15 -> 14022.14 | P21: =IF(ISBLANK(O21),"",O21/$O$28) -> 0.019623426 | Q21: =Progress!N15 -> 171.43 | R21: =Progress!O15 -> 0 | S21: =IFERROR(IF(ISBLANK(Q21),"",Q21/O21),0) -> 0.012225666 | T21: =IFERROR(IF(ISBLANK(R21),"",R21/O21),0) -> 0 | U21: =Progress!P15 -> 7721.43 | V21: =Progress!Q15 -> 12207.14 | W21: =IFERROR(IF(ISBLANK(U21),"",U21/O21),0) -> 0.55065989 | X21: =IFERROR(IF(ISBLANK(V21),"",V21/O21),0) -> 0.87056184 | Y21: =IFERROR(X21-W21,"") -> 0.31990196 | Z21: =IFERROR(X21/W21,"") -> 1.5809429
A22: =Progress!A16 -> Outside Boundary Area (Tie-in Lines) | C22: =Progress!C16 -> 2681726.3 | D22: =Progress!D16 -> 0.030901749 | E22: =Progress!E16 -> 71160.39 | F22: =Progress!F16 -> 0 | G22: =Progress!G16 -> 1339359.5 | H22: =Progress!H16 -> 1410519.9 | I22: =Progress!I16 -> 2663147.2 | J22: =IFERROR(IF(ISBLANK(G22),"",G22/C22),0) -> 0.4994393 | K22: =IFERROR(IF(ISBLANK(H22),"",H22/C22),0) -> 0.52597459 | L22: =IFERROR(IF(ISBLANK(I22),"",I22/C22),0) -> 0.99307196 | M22: =IFERROR(L22-K22,"") -> 0.46709737 | N22: =IFERROR(L22/K22,"") -> 1.8880607 | O22: =Progress!L16 -> 19949.2 | P22: =IF(ISBLANK(O22),"",O22/$O$28) -> 0.02791811 | Q22: =Progress!N16 -> 681.43 | R22: =Progress!O16 -> 0 | S22: =IFERROR(IF(ISBLANK(Q22),"",Q22/O22),0) -> 0.034158262 | T22: =IFERROR(IF(ISBLANK(R22),"",R22/O22),0) -> 0 | U22: =Progress!P16 -> 9933.13 | V22: =Progress!Q16 -> 19885.03 | W22: =IFERROR(IF(ISBLANK(U22),"",U22/O22),0) -> 0.49792122 | X22: =IFERROR(IF(ISBLANK(V22),"",V22/O22),0) -> 0.99678333 | Y22: =IFERROR(X22-W22,"") -> 0.49886211 | Z22: =IFERROR(X22/W22,"") -> 2.0018896
A23: =Progress!A17 -> Roads Finishing | C23: =Progress!C17 -> 8138565 | D23: =Progress!D17 -> 0.093781345 | E23: =Progress!E17 -> 0 | F23: =Progress!F17 -> 83647.88 | G23: =Progress!G17 -> 0 | H23: =Progress!H17 -> 0 | I23: =Progress!I17 -> 5591559.2 | J23: =IFERROR(IF(ISBLANK(G23),"",G23/C23),0) -> 0 | K23: =IFERROR(IF(ISBLANK(H23),"",H23/C23),0) -> 0 | L23: =IFERROR(IF(ISBLANK(I23),"",I23/C23),0) -> 0.68704485 | M23: =IFERROR(L23-K23,"") -> 0.68704485 | N23: =IFERROR(L23/K23,"") | O23: =Progress!L17 -> 65951.79 | P23: =IF(ISBLANK(O23),"",O23/$O$28) -> 0.092296901 | Q23: =Progress!N17 -> 0 | R23: =Progress!O17 -> 190 | S23: =IFERROR(IF(ISBLANK(Q23),"",Q23/O23),0) -> 0 | T23: =IFERROR(IF(ISBLANK(R23),"",R23/O23),0) -> 0.0028808922 | U23: =Progress!P17 -> 0 | V23: =Progress!Q17 -> 45112.37 | W23: =IFERROR(IF(ISBLANK(U23),"",U23/O23),0) -> 0 | X23: =IFERROR(IF(ISBLANK(V23),"",V23/O23),0) -> 0.6840204 | Y23: =IFERROR(X23-W23,"") -> 0.6840204 | Z23: =IFERROR(X23/W23,"")
A24: =Progress!A18 -> Fence and Gate | C24: =Progress!C18 -> 8127691.9 | D24: =Progress!D18 -> 0.093656053 | E24: =Progress!E18 -> 88958.71 | F24: =Progress!F18 -> 0 | G24: =Progress!G18 -> 2119815.9 | H24: =Progress!H18 -> 2208774.6 | I24: =Progress!I18 -> 5352415.6 | J24: =IFERROR(IF(ISBLANK(G24),"",G24/C24),0) -> 0.26081401 | K24: =IFERROR(IF(ISBLANK(H24),"",H24/C24),0) -> 0.27175914 | L24: =IFERROR(IF(ISBLANK(I24),"",I24/C24),0) -> 0.65854066 | M24: =IFERROR(L24-K24,"") -> 0.38678151 | N24: =IFERROR(L24/K24,"") -> 2.4232511 | O24: =Progress!L18 -> 43715 | P24: =IF(ISBLANK(O24),"",O24/$O$28) -> 0.0611774 | Q24: =Progress!N18 -> 50 | R24: =Progress!O18 -> 0 | S24: =IFERROR(IF(ISBLANK(Q24),"",Q24/O24),0) -> 0.0011437722 | T24: =IFERROR(IF(ISBLANK(R24),"",R24/O24),0) -> 0 | U24: =Progress!P18 -> 24025 | V24: =Progress!Q18 -> 25427 | W24: =IFERROR(IF(ISBLANK(U24),"",U24/O24),0) -> 0.54958252 | X24: =IFERROR(IF(ISBLANK(V24),"",V24/O24),0) -> 0.58165389 | Y24: =IFERROR(X24-W24,"") -> 0.032071371 | Z24: =IFERROR(X24/W24,"") -> 1.0583559
... A27: =Progress!A21 -> Project Close-out | C27: =Progress!C21 -> 0 | D27: =Progress!D21 -> 0 | E27: =Progress!E21 -> 0 | F27: =Progress!F21 -> 0 | G27: =Progress!G21 -> 0 | H27: =Progress!H21 -> 0 | I27: =Progress!I21 -> 0 | J27: =IFERROR(IF(ISBLANK(G27),"",G27/C27),0) -> 0 | K27: =IFERROR(IF(ISBLANK(H27),"",H27/C27),0) -> 0 | L27: =IFERROR(IF(ISBLANK(I27),"",I27/C27),0) -> 0 | M27: =IFERROR(L27-K27,"") -> 0 | N27: =IFERROR(L27/K27,"") | O27: =Progress!L21 -> 13364 | P27: =IF(ISBLANK(O27),"",O27/$O$28) -> 0.018702385 | Q27: =Progress!N21 -> 0 | R27: =Progress!O21 -> 0 | S27: =IFERROR(IF(ISBLANK(Q27),"",Q27/O27),0) -> 0 | T27: =IFERROR(IF(ISBLANK(R27),"",R27/O27),0) -> 0 | U27: =Progress!P21 -> 0 | V27: =Progress!Q21 -> 0 | W27: =IFERROR(IF(ISBLANK(U27),"",U27/O27),0) -> 0 | X27: =IFERROR(IF(ISBLANK(V27),"",V27/O27),0) -> 0 | Y27: =IFERROR(X27-W27,"") -> 0 | Z27: =IFERROR(X27/W27,"")
B28: Total | C28: =Progress!C25 -> 86782345 | D28: =Progress!D25 -> 1 | E28: =SUM(E12:E22) -> 815665.01 | F28: =SUM(F12:F22) -> 505074.46 | G28: =Progress!G25 -> 45732412 | H28: =Progress!H25 -> 46153497 | I28: =Progress!I25 -> 68315969 | J28: =IFERROR(IF(ISBLANK(G28),"",G28/C28),0) -> 0.5269783 | K28: =IFERROR(IF(ISBLANK(H28),"",H28/C28),0) -> 0.53183049 | L28: =I28/C28 -> 0.78721045 | M28: =+L28-K28 -> 0.25537996 | N28: =L28/K28 -> 1.4801905 | O28: =Progress!L25 -> 714561.26 | P28: =Progress!M25 -> 1 | Q28: =Progress!N25 -> 5590.01 | R28: =Progress!O25 -> 1907.15 | S28: =IFERROR(IF(ISBLANK(Q28),"",Q28/O28),0) -> 0.0078229962 | T28: =IFERROR(IF(ISBLANK(R28),"",R28/O28),0) -> 0.0026689804 | U28: =Progress!P25 -> 335745.11 | V28: =Progress!Q25 -> 518858.48 | W28: =IFERROR(IF(ISBLANK(U28),"",U28/O28),0) -> 0.4698619 | X28: =IFERROR(IF(ISBLANK(V28),"",V28/O28),0) -> 0.72612176 | Y28: =+X28-W28 -> 0.25625986 | Z28: =X28/W28 -> 1.545394
AA29: Construction Milestones
AA30: Item No. | AB30: Milestones | AD30: Original (Baseline) | AE30: Latest Plan | AF30: Forecast | AG30: Status | AH30: Days Change
AA31: =+Milestones!A4 -> 1 | AB31: =+Milestones!B4 -> Project Finish | AD31: =+Milestones!D4 -> 46886 | AE31: =+Milestones!E4 -> 46893 | AF31: =+Milestones!E4 -> 46893 | AG31: =+Milestones!F4 -> F | AH31: =+Milestones!G4 -> -7
Z32: =+Milestones!#REF! -> #REF! | AA32: =+Milestones!A5 -> 2 | AB32: =+Milestones!B5 -> Project Start | AD32: =+Milestones!D5 -> 45980 | AE32: =+Milestones!E5 -> 45980 | AF32: =+Milestones!E5 -> 45980 | AG32: =+Milestones!F5 -> A | AH32: =+Milestones!G5 -> 0
Z33: =+Milestones!#REF! -> #REF! | AA33: =+Milestones!A6 -> 3 | AB33: =+Milestones!B6 -> Finish Mobilization | AD33: =+Milestones!D6 -> 46085 | AE33: =+Milestones!E6 -> 46085 | AF33: =+Milestones!E6 -> 46085 | AG33: =+Milestones!F6 -> A | AH33: =+Milestones!G6 -> 0
Z34: =+Milestones!#REF! -> #REF! | AA34: =+Milestones!A7 -> 4 | AB34: =+Milestones!B7 -> Finish Baseline Time Schedule | AD34: =+Milestones!D7 -> 46009 | AE34: =+Milestones!E7 -> 46009 | AF34: =+Milestones!E7 -> 46009 | AG34: =+Milestones!F7 -> A | AH34: =+Milestones!G7 -> 0
Z35: =+Milestones!#REF! -> #REF! | AA35: =+Milestones!A8 -> 5 | AB35: =+Milestones!B8 -> Finish Submission and Approval for Shop Drawings, Method of Statement, Prequalification and Materials | AD35: =+Milestones!D8 -> 46326 | AE35: =+Milestones!E8 -> 46333 | AF35: =+Milestones!E8 -> 46333 | AG35: =+Milestones!F8 -> F | AH35: =+Milestones!G8 -> -7
Z36: =+Milestones!#REF! -> #REF! | AA36: =+Milestones!A9 -> 6 | AB36: =+Milestones!B9 -> Finish PO for Short Lead Item & Long Lead Item | AD36: =+Milestones!D9 -> 46320 | AE36: =+Milestones!E9 -> 46327 | AF36: =+Milestones!E9 -> 46327 | AG36: =+Milestones!F9 -> F | AH36: =+Milestones!G9 -> -7
G37: 20000000 | Z37: =+Milestones!#REF! -> #REF! | AA37: =+Milestones!A10 -> 7 | AB37: =+Milestones!B10 -> Completion of Roads & Meduim Voltage | AD37: =+Milestones!D10 -> 46398 | AE37: =+Milestones!E10 -> 46405 | AF37: =+Milestones!E10 -> 46405 | AG37: =+Milestones!F10 -> F | AH37: =+Milestones!G10 -> -7
AA38: =+Milestones!A11 -> 8 | AB38: =+Milestones!B11 -> Completion of Deep infrastructure network | AD38: =+Milestones!D11 -> 46550 | AE38: =+Milestones!E11 -> 46557 | AF38: =+Milestones!E11 -> 46557 | AG38: =+Milestones!F11 -> F | AH38: =+Milestones!G11 -> -7
AA39: =+Milestones!A12 -> 9 | AB39: =+Milestones!B12 -> Completion of Shallow infrastructure network | AD39: =+Milestones!D12 -> 46656 | AE39: =+Milestones!E12 -> 46663 | AF39: =+Milestones!E12 -> 46663 | AG39: =+Milestones!F12 -> F | AH39: =+Milestones!G12 -> -7
Z40: =+Milestones!#REF! -> #REF! | AA40: =+Milestones!A13 -> 10 | AB40: =+Milestones!B13 -> Completion all Works | AD40: =+Milestones!D13 -> 46886 | AE40: =+Milestones!E13 -> 46893 | AF40: =+Milestones!E13 -> 46893 | AG40: =+Milestones!F13 -> F | AH40: =+Milestones!G13 -> -7
Z41: =+Milestones!#REF! -> #REF!
Z42: =+Milestones!#REF! -> #REF!
Z43: =+Milestones!#REF! -> #REF!
...

Sheet General Information
A1: Weekly Progress Report - Construction Projects | K1: Data Date | L1: 46315
A2: Contract General Information | K2: Week No. | L2: =(L1-C14)/7 -> 47.857143
A3: Project Name | C3: INFRASTRUCTURE DEVELOPMENT FOR INDUSTRIAL CITY 1 IN JEDDAH
A4: Project ID | C4: JDH1-02-003
A5: Contractor | C5: Al Enjaz Company for Trading and Contracting
A6: Consultant | C6: Saudi Arabia Consulting Engineering Company "EGIS"
A7: Stage | C7: Construction
A8: Status | C8: Active
A9: Modon PM | C9: Engr.Abdallah Aljulayfi
A11: Key Dates
A12: Contract Award Date | C12: 45963
A13: Contract Sign Date | C13: 45974
A14: Site Handover Date | C14: 45980
A15: Original Completion | C15: 46709
A16: Contract Award Date (Hijri) | C16: =C12 -> 45963
A17: Contract Sign Date (Hijri) | C17: =C13 -> 45974
A18: Site Handover Date (Hijri) | C18: =C14 -> 45980
A19: Original Completion (Hijri) | C19: =C15 -> 46709
A20: Revised Completion Date | C20: 46709
A21: Committed Completion Date | C21: 46709
A22: Forecast Completion | C22: 46893
A23: Variance | C23: =C20-C22 -> -184
A25: Key Project Submittals | C25: Submission Date | D25: Days taken to approve orginal plan from site handover date
A26: Quality Plan submission | C26: 45986 | D26: =C26-C14 -> 6
A27: Quality Plan approval | C27: 46062
A28: Quality Plan Last Update | C28: -
A30: Safety Plan submission | C30: 46001 | D30: =C30-C14 -> 21
A31: Safety Plan approval | C31: 46056
A32: Safety Plan Last Update | C32: -
A34: Risk Management Plan submission | C34: 46006 | D34: =C34-C14 -> 26
A35: Risk Management Plan approval | C35: 46009
A36: Risk Management Plan Last Update | C36: -
A38: Baseline Schedule submission | C38: 46007 | D38: =C38-C14 -> 27
A39: Baseline Schedule approval | C39: 46009
A40: No of Schedule Versions | C40: 1
A41: Last Revised Schedule Approval Date | C41: -
A43: BOQ submission | C43: 45980 | D43: =C43-C14 -> 0
A44: BOQ approval | C44: 45980
A45: No of Approved Version of BOQ
A47: Execution Plan submission | C47: 45986 | D47: =C47-C14 -> 6
...

Sheet Progress
A1: Project Scope Statement
A4: Earned Value Progress (SAR) | L4: Physical Progress (Effort)
A5: WBS | C5: BOQ Value (SAR) | D5: % Wt. | E5: Weekly (SAR) | H5: To Date (SAR) | J5: Actual % | L5: Budgeted | M5: % Wt. | N5: Weekly Physical Progress | P5: To Date Physical Progress | T5: Last Week Cost (SAR) | V5: Last Week Physical Progress
E6: Planned | F6: Earned | G6: Original Plan | H6: Planned | I6: Earned | L6: (Manhours) | N6: Planned | O6: Earned | P6: Planned | Q6: Earned | S6: 5508011 | T6: Planned | U6: Earned | V6: Planned | W6: Earned
A7: Mobilization | C7: 0 | E7: =H7-T7 -> 0 | F7: =I7-U7 -> 0 | G7: 0 | H7: =E39 -> 0 | I7: =F39 -> 0 | J7: =I7/$C$25 -> 0 | L7: 20050 | M7: =L7/$L$25 -> 0.028059176 | N7: =P7-V7 -> 0 | O7: =Q7-W7 -> 0 | P7: =H39 -> 20050 | Q7: =I39 -> 20050 | S7: 0 | T7: 0 | U7: 0 | V7: 20050 | W7: 20050
A8: Engineering | C8: 2601460.4 | D8: =C8/$C$25 -> 0.029976839 | E8: =H8-T8 -> 0 | F8: =I8-U8 -> 0 | G8: 2601460.4 | H8: =E40 -> 2601460.4 | I8: =F40 -> 2579200.4 | J8: =I8/$C$25 -> 0.029720335 | L8: 33415 | M8: =L8/$L$25 -> 0.046762961 | N8: =P8-V8 -> 0 | O8: =Q8-W8 -> 0 | P8: 33415 | Q8: 33009.2 | S8: 0 | T8: 2601460.4 | U8: 2579200.4 | V8: 33415 | W8: 33009.2
A9: Procurement | C9: 17355662 | D9: =C9/$C$25 -> 0.1999907 | E9: =H9-T9 -> 26504 | F9: =I9-U9 -> 208500 | G9: 13492073 | H9: =E41 -> 13518577 | I9: =F41 -> 15737880 | J9: =I9/$C$25 -> 0.18134887 | L9: 82413.81 | M9: =L9/$L$25 -> 0.11533484 | N9: =P9-V9 -> 0 | O9: =Q9-W9 -> 0 | P9: 35843.52 | Q9: 65032.49 | S9: 1889863.4 | T9: 13492073 | U9: 15529380 | V9: 35843.52 | W9: 65032.49
A10: Construction | C10: 58147531 | D10: =C10/$C$25 -> 0.67003872 | E10: =H10-T10 -> 394580.51 | F10: =I10-U10 -> 190111.17 | G10: 29638879 | H10: =E42 -> 30033459 | I10: =F42 -> 44572325 | J10: =I10/$C$25 -> 0.51361052 | L10: 545268.46 | M10: =L10/$L$25 -> 0.76308147 | N10: =P10-V10 -> 5590.01 | O10: =Q10-W10 -> 1907.14 | P10: =H42 -> 246436.59 | Q10: =I42 -> 390120.29 | S10: 1520807.4 | T10: 29638879 | U10: 44382214 | V10: 240846.58 | W10: 388213.15
A11: Site Demolition | C11: 279942.75 | D11: =C11/$C$25 -> 0.003225803 | E11: =H11-T11 -> 0 | F11: =I11-U11 -> 0 | G11: 279942.75 | H11: =E43 -> 279942.75 | I11: =F43 -> 279942.75 | J11: =I11/$C$25 -> 0.003225803 | L11: 7350 | M11: =L11/$L$25 -> 0.010286032 | N11: =P11-V11 -> 0 | O11: =Q11-W11 -> 0 | P11: =H43 -> 7350 | Q11: =I43 -> 7350 | S11: 2097340.2 | T11: 279942.75 | U11: 279942.75 | V11: 7350 | W11: 7350
A12: Roads & Meduim Voltage | C12: 11810039 | D12: =C12/$C$25 -> 0.13608803 | E12: =H12-T12 -> 0 | F12: =I12-U12 -> 0 | G12: 11810039 | H12: =E44 -> 11810039 | I12: =F44 -> 8650438.8 | J12: =I12/$C$25 -> 0.099679708 | L12: 100175 | M12: =L12/$L$25 -> 0.14019092 | N12: =P12-V12 -> 0 | O12: =Q12-W12 -> 0 | P12: =H44 -> 100175 | Q12: =I44 -> 73591 | S12: 957625.34 | T12: 11810039 | U12: 8650438.8 | V12: 100175 | W12: 73591
A13: Deep Infrastructure network | C13: 10009830 | D13: =C13/$C$25 -> 0.11534409 | E13: =H13-T13 -> 10082.82 | F13: =I13-U13 -> 7209.5 | G13: 9958787.2 | H13: =E45 -> 9968870 | I13: =F45 -> 9750710.5 | J13: =I13/$C$25 -> 0.11235823 | L13: 54025 | M13: =L13/$L$25 -> 0.075605834 | N13: =P13-V13 -> 0 | O13: =Q13-W13 -> 0 | P13: =H45 -> 54025 | Q13: =I45 -> 51820.5 | S13: 583145.23 | T13: 9958787.2 | U13: 9743501 | V13: 54025 | W13: 51820.5
A14: Shallow infrastructure network | C14: 12539076 | D14: =C14/$C$25 -> 0.14448879 | E14: =H14-T14 -> 209087.15 | F14: =I14-U14 -> 99253.79 | G14: 2810927.8 | H14: =E46 -> 3020015 | I14: =F46 -> 10453768 | J14: =I14/$C$25 -> 0.12045962 | L14: 198577.38 | M14: =L14/$L$25 -> 0.27790113 | N14: =P14-V14 -> 4687.15 | O14: =Q14-W14 -> 1717.15 | P14: =H46 -> 43207.03 | Q14: =I46 -> 154727.25 | S14: 556569.64 | T14: 2810927.8 | U14: 10354514 | V14: 38519.88 | W14: 153010.1
A15: Bridge | C15: 2513307 | D15: =C15/$C$25 -> 0.02896104 | E15: =H15-T15 -> 15291.43 | F15: =I15-U15 -> 0 | G15: 1320006.9 | H15: =E47 -> 1335298.3 | I15: =F47 -> 1830342.9 | J15: =I15/$C$25 -> 0.02109119 | L15: 14022.14 | M15: =L15/$L$25 -> 0.019623426 | N15: =P15-V15 -> 171.43 | O15: =Q15-W15 -> 0 | P15: =H47 -> 7721.43 | Q15: =I47 -> 12207.14 | S15: 0 | T15: 1320006.9 | U15: 1830342.9 | V15: 7550 | W15: 12207.14
A16: Outside Boundary Area (Tie-in Lines) | C16: 2681726.3 | D16: =C16/$C$25 -> 0.030901749 | E16: =H16-T16 -> 71160.39 | F16: =I16-U16 -> 0 | G16: 1339359.5 | H16: =E48 -> 1410519.9 | I16: =F48 -> 2663147.2 | J16: =I16/$C$25 -> 0.030687661 | L16: 19949.2 | M16: =L16/$L$25 -> 0.02791811 | N16: =P16-V16 -> 681.43 | O16: =Q16-W16 -> 0 | P16: =H48 -> 9933.13 | Q16: =I48 -> 19885.03 | S16: 0 | T16: 1339359.5 | U16: 2663147.2 | V16: 9251.7 | W16: 19885.03
A17: Roads Finishing | C17: 8138565 | D17: =C17/$C$25 -> 0.093781345 | E17: =H17-T17 -> 0 | F17: =I17-U17 -> 83647.88 | G17: 0 | H17: =E49 -> 0 | I17: =F49 -> 5591559.2 | J17: =I17/$C$25 -> 0.06443199 | L17: 65951.79 | M17: =L17/$L$25 -> 0.092296901 | N17: =P17-V17 -> 0 | O17: =Q17-W17 -> 190 | P17: =H49 -> 0 | Q17: =I49 -> 45112.37 | T17: 0 | U17: 5507911.3 | V17: 0 | W17: 44922.37
A18: Fence and Gate | C18: 8127691.9 | D18: =C18/$C$25 -> 0.093656053 | E18: =H18-T18 -> 88958.71 | F18: =I18-U18 -> 0 | G18: 2119815.9 | H18: =E50 -> 2208774.6 | I18: =F50 -> 5352415.6 | J18: =I18/$C$25 -> 0.061676319 | L18: 43715 | M18: =L18/$L$25 -> 0.0611774 | N18: =P18-V18 -> 50 | O18: =Q18-W18 -> 0 | P18: =H50 -> 24025 | Q18: =I50 -> 25427 | T18: 2119815.9 | U18: 5352415.6 | V18: 23975 | W18: 25427
A19: Roundabout & Landscape | C19: 2047352.9 | D19: =C19/$C$25 -> 0.023591814 | E19: =H19-T19 -> 0 | F19: =I19-U19 -> 0 | G19: 0 | H19: =E51 -> 0 | I19: =F51 -> 0 | J19: =I19/$C$25 -> 0 | L19: 41502.94 | M19: =L19/$L$25 -> 0.05808171 | N19: =P19-V19 -> 0 | O19: =Q19-W19 -> 0 | P19: =H51 -> 0 | Q19: =I51 -> 0 | T19: 0 | U19: 0 | V19: 0 | W19: 0
A20: Testing & Commissioning | C20: 8677691.2 | D20: =C20/$C$25 -> 0.09999374 | E20: =H20-T20 -> 0 | F20: =I20-U20 -> 0 | G20: 0 | H20: =E52 -> 0 | I20: =F52 -> 5426563.3 | J20: =I20/$C$25 -> 0.062530729 | L20: 20050 | M20: =L20/$L$25 -> 0.028059176 | N20: =P20-V20 -> 0 | O20: =Q20-W20 -> 0 | P20: =H52 -> 0 | Q20: =I52 -> 10646.5 | T20: 0 | U20: 5426563.3 | V20: 0 | W20: 10646.5
A21: Project Close-out | C21: 0 | D21: 0 | E21: =H21-T21 -> 0 | F21: =I21-U21 -> 0 | G21: 0 | H21: =E53 -> 0 | I21: =F53 -> 0 | J21: =I21/$C$25 -> 0 | L21: 13364 | M21: =L21/$L$25 -> 0.018702385 | N21: =P21-V21 -> 0 | O21: =Q21-W21 -> 0 | P21: =H53 -> 0 | Q21: =I53 -> 0 | T21: 0 | U21: 0 | V21: 0 | W21: 0
E22: =H22-T22 -> 0 | F22: =I22-U22 -> 0 | N22: =P22-V22 -> 0 | O22: =Q22-W22 -> 0
E23: =H23-T23 -> 0 | F23: =I23-U23 -> 0 | N23: =P23-V23 -> 0 | O23: =Q23-W23 -> 0
E24: =H24-T24 -> 0 | F24: =I24-U24 -> 0 | N24: =P24-V24 -> 0 | O24: =Q24-W24 -> 0
B25: Total | C25: =C7+C8+C9+C11+C12+C13+C14+C15+C16+C17+C18+C19+C20+C21 -> 86782345 | D25: =D7+D8+D9+D11+D12+D13+D14+D15+D16+D17+D18+D19+D20+D21 -> 1 | E25: =E7+E8+E9+E11+E12+E13+E14+E15+E16+E17+E18+E19+E20+E21 -> 421084.5 | F25: =F7+F8+F9+F11+F12+F13+F14+F15+F16+F17+F18+F19+F20+F21 -> 398611.17 | G25: =G7+G8+G9+G11+G12+G13+G14+G15+G16+G17+G18+G19+G20+G21 -> 45732412 | H25: =H7+H8+H9+H11+H12+H13+H14+H15+H16+H17+H18+H19+H20+H21 -> 46153497 | I25: =I7+I8+I9+I11+I12+I13+I14+I15+I16+I17+I18+I19+I20+I21 -> 68315969 | J25: =I25/$C$25 -> 0.78721045 | L25: =L7+L8+L9+L11+L12+L13+L14+L15+L16+L17+L18+L19+L20+L21 -> 714561.26 | M25: =M7+M8+M9+M11+M12+M13+M14+M15+M16+M17+M18+M19+M20+M21 -> 1 | N25: =N7+N8+N9+N11+N12+N13+N14+N15+N16+N17+N18+N19+N20+N21 -> 5590.01 | O25: =O7+O8+O9+O11+O12+O13+O14+O15+O16+O17+O18+O19+O20+O21 -> 1907.15 | P25: =P7+P8+P9+P11+P12+P13+P14+P15+P16+P17+P18+P19+P20+P21 -> 335745.11 | Q25: =Q7+Q8+Q9+Q11+Q12+Q13+Q14+Q15+Q16+Q17+Q18+Q19+Q20+Q21 -> 518858.48 | T25: =T7+T8+T9+T11+T12+T13+T14+T15+T16+T17+T18+T19+T20+T21 -> 45732412 | U25: =U7+U8+U9+U11+U12+U13+U14+U15+U16+U17+U18+U19+U20+U21 -> 67917358 | V25: =V7+V8+V9+V11+V12+V13+V14+V15+V16+V17+V18+V19+V20+V21 -> 330155.1 | W25: =W7+W8+W9+W11+W12+W13+W14+W15+W16+W17+W18+W19+W20+W21 -> 516951.33
G26: =G25/C25 -> 0.5269783 | H26: =H25/C25 -> 0.53183049 | I26: =I25/C25 -> 0.78721045 | P26: =P25/L25 -> 0.4698619 | Q26: =Q25/L25 -> 0.72612176
I27: =H26-I26 -> -0.25537996
A36: Activity ID | B36: Activity Name | C36: Original Duration | D36: Budgeted Total Cost | E36: Planned Value Cost | F36: Earned Value Cost | G36: Budgeted Labor Units | H36: Planned Value Labor Units | I36: Earned Value Labor Units
A37: JDH1-02-003 - Infrastructure Development For Industrial City 1 In Jeddah - Update - 20.10.2026 | C37: 763 | D37: 86782345 | E37: 46153497 | F37: 68315969 | G37: 714561.27 | H37: 347982.15 | I37: 528822.75 | J37: 461520.15 | K37: =I37-J37 -> 67302.6
A38: Milestones | C38: 763 | D38: 0 | E38: 0 | F38: 0 | G38: 0 | H38: 0 | I38: 0 | J38: 0 | K38: =I38-J38 -> 0
A39: Mobilization | C39: 112 | D39: 0 | E39: 0 | F39: 0 | G39: 20050 | H39: 20050 | I39: 20050 | J39: 20050 | K39: =I39-J39 -> 0
A40: Engineering | C40: 287 | D40: 2601460.4 | E40: 2601460.4 | F40: 2579200.4 | G40: 33415 | H40: 33415 | I40: 33009.2 | J40: 33009.2 | K40: =I40-J40 -> 0
A41: Procurement | C41: 502 | D41: 17355662 | E41: 13518577 | F41: 15737880 | G41: 82413.81 | H41: 48080.56 | I41: 74996.76 | J41: 65032.49 | K41: =I41-J41 -> 9964.27
A42: Construction | C42: 710 | D42: 58147531 | E42: 30033459 | F42: 44572325 | G42: 545268.46 | H42: 246436.59 | I42: 390120.29 | J42: 339660.46 | K42: =I42-J42 -> 50459.83
A43: Site Demolition | C43: 93 | D43: 279942.75 | E43: 279942.75 | F43: 279942.75 | G43: 7350 | H43: 7350 | I43: 7350 | J43: 7350 | K43: =I43-J43 -> 0
A44: Roads & Meduim Voltage | C44: 423 | D44: 11810039 | E44: 11810039 | F44: 8650438.8 | G44: 100175 | H44: 100175 | I44: 73591 | J44: 72812.5 | K44: =I44-J44 -> 778.5
A45: Deep Infrastructure network | C45: 277 | D45: 10009830 | E45: 9968870 | F45: 9750710.5 | G45: 54025 | H45: 54025 | I45: 51820.5 | J45: 51617.5 | K45: =I45-J45 -> 203
A46: Shallow infrastructure network | C46: 433 | D46: 12539076 | E46: 3020015 | F46: 10453768 | G46: 198577.38 | H46: 43207.03 | I46: 154727.25 | J46: 126285.02 | K46: =I46-J46 -> 28442.23
A47: Bridge | C47: 452 | D47: 2513307 | E47: 1335298.3 | F47: 1830342.9 | G47: 14022.14 | H47: 7721.43 | I47: 12207.14 | J47: 11391.07 | K47: =I47-J47 -> 816.07
A48: Outside Boundary Area (Tie-in Lines) | C48: 419 | D48: 2681726.3 | E48: 1410519.9 | F48: 2663147.2 | G48: 19949.2 | H48: 9933.13 | I48: 19885.03 | J48: 17900.29 | K48: =I48-J48 -> 1984.74
... A53: Project Close-out | C53: 145 | D53: 0 | E53: 0 | F53: 0 | G53: 13364 | H53: 0 | I53: 0 | J53: 0 | K53: =I53-J53 -> 0
F74: Activity ID | G74: Activity Name | H74: Original Duration | I74: BL Project Start | J74: BL Project Finish | L74: Start | M74: Finish | N74: Planned Value Cost | O74: Actual Total Cost | P74: Earned Value Cost | Q74: Schedule % Complete | R74: Performance % Complete | S74: Budgeted Total Cost | U74: Actual Labor Units | V74: Earned Value Labor Units | W74: Total Float
...

Sheet Weekly Photos
V1: ='[37]General Information'!K1 -> Data Date | W1: ='General Information'!L1 -> 46315
B2: L01 - Installation of Telecom Pipes | L2: Curbstone works
B21: L01 - Backfilling of Telecom Pipes | L21: Interlock works
B41: Interlock works | L41: Installation of street lights fuse box of local 1
B60: Installation of Light Poles | L60: Excavation of irrigation main pipes in plot no 10 for landscaping

Sheet Major Quantities
A1: BOQ Number | B1: Description of Item | C1: Total Quantity | D1: Unit of Measurement | E1: Plan To Date | F1: Actual To Date | G1: Remaining Total | H1: Variance
A2: 31 22 00.01 | B2: Excavation for Roadway, fences and bridge, cuttings including dump locations (all types of soil) | C2: 116177.4 | D2: m3 | E2: =C2*1 -> 116177.4 | F2: =C2*1 -> 116177.4 | G2: =C2-F2 -> 0 | H2: =F2-E2 -> 0
A3: 31 22 00.02 | B3: Parcrels Excavation for cuttings (all types of soil) | C3: 123555 | D3: m3 | E3: =C3*1 -> 123555 | F3: =1*C3 -> 123555 | G3: =C3-F3 -> 0 | H3: =F3-E3 -> 0
A4: 31 22 00.03 | B4: Embankments to the roads , fences and bridge. | C4: 80919.7 | D4: m3 | E4: =1*C4 -> 80919.7 | F4: =1*C4 -> 80919.7 | G4: =C4-F4 -> 0 | H4: =F4-E4 -> 0
A5: 31 22 00.04 | B5: Embankments to the parcels | C5: 94645 | D5: m3 | E5: =1*C5 -> 94645 | F5: =0.998*C5 -> 94455.71 | G5: =C5-F5 -> 189.29 | H5: =F5-E5 -> -189.29
A6: 31 22 00.05 | B6: Subgrade | C6: 34693.65 | D6: m3 | E6: =1*C6 -> 34693.65 | F6: =1*C6 -> 34693.65 | G6: =C6-F6 -> 0 | H6: =F6-E6 -> 0
A7: 32 11 23.01 | B7: Aggregate base course | C7: 23129.1 | D7: m3 | E7: =1*C7 -> 23129.1 | F7: =1*C7 -> 23129.1 | G7: =C7-F7 -> 0 | H7: =F7-E7 -> 0
A8: 32 11 26.01 | B8: Bituminous base course (Grading I - Class A), including Prime Coat (MC1) according to drawings | C8: 8290 | D8: m3 | E8: =1*C8 -> 8290 | F8: =C8*1 -> 8290 | G8: =C8-F8 -> 0 | H8: =F8-E8 -> 0
A9: 32 12 16.01 | B9: Bituminous concrete wearing course, (Grading I - Class A), including tack coat (RC2) according to drawings. | C9: 5920 | D9: m3 | E9: 0 | F9: 2074 | G9: =C9-F9 -> 3846 | H9: =F9-E9 -> 2074
A10: 33 42 11 | B10: GRP Pipes for Storm network | C10: 5650 | D10: m | E10: =1*C10 -> 5650 | F10: 5650 | G10: =C10-F10 -> 0 | H10: =F10-E10 -> 0 | J10: =F10/C10 -> 1
A11: 33 14 13 | B11: High Density Polyethylene pipes PE 100 SDR 11 (PN 16 Bars) | C11: =4575+738.28+3182+3580 -> 12075.28 | D11: m | E11: =0.578*C11 -> 6979.5118 | F11: 12075 | G11: =C11-F11 -> 0.28 | H11: =F11-E11 -> 5095.4882 | J11: =F11/C11 -> 0.99997681
A12: 33 14 13 | B12: High Density Polyethylene pipes PE 100 SDR 11 (PN 16 Bars) | C12: 8722 | D12: m | E12: =0.733*C12 -> 6393.226 | F12: 8700 | G12: =C12-F12 -> 22 | H12: =F12-E12 -> 2306.774 | J12: =F12/C12 -> 0.99747764
A13: 33 31 00 | B13: Glass Reinforced Plastic (GRP) for Sewer network | C13: 6244 | D13: m | E13: =1*C13 -> 6244 | F13: 6244 | G13: =C13-F13 -> 0 | H13: =F13-E13 -> 0 | J13: =F13/C13 -> 1
G14: =C14-F14 -> 0 | H14: =F14-E14 -> 0
G15: =C15-F15 -> 0 | H15: =F15-E15 -> 0
G16: =C16-F16 -> 0 | H16: =F16-E16 -> 0
G17: =C17-F17 -> 0 | H17: =F17-E17 -> 0
G18: =C18-F18 -> 0 | H18: =F18-E18 -> 0
G19: =C19-F19 -> 0 | H19: =F19-E19 -> 0

Sheet Quality  
B2: QC OBSERVATIONS CHECKLIST
B6: Project No. | E6: JDH1-02-003 | K6: OBS No. | O6: ='General Information'!L2 -> 47.857143 | U6: Inspection Day: | X6: ='General Information'!L1 -> 46315
B8: Project | E8: INFRASTRUCTURE DEVELOPMENT FOR INDUSTRIAL CITY 1 IN JEDDAH | O8: Contractor: | U8: Al Enjaz Company for Trading and Contracting
O9: Consultant: | U9: EGIS Saudi ARABIA CONSULTANT ENGINEERING COMPANY
B11: 4 | D11: Excellent | G11: Quality Management System is being practiced and applies to MODON System | Z11: 90 - 100 | AB11: QC Overall Score | AC11: =Q50 -> 0.85206897 | AN11: =SUM(Z11:Z14) -> 0 | AO11: 100 | AP11: 0.22883295
B12: 3 | D12: Good | G12: Evidence of compliance with plans and procedures. | Z12: 80 - 89 | AN12: =SUM(Y11:Y15) -> 0 | AO12: 89 | AP12: 0.20366133
B13: 2 | D13: Average | G13: Indication level of compliance with standards but there is room for improvement | Z13: 70 - 79 | AO13: 79 | AP13: 0.18077803
B14: 1 | D14: Improve | G14: Quality and Control is NOT being managed effectively. Needs Improvement | Z14: ≤ 69 | AO14: 69 | AP14: 0.15789474
B15: 0 | D15: N/A | G15: Item was not applicable or this item was not reviewed during the inspection. | Z15: Zero | AO15: 100 | AP15: 0.22883295
B17: No. | C17: Topic | K17: E (4) | L17: G (3) | M17: A (2) | N17: I (1) | O17: N/A (0) | Q17: No. | R17: Topic | Z17: E (4) | AA17: G (3) | AB17: A (2) | AC17: I (1) | AD17: N/A (0) | AO17: =SUM(AO11:AO16) -> 437
K18: 1 | L18: 0.89 | M18: 0.79 | N18: 0.69 | O18: 1 | Z18: 1 | AA18: 0.89 | AB18: 0.79 | AC18: 0.69 | AD18: 1 | AF18: =SUM(AF19:AG47)/COUNT(AF19:AG47) -> 0.85206897
B19: 1 | C19: Control of Access to Site/Office | L19: 1 | N19: 0 | Q19: 30 | R19: QC of Excavation | AB19: 1 | AC19: 0 | AD19: 0 | AF19: =SUMPRODUCT($K$18:$O$18,K19:O19) -> 0.89 | AG19: =SUMPRODUCT($Z$18:$AD$18,Z19:AD19) -> 0.79 | AV19: Item Count | AW19: Score | AX19: Distributtion
B20: 2 | C20: Document Control Administration | L20: 1 | M20: 0 | N20: 0 | Q20: 31 | R20: QC of Roads/Round about | AB20: 1 | AC20: 0 | AD20: 0 | AF20: =SUMPRODUCT($K$18:$O$18,K20:O20) -> 0.89 | AG20: =SUMPRODUCT($Z$18:$AD$18,Z20:AD20) -> 0.79 | AX20: Overall | AY20: Relevant
B21: 3 | C21: Project Documents and Progress | L21: 1 | M21: 0 | N21: 0 | Q21: 32 | R21: QC of Interlock & Curbstone | AB21: 1 | AF21: =SUMPRODUCT($K$18:$O$18,K21:O21) -> 0.89 | AG21: =SUMPRODUCT($Z$18:$AD$18,Z21:AD21) -> 0.79 | AM21: 4 | AN21: =58 -> 58 | AO21: counts | AQ21: 4 | AR21: Excellent | AV21: =SUM(Z19:Z47,K19:K47) -> 0 | AW21: =AQ21*AV21 -> 0 | AX21: =AV21/$AV$26 -> 0 | AY21: =AV21/SUM($AV$21:$AV$24) -> 0
B22: 4 | C22: Contractor's Quality Plan/CM (Updated and Reviewed) | M22: 1 | Q22: 33 | R22: Layers/Backfilling Sampling | AB22: 1 | AC22: 0 | AD22: 0 | AF22: =SUMPRODUCT($K$18:$O$18,K22:O22) -> 0.79 | AG22: =SUMPRODUCT($Z$18:$AD$18,Z22:AD22) -> 0.79 | AM22: 3 | AN22: =58 -> 58 | AO22: counts | AQ22: 3 | AR22: Good | AV22: =SUM(L19:L47,AA19:AA47) -> 15 | AW22: =AQ22*AV22 -> 45 | AX22: =AV22/$AV$26 -> 0.25862069 | AY22: =AV22/SUM($AV$21:$AV$24) -> 0.3125
B23: 5 | C23: MS Log and Paperwork | M23: 1 | Q23: 34 | R23: Pump Stations Units | AD23: 1 | AF23: =SUMPRODUCT($K$18:$O$18,K23:O23) -> 0.79 | AG23: =SUMPRODUCT($Z$18:$AD$18,Z23:AD23) -> 1 | AM23: 2 | AN23: =58 -> 58 | AO23: counts | AQ23: 2 | AR23: Average | AV23: =SUM(M19:M47,AB19:AB47) -> 33 | AW23: =AQ23*AV23 -> 66 | AX23: =AV23/$AV$26 -> 0.56896552 | AY23: =AV23/SUM($AV$21:$AV$24) -> 0.6875
B24: 6 | C24: RFI, FIR, & MIR Procedure | M24: 1 | N24: 0 | Q24: 35 | R24: Quality of Form Work | AB24: 1 | AD24: 0 | AF24: =SUMPRODUCT($K$18:$O$18,K24:O24) -> 0.79 | AG24: =SUMPRODUCT($Z$18:$AD$18,Z24:AD24) -> 0.79 | AM24: 1 | AN24: =58 -> 58 | AO24: counts | AQ24: 1 | AR24: Improve | AV24: =SUM(N19:N47,AC19:AC47) -> 0 | AW24: =AQ24*AV24 -> 0 | AX24: =AV24/$AV$26 -> 0 | AY24: =AV24/SUM($AV$21:$AV$24) -> 0
B25: 7 | C25: RFI, FIR, & MIR Inventory system | L25: 1 | M25: 0 | N25: 0 | Q25: 36 | R25: Design Change List | AD25: 1 | AF25: =SUMPRODUCT($K$18:$O$18,K25:O25) -> 0.89 | AG25: =SUMPRODUCT($Z$18:$AD$18,Z25:AD25) -> 1 | AM25: 0 | AN25: =58 -> 58 | AO25: counts | AQ25: 0 | AR25: N/A | AV25: =SUM(O19:O47,AD19:AD47) -> 10 | AW25: =AQ25*AV25 -> 0 | AX25: =AV25/$AV$26 -> 0.17241379 | AY25: -
B26: 8 | C26: NCRs Control & Procedure | M26: 1 | N26: 0 | Q26: 37 | R26: Quality of Concrete Placing | AB26: 1 | AC26: 0 | AD26: 0 | AF26: =SUMPRODUCT($K$18:$O$18,K26:O26) -> 0.79 | AG26: =SUMPRODUCT($Z$18:$AD$18,Z26:AD26) -> 0.79 | AR26: Total | AV26: =SUM(AV21:AV25) -> 58 | AW26: =SUM(AW21:AW25) -> 111 | AX26: =SUM(AX21:AX25) -> 1 | AY26: =SUM(AY21:AY25) -> 1
B27: 9 | C27: NCR Log | L27: 1 | M27: 0 | N27: 0 | Q27: 38 | R27: Concrete Surface Finishing | AB27: 1 | AD27: 0 | AF27: =SUMPRODUCT($K$18:$O$18,K27:O27) -> 0.89 | AG27: =SUMPRODUCT($Z$18:$AD$18,Z27:AD27) -> 0.79
B28: 10 | C28: MODON Standard* | M28: 1 | N28: 0 | Q28: 39 | R28: Pedestals/Columns/Beams Alignment | AB28: 1 | AD28: 0 | AF28: =SUMPRODUCT($K$18:$O$18,K28:O28) -> 0.79 | AG28: =SUMPRODUCT($Z$18:$AD$18,Z28:AD28) -> 0.79 | AV28: Maz Score Available: | AW28: =SUM(AV21:AV24)*AQ21 -> 192 | AX28: <- Excludes N/A items
B29: 11 | C29: Project Risk Plan/Management* | M29: 1 | N29: 0 | Q29: 40 | R29: Siporex Lifting & Unloading | AD29: 1 | AF29: =SUMPRODUCT($K$18:$O$18,K29:O29) -> 0.79 | AG29: =SUMPRODUCT($Z$18:$AD$18,Z29:AD29) -> 1
B30: 12 | C30: Monthly Quality Reports* | L30: 1 | M30: 0 | N30: 0 | O30: 0 | Q30: 41 | R30: Siporex Quality Pre-installation | AD30: 1 | AF30: =SUMPRODUCT($K$18:$O$18,K30:O30) -> 0.89 | AG30: =SUMPRODUCT($Z$18:$AD$18,Z30:AD30) -> 1
B31: 13 | C31: ITP | M31: 1 | Q31: 42 | R31: Siporex Finishing Quality | AD31: 1 | AF31: =SUMPRODUCT($K$18:$O$18,K31:O31) -> 0.79 | AG31: =SUMPRODUCT($Z$18:$AD$18,Z31:AD31) -> 1 | AR31: Total Score | AW31: Percentage (%)
B32: 14 | C32: MODON Weekly Report | L32: 1 | M32: 0 | Q32: 43 | R32: Roads / Parking Markings | AB32: 1 | AF32: =SUMPRODUCT($K$18:$O$18,K32:O32) -> 0.89 | AG32: =SUMPRODUCT($Z$18:$AD$18,Z32:AD32) -> 0.79 | AN32: =MAX(AN21:AN25) -> 58 | AR32: =AW26 -> 111 | AW32: =SUM(100/AR34*AR32) -> 57.8125 | AY32: %
B33: 15 | C33: Design Change Official Paperwork* | L33: 1 | Q33: 44 | R33: QC of Finishing Outdoors | AB33: 1 | AF33: =SUMPRODUCT($K$18:$O$18,K33:O33) -> 0.89 | AG33: =SUMPRODUCT($Z$18:$AD$18,Z33:AD33) -> 0.79 | AR33: Max Score Available | BP33: 31
B34: 16 | C34: Design Change was Applied* | L34: 1 | Q34: 45 | R34: Quality of Finishing Indoors | AD34: 1 | AF34: =SUMPRODUCT($K$18:$O$18,K34:O34) -> 0.89 | AG34: =SUMPRODUCT($Z$18:$AD$18,Z34:AD34) -> 1 | AR34: =AW28 -> 192 | BP34: 32
B35: 17 | C35: Material List | L35: 1 | M35: 0 | O35: 0 | Q35: 46 | R35: Stairs Quality | AD35: 1 | AF35: =SUMPRODUCT($K$18:$O$18,K35:O35) -> 0.89 | AG35: =SUMPRODUCT($Z$18:$AD$18,Z35:AD35) -> 1 | BP35: 33
B36: 18 | C36: Pending Material Status | L36: 1 | M36: 0 | Q36: 47 | R36: Tanks Method Statement Work | AD36: 1 | AF36: =SUMPRODUCT($K$18:$O$18,K36:O36) -> 0.89 | AG36: =SUMPRODUCT($Z$18:$AD$18,Z36:AD36) -> 1 | BP36: 34
B37: 19 | C37: Lifting Plan* | M37: 1 | Q37: 48 | R37: Electric Rooms | AB37: 1 | AF37: =SUMPRODUCT($K$18:$O$18,K37:O37) -> 0.79 | AG37: =SUMPRODUCT($Z$18:$AD$18,Z37:AD37) -> 0.79 | BP37: 35
B38: 20 | C38: DWG Log | L38: 1 | Q38: 49 | R38: QC of MCC/ATS Plant Units | AB38: 0 | AD38: 1 | AF38: =SUMPRODUCT($K$18:$O$18,K38:O38) -> 0.89 | AG38: =SUMPRODUCT($Z$18:$AD$18,Z38:AD38) -> 1 | BP38: 36
B39: 21 | C39: Invoice Status | L39: 1 | Q39: 50 | R39: Qualified Subcontractor | AB39: 1 | AD39: 0 | AF39: =SUMPRODUCT($K$18:$O$18,K39:O39) -> 0.89 | AG39: =SUMPRODUCT($Z$18:$AD$18,Z39:AD39) -> 0.79 | BP39: 37
B40: 22 | C40: Site Handover Letter | O40: 1 | Q40: 51 | R40: Scaffold/Ladders/Slope/Bridge Compliance | AB40: 1 | AF40: =SUMPRODUCT($K$18:$O$18,K40:O40) -> 1 | AG40: =SUMPRODUCT($Z$18:$AD$18,Z40:AD40) -> 0.79 | BP40: 38
B41: 23 | C41: Material Testing Results & Certification | L41: 1 | M41: 0 | Q41: 52 | R41: Protection Applied to Completed Work | AB41: 1 | AD41: 0 | AF41: =SUMPRODUCT($K$18:$O$18,K41:O41) -> 0.89 | AG41: =SUMPRODUCT($Z$18:$AD$18,Z41:AD41) -> 0.79
B42: 24 | C42: As Build Drawings Status* | M42: 1 | Q42: 53 | R42: Storage Management in/out Control | AB42: 1 | AC42: 0 | AF42: =SUMPRODUCT($K$18:$O$18,K42:O42) -> 0.79 | AG42: =SUMPRODUCT($Z$18:$AD$18,Z42:AD42) -> 0.79
B43: 25 | C43: Calibrated Lab Tools & Equipment | L43: 1 | M43: 0 | O43: 0 | Q43: 54 | R43: Material Control | AB43: 1 | AC43: 0 | AD43: 0 | AF43: =SUMPRODUCT($K$18:$O$18,K43:O43) -> 0.89 | AG43: =SUMPRODUCT($Z$18:$AD$18,Z43:AD43) -> 0.79
B44: 26 | C44: Storage Inventory System | M44: 1 | Q44: 55 | R44: Manholes Storing and Quality | AB44: 1 | AC44: 0 | AD44: 0 | AF44: =SUMPRODUCT($K$18:$O$18,K44:O44) -> 0.79 | AG44: =SUMPRODUCT($Z$18:$AD$18,Z44:AD44) -> 0.79
B45: 27 | C45: Logistics Plan | M45: 1 | Q45: 56 | R45: Reinforced Steel Quality | AB45: 1 | AC45: 0 | AD45: 0 | AF45: =SUMPRODUCT($K$18:$O$18,K45:O45) -> 0.79 | AG45: =SUMPRODUCT($Z$18:$AD$18,Z45:AD45) -> 0.79
B46: 28 | C46: Project Progress Planview | M46: 1 | Q46: 57 | R46: Safety Overview | AB46: 1 | AC46: 0 | AD46: 0 | AF46: =SUMPRODUCT($K$18:$O$18,K46:O46) -> 0.79 | AG46: =SUMPRODUCT($Z$18:$AD$18,Z46:AD46) -> 0.79
B47: 29 | C47: Sufficient Number of QC Inspectors | M47: 1 | Q47: 58 | R47: Waste Management Control | AB47: 1 | AD47: 0 | AF47: =SUMPRODUCT($K$18:$O$18,K47:O47) -> 0.79 | AG47: =SUMPRODUCT($Z$18:$AD$18,Z47:AD47) -> 0.79
...

Sheet Quality-Stat  
A1: Quality Reports
A2: Item | D2: Issued | E2: A | F2: B | G2: C | H2: D | I2: Approved
J3: Remaining | K3: Submittals With Consultant | L3: Total Submittals
A5: Non Conforomance Report (NCR) | D5: 16 | E5: 0 | F5: 16 | G5: 0 | H5: 0 | I5: 16 | J5: 0 | K5: =-D515 -> 0 | L5: 16
A6: Site Instruction (SI) | D6: 21 | E6: 0 | F6: 21 | G6: 0 | H6: 0 | I6: 21 | J6: 0 | K6: 0 | L6: 21
A7: Material Inspection Report (MIR) | D7: 100 | E7: 100 | F7: 0 | G7: 0 | H7: 0 | I7: 100 | J7: 0 | K7: 0 | L7: 100
A8: Field Inspection Report (FIR) | D8: 5477 | E8: 905 | F8: 4522 | G8: 5 | H8: 0 | I8: 5427 | J8: 0 | K8: 45 | L8: 5477
A10: Shop Drawings
A11: Item Per WBS | D11: Total IFC | E11: Total Drawings Submitted | J11: Remaining Drawings | K11: Pending | L11: Total Submittals
E12: A | F12: B | G12: C | H12: D | I12: Processed | J12: with Designer | K12: Submittals With Consultant
A13: Roads | D13: 268 | E13: 2 | F13: 266 | G13: 0 | H13: 0 | I13: 268 | K13: 0 | L13: 268
A14: General | D14: 11 | E14: 0 | F14: 11 | G14: 0 | H14: 0 | I14: 11 | K14: 0 | L14: 11
A15: Structural | D15: 590 | E15: 2 | F15: 588 | G15: 0 | H15: 109 | I15: 480 | K15: 0 | L15: 590
A16: Architectural | D16: 2 | E16: 0 | F16: 2 | G16: 0 | H16: 0 | I16: 2 | K16: 0 | L16: 2
A17: Mechanical | C17: Mechanical | D17: 336 | E17: 2 | F17: 397 | G17: 0 | H17: 1 | I17: 264 | K17: 65 | L17: 406
A18: Electrical | C18: Electrical | D18: 220 | E18: 3 | F18: 214 | G18: 0 | H18: 0 | I18: 220 | K18: 0 | L18: 220
A19: TOTAL | D19: =SUM(D13:D18) -> 1427 | E19: =SUM(E13:E18) -> 9 | F19: =SUM(F13:F18) -> 1478 | G19: =SUM(G13:G18) -> 0 | H19: =SUM(H13:H18) -> 110 | I19: =SUM(I13:I18) -> 1245 | K19: =SUM(K13:K18) -> 65 | L19: =SUM(L13:L18) -> 1497
A22: Material Approval
A23: Item Per WBS | D23: Total | E23: Total Materials Submitted | J23: Remaining to approve | K23: Pending | L23: Total Submittals
E24: A | F24: B | G24: C | H24: D | I24: Processed | J24: with Designer | K24: Submittals With Consultant
A25: Civil /Structural /Architectural | D25: 95 | E25: 2 | F25: 90 | G25: 0 | H25: 1 | I25: 92 | K25: 0 | L25: 95
A26: Mechanical | C26: Mechanical | D26: 33 | E26: 2 | F26: 33 | G26: 0 | H26: 0 | I26: 33 | K26: 0 | L26: 33
A27: Electrical | C27: Electrical | D27: 22 | E27: 0 | F27: 16 | G27: 0 | H27: 6 | I27: 16 | K27: 0 | L27: 22
A28: TOTAL | D28: =SUM(D25:D27) -> 150 | E28: =SUM(E25:E27) -> 4 | F28: =SUM(F25:F27) -> 139 | G28: =SUM(G25:G27) -> 0 | H28: =SUM(H25:H27) -> 7 | I28: =SUM(I25:I27) -> 141 | K28: =SUM(K25:K27) -> 0 | L28: =SUM(L25:L27) -> 150
A30: Procurement Summary
A31: Item Per WBS | D31: Total Materials | E31: Total Number of P.O. | F31: Actual P.O. To Date | G31: Remaining P.O | H31: Actual Material on Site | I31: Remaining Materials | J31: Material Delivery Completion (Date)
E32: A | F32: B | G32: C | H32: D | I32: Processed
A33: Civil /Structural /Architectural | D33: 31 | E33: 31 | F33: 31 | G33: =D33-F33 -> 0 | H33: 28 | I33: =D33-H33 -> 3 | J33: 46526
A34: Mechanical | C34: Mechanical | D34: 19 | E34: 19 | F34: 19 | G34: =D34-F34 -> 0 | H34: 19 | I34: =D34-H34 -> 0 | J34: 46567
A35: Electrical | C35: Electrical | D35: 63 | E35: 63 | F35: 58 | G35: =D35-F35 -> 5 | H35: 58 | I35: =D35-H35 -> 5 | J35: 46457
A36: TOTAL | D36: =SUM(D33:D35) -> 113 | E36: =SUM(E33:E35) -> 113 | F36: =SUM(F33:F35) -> 108 | G36: =SUM(G33:G35) -> 5 | H36: =SUM(H33:H35) -> 105 | I36: =SUM(I33:I35) -> 8
A38: Consultant Quality Inspections / Observations (Weekly Basis) | I38: Overall Average | J38: =AVERAGE(E45:E827) -> 0.82810617 | L38: Average Closing | M38: =AVERAGE(G45:G116) -> 2.3414634
A39: Week Number | B39: Date of Audit | C39: Date Issued | D39: Numbers Of Comments | E39: Quality Score | F39: Date Closed | G39: Closure Duration | I39: This Week Score | J39: ='Quality '!AC11 -> 0.85206897 | L39: Average Number of Comments Per Audit | M39: =AVERAGE(D45:D116) -> 3.0731707
A40: Week-1 | B40: 45986
A41: Week-2 | B41: =B40+7 -> 45993
A42: Week-3 | B42: =B41+7 -> 46000
A43: Week-4 | B43: =B42+7 -> 46007
A44: Week-5 | B44: =B43+7 -> 46014
A45: Week-6 | B45: =B44+7 -> 46021 | C45: 46018 | D45: 3 | E45: 0.8 | F45: 46019 | G45: =F45-C45 -> 1
A46: Week-7 | B46: =B45+7 -> 46028 | C46: 46024 | D46: 2 | E46: 0.7 | F46: 46026 | G46: =F46-C46 -> 2
...

Sheet HSE
B1: MODON HSE Site Inspection Report
B2: Date | E2: ='General Information'!L1 -> 46315 | L2: Inspected By: | T2: Raef M. M.
B4: Project ID. | E4: JDH01-02-003 | L4: Report No. | P4: ='General Information'!L2 -> 47.857143 | W4: MODON PM Name | Y4: Engr.Abdallah Aljulayfi
B6: Project Name: | E6: INFRASTRUCTURE DEVELOPMENT FOR INDUSTRIAL CITY 1 IN JEDDAH | L6: Contractor: | R6: Al Enjaz Company for Trading and Contracting | X6: Safety Performance | AA6: =IF(W29>0,3,IF(L29>6,2,IF(D29>0,2,1)*1)*1) -> 3 | AE6: =(((COUNTIF(L13:Q25,"1")+COUNTIF(AC13:AH25,"1"))*AR13)+(COUNTIF(L13:Q25,"2")+COUNTIF(AC13:AH25,"2"))*AR14+(COUNTIF(L13:Q25,"3")+COUNTIF(AC13:AH25,"3"))*AR15)/((COUNT(L13:Q25)+COUNT(AC13:AH25))*100) -> 0.77173913
B8: Inspections are a snapshot in time and refer only to the practices and documentation observed at the time of the Inspection. It remains the responsibility of the Consultant and Contractor to ensure that all aspects of Health & Safety are suitably managed.
B9: 1 | D9: Good Practice | H9: 2 | I9: Need Improvement | T9: 3 | U9: Fail (Life Threatening Activity) / Comliance with Plan & Procedures | X9: N/A | Y9: Atcitty Not Applicable for this Site Inspection Report
B11: No. | C11: Topic | K11: Wt. | L11: HSE Compliance | S11: No. | T11: Topic | AB11: Wt. | AC11: HSE Compliance
B13: 1 | C13: Access and Egress - (General access to site, segregated from vehicles, / Overhead protection, while entering into the building /Adequate lighting provided when dark or overnight work) | K13: 0.05 | L13: 1 | S13: 14 | T13: Work at Height - (PPE/Fall Protection(Same level, above and blow) / Training / Fall restraint / competency /Safe access & egress to and from work at height / Ladders / Openings (floor/shafts/Provision of emergency rescue) | AB13: 0.05 | AC13: N/A | AP13: 1 | AR13: 100 | AU13: 1
B14: 2 | C14: Traffic Management - (Loading/unloading/sheeting/temp. routes/speed/parking/competence) | K14: 0.03 | L14: 1 | S14: 15 | T14: Scaffolding - (Temp. Scaffolding Work-platform (All types) - qualified scaffolder / Inspection / Tagged / Safe Access/egress / PTW/Falsework & Formwork) | AB14: 0.04 | AC14: N/A | AP14: 2 | AR14: 75 | AU14: 2
B15: 3 | C15: Site Signage - (Project Notice Board & General Signage) | K15: 0.02 | L15: 1 | S15: 16 | T15: Mobile Elevated Work platform (MEWP) - (PTW/competence requirements/conditions/inspections/tagged/training/Full-body harness) | AB15: 0.04 | AC15: N/A | AP15: 3 | AR15: 0 | AU15: 3
B16: 4 | C16: PPE Compliance - (Use, storage, stock, handling & checks - Head, Foot, Eye, Hearing) | K16: 0.05 | L16: 2 | S16: 17 | T16: Excavation & Trenches - (PTW/Edge protection/buffer zone/Slope/Benching/Shoring/Geo-tech report/Atmospheric hazards/Acess&egress/Emergency management / MS&RA/H.E) | AB16: 0.03 | AC16: 2 | AU16: N/A
B17: 5 | C17: Housekeeping - (Material correctly stored/Rubbish cleaned & removed daily/slips & trips hazards) | K17: 0.03 | L17: 2 | S17: 18 | T17: Confined Space - (PTW/Training/competence/Emergency Management/MS & RA/Safe access/egress) | AB17: 0.05 | AC17: 2
B18: 6 | C18: Storage of Materials - (Transporting, storage, training and use - Combustible / Flammable / Hazardous substances (COSHH) | L18: 2 | S18: 19 | T18: Fire Protection - (Flammable/Oxy. LPG /Combustible separated/FE's/Flashback arrestor/Sparks & slags/Smoking area/PTW/Generators/MS & RA/Emergency Management) | AC18: 2 | AL18: Red | AM18: Serious injury or death (immediately)
B19: 7 | C19: Site Waste Management - (Hazardous waste /Combustible waste / Human waste / Construction waste - asphalt, cable, timber, paving roof sheeting tiles, plastic & bricks) | L19: 2 | S19: 20 | T19: Health & Welfare - (Adequate drinking water/shaded - eating & rest area/washing & sanitary facilities/Certified FA/FA Box & Stock/adequate toilets/Ambulance) | AC19: 1 | AL19: Yellow | AM19: Minor or near miss (3 days to comply)
B20: 8 | C20: Health Surveillance - (Expose to excessive noise/vibration/dust/silica/CO/cement/radiation/extreme weather condition) | K20: 0.03 | L20: 1 | S20: 21 | T20: Environmental Incident Measures - (Spill/ Leakage / Concrete wash / vehicle & eqpts. wash / waste disposal/Sewers and drains/emissions/Emergency Management/Training/site run-off water) | AB20: 0.05 | AC20: 2 | AL20: Green | AM20: No issues
B21: 9 | C21: Electrical Safety - (Electrical qualified /RCD/GFCI/Industrial Cocket/LOTO/Cable-overhung or buried/Cords in good condition/current inspection tag) | K21: 0.05 | L21: 2 | S21: 22 | T21: HSE Communications & Meetings - (Schedule HSE Meetings/Safety Committee meetings/Alerts / Lesson learned/Safety Bulletin contains latest HSE KPI) | AB21: 0.05 | AC21: 3
B22: 10 | C22: Tools & Equipment - (Includes, powered, hydraulic & pneumatic/Guards in place/Properly stored/RCD Protection/Earthed/Good condition & tagged) | K22: 0.03 | L22: 2 | S22: 23 | T22: HSE Plan & Associated Procedures - (Approved updated HSE Plan/ CEMP/HAZComm/Procedures/Standards/Project Safety Risk Register) | AB22: 0.03 | AC22: 1 | AL22: 26 points > 4 minors then is it’s a serious issue
B23: 11 | C23: Manual Handling - (Lifting/loading/pulling/pushing/twisting/awkward posture/repetitive task/frequent and prolong physical effort/Reasonable practicable use of mechanical aid) | K23: 0.03 | L23: 2 | S23: 24 | T23: Health, Safety & Environment Incident reporting - (Review of HSE Statistics, Reporting of Unsafe Act & Conditions/ Reporting of Near Miss incident/Reporting of FA cases/Record MT cases) | AB23: 0.03 | AC23: 1
B24: 12 | C24: Vehicle and mobile equipment / Plant - (dumpers; excavators, cranes, piling rigs, grader, roller, loaders/condition/KSA License/certification) | K24: 0.05 | L24: 2 | S24: 25 | T24: HSE Awareness, Training & Competence - (Policy /Objective & targets/Information, training/Climatic condition awareness/Reponses in emergency situation/ Safety Behavior Observation) | AB24: 0.04 | AC24: 1
B25: 13 | C25: Lifting Operations & Rigging - (Lifting Plan/Lifting devices & gears/PTW/Condition/3rd party certification/bank-man/rigger/slingers/man-basket/inspection record/tagged) | L25: 2 | S25: 26 | T25: Project Leadership Site Tours - (Provide evidence of proactive safety performance/Deficient discovered discussed/Positive feedback/Workers resolving safety issues) | AC25: 3
B27: Prepared by: | G27: =T2 -> Raef M. M. | S27: Sent to MODON PM: | X27: Engr.Abdallah Aljulayfi
B28: Safety Results
B29: 1 | D29: =COUNTIF(L13:Q26,"1")+COUNTIF(AB13:AG26,"1") -> 8 | I29: 2 | L29: =COUNTIF(L13:Q26,"2")+COUNTIF(AB13:AG26,"2") -> 13 | U29: 3 | W29: =COUNTIF(L13:Q26,"3")+COUNTIF(AB13:AG26,"3") -> 2

Sheet HSE-Stat 
