Workbook
Name _1B.05.M.010.0010: #REF!
Name _1B.05.M.010.0010: #REF!
Name _1B.05.M.010.0010: #REF!
Name _1B.05.M.010.0050: #REF!
Name _1B.05.M.010.0050: #REF!
Name _1B.05.M.010.0050: #REF!
Name _1B.05.M.0100.0010: #REF!
Name _1B.05.M.0100.0010: #REF!
Name _1B.05.M.020.0010: #REF!
Name _1B.05.M.020.0010: #REF!
Name _1B.05.M.020.0020: #REF!
Name _1B.05.M.020.0020: #REF!
Name _1B.05.M.020.0030: #REF!
Name _1B.05.M.020.0030: #REF!
Name _1B.05.M.020.0040: #REF!
Name _1B.05.M.020.0040: #REF!
Name _1B.05.M.030.0010: #REF!
Name _1B.05.M.030.0010: #REF!
Name _1B.05.M.030.0020: #REF!
Name _1B.05.M.030.0020: #REF!
Name _1B.05.M.040.0010: #REF!
Name _1B.05.M.040.0010: #REF!
Name _1B.05.M.050.0010: #REF!
Name _1B.05.M.050.0010: #REF!
Name _1B.05.M.050.0020: #REF!
Name _1B.05.M.050.0020: #REF!
Name _1B.05.M.050.0030: #REF!
Name _1B.05.M.050.0030: #REF!
Name _1B.05.M.060.0020: #REF!
Name _1B.05.M.060.0020: #REF!
Name _1B.05.M.060.0100: #REF!
Name _1B.05.M.060.0100: #REF!
Name _1B.05.M.070.0010: #REF!
Name _1B.05.M.070.0010: #REF!
Name _1B.05.M.070.0020: #REF!
Name _1B.05.M.070.0020: #REF!
Name _1B.05.M.070.0030: #REF!
Name _1B.05.M.070.0030: #REF!
Name _1B.05.M.070.0040: #REF!
Name _1B.05.M.070.0040: #REF!
Name _1B.05.M.070.0050: #REF!
Name _1B.05.M.070.0050: #REF!
Name _1B.05.M.080.0010: #REF!
Name _1B.05.M.080.0010: #REF!
Name _1B.05.M.090.0010: #REF!
Name _1B.05.M.090.0010: #REF!
Name _1B.09.P.010.0010: #REF!
Name _1B.09.P.010.0010: #REF!
Name _1B.09.P.010.0020: #REF!
Name _1B.09.P.010.0020: #REF!
Name _1B.09.P.010.0030: #REF!
Name _1B.09.P.010.0030: #REF!
Name _1B.09.P.010.0040: #REF!
Name _1B.09.P.010.0040: #REF!
Name _1B.09.P.010.0050: #REF!
Name _1B.09.P.010.0050: #REF!
Name _1B.09.P.010.0060: #REF!
Name _1B.09.P.010.0060: #REF!
Name _1B.09.P.010.0070: #REF!
Name _1B.09.P.010.0070: #REF!

Sheet DB
A1: ='Weekly Progress Report'!$A$1 -> MODON - Weekly Progress Report - Construction Projects
B2: ='Weekly Progress Report'!$A$2 -> Contract General Information | J2: ='Weekly Progress Report'!G2 -> Key Dates | U2: ='Weekly Progress Report'!$M$2 -> Cost Summary (SR) | AD2: ='Weekly Progress Report'!$U$2 -> Performance Summary | AP2: ='Weekly Progress Report'!A56 -> Shop Drawings | AT2: ='Weekly Progress Report'!A65 -> Material Approval | AW2: ='Weekly Progress Report'!A74 -> Procurement Summary | BD2: ='Weekly Progress Report'!L56 -> Quality Reports | BT2: ='Weekly Progress Report'!L64 -> Key Submittals Approval Status | CD2: ='Weekly Progress Report'!L70 -> Invoices Summary | CR2: ='Weekly Progress Report'!L78 -> Resources at Site | CY2: ='Weekly Progress Report'!W56 -> Safety Statistics | FK2: ='Weekly Progress Report'!A83 -> Primavera P6 Schedule Status | FS2: ='Weekly Progress Report'!A92 -> Weekly Prgoress Photos
A3: ='Weekly Progress Report'!AF1 -> Data Date | B3: ='Weekly Progress Report'!A3 -> Project Name | C3: ='Weekly Progress Report'!A4 -> Project ID | D3: ='Weekly Progress Report'!A5 -> Contractor | E3: ='Weekly Progress Report'!A6 -> Consultant | F3: ='Weekly Progress Report'!D4 -> Stage | G3: ='Weekly Progress Report'!D5 -> Status | H3: ='Weekly Progress Report'!D6 -> Modon PM | I3: ='Weekly Progress Report'!AA2 -> Project Scope | J3: ='Weekly Progress Report'!G3 -> Contract Award | K3: ='Weekly Progress Report'!G4 -> Contract Sign | L3: ='Weekly Progress Report'!G5 -> Site Handover | M3: ='Weekly Progress Report'!G6 -> Original Completion | N3: ='Weekly Progress Report'!$I$3 -> Contract Award (Hijri) | O3: ='Weekly Progress Report'!$I$4 -> Contract Sign (Hijri) | P3: ='Weekly Progress Report'!$I$5 -> Site Handover (Hijri) | Q3: ='Weekly Progress Report'!$I$6 -> Original Completion (Hijri) | R3: ='Weekly Progress Report'!$K$3 -> Revised Completion | S3: ='Weekly Progress Report'!$K$4 -> Committed Completion | T3: ='Weekly Progress Report'!$K$5 -> Forecast Completion | U3: ='Weekly Progress Report'!$M$3 -> Original Contract Value | V3: ='Weekly Progress Report'!$M$4 -> Revised Contract Value | W3: ='Weekly Progress Report'!$M$5 -> Estimate At Completion Value | X3: ='Weekly Progress Report'!$M$6 -> Potential Changes | Y3: ='Weekly Progress Report'!$Q$3 -> O&M Value (if any) | Z3: ='Weekly Progress Report'!$Q$4 -> Submitted Invoices (Gross Value) | AA3: ='Weekly Progress Report'!$Q$5 -> Penalities | AB3: ='Weekly Progress Report'!$Q$6 -> FIR Value (Todate) | AC3: Original Plan Value | AD3: ='Weekly Progress Report'!$U$3 -> Plan Value | AE3: ='Weekly Progress Report'!$U$4 -> Earn Value | AF3: ='Weekly Progress Report'!$W$3 -> Phys. Plan Value | AG3: ='Weekly Progress Report'!$W$4 -> Phys. Earn Value | AH3: ='Weekly Progress Report'!$Y$3 -> Quality Score | AI3: ='Weekly Progress Report'!$Y$5 -> Safety Score | AJ3: Weekly PV (SAR) | AK3: Weekly EV (SAR) | AL3: Weekly PV % | AM3: Weekly PV % | AN3: Weekly Phys PV% | AO3: Weekly Phys PV% | AP3: Total SD Planned | AQ3: SD Remaining | AR3: SD Pending | AS3: Total SD Submittals | AT3: Planned Materials Approv | AU3: Material Pending Approval | AV3: Materila Total Submittals | AW3: ='Weekly Progress Report'!C75 -> Total Materials | AX3: ='Weekly Progress Report'!D75 -> Total Number of P.O. | AY3: ='Weekly Progress Report'!E75 -> Actual P.O. To Date | AZ3: ='Weekly Progress Report'!F75 -> Remaining P.O | BA3: ='Weekly Progress Report'!G75 -> Material on Site | BB3: ='Weekly Progress Report'!H75 -> Remaining Materials | BC3: ='Weekly Progress Report'!I75 -> Material Delivery Completion (Date) | BD3: ="NCR "&'Weekly Progress Report'!N57 -> NCR Issued | BE3: ="NCR "&'Weekly Progress Report'!O57 -> NCR Closed | BF3: ="NCR "&'Weekly Progress Report'!P57 -> NCR Pending | BG3: ="NCR "&'Weekly Progress Report'!Q57 -> NCR Avg. Closing (Days) | BH3: ="SIR "&'Weekly Progress Report'!N57 -> SIR Issued | BI3: ="SIR "&'Weekly Progress Report'!O57 -> SIR Closed | BJ3: ="SIR "&'Weekly Progress Report'!P57 -> SIR Pending | BK3: ="SIR "&'Weekly Progress Report'!Q57 -> SIR Avg. Closing (Days) | BL3: ="MIR "&'Weekly Progress Report'!N57 -> MIR Issued | BM3: ="MIR "&'Weekly Progress Report'!O57 -> MIR Closed | BN3: ="MIR "&'Weekly Progress Report'!P57 -> MIR Pending | BO3: ="MIR "&'Weekly Progress Report'!Q57 -> MIR Avg. Closing (Days) | BP3: ="FIR "&'Weekly Progress Report'!N57 -> FIR Issued | BQ3: ="FIR "&'Weekly Progress Report'!O57 -> FIR Closed | BR3: ="FIR "&'Weekly Progress Report'!P57 -> FIR Pending | BS3: ="FIR "&'Weekly Progress Report'!Q57 -> FIR Avg. Closing (Days) | BT3: ='Weekly Progress Report'!L65 -> 1 Quality Plan Approval | BU3: ='Weekly Progress Report'!L66 -> 2 Quality Plan Last Up | BV3: ='Weekly Progress Report'!L67 -> 3 Safety Plan Approval | BW3: ='Weekly Progress Report'!L68 -> 4 Safety Plan Last Up | BX3: ='Weekly Progress Report'!L69 -> 5 Construction Plan Approval | BY3: ='Weekly Progress Report'!Q65 -> 6 Baseline Approval | BZ3: ='Weekly Progress Report'!Q66 -> 7 No of Approved Version of Schedule | CA3: ='Weekly Progress Report'!Q67 -> 8 Last Approved Schedule | CB3: ='Weekly Progress Report'!Q68 -> 9 BOQ Approval Date | CC3: ='Weekly Progress Report'!Q69 -> 10 No of Approved Version of BOQ | CD3: ='Weekly Progress Report'!L71 -> Total Submitted Invoices | CE3: ='Weekly Progress Report'!L72 -> PM Approved Invoices | CF3: ='Weekly Progress Report'!L73 -> No of Paid Invoices | CG3: ='Weekly Progress Report'!L74 -> No of Pending Invoices | CH3: ='Weekly Progress Report'!L75 -> Advance Payment % | CI3: ='Weekly Progress Report'!L76 -> Retention % | CJ3: ='Weekly Progress Report'!L77 -> Deduction / Penalties % | CK3: ='Weekly Progress Report'!O71 -> Submitted Invoices (SAR) | CL3: ='Weekly Progress Report'!O72 -> PM Approved Invoices (SAR) | CM3: ='Weekly Progress Report'!O73 -> Paid Invoices (SAR) | CN3: ='Weekly Progress Report'!O74 -> Last Submitted Period | CO3: ='Weekly Progress Report'!O75 -> Advance Payment (SAR) | CP3: ='Weekly Progress Report'!O76 -> Retention (SAR) | CQ3: ='Weekly Progress Report'!O77 -> Deduction / Penalties (SAR) | CR3: Planned Head Count | CS3: Actual Head Count | CT3: Saudi Staff | CU3: Labor Planned | CV3: Labor Actual | CW3: Equipment Planned | CX3: Equipment Actual | CY3: ="This Week "&'Weekly Progress Report'!X59 -> This Week Total Hours Worked | CZ3: ="This Week "&'Weekly Progress Report'!X60 -> This Week Safe Hours Worked | DA3: ="This Week "&'Weekly Progress Report'!X61 -> This Week LTI | DB3: ="This Week "&'Weekly Progress Report'!X62 -> This Week MTC (Healed w/o Disability) | DC3: ="This Week "&'Weekly Progress Report'!X63 -> This Week MTC (Healed w/ Disability) | DD3: ="This Week "&'Weekly Progress Report'!X64 -> This Week Near Miss | DE3: ="This Week "&'Weekly Progress Report'!X65 -> This Week First Aid Cases | DF3: ="This Week "&'Weekly Progress Report'!X66 -> This Week Fatality | DG3: ="This Week "&'Weekly Progress Report'!X67 -> This Week Fire Incident Cases | DH3: ="This Week "&'Weekly Progress Report'!X68 -> This Week Vehicle Incident | DI3: ="This Week "&'Weekly Progress Report'!X69 -> This Week Property Damages | DJ3: ="This Week "&'Weekly Progress Report'!X70 -> This Week Induction Training | DK3: ="This Week "&'Weekly Progress Report'!X71 -> This Week No.of Internal Training | DL3: ="This Week "&'Weekly Progress Report'!X72 -> This Week No.of Internal Audit | DM3: ="This Week "&'Weekly Progress Report'!X73 -> This Week No. of Toolbox Talks | DN3: ="This Week "&'Weekly Progress Report'!X74 -> This Week Safety Awards/Incentives | DO3: ="This Month "&'Weekly Progress Report'!X59 -> This Month Total Hours Worked | DP3: ="This Month "&'Weekly Progress Report'!X60 -> This Month Safe Hours Worked | DQ3: ="This Month "&'Weekly Progress Report'!X61 -> This Month LTI | DR3: ="This Month "&'Weekly Progress Report'!X62 -> This Month MTC (Healed w/o Disability) | DS3: ="This Month "&'Weekly Progress Report'!X63 -> This Month MTC (Healed w/ Disability) | DT3: ="This Month "&'Weekly Progress Report'!X64 -> This Month Near Miss | DU3: ="This Month "&'Weekly Progress Report'!X65 -> This Month First Aid Cases | DV3: ="This Month "&'Weekly Progress Report'!X66 -> This Month Fatality | DW3: ="This Month "&'Weekly Progress Report'!X67 -> This Month Fire Incident Cases | DX3: ="This Month "&'Weekly Progress Report'!X68 -> This Month Vehicle Incident | DY3: ="This Month "&'Weekly Progress Report'!X69 -> This Month Property Damages | DZ3: ="This Month "&'Weekly Progress Report'!X70 -> This Month Induction Training | EA3: ="This Month "&'Weekly Progress Report'!X71 -> This Month No.of Internal Training | EB3: ="This Month "&'Weekly Progress Report'!X72 -> This Month No.of Internal Audit | EC3: ="This Month "&'Weekly Progress Report'!X73 -> This Month No. of Toolbox Talks | ED3: ="This Month "&'Weekly Progress Report'!X74 -> This Month Safety Awards/Incentives | EE3: ="YTD "&'Weekly Progress Report'!X59 -> YTD Total Hours Worked | EF3: ="YTD "&'Weekly Progress Report'!X60 -> YTD Safe Hours Worked | EG3: ="YTD "&'Weekly Progress Report'!X61 -> YTD LTI | EH3: ="YTD "&'Weekly Progress Report'!X62 -> YTD MTC (Healed w/o Disability) | EI3: ="YTD "&'Weekly Progress Report'!X63 -> YTD MTC (Healed w/ Disability) | EJ3: ="YTD "&'Weekly Progress Report'!X64 -> YTD Near Miss | EK3: ="YTD "&'Weekly Progress Report'!X65 -> YTD First Aid Cases | EL3: ="YTD "&'Weekly Progress Report'!X66 -> YTD Fatality | EM3: ="YTD "&'Weekly Progress Report'!X67 -> YTD Fire Incident Cases | EN3: ="YTD "&'Weekly Progress Report'!X68 -> YTD Vehicle Incident | EO3: ="YTD "&'Weekly Progress Report'!X69 -> YTD Property Damages | EP3: ="YTD "&'Weekly Progress Report'!X70 -> YTD Induction Training | EQ3: ="YTD "&'Weekly Progress Report'!X71 -> YTD No.of Internal Training | ER3: ="YTD "&'Weekly Progress Report'!X72 -> YTD No.of Internal Audit | ES3: ="YTD "&'Weekly Progress Report'!X73 -> YTD No. of Toolbox Talks | ET3: ="YTD "&'Weekly Progress Report'!X74 -> YTD Safety Awards/Incentives | EU3: ="Cum "&'Weekly Progress Report'!X59 -> Cum Total Hours Worked | EV3: ="Cum "&'Weekly Progress Report'!X60 -> Cum Safe Hours Worked | EW3: ="Cum "&'Weekly Progress Report'!X61 -> Cum LTI | EX3: ="Cum "&'Weekly Progress Report'!X62 -> Cum MTC (Healed w/o Disability) | EY3: ="Cum "&'Weekly Progress Report'!X63 -> Cum MTC (Healed w/ Disability) | EZ3: ="Cum "&'Weekly Progress Report'!X64 -> Cum Near Miss | FA3: ="Cum "&'Weekly Progress Report'!X65 -> Cum First Aid Cases | FB3: ="Cum "&'Weekly Progress Report'!X66 -> Cum Fatality | FC3: ="Cum "&'Weekly Progress Report'!X67 -> Cum Fire Incident Cases | FD3: ="Cum "&'Weekly Progress Report'!X68 -> Cum Vehicle Incident | FE3: ="Cum "&'Weekly Progress Report'!X69 -> Cum Property Damages | FF3: ="Cum "&'Weekly Progress Report'!X70 -> Cum Induction Training | FG3: ="Cum "&'Weekly Progress Report'!X71 -> Cum No.of Internal Training | FH3: ="Cum "&'Weekly Progress Report'!X72 -> Cum No.of Internal Audit | FI3: ="Cum "&'Weekly Progress Report'!X73 -> Cum No. of Toolbox Talks | FJ3: ="Cum "&'Weekly Progress Report'!X74 -> Cum Safety Awards/Incentives | FK3: ='Weekly Progress Report'!A86 -> Total Act. | FL3: ='Weekly Progress Report'!B86 -> Not Started | FM3: ='Weekly Progress Report'!C86 -> In Progress | FN3: ='Weekly Progress Report'!D86 -> Completed | FO3: Critical Path Act.Last Week | FP3: Critical Path Act.This Week | FQ3: Failed start Last Week | FR3: Failed start This Week | FS3: ='Weekly Progress Report'!B94 -> 0 | FT3: ='Weekly Progress Report'!D94 -> 0 | FU3: ='Weekly Progress Report'!F94 -> 0 | FV3: ='Weekly Progress Report'!H94 -> 0 | FW3: ='Weekly Progress Report'!J94 -> 0 | FX3: ='Weekly Progress Report'!L94 -> 0 | FY3: ='Weekly Progress Report'!N94 -> 0 | FZ3: ='Weekly Progress Report'!O94 -> 0 | GA3: ='Weekly Progress Report'!P94 -> 0
A4: ='Weekly Progress Report'!AG1 -> 46308 | B4: ='Weekly Progress Report'!B3 -> Construction of Industrial Units for Artisans in Najran | C4: ='Weekly Progress Report'!B4 -> NJR1-05-005 | D4: ='Weekly Progress Report'!B5 -> Labenat Al Bena | E4: ='Weekly Progress Report'!B6 -> EGIS | F4: ='Weekly Progress Report'!E4 -> Construction | G4: ='Weekly Progress Report'!E5 -> Active | H4: ='Weekly Progress Report'!E6 -> Eng. Ahmed Kotbi | I4: ='Weekly Progress Report'!AA3 -> The project scope covers the construction of the Low Process RBF Unit, Outside Mosque, Pump Shed, and GRP Water Tank, including site preparation works (demolition, excavation, and backfilling), concrete and masonry works, thermal and waterproofing systems, installation of doors and windows, finishing works, and specialties. It also includes pre-engineered structures, mechanical systems (sanitary, water supply, HVAC, and firefighting), and electrical systems such as substations, distribution networks, lighting, power, telecom, fire alarm, and solar power. | J4: ='Weekly Progress Report'!H3 -> 46047 | K4: ='Weekly Progress Report'!H4 -> 46065 | L4: ='Weekly Progress Report'!H5 -> 46084 | M4: ='Weekly Progress Report'!H6 -> 46389 | N4: ='Weekly Progress Report'!$J$3 -> 46047 | O4: ='Weekly Progress Report'!$J$4 -> 46065 | P4: ='Weekly Progress Report'!$J$5 -> 46084 | Q4: ='Weekly Progress Report'!$J$6 -> 46389 | R4: ='Weekly Progress Report'!$L$3 -> 46389 | S4: ='Weekly Progress Report'!$L$4 -> 46310 | T4: ='Weekly Progress Report'!$L$5 -> 46310 | U4: ='Weekly Progress Report'!$O$3 -> 9554134 | V4: ='Weekly Progress Report'!$O$4 -> 9554134 | W4: ='Weekly Progress Report'!$O$5 -> 9554134 | X4: ='Weekly Progress Report'!$O$6 -> 0 | Y4: ='Weekly Progress Report'!$S$3 -> 0 | Z4: ='Weekly Progress Report'!$S$4 -> 7935744 | AA4: ='Weekly Progress Report'!$S$5 -> -20000 | AB4: ='Weekly Progress Report'!$S$6 -> 9266829.7 | AC4: ='Weekly Progress Report'!$J$27 -> 0.9999999 | AD4: ='Weekly Progress Report'!$V$3 -> 0.75185056 | AE4: ='Weekly Progress Report'!$V$4 -> 0.96947719 | AF4: ='Weekly Progress Report'!$X$3 -> 0.78657431 | AG4: ='Weekly Progress Report'!$X$4 -> 0.96524679 | AH4: ='Weekly Progress Report'!$Z$3 -> 0.88775862 | AI4: ='Weekly Progress Report'!$Z$5 -> 0.83 | AJ4: ='Weekly Progress Report'!$E$27 -> 381787 | AK4: ='Weekly Progress Report'!$F$27 -> 218625 | AL4: =AJ4/V4 -> 0.039960398 | AM4: =AK4/V4 -> 0.022882765 | AN4: ='Weekly Progress Report'!S27 -> 0.031469017 | AO4: ='Weekly Progress Report'!T27 -> 0.0079315264 | AP4: ='Weekly Progress Report'!C64 -> 93 | AQ4: ='Weekly Progress Report'!I64 -> 0 | AR4: ='Weekly Progress Report'!J64 -> 0 | AS4: ='Weekly Progress Report'!K64 -> 93 | AT4: ='Weekly Progress Report'!C73 -> 95 | AU4: ='Weekly Progress Report'!J73 -> 0 | AV4: ='Weekly Progress Report'!K73 -> 95 | AW4: ='Weekly Progress Report'!C82 -> 95 | AX4: ='Weekly Progress Report'!D82 -> 95 | AY4: ='Weekly Progress Report'!E82 -> 95 | AZ4: ='Weekly Progress Report'!F82 -> 0 | BA4: ='Weekly Progress Report'!G82 -> 95 | BB4: ='Weekly Progress Report'!H82 -> 0 | BC4: ='Weekly Progress Report'!I82 -> 46274 | BD4: ='Weekly Progress Report'!N60 -> 17 | BE4: ='Weekly Progress Report'!O60 -> 17 | BF4: ='Weekly Progress Report'!P60 -> 0 | BG4: ='Weekly Progress Report'!Q60 -> 3 | BH4: ='Weekly Progress Report'!N61 -> 18 | BI4: ='Weekly Progress Report'!O61 -> 18 | BJ4: ='Weekly Progress Report'!P61 -> 0 | BK4: ='Weekly Progress Report'!Q61 -> 3 | BL4: ='Weekly Progress Report'!N62 -> 64 | BM4: ='Weekly Progress Report'!O62 -> 64 | BN4: ='Weekly Progress Report'!P62 -> 0 | BO4: ='Weekly Progress Report'!Q62 -> 3 | BP4: ='Weekly Progress Report'!N63 -> 407 | BQ4: ='Weekly Progress Report'!O63 -> 407 | BR4: ='Weekly Progress Report'!P63 -> 0 | BS4: ='Weekly Progress Report'!Q63 -> 3 | BT4: ='Weekly Progress Report'!O65 -> 46134 | BU4: ='Weekly Progress Report'!O66 -> 46134 | BV4: ='Weekly Progress Report'!O67 -> 46130 | BW4: ='Weekly Progress Report'!O68 -> 46130 | BX4: ='Weekly Progress Report'!O69 -> 46114 | BY4: ='Weekly Progress Report'!U65 -> 46113 | BZ4: ='Weekly Progress Report'!U66 -> 0 | CA4: ='Weekly Progress Report'!U67 -> 46113 | CB4: ='Weekly Progress Report'!U68 -> N/A | CC4: ='Weekly Progress Report'!U69 -> 0 | CD4: ='Weekly Progress Report'!N71 -> 6 | CE4: ='Weekly Progress Report'!N72 -> 6 | CF4: ='Weekly Progress Report'!N73 -> 4 | CG4: ='Weekly Progress Report'!N74 -> 2 | CH4: ='Weekly Progress Report'!N75 -> 0 | CI4: ='Weekly Progress Report'!N76 -> 0 | CJ4: ='Weekly Progress Report'!N77 -> 0.0020933347 | CK4: ='Weekly Progress Report'!R71 -> 7935744 | CL4: ='Weekly Progress Report'!R72 -> 7935744 | CM4: ='Weekly Progress Report'!R73 -> 4460610 | CN4: ='Weekly Progress Report'!R74 -> 46295 | CO4: ='Weekly Progress Report'!R75 -> 0 | CP4: ='Weekly Progress Report'!R76 -> 0 | CQ4: ='Weekly Progress Report'!R77 -> -20000 | CR4: ='Weekly Progress Report'!L81 -> 13 | CS4: ='Weekly Progress Report'!M81 -> 14 | CT4: ='Weekly Progress Report'!O81 -> 0 | CU4: ='Weekly Progress Report'!P81 -> 119 | CV4: ='Weekly Progress Report'!Q81 -> 21 | CW4: ='Weekly Progress Report'!T91 -> 34 | CX4: ='Weekly Progress Report'!U91 -> 8 | CY4: ='Weekly Progress Report'!Z59 -> 1920 | CZ4: ='Weekly Progress Report'!Z60 -> 2040 | DA4: ='Weekly Progress Report'!Z61 -> 0 | DB4: ='Weekly Progress Report'!Z62 -> 0 | DC4: ='Weekly Progress Report'!Z63 -> 0 | DD4: ='Weekly Progress Report'!Z64 -> 0 | DE4: ='Weekly Progress Report'!Z65 -> 0 | DF4: ='Weekly Progress Report'!Z66 -> 0 | DG4: ='Weekly Progress Report'!Z67 -> 0 | DH4: ='Weekly Progress Report'!Z68 -> 0 | DI4: ='Weekly Progress Report'!Z69 -> 0 | DJ4: ='Weekly Progress Report'!Z70 -> 1 | DK4: ='Weekly Progress Report'!Z71 -> 0 | DL4: ='Weekly Progress Report'!Z72 -> 0 | DM4: ='Weekly Progress Report'!Z73 -> 1 | DN4: ='Weekly Progress Report'!Z74 -> 1 | DO4: ='Weekly Progress Report'!AB59 -> 3960 | DP4: ='Weekly Progress Report'!AB60 -> 3960 | DQ4: ='Weekly Progress Report'!AB61 -> 0 | DR4: ='Weekly Progress Report'!AB62 -> 0 | DS4: ='Weekly Progress Report'!AB63 -> 0 | DT4: ='Weekly Progress Report'!AB64 -> 0 | DU4: ='Weekly Progress Report'!AB65 -> 0 | DV4: ='Weekly Progress Report'!AB66 -> 0 | DW4: ='Weekly Progress Report'!AB67 -> 0 | DX4: ='Weekly Progress Report'!AB68 -> 0 | DY4: ='Weekly Progress Report'!AB69 -> 0 | DZ4: ='Weekly Progress Report'!AB70 -> 1 | EA4: ='Weekly Progress Report'!AB71 -> 0 | EB4: ='Weekly Progress Report'!AB72 -> 0 | EC4: ='Weekly Progress Report'!AB73 -> 2 | ED4: ='Weekly Progress Report'!AB74 -> 1 | EE4: ='Weekly Progress Report'!AC59 -> 82166 | EF4: ='Weekly Progress Report'!AC60 -> 82166 | EG4: ='Weekly Progress Report'!AC61 -> 0 | EH4: ='Weekly Progress Report'!AC62 -> 0 | EI4: ='Weekly Progress Report'!AC63 -> 0 | EJ4: ='Weekly Progress Report'!AC64 -> 2 | EK4: ='Weekly Progress Report'!AC65 -> 1 | EL4: ='Weekly Progress Report'!AC66 -> 0 | EM4: ='Weekly Progress Report'!AC67 -> 1 | EN4: ='Weekly Progress Report'!AC68 -> 0 | EO4: ='Weekly Progress Report'!AC69 -> 0 | EP4: ='Weekly Progress Report'!AC70 -> 49 | EQ4: ='Weekly Progress Report'!AC71 -> 4 | ER4: ='Weekly Progress Report'!AC72 -> 1 | ES4: ='Weekly Progress Report'!AC73 -> 27 | ET4: ='Weekly Progress Report'!AC74 -> 3 | EU4: ='Weekly Progress Report'!AD59 -> 82166 | EV4: ='Weekly Progress Report'!AD60 -> 82166 | EW4: ='Weekly Progress Report'!AD61 -> 0 | EX4: ='Weekly Progress Report'!AD62 -> 0 | EY4: ='Weekly Progress Report'!AD63 -> 0 | EZ4: ='Weekly Progress Report'!AD64 -> 2 | FA4: ='Weekly Progress Report'!AD65 -> 1 | FB4: ='Weekly Progress Report'!AD66 -> 0 | FC4: ='Weekly Progress Report'!AD67 -> 1 | FD4: ='Weekly Progress Report'!AD68 -> 0 | FE4: ='Weekly Progress Report'!AD69 -> 0 | FF4: ='Weekly Progress Report'!AD70 -> 49 | FG4: ='Weekly Progress Report'!AD71 -> 4 | FH4: ='Weekly Progress Report'!AD72 -> 1 | FI4: ='Weekly Progress Report'!AD73 -> 27 | FJ4: ='Weekly Progress Report'!AD74 -> 3 | FK4: ='Weekly Progress Report'!A87 -> 1462 | FL4: ='Weekly Progress Report'!B87 -> 22 | FM4: ='Weekly Progress Report'!C87 -> 30 | FN4: ='Weekly Progress Report'!D87 -> 1410 | FO4: ='Weekly Progress Report'!A91 -> 0 | FP4: ='Weekly Progress Report'!B91 -> 0 | FQ4: ='Weekly Progress Report'!H91 -> 13 | FR4: ='Weekly Progress Report'!I91 -> 9 | FS4: ='Weekly Progress Report'!B99 -> 0 | FT4: ='Weekly Progress Report'!D99 -> 0 | FU4: ='Weekly Progress Report'!F99 -> 0 | FV4: ='Weekly Progress Report'!H99 -> 0 | FW4: ='Weekly Progress Report'!J99 -> 0 | FX4: ='Weekly Progress Report'!L99 -> 0 | FY4: ='Weekly Progress Report'!N99 -> 0 | FZ4: ='Weekly Progress Report'!O99 -> 0 | GA4: ='Weekly Progress Report'!P99 -> 0

Sheet Weekly Progress Report
A1: MODON - Weekly Progress Report - Construction Projects | AF1: Data Date | AG1: ='General Information'!L1 -> 46308
A2: Contract General Information | G2: Key Dates | M2: Cost Summary (SR) | U2: Performance Summary | AA2: Project Scope
A3: Project Name | B3: ='General Information'!C3 -> Construction of Industrial Units for Artisans in Najran | G3: Contract Award | H3: ='General Information'!C12 -> 46047 | I3: Contract Award (Hijri) | J3: ='General Information'!C16 -> 46047 | K3: Revised Completion | L3: ='General Information'!C20 -> 46389 | M3: Original Contract Value | O3: ='Invoice Log'!E3 -> 9554134 | Q3: O&M Value (if any) | S3: ='Invoice Log'!I3 -> 0 | T3: EAC | U3: Plan Value | V3: =K27 -> 0.75185056 | W3: Phys. Plan Value | X3: =W27 -> 0.78657431 | Y3: Quality Score | Z3: ='Quality-Stat'!J43 -> 0.88775862 | AA3: =+Progress!B1 -> The project scope covers the construction of the Low Process RBF Unit, Outside Mosque, Pump Shed, and GRP Water Tank, including site preparation works (demolition, excavation, and backfilling), concrete and masonry works, thermal and waterproofing systems, installation of doors and windows, finishing works, and specialties. It also includes pre-engineered structures, mechanical systems (sanitary, water supply, HVAC, and firefighting), and electrical systems such as substations, distribution networks, lighting, power, telecom, fire alarm, and solar power.
A4: Project ID | B4: ='General Information'!C4 -> NJR1-05-005 | D4: Stage | E4: ='General Information'!C7 -> Construction | G4: Contract Sign | H4: ='General Information'!C13 -> 46065 | I4: Contract Sign (Hijri) | J4: ='General Information'!C17 -> 46065 | K4: Committed Completion | L4: ='General Information'!C21 -> 46310 | M4: Revised Contract Value | O4: ='Invoice Log'!E4 -> 9554134 | P4: EAC | Q4: Submitted Invoices (Gross Value) | S4: ='Invoice Log'!I5 -> 7935744 | U4: Earn Value | V4: =L27 -> 0.96947719 | W4: Phys. Earn Value | X4: =X27 -> 0.96524679 | Z4: =REPT("¢",IF(INT(+Z3*10)>5,5,INT(+Z3*10)))&REPT("£",IF(INT(+Z3*10)>5,0,5-INT(+Z3*10)))&CHAR(10)&REPT("¢",+IF(INT(+Z3*10)>5,-5+INT(+Z3*10),0))&REPT("£",IF(INT(+Z3*10)>5,10-INT(+Z3*10),5)) -> ¢¢¢¢¢ ¢¢¢££
A5: Contractor | B5: ='General Information'!C5 -> Labenat Al Bena | D5: Status | E5: ='General Information'!C8 -> Active | G5: Site Handover | H5: ='General Information'!C14 -> 46084 | I5: Site Handover (Hijri) | J5: ='General Information'!C18 -> 46084 | K5: Forecast Completion | L5: ='General Information'!C22 -> 46310 | M5: Estimate At Completion Value | O5: ='Invoice Log'!E5 -> 9554134 | P5: =+#REF!+#REF!+O5 -> #REF! | Q5: Penalities | S5: ='Invoice Log'!I6 -> -20000 | U5: Variance | V5: =V4-V3 -> 0.21762663 | W5: Variance | X5: =Y27 -> 0.17867248 | Y5: Safety Score | Z5: =HSE!AE6 -> 0.83
A6: Consultant | B6: ='General Information'!C6 -> EGIS | D6: Modon PM | E6: ='General Information'!C9 -> Eng. Ahmed Kotbi | G6: Original Completion | H6: ='General Information'!C15 -> 46389 | I6: Original Completion (Hijri) | J6: ='General Information'!C19 -> 46389 | K6: Variance | L6: ='General Information'!C23 -> 79 | M6: Potential Changes | O6: =O4-O5 -> 0 | Q6: FIR Value (Todate) | S6: ='FIR Summary'!H17 -> 9266829.7 | U6: SPI | V6: =V4/V3 -> 1.2894546 | W6: SPI | X6: =X4/X3 -> 1.2271527 | Z6: =REPT("¢",IF(INT(+Z5*10)>5,5,INT(+Z5*10)))&REPT("£",IF(INT(+Z5*10)>5,0,5-INT(+Z5*10)))&CHAR(10)&REPT("¢",+IF(INT(+Z5*10)>5,-5+INT(+Z5*10),0))&REPT("£",IF(INT(+Z5*10)>5,10-INT(+Z5*10),5)) -> ¢¢¢¢¢ ¢¢¢££
A8: Progress Overview
A9: Earned Value Progress (SAR) | O9: Physical Progress (Effort) | AA9: Earned Value Progress (%)
A10: WBS | C10: BOQ Value (SAR) | D10: % Wt. | E10: Weekly (SAR) | G10: To Date (SAR) | O10: Budgeted | P10: % Wt. | Q10: Weekly Physical Progress | U10: To Date Physical Progress
E11: Planned | F11: Earned | G11: Crushed Planned | H11: Original Plan | I11: Earned | J11: Crushed Plan % | K11: Original Plan % | L11: Earned % | M11: Variance | N11: SPI | O11: (Manhours) | Q11: Planned | R11: Earned | S11: Plan % | T11: Earned % | U11: Planned | V11: Earned | W11: Plan % | X11: Earned % | Y11: Variance | Z11: SPI
A12: =+Progress!A7 -> MOBILIZATION | C12: =+Progress!C7 -> 0 | D12: =IF(ISBLANK(C12),"",C12/$C$27) -> 0 | E12: =+Progress!E7 -> 0 | F12: =+Progress!F7 -> 0 | G12: =Progress!G7 -> 0 | H12: =+Progress!H7 -> 0 | I12: =+Progress!I7 -> 0 | J12: =IFERROR(IF(ISBLANK(G12),"",G12/C12),0) -> 0 | K12: =IFERROR(IF(ISBLANK(H12),"",H12/C12),0) -> 0 | L12: =IFERROR(IF(ISBLANK(I12),"",I12/C12),0) -> 0 | M12: =IFERROR(L12-K12,"") -> 0 | N12: =IFERROR(L12/K12,"") | O12: =+Progress!K7 -> 8972.8 | P12: =IF(ISBLANK(O12),"",O12/$O$27) -> 0.04 | Q12: =+Progress!M7 -> 0 | R12: =+Progress!N7 -> 0 | S12: =IFERROR(IF(ISBLANK(Q12),"",Q12/O12),0) -> 0 | T12: =IFERROR(IF(ISBLANK(R12),"",R12/O12),0) -> 0 | U12: =+Progress!O7 -> 8972.8 | V12: =+Progress!P7 -> 8972.8 | W12: =IFERROR(IF(ISBLANK(U12),"",U12/O12),0) -> 1 | X12: =IFERROR(IF(ISBLANK(V12),"",V12/O12),0) -> 1 | Y12: =IFERROR(X12-W12,"") -> 0 | Z12: =IFERROR(X12/W12,"") -> 1
A13: =+Progress!A8 -> ENGINEERING | C13: =Progress!C8 -> 281825.22 | D13: =IF(ISBLANK(C13),"",C13/$C$27) -> 0.029497725 | E13: =+Progress!E8 -> 0 | F13: =+Progress!F8 -> 0 | G13: =Progress!G8 -> 281825 | H13: =+Progress!H8 -> 281825 | I13: =+Progress!I8 -> 281825 | J13: =IFERROR(IF(ISBLANK(G13),"",G13/C13),0) -> 0.99999922 | K13: =IFERROR(IF(ISBLANK(H13),"",H13/C13),0) -> 0.99999922 | L13: =IFERROR(IF(ISBLANK(I13),"",I13/C13),0) -> 0.99999922 | M13: =IFERROR(L13-K13,"") -> 0 | N13: =IFERROR(L13/K13,"") -> 1 | O13: =+Progress!K8 -> 8972.8 | P13: =IF(ISBLANK(O13),"",O13/$O$27) -> 0.04 | Q13: =+Progress!M8 -> 0 | R13: =+Progress!N8 -> 0 | S13: =IFERROR(IF(ISBLANK(Q13),"",Q13/O13),0) -> 0 | T13: =IFERROR(IF(ISBLANK(R13),"",R13/O13),0) -> 0 | U13: =+Progress!O8 -> 8972.8 | V13: =+Progress!P8 -> 8972.8 | W13: =IFERROR(IF(ISBLANK(U13),"",U13/O13),0) -> 1 | X13: =IFERROR(IF(ISBLANK(V13),"",V13/O13),0) -> 1 | Y13: =IFERROR(X13-W13,"") -> 0 | Z13: =IFERROR(X13/W13,"") -> 1
A14: =+Progress!A9 -> PROCUREMENT | C14: =Progress!C9 -> 2536427 | D14: =IF(ISBLANK(C14),"",C14/$C$27) -> 0.26547953 | E14: =+Progress!E9 -> 152357 | F14: =+Progress!F9 -> 0 | G14: =Progress!G9 -> 2536427 | H14: =+Progress!H9 -> 2457598 | I14: =+Progress!I9 -> 2536427 | J14: =IFERROR(IF(ISBLANK(G14),"",G14/C14),0) -> 1 | K14: =IFERROR(IF(ISBLANK(H14),"",H14/C14),0) -> 0.96892125 | L14: =IFERROR(IF(ISBLANK(I14),"",I14/C14),0) -> 1 | M14: =IFERROR(L14-K14,"") -> 0.031078758 | N14: =IFERROR(L14/K14,"") -> 1.0320756 | O14: =+Progress!K9 -> 26918.4 | P14: =IF(ISBLANK(O14),"",O14/$O$27) -> 0.12 | Q14: =+Progress!M9 -> 171.13 | R14: =+Progress!N9 -> 0 | S14: =IFERROR(IF(ISBLANK(Q14),"",Q14/O14),0) -> 0.0063573615 | T14: =IFERROR(IF(ISBLANK(R14),"",R14/O14),0) -> 0 | U14: =+Progress!O9 -> 26338.75 | V14: =+Progress!P9 -> 26918.4 | W14: =IFERROR(IF(ISBLANK(U14),"",U14/O14),0) -> 0.9784664 | X14: =IFERROR(IF(ISBLANK(V14),"",V14/O14),0) -> 1 | Y14: =IFERROR(X14-W14,"") -> 0.021533598 | Z14: =IFERROR(X14/W14,"") -> 1.0220075
A15: =Progress!A11 -> Site Works | C15: =Progress!C11 -> 682299 | D15: =IF(ISBLANK(C15),"",C15/$C$27) -> 0.071414008 | E15: =Progress!E11 -> 48693 | F15: =Progress!F11 -> 0 | G15: =Progress!G11 -> 682299 | H15: =Progress!H11 -> 189310 | I15: =Progress!I11 -> 682299 | J15: =IFERROR(IF(ISBLANK(G15),"",G15/C15),0) -> 1 | K15: =IFERROR(IF(ISBLANK(H15),"",H15/C15),0) -> 0.277459 | L15: =IFERROR(IF(ISBLANK(I15),"",I15/C15),0) -> 1 | M15: =IFERROR(L15-K15,"") -> 0.722541 | N15: =IFERROR(L15/K15,"") -> 3.6041361 | O15: =Progress!K11 -> 10600 | P15: =IF(ISBLANK(O15),"",O15/$O$27) -> 0.047253923 | Q15: =Progress!M11 -> 1552 | R15: =Progress!N11 -> 0 | S15: =IFERROR(IF(ISBLANK(Q15),"",Q15/O15),0) -> 0.14641509 | T15: =IFERROR(IF(ISBLANK(R15),"",R15/O15),0) -> 0 | U15: =Progress!O11 -> 5528 | V15: =Progress!P11 -> 10600 | W15: =IFERROR(IF(ISBLANK(U15),"",U15/O15),0) -> 0.52150943 | X15: =IFERROR(IF(ISBLANK(V15),"",V15/O15),0) -> 1 | Y15: =IFERROR(X15-W15,"") -> 0.47849057 | Z15: =IFERROR(X15/W15,"") -> 1.9175109
A16: =Progress!A12 -> Concrete | C16: =Progress!C12 -> 508590 | D16: =IF(ISBLANK(C16),"",C16/$C$27) -> 0.053232454 | E16: =Progress!E12 -> 0 | F16: =Progress!F12 -> 0 | G16: =Progress!G12 -> 508590 | H16: =Progress!H12 -> 508590 | I16: =Progress!I12 -> 508590 | J16: =IFERROR(IF(ISBLANK(G16),"",G16/C16),0) -> 1 | K16: =IFERROR(IF(ISBLANK(H16),"",H16/C16),0) -> 1 | L16: =IFERROR(IF(ISBLANK(I16),"",I16/C16),0) -> 1 | M16: =IFERROR(L16-K16,"") -> 0 | N16: =IFERROR(L16/K16,"") -> 1 | O16: =Progress!K12 -> 38936 | P16: =IF(ISBLANK(O16),"",O16/$O$27) -> 0.17357347 | Q16: =Progress!M12 -> 0 | R16: =Progress!N12 -> 0 | S16: =IFERROR(IF(ISBLANK(Q16),"",Q16/O16),0) -> 0 | T16: =IFERROR(IF(ISBLANK(R16),"",R16/O16),0) -> 0 | U16: =Progress!O12 -> 38936 | V16: =Progress!P12 -> 38936 | W16: =IFERROR(IF(ISBLANK(U16),"",U16/O16),0) -> 1 | X16: =IFERROR(IF(ISBLANK(V16),"",V16/O16),0) -> 1 | Y16: =IFERROR(X16-W16,"") -> 0 | Z16: =IFERROR(X16/W16,"") -> 1 | AJ16: 0
A17: =Progress!A13 -> Masonry Work | C17: =Progress!C13 -> 25032 | D17: =IF(ISBLANK(C17),"",C17/$C$27) -> 0.0026200177 | E17: =Progress!E13 -> 699 | F17: =Progress!F13 -> 0 | G17: =Progress!G13 -> 25032 | H17: =Progress!H13 -> 25032 | I17: =Progress!I13 -> 25032 | J17: =IFERROR(IF(ISBLANK(G17),"",G17/C17),0) -> 1 | K17: =IFERROR(IF(ISBLANK(H17),"",H17/C17),0) -> 1 | L17: =IFERROR(IF(ISBLANK(I17),"",I17/C17),0) -> 1 | M17: =IFERROR(L17-K17,"") -> 0 | N17: =IFERROR(L17/K17,"") -> 1 | O17: =Progress!K13 -> 4992 | P17: =IF(ISBLANK(O17),"",O17/$O$27) -> 0.022253923 | Q17: =Progress!M13 -> 384 | R17: =Progress!N13 -> 0 | S17: =IFERROR(IF(ISBLANK(Q17),"",Q17/O17),0) -> 0.076923077 | T17: =IFERROR(IF(ISBLANK(R17),"",R17/O17),0) -> 0 | U17: =Progress!O13 -> 4992 | V17: =Progress!P13 -> 4992 | W17: =IFERROR(IF(ISBLANK(U17),"",U17/O17),0) -> 1 | X17: =IFERROR(IF(ISBLANK(V17),"",V17/O17),0) -> 1 | Y17: =IFERROR(X17-W17,"") -> 0 | Z17: =IFERROR(X17/W17,"") -> 1 | AJ17: 0
A18: =Progress!A14 -> Metal Works | C18: =Progress!C14 -> 43560 | D18: =IF(ISBLANK(C18),"",C18/$C$27) -> 0.0045592829 | E18: =Progress!E14 -> 2160 | F18: =Progress!F14 -> 0 | G18: =Progress!G14 -> 43560 | H18: =Progress!H14 -> 8640 | I18: =Progress!I14 -> 43560 | J18: =IFERROR(IF(ISBLANK(G18),"",G18/C18),0) -> 1 | K18: =IFERROR(IF(ISBLANK(H18),"",H18/C18),0) -> 0.19834711 | L18: =IFERROR(IF(ISBLANK(I18),"",I18/C18),0) -> 1 | M18: =IFERROR(L18-K18,"") -> 0.80165289 | N18: =IFERROR(L18/K18,"") -> 5.0416667 | O18: =Progress!K14 -> 1288 | P18: =IF(ISBLANK(O18),"",O18/$O$27) -> 0.0057417974 | Q18: =Progress!M14 -> 96 | R18: =Progress!N14 -> 0 | S18: =IFERROR(IF(ISBLANK(Q18),"",Q18/O18),0) -> 0.074534161 | T18: =IFERROR(IF(ISBLANK(R18),"",R18/O18),0) -> 0 | U18: =Progress!O14 -> 384 | V18: =Progress!P14 -> 1288 | W18: =IFERROR(IF(ISBLANK(U18),"",U18/O18),0) -> 0.29813665 | X18: =IFERROR(IF(ISBLANK(V18),"",V18/O18),0) -> 1 | Y18: =IFERROR(X18-W18,"") -> 0.70186335 | Z18: =IFERROR(X18/W18,"") -> 3.3541667
A19: =Progress!A15 -> Thermal & Moisture Protection | C19: =Progress!C15 -> 114132 | D19: =IF(ISBLANK(C19),"",C19/$C$27) -> 0.011945824 | E19: =Progress!E15 -> 2911 | F19: =Progress!F15 -> 0 | G19: =Progress!G15 -> 114132 | H19: =Progress!H15 -> 104262 | I19: =Progress!I15 -> 114132 | J19: =IFERROR(IF(ISBLANK(G19),"",G19/C19),0) -> 1 | K19: =IFERROR(IF(ISBLANK(H19),"",H19/C19),0) -> 0.91352119 | L19: =IFERROR(IF(ISBLANK(I19),"",I19/C19),0) -> 1 | M19: =IFERROR(L19-K19,"") -> 0.086478814 | N19: =IFERROR(L19/K19,"") -> 1.0946654 | O19: =Progress!K15 -> 5984 | P19: =IF(ISBLANK(O19),"",O19/$O$27) -> 0.026676177 | Q19: =Progress!M15 -> 560 | R19: =Progress!N15 -> 0 | S19: =IFERROR(IF(ISBLANK(Q19),"",Q19/O19),0) -> 0.093582888 | T19: =IFERROR(IF(ISBLANK(R19),"",R19/O19),0) -> 0 | U19: =Progress!O15 -> 4880 | V19: =Progress!P15 -> 5984 | W19: =IFERROR(IF(ISBLANK(U19),"",U19/O19),0) -> 0.81550802 | X19: =IFERROR(IF(ISBLANK(V19),"",V19/O19),0) -> 1 | Y19: =IFERROR(X19-W19,"") -> 0.18449198 | Z19: =IFERROR(X19/W19,"") -> 1.2262295
A20: =Progress!A16 -> Doors and Windows | C20: =Progress!C16 -> 198780 | D20: =IF(ISBLANK(C20),"",C20/$C$27) -> 0.020805653 | E20: =Progress!E16 -> 63746 | F20: =Progress!F16 -> 0 | G20: =Progress!G16 -> 198780 | H20: =Progress!H16 -> 150146 | I20: =Progress!I16 -> 198780 | J20: =IFERROR(IF(ISBLANK(G20),"",G20/C20),0) -> 1 | K20: =IFERROR(IF(ISBLANK(H20),"",H20/C20),0) -> 0.75533756 | L20: =IFERROR(IF(ISBLANK(I20),"",I20/C20),0) -> 1 | M20: =IFERROR(L20-K20,"") -> 0.24466244 | N20: =IFERROR(L20/K20,"") -> 1.3239114 | O20: =Progress!K16 -> 8048 | P20: =IF(ISBLANK(O20),"",O20/$O$27) -> 0.035877318 | Q20: =Progress!M16 -> 1432 | R20: =Progress!N16 -> 0 | S20: =IFERROR(IF(ISBLANK(Q20),"",Q20/O20),0) -> 0.17793241 | T20: =IFERROR(IF(ISBLANK(R20),"",R20/O20),0) -> 0 | U20: =Progress!O16 -> 2584 | V20: =Progress!P16 -> 8048 | W20: =IFERROR(IF(ISBLANK(U20),"",U20/O20),0) -> 0.32107356 | X20: =IFERROR(IF(ISBLANK(V20),"",V20/O20),0) -> 1 | Y20: =IFERROR(X20-W20,"") -> 0.67892644 | Z20: =IFERROR(X20/W20,"") -> 3.1145511
A21: =Progress!A17 -> Finishes | C21: =Progress!C17 -> 173460 | D21: =IF(ISBLANK(C21),"",C21/$C$27) -> 0.018155492 | E21: =Progress!E17 -> 3633 | F21: =Progress!F17 -> 0 | G21: =Progress!G17 -> 173460 | H21: =Progress!H17 -> 14069 | I21: =Progress!I17 -> 173460 | J21: =IFERROR(IF(ISBLANK(G21),"",G21/C21),0) -> 1 | K21: =IFERROR(IF(ISBLANK(H21),"",H21/C21),0) -> 0.081108036 | L21: =IFERROR(IF(ISBLANK(I21),"",I21/C21),0) -> 1 | M21: =IFERROR(L21-K21,"") -> 0.91889196 | N21: =IFERROR(L21/K21,"") -> 12.329234 | O21: =Progress!K17 -> 11200 | P21: =IF(ISBLANK(O21),"",O21/$O$27) -> 0.049928673 | Q21: =Progress!M17 -> 480 | R21: =Progress!N17 -> 0 | S21: =IFERROR(IF(ISBLANK(Q21),"",Q21/O21),0) -> 0.042857143 | T21: =IFERROR(IF(ISBLANK(R21),"",R21/O21),0) -> 0 | U21: =Progress!O17 -> 2560 | V21: =Progress!P17 -> 11200 | W21: =IFERROR(IF(ISBLANK(U21),"",U21/O21),0) -> 0.22857143 | X21: =IFERROR(IF(ISBLANK(V21),"",V21/O21),0) -> 1 | Y21: =IFERROR(X21-W21,"") -> 0.77142857 | Z21: =IFERROR(X21/W21,"") -> 4.375
A22: =Progress!A18 -> Specialties | C22: =Progress!C18 -> 27450 | D22: =IF(ISBLANK(C22),"",C22/$C$27) -> 0.0028731018 | E22: =Progress!E18 -> 0 | F22: =Progress!F18 -> 0 | G22: =Progress!G18 -> 27450 | H22: =Progress!H18 -> 0 | I22: =Progress!I18 -> 27450 | J22: =IFERROR(IF(ISBLANK(G22),"",G22/C22),0) -> 1 | K22: =IFERROR(IF(ISBLANK(H22),"",H22/C22),0) -> 0 | L22: =IFERROR(IF(ISBLANK(I22),"",I22/C22),0) -> 1 | M22: =IFERROR(L22-K22,"") -> 1 | N22: =IFERROR(L22/K22,"") | O22: =Progress!K18 -> 1392 | P22: =IF(ISBLANK(O22),"",O22/$O$27) -> 0.0062054208 | Q22: =Progress!M18 -> 0 | R22: =Progress!N18 -> 0 | S22: =IFERROR(IF(ISBLANK(Q22),"",Q22/O22),0) -> 0 | T22: =IFERROR(IF(ISBLANK(R22),"",R22/O22),0) -> 0 | U22: =Progress!O18 -> 0 | V22: =Progress!P18 -> 1392 | W22: =IFERROR(IF(ISBLANK(U22),"",U22/O22),0) -> 0 | X22: =IFERROR(IF(ISBLANK(V22),"",V22/O22),0) -> 1 | Y22: =IFERROR(X22-W22,"") -> 1 | Z22: =IFERROR(X22/W22,"")
A23: =Progress!A19 -> Pre Engineered Structure | C23: =Progress!C19 -> 1223640 | D23: =IF(ISBLANK(C23),"",C23/$C$27) -> 0.1280744 | E23: =Progress!E19 -> 0 | F23: =Progress!F19 -> 0 | G23: =Progress!G19 -> 1223640 | H23: =Progress!H19 -> 1223640 | I23: =Progress!I19 -> 1188960 | J23: =IFERROR(IF(ISBLANK(G23),"",G23/C23),0) -> 1 | K23: =IFERROR(IF(ISBLANK(I23),"",I23/C23),0) -> 0.97165833 | L23: =IFERROR(IF(ISBLANK(I23),"",I23/C23),0) -> 0.97165833 | M23: =IFERROR(L23-K23,"") -> 0 | N23: =IFERROR(L23/K23,"") -> 1 | O23: =Progress!K19 -> 18224 | P23: =IF(ISBLANK(O23),"",O23/$O$27) -> 0.081241084 | Q23: =Progress!M19 -> 0 | R23: =Progress!N19 -> 0 | S23: =IFERROR(IF(ISBLANK(Q23),"",Q23/O23),0) -> 0 | T23: =IFERROR(IF(ISBLANK(R23),"",R23/O23),0) -> 0 | U23: =Progress!O19 -> 18224 | V23: =Progress!P19 -> 16640 | W23: =IFERROR(IF(ISBLANK(U23),"",U23/O23),0) -> 1 | X23: =IFERROR(IF(ISBLANK(V23),"",V23/O23),0) -> 0.91308165 | Y23: =IFERROR(X23-W23,"") -> -0.086918349 | Z23: =IFERROR(X23/W23,"") -> 0.91308165
A24: =Progress!A20 -> Mechanical Work | C24: =Progress!C20 -> 1175904 | D24: =IF(ISBLANK(C24),"",C24/$C$27) -> 0.12307803 | E24: =Progress!E20 -> 6048 | F24: =Progress!F20 -> 201600 | G24: =Progress!G20 -> 1175904 | H24: =Progress!H20 -> 1099852 | I24: =Progress!I20 -> 1175904 | J24: =IFERROR(IF(ISBLANK(G24),"",G24/C24),0) -> 1 | K24: =IFERROR(IF(ISBLANK(I24),"",I24/C24),0) -> 1 | L24: =IFERROR(IF(ISBLANK(I24),"",I24/C24),0) -> 1 | M24: =IFERROR(L24-K24,"") -> 0 | N24: =IFERROR(L24/K24,"") -> 1 | O24: =Progress!K20 -> 29328 | P24: =IF(ISBLANK(O24),"",O24/$O$27) -> 0.1307418 | Q24: =Progress!M20 -> 592 | R24: =Progress!N20 -> 1152 | S24: =IFERROR(IF(ISBLANK(Q24),"",Q24/O24),0) -> 0.020185488 | T24: =IFERROR(IF(ISBLANK(R24),"",R24/O24),0) -> 0.039279869 | U24: =Progress!O20 -> 24816 | V24: =Progress!P20 -> 29328 | W24: =IFERROR(IF(ISBLANK(U24),"",U24/O24),0) -> 0.84615385 | X24: =IFERROR(IF(ISBLANK(V24),"",V24/O24),0) -> 1 | Y24: =IFERROR(X24-W24,"") -> 0.15384615 | Z24: =IFERROR(X24/W24,"") -> 1.1818182
A25: =Progress!A21 -> Electrical Work | C25: =Progress!C21 -> 1607621.4 | D25: =IF(ISBLANK(C25),"",C25/$C$27) -> 0.16826448 | E25: =Progress!E21 -> 101540 | F25: =Progress!F21 -> 15744 | G25: =Progress!G21 -> 1607621 | H25: =Progress!H21 -> 1120317 | I25: =Progress!I21 -> 1581472 | J25: =IFERROR(IF(ISBLANK(G25),"",G25/C25),0) -> 0.99999975 | K25: =IFERROR(IF(ISBLANK(I25),"",I25/C25),0) -> 0.98373411 | L25: =IFERROR(IF(ISBLANK(I25),"",I25/C25),0) -> 0.98373411 | M25: =IFERROR(L25-K25,"") -> 0 | N25: =IFERROR(L25/K25,"") -> 1 | O25: =Progress!K21 -> 41144 | P25: =IF(ISBLANK(O25),"",O25/$O$27) -> 0.18341655 | Q25: =Progress!M21 -> 1792 | R25: =Progress!N21 -> 537.6 | S25: =IFERROR(IF(ISBLANK(Q25),"",Q25/O25),0) -> 0.043554346 | T25: =IFERROR(IF(ISBLANK(R25),"",R25/O25),0) -> 0.013066304 | U25: =Progress!O21 -> 29256 | V25: =Progress!P21 -> 40090.56 | W25: =IFERROR(IF(ISBLANK(U25),"",U25/O25),0) -> 0.71106358 | X25: =IFERROR(IF(ISBLANK(V25),"",V25/O25),0) -> 0.97439627 | Y25: =IFERROR(X25-W25,"") -> 0.26333269 | Z25: =IFERROR(X25/W25,"") -> 1.3703363
A26: =Progress!A23 -> Close-Out | C26: =Progress!C23 -> 955413.4 | D26: =IF(ISBLANK(C26),"",C26/$C$27) -> 0.1 | E26: =Progress!E23 -> 0 | F26: =Progress!F23 -> 1281 | G26: =Progress!G23 -> 955413 | H26: =Progress!H23 -> 0 | I26: =Progress!I23 -> 724624 | J26: =IFERROR(IF(ISBLANK(G26),"",G26/C26),0) -> 0.99999958 | K26: =IFERROR(IF(ISBLANK(I26),"",I26/C26),0) -> 0.75844027 | L26: =IFERROR(IF(ISBLANK(I26),"",I26/C26),0) -> 0.75844027 | M26: =IFERROR(L26-K26,"") -> 0 | N26: =IFERROR(L26/K26,"") -> 1 | O26: =Progress!K22 -> 8320 | P26: =IF(ISBLANK(O26),"",O26/$O$27) -> 0.037089872 | Q26: =Progress!M23 -> 0 | R26: =Progress!N23 -> 89.6 | S26: =IFERROR(IF(ISBLANK(Q26),"",Q26/O26),0) -> 0 | T26: =IFERROR(IF(ISBLANK(R26),"",R26/O26),0) -> 0.010769231 | U26: =Progress!O23 -> 0 | V26: =Progress!P23 -> 3161.6 | W26: =IFERROR(IF(ISBLANK(U26),"",U26/O26),0) -> 0 | X26: =IFERROR(IF(ISBLANK(V26),"",V26/O26),0) -> 0.38 | Y26: =IFERROR(X26-W26,"") -> 0.38 | Z26: =IFERROR(X26/W26,"")
B27: Total | C27: =SUM(C12:C26) -> 9554134 | D27: =SUM(D12:D26) -> 1 | E27: =SUM(E12:E26) -> 381787 | F27: =SUM(F12:F26) -> 218625 | G27: =SUM(G12:G26) -> 9554133 | H27: =SUM(H12:H26) -> 7183281 | I27: =SUM(I12:I26) -> 9262515 | J27: =IFERROR(IF(ISBLANK(G27),"",G27/C27),0) -> 0.9999999 | K27: =IFERROR(IF(ISBLANK(H27),"",H27/C27),0) -> 0.75185056 | L27: =IFERROR(IF(ISBLANK(I27),"",I27/C27),0) -> 0.96947719 | M27: =+L27-K27 -> 0.21762663 | N27: =L27/K27 -> 1.2894546 | O27: =SUM(O12:O26) -> 224320 | P27: =SUM(P12:P26) -> 1 | Q27: =SUM(Q12:Q26) -> 7059.13 | R27: =SUM(R12:R26) -> 1779.2 | S27: =IFERROR(IF(ISBLANK(Q27),"",Q27/O27),0) -> 0.031469017 | T27: =IFERROR(IF(ISBLANK(R27),"",R27/O27),0) -> 0.0079315264 | U27: =SUM(U12:U26) -> 176444.35 | V27: =SUM(V12:V26) -> 216524.16 | W27: =IFERROR(IF(ISBLANK(U27),"",U27/O27),0) -> 0.78657431 | X27: =IFERROR(IF(ISBLANK(V27),"",V27/O27),0) -> 0.96524679 | Y27: =+X27-W27 -> 0.17867248 | Z27: =X27/W27 -> 1.2271527
AA28: Construction Milestones
AA29: Item No. | AB29: Milestones | AD29: Original (Baseline) | AE29: Latest Plan | AF29: Forecast | AG29: Status | AH29: Days Change
AA30: =+Milestones!A4 -> 1 | AB30: =+Milestones!B4 -> Award Date | AD30: =+Milestones!C4 -> 46047 | AE30: =+Milestones!D4 -> 46047 | AF30: =+Milestones!E4 -> 46047 | AG30: =+Milestones!F4 -> A | AH30: =+Milestones!G4 -> 0
AA31: =+Milestones!A5 -> 2 | AB31: =+Milestones!B5 -> Contract Sign Date | AD31: =+Milestones!C5 -> 46065 | AE31: =+Milestones!D5 -> 46065 | AF31: =+Milestones!E5 -> 46065 | AG31: =+Milestones!F5 -> A | AH31: =+Milestones!G5 -> 0
AA32: =+Milestones!A6 -> 3 | AB32: =+Milestones!B6 -> Site Handover Date | AD32: =+Milestones!C6 -> 46084 | AE32: =+Milestones!D6 -> 46084 | AF32: =+Milestones!E6 -> 46084 | AG32: =+Milestones!F6 -> A | AH32: =+Milestones!G6 -> 0
AA33: =+Milestones!A7 -> 4 | AB33: =+Milestones!B7 -> Complete Mobilization | AD33: =+Milestones!C7 -> 45747 | AE33: =+Milestones!D7 -> 45747 | AF33: =+Milestones!E7 -> 45747 | AG33: =+Milestones!F7 -> A | AH33: =+Milestones!G7 -> 0
AA34: =+Milestones!A8 -> 5 | AB34: =+Milestones!B8 -> Complete existing condition survey, submission of Final Reports | AD34: =+Milestones!C8 -> 45747 | AE34: =+Milestones!D8 -> 45747 | AF34: =+Milestones!E8 -> 45747 | AG34: =+Milestones!F8 -> A | AH34: =+Milestones!G8 -> 0
AA35: =+Milestones!A9 -> 6 | AB35: =+Milestones!B9 -> Completion of Long Lead Procurement and Material Delivery | AD35: =+Milestones!C9 -> 46322 | AE35: =+Milestones!D9 -> 46322 | AF35: =+Milestones!E9 -> 46322 | AG35: =+Milestones!F9 -> A | AH35: =+Milestones!G9 -> 0
AA36: =+Milestones!A10 -> 7 | AB36: =+Milestones!B10 -> Completion of Short Lead Procurement and Material Delivery | AD36: =+Milestones!C10 -> 46324 | AE36: =+Milestones!D10 -> 46270 | AF36: =+Milestones!E10 -> 46270 | AG36: =+Milestones!F10 -> A | AH36: =+Milestones!G10 -> 0
AA37: =+Milestones!A11 -> 8 | AB37: =+Milestones!B11 -> Complete All Warehouse | AD37: =+Milestones!C11 -> 46355 | AE37: =+Milestones!D11 -> 46298 | AF37: =+Milestones!E11 -> 46298 | AG37: =+Milestones!F11 -> A | AH37: =+Milestones!G11 -> 0
AA38: =+Milestones!A12 -> 9 | AB38: =+Milestones!B12 -> Complete All Outside Mosque (Prayer Room) | AD38: =+Milestones!C12 -> 46361 | AE38: =+Milestones!D12 -> 46295 | AF38: =+Milestones!E12 -> 46295 | AG38: =+Milestones!F12 -> A | AH38: =+Milestones!G12 -> 0
A54: Performance overview
A55: Submittals Status | L55: Quality | W55: Safety
A56: Shop Drawings | L56: Quality Reports | W56: Safety Statistics | AE56: Proactive Vs Reactive Actions Taken
...

Sheet General Information
A1: Weekly Progress Report - Construction Projects | K1: Data Date | L1: 46308
A2: Contract General Information
A3: Project Name | C3: Construction of Industrial Units for Artisans in Najran
A4: Project ID | C4: NJR1-05-005
A5: Contractor | C5: Labenat Al Bena
A6: Consultant | C6: EGIS
A7: Stage | C7: Construction
A8: Status | C8: Active
A9: Modon PM | C9: Eng. Ahmed Kotbi
A11: Key Dates
A12: Contract Award Date | C12: =Milestones!C4 -> 46047
A13: Contract Sign Date | C13: =Milestones!C5 -> 46065
A14: Site Handover Date | C14: =Milestones!C6 -> 46084
A15: Original Completion | C15: =Milestones!C15 -> 46389
A16: Contract Award Date (Hijri) | C16: =C12 -> 46047
A17: Contract Sign Date (Hijri) | C17: =C13 -> 46065
A18: Site Handover Date (Hijri) | C18: =C14 -> 46084
A19: Original Completion (Hijri) | C19: =C15 -> 46389
A20: Revised Completion Date | C20: =Milestones!D15 -> 46389
A21: Committed Completion Date | C21: =Milestones!E15 -> 46310
A22: Forecast Completion | C22: =Milestones!E15 -> 46310
A23: Variance | C23: =C20-C22 -> 79
A25: Key Project Submittals | C25: Submission Date | D25: Days taken to approve orginal plan from site handover date
A26: Quality Plan submission | C26: 46128 | D26: =C26-C14 -> 44
A27: Quality Plan approval | C27: 46134
A28: Quality Plan Last Update | C28: 46134
A30: Safety Plan submission | C30: 46117 | D30: =C30-C14 -> 33
A31: Safety Plan approval | C31: 46130
A32: Safety Plan Last Update | C32: 46130
A34: Risk Management Plan submission | C34: 46155 | D34: =C34-C14 -> 71
A35: Risk Management Plan approval | C35: 46167
A36: Risk Management Plan Last Update | C36: 46167
A38: Baseline Schedule submission | C38: 46113 | D38: =C38-C14 -> 29
A39: Baseline Schedule approval | C39: 46113
A40: No of Schedule Versions | C40: 0
A41: Last Recovery Schedule Approval Date | C41: 46113
A43: BOQ submission | C43: =C14 -> 46084 | D43: =C43-C19 -> -305
A44: BOQ approval | C44: N/A | E44: There is one revision of BOQ submitted
A45: No of Approved Version of BOQ | C45: 0
A47: Construction Plan submission | C47: 46114 | D47: =C47-C14 -> 30
...

Sheet PV-PH
E4: Tuesday | F4: Tuesday | G4: Tuesday | H4: Tuesday | I4: Tuesday | J4: Tuesday | K4: Tuesday | L4: Tuesday | M4: Tuesday | N4: Tuesday | O4: Tuesday | P4: Tuesday | Q4: Tuesday | R4: Tuesday | S4: Tuesday | T4: Tuesday | U4: Tuesday | V4: Tuesday | W4: Tuesday | X4: Tuesday | Y4: Tuesday | Z4: Tuesday | AA4: Tuesday | AB4: Tuesday | AC4: Tuesday | AD4: Tuesday | AE4: Tuesday | AF4: Tuesday | AG4: Tuesday | AH4: Tuesday | AI4: Tuesday | AJ4: Tuesday | AK4: Tuesday | AL4: Tuesday | AM4: Tuesday | AN4: Tuesday | AO4: Tuesday | AP4: Tuesday | AQ4: Tuesday | AR4: Tuesday | AS4: Tuesday | AT4: Tuesday | AU4: Tuesday | AV4: Tuesday | AW4: Tuesday | AX4: Tuesday | AY4: Tuesday | AZ4: Tuesday | BA4: Tuesday | BB4: Tuesday | BC4: Tuesday | BD4: Tuesday
E5: =E6 -> 45300 | F5: =F6 -> 45307 | G5: =G6 -> 45314 | H5: =H6 -> 45321 | I5: =I6 -> 45328 | J5: =J6 -> 45335 | K5: =K6 -> 45342 | L5: =L6 -> 45349 | ... BD5: =BD6 -> 45657
B6: Activity ID | C6: Budgeted Units | D6: Spreadsheet Field | E6: 45300 | F6: 45307 | G6: 45314 | H6: 45321 | I6: 45328 | J6: 45335 | K6: 45342 | L6: 45349 | M6: 45356 | N6: 45363 | O6: 45370 | P6: 45377 | Q6: 45384 | R6: 45391 | S6: 45398 | T6: 45405 | U6: 45412 | V6: 45419 | W6: 45426 | X6: 45433 | Y6: 45440 | Z6: 45447 | AA6: 45454 | AB6: 45461 | AC6: 45468 | AD6: 45475 | AE6: 45482 | AF6: 45489 | AG6: 45496 | AH6: 45503 | AI6: 45510 | AJ6: 45517 | AK6: 45524 | AL6: 45531 | AM6: 45538 | AN6: 45545 | AO6: 45552 | AP6: 45559 | AQ6: 45566 | AR6: 45573 | AS6: 45580 | AT6: 45587 | AU6: 45594 | AV6: 45601 | AW6: 45608 | AX6: 45615 | AY6: 45622 | AZ6: 45629 | BA6: 45636 | BB6: 45643 | BC6: 45650 | BD6: 45657
B7: Project: HAL1-05-1 Civil Defense Fire Station in Hail Industrial City | C7: 220460.02 | D7: Budgeted Units | E7: =E8 -> 255.34 | F7: =F8-E8 -> 533.36 | G7: =G8-F8 -> 831.16 | H7: =H8-G8 -> 2077.87 | I7: =I8-H8 -> 2245.69 | J7: =J8-I8 -> 1087.72 | K7: =K8-J8 -> 1210.9 | L7: =L8-K8 -> 888.95 | M7: =M8-L8 -> 1077.11 | ... BD7: =BD8-BC8 -> 4056.33
B8: Project: HAL1-05-1 Civil Defense Fire Station in Hail Industrial City | C8: 220460.02 | D8: Cum Budgeted Units | E8: 255.34 | F8: 788.7 | G8: 1619.86 | H8: 3697.73 | I8: 5943.42 | J8: 7031.14 | K8: 8242.04 | L8: 9130.99 | M8: 10208.1 | N8: 11381.53 | O8: 12793.76 | P8: 14373.94 | Q8: 16376.73 | R8: 17684.7 | S8: 18685.95 | T8: 20449.72 | U8: 22408.53 | V8: 26223.73 | W8: 30933.46 | X8: 35121.81 | Y8: 39534.02 | Z8: 44758.71 | AA8: 49842.92 | AB8: 51760.8 | AC8: 59081.04 | AD8: 63023.99 | AE8: 67887.31 | AF8: 73180.87 | AG8: 81643.94 | AH8: 99223.69 | AI8: 118314.53 | AJ8: 128622.04 | AK8: 133738.93 | AL8: 137361.8 | AM8: 139381.34 | AN8: 142958.41 | AO8: 147374.26 | AP8: 152520 | AQ8: 161471.54 | AR8: 168527.25 | AS8: 172440.36 | AT8: 180991.98 | AU8: 187776.76 | AV8: 197084.19 | AW8: 201472.02 | AX8: 208589.52 | AY8: 209414.52 | AZ8: 209672.02 | BA8: 210165.22 | BB8: 210650.82 | BC8: 211705.36 | BD8: 215761.69
B9: WBS: HAL1-05-1.2 MOBILIZATION | C9: 3445.8 | D9: Budgeted Units | E9: =E10 -> 147.78 | F9: =F10-E10 -> 295.56 | G9: =G10-F10 -> 511.56 | H9: =H10-G10 -> 1259.34 | I9: =I10-H10 -> 1231.56 | J9: =J10-I10 -> 0 | K9: =K10-J10 -> 0 | L9: =L10-K10 -> 0 | M9: =M10-L10 -> 0 | ... BD9: =BD10-BC10 -> 0
B10: WBS: HAL1-05-1.2 MOBILIZATION | C10: 3445.8 | D10: Cum Budgeted Units | E10: 147.78 | F10: 443.34 | G10: 954.9 | H10: 2214.24 | I10: 3445.8 | J10: 3445.8 | K10: 3445.8 | L10: 3445.8 | M10: 3445.8 | N10: 3445.8 | O10: 3445.8 | P10: 3445.8 | Q10: 3445.8 | R10: 3445.8 | S10: 3445.8 | T10: 3445.8 | U10: 3445.8 | V10: 3445.8 | W10: 3445.8 | X10: 3445.8 | Y10: 3445.8 | Z10: 3445.8 | AA10: 3445.8 | AB10: 3445.8 | AC10: 3445.8 | AD10: 3445.8 | AE10: 3445.8 | AF10: 3445.8 | AG10: 3445.8 | AH10: 3445.8 | AI10: 3445.8 | AJ10: 3445.8 | AK10: 3445.8 | AL10: 3445.8 | AM10: 3445.8 | AN10: 3445.8 | AO10: 3445.8 | AP10: 3445.8 | AQ10: 3445.8 | AR10: 3445.8 | AS10: 3445.8 | AT10: 3445.8 | AU10: 3445.8 | AV10: 3445.8 | AW10: 3445.8 | AX10: 3445.8 | AY10: 3445.8 | AZ10: 3445.8 | BA10: 3445.8 | BB10: 3445.8 | BC10: 3445.8 | BD10: 3445.8
B11: WBS: HAL1-05-1.7 SITE | C11: 66611.78 | D11: Budgeted Units | E11: =E12 -> 22.08 | F11: =F12-E12 -> 46.22 | G11: =G12-F12 -> 55.61 | H11: =H12-G12 -> 163.79 | I11: =I12-H12 -> 240.88 | J11: =J12-I12 -> 350.73 | K11: =K12-J12 -> 366.06 | L11: =L12-K12 -> 157.13 | M11: =M12-L12 -> 268.48 | ... BD11: =BD12-BC12 -> 0
B12: WBS: HAL1-05-1.7 SITE | C12: 66611.78 | D12: Cum Budgeted Units | E12: 22.08 | F12: 68.3 | G12: 123.91 | H12: 287.7 | I12: 528.58 | J12: 879.31 | K12: 1245.37 | L12: 1402.5 | M12: 1670.98 | N12: 1878.94 | O12: 1932.17 | P12: 1935.95 | Q12: 2076.79 | R12: 2172.1 | S12: 2284.56 | T12: 2558.02 | U12: 3091.03 | V12: 4406.94 | W12: 6292.79 | X12: 8347.05 | Y12: 9983.23 | Z12: 11275.75 | AA12: 12225.03 | AB12: 12552.93 | AC12: 13681.42 | AD12: 14996.13 | AE12: 16434.3 | AF12: 17785.21 | AG12: 19054.07 | AH12: 28098.78 | AI12: 37613.83 | AJ12: 41436.65 | AK12: 41936.91 | AL12: 42693.59 | AM12: 43386.61 | AN12: 44314.27 | AO12: 45261.28 | AP12: 45706.33 | AQ12: 46519.29 | AR12: 47168.38 | AS12: 47897.78 | AT12: 50434.06 | AU12: 51791.35 | AV12: 56267.61 | AW12: 59290.78 | AX12: 65081.78 | AY12: 65081.78 | AZ12: 65201.78 | BA12: 65694.98 | BB12: 66180.58 | BC12: 66611.78 | BD12: 66611.78
B13: WBS: HAL1-05-1.7.1 Engineering | C13: 1607.2 | D13: Budgeted Units | E13: =E14 -> 22.08 | F13: =F14-E14 -> 46.22 | G13: =G14-F14 -> 55.61 | H13: =H14-G14 -> 163.79 | I13: =I14-H14 -> 240.88 | J13: =J14-I14 -> 229.01 | K13: =K14-J14 -> 244.35 | L13: =L14-K14 -> 116.56 | M13: =M14-L14 -> 241.48 | ... BD13: =BD14-BC14 -> 0
B14: WBS: HAL1-05-1.7.1 Engineering | C14: 1607.2 | D14: Cum Budgeted Units | E14: 22.08 | F14: 68.3 | G14: 123.91 | H14: 287.7 | I14: 528.58 | J14: 757.59 | K14: 1001.94 | L14: 1118.5 | M14: 1359.98 | N14: 1540.95 | O14: 1582.66 | P14: 1582.66 | Q14: 1592.88 | R14: 1601.06 | S14: 1604.74 | T14: 1607.2 | U14: 1607.2 | V14: 1607.2 | W14: 1607.2 | X14: 1607.2 | Y14: 1607.2 | Z14: 1607.2 | AA14: 1607.2 | AB14: 1607.2 | AC14: 1607.2 | AD14: 1607.2 | AE14: 1607.2 | AF14: 1607.2 | AG14: 1607.2 | AH14: 1607.2 | AI14: 1607.2 | AJ14: 1607.2 | AK14: 1607.2 | AL14: 1607.2 | AM14: 1607.2 | AN14: 1607.2 | AO14: 1607.2 | AP14: 1607.2 | AQ14: 1607.2 | AR14: 1607.2 | AS14: 1607.2 | AT14: 1607.2 | AU14: 1607.2 | AV14: 1607.2 | AW14: 1607.2 | AX14: 1607.2 | AY14: 1607.2 | AZ14: 1607.2 | BA14: 1607.2 | BB14: 1607.2 | BC14: 1607.2 | BD14: 1607.2
B15: WBS: HAL1-05-1.7.2 Procurement | C15: 7653.58 | D15: Budgeted Units | E15: =E16 -> 0 | F15: =F16-E16 -> 0 | G15: =G16-F16 -> 0 | H15: =H16-G16 -> 0 | I15: =I16-H16 -> 0 | J15: =J16-I16 -> 0 | K15: =K16-J16 -> 0 | L15: =L16-K16 -> 0 | M15: =M16-L16 -> 27 | ... BD15: =BD16-BC16 -> 0
B16: WBS: HAL1-05-1.7.2 Procurement | C16: 7653.58 | D16: Cum Budgeted Units | M16: 27 | N16: 53.99 | O16: 65.51 | P16: 69.29 | Q16: 199.91 | R16: 287.04 | S16: 322.48 | T16: 373.49 | U16: 409.83 | V16: 459.74 | W16: 527.93 | X16: 659.18 | Y16: 703.7 | Z16: 777.89 | AA16: 824.67 | AB16: 851.4 | AC16: 978.39 | AD16: 1177.8 | AE16: 1308.55 | AF16: 1449.79 | AG16: 1711.98 | AH16: 1777.5 | AI16: 1794.3 | AJ16: 2430.12 | AK16: 2436.38 | AL16: 2456.39 | AM16: 2496.41 | AN16: 2512.07 | AO16: 2619.08 | AP16: 2632.13 | AQ16: 2965.09 | AR16: 3134.18 | AS16: 3143.58 | AT16: 4911.87 | AU16: 5126.15 | AV16: 7653.58 | AW16: 7653.58 | AX16: 7653.58 | AY16: 7653.58 | AZ16: 7653.58 | BA16: 7653.58 | BB16: 7653.58 | BC16: 7653.58 | BD16: 7653.58
B17: WBS: HAL1-05-1.7.3 Construction | C17: 57351 | D17: Budgeted Units | E17: =E18 -> 0 | F17: =F18-E18 -> 0 | G17: =G18-F18 -> 0 | H17: =H18-G18 -> 0 | I17: =I18-H18 -> 0 | J17: =J18-I18 -> 121.71 | K17: =K18-J18 -> 121.72 | L17: =L18-K18 -> 40.57 | M17: =M18-L18 -> 0 | ... BD17: =BD18-BC18 -> 0
B18: WBS: HAL1-05-1.7.3 Construction | C18: 57351 | D18: Cum Budgeted Units | J18: 121.71 | K18: 243.43 | L18: 284 | M18: 284 | N18: 284 | O18: 284 | P18: 284 | Q18: 284 | R18: 284 | S18: 357.33 | T18: 577.33 | U18: 1074 | V18: 2340 | W18: 4157.67 | X18: 6080.67 | Y18: 7672.33 | Z18: 8890.67 | AA18: 9793.17 | AB18: 10094.33 | AC18: 11095.83 | AD18: 12211.13 | AE18: 13518.56 | AF18: 14728.22 | AG18: 15734.89 | AH18: 24714.08 | AI18: 34212.33 | AJ18: 37399.33 | AK18: 37893.33 | AL18: 38630 | AM18: 39283 | AN18: 40195 | AO18: 41035 | AP18: 41467 | AQ18: 41947 | AR18: 42427 | AS18: 43147 | AT18: 43915 | AU18: 45058 | AV18: 47006.83 | AW18: 50030 | AX18: 55821 | AY18: 55821 | AZ18: 55941 | BA18: 56434.2 | BB18: 56919.8 | BC18: 57351 | BD18: 57351
B19: WBS: HAL1-05-1.8 MAIN BUILDING | C19: 86348.45 | D19: Budgeted Units | E19: =E20 -> 43.76 | F19: =F20-E20 -> 106.12 | G19: =G20-F20 -> 162.97 | H19: =H20-G20 -> 403.24 | I19: =I20-H20 -> 538.92 | J19: =J20-I20 -> 523.51 | K19: =K20-J20 -> 627.47 | L19: =L20-K20 -> 570.49 | M19: =M20-L20 -> 708.78 | ... BD19: =BD20-BC20 -> 0
B20: WBS: HAL1-05-1.8 MAIN BUILDING | C20: 86348.45 | D20: Cum Budgeted Units | E20: 43.76 | F20: 149.88 | G20: 312.85 | H20: 716.09 | I20: 1255.01 | J20: 1778.52 | K20: 2405.99 | L20: 2976.48 | M20: 3685.26 | N20: 4381.79 | O20: 4910.18 | P20: 5342.23 | Q20: 5674.68 | R20: 6031.27 | S20: 6307.46 | T20: 6658.3 | U20: 7241.47 | V20: 8485.4 | W20: 9239.56 | X20: 10073.28 | Y20: 11610.58 | Z20: 14033.99 | AA20: 16345.19 | AB20: 17031.9 | AC20: 19442.03 | AD20: 20252.43 | AE20: 21318.82 | AF20: 22858.1 | AG20: 27631.5 | AH20: 34063.19 | AI20: 39051.74 | AJ20: 43859.87 | AK20: 45224.45 | AL20: 46298.39 | AM20: 47552.29 | AN20: 49890.61 | AO20: 51969.6 | AP20: 54716.65 | AQ20: 62082.85 | AR20: 67916.4 | AS20: 70520.11 | AT20: 74007.45 | AU20: 78863.61 | AV20: 82694.78 | AW20: 84059.45 | AX20: 85385.95 | AY20: 86210.95 | AZ20: 86348.45 | BA20: 86348.45 | BB20: 86348.45 | BC20: 86348.45 | BD20: 86348.45
B21: WBS: HAL1-05-1.8.1 Engineering | C21: 3103.98 | D21: Budgeted Units | E21: =E22 -> 43.76 | F21: =F22-E22 -> 106.12 | G21: =G22-F22 -> 162.97 | H21: =H22-G22 -> 376.24 | I21: =I22-H22 -> 474.59 | J21: =J22-I22 -> 456.81 | K21: =K22-J22 -> 535.94 | L21: =L22-K22 -> 358.45 | M21: =M22-L22 -> 235.35 | ... BD21: =BD22-BC22 -> 0
B22: WBS: HAL1-05-1.8.1 Engineering | C22: 3103.98 | D22: Cum Budgeted Units | E22: 43.76 | F22: 149.88 | G22: 312.85 | H22: 689.09 | I22: 1163.68 | J22: 1620.49 | K22: 2156.43 | L22: 2514.88 | M22: 2750.23 | N22: 2879.05 | O22: 2923.01 | P22: 2988.45 | Q22: 3050.81 | R22: 3091.71 | S22: 3099.07 | T22: 3103.98 | U22: 3103.98 | V22: 3103.98 | W22: 3103.98 | X22: 3103.98 | Y22: 3103.98 | Z22: 3103.98 | AA22: 3103.98 | AB22: 3103.98 | AC22: 3103.98 | AD22: 3103.98 | AE22: 3103.98 | AF22: 3103.98 | AG22: 3103.98 | AH22: 3103.98 | AI22: 3103.98 | AJ22: 3103.98 | AK22: 3103.98 | AL22: 3103.98 | AM22: 3103.98 | AN22: 3103.98 | AO22: 3103.98 | AP22: 3103.98 | AQ22: 3103.98 | AR22: 3103.98 | AS22: 3103.98 | AT22: 3103.98 | AU22: 3103.98 | AV22: 3103.98 | AW22: 3103.98 | AX22: 3103.98 | AY22: 3103.98 | AZ22: 3103.98 | BA22: 3103.98 | BB22: 3103.98 | BC22: 3103.98 | BD22: 3103.98
B23: WBS: HAL1-05-1.8.2 Procurement | C23: 11205.47 | D23: Budgeted Units | E23: =E24 -> 0 | F23: =F24-E24 -> 0 | G23: =G24-F24 -> 0 | H23: =H24-G24 -> 27 | I23: =I24-H24 -> 64.32 | J23: =J24-I24 -> 66.71 | K23: =K24-J24 -> 91.53 | L23: =L24-K24 -> 20.04 | M23: =M24-L24 -> 9.43 | ... BD23: =BD24-BC24 -> 0
B24: WBS: HAL1-05-1.8.2 Procurement | C24: 11205.47 | D24: Cum Budgeted Units | H24: 27 | I24: 91.32 | J24: 158.03 | K24: 249.56 | L24: 269.6 | M24: 279.03 | N24: 306.73 | O24: 316.17 | P24: 337.78 | Q24: 426.15 | R24: 515.56 | S24: 582.39 | T24: 664.32 | U24: 739.22 | V24: 1010.36 | W24: 1287.59 | X24: 1614.3 | Y24: 1924.6 | Z24: 2328.01 | AA24: 2619.22 | AB24: 2723.42 | AC24: 3386.05 | AD24: 3705.65 | AE24: 4252.85 | AF24: 5024.13 | AG24: 5355.53 | AH24: 5777.21 | AI24: 6123.02 | AJ24: 7153.7 | AK24: 7487.8 | AL24: 7888.42 | AM24: 8338.32 | AN24: 9745.13 | AO24: 10340.62 | AP24: 11205.47 | AQ24: 11205.47 | AR24: 11205.47 | AS24: 11205.47 | AT24: 11205.47 | AU24: 11205.47 | AV24: 11205.47 | AW24: 11205.47 | AX24: 11205.47 | AY24: 11205.47 | AZ24: 11205.47 | BA24: 11205.47 | BB24: 11205.47 | BC24: 11205.47 | BD24: 11205.47
B25: WBS: HAL1-05-1.8.3 Construction | C25: 72039 | D25: Budgeted Units | E25: =E26 -> 0 | F25: =F26-E26 -> 0 | G25: =G26-F26 -> 0 | H25: =H26-G26 -> 0 | I25: =I26-H26 -> 0 | J25: =J26-I26 -> 0 | K25: =K26-J26 -> 0 | L25: =L26-K26 -> 192 | M25: =M26-L26 -> 464 | ... BD25: =BD26-BC26 -> 0
