Workbook
Name \0: #N/A
Name \00: #REF!
Name \44333: #REF!
Name \a: #REF!
Name \add9a: #REF!
Name \b: #N/A
Name \c: #REF!
Name \d: #REF!
Name \e: #REF!
Name \F: #REF!
Name \h: #REF!
Name \i: #N/A
Name \j: #REF!
Name \k: #REF!
Name \l: #REF!
Name \m: #REF!
Name \n: #REF!
Name \o: #REF!
Name \P: #REF!
Name \q: #N/A
Name \r: #REF!
Name \s: #N/A
Name \T: #REF!
Name \X: #REF!
Name \z: #N/A
Name \zpr: #REF!
Name __________________________dep2: #REF!
Name __________________________dep3: #REF!
Name __________________________ext2: #REF!
Name __________________________ext3: #REF!
Name __________________________len2: #REF!
Name __________________________len3: #REF!
Name __________________________pc1: #REF!
Name __________________________pc2: #REF!
Name __________________________pc3: #REF!
Name __________________________tbc2: #REF!
Name __________________________tbc3: #REF!
Name __________________________wid2: #REF!
Name __________________________wid3: #REF!
Name _________________________dep2: #REF!
Name _________________________dep3: #REF!
Name _________________________ext2: #REF!
Name _________________________ext3: #REF!
Name _________________________len2: #REF!
Name _________________________len3: #REF!
Name _________________________pc1: #REF!
Name _________________________pc2: #REF!
Name _________________________pc3: #REF!
Name _________________________tbc2: #REF!
Name _________________________tbc3: #REF!
Name _________________________wid2: #REF!
Name _________________________wid3: #REF!
Name _______________________dep2: #REF!
Name _______________________dep3: #REF!
Name _______________________ext2: #REF!
Name _______________________ext3: #REF!
Name _______________________len2: #REF!
Name _______________________len3: #REF!
Name _______________________pc1: #REF!
Name _______________________pc2: #REF!

Sheet General Summary 
A2: Client: | C2: Saudi Industrial Property Authority (MODON) | D2: المالك: الهيئة السعودية للمدن الصناعية ومناطق التقنية
A3: Project: | C3: Development of Infrastructure in Kharj Industrial City | D3: اسم المشروع: تطوير شبكات البنية التحتية في المدينة الصناعية بالخرج
A4: Location: | C4: Kharj 1 Industrial City | D4: موقع المشروع: المدينة الصناعية الاولى بالخرج
A5: Project No.: | C5: KHJ1-02-007 | D5: رقم المشروع:KHJ1-02-007
A6: Item | C6: DESCRIPTION | I6: Amount SR
D7: وصف البند
A11: Package.01 | C11: Infrastructure works for AlKharj - 3.5km2 | D11: مشروع تطوير شبكات البنية التحتية في المدينة الصناعية بالخرج بمساحة 3.5 كم2 | F11: حزمة 01 | I11: =P.1!F601 -> 226527683
A13: Package.02 | C13: Infrastructure works for Labour Camp area | D13: مشروع تطوير شبكات البنية التحتية في المدينة الصناعية بالخرج للقرية العمالية | F13: حزمة 02 | I13: =P.2!F632 -> 18085168
A15: Package.03 | C15: Development of Mosuqe, Helipad, Stormwater network and Road rehabilitation | D15: مشروع تطوير مسجد و مهبط هلكبتر و شبكات سيول و تاهيل طرق | F15: حزمة 03 | I15: =P.3!I1208 -> 23118731
C37: Total - SAR Carried to General Summary | D37: التكلفة الإجمالية للمشروع | I37: =SUM(I9:I35) -> 267731582

Sheet Cover1
B4: مدن | J4: MODON
B5: الهيئة السعودية للمدن الصناعية ومناطق التقنية | J5: SAUDI AUTHORITY FOR INDUSTRIAL CITIES AND TECHNOLOGY ZONES
B12: ='General Summary '!D3 -> اسم المشروع: تطوير شبكات البنية التحتية في المدينة الصناعية بالخرج | J12: ='General Summary '!C3 -> Development of Infrastructure in Kharj Industrial City
B17: البنية التحتية والخدمات | J17: INFRASTRUCTURE AND UTILITIES
B21: جدول الكميات | J21: BILL OF QUANTITIES
B26: نوفمبر 2025 | J26: 45972

Sheet Preamble1
A1: =Cover1!B12 -> اسم المشروع: تطوير شبكات البنية التحتية في المدينة الصناعية بالخرج | D1: =Cover1!J12 -> Development of Infrastructure in Kharj Industrial City
A2: جدول الكميات | D2: BILL OF QUANTITIES
B5: مقدمة البنود - مكونات البنود | C5: ITEMS PREAMBLE - ITEMS CONTENTS
B6: أعمال الموقع والأعمال الترابية | C6: Site and Earth Works
A7: 1.1 | B7: يعتبر المقاول من خلال زيارته للموقع بأنه قام بفحص واستكشاف الموقع ومحيطه وأنه قام بتحديد والأخذ بعين الاعتبار عند إعطاء أسعاره كافة التكاليف الإضافية المتعلقة بهدم (بشكل حذر) المنشآت القائمة وطرق الوصول إلى الموقع وإزالة طبقات الأعشاب الموجودة والخرسانة والأرصفة وطبقات الرصف والاسفلت وأحجار الارصفة و التربة العلوية والسياج وحماية خطوط الخدمات القائمة وكافة ملحقاتها...الخ. | C7: The Contractor shall be deemed to have inspected and examined the Site and it's surroundings, and identified, considered and deemed to included all costs related to (carefully)demolition of existing structures, access roads, existing turfs, concrete, flagging, paving, curbing, road-metalling, topsoil, fencing, demolish and seal existing services, protection of existing service lines, accessories etc., and cart away debris, as directed by the Engineer and return of surface to its original conditions. | D7: 1.1
A8: 1.2 | B8: يشمل الهدم وإخلاء الموقع أيضا التخلص من المواد الناتجة وردم الفراغات باستخدام المواد المناسبة ما لم يتم التوجيه بغير ذلك. بالاعتماد على زيارة الموقع والمعلومات المتوفرة، على المتقدم للعطاء أن يشمل فوق سعره تكاليف إزالة المخلفات الملقاة وإزالة طبقات الرصف في الأرصفة والجزر الوسطية... ألخ. والتخلص من المخلفات إلى الأمكان العمومية المسموح بها حسب تعليمات المهندس وإعادة السطح إلى حالته الأصلية باستثناء ما تم قياسه بشكل منفرد أو تم وصفه في مكان آخر. يجب على المتقدم للعطاء أن يشمل في سعره جميع التكاليف الإضافية والناتجة عن إزالة خطوط الخدمات والمياه والكهرباء وصرف مياه الأمطار والصرف الصحي والهاتف ...ألخ. وتعديل مسارها في حال استخدامها من أجل تشغيل مباني قائمة أخرى كما تشمل إعادة السطح إلى حالته الأصلية باستثناء ما تم قياسه بشكل منفرد أو تم وصفه في مكان آخر. | C8: Item for Demolition and Site clearance shall also include disposal of the materials arising and backfilling of voids with suitable material except as otherwise directed. Based on site visit & available information, the tenderer shall allow in above rates for all Removal of dumped rubbish, removal of sidewalk & median pavements etc, and cart away debris, as directed by the Engineer and return of surface to its original conditions , unless otherwise measured separately or specified elsewhere. The tenderer shall allow in his rates for all extra costs for removal of underground utility lines, water, electrical, storm, sanitary, telephone, etc., including return of surface to its original conditions, unless otherwise measured separately or specified elsewhere. as well as ultimate development/design requirements, and to price comprehensively. | D8: 1.2
A9: 1.3 | B9: يتم حساب كميات الأعمال الترابية على أساس صافي الأبعاد الناتجة عن المخططات مع عدم السماح بمخصصات للزيادة أو النقصان أو الإهدار أو مساحات العمل. تشمل أسعار أعمال الحفر الحفاظ على الحفر جافة بالطرق المعتمدة | C9: The quantities of earthworks shall be computed net using dimensions from the Drawings with no allowance for bulking, shrinkage, waste or working space. Rates for excavation shall include for keeping excavations free from water by acceptable means. | D9: 1.3
A10: 1.4 | B10: أسعار الحفر (في مناطق القطع) تشمل تثبيت مستوى السطح النهائي المتكون طبقا للمواصفات. على المتقدمين للمناقصة الرجوع إلى المعلومات والتقارير الجيولوجية المتوفرة بخصوص حالة التربة والقيام باستكشاف الموقع بشكل ملائم للحصول على فهم كامل لحالة الارض و التربة في الموقع قبل وضع الأسعار في جدول الكميات ويجب تضمين أية تكلفة أضافية متعلقة بفحص التربة وبأعمال الحفر. ويتضمن البند الحفر في جميع انواع التربة (ترابية أو صخرية) ما لم يتم قياس الحفر في التربه الصخريه في بند منفصل. | C10: Excavation prices (in cut areas) includes installing the final surface formed according to the specifications. The Tenderers are to refer to the information and geological reports that are available relating to the condition of the soil as well as exploring the site properly to get a full understanding of the status of the land and soil at the site before pricing of the bill of quantities. Rates must include any additional costs related to examination of the soil and excavation work. The item includes excavation in all types of soil (including rocks and hard material that requires special equipment), unless otherwise measured separately or specified elsewhere | D10: 1.4
A11: 1.5 | B11: تعتبر تكاليف أعمال الحفر في مناطق القطع متضمنة لحميع الموارد المطلوبة الإضافية والمصاريف المتعلقة بالحفر لجميع الأعماق ما لم يتم قياسها بشكل منفرد. | C11: Excavation for cuttings; deemed to be included all additional resources and expenses related to various and all depths, unless otherwise measured seperately. | D11: 1.5
A12: 1.6 | B12: تشمل أسعار المواد المستخدمة في الردم من خارج الموقع الحفر في الموقع الخارجي (عند الحاجة) والنقل والتفريغ والدمك في طبقات حسب المواصفات. يجب أن تكون المواد المستوردة من خارج الموقع خالية من أية مواد عضوية أو نفايات أو أتربة سطحية أو صخور... الخ حسب المواصفات وباعتماد المهندس. | C12: The rate for imported fill material shall deemed to include borrow pit excavation, hauling, placement and compaction in layers as specified. Imported material must be free from all organic materials, waste, top soil, rock, etc., as specified, and to approval of the Engineer. | D12: 1.6
A13: 1.7 | B13: لن يتم دفع تكاليف تكديس المواد والمناولة المزدوجة للمواد التي يتم حفرها على أن يتضمنها المقاول في الأسعار المقدمة ما لم يتم قياسها بشكل منفرد. | C13: Stockpiling and Double handling of excavated material shall not be payed seperately and the Contractor shall be deemed to have included in his rates, unless measured seperately. | D13: 1.7
A14: 1.8 | B14: التكاليف الخاصة بقطع وتجهيز الأسطح التي يتم حفرها متضمنة في أسعار الحفر ذات الصلة. | C14: Trimming and preparation of excavated surfaces, are deemed to be included within the relevant excavation rates. | D14: 1.8
A15: 1.10 | B15: التكاليف الخاصة بقطع وتجهيز الأسطح التي تم ردمها متضمنة في أسعار الردم ذات الصلة. | C15: Trimming and preparation of filled surfaces, are deemed to be included within the relevant filling rates. | D15: 1.10
A16: 1.11 | B16: يجب أن تشمل أسعار المتقدم للمناقصة فيما يتعلق بالحفر أية تكاليف إضافية للحفر في أي مواد مثل التربة الترسيبية والرمال والصخور وإجراء الحفر و الردم في أوضاع التربة الغير مناسبة و معالجة التربة و الحفر علي أي أعماق والحفر تحت منسوب المياه العادي والحفر حول المرافق والخدمات القائمة و العمل ضمن مناطق محصورة وعالية الخطورة وإزالة تلك المرافق والخدمات المهملة وغير المستخدمة ودعم الجوانب العمودية ومساحات العمل وردم المناطق غير الثابتة أثناء الحفر ما لم يتم قياسها بشكل منفرد أوما لم ينص على خلاف ذلك. | C16: The tenderer shall allow in his earthworks rates for all extra costs; for excavating in any material including running silt, running sand and rock, additional cut and fill for unsuitable soil conditions, soil treatments, commencing excavation at any depth, excavating below the normal water table, excavating around existing services and mains, working in restricted areas, high risk areas, the removal of dead services , supporting the vertical sides or excavations, working space and filling soft spots , unless otherwise measured separately or specified elsewhere. | D16: 1.11
A17: 1.12 | B17: يجب أن تشمل أسعار المتقدم للمناقصة تكاليف ازالة مواد ناتج الحفر الزائدة الى المقالب العمومية المعتمدة التى تحددها الجهات المختصة | C17: The price of the contractor must include costs for materials disposal to public landfills approved by the competent authorities | D17: 1.12
B18: أعمال الخرسانة | C18: CONCRETE Works
A19: 2.1 | B19: تشمل الأسعار الخاصة بالخرسانة المصبوبة في الموقع توفير الخرسانة وصبها ويشمل ذلك كافة الوصلات وموانع التسرب وخلاطات الخرسانة والأوتاد وأساليب التحكم في الشقوق وملحقات خرسانية والإضافات والتحبيب والأعمال النهائية لتمليس السطح الخ ما لم ينص على خلاف ذلك | C19: The rates inserted for in-situ concrete in all classifications shall include for provision of concrete, and placing of concrete including all joints, water stops, rebates, groves, dowels, crack controls, concrete accessories, inserts, grouting and finishing to top surface, etc, unless otherwise measured separately. | D19: 2.1
A20: 2.2 | B20: تشمل الأسعار الخاصة بالخرسانة العادية الشدات وفي الأركان أو أي أبعاد إضافية للخرسانة طبقا لما يراه المقاول مناسبا | C20: The rates for blinding shall include for shuttering at edges or additional width of concrete at the discretion of the Contractor. | D20: 2.2
A21: 2.3 | B21: تشمل الأسعار الخاصة بالخرسانة لكافة الفئات التجويفات والفراغات وتثبيت البراغي وفتحات التثبيت | C21: The rates for concrete in all classifications shall include for forming mortises and holes, which shall include mortises for holding down bolts and weep holes. | D21: 2.3
A22: 2.4 | B22: تشمل الأسعار الخاصة بالخرسانة المسلحة الشدات بكافة أنواعها وحديد التسليح والخرسانات وكل مايلزم طبقا لما يراه المقاول مناسبا لإنهاء العمل حسب المخططات والمتطلبات الخاصة بالمواصفات. | C22: The rates for reinforcement concrete shall include all type of shuttering ,steel, concrete, as the discretion of the Contractor according to the Drawings and requirements of the Specification.. | D22: 2.4
A23: 2.5 | B23: بما لا يتعارض مع قاعدة القياس M10 يجب أن يتضمن المقاول في أسعاره إنشاء كافة الوصلات التي قد لا تكون موضحة تفصيلا أو موجودة في المخططات والمتطلبات الخاصة بالمواصفات | C23: Notwithstanding measurement rule M10, the Contractor shall be deemed to have included in his rates for all construction joints not expressly detailed or located on the Drawings and requirements of the Specification. | D23: 2.5
A24: 2.6 | B24: بما لا يتعارض مع قاعدة القياس M13 to M16 يجب أن يتضمن المقاول في أسعاره إنشاء كافة الملحقات الخرسانية التي قد لا تكون موضحة تفصيلا أو موجودة في المخططات والمتطلبات الخاصة بالمواصفات | C24: Notwithstanding measurement rule M13 to M16, the Contractor shall be deemed to have included in his rates for all concrete accessories not expressly detailed or located on the Drawings and requirements of the Specification. | D24: 2.6
A25: 2.7 | B25: تشمل الأسعار الخاصة بالدعامات أعمال الثني والتمليس والقطع المنحني وأسلاك الربط واللفات والكتل والجلسات والفواصل | C25: The rates for reinforcement shall include for bending, raking and curved cutting, notching, tying wire, laps, distance blocks, chairs and spacers. | D25: 2.7
A26: 2.8 | B26: تشمل الأسعار الخاصة بالخرسانة سابقة التجهيز الشدات أو القوالب والتشكيل ومواد الوصلات وفواصل التغطية ومواد التبطين مقاومة للمياه وأغطية خاصة ووصلات خاصة بين الوحدات وهياكل وروابط وصبات وأي وسائل تثبيت أخرى وتمليس وتشطيب مسبق ونهائي | C26: The rates for pre-cast concrete shall include shuttering or moulds, bedding, pointing, expansion material, cover strips, damp proof membranes, special sealing and special pointing between Units and Units and structure, anchor bolts, casting, other fixing devices, grouting and pre & final finishes | D26: 2.8
A27: 2.9 | B27: تشمل عناصر الخرسانة سابقة التجهيز كافة التكاليف المرتبطة بالتصنيع والتوريد والنقل للموقع والتفريغ والتخزين في الموقع وتكلفة كافة العمليات في الموقع من النقل والصب والتركيب بما فيها أجور الكرينات (الونش)وتنفيذ الأعمال على أكمل وجه وتشمل اختبارات الأنظمة بالمصنع والموقع والانظمة النهائية وبدء التنفيذ والصيانة والتأمين على المعدات في الموقع الخ طبقا للمخططات والمواصفات | C27: Pre-cast concrete components shall include for all costs associated with manufacture, supply, transportation to site, offloading, on-site storage, the cost of all operations at the site, site transportation, erection and installation, setting to work, including factory, site and final system tests and for commissioning, maintenance and insurance of the equipment on site, etc., all as specified and according to drawings | D27: 2.9
A28: 2.10 | B28: تشمل الأسعار الخاصة بصب الخرسانة والأعمال الترابية والخرسانة العادية والشدات وأعمال المبانى وأعمال التشطيبات النهائية وكافة الأعمال المدنية الضرورية ما لم يتم قياسها بشكل منفصل | C28: The rate for placing of concrete deemed to be including , earthworks, blinding, steps, masonry, concreting, final finishes and all other civil works as necessary, unless measured separately | D28: 2.10
A29: 2.11 | B29: أعمال البردورات مسبقة الصب وتشمل صب خرسانة الأساسات بالموقع، المونة الأسمنتية ، التسليح ، الحفر ، الردم ، الدمك ، الدهانات والتخلص من المخلفات وانهاء الأعمال على النحو المطلوب طبقاً لمعايير الجهات المختصة والمواصفات والمخططات التصميمية. | C29: Pre-cast concrete kerbs including in-situ concrete foundation, hunching, cement mortar, dowel bars, jointed and pointed in mortar, excavation, filling, compaction, disposal including painting and final finishes etc., all in accordance with authority standards and complete as per specifications and drawings | D29: 2.11
A30: 2.12 | B30: أعمال القواعد الخرسانية لأعمدة الإنارة واللواحات والمرورية والإرشادية تعتبر متضمّنة | C30: RCC foundations for light poles and traffic signs are considered part of the main items | D30: 2.12
B31: أعمال المواسير والتركيبات والصمامات | C31: PIPEWORK , PIPES AND FITTINGS AND VALVES
A32: 3.1 | B32: أعمال المواسير: | C32: Pipeworks: | D32: 3.1
B33: يشمل قياس أعمال المواسيرما يلي: - توريد و تشوين المواسير والقطع الخاصة - الحفر في جميع أنواع التربة (الترابية والصخرية) وإعداد الأسطح وإزالة المخلفات و يشمل تدعيم الجوانب الخاصة بالحفر وإزالة المرافق والخدمات المهملة وغير المستخدمة و نزح المياه - تركيب المواسير والقطع الخاصة في الخنادق المخصصة شاملا طبقه الأساس تحت المواسير و الطبقة المحيطة و الشريط التحذيري - الردم ويشمل الدمك باستخدام المواد المعتمدة طبقا للإجراءات الخاصة بالجهات المختصة - الحماية والدعامات الخرسانية (ان وجدت) وفقا للرسومات و المواصفات -جميع الاعمال اللازمه لربط الشبكات الجديده علي الشبكات القائمه وعمل كافة الاختبارات اللازمه وإعاده الوضع كما كان عليه وكافة الاعمال اللازمة لأتمام البند الحماية الخاصة للمرافق والخدمات المجاورة أو الطبقات المتعددة من المواسير - الاختبارات والتنظيف النهائي والغسيل والتعقيم - جميع الاعمال اللازمة لإنهاء تركيب المواسير. - جميع الاعمال يتم تنفيذها وفقا للرسومات و المواصفات الفنيه. | C33: The rate for pipeworks shall include the following: - supply and storage of pipes and special parts. - excavation in all types of soil (including rock), surface preparation, demlition, upholding the vertical sides of excavations, the removal of dead services, and dewatering. - installation of pipes and special parts in the proposed trenches including the foundation layer under pipes and the surrounding layer and caution tape. - Backfilling including compaction with approved materials all in accordance with authority regulations. - Concrete Stools and Thrust Blocks (if any) indicated in the relevant drawings and specifications. -All necessary items to interface between the new networks and the existing networks, all necessary testing, return of surface to its original conditions.and all other items to complete this item. - Special protection for utilities adjacent or multiple pipe laying, and pipe supports. - Commissioning, final cleaning, flushing and sterilisation of works. - All the works required to complete the installation of pipes. - All the works shall be in accordance with the Drawings and Specifications.
A34: 3.2 | B34: أعمال غرف المحابس و المطابق: | C34: Valve Chambers and Manholes: | D34: 3.2
B35: يشمل قياس أعمال غرف المحابس و المطابق ما يلي: - توريد المواسير والقطع الخاصة - الحفر في جميع أنواع التربة (الترابية والصخرية) وإعداد الأسطح وإزالة المخلفات ويشمل تدعيم الجوانب الخاصة بالحفر وإزالة المرافق والخدمات المهملة وغير المستخدمة و نزح المياه. - جميع الاعمال الخرسانية و تشمل الاساسات و الحوائط و الاسقف و الكراسى والدعمات الخرسانية وكتل التثبيت الخرسانية وكافة المتطلبات طبقا للمخططات والمواصفات ذات الصلة مثل دهان بيتوميني وطبقات نيوبرين.....الخ. - أعمال البناء وفرشة المونة وأعمال مقاومة المياه والدرج والاغطيه والإطارات ,و سلسله الدعم و السلامة وجميع الوصلات. - تركيب المواسير والقطع الخاصه - الحماية الخاصة للمرافق والخدمات المجاورة أو الطبقات المتعددة من المواسير - الاختبارات والتنظيف النهائي والغسيل والتعقيم - جميع الاعمال اللازمه لانهاء غرف المحابس و تركيب المواسير. - جميع الاعمال يتم تنفيذها وفقا للرسومات و المواصفات الفنيه | C35: The rate for Valve Chambers and Manholes shall include the following: - supply of pipes and special parts. - excavation in all types of soil (including rock), surface preparation, demlition, upholding the vertical sides of excavations, the removal of dead services, and dewatering. - All the concrete works including foundation, walls, slabs, stools, and thrust blocks and all the requirements in accordance with the Drawings and Soecifications such as bituminous coat, neoprene layer, etc. - All the civil works, mortar, waterproofing, stairs, covers, frames and chainlinks. - installation of pipes and special parts. - Special protection for utilities adjacent or multiple pipe laying, and pipe supports. - Commissioning, final cleaning, flushing and sterilisation of works. - All the works required to complete the installation of valve chambers and manholes. - All the works shall be in accordance with the Drawings and Soecifications.
A36: 3.3 | B36: حنفيات الحريق | C36: Fire Hydrants | D36: 3.3
B37: تشمل تكلفة حنفيات الحريق ما يلي: - توريد حنفيات الحريق والصمامات و المواسير والقطع الخاصة - الحفر في جميع أنواع التربة (الترابية والصخرية) وإعداد الأسطح وإزالة المخلفات ويشمل تدعيم الجوانب الخاصة بالحفر وإزالة المرافق والخدمات المهملة وغير المستخدمة و نزح المياه. - كافة أعمال تركيب المواسير والصمامات وصناديق الصمامات وملحقاتها وحواجز التأمين والتركيبات اللازمة والملحقات وأعمال البناء. - جميع الاعمال اللازمه لانهاء تركيب حنفيات الحريق. - جميع الاعمال يتم تنفيذها وفقا للرسومات و المواصفات الفنيه | C37: The rate for fire hydrants shall include the following: - Supply of fire hydrants, valves, pipes and special parts. - Excavation in all types of soil (including rock), surface preparation, demlition, upholding the vertical sides of excavations, the removal of dead services, and dewatering. - All the works required for pipework, valves, surface boxes, accessories, protection barricades, necessary fittings, and accessories, and civil works, - All the works required to complete the installation of fire hydrants. - All the works shall be in accordance with the Drawings and Specifications.
A38: 3.4 | B38: الصمامات المردومة | C38: Buried Valves | D38: 3.4
B39: تشمل تكلفة الصمامات المردومة ما يلي: - توريد الصمامات و المواسير والقطع الخاصة - الحفر في جميع أنواع التربة (الترابية والصخرية) وإعداد الأسطح وإزالة المخلفات ويشمل تدعيم الجوانب الخاصة بالحفر وإزالة المرافق والخدمات المهملة وغير المستخدمة و نزح المياه. - كافة أعمال تركيب المواسير والصمامات وصناديق الصمامات وملحقاتها وحواجز التأمين والتركيبات اللازمة والملحقات وأعمال البناء. - جميع الاعمال اللازمه لانهاء تركيب المحابس. - جميع الاعمال يتم تنفيذها وفقا للرسومات و المواصفات الفنيه | C39: The rate for buried valves shall include the following: - Supply of fire hydrants, valves, pipes and special parts. - Excavation in all types of soil (including rock), surface preparation, demlition, upholding the vertical sides of excavations, the removal of dead services, and dewatering. - All the works required for pipework, valves, surface boxes, accessories, protection barricades, necessary fittings, and accessories, and civil works, - All the works required to complete the installation of buried valves. - All the works shall be in accordance with the Drawings and Specifications.
A40: 3.5 | B40: يعد سطح التسوية هو سطح بداية العمل لأعمال المواسير والعمق المذكور مقاس من سطح التسوية حتى منسوب قاع المواسير. | C40: The "Grading level" shall be considered as "Commencing Surface" for pipes , the mentioned depth is from grading level to the pipe invert level. | D40: 3.5
A41: 3.6 | B41: يعد العمق المذكور لأعمال المناهل وغرف المحابس هو العمق المقاس من أعلى الغطاء حتى منسوب قاع المانهول / الغرفة | C41: The mentioned depth for manholes and valve chambers shall be considered from the top of cover to the manhole/chamber bottom | D41: 3.6
A42: 3.7 | B42: الفواصل وأعمال حقن الخرسانة للمواسير داخل العبارات/ مناطق القطع تكون مشمولة ضمن أسعار المواسير كما يجب أن تشمل إعادة الشئ لأصله المانهولات والغرف الأخرى | C42: Spacers and grouting for pipes within ducts/crossings deemed to be included within pipes rates. Additional reinstatement shall be deemed to include for manholes and other chambers. | D42: 3.7
...

Sheet P.1
A1: =Cover1!B12 -> اسم المشروع: تطوير شبكات البنية التحتية في المدينة الصناعية بالخرج | H1: =Cover1!J12 -> Development of Infrastructure in Kharj Industrial City
A2: جدول الكميات | H2: BILL OF QUANTITIES
A4: البند | B4: وصف البند | C4: الوحدة | D4: الكمية | E4: السعر (ريال سعودي) | F4: المبلغ (ريال سعودي) | G4: ITEM DESCRIPTION | H4: ITEM
C5: Unit | D5: QUANTITY | E5: PRICE (S.R) | F5: AMOUNT (S.R)
A6: أعمال الطرق | G6: ROAD WORKS
A7: =H7 -> 02 41 00 | B7: أعمال الهدم | G7: DEMOLITION | H7: 02 41 00
A8: =H8 -> B1.02 41 00.1 | B8: إزالة أسفلت قائم | C8: m2 | D8: 2200 | E8: 9 | F8: =E8*D8 -> 19800 | G8: Demolition of existing Asphalt | H8: B1.02 41 00.1
A9: =H9 -> B1.02 41 00.2 | B9: اعداد طبقة الاساس الحصوي القائمة | C9: m2 | D9: 2200 | E9: 5 | F9: =E9*D9 -> 11000 | G9: Compaction of existing aggregate base course layer | H9: B1.02 41 00.2
A10: =H10 -> B1.02 41 00.3 | B10: إزالة بردورات قائمه | C10: m | D10: 464 | E10: 12 | F10: =E10*D10 -> 5568 | G10: Demolition of existing Kerbs | H10: B1.02 41 00.3
A11: =H11 -> 31 22 00 | B11: الأعمال الترابية و التسوية | D11: 0 | G11: EARTHWORKS AND SITE GRADING | H11: 31 22 00
A12: =H12 -> B1.31 22 00.01 | B12: حفريات الطرق | C12: m3 | D12: 205106 | E12: 14 | F12: =E12*D12 -> 2871484 | G12: Excavation for cuttings | H12: B1.31 22 00.01
A13: =H13 -> B1.31 22 00.02 | B13: ردميات الطرق | C13: m3 | D13: 1378709 | E13: 20 | F13: =E13*D13 -> 27574180 | G13: Fill to the roads | H13: B1.31 22 00.02
A14: =H14 -> B1.31 22 00.03 | B14: طبقة القاعدة | C14: m3 | D14: 222337 | E14: 18 | F14: =E14*D14 -> 4002066 | G14: Subgrade | H14: B1.31 22 00.03
A15: =H15 -> 32 11 23 | B15: طبقة أساس حصوية | D15: 0 | G15: AGGREGATE BASE COURSE | H15: 32 11 23
A16: =H16 -> B1.32 11 23.01 | B16: طبقة أساس حصوية | C16: m3 | D16: 145216 | E16: 65 | F16: =E16*D16 -> 9439040 | G16: Aggregate base course | H16: B1.32 11 23.01
A17: =H17 -> 32 11 26 | B17: الإنشاء البيتوميني | D17: 0 | G17: BITUMINOUS CONSTRUCTION | H17: 32 11 26
A18: =H18 -> B1.32 11 26.02 | B18: الطبقة الأساس البيتومينية (تدرج 1 - صنف أ)، شاملاً الطبقة اللاصقة (MC1) & (RC2) . | C18: m3 | D18: 63389 | E18: 642 | F18: =E18*D18 -> 40695738 | G18: Bituminous base course (Grading I - Class A), including Prime Coat (MC1) & (RC2). | H18: B1.32 11 26.02
A19: =H19 -> 32 12 16 | B19: طبقة السطح العليا | D19: 0 | G19: ASPHALT WEARING COURSE | H19: 32 12 16
A20: =H20 -> B1.32 12 16.01 | B20: طبقة السطح العليا من الخرسانة البيتومينية (تدرج 1 - صنف أ) شاملاً الطبقة اللاصقة (RC2) . | C20: m3 | D20: 36304 | E20: 648 | F20: =E20*D20 -> 23524992 | G20: Bituminous concrete wearing course, (Grading I - Class A), including tack coat (RC2). | H20: B1.32 12 16.01
A21: =H21 -> 32 14 13 | B21: بردورات مسبقة الصب | D21: 0 | G21: PRECAST CONCRETE CURB | H21: 32 14 13
A22: =H22 -> B1.32 14 13.01 | B22: بردورات نوع (K1A) | C22: m | D22: 79448 | E22: 65 | F22: =E22*D22 -> 5164120 | G22: Concrete curb, Type (K1A) | H22: B1.32 14 13.01
A23: =H23 -> B1.32 14 13.02 | B23: بردورات نوع (K1B) | C23: m | D23: 21624 | E23: 60 | F23: =E23*D23 -> 1297440 | G23: Concrete curb, Type (K1B) | H23: B1.32 14 13.02
A24: =H24 -> B1.32 14 13.03 | B24: بردورات نوع (K2) | C24: m | D24: 2755 | E24: 63 | F24: =E24*D24 -> 173565 | G24: Concrete curb, Type (K2) | H24: B1.32 14 13.03
B32: يتم ترحيل الطرق - إلى التجميع | C32: ريال سعودي | F32: =SUM(F8:F24) -> 114778993 | G32: CARRIED TO ROADS - COLLECTION
A33: =H33 -> 32 17 23 | B33: العلامات الأرضية | G33: PAVEMENT MARKINGS | H33: 32 17 23
A34: =H34 -> 32 17 23.01 | B34: دهان ثرموبلاستيك (أبيض / أصفر) | G34: Thermoplastic pavement marking (White/Yellow) | H34: 32 17 23.01
A35: =H35 -> B1.32 17 23.01.01 | B35: دهانات مرورية بيضاء عاكسة بلاستيكية حرارية | C35: m² | D35: 18149 | E35: 41 | F35: =E35*D35 -> 744109 | G35: Retroreflective Thermoplastic White Traffic | H35: B1.32 17 23.01.01
A36: =H36 -> B1.32 17 23.01.02 | B36: دهانات مرورية صفراء عاكسة بلاستيكية حرارية | C36: m² | D36: 11771 | E36: 41 | F36: =E36*D36 -> 482611 | G36: Retroreflective Thermoplastic Yellow Traffic | H36: B1.32 17 23.01.02
A37: =H37 -> 10 14 53 | B37: اللوحات الإرشادية للطرق | D37: 0 | G37: TRAFFIC SIGNAGE | H37: 10 14 53
A38: =H38 -> B1.10 14 53.01 | B38: لوحات مرورية المثبتة بالأرض مصنوعة من ألواح ألومنيوم مع حواملها القابلة للإنفصال بالقاعدة مكونة من لوحة مروريه وعمود واحد مع كافة الاكسسورات وكل ما يلزم حسب المخططات والمواصفات. | C38: Unit | D38: 482 | E38: 1065 | F38: =E38*D38 -> 513330 | G38: Traffic signs, ground mounted, 1 Sheet Alumenium, (breakaway) Single post, with all accessories according to the drawings and specifications. | H38: B1.10 14 53.01
A39: =H39 -> B1.10 14 53.02 | B39: لوحات مرورية المثبتة بالأرض مصنوعة من ألواح ألومنيوم مع حواملها القابلة للإنفصال بالقاعدة مكونة من لوحتين مروريتين وعمود واحد مع كافة الاكسسورات وكل ما يلزم حسب المخططات والمواصفات. | C39: Unit | D39: 275 | E39: 1597 | F39: =E39*D39 -> 439175 | G39: Traffic signs, ground mounted, 2 Sheet Alumenium, (breakaway) Single post, with all accessories according to the drawings and specifications. | H39: B1.10 14 53.02
A40: =H40 -> B1.10 14 53.03 | B40: لوحات مرورية مصنوعة من ألواح الإلمنيوم مع حواملها (قابلة للانفصال بالقاعدة) مكونة من لوحه مروريه وعمودين مع كافات الاكسسورات، وكل ما يلزم حسب المخططات والمواصفات. | C40: Unit | D40: 45 | E40: 2070 | F40: =E40*D40 -> 93150 | G40: Traffic signs, ground mounted, Sheet Alumenium, (breakaway) Double post with all accessories according to the drawings and specifications. | H40: B1.10 14 53.03
A41: =H41 -> B1.10 14 53.04 | B41: علامات أرضية بارزة عاكسة (نوع - أ) | C41: Unit | D41: 500 | E41: 30 | F41: =E41*D41 -> 15000 | G41: Retroreflective raised pavement markers (Type A) | H41: B1.10 14 53.04
A42: =H42 -> B1.10 14 53.05 | B42: علامات أرضية بارزة مصنوعة من السيراميك | C42: Unit | D42: 500 | E42: 12 | F42: =E42*D42 -> 6000 | G42: Ceramic raised pavement markers | H42: B1.10 14 53.05
A43: =H43 -> B1.10 14 53.06 | B43: علامات أرضية مضيئة تعمل بالطاقة الشمسية (عيون القط) | C43: Unit | D43: 500 | E43: 166 | F43: =E43*D43 -> 83000 | G43: Solar powered lighting cateyes pavement markers | H43: B1.10 14 53.06
F44: =E44+D44 -> 0
F45: =E45+D45 -> 0
F46: =E46+D46 -> 0
F50: =E50+D50 -> 0
F52: =E52+D52 -> 0
...

Sheet Cover2
B4: مدن | J4: MODON
B5: الهيئة السعودية للمدن الصناعية ومناطق التقنية | J5: SAUDI AUTHORITY FOR INDUSTRIAL CITIES AND TECHNOLOGY ZONES
B12: ='General Summary '!D3 -> اسم المشروع: تطوير شبكات البنية التحتية في المدينة الصناعية بالخرج | J12: ='General Summary '!C3 -> Development of Infrastructure in Kharj Industrial City
B13: المرحلة A | J13: Phase A
B17: البنية التحتية والخدمات | J17: INFRASTRUCTURE AND UTILITIES
B21: جدول الكميات | J21: BILL OF QUANTITIES
B26: نوفمبر 2025 | J26: 45972

Sheet Preamble2
A1: اسم المشروع: تطوير شبكات البنية التحتية في المدينة الصناعية بالخرج | D1: =Cover2!J12 -> Development of Infrastructure in Kharj Industrial City
A2: جدول الكميات | D2: BILL OF QUANTITIES
B5: مقدمة البنود - مكونات البنود | C5: ITEMS PREAMBLE - ITEMS CONTENTS
B6: أعمال الموقع والأعمال الترابية | C6: Site and Earth Works
A7: 1.1 | B7: يعتبر المقاول من خلال زيارته للموقع بأنه قام بفحص واستكشاف الموقع ومحيطه وأنه قام بتحديد والأخذ بعين الاعتبار عند إعطاء أسعاره كافة التكاليف الإضافية المتعلقة بهدم (بشكل حذر) المنشآت القائمة وطرق الوصول إلى الموقع وإزالة طبقات الأعشاب الموجودة والخرسانة والأرصفة وطبقات الرصف والاسفلت وأحجار الارصفة و التربة العلوية والسياج وحماية خطوط الخدمات القائمة وكافة ملحقاتها...الخ. | C7: The Contractor shall be deemed to have inspected and examined the Site and it's surroundings, and identified, considered and deemed to included all costs related to (carefully)demolition of existing structures, access roads, existing turfs, concrete, flagging, paving, curbing, road-metalling, topsoil, fencing, demolish and seal existing services, protection of existing service lines, accessories etc., and cart away debris, as directed by the Engineer and return of surface to its original conditions. | D7: 1.1
A8: 1.2 | B8: يشمل الهدم وإخلاء الموقع أيضا التخلص من المواد الناتجة وردم الفراغات باستخدام المواد المناسبة ما لم يتم التوجيه بغير ذلك. بالاعتماد على زيارة الموقع والمعلومات المتوفرة، على المتقدم للعطاء أن يشمل فوق سعره تكاليف إزالة المخلفات الملقاة وإزالة طبقات الرصف في الأرصفة والجزر الوسطية... ألخ. والتخلص من المخلفات إلى الأمكان العمومية المسموح بها حسب تعليمات المهندس وإعادة السطح إلى حالته الأصلية باستثناء ما تم قياسه بشكل منفرد أو تم وصفه في مكان آخر. يجب على المتقدم للعطاء أن يشمل في سعره جميع التكاليف الإضافية والناتجة عن إزالة خطوط الخدمات والمياه والكهرباء وصرف مياه الأمطار والصرف الصحي والهاتف ...ألخ. وتعديل مسارها في حال استخدامها من أجل تشغيل مباني قائمة أخرى كما تشمل إعادة السطح إلى حالته الأصلية باستثناء ما تم قياسه بشكل منفرد أو تم وصفه في مكان آخر. | C8: Item for Demolition and Site clearance shall also include disposal of the materials arising and backfilling of voids with suitable material except as otherwise directed. Based on site visit & available information, the tenderer shall allow in above rates for all Removal of dumped rubbish, removal of sidewalk & median pavements etc, and cart away debris, as directed by the Engineer and return of surface to its original conditions , unless otherwise measured separately or specified elsewhere. The tenderer shall allow in his rates for all extra costs for removal of underground utility lines, water, electrical, storm, sanitary, telephone, etc., including return of surface to its original conditions, unless otherwise measured separately or specified elsewhere. as well as ultimate development/design requirements, and to price comprehensively. | D8: 1.2
A9: 1.3 | B9: يتم حساب كميات الأعمال الترابية على أساس صافي الأبعاد الناتجة عن المخططات مع عدم السماح بمخصصات للزيادة أو النقصان أو الإهدار أو مساحات العمل. تشمل أسعار أعمال الحفر الحفاظ على الحفر جافة بالطرق المعتمدة | C9: The quantities of earthworks shall be computed net using dimensions from the Drawings with no allowance for bulking, shrinkage, waste or working space. Rates for excavation shall include for keeping excavations free from water by acceptable means. | D9: 1.3
A10: 1.4 | B10: أسعار الحفر (في مناطق القطع) تشمل تثبيت مستوى السطح النهائي المتكون طبقا للمواصفات. على المتقدمين للمناقصة الرجوع إلى المعلومات والتقارير الجيولوجية المتوفرة بخصوص حالة التربة والقيام باستكشاف الموقع بشكل ملائم للحصول على فهم كامل لحالة الارض و التربة في الموقع قبل وضع الأسعار في جدول الكميات ويجب تضمين أية تكلفة أضافية متعلقة بفحص التربة وبأعمال الحفر. ويتضمن البند الحفر في جميع انواع التربة (ترابية أو صخرية) ما لم يتم قياس الحفر في التربه الصخريه في بند منفصل. | C10: Excavation prices (in cut areas) includes installing the final surface formed according to the specifications. The Tenderers are to refer to the information and geological reports that are available relating to the condition of the soil as well as exploring the site properly to get a full understanding of the status of the land and soil at the site before pricing of the bill of quantities. Rates must include any additional costs related to examination of the soil and excavation work. The item includes excavation in all types of soil (including rocks and hard material that requires special equipment), unless otherwise measured separately or specified elsewhere | D10: 1.4
A11: 1.5 | B11: تعتبر تكاليف أعمال الحفر في مناطق القطع متضمنة لحميع الموارد المطلوبة الإضافية والمصاريف المتعلقة بالحفر لجميع الأعماق ما لم يتم قياسها بشكل منفرد. | C11: Excavation for cuttings; deemed to be included all additional resources and expenses related to various and all depths, unless otherwise measured seperately. | D11: 1.5
A12: 1.6 | B12: تشمل أسعار المواد المستخدمة في الردم من خارج الموقع الحفر في الموقع الخارجي (عند الحاجة) والنقل والتفريغ والدمك في طبقات حسب المواصفات. يجب أن تكون المواد المستوردة من خارج الموقع خالية من أية مواد عضوية أو نفايات أو أتربة سطحية أو صخور... الخ حسب المواصفات وباعتماد المهندس. | C12: The rate for imported fill material shall deemed to include borrow pit excavation, hauling, placement and compaction in layers as specified. Imported material must be free from all organic materials, waste, top soil, rock, etc., as specified, and to approval of the Engineer. | D12: 1.6
A13: 1.7 | B13: لن يتم دفع تكاليف تكديس المواد والمناولة المزدوجة للمواد التي يتم حفرها على أن يتضمنها المقاول في الأسعار المقدمة ما لم يتم قياسها بشكل منفرد. | C13: Stockpiling and Double handling of excavated material shall not be payed seperately and the Contractor shall be deemed to have included in his rates, unless measured seperately. | D13: 1.7
A14: 1.8 | B14: التكاليف الخاصة بقطع وتجهيز الأسطح التي يتم حفرها متضمنة في أسعار الحفر ذات الصلة. | C14: Trimming and preparation of excavated surfaces, are deemed to be included within the relevant excavation rates. | D14: 1.8
A15: 1.10 | B15: التكاليف الخاصة بقطع وتجهيز الأسطح التي تم ردمها متضمنة في أسعار الردم ذات الصلة. | C15: Trimming and preparation of filled surfaces, are deemed to be included within the relevant filling rates. | D15: 1.10
A16: 1.11 | B16: يجب أن تشمل أسعار المتقدم للمناقصة فيما يتعلق بالحفر أية تكاليف إضافية للحفر في أي مواد مثل التربة الترسيبية والرمال والصخور وإجراء الحفر و الردم في أوضاع التربة الغير مناسبة و معالجة التربة و الحفر علي أي أعماق والحفر تحت منسوب المياه العادي والحفر حول المرافق والخدمات القائمة و العمل ضمن مناطق محصورة وعالية الخطورة وإزالة تلك المرافق والخدمات المهملة وغير المستخدمة ودعم الجوانب العمودية ومساحات العمل وردم المناطق غير الثابتة أثناء الحفر ما لم يتم قياسها بشكل منفرد أوما لم ينص على خلاف ذلك. | C16: The tenderer shall allow in his earthworks rates for all extra costs; for excavating in any material including running silt, running sand and rock, additional cut and fill for unsuitable soil conditions, soil treatments, commencing excavation at any depth, excavating below the normal water table, excavating around existing services and mains, working in restricted areas, high risk areas, the removal of dead services , supporting the vertical sides or excavations, working space and filling soft spots , unless otherwise measured separately or specified elsewhere. | D16: 1.11
A17: 1.12 | B17: يجب أن تشمل أسعار المتقدم للمناقصة تكاليف ازالة مواد ناتج الحفر الزائدة الى المقالب العمومية المعتمدة التى تحددها الجهات المختصة | C17: The price of the contractor must include costs for materials disposal to public landfills approved by the competent authorities | D17: 1.12
B18: أعمال الخرسانة | C18: CONCRETE Works
A19: 2.1 | B19: تشمل الأسعار الخاصة بالخرسانة المصبوبة في الموقع توفير الخرسانة وصبها ويشمل ذلك كافة الوصلات وموانع التسرب وخلاطات الخرسانة والأوتاد وأساليب التحكم في الشقوق وملحقات خرسانية والإضافات والتحبيب والأعمال النهائية لتمليس السطح الخ ما لم ينص على خلاف ذلك | C19: The rates inserted for in-situ concrete in all classifications shall include for provision of concrete, and placing of concrete including all joints, water stops, rebates, groves, dowels, crack controls, concrete accessories, inserts, grouting and finishing to top surface, etc, unless otherwise measured separately. | D19: 2.1
A20: 2.2 | B20: تشمل الأسعار الخاصة بالخرسانة العادية الشدات وفي الأركان أو أي أبعاد إضافية للخرسانة طبقا لما يراه المقاول مناسبا | C20: The rates for blinding shall include for shuttering at edges or additional width of concrete at the discretion of the Contractor. | D20: 2.2
A21: 2.3 | B21: تشمل الأسعار الخاصة بالخرسانة لكافة الفئات التجويفات والفراغات وتثبيت البراغي وفتحات التثبيت | C21: The rates for concrete in all classifications shall include for forming mortises and holes, which shall include mortises for holding down bolts and weep holes. | D21: 2.3
A22: 2.4 | B22: تشمل الأسعار الخاصة بالخرسانة المسلحة الشدات بكافة أنواعها وحديد التسليح والخرسانات وكل مايلزم طبقا لما يراه المقاول مناسبا لإنهاء العمل حسب المخططات والمتطلبات الخاصة بالمواصفات. | C22: The rates for reinforcement concrete shall include all type of shuttering ,steel, concrete, as the discretion of the Contractor according to the Drawings and requirements of the Specification.. | D22: 2.4
A23: 2.5 | B23: بما لا يتعارض مع قاعدة القياس M10 يجب أن يتضمن المقاول في أسعاره إنشاء كافة الوصلات التي قد لا تكون موضحة تفصيلا أو موجودة في المخططات والمتطلبات الخاصة بالمواصفات | C23: Notwithstanding measurement rule M10, the Contractor shall be deemed to have included in his rates for all construction joints not expressly detailed or located on the Drawings and requirements of the Specification. | D23: 2.5
A24: 2.6 | B24: بما لا يتعارض مع قاعدة القياس M13 to M16 يجب أن يتضمن المقاول في أسعاره إنشاء كافة الملحقات الخرسانية التي قد لا تكون موضحة تفصيلا أو موجودة في المخططات والمتطلبات الخاصة بالمواصفات | C24: Notwithstanding measurement rule M13 to M16, the Contractor shall be deemed to have included in his rates for all concrete accessories not expressly detailed or located on the Drawings and requirements of the Specification. | D24: 2.6
A25: 2.7 | B25: تشمل الأسعار الخاصة بالدعامات أعمال الثني والتمليس والقطع المنحني وأسلاك الربط واللفات والكتل والجلسات والفواصل | C25: The rates for reinforcement shall include for bending, raking and curved cutting, notching, tying wire, laps, distance blocks, chairs and spacers. | D25: 2.7
A26: 2.8 | B26: تشمل الأسعار الخاصة بالخرسانة سابقة التجهيز الشدات أو القوالب والتشكيل ومواد الوصلات وفواصل التغطية ومواد التبطين مقاومة للمياه وأغطية خاصة ووصلات خاصة بين الوحدات وهياكل وروابط وصبات وأي وسائل تثبيت أخرى وتمليس وتشطيب مسبق ونهائي | C26: The rates for pre-cast concrete shall include shuttering or moulds, bedding, pointing, expansion material, cover strips, damp proof membranes, special sealing and special pointing between Units and Units and structure, anchor bolts, casting, other fixing devices, grouting and pre & final finishes | D26: 2.8
A27: 2.9 | B27: تشمل عناصر الخرسانة سابقة التجهيز كافة التكاليف المرتبطة بالتصنيع والتوريد والنقل للموقع والتفريغ والتخزين في الموقع وتكلفة كافة العمليات في الموقع من النقل والصب والتركيب بما فيها أجور الكرينات (الونش)وتنفيذ الأعمال على أكمل وجه وتشمل اختبارات الأنظمة بالمصنع والموقع والانظمة النهائية وبدء التنفيذ والصيانة والتأمين على المعدات في الموقع الخ طبقا للمخططات والمواصفات | C27: Pre-cast concrete components shall include for all costs associated with manufacture, supply, transportation to site, offloading, on-site storage, the cost of all operations at the site, site transportation, erection and installation, setting to work, including factory, site and final system tests and for commissioning, maintenance and insurance of the equipment on site, etc., all as specified and according to drawings | D27: 2.9
A28: 2.10 | B28: تشمل الأسعار الخاصة بصب الخرسانة والأعمال الترابية والخرسانة العادية والشدات وأعمال المبانى وأعمال التشطيبات النهائية وكافة الأعمال المدنية الضرورية ما لم يتم قياسها بشكل منفصل | C28: The rate for placing of concrete deemed to be including , earthworks, blinding, steps, masonry, concreting, final finishes and all other civil works as necessary, unless measured separately | D28: 2.10
A29: 2.11 | B29: أعمال البردورات مسبقة الصب وتشمل صب خرسانة الأساسات بالموقع، المونة الأسمنتية ، التسليح ، الحفر ، الردم ، الدمك ، الدهانات والتخلص من المخلفات وانهاء الأعمال على النحو المطلوب طبقاً لمعايير الجهات المختصة والمواصفات والمخططات التصميمية. | C29: Pre-cast concrete kerbs including in-situ concrete foundation, hunching, cement mortar, dowel bars, jointed and pointed in mortar, excavation, filling, compaction, disposal including painting and final finishes etc., all in accordance with authority standards and complete as per specifications and drawings | D29: 2.11
A30: 2.12 | B30: أعمال القواعد الخرسانية لأعمدة الإنارة واللواحات والمرورية والإرشادية تعتبر متضمّنة | C30: RCC foundations for light poles and traffic signs are considered part of the main items | D30: 2.12
B31: أعمال المواسير والتركيبات والصمامات | C31: PIPEWORK , PIPES AND FITTINGS AND VALVES
A32: 3.1 | B32: أعمال المواسير: | C32: Pipeworks: | D32: 3.1
B33: يشمل قياس أعمال المواسيرما يلي: - توريد و تشوين المواسير والقطع الخاصة - الحفر في جميع أنواع التربة (الترابية والصخرية) وإعداد الأسطح وإزالة المخلفات و يشمل تدعيم الجوانب الخاصة بالحفر وإزالة المرافق والخدمات المهملة وغير المستخدمة و نزح المياه - تركيب المواسير والقطع الخاصة في الخنادق المخصصة شاملا طبقه الأساس تحت المواسير و الطبقة المحيطة و الشريط التحذيري - الردم ويشمل الدمك باستخدام المواد المعتمدة طبقا للإجراءات الخاصة بالجهات المختصة - الحماية والدعامات الخرسانية (ان وجدت) وفقا للرسومات و المواصفات -جميع الاعمال اللازمه لربط الشبكات الجديده علي الشبكات القائمه وعمل كافة الاختبارات اللازمه وإعاده الوضع كما كان عليه وكافة الاعمال اللازمة لأتمام البند الحماية الخاصة للمرافق والخدمات المجاورة أو الطبقات المتعددة من المواسير - الاختبارات والتنظيف النهائي والغسيل والتعقيم - جميع الاعمال اللازمة لإنهاء تركيب المواسير. - جميع الاعمال يتم تنفيذها وفقا للرسومات و المواصفات الفنيه. | C33: The rate for pipeworks shall include the following: - supply and storage of pipes and special parts. - excavation in all types of soil (including rock), surface preparation, demlition, upholding the vertical sides of excavations, the removal of dead services, and dewatering. - installation of pipes and special parts in the proposed trenches including the foundation layer under pipes and the surrounding layer and caution tape. - Backfilling including compaction with approved materials all in accordance with authority regulations. - Concrete Stools and Thrust Blocks (if any) indicated in the relevant drawings and specifications. -All necessary items to interface between the new networks and the existing networks, all necessary testing, return of surface to its original conditions.and all other items to complete this item. - Special protection for utilities adjacent or multiple pipe laying, and pipe supports. - Commissioning, final cleaning, flushing and sterilisation of works. - All the works required to complete the installation of pipes. - All the works shall be in accordance with the Drawings and Specifications.
A34: 3.2 | B34: أعمال غرف المحابس و المطابق: | C34: Valve Chambers and Manholes: | D34: 3.2
B35: يشمل قياس أعمال غرف المحابس و المطابق ما يلي: - توريد المواسير والقطع الخاصة - الحفر في جميع أنواع التربة (الترابية والصخرية) وإعداد الأسطح وإزالة المخلفات ويشمل تدعيم الجوانب الخاصة بالحفر وإزالة المرافق والخدمات المهملة وغير المستخدمة و نزح المياه. - جميع الاعمال الخرسانية و تشمل الاساسات و الحوائط و الاسقف و الكراسى والدعمات الخرسانية وكتل التثبيت الخرسانية وكافة المتطلبات طبقا للمخططات والمواصفات ذات الصلة مثل دهان بيتوميني وطبقات نيوبرين.....الخ. - أعمال البناء وفرشة المونة وأعمال مقاومة المياه والدرج والاغطيه والإطارات ,و سلسله الدعم و السلامة وجميع الوصلات. - تركيب المواسير والقطع الخاصه - الحماية الخاصة للمرافق والخدمات المجاورة أو الطبقات المتعددة من المواسير - الاختبارات والتنظيف النهائي والغسيل والتعقيم - جميع الاعمال اللازمه لانهاء غرف المحابس و تركيب المواسير. - جميع الاعمال يتم تنفيذها وفقا للرسومات و المواصفات الفنيه | C35: The rate for Valve Chambers and Manholes shall include the following: - supply of pipes and special parts. - excavation in all types of soil (including rock), surface preparation, demlition, upholding the vertical sides of excavations, the removal of dead services, and dewatering. - All the concrete works including foundation, walls, slabs, stools, and thrust blocks and all the requirements in accordance with the Drawings and Soecifications such as bituminous coat, neoprene layer, etc. - All the civil works, mortar, waterproofing, stairs, covers, frames and chainlinks. - installation of pipes and special parts. - Special protection for utilities adjacent or multiple pipe laying, and pipe supports. - Commissioning, final cleaning, flushing and sterilisation of works. - All the works required to complete the installation of valve chambers and manholes. - All the works shall be in accordance with the Drawings and Soecifications.
A36: 3.3 | B36: حنفيات الحريق | C36: Fire Hydrants | D36: 3.3
B37: تشمل تكلفة حنفيات الحريق ما يلي: - توريد حنفيات الحريق والصمامات و المواسير والقطع الخاصة - الحفر في جميع أنواع التربة (الترابية والصخرية) وإعداد الأسطح وإزالة المخلفات ويشمل تدعيم الجوانب الخاصة بالحفر وإزالة المرافق والخدمات المهملة وغير المستخدمة و نزح المياه. - كافة أعمال تركيب المواسير والصمامات وصناديق الصمامات وملحقاتها وحواجز التأمين والتركيبات اللازمة والملحقات وأعمال البناء. - جميع الاعمال اللازمه لانهاء تركيب حنفيات الحريق. - جميع الاعمال يتم تنفيذها وفقا للرسومات و المواصفات الفنيه | C37: The rate for fire hydrants shall include the following: - Supply of fire hydrants, valves, pipes and special parts. - Excavation in all types of soil (including rock), surface preparation, demlition, upholding the vertical sides of excavations, the removal of dead services, and dewatering. - All the works required for pipework, valves, surface boxes, accessories, protection barricades, necessary fittings, and accessories, and civil works, - All the works required to complete the installation of fire hydrants. - All the works shall be in accordance with the Drawings and Specifications.
A38: 3.4 | B38: الصمامات المردومة | C38: Buried Valves | D38: 3.4
B39: تشمل تكلفة الصمامات المردومة ما يلي: - توريد الصمامات و المواسير والقطع الخاصة - الحفر في جميع أنواع التربة (الترابية والصخرية) وإعداد الأسطح وإزالة المخلفات ويشمل تدعيم الجوانب الخاصة بالحفر وإزالة المرافق والخدمات المهملة وغير المستخدمة و نزح المياه. - كافة أعمال تركيب المواسير والصمامات وصناديق الصمامات وملحقاتها وحواجز التأمين والتركيبات اللازمة والملحقات وأعمال البناء. - جميع الاعمال اللازمه لانهاء تركيب المحابس. - جميع الاعمال يتم تنفيذها وفقا للرسومات و المواصفات الفنيه | C39: The rate for buried valves shall include the following: - Supply of fire hydrants, valves, pipes and special parts. - Excavation in all types of soil (including rock), surface preparation, demlition, upholding the vertical sides of excavations, the removal of dead services, and dewatering. - All the works required for pipework, valves, surface boxes, accessories, protection barricades, necessary fittings, and accessories, and civil works, - All the works required to complete the installation of buried valves. - All the works shall be in accordance with the Drawings and Specifications.
A40: 3.5 | B40: يعد سطح التسوية هو سطح بداية العمل لأعمال المواسير والعمق المذكور مقاس من سطح التسوية حتى منسوب قاع المواسير. | C40: The "Grading level" shall be considered as "Commencing Surface" for pipes , the mentioned depth is from grading level to the pipe invert level. | D40: 3.5
A41: 3.6 | B41: يعد العمق المذكور لأعمال المناهل وغرف المحابس هو العمق المقاس من أعلى الغطاء حتى منسوب قاع المانهول / الغرفة | C41: The mentioned depth for manholes and valve chambers shall be considered from the top of cover to the manhole/chamber bottom | D41: 3.6
A42: 3.7 | B42: الفواصل وأعمال حقن الخرسانة للمواسير داخل العبارات/ مناطق القطع تكون مشمولة ضمن أسعار المواسير كما يجب أن تشمل إعادة الشئ لأصله المانهولات والغرف الأخرى | C42: Spacers and grouting for pipes within ducts/crossings deemed to be included within pipes rates. Additional reinstatement shall be deemed to include for manholes and other chambers. | D42: 3.7
...

Sheet P.2
A1: ='General Summary '!D3 -> اسم المشروع: تطوير شبكات البنية التحتية في المدينة الصناعية بالخرج | H1: ='General Summary '!C3 -> Development of Infrastructure in Kharj Industrial City
A2: جدول الكميات | H2: BILL OF QUANTITIES
A4: البند | B4: وصف البند | C4: الوحدة | D4: الكمية | E4: السعر (ريال سعودي) | F4: المبلغ (ريال سعودي) | G4: ITEM DESCRIPTION | H4: ITEM
C5: Unit | D5: QUANTITY | E5: PRICE (S.R) | F5: AMOUNT (S.R)
A6: أعمال الطرق | G6: ROAD WORKS
A7: =H7 -> 02 41 00 | B7: أعمال الهدم | G7: DEMOLITION | H7: 02 41 00
A8: =H8 -> B1.02 41 00.1 | B8: إزالة أسفلت قائم | C8: m2 | D8: 100 | E8: 9 | F8: =E8*D8 -> 900 | G8: Demolition of existing Asphalt | H8: B1.02 41 00.1
A9: =H9 -> B1.02 41 00.2 | B9: إزالة بردورات قائمه | C9: m | D9: 100 | E9: 12 | F9: =E9*D9 -> 1200 | G9: Demolition of existing Kerbs | H9: B1.02 41 00.2
A10: =H10 -> 31 22 00 | B10: الأعمال الترابية و التسوية | G10: EARTHWORKS AND SITE GRADING | H10: 31 22 00
A11: =H11 -> B1.31 22 00.01 | B11: حفريات (في جميع أنواع التربة) | C11: m3 | D11: 17489 | E11: 14 | F11: =E11*D11 -> 244846 | G11: Excavation for cuttings (all types of soil) | H11: B1.31 22 00.01
A12: =H12 -> B1.31 22 00.02 | B12: ردميات للموقع من ناتج الحفر أو مورده من خارج الموقع | C12: m3 | D12: 6422 | E12: 24 | F12: =E12*D12 -> 154128 | G12: Embankments to the site with common / suitable excavated material or suitable imported material | H12: B1.31 22 00.02
A13: =H13 -> B1.31 22 00.03 | B13: طبقة القاعدة | C13: m3 | D13: 8953 | E13: 18 | F13: =E13*D13 -> 161154 | G13: Subgrade | H13: B1.31 22 00.03
A14: =H14 -> 32 11 23 | B14: طبقة أساس حصوية | G14: AGGREGATE BASE COURSE | H14: 32 11 23
A15: =H15 -> B1.32 11 23.01 | B15: طبقة أساس حصوية | C15: m3 | D15: 5193 | E15: 65 | F15: =E15*D15 -> 337545 | G15: Aggregate base course | H15: B1.32 11 23.01
A16: =H16 -> 32 11 26 | B16: الإنشاء البيتوميني | G16: BITUMINOUS CONSTRUCTION | H16: 32 11 26
A17: =H17 -> B1.32 11 26.01 | B17: الطبقة الأساس البيتومينية (تدرج 1 - صنف أ) بعد الدمك ، شاملاً الطبقة اللاصقة (MC1) والطبقة اللاصقة (RC2) (إن وجدت) | C17: m3 | D17: 1664 | E17: 642 | F17: =E17*D17 -> 1068288 | G17: Bituminous base course (Grading I - Class A), after compaction , including Prime Coat (MC1) (if needed) | H17: B1.32 11 26.01
A18: =H18 -> 32 12 16 | B18: طبقة السطح العليا | G18: ASPHALT WEARING COURSE | H18: 32 12 16
A19: =H19 -> B1.32 12 16.01 | B19: طبقة السطح العليا من الخرسانة البيتومينية بعد الدمك (تدرج 1 - صنف أ) شاملاً الطبقة اللاصقة (RC2) . | C19: m3 | D19: 1200 | E19: 648 | F19: =E19*D19 -> 777600 | G19: Bituminous concrete wearing course, after compaction (Grading I - Class A), including tack coat (RC2). | H19: B1.32 12 16.01
A20: =H20 -> 32 14 13 | B20: بردورات مسبقة الصب | G20: PRECAST CONCRETE CURB | H20: 32 14 13
A21: =H21 -> B1.32 14 13.01 | B21: بردورات نوع (K1A) | C21: m | D21: 2922 | E21: 65 | F21: =E21*D21 -> 189930 | G21: Concrete curb, Type (K1A) | H21: B1.32 14 13.01
A22: =H22 -> B1.32 14 13.02 | B22: بردورات نوع (K1B) | C22: m | D22: 1304 | E22: 60 | F22: =E22*D22 -> 78240 | G22: Concrete curb, Type (K1B) | H22: B1.32 14 13.02
A23: =H23 -> 32 17 23 | B23: العلامات الأرضية | G23: PAVEMENT MARKINGS | H23: 32 17 23
A24: =H24 -> 32 17 23.01 | B24: دهان ثرموبلاستيك (أبيض / أصفر) | G24: Thermoplastic pavement marking (White/Yellow) | H24: 32 17 23.01
A25: =H25 -> B1.32 17 23.01.01 | B25: خطوط مرورية بيضاء عاكسة بلاستيكية حرارية | C25: m² | D25: 789 | E25: 41 | F25: =E25*D25 -> 32349 | G25: Retroreflective Thermoplastic White Traffic lines | H25: B1.32 17 23.01.01
A26: =H26 -> B1.32 17 23.01.02 | B26: خطوط مرورية صفراء عاكسة بلاستيكية حرارية | C26: m² | D26: 495 | E26: 41 | F26: =E26*D26 -> 20295 | G26: Retroreflective Thermoplastic Yellow Traffic lines | H26: B1.32 17 23.01.02
A27: B1.32 17 23.03 | B27: علامات أرضية بارزة عاكسة (نوع - أ) | C27: nr | D27: 200 | E27: 30 | F27: =E27*D27 -> 6000 | G27: Retroreflective raised pavement markers (Type A) | H27: B1.32 17 23.03
A28: B1.32 17 23.04 | B28: علامات أرضية بارزة مصنوعة من السيراميك | C28: nr | D28: 200 | E28: 12 | F28: =E28*D28 -> 2400 | G28: Ceramic raised pavement markers | H28: B1.32 17 23.04
A29: B1.32 17 23.05 | B29: علامات أرضية مضيئة تعمل بالطاقة الشمسية (عيون القط) | C29: nr | D29: 200 | E29: 166 | F29: =E29*D29 -> 33200 | G29: Solar powered lighting cateyes pavement markers | H29: B1.32 17 23.05
A30: =H30 -> 10 14 53 | B30: اللوحات الإرشادية للطرق | G30: TRAFFIC SIGNAGE | H30: 10 14 53
A31: =H31 -> B1.10 14 53.01 | B31: لوحات مرورية المثبتة بالأرض مصنوعة من ألواح ألومنيوم مع حواملها القابلة للإنفصال بالقاعدة مكونة من لوحة مروريه وعمود واحد مع كافة الاكسسورات وكل ما يلزم حسب المخططات والمواصفات. | C31: nr | D31: 87 | E31: 1065 | F31: =E31*D31 -> 92655 | G31: Traffic signs, ground mounted, 1 Sheet Alumenium, (breakaway) Single post, with all accessories according to the drawings and specifications. | H31: B1.10 14 53.01
A32: =H32 -> B1.10 14 53.02 | B32: لوحات مرورية المثبتة بالأرض مصنوعة من ألواح ألومنيوم مع حواملها القابلة للإنفصال بالقاعدة مكونة من لوحتين مروريتين وعمود واحد مع كافة الاكسسورات وكل ما يلزم حسب المخططات والمواصفات. | C32: nr | D32: 74 | E32: 1479 | F32: =E32*D32 -> 109446 | G32: Traffic signs, ground mounted, 2 Sheet Alumenium, (breakaway) Single post, with all accessories according to the drawings and specifications. | H32: B1.10 14 53.02
A33: =H33 -> B1.10 14 53.03 | B33: لوحات مرورية مصنوعة من ألواح الإلمنيوم مع حواملها (قابلة للانفصال بالقاعدة) مكونة من لوحه مروريه وعمودين مع كافات الاكسسورات، وكل ما يلزم حسب المخططات والمواصفات. | C33: nr | D33: 6 | E33: 2011 | F33: =E33*D33 -> 12066 | G33: Traffic signs, ground mounted, Sheet Alumenium, (breakaway) Double post with all accessories according to the drawings and specifications. | H33: B1.10 14 53.03
B52: يتم ترحيل الطرق - إلى التجميع | C52: ريال سعودي | F52: =SUM(F8:F33) -> 3322242 | G52: CARRIED TO ROADS - COLLECTION
A53: خدمات أعمال الكهرباء والإتصالات | G53: DRY UTILITIES
A54: =H54 -> 31 23 00 | B54: خندق كابل الجهد المتوسط | G54: MEDIUM VOLTAGE CABLE TRENCH | H54: 31 23 00
A55: =H55 -> B2.31 23 00.01 | B55: حفر خندق كابل عرض 1.2 م وعمق 80 سم | C55: m³ | D55: =D59 -> 3817 | E55: 23 | F55: =E55*D55 -> 87791 | G55: Excavation for Trench size 1.2m wide and 80cm deep | H55: B2.31 23 00.01
A56: =H56 -> 33 71 19 | B56: عبارات كابلات الجهد المتوسط | G56: MEDIUM VOLTAGE CABLES DUCT BANKS | H56: 33 71 19
A57: =H57 -> B2.33 71 19.01 | B57: عبارات كوابل 4 مسارات (4x200mm duct) | C57: m | D57: 109 | E57: 573 | F57: =E57*D57 -> 62457 | G57: 4-way Duct Bank (4x200mm duct) | H57: B2.33 71 19.01
A58: =H58 -> 26 05 13.16 | B58: كيابل الجهد المتوسط | G58: MEDIUM VOLTAGE CABLES | H58: 26 05 13.16
A59: =H59 -> B2.26.05.13.16.01 | B59: كيبل جهد 33 ك.ف.400*3C مم2 AL/ XLPE/ LLDPE غير مسلح | C59: m | D59: 3817 | E59: 172 | F59: =E59*D59 -> 656524 | G59: Cable: 33KV 3Cx400mm² AL/XLPE/LLDPE unarmored | H59: B2.26.05.13.16.01
...

Sheet Cover3
B4: مدن | J4: MODON
B5: الهيئة السعودية للمدن الصناعية ومناطق التقنية | J5: SAUDI AUTHORITY FOR INDUSTRIAL CITIES AND TECHNOLOGY ZONES
B12: المدينة الصناعية الأولى بالخرج | J12: Kharj 1st Industrial City
B15: ='General Summary '!D3 -> اسم المشروع: تطوير شبكات البنية التحتية في المدينة الصناعية بالخرج | N15: ='General Summary '!C3 -> Development of Infrastructure in Kharj Industrial City
B18: مبنى المسجد ومهبط الطائرات | J18: Mosque and helipad
B23: جدول الكميات | J23: BILL OF QUANTITIES
B28: نوفمبر- 25 | J28: 45972

Sheet Preamble3
A1: اسم المشروع: تطوير شبكات البنية التحتية في المدينة الصناعية بالخرج | D1: ='General Summary '!C3 -> Development of Infrastructure in Kharj Industrial City
A2: جدول الكميات | D2: BILL OF QUANTITIES
B5: مقدمة البنود - مكونات البنود | C5: ITEMS PREAMBLE - ITEMS CONTENTS
B6: أعمال الموقع والأعمال الترابية | C6: Site and Earth Works
A7: 1.1 | B7: يعتبر المقاول من خلال زيارته للموقع بأنه قام بفحص واستكشاف الموقع ومحيطه وأنه قام بتحديد والأخذ بعين الاعتبار عند إعطاء أسعاره كافة التكاليف الإضافية المتعلقة بهدم (بشكل حذر) المنشآت القائمة وطرق الوصول إلى الموقع وإزالة طبقات الأعشاب الموجودة والخرسانة والأرصفة وطبقات الرصف والاسفلت وأحجار الارصفة و التربة العلوية والسياج وحماية خطوط الخدمات القائمة وكافة ملحقاتها...الخ. | C7: The Contractor shall be deemed to have inspected and examined the Site and it's surroundings, and identified, considered and deemed to included all costs related to (carefully)demolition of existing structures, access roads, existing turfs, concrete, flagging, paving, curbing, road-metalling, topsoil, fencing, demolish and seal existing services, protection of existing service lines, accessories etc., and cart away debris, as directed by the Engineer and return of surface to its original conditions. | D7: 1.1
