Workbook

Sheet Sheet3
A1: م | B1: الطريق | C1: تاريخ بداية الاعمال | D1: تاريخ نهاية الاعمال | E1: الشبكة | F1: البند | G1: الوحدة | H1: الكمية الإجمالية | I1: الكمية المنفذة | J1: الكمية المتبقية | K1: نسبة المنفذ | L1: نسبة المتبقي | M1: تاريخ البداية | N1: تاريخ النهاية | O1: المخطط % حتى اليوم | P1: الكمية المخططة حتى اليوم | Q1: المنفذ % فعلياً | R1: الفرق % (منفذ − مخطط) | S1: الفرق بالكمية (منفذ − مخطط) | T1: الحالة | V1: تاريخ التحديث
A2: 1 | B2: RD10 | C2: 46272 | D2: 30-10-2026 | E2: شبكة تصريف السيول | F2: تركيب المناهل Manhole | G2: عدد | H2: 50 | I2: =H2-5 -> 45 | J2: =H2-I2 -> 5 | K2: =I2/H2 -> 0.9 | L2: =J2/H2 -> 0.1 | M2: 46272 | N2: 46280 | O2: =IF(OR(M2="",N2=""),"",IF($V$2<M2,0,IF($V$2>=N2,1,NETWORKDAYS.INTL(M2,$V$2,"0000110")/MAX(1,NETWORKDAYS.INTL(M2,N2,"0000110"))))) -> 1 | P2: =IF(O2="","",O2*H2) -> 50 | Q2: =K2 -> 0.9 | R2: =IF(O2="","",Q2-O2) -> -0.1 | S2: =IF(O2="","",I2-P2) -> -5 | T2: =IF(O2="","",IF(AND(O2=0,Q2=0),"لم يحن موعده",IF(R2<-0.005,"متأخر",IF(R2>0.005,"متقدم","مطابق")))) -> متأخر | V2: 46294
F3: تركيب مصائد الأمطارCatchBase | G3: عدد | H3: 106 | I3: =H3-9 -> 97 | J3: =H3-I3 -> 9 | K3: =I3/H3 -> 0.91509434 | L3: =J3/H3 -> 0.08490566 | M3: 46272 | N3: 46280 | O3: =IF(OR(M3="",N3=""),"",IF($V$2<M3,0,IF($V$2>=N3,1,NETWORKDAYS.INTL(M3,$V$2,"0000110")/MAX(1,NETWORKDAYS.INTL(M3,N3,"0000110"))))) -> 1 | P3: =IF(O3="","",O3*H3) -> 106 | Q3: =K3 -> 0.91509434 | R3: =IF(O3="","",Q3-O3) -> -0.08490566 | S3: =IF(O3="","",I3-P3) -> -9 | T3: =IF(O3="","",IF(AND(O3=0,Q3=0),"لم يحن موعده",IF(R3<-0.005,"متأخر",IF(R3>0.005,"متقدم","مطابق")))) -> متأخر
F4: تشكيل قاع المناهل الرئيسيه Penching | G4: عدد | H4: 50 | I4: =H4-50 -> 0 | J4: =H4-I4 -> 50 | K4: =I4/H4 -> 0 | L4: =J4/H4 -> 1 | M4: 46295 | N4: 46302 | O4: =IF(OR(M4="",N4=""),"",IF($V$2<M4,0,IF($V$2>=N4,1,NETWORKDAYS.INTL(M4,$V$2,"0000110")/MAX(1,NETWORKDAYS.INTL(M4,N4,"0000110"))))) -> 0 | P4: =IF(O4="","",O4*H4) -> 0 | Q4: =K4 -> 0 | R4: =IF(O4="","",Q4-O4) -> 0 | S4: =IF(O4="","",I4-P4) -> 0 | T4: =IF(O4="","",IF(AND(O4=0,Q4=0),"لم يحن موعده",IF(R4<-0.005,"متأخر",IF(R4>0.005,"متقدم","مطابق")))) -> لم يحن موعده
F5: تركيب الكفرات مصائد الأمطارCovers Catsh Base | G5: عدد | H5: 106 | I5: 0 | J5: =H5-I5 -> 106 | K5: =I5/H5 -> 0 | L5: =J5/H5 -> 1 | M5: 46295 | N5: 46302 | O5: =IF(OR(M5="",N5=""),"",IF($V$2<M5,0,IF($V$2>=N5,1,NETWORKDAYS.INTL(M5,$V$2,"0000110")/MAX(1,NETWORKDAYS.INTL(M5,N5,"0000110"))))) -> 0 | P5: =IF(O5="","",O5*H5) -> 0 | Q5: =K5 -> 0 | R5: =IF(O5="","",Q5-O5) -> 0 | S5: =IF(O5="","",I5-P5) -> 0 | T5: =IF(O5="","",IF(AND(O5=0,Q5=0),"لم يحن موعده",IF(R5<-0.005,"متأخر",IF(R5>0.005,"متقدم","مطابق")))) -> لم يحن موعده
F6: تركيب الكفرات للمناهل الرئيسية Manhole Cover | G6: عدد | H6: 50 | I6: =H6-50 -> 0 | J6: =H6-I6 -> 50 | K6: =I6/H6 -> 0 | L6: =J6/H6 -> 1 | M6: 46296 | N6: 46303 | O6: =IF(OR(M6="",N6=""),"",IF($V$2<M6,0,IF($V$2>=N6,1,NETWORKDAYS.INTL(M6,$V$2,"0000110")/MAX(1,NETWORKDAYS.INTL(M6,N6,"0000110"))))) -> 0 | P6: =IF(O6="","",O6*H6) -> 0 | Q6: =K6 -> 0 | R6: =IF(O6="","",Q6-O6) -> 0 | S6: =IF(O6="","",I6-P6) -> 0 | T6: =IF(O6="","",IF(AND(O6=0,Q6=0),"لم يحن موعده",IF(R6<-0.005,"متأخر",IF(R6>0.005,"متقدم","مطابق")))) -> لم يحن موعده
E7: شبكة المياه | F7: حفر وتمديد الخطوط الرئيسية Main Pipe | G7: م.ط | H7: 4583 | I7: =H7-150 -> 4433 | J7: =H7-I7 -> 150 | K7: =I7/H7 -> 0.96727035 | L7: =J7/H7 -> 0.032729653 | M7: 46272 | N7: 46280 | O7: =IF(OR(M7="",N7=""),"",IF($V$2<M7,0,IF($V$2>=N7,1,NETWORKDAYS.INTL(M7,$V$2,"0000110")/MAX(1,NETWORKDAYS.INTL(M7,N7,"0000110"))))) -> 1 | P7: =IF(O7="","",O7*H7) -> 4583 | Q7: =K7 -> 0.96727035 | R7: =IF(O7="","",Q7-O7) -> -0.032729653 | S7: =IF(O7="","",I7-P7) -> -150 | T7: =IF(O7="","",IF(AND(O7=0,Q7=0),"لم يحن موعده",IF(R7<-0.005,"متأخر",IF(R7>0.005,"متقدم","مطابق")))) -> متأخر
E8: شبكة الري | F8: حفر وتمديد الخطوط الرئيسية Main Pipe | G8: م.ط | H8: 5866 | I8: =H8-3381 -> 2485 | J8: =H8-I8 -> 3381 | K8: =I8/H8 -> 0.42362768 | L8: =J8/H8 -> 0.57637232 | M8: 46272 | N8: 46283 | O8: =IF(OR(M8="",N8=""),"",IF($V$2<M8,0,IF($V$2>=N8,1,NETWORKDAYS.INTL(M8,$V$2,"0000110")/MAX(1,NETWORKDAYS.INTL(M8,N8,"0000110"))))) -> 1 | P8: =IF(O8="","",O8*H8) -> 5866 | Q8: =K8 -> 0.42362768 | R8: =IF(O8="","",Q8-O8) -> -0.57637232 | S8: =IF(O8="","",I8-P8) -> -3381 | T8: =IF(O8="","",IF(AND(O8=0,Q8=0),"لم يحن موعده",IF(R8<-0.005,"متأخر",IF(R8>0.005,"متقدم","مطابق")))) -> متأخر
F9: المحابس valve | G9: عدد | H9: 30 | I9: =H9-30 -> 0 | J9: =H9-I9 -> 30 | K9: =I9/H9 -> 0 | L9: =J9/H9 -> 1 | M9: 46283 | N9: 46290 | O9: =IF(OR(M9="",N9=""),"",IF($V$2<M9,0,IF($V$2>=N9,1,NETWORKDAYS.INTL(M9,$V$2,"0000110")/MAX(1,NETWORKDAYS.INTL(M9,N9,"0000110"))))) -> 1 | P9: =IF(O9="","",O9*H9) -> 30 | Q9: =K9 -> 0 | R9: =IF(O9="","",Q9-O9) -> -1 | S9: =IF(O9="","",I9-P9) -> -30 | T9: =IF(O9="","",IF(AND(O9=0,Q9=0),"لم يحن موعده",IF(R9<-0.005,"متأخر",IF(R9>0.005,"متقدم","مطابق")))) -> متأخر
F10: غرف الري(خرسانة) valve Chamber | G10: عدد | H10: 19 | I10: =H10-12 -> 7 | J10: =H10-I10 -> 12 | K10: =I10/H10 -> 0.36842105 | L10: =J10/H10 -> 0.63157895 | M10: 46278 | N10: 46285 | O10: =IF(OR(M10="",N10=""),"",IF($V$2<M10,0,IF($V$2>=N10,1,NETWORKDAYS.INTL(M10,$V$2,"0000110")/MAX(1,NETWORKDAYS.INTL(M10,N10,"0000110"))))) -> 1 | P10: =IF(O10="","",O10*H10) -> 19 | Q10: =K10 -> 0.36842105 | R10: =IF(O10="","",Q10-O10) -> -0.63157895 | S10: =IF(O10="","",I10-P10) -> -12 | T10: =IF(O10="","",IF(AND(O10=0,Q10=0),"لم يحن موعده",IF(R10<-0.005,"متأخر",IF(R10>0.005,"متقدم","مطابق")))) -> متأخر
F11: تركيب غرف المحابس (ميكانيكا) valve Chamber | G11: عدد | H11: 19 | I11: =H11-19 -> 0 | J11: =H11-I11 -> 19 | K11: =I11/H11 -> 0 | L11: =J11/H11 -> 1 | M11: 46281 | N11: 46288 | O11: =IF(OR(M11="",N11=""),"",IF($V$2<M11,0,IF($V$2>=N11,1,NETWORKDAYS.INTL(M11,$V$2,"0000110")/MAX(1,NETWORKDAYS.INTL(M11,N11,"0000110"))))) -> 1 | P11: =IF(O11="","",O11*H11) -> 19 | Q11: =K11 -> 0 | R11: =IF(O11="","",Q11-O11) -> -1 | S11: =IF(O11="","",I11-P11) -> -19 | T11: =IF(O11="","",IF(AND(O11=0,Q11=0),"لم يحن موعده",IF(R11<-0.005,"متأخر",IF(R11>0.005,"متقدم","مطابق")))) -> متأخر
F12: اختبارات الخطوط Test | G12: م.ط | H12: 5866 | I12: =H12-5866 -> 0 | J12: =H12-I12 -> 5866 | K12: =I12/H12 -> 0 | L12: =J12/H12 -> 1 | M12: 46307 | N12: 46325 | O12: =IF(OR(M12="",N12=""),"",IF($V$2<M12,0,IF($V$2>=N12,1,NETWORKDAYS.INTL(M12,$V$2,"0000110")/MAX(1,NETWORKDAYS.INTL(M12,N12,"0000110"))))) -> 0 | P12: =IF(O12="","",O12*H12) -> 0 | Q12: =K12 -> 0 | R12: =IF(O12="","",Q12-O12) -> 0 | S12: =IF(O12="","",I12-P12) -> 0 | T12: =IF(O12="","",IF(AND(O12=0,Q12=0),"لم يحن موعده",IF(R12<-0.005,"متأخر",IF(R12>0.005,"متقدم","مطابق")))) -> لم يحن موعده
E13: شبكة الاتصالات | F13: اعمال الحفر والتأسيس للشبكه | G13: م.ط | H13: 3140 | I13: 0 | J13: =H13-I13 -> 3140 | K13: =I13/H13 -> 0 | L13: =J13/H13 -> 1 | M13: 46285 | N13: 46290 | O13: =IF(OR(M13="",N13=""),"",IF($V$2<M13,0,IF($V$2>=N13,1,NETWORKDAYS.INTL(M13,$V$2,"0000110")/MAX(1,NETWORKDAYS.INTL(M13,N13,"0000110"))))) -> 1 | P13: =IF(O13="","",O13*H13) -> 3140 | Q13: =K13 -> 0 | R13: =IF(O13="","",Q13-O13) -> -1 | S13: =IF(O13="","",I13-P13) -> -3140 | T13: =IF(O13="","",IF(AND(O13=0,Q13=0),"لم يحن موعده",IF(R13<-0.005,"متأخر",IF(R13>0.005,"متقدم","مطابق")))) -> متأخر
F14: اعمال تركيب الهاند هول/مانهول | G14: عدد | H14: 18 | I14: =H14-18 -> 0 | J14: =H14-I14 -> 18 | K14: =I14/H14 -> 0 | L14: =J14/H14 -> 1 | M14: 46285 | N14: 46287 | O14: =IF(OR(M14="",N14=""),"",IF($V$2<M14,0,IF($V$2>=N14,1,NETWORKDAYS.INTL(M14,$V$2,"0000110")/MAX(1,NETWORKDAYS.INTL(M14,N14,"0000110"))))) -> 1 | P14: =IF(O14="","",O14*H14) -> 18 | Q14: =K14 -> 0 | R14: =IF(O14="","",Q14-O14) -> -1 | S14: =IF(O14="","",I14-P14) -> -18 | T14: =IF(O14="","",IF(AND(O14=0,Q14=0),"لم يحن موعده",IF(R14<-0.005,"متأخر",IF(R14>0.005,"متقدم","مطابق")))) -> متأخر
E15: اعمال الطرق | F15: اعمال البردورات+انترلوك | G15: م.ط | H15: 14500 | I15: =H15-14500 -> 0 | J15: =H15-I15 -> 14500 | K15: =I15/H15 -> 0 | L15: =J15/H15 -> 1 | M15: 46283 | N15: 46294 | O15: =IF(OR(M15="",N15=""),"",IF($V$2<M15,0,IF($V$2>=N15,1,NETWORKDAYS.INTL(M15,$V$2,"0000110")/MAX(1,NETWORKDAYS.INTL(M15,N15,"0000110"))))) -> 1 | P15: =IF(O15="","",O15*H15) -> 14500 | Q15: =K15 -> 0 | R15: =IF(O15="","",Q15-O15) -> -1 | S15: =IF(O15="","",I15-P15) -> -14500 | T15: =IF(O15="","",IF(AND(O15=0,Q15=0),"لم يحن موعده",IF(R15<-0.005,"متأخر",IF(R15>0.005,"متقدم","مطابق")))) -> متأخر
F16: أعمال طبقة ال Capping (30سم) | G16: م3 | H16: 17615 | I16: =H16-17615 -> 0 | J16: =H16-I16 -> 17615 | K16: =I16/H16 -> 0 | L16: =J16/H16 -> 1 | M16: 46278 | N16: 46283 | O16: =IF(OR(M16="",N16=""),"",IF($V$2<M16,0,IF($V$2>=N16,1,NETWORKDAYS.INTL(M16,$V$2,"0000110")/MAX(1,NETWORKDAYS.INTL(M16,N16,"0000110"))))) -> 1 | P16: =IF(O16="","",O16*H16) -> 17615 | Q16: =K16 -> 0 | R16: =IF(O16="","",Q16-O16) -> -1 | S16: =IF(O16="","",I16-P16) -> -17615 | T16: =IF(O16="","",IF(AND(O16=0,Q16=0),"لم يحن موعده",IF(R16<-0.005,"متأخر",IF(R16>0.005,"متقدم","مطابق")))) -> متأخر
F17: أعمال طبقة الصب جريد (30سم) | G17: م3 | H17: 16969 | I17: =H17-16969 -> 0 | J17: =H17-I17 -> 16969 | K17: =I17/H17 -> 0 | L17: =J17/H17 -> 1 | M17: 46281 | N17: 46288 | O17: =IF(OR(M17="",N17=""),"",IF($V$2<M17,0,IF($V$2>=N17,1,NETWORKDAYS.INTL(M17,$V$2,"0000110")/MAX(1,NETWORKDAYS.INTL(M17,N17,"0000110"))))) -> 1 | P17: =IF(O17="","",O17*H17) -> 16969 | Q17: =K17 -> 0 | R17: =IF(O17="","",Q17-O17) -> -1 | S17: =IF(O17="","",I17-P17) -> -16969 | T17: =IF(O17="","",IF(AND(O17=0,Q17=0),"لم يحن موعده",IF(R17<-0.005,"متأخر",IF(R17>0.005,"متقدم","مطابق")))) -> متأخر
F18: أعمال طبقة البيسكورس | G18: م3 | H18: 10929 | I18: =H18-10929 -> 0 | J18: =H18-I18 -> 10929 | K18: =I18/H18 -> 0 | L18: =J18/H18 -> 1 | M18: 46288 | N18: 46293 | O18: =IF(OR(M18="",N18=""),"",IF($V$2<M18,0,IF($V$2>=N18,1,NETWORKDAYS.INTL(M18,$V$2,"0000110")/MAX(1,NETWORKDAYS.INTL(M18,N18,"0000110"))))) -> 1 | P18: =IF(O18="","",O18*H18) -> 10929 | Q18: =K18 -> 0 | R18: =IF(O18="","",Q18-O18) -> -1 | S18: =IF(O18="","",I18-P18) -> -10929 | T18: =IF(O18="","",IF(AND(O18=0,Q18=0),"لم يحن موعده",IF(R18<-0.005,"متأخر",IF(R18>0.005,"متقدم","مطابق")))) -> متأخر
F19: أعمال الأسفلت طبقة اولي | G19: م3 | H19: 4284.6667 | I19: 0 | J19: =H19-I19 -> 4284.6667 | K19: =I19/H19 -> 0 | L19: =J19/H19 -> 1 | M19: 46293 | N19: 46295 | O19: =IF(OR(M19="",N19=""),"",IF($V$2<M19,0,IF($V$2>=N19,1,NETWORKDAYS.INTL(M19,$V$2,"0000110")/MAX(1,NETWORKDAYS.INTL(M19,N19,"0000110"))))) -> 0.66666667 | P19: =IF(O19="","",O19*H19) -> 2856.4444 | Q19: =K19 -> 0 | R19: =IF(O19="","",Q19-O19) -> -0.66666667 | S19: =IF(O19="","",I19-P19) -> -2856.4444 | T19: =IF(O19="","",IF(AND(O19=0,Q19=0),"لم يحن موعده",IF(R19<-0.005,"متأخر",IF(R19>0.005,"متقدم","مطابق")))) -> متأخر
F20: أعمال الأسفلت طبقة تانيه | G20: م3 | H20: 2677.9167 | I20: 0 | J20: =H20-I20 -> 2677.9167 | K20: =I20/H20 -> 0 | L20: =J20/H20 -> 1 | M20: 46304 | N20: 46306 | O20: =IF(OR(M20="",N20=""),"",IF($V$2<M20,0,IF($V$2>=N20,1,NETWORKDAYS.INTL(M20,$V$2,"0000110")/MAX(1,NETWORKDAYS.INTL(M20,N20,"0000110"))))) -> 0 | P20: =IF(O20="","",O20*H20) -> 0 | Q20: =K20 -> 0 | R20: =IF(O20="","",Q20-O20) -> 0 | S20: =IF(O20="","",I20-P20) -> 0 | T20: =IF(O20="","",IF(AND(O20=0,Q20=0),"لم يحن موعده",IF(R20<-0.005,"متأخر",IF(R20>0.005,"متقدم","مطابق")))) -> لم يحن موعده
A21: 2 | B21: RD9 | C21: 46272 | D21: 30-10-2026 | E21: شبكة تصريف السيول | F21: حفر وتمديد الخطوط الرئيسيه Main Pipe | G21: م.ط | H21: 2007 | I21: =H21-306 -> 1701 | J21: =H21-I21 -> 306 | K21: =I21/H21 -> 0.84753363 | L21: =J21/H21 -> 0.15246637 | M21: 46273 | N21: 46280 | O21: =IF(OR(M21="",N21=""),"",IF($V$2<M21,0,IF($V$2>=N21,1,NETWORKDAYS.INTL(M21,$V$2,"0000110")/MAX(1,NETWORKDAYS.INTL(M21,N21,"0000110"))))) -> 1 | P21: =IF(O21="","",O21*H21) -> 2007 | Q21: =K21 -> 0.84753363 | R21: =IF(O21="","",Q21-O21) -> -0.15246637 | S21: =IF(O21="","",I21-P21) -> -306 | T21: =IF(O21="","",IF(AND(O21=0,Q21=0),"لم يحن موعده",IF(R21<-0.005,"متأخر",IF(R21>0.005,"متقدم","مطابق")))) -> متأخر
F22: غرف الخط المزدوج | G22: عدد | H22: 24 | I22: =H22-14 -> 10 | J22: =H22-I22 -> 14 | K22: =I22/H22 -> 0.41666667 | L22: =J22/H22 -> 0.58333333 | M22: 46274 | N22: 46278 | O22: =IF(OR(M22="",N22=""),"",IF($V$2<M22,0,IF($V$2>=N22,1,NETWORKDAYS.INTL(M22,$V$2,"0000110")/MAX(1,NETWORKDAYS.INTL(M22,N22,"0000110"))))) -> 1 | P22: =IF(O22="","",O22*H22) -> 24 | Q22: =K22 -> 0.41666667 | R22: =IF(O22="","",Q22-O22) -> -0.58333333 | S22: =IF(O22="","",I22-P22) -> -14 | T22: =IF(O22="","",IF(AND(O22=0,Q22=0),"لم يحن موعده",IF(R22<-0.005,"متأخر",IF(R22>0.005,"متقدم","مطابق")))) -> متأخر
F23: تركيب المناهل Manhole | G23: عدد | H23: 44 | I23: =H23-18 -> 26 | J23: =H23-I23 -> 18 | K23: =I23/H23 -> 0.59090909 | L23: =J23/H23 -> 0.40909091 | M23: 46275 | N23: 46280 | O23: =IF(OR(M23="",N23=""),"",IF($V$2<M23,0,IF($V$2>=N23,1,NETWORKDAYS.INTL(M23,$V$2,"0000110")/MAX(1,NETWORKDAYS.INTL(M23,N23,"0000110"))))) -> 1 | P23: =IF(O23="","",O23*H23) -> 44 | Q23: =K23 -> 0.59090909 | R23: =IF(O23="","",Q23-O23) -> -0.40909091 | S23: =IF(O23="","",I23-P23) -> -18 | T23: =IF(O23="","",IF(AND(O23=0,Q23=0),"لم يحن موعده",IF(R23<-0.005,"متأخر",IF(R23>0.005,"متقدم","مطابق")))) -> متأخر
F24: حفر وتمديد الخطوط الفرعية Main Pipe | G24: م.ط | H24: 2655 | I24: =H24-2655 -> 0 | J24: =H24-I24 -> 2655 | K24: =I24/H24 -> 0 | L24: =J24/H24 -> 1 | M24: 46280 | N24: 46285 | O24: =IF(OR(M24="",N24=""),"",IF($V$2<M24,0,IF($V$2>=N24,1,NETWORKDAYS.INTL(M24,$V$2,"0000110")/MAX(1,NETWORKDAYS.INTL(M24,N24,"0000110"))))) -> 1 | P24: =IF(O24="","",O24*H24) -> 2655 | Q24: =K24 -> 0 | R24: =IF(O24="","",Q24-O24) -> -1 | S24: =IF(O24="","",I24-P24) -> -2655 | T24: =IF(O24="","",IF(AND(O24=0,Q24=0),"لم يحن موعده",IF(R24<-0.005,"متأخر",IF(R24>0.005,"متقدم","مطابق")))) -> متأخر
F25: تشكيل قاع المناهل الرئيسيه Penching | G25: عدد | H25: 44 | I25: =H25-44 -> 0 | J25: =H25-I25 -> 44 | K25: =I25/H25 -> 0 | L25: =J25/H25 -> 1 | M25: 46305 | N25: 46312 | O25: =IF(OR(M25="",N25=""),"",IF($V$2<M25,0,IF($V$2>=N25,1,NETWORKDAYS.INTL(M25,$V$2,"0000110")/MAX(1,NETWORKDAYS.INTL(M25,N25,"0000110"))))) -> 0 | P25: =IF(O25="","",O25*H25) -> 0 | Q25: =K25 -> 0 | R25: =IF(O25="","",Q25-O25) -> 0 | S25: =IF(O25="","",I25-P25) -> 0 | T25: =IF(O25="","",IF(AND(O25=0,Q25=0),"لم يحن موعده",IF(R25<-0.005,"متأخر",IF(R25>0.005,"متقدم","مطابق")))) -> لم يحن موعده
F26: تركيب الكفرات للمناهل الرئيسية Manhole Cover | G26: عدد | H26: 44 | I26: =H26-44 -> 0 | J26: =H26-I26 -> 44 | K26: =I26/H26 -> 0 | L26: =J26/H26 -> 1 | M26: 46305 | N26: 46312 | O26: =IF(OR(M26="",N26=""),"",IF($V$2<M26,0,IF($V$2>=N26,1,NETWORKDAYS.INTL(M26,$V$2,"0000110")/MAX(1,NETWORKDAYS.INTL(M26,N26,"0000110"))))) -> 0 | P26: =IF(O26="","",O26*H26) -> 0 | Q26: =K26 -> 0 | R26: =IF(O26="","",Q26-O26) -> 0 | S26: =IF(O26="","",I26-P26) -> 0 | T26: =IF(O26="","",IF(AND(O26=0,Q26=0),"لم يحن موعده",IF(R26<-0.005,"متأخر",IF(R26>0.005,"متقدم","مطابق")))) -> لم يحن موعده
F27: تركيب مصائد الأمطارCatchBase | G27: عدد | H27: 127 | I27: =H27-55 -> 72 | J27: =H27-I27 -> 55 | K27: =I27/H27 -> 0.56692913 | L27: =J27/H27 -> 0.43307087 | M27: 46275 | N27: 46279 | O27: =IF(OR(M27="",N27=""),"",IF($V$2<M27,0,IF($V$2>=N27,1,NETWORKDAYS.INTL(M27,$V$2,"0000110")/MAX(1,NETWORKDAYS.INTL(M27,N27,"0000110"))))) -> 1 | P27: =IF(O27="","",O27*H27) -> 127 | Q27: =K27 -> 0.56692913 | R27: =IF(O27="","",Q27-O27) -> -0.43307087 | S27: =IF(O27="","",I27-P27) -> -55 | T27: =IF(O27="","",IF(AND(O27=0,Q27=0),"لم يحن موعده",IF(R27<-0.005,"متأخر",IF(R27>0.005,"متقدم","مطابق")))) -> متأخر
F28: تركيب الكفرات مصائد الأمطارCovers Catsh Base | G28: عدد | H28: 127 | I28: =H28-127 -> 0 | J28: =H28-I28 -> 127 | K28: =I28/H28 -> 0 | L28: =J28/H28 -> 1 | M28: 46305 | N28: 46312 | O28: =IF(OR(M28="",N28=""),"",IF($V$2<M28,0,IF($V$2>=N28,1,NETWORKDAYS.INTL(M28,$V$2,"0000110")/MAX(1,NETWORKDAYS.INTL(M28,N28,"0000110"))))) -> 0 | P28: =IF(O28="","",O28*H28) -> 0 | Q28: =K28 -> 0 | R28: =IF(O28="","",Q28-O28) -> 0 | S28: =IF(O28="","",I28-P28) -> 0 | T28: =IF(O28="","",IF(AND(O28=0,Q28=0),"لم يحن موعده",IF(R28<-0.005,"متأخر",IF(R28>0.005,"متقدم","مطابق")))) -> لم يحن موعده
E29: شبكة الصرف | F29: تركيب المناهل Manhole | G29: عدد | H29: 41 | I29: =H29-10 -> 31 | J29: =H29-I29 -> 10 | K29: =I29/H29 -> 0.75609756 | L29: =J29/H29 -> 0.24390244 | M29: 46272 | N29: 46280 | O29: =IF(OR(M29="",N29=""),"",IF($V$2<M29,0,IF($V$2>=N29,1,NETWORKDAYS.INTL(M29,$V$2,"0000110")/MAX(1,NETWORKDAYS.INTL(M29,N29,"0000110"))))) -> 1 | P29: =IF(O29="","",O29*H29) -> 41 | Q29: =K29 -> 0.75609756 | R29: =IF(O29="","",Q29-O29) -> -0.24390244 | S29: =IF(O29="","",I29-P29) -> -10 | T29: =IF(O29="","",IF(AND(O29=0,Q29=0),"لم يحن موعده",IF(R29<-0.005,"متأخر",IF(R29>0.005,"متقدم","مطابق")))) -> متأخر
F30: حفر وتمديد الخطوط الرئيسيه Main Pipe | G30: م.ط | H30: 2226 | I30: =H30-598 -> 1628 | J30: =H30-I30 -> 598 | K30: =I30/H30 -> 0.73135669 | L30: =J30/H30 -> 0.26864331 | M30: 46272 | N30: 46280 | O30: =IF(OR(M30="",N30=""),"",IF($V$2<M30,0,IF($V$2>=N30,1,NETWORKDAYS.INTL(M30,$V$2,"0000110")/MAX(1,NETWORKDAYS.INTL(M30,N30,"0000110"))))) -> 1 | P30: =IF(O30="","",O30*H30) -> 2226 | Q30: =K30 -> 0.73135669 | R30: =IF(O30="","",Q30-O30) -> -0.26864331 | S30: =IF(O30="","",I30-P30) -> -598 | T30: =IF(O30="","",IF(AND(O30=0,Q30=0),"لم يحن موعده",IF(R30<-0.005,"متأخر",IF(R30>0.005,"متقدم","مطابق")))) -> متأخر
F31: تشكيل قاع المناهل Penching | G31: عدد | H31: 41 | I31: =H31-41 -> 0 | J31: =H31-I31 -> 41 | K31: =I31/H31 -> 0 | L31: =J31/H31 -> 1 | M31: 46274 | N31: 46282 | O31: =IF(OR(M31="",N31=""),"",IF($V$2<M31,0,IF($V$2>=N31,1,NETWORKDAYS.INTL(M31,$V$2,"0000110")/MAX(1,NETWORKDAYS.INTL(M31,N31,"0000110"))))) -> 1 | P31: =IF(O31="","",O31*H31) -> 41 | Q31: =K31 -> 0 | R31: =IF(O31="","",Q31-O31) -> -1 | S31: =IF(O31="","",I31-P31) -> -41 | T31: =IF(O31="","",IF(AND(O31=0,Q31=0),"لم يحن موعده",IF(R31<-0.005,"متأخر",IF(R31>0.005,"متقدم","مطابق")))) -> متأخر
F32: تركيب الكفرات للمناهل Manhole Cover | G32: عدد | H32: 41 | I32: =H32-41 -> 0 | J32: =H32-I32 -> 41 | K32: =I32/H32 -> 0 | L32: =J32/H32 -> 1 | M32: 46280 | N32: 46282 | O32: =IF(OR(M32="",N32=""),"",IF($V$2<M32,0,IF($V$2>=N32,1,NETWORKDAYS.INTL(M32,$V$2,"0000110")/MAX(1,NETWORKDAYS.INTL(M32,N32,"0000110"))))) -> 1 | P32: =IF(O32="","",O32*H32) -> 41 | Q32: =K32 -> 0 | R32: =IF(O32="","",Q32-O32) -> -1 | S32: =IF(O32="","",I32-P32) -> -41 | T32: =IF(O32="","",IF(AND(O32=0,Q32=0),"لم يحن موعده",IF(R32<-0.005,"متأخر",IF(R32>0.005,"متقدم","مطابق")))) -> متأخر
F33: اختبارات الخطوط الرئيسية test | G33: م.ط | H33: 2226 | I33: =H33-598 -> 1628 | J33: =H33-I33 -> 598 | K33: =I33/H33 -> 0.73135669 | L33: =J33/H33 -> 0.26864331 | M33: 46310 | N33: 46325 | O33: =IF(OR(M33="",N33=""),"",IF($V$2<M33,0,IF($V$2>=N33,1,NETWORKDAYS.INTL(M33,$V$2,"0000110")/MAX(1,NETWORKDAYS.INTL(M33,N33,"0000110"))))) -> 0 | P33: =IF(O33="","",O33*H33) -> 0 | Q33: =K33 -> 0.73135669 | R33: =IF(O33="","",Q33-O33) -> 0.73135669 | S33: =IF(O33="","",I33-P33) -> 1628 | T33: =IF(O33="","",IF(AND(O33=0,Q33=0),"لم يحن موعده",IF(R33<-0.005,"متأخر",IF(R33>0.005,"متقدم","مطابق")))) -> متقدم
E34: شبكة المياه | F34: حفر وتمديد الخطوط الرئيسية Main Pipe | G34: م.ط | H34: 2800 | I34: =H34-1389 -> 1411 | J34: =H34-I34 -> 1389 | K34: =I34/H34 -> 0.50392857 | L34: =J34/H34 -> 0.49607143 | M34: 46275 | N34: 46282 | O34: =IF(OR(M34="",N34=""),"",IF($V$2<M34,0,IF($V$2>=N34,1,NETWORKDAYS.INTL(M34,$V$2,"0000110")/MAX(1,NETWORKDAYS.INTL(M34,N34,"0000110"))))) -> 1 | P34: =IF(O34="","",O34*H34) -> 2800 | Q34: =K34 -> 0.50392857 | R34: =IF(O34="","",Q34-O34) -> -0.49607143 | S34: =IF(O34="","",I34-P34) -> -1389 | T34: =IF(O34="","",IF(AND(O34=0,Q34=0),"لم يحن موعده",IF(R34<-0.005,"متأخر",IF(R34>0.005,"متقدم","مطابق")))) -> متأخر
F35: غرف المحابس valve Chamber | G35: عدد | H35: 3 | I35: =H35-3 -> 0 | J35: =H35-I35 -> 3 | K35: =I35/H35 -> 0 | L35: =J35/H35 -> 1 | M35: 46283 | N35: 46283 | O35: =IF(OR(M35="",N35=""),"",IF($V$2<M35,0,IF($V$2>=N35,1,NETWORKDAYS.INTL(M35,$V$2,"0000110")/MAX(1,NETWORKDAYS.INTL(M35,N35,"0000110"))))) -> 1 | P35: =IF(O35="","",O35*H35) -> 3 | Q35: =K35 -> 0 | R35: =IF(O35="","",Q35-O35) -> -1 | S35: =IF(O35="","",I35-P35) -> -3 | T35: =IF(O35="","",IF(AND(O35=0,Q35=0),"لم يحن موعده",IF(R35<-0.005,"متأخر",IF(R35>0.005,"متقدم","مطابق")))) -> متأخر
F36: المحابس valve | G36: عدد | H36: 19 | I36: =H36-19 -> 0 | J36: =H36-I36 -> 19 | K36: =I36/H36 -> 0 | L36: =J36/H36 -> 1 | M36: 46283 | N36: 46290 | O36: =IF(OR(M36="",N36=""),"",IF($V$2<M36,0,IF($V$2>=N36,1,NETWORKDAYS.INTL(M36,$V$2,"0000110")/MAX(1,NETWORKDAYS.INTL(M36,N36,"0000110"))))) -> 1 | P36: =IF(O36="","",O36*H36) -> 19 | Q36: =K36 -> 0 | R36: =IF(O36="","",Q36-O36) -> -1 | S36: =IF(O36="","",I36-P36) -> -19 | T36: =IF(O36="","",IF(AND(O36=0,Q36=0),"لم يحن موعده",IF(R36<-0.005,"متأخر",IF(R36>0.005,"متقدم","مطابق")))) -> متأخر
F37: تركيب غرف المحابس valve Chamber | G37: عدد | H37: 3 | I37: =H37-3 -> 0 | J37: =H37-I37 -> 3 | K37: =I37/H37 -> 0 | L37: =J37/H37 -> 1 | M37: 46283 | N37: 46290 | O37: =IF(OR(M37="",N37=""),"",IF($V$2<M37,0,IF($V$2>=N37,1,NETWORKDAYS.INTL(M37,$V$2,"0000110")/MAX(1,NETWORKDAYS.INTL(M37,N37,"0000110"))))) -> 1 | P37: =IF(O37="","",O37*H37) -> 3 | Q37: =K37 -> 0 | R37: =IF(O37="","",Q37-O37) -> -1 | S37: =IF(O37="","",I37-P37) -> -3 | T37: =IF(O37="","",IF(AND(O37=0,Q37=0),"لم يحن موعده",IF(R37<-0.005,"متأخر",IF(R37>0.005,"متقدم","مطابق")))) -> متأخر
F38: تركيب طفايات الحريق Fire | G38: عدد | H38: 16 | I38: =H38-16 -> 0 | J38: =H38-I38 -> 16 | K38: =I38/H38 -> 0 | L38: =J38/H38 -> 1 | M38: 46296 | N38: 46304 | O38: =IF(OR(M38="",N38=""),"",IF($V$2<M38,0,IF($V$2>=N38,1,NETWORKDAYS.INTL(M38,$V$2,"0000110")/MAX(1,NETWORKDAYS.INTL(M38,N38,"0000110"))))) -> 0 | P38: =IF(O38="","",O38*H38) -> 0 | Q38: =K38 -> 0 | R38: =IF(O38="","",Q38-O38) -> 0 | S38: =IF(O38="","",I38-P38) -> 0 | T38: =IF(O38="","",IF(AND(O38=0,Q38=0),"لم يحن موعده",IF(R38<-0.005,"متأخر",IF(R38>0.005,"متقدم","مطابق")))) -> لم يحن موعده
F39: اختبارات الخطوط test | G39: م.ط | H39: 2800 | I39: =H39-2800 -> 0 | J39: =H39-I39 -> 2800 | K39: =I39/H39 -> 0 | L39: =J39/H39 -> 1 | M39: 46310 | N39: 46325 | O39: =IF(OR(M39="",N39=""),"",IF($V$2<M39,0,IF($V$2>=N39,1,NETWORKDAYS.INTL(M39,$V$2,"0000110")/MAX(1,NETWORKDAYS.INTL(M39,N39,"0000110"))))) -> 0 | P39: =IF(O39="","",O39*H39) -> 0 | Q39: =K39 -> 0 | R39: =IF(O39="","",Q39-O39) -> 0 | S39: =IF(O39="","",I39-P39) -> 0 | T39: =IF(O39="","",IF(AND(O39=0,Q39=0),"لم يحن موعده",IF(R39<-0.005,"متأخر",IF(R39>0.005,"متقدم","مطابق")))) -> لم يحن موعده
E40: شبكة الري | F40: حفر وتمديد الخطوط الرئيسية Main Pipe | G40: م.ط | H40: 3634 | I40: =H40-3634 -> 0 | J40: =H40-I40 -> 3634 | K40: =I40/H40 -> 0 | L40: =J40/H40 -> 1 | M40: 46283 | N40: 46290 | O40: =IF(OR(M40="",N40=""),"",IF($V$2<M40,0,IF($V$2>=N40,1,NETWORKDAYS.INTL(M40,$V$2,"0000110")/MAX(1,NETWORKDAYS.INTL(M40,N40,"0000110"))))) -> 1 | P40: =IF(O40="","",O40*H40) -> 3634 | Q40: =K40 -> 0 | R40: =IF(O40="","",Q40-O40) -> -1 | S40: =IF(O40="","",I40-P40) -> -3634 | T40: =IF(O40="","",IF(AND(O40=0,Q40=0),"لم يحن موعده",IF(R40<-0.005,"متأخر",IF(R40>0.005,"متقدم","مطابق")))) -> متأخر
...

Sheet Sheet2
A1: اسم المعده | B1: العدد
A2: حفار | B2: 20
A3: شيول | B3: 5
A4: جريدر | B4: 5
A5: جي سي بي | B5: 3
A6: رصاصة | B6: 5
A7: بلدوزر | B7: 10
A8: تانكر مياه | B8: 5
A9: قلاب | B9: 10
A10: مضخة | B10: 10
A11: كرين | B11: 3
A12: سطحة | B12: 3
A13: مولد كهربائي | B13: 3
... A16: اجمالي العمالة | B16: 208
A17: اجمالي المعدات | B17: =SUM(B2:B14) -> 84

Sheet ملخص الانحراف
A1: ملخص الانحراف بين المخطط والمنفذ لكل طريق — Block J
A2: تاريخ التحديث | B2: =Sheet3!V2 -> 46294
A4: الطريق | B4: عدد البنود | C4: متوسط المخطط % | D4: متوسط المنفذ % | E4: الفرق % (منفذ − مخطط) | F4: بنود متأخرة | G4: بنود مطابقة / متقدمة | H4: بنود لم يحن موعدها
A5: RD10 | B5: =COUNTA(Sheet3!F2:F20) -> 19 | C5: =AVERAGE(Sheet3!O2:O20) -> 0.71929825 | D5: =AVERAGE(Sheet3!Q2:Q20) -> 0.18812702 | E5: =D5-C5 -> -0.53117122 | F5: =COUNTIF(Sheet3!T2:T20,"متأخر") -> 14 | G5: =COUNTIF(Sheet3!T2:T20,"مطابق")+COUNTIF(Sheet3!T2:T20,"متقدم") -> 0 | H5: =COUNTIF(Sheet3!T2:T20,"لم يحن موعده") -> 5
A6: RD9 | B6: =COUNTA(Sheet3!F21:F59) -> 39 | C6: =AVERAGE(Sheet3!O21:O59) -> 0.74426451 | D6: =AVERAGE(Sheet3!Q21:Q59) -> 0.17037892 | E6: =D6-C6 -> -0.57388558 | F6: =COUNTIF(Sheet3!T21:T59,"متأخر") -> 30 | G6: =COUNTIF(Sheet3!T21:T59,"مطابق")+COUNTIF(Sheet3!T21:T59,"متقدم") -> 1 | H6: =COUNTIF(Sheet3!T21:T59,"لم يحن موعده") -> 8
A7: RD11 | B7: =COUNTA(Sheet3!F60:F62) -> 3 | C7: =AVERAGE(Sheet3!O60:O62) -> 0.33333333 | D7: =AVERAGE(Sheet3!Q60:Q62) -> 0.33333333 | E7: =D7-C7 -> 0 | F7: =COUNTIF(Sheet3!T60:T62,"متأخر") -> 0 | G7: =COUNTIF(Sheet3!T60:T62,"مطابق")+COUNTIF(Sheet3!T60:T62,"متقدم") -> 1 | H7: =COUNTIF(Sheet3!T60:T62,"لم يحن موعده") -> 2
A8: RD14 | B8: =COUNTA(Sheet3!F63:F65) -> 3 | C8: =AVERAGE(Sheet3!O63:O65) -> 0.66666667 | D8: =AVERAGE(Sheet3!Q63:Q65) -> 0.13541874 | E8: =D8-C8 -> -0.53124792 | F8: =COUNTIF(Sheet3!T63:T65,"متأخر") -> 2 | G8: =COUNTIF(Sheet3!T63:T65,"مطابق")+COUNTIF(Sheet3!T63:T65,"متقدم") -> 0 | H8: =COUNTIF(Sheet3!T63:T65,"لم يحن موعده") -> 1
A9: RD15 | B9: =COUNTA(Sheet3!F66:F67) -> 2 | C9: =AVERAGE(Sheet3!O66:O67) -> 0.5 | D9: =AVERAGE(Sheet3!Q66:Q67) -> 0.5 | E9: =D9-C9 -> 0 | F9: =COUNTIF(Sheet3!T66:T67,"متأخر") -> 0 | G9: =COUNTIF(Sheet3!T66:T67,"مطابق")+COUNTIF(Sheet3!T66:T67,"متقدم") -> 1 | H9: =COUNTIF(Sheet3!T66:T67,"لم يحن موعده") -> 1
A10: RD16 | B10: =COUNTA(Sheet3!F68:F69) -> 2 | C10: =AVERAGE(Sheet3!O68:O69) -> 0.5 | D10: =AVERAGE(Sheet3!Q68:Q69) -> 0.5 | E10: =D10-C10 -> 0 | F10: =COUNTIF(Sheet3!T68:T69,"متأخر") -> 0 | G10: =COUNTIF(Sheet3!T68:T69,"مطابق")+COUNTIF(Sheet3!T68:T69,"متقدم") -> 1 | H10: =COUNTIF(Sheet3!T68:T69,"لم يحن موعده") -> 1
A11: RD17 | B11: =COUNTA(Sheet3!F70:F71) -> 2 | C11: =AVERAGE(Sheet3!O70:O71) -> 0.5 | D11: =AVERAGE(Sheet3!Q70:Q71) -> 0.5 | E11: =D11-C11 -> 0 | F11: =COUNTIF(Sheet3!T70:T71,"متأخر") -> 0 | G11: =COUNTIF(Sheet3!T70:T71,"مطابق")+COUNTIF(Sheet3!T70:T71,"متقدم") -> 1 | H11: =COUNTIF(Sheet3!T70:T71,"لم يحن موعده") -> 1
A12: RD18 | B12: =COUNTA(Sheet3!F72:F73) -> 2 | C12: =AVERAGE(Sheet3!O72:O73) -> 0.5 | D12: =AVERAGE(Sheet3!Q72:Q73) -> 0.5 | E12: =D12-C12 -> 0 | F12: =COUNTIF(Sheet3!T72:T73,"متأخر") -> 0 | G12: =COUNTIF(Sheet3!T72:T73,"مطابق")+COUNTIF(Sheet3!T72:T73,"متقدم") -> 1 | H12: =COUNTIF(Sheet3!T72:T73,"لم يحن موعده") -> 1
A13: RD23 | B13: =COUNTA(Sheet3!F74:F87) -> 14 | C13: =AVERAGE(Sheet3!O74:O87) -> 0.44047619 | D13: =AVERAGE(Sheet3!Q74:Q87) -> 0.29996546 | E13: =D13-C13 -> -0.14051074 | F13: =COUNTIF(Sheet3!T74:T87,"متأخر") -> 6 | G13: =COUNTIF(Sheet3!T74:T87,"مطابق")+COUNTIF(Sheet3!T74:T87,"متقدم") -> 4 | H13: =COUNTIF(Sheet3!T74:T87,"لم يحن موعده") -> 4
A14: RDEXT | B14: =COUNTA(Sheet3!F88:F90) -> 3 | C14: =AVERAGE(Sheet3!O88:O90) -> 0.33333333 | D14: =AVERAGE(Sheet3!Q88:Q90) -> 0.20463847 | E14: =D14-C14 -> -0.12869486 | F14: =COUNTIF(Sheet3!T88:T90,"متأخر") -> 1 | G14: =COUNTIF(Sheet3!T88:T90,"مطابق")+COUNTIF(Sheet3!T88:T90,"متقدم") -> 1 | H14: =COUNTIF(Sheet3!T88:T90,"لم يحن موعده") -> 1
A15: Lift Station | B15: =COUNTA(Sheet3!F91:F93) -> 3 | C15: =AVERAGE(Sheet3!O91:O93) -> 0.54901961 | D15: =AVERAGE(Sheet3!Q91:Q93) -> 0.43333333 | E15: =D15-C15 -> -0.11568627 | F15: =COUNTIF(Sheet3!T91:T93,"متأخر") -> 1 | G15: =COUNTIF(Sheet3!T91:T93,"مطابق")+COUNTIF(Sheet3!T91:T93,"متقدم") -> 1 | H15: =COUNTIF(Sheet3!T91:T93,"لم يحن موعده") -> 1
A16: الإجمالي | B16: =SUM(B5:B15) -> 92 | C16: =AVERAGE(Sheet3!O2:O93) -> 0.63594248 | D16: =AVERAGE(Sheet3!Q2:Q93) -> 0.23629217 | E16: =D16-C16 -> -0.39965031 | F16: =SUM(F5:F15) -> 54 | G16: =SUM(G5:G15) -> 12 | H16: =SUM(H5:H15) -> 26
