Workbook
Name _1B.05.M.010.0010: #REF!
Name _1B.05.M.010.0010: #REF!
Name _1B.05.M.010.0010: #REF!
Name _1B.05.M.010.0010: #REF!
Name _1B.05.M.010.0050: #REF!
Name _1B.05.M.010.0050: #REF!
Name _1B.05.M.010.0050: #REF!
Name _1B.05.M.010.0050: #REF!
Name _1B.05.M.0100.0010: #REF!
Name _1B.05.M.0100.0010: #REF!
Name _1B.05.M.020.0010: #REF!
Name _1B.05.M.020.0010: #REF!
Name _1B.05.M.020.0020: #REF!
Name _1B.05.M.020.0020: #REF!
Name _1B.05.M.020.0030: #REF!
Name _1B.05.M.020.0030: #REF!
Name _1B.05.M.020.0040: #REF!
Name _1B.05.M.020.0040: #REF!
Name _1B.05.M.030.0010: #REF!
Name _1B.05.M.030.0010: #REF!
Name _1B.05.M.030.0020: #REF!
Name _1B.05.M.030.0020: #REF!
Name _1B.05.M.040.0010: #REF!
Name _1B.05.M.040.0010: #REF!
Name _1B.05.M.050.0010: #REF!
Name _1B.05.M.050.0010: #REF!
Name _1B.05.M.050.0020: #REF!
Name _1B.05.M.050.0020: #REF!
Name _1B.05.M.050.0030: #REF!
Name _1B.05.M.050.0030: #REF!
Name _1B.05.M.060.0020: #REF!
Name _1B.05.M.060.0020: #REF!
Name _1B.05.M.060.0100: #REF!
Name _1B.05.M.060.0100: #REF!
Name _1B.05.M.070.0010: #REF!
Name _1B.05.M.070.0010: #REF!
Name _1B.05.M.070.0020: #REF!
Name _1B.05.M.070.0020: #REF!
Name _1B.05.M.070.0030: #REF!
Name _1B.05.M.070.0030: #REF!
Name _1B.05.M.070.0040: #REF!
Name _1B.05.M.070.0040: #REF!
Name _1B.05.M.070.0050: #REF!
Name _1B.05.M.070.0050: #REF!
Name _1B.05.M.080.0010: #REF!
Name _1B.05.M.080.0010: #REF!
Name _1B.05.M.090.0010: #REF!
Name _1B.05.M.090.0010: #REF!
Name _1B.09.P.010.0010: #REF!
Name _1B.09.P.010.0010: #REF!
Name _1B.09.P.010.0020: #REF!
Name _1B.09.P.010.0020: #REF!
Name _1B.09.P.010.0030: #REF!
Name _1B.09.P.010.0030: #REF!
Name _1B.09.P.010.0040: #REF!
Name _1B.09.P.010.0040: #REF!
Name _1B.09.P.010.0050: #REF!
Name _1B.09.P.010.0050: #REF!
Name _1B.09.P.010.0060: #REF!
Name _1B.09.P.010.0060: #REF!

Sheet DB
A1: ='Weekly Progress Report'!$A$1 -> MODON - Weekly Progress Report - Construction Projects
B2: ='Weekly Progress Report'!$A$2 -> Contract General Information | J2: ='Weekly Progress Report'!G2 -> Key Dates | U2: ='Weekly Progress Report'!$M$2 -> Cost Summary (SR) | AD2: ='Weekly Progress Report'!$U$2 -> Performance Summary | AP2: ='Weekly Progress Report'!A59 -> Shop Drawings | AT2: ='Weekly Progress Report'!A68 -> Material Approval | AW2: ='Weekly Progress Report'!A77 -> Procurement Summary | BD2: ='Weekly Progress Report'!L59 -> Quality Reports | BT2: ='Weekly Progress Report'!L67 -> Key Submittals Approval Status | CD2: ='Weekly Progress Report'!L73 -> Invoices Summary | CR2: ='Weekly Progress Report'!L81 -> Resources at Site | CY2: ='Weekly Progress Report'!W59 -> Safety Statistics | FK2: ='Weekly Progress Report'!A86 -> Primavera P6 Schedule Status | FS2: ='Weekly Progress Report'!A95 -> Weekly Prgoress Photos
A3: ='Weekly Progress Report'!AF1 -> Data Date | B3: ='Weekly Progress Report'!A3 -> Project Name | C3: ='Weekly Progress Report'!A4 -> Project ID | D3: ='Weekly Progress Report'!A5 -> Contractor | E3: ='Weekly Progress Report'!A6 -> Consultant | F3: ='Weekly Progress Report'!D4 -> Stage | G3: ='Weekly Progress Report'!D5 -> Status | H3: ='Weekly Progress Report'!D6 -> Modon PM | I3: ='Weekly Progress Report'!AA2 -> Project Scope | J3: ='Weekly Progress Report'!G3 -> Contract Award | K3: ='Weekly Progress Report'!G4 -> Contract Sign | L3: ='Weekly Progress Report'!G5 -> Site Handover | M3: ='Weekly Progress Report'!G6 -> Original Completion | N3: ='Weekly Progress Report'!$I$3 -> Contract Award (Hijri) | O3: ='Weekly Progress Report'!$I$4 -> Contract Sign (Hijri) | P3: ='Weekly Progress Report'!$I$5 -> Site Handover (Hijri) | Q3: ='Weekly Progress Report'!$I$6 -> Original Completion (Hijri) | R3: ='Weekly Progress Report'!$K$3 -> Revised Completion | S3: ='Weekly Progress Report'!$K$4 -> Committed Completion | T3: ='Weekly Progress Report'!$K$5 -> Forecast Completion | U3: ='Weekly Progress Report'!$M$3 -> Original Contract Value | V3: ='Weekly Progress Report'!$M$4 -> Revised Contract Value | W3: ='Weekly Progress Report'!$M$5 -> Estimate At Completion Value | X3: ='Weekly Progress Report'!$M$6 -> Potential Changes | Y3: ='Weekly Progress Report'!$Q$3 -> O&M Value (if any) | Z3: ='Weekly Progress Report'!$Q$4 -> Submitted Invoices (Gross Value) | AA3: ='Weekly Progress Report'!$Q$5 -> Penalities | AB3: ='Weekly Progress Report'!$Q$6 -> FIR Value (Todate) | AC3: Original Plan Value | AD3: ='Weekly Progress Report'!$U$3 -> Plan Value | AE3: ='Weekly Progress Report'!$U$4 -> Earn Value | AF3: ='Weekly Progress Report'!$W$3 -> Phys. Plan Value | AG3: ='Weekly Progress Report'!$W$4 -> Phys. Earn Value | AH3: ='Weekly Progress Report'!$Y$3 -> Quality Score | AI3: ='Weekly Progress Report'!$Y$5 -> Safety Score | AJ3: Weekly PV (SAR) | AK3: Weekly EV (SAR) | AL3: Weekly PV % | AM3: Weekly PV % | AN3: Weekly Phys PV% | AO3: Weekly Phys PV% | AP3: Total SD Planned | AQ3: SD Remaining | AR3: SD Pending | AS3: Total SD Submittals | AT3: Planned Materials Approv | AU3: Material Pending Approval | AV3: Materila Total Submittals | AW3: ='Weekly Progress Report'!C78 -> Total Materials | AX3: ='Weekly Progress Report'!D78 -> Total Number of P.O. | AY3: ='Weekly Progress Report'!E78 -> Actual P.O. To Date | AZ3: ='Weekly Progress Report'!F78 -> Remaining P.O | BA3: ='Weekly Progress Report'!G78 -> Material on Site | BB3: ='Weekly Progress Report'!H78 -> Remaining Materials | BC3: ='Weekly Progress Report'!I78 -> Material Delivery Completion (Date) | BD3: ="NCR "&'Weekly Progress Report'!N60 -> NCR Issued | BE3: ="NCR "&'Weekly Progress Report'!O60 -> NCR Closed | BF3: ="NCR "&'Weekly Progress Report'!P60 -> NCR Pending | BG3: ="NCR "&'Weekly Progress Report'!Q60 -> NCR Avg. Closing (Days) | BH3: ="SIR "&'Weekly Progress Report'!N60 -> SIR Issued | BI3: ="SIR "&'Weekly Progress Report'!O60 -> SIR Closed | BJ3: ="SIR "&'Weekly Progress Report'!P60 -> SIR Pending | BK3: ="SIR "&'Weekly Progress Report'!Q60 -> SIR Avg. Closing (Days) | BL3: ="MIR "&'Weekly Progress Report'!N60 -> MIR Issued | BM3: ="MIR "&'Weekly Progress Report'!O60 -> MIR Closed | BN3: ="MIR "&'Weekly Progress Report'!P60 -> MIR Pending | BO3: ="MIR "&'Weekly Progress Report'!Q60 -> MIR Avg. Closing (Days) | BP3: ="FIR "&'Weekly Progress Report'!N60 -> FIR Issued | BQ3: ="FIR "&'Weekly Progress Report'!O60 -> FIR Closed | BR3: ="FIR "&'Weekly Progress Report'!P60 -> FIR Pending | BS3: ="FIR "&'Weekly Progress Report'!Q60 -> FIR Avg. Closing (Days) | BT3: ='Weekly Progress Report'!L68 -> 1 Quality Plan Approval | BU3: ='Weekly Progress Report'!L69 -> 2 Quality Plan Last Up | BV3: ='Weekly Progress Report'!L70 -> 3 Safety Plan Approval | BW3: ='Weekly Progress Report'!L71 -> 4 Safety Plan Last Up | BX3: ='Weekly Progress Report'!L72 -> 5 Construction Plan Approval | BY3: ='Weekly Progress Report'!Q68 -> 6 Baseline Approval | BZ3: ='Weekly Progress Report'!Q69 -> 7 No of Approved Version of Schedule | CA3: ='Weekly Progress Report'!Q70 -> 8 Last Approved Schedule | CB3: ='Weekly Progress Report'!Q71 -> 9 BOQ Approval Date | CC3: ='Weekly Progress Report'!Q72 -> 10 No of Approved Version of BOQ | CD3: ='Weekly Progress Report'!L74 -> Total Submitted Invoices | CE3: ='Weekly Progress Report'!L75 -> PM Approved Invoices | CF3: ='Weekly Progress Report'!L76 -> No of Paid Invoices | CG3: ='Weekly Progress Report'!L77 -> No of Pending Invoices | CH3: ='Weekly Progress Report'!L78 -> Advance Payment % | CI3: ='Weekly Progress Report'!L79 -> Retention % | CJ3: ='Weekly Progress Report'!L80 -> Deduction / Penalties % | CK3: ='Weekly Progress Report'!O74 -> Submitted Invoices (SAR) | CL3: ='Weekly Progress Report'!O75 -> PM Approved Invoices (SAR) | CM3: ='Weekly Progress Report'!O76 -> Paid Invoices (SAR) | CN3: ='Weekly Progress Report'!O77 -> Last Submitted Period | CO3: ='Weekly Progress Report'!O78 -> Advance Payment (SAR) | CP3: ='Weekly Progress Report'!O79 -> Retention (SAR) | CQ3: ='Weekly Progress Report'!O80 -> Deduction / Penalties (SAR) | CR3: Planned Head Count | CS3: Actual Head Count | CT3: Saudi Staff | CU3: Labor Planned | CV3: Labor Actual | CW3: Equipment Planned | CX3: Equipment Actual | CY3: ="This Week "&'Weekly Progress Report'!X62 -> This Week Total Hours Worked | CZ3: ="This Week "&'Weekly Progress Report'!X63 -> This Week Safe Hours Worked | DA3: ="This Week "&'Weekly Progress Report'!X64 -> This Week LTI | DB3: ="This Week "&'Weekly Progress Report'!X65 -> This Week MTC (Healed w/o Disability) | DC3: ="This Week "&'Weekly Progress Report'!X66 -> This Week MTC (Healed w/ Disability) | DD3: ="This Week "&'Weekly Progress Report'!X67 -> This Week Near Miss | DE3: ="This Week "&'Weekly Progress Report'!X68 -> This Week First Aid Cases | DF3: ="This Week "&'Weekly Progress Report'!X69 -> This Week Fatality | DG3: ="This Week "&'Weekly Progress Report'!X70 -> This Week Fire Incident Cases | DH3: ="This Week "&'Weekly Progress Report'!X71 -> This Week Vehicle Incident | DI3: ="This Week "&'Weekly Progress Report'!X72 -> This Week Property Damages | DJ3: ="This Week "&'Weekly Progress Report'!X73 -> This Week Induction Training | DK3: ="This Week "&'Weekly Progress Report'!X74 -> This Week No.of Internal Training | DL3: ="This Week "&'Weekly Progress Report'!X75 -> This Week No.of Internal Audit | DM3: ="This Week "&'Weekly Progress Report'!X76 -> This Week No. of Toolbox Talks | DN3: ="This Week "&'Weekly Progress Report'!X77 -> This Week Safety Awards/Incentives | DO3: ="This Month "&'Weekly Progress Report'!X62 -> This Month Total Hours Worked | DP3: ="This Month "&'Weekly Progress Report'!X63 -> This Month Safe Hours Worked | DQ3: ="This Month "&'Weekly Progress Report'!X64 -> This Month LTI | DR3: ="This Month "&'Weekly Progress Report'!X65 -> This Month MTC (Healed w/o Disability) | DS3: ="This Month "&'Weekly Progress Report'!X66 -> This Month MTC (Healed w/ Disability) | DT3: ="This Month "&'Weekly Progress Report'!X67 -> This Month Near Miss | DU3: ="This Month "&'Weekly Progress Report'!X68 -> This Month First Aid Cases | DV3: ="This Month "&'Weekly Progress Report'!X69 -> This Month Fatality | DW3: ="This Month "&'Weekly Progress Report'!X70 -> This Month Fire Incident Cases | DX3: ="This Month "&'Weekly Progress Report'!X71 -> This Month Vehicle Incident | DY3: ="This Month "&'Weekly Progress Report'!X72 -> This Month Property Damages | DZ3: ="This Month "&'Weekly Progress Report'!X73 -> This Month Induction Training | EA3: ="This Month "&'Weekly Progress Report'!X74 -> This Month No.of Internal Training | EB3: ="This Month "&'Weekly Progress Report'!X75 -> This Month No.of Internal Audit | EC3: ="This Month "&'Weekly Progress Report'!X76 -> This Month No. of Toolbox Talks | ED3: ="This Month "&'Weekly Progress Report'!X77 -> This Month Safety Awards/Incentives | EE3: ="YTD "&'Weekly Progress Report'!X62 -> YTD Total Hours Worked | EF3: ="YTD "&'Weekly Progress Report'!X63 -> YTD Safe Hours Worked | EG3: ="YTD "&'Weekly Progress Report'!X64 -> YTD LTI | EH3: ="YTD "&'Weekly Progress Report'!X65 -> YTD MTC (Healed w/o Disability) | EI3: ="YTD "&'Weekly Progress Report'!X66 -> YTD MTC (Healed w/ Disability) | EJ3: ="YTD "&'Weekly Progress Report'!X67 -> YTD Near Miss | EK3: ="YTD "&'Weekly Progress Report'!X68 -> YTD First Aid Cases | EL3: ="YTD "&'Weekly Progress Report'!X69 -> YTD Fatality | EM3: ="YTD "&'Weekly Progress Report'!X70 -> YTD Fire Incident Cases | EN3: ="YTD "&'Weekly Progress Report'!X71 -> YTD Vehicle Incident | EO3: ="YTD "&'Weekly Progress Report'!X72 -> YTD Property Damages | EP3: ="YTD "&'Weekly Progress Report'!X73 -> YTD Induction Training | EQ3: ="YTD "&'Weekly Progress Report'!X74 -> YTD No.of Internal Training | ER3: ="YTD "&'Weekly Progress Report'!X75 -> YTD No.of Internal Audit | ES3: ="YTD "&'Weekly Progress Report'!X76 -> YTD No. of Toolbox Talks | ET3: ="YTD "&'Weekly Progress Report'!X77 -> YTD Safety Awards/Incentives | EU3: ="Cum "&'Weekly Progress Report'!X62 -> Cum Total Hours Worked | EV3: ="Cum "&'Weekly Progress Report'!X63 -> Cum Safe Hours Worked | EW3: ="Cum "&'Weekly Progress Report'!X64 -> Cum LTI | EX3: ="Cum "&'Weekly Progress Report'!X65 -> Cum MTC (Healed w/o Disability) | EY3: ="Cum "&'Weekly Progress Report'!X66 -> Cum MTC (Healed w/ Disability) | EZ3: ="Cum "&'Weekly Progress Report'!X67 -> Cum Near Miss | FA3: ="Cum "&'Weekly Progress Report'!X68 -> Cum First Aid Cases | FB3: ="Cum "&'Weekly Progress Report'!X69 -> Cum Fatality | FC3: ="Cum "&'Weekly Progress Report'!X70 -> Cum Fire Incident Cases | FD3: ="Cum "&'Weekly Progress Report'!X71 -> Cum Vehicle Incident | FE3: ="Cum "&'Weekly Progress Report'!X72 -> Cum Property Damages | FF3: ="Cum "&'Weekly Progress Report'!X73 -> Cum Induction Training | FG3: ="Cum "&'Weekly Progress Report'!X74 -> Cum No.of Internal Training | FH3: ="Cum "&'Weekly Progress Report'!X75 -> Cum No.of Internal Audit | FI3: ="Cum "&'Weekly Progress Report'!X76 -> Cum No. of Toolbox Talks | FJ3: ="Cum "&'Weekly Progress Report'!X77 -> Cum Safety Awards/Incentives | FK3: ='Weekly Progress Report'!A89 -> Total Act. | FL3: ='Weekly Progress Report'!B89 -> Not Started | FM3: ='Weekly Progress Report'!C89 -> In Progress | FN3: ='Weekly Progress Report'!D89 -> Completed | FO3: Critical Path Act.Last Week | FP3: Critical Path Act.This Week | FQ3: Failed start Last Week | FR3: Failed start This Week | FS3: ='Weekly Progress Report'!B97 -> 0 | FT3: ='Weekly Progress Report'!D97 -> 0 | FU3: ='Weekly Progress Report'!F97 -> 0 | FV3: ='Weekly Progress Report'!H97 -> 0 | FW3: ='Weekly Progress Report'!J97 -> 0 | FX3: ='Weekly Progress Report'!L97 -> 0 | FY3: ='Weekly Progress Report'!N97 -> 0 | FZ3: ='Weekly Progress Report'!O97 -> 0 | GA3: ='Weekly Progress Report'!P97 -> 0
A4: ='Weekly Progress Report'!AG1 -> 46301 | B4: ='Weekly Progress Report'!B3 -> Development of Infrastructure for phase 1 of the Logistics area at the 2nd Industrial City in Dammam | C4: ='Weekly Progress Report'!B4 -> DAM2-02-009 | D4: ='Weekly Progress Report'!B5 -> Shibh Aljazira Contracting Company | E4: ='Weekly Progress Report'!B6 -> Egis | F4: ='Weekly Progress Report'!E4 -> Construction | G4: ='Weekly Progress Report'!E5 -> Active | H4: ='Weekly Progress Report'!E6 -> Muhammad H Al-Essa | I4: ='Weekly Progress Report'!AA3 -> The project consists of the wet networks mainlines (Sewerage, Storm, Potable, Firefighting & TSE) including the force main line, in addition to the dry networks (Medium Voltage, Low Voltage, Street Lighting & Telecommunication) road crossings & main line connections, scope also included supply, install, testing & commissioning for the potable water pump station and the sewage lift station and implementation of guard rooms and applying all the road earth layers till the asphalt wearing coarse for the project scope area internal roads & finishing the landscape | J4: ='Weekly Progress Report'!H3 -> 45838 | K4: ='Weekly Progress Report'!H4 -> 45852 | L4: ='Weekly Progress Report'!H5 -> 45868 | M4: ='Weekly Progress Report'!H6 -> 46416 | N4: ='Weekly Progress Report'!$J$3 -> 45838 | O4: ='Weekly Progress Report'!$J$4 -> 45852 | P4: ='Weekly Progress Report'!$J$5 -> 45868 | Q4: ='Weekly Progress Report'!$J$6 -> 46416 | R4: ='Weekly Progress Report'!$L$3 -> 46416 | S4: ='Weekly Progress Report'!$L$4 -> 46416 | T4: ='Weekly Progress Report'!$L$5 -> 46418 | U4: ='Weekly Progress Report'!$O$3 -> 1.9890616e+08 | V4: ='Weekly Progress Report'!$O$4 -> 1.9890616e+08 | W4: ='Weekly Progress Report'!$O$5 -> 1.9890616e+08 | X4: ='Weekly Progress Report'!$O$6 -> 0 | Y4: ='Weekly Progress Report'!$S$3 -> 0 | Z4: ='Weekly Progress Report'!$S$4 -> 62889674 | AA4: ='Weekly Progress Report'!$S$5 -> -104500 | AB4: ='Weekly Progress Report'!$S$6 -> 77303418 | AC4: ='Weekly Progress Report'!$J$29 -> 0.72325518 | AD4: ='Weekly Progress Report'!$V$3 -> 0.72325518 | AE4: ='Weekly Progress Report'!$V$4 -> 0.51489574 | AF4: ='Weekly Progress Report'!$X$3 -> 0.60876731 | AG4: ='Weekly Progress Report'!$X$4 -> 0.42474035 | AH4: ='Weekly Progress Report'!$Z$3 -> 0.93 | AI4: ='Weekly Progress Report'!$Z$5 -> 0.92857143 | AJ4: ='Weekly Progress Report'!$E$29 -> -27037643 | AK4: ='Weekly Progress Report'!$F$29 -> -17134541 | AL4: =AJ4/V4 -> -0.13593165 | AM4: =AK4/V4 -> -0.086143842 | AN4: ='Weekly Progress Report'!S29 -> -0.30760358 | AO4: ='Weekly Progress Report'!T29 -> -0.018735675 | AP4: ='Weekly Progress Report'!C67 -> 1774 | AQ4: ='Weekly Progress Report'!I67 -> 0 | AR4: ='Weekly Progress Report'!J67 -> 0 | AS4: ='Weekly Progress Report'!K67 -> 1774 | AT4: ='Weekly Progress Report'!C76 -> 153 | AU4: ='Weekly Progress Report'!J76 -> 3 | AV4: ='Weekly Progress Report'!K76 -> 147 | AW4: ='Weekly Progress Report'!C85 -> 48 | AX4: ='Weekly Progress Report'!D85 -> 48 | AY4: ='Weekly Progress Report'!E85 -> 42 | AZ4: ='Weekly Progress Report'!F85 -> 0 | BA4: ='Weekly Progress Report'!G85 -> 21 | BB4: ='Weekly Progress Report'!H85 -> 27 | BC4: ='Weekly Progress Report'!I85 -> 46335 | BD4: ='Weekly Progress Report'!N63 -> 4 | BE4: ='Weekly Progress Report'!O63 -> 3 | BF4: ='Weekly Progress Report'!P63 -> 1 | BG4: ='Weekly Progress Report'!Q63 -> 0 | BH4: ='Weekly Progress Report'!N64 -> 50 | BI4: ='Weekly Progress Report'!O64 -> 41 | BJ4: ='Weekly Progress Report'!P64 -> 9 | BK4: ='Weekly Progress Report'!Q64 -> 0 | BL4: ='Weekly Progress Report'!N65 -> 109 | BM4: ='Weekly Progress Report'!O65 -> 108 | BN4: ='Weekly Progress Report'!P65 -> 1 | BO4: ='Weekly Progress Report'!Q65 -> 0 | BP4: ='Weekly Progress Report'!N66 -> 4296 | BQ4: ='Weekly Progress Report'!O66 -> 4128 | BR4: ='Weekly Progress Report'!P66 -> 168 | BS4: ='Weekly Progress Report'!Q66 -> 0 | BT4: ='Weekly Progress Report'!O68 -> 45346 | BU4: ='Weekly Progress Report'!O69 -> 45346 | BV4: ='Weekly Progress Report'!O70 -> 45350 | BW4: ='Weekly Progress Report'!O71 -> 45350 | BX4: ='Weekly Progress Report'!O72 -> 45348 | BY4: ='Weekly Progress Report'!U68 -> 45361 | BZ4: ='Weekly Progress Report'!U69 -> 1 | CA4: ='Weekly Progress Report'!U70 -> 45361 | CB4: ='Weekly Progress Report'!U71 -> 0 | CC4: ='Weekly Progress Report'!U72 -> 1 | CD4: ='Weekly Progress Report'!N74 -> 6 | CE4: ='Weekly Progress Report'!N75 -> 0 | CF4: ='Weekly Progress Report'!N76 -> 0 | CG4: ='Weekly Progress Report'!N77 -> 0 | CH4: ='Weekly Progress Report'!N78 -> 0 | CI4: ='Weekly Progress Report'!N79 -> 0 | CJ4: ='Weekly Progress Report'!N80 -> 0.00052537337 | CK4: ='Weekly Progress Report'!R74 -> 62889674 | CL4: ='Weekly Progress Report'!R75 -> 0 | CM4: ='Weekly Progress Report'!R76 -> 0 | CN4: ='Weekly Progress Report'!R77 -> 46280 | CO4: ='Weekly Progress Report'!R78 -> 0 | CP4: ='Weekly Progress Report'!R79 -> 0 | CQ4: ='Weekly Progress Report'!R80 -> -104500 | CR4: ='Weekly Progress Report'!L84 -> 35 | CS4: ='Weekly Progress Report'!M84 -> 57 | CT4: ='Weekly Progress Report'!O84 -> 4 | CU4: ='Weekly Progress Report'!P84 -> 360 | CV4: ='Weekly Progress Report'!Q84 -> 483 | CW4: ='Weekly Progress Report'!T94 -> 150 | CX4: ='Weekly Progress Report'!U94 -> 326 | CY4: ='Weekly Progress Report'!Z62 -> 34740 | CZ4: ='Weekly Progress Report'!Z63 -> 34740 | DA4: ='Weekly Progress Report'!Z64 -> 0 | DB4: ='Weekly Progress Report'!Z65 -> 0 | DC4: ='Weekly Progress Report'!Z66 -> 0 | DD4: ='Weekly Progress Report'!Z67 -> 0 | DE4: ='Weekly Progress Report'!Z68 -> 0 | DF4: ='Weekly Progress Report'!Z69 -> 0 | DG4: ='Weekly Progress Report'!Z70 -> 0 | DH4: ='Weekly Progress Report'!Z71 -> 0 | DI4: ='Weekly Progress Report'!Z72 -> 0 | DJ4: ='Weekly Progress Report'!Z73 -> 29 | DK4: ='Weekly Progress Report'!Z74 -> 0 | DL4: ='Weekly Progress Report'!Z75 -> 0 | DM4: ='Weekly Progress Report'!Z76 -> 3(325) | DN4: ='Weekly Progress Report'!Z77 -> 0 | DO4: ='Weekly Progress Report'!AB62 -> 34740 | DP4: ='Weekly Progress Report'!AB63 -> 34740 | DQ4: ='Weekly Progress Report'!AB64 -> 0 | DR4: ='Weekly Progress Report'!AB65 -> 0 | DS4: ='Weekly Progress Report'!AB66 -> 0 | DT4: ='Weekly Progress Report'!AB67 -> 0 | DU4: ='Weekly Progress Report'!AB68 -> 0 | DV4: ='Weekly Progress Report'!AB69 -> 0 | DW4: ='Weekly Progress Report'!AB70 -> 0 | DX4: ='Weekly Progress Report'!AB71 -> 0 | DY4: ='Weekly Progress Report'!AB72 -> 0 | DZ4: ='Weekly Progress Report'!AB73 -> 29 | EA4: ='Weekly Progress Report'!AB74 -> 2 (9) | EB4: ='Weekly Progress Report'!AB75 -> 1 | EC4: ='Weekly Progress Report'!AB76 -> 3(325) | ED4: ='Weekly Progress Report'!AB77 -> 0 | EE4: ='Weekly Progress Report'!AC62 -> 740184 | EF4: ='Weekly Progress Report'!AC63 -> 740184 | EG4: ='Weekly Progress Report'!AC64 -> 0 | EH4: ='Weekly Progress Report'!AC65 -> 0 | EI4: ='Weekly Progress Report'!AC66 -> 0 | EJ4: ='Weekly Progress Report'!AC67 -> 0 | EK4: ='Weekly Progress Report'!AC68 -> 0 | EL4: ='Weekly Progress Report'!AC69 -> 0 | EM4: ='Weekly Progress Report'!AC70 -> 0 | EN4: ='Weekly Progress Report'!AC71 -> 0 | EO4: ='Weekly Progress Report'!AC72 -> 0 | EP4: ='Weekly Progress Report'!AC73 -> 114(531) | EQ4: ='Weekly Progress Report'!AC74 -> 5(23) | ER4: ='Weekly Progress Report'!AC75 -> 4 | ES4: ='Weekly Progress Report'!AC76 -> (40)3119 | ET4: ='Weekly Progress Report'!AC77 -> 1 | EU4: ='Weekly Progress Report'!AD62 -> 805242 | EV4: ='Weekly Progress Report'!AD63 -> 805242 | EW4: ='Weekly Progress Report'!AD64 -> 0 | EX4: ='Weekly Progress Report'!AD65 -> 0 | EY4: ='Weekly Progress Report'!AD66 -> 0 | EZ4: ='Weekly Progress Report'!AD67 -> 0 | FA4: ='Weekly Progress Report'!AD68 -> 0 | FB4: ='Weekly Progress Report'!AD69 -> 0 | FC4: ='Weekly Progress Report'!AD70 -> 0 | FD4: ='Weekly Progress Report'!AD71 -> 0 | FE4: ='Weekly Progress Report'!AD72 -> 0 | FF4: ='Weekly Progress Report'!AD73 -> 143(855) | FG4: ='Weekly Progress Report'!AD74 -> 13(98) | FH4: ='Weekly Progress Report'!AD75 -> 4 | FI4: ='Weekly Progress Report'!AD76 -> 53(8348 | FJ4: ='Weekly Progress Report'!AD77 -> 2 | FK4: ='Weekly Progress Report'!A90 -> 4851 | FL4: ='Weekly Progress Report'!B90 -> 2454 | FM4: ='Weekly Progress Report'!C90 -> 157 | FN4: ='Weekly Progress Report'!D90 -> 2240 | FO4: ='Weekly Progress Report'!A94 -> 129 | FP4: ='Weekly Progress Report'!B94 -> 45 | FQ4: ='Weekly Progress Report'!H94 -> 1796 | FR4: ='Weekly Progress Report'!I94 -> 1152 | FS4: ='Weekly Progress Report'!B102 -> 0 | FT4: ='Weekly Progress Report'!D102 -> 0 | FU4: ='Weekly Progress Report'!F102 -> 0 | FV4: ='Weekly Progress Report'!H102 -> 0 | FW4: ='Weekly Progress Report'!J102 -> 0 | FX4: ='Weekly Progress Report'!L102 -> 0 | FY4: ='Weekly Progress Report'!N102 -> 0 | FZ4: ='Weekly Progress Report'!O102 -> 0 | GA4: ='Weekly Progress Report'!P102 -> 0

Sheet Weekly Progress Report
A1: MODON - Weekly Progress Report - Construction Projects | AF1: Data Date | AG1: ='General Information'!L1 -> 46301
A2: Contract General Information | G2: Key Dates | M2: Cost Summary (SR) | U2: Performance Summary | AA2: Project Scope
A3: Project Name | B3: ='General Information'!C3 -> Development of Infrastructure for phase 1 of the Logistics area at the 2nd Industrial City in Dammam | G3: Contract Award | H3: ='General Information'!C12 -> 45838 | I3: Contract Award (Hijri) | J3: ='General Information'!C16 -> 45838 | K3: Revised Completion | L3: ='General Information'!C20 -> 46416 | M3: Original Contract Value | O3: ='Invoice Log'!E3 -> 1.9890616e+08 | Q3: O&M Value (if any) | S3: ='Invoice Log'!I3 -> 0 | T3: EAC | U3: Plan Value | V3: =K29 -> 0.72325518 | W3: Phys. Plan Value | X3: =W29 -> 0.60876731 | Y3: Quality Score | Z3: =Quality!AC10 -> 0.93 | AA3: =+Progress!B1 -> The project consists of the wet networks mainlines (Sewerage, Storm, Potable, Firefighting & TSE) including the force main line, in addition to the dry networks (Medium Voltage, Low Voltage, Street Lighting & Telecommunication) road crossings & main line connections, scope also included supply, install, testing & commissioning for the potable water pump station and the sewage lift station and implementation of guard rooms and applying all the road earth layers till the asphalt wearing coarse for the project scope area internal roads & finishing the landscape
A4: Project ID | B4: ='General Information'!C4 -> DAM2-02-009 | D4: Stage | E4: ='General Information'!C7 -> Construction | G4: Contract Sign | H4: ='General Information'!C13 -> 45852 | I4: Contract Sign (Hijri) | J4: ='General Information'!C17 -> 45852 | K4: Committed Completion | L4: ='General Information'!C21 -> 46416 | M4: Revised Contract Value | O4: ='Invoice Log'!E4 -> 1.9890616e+08 | P4: EAC | Q4: Submitted Invoices (Gross Value) | S4: ='Invoice Log'!I5 -> 62889674 | U4: Earn Value | V4: =L29 -> 0.51489574 | W4: Phys. Earn Value | X4: =X29 -> 0.42474035 | Z4: =REPT("¢",IF(INT(+Z3*10)>5,5,INT(+Z3*10)))&REPT("£",IF(INT(+Z3*10)>5,0,5-INT(+Z3*10)))&CHAR(10)&REPT("¢",+IF(INT(+Z3*10)>5,-5+INT(+Z3*10),0))&REPT("£",IF(INT(+Z3*10)>5,10-INT(+Z3*10),5)) -> ¢¢¢¢¢ ¢¢¢¢£
A5: Contractor | B5: ='General Information'!C5 -> Shibh Aljazira Contracting Company | D5: Status | E5: ='General Information'!C8 -> Active | G5: Site Handover | H5: ='General Information'!C14 -> 45868 | I5: Site Handover (Hijri) | J5: ='General Information'!C18 -> 45868 | K5: Forecast Completion | L5: ='General Information'!C22 -> 46418 | M5: Estimate At Completion Value | O5: ='Invoice Log'!E5 -> 1.9890616e+08 | P5: =+#REF!+#REF!+O5 -> #REF! | Q5: Penalities | S5: ='Invoice Log'!I6 -> -104500 | U5: Variance | V5: =V4-V3 -> -0.20835944 | W5: Variance | X5: =Y29 -> -0.18402696 | Y5: Safety Score | Z5: ='HSE-Stat'!J23 -> 0.92857143
A6: Consultant | B6: ='General Information'!C6 -> Egis | D6: Modon PM | E6: ='General Information'!C9 -> Muhammad H Al-Essa | G6: Original Completion | H6: ='General Information'!C15 -> 46416 | I6: Original Completion (Hijri) | J6: ='General Information'!C19 -> 46416 | K6: Variance | L6: ='General Information'!C23 -> -2 | M6: Potential Changes | O6: =O4-O5 -> 0 | Q6: FIR Value (Todate) | S6: ='FIR Summary'!I3 -> 77303418 | U6: FIR % | V6: =S6/O4 -> 0.38864265 | W6: Invoiced % | X6: =S4/O4 -> 0.3161776 | Z6: =REPT("¢",IF(INT(+Z5*10)>5,5,INT(+Z5*10)))&REPT("£",IF(INT(+Z5*10)>5,0,5-INT(+Z5*10)))&CHAR(10)&REPT("¢",+IF(INT(+Z5*10)>5,-5+INT(+Z5*10),0))&REPT("£",IF(INT(+Z5*10)>5,10-INT(+Z5*10),5)) -> ¢¢¢¢¢ ¢¢¢¢£
A8: Progress Overview
A9: Earned Value Progress (SAR) | O9: Physical Progress (Effort) | AA9: Earned Value Progress (%)
A10: WBS | C10: BOQ Value (SAR) | D10: % Wt. | E10: Weekly (SAR) | G10: To Date (SAR) | O10: Budgeted | P10: % Wt. | Q10: Weekly Physical Progress | U10: To Date Physical Progress
E11: Planned | F11: Earned | G11: Original Plan | H11: Revised Planned | I11: Earned | J11: Original Plan % | K11: Revised Planned % | L11: Earned % | M11: Variance | N11: SPI | O11: (Manhours) | Q11: Planned | R11: Earned | S11: Plan % | T11: Earned % | U11: Planned | V11: Earned | W11: Plan % | X11: Earned % | Y11: Variance | Z11: SPI
A12: =+Progress!A7 -> Demolishing & Site Clearing | C12: =+Progress!C7 -> 457401.18 | D12: =IF(ISBLANK(C12),"",C12/$C$29) -> 0.0022995827 | E12: =+Progress!E7 -> 457401.18 | F12: =+Progress!F7 -> 136666.96 | G12: =+Progress!G7 -> 457401.18 | H12: =+Progress!H7 -> 457401.18 | I12: =+Progress!I7 -> 457401.18 | J12: =IFERROR(IF(ISBLANK(G12),"",G12/C12),0) -> 1 | K12: =IFERROR(IF(ISBLANK(H12),"",H12/C12),0) -> 1 | L12: =IFERROR(IF(ISBLANK(I12),"",I12/C12),0) -> 1 | M12: =IFERROR(L12-K12,"") -> 0 | N12: =IFERROR(L12/K12,"") -> 1 | O12: =+Progress!K7 -> 3437.41 | P12: =IF(ISBLANK(O12),"",O12/$O$29) -> 0.0037353813 | Q12: =+Progress!M7 -> 3437.41 | R12: =+Progress!N7 -> -442.59 | S12: =IFERROR(IF(ISBLANK(Q12),"",Q12/O12),0) -> 1 | T12: =IFERROR(IF(ISBLANK(R12),"",R12/O12),0) -> -0.12875683 | U12: =+Progress!O7 -> 3437.41 | V12: =+Progress!P7 -> 3437.41 | W12: =IFERROR(IF(ISBLANK(U12),"",U12/O12),0) -> 1 | X12: =IFERROR(IF(ISBLANK(V12),"",V12/O12),0) -> 1 | Y12: =IFERROR(X12-W12,"") -> 0 | Z12: =IFERROR(X12/W12,"") -> 1
A13: =+Progress!A8 -> Earthworks & Site Grading | C13: =+Progress!C8 -> 31040592 | D13: =IF(ISBLANK(C13),"",C13/$C$29) -> 0.15605646 | E13: =+Progress!E8 -> -21385797 | F13: =+Progress!F8 -> -22502335 | G13: =+Progress!G8 -> 31040592 | H13: =+Progress!H8 -> 31040592 | I13: =+Progress!I8 -> 29924053 | J13: =IFERROR(IF(ISBLANK(G13),"",G13/C13),0) -> 1 | K13: =IFERROR(IF(ISBLANK(H13),"",H13/C13),0) -> 1 | L13: =IFERROR(IF(ISBLANK(I13),"",I13/C13),0) -> 0.96402973 | M13: =IFERROR(L13-K13,"") -> -0.035970271 | N13: =IFERROR(L13/K13,"") -> 0.96402973 | O13: =+Progress!K8 -> 22808.8 | P13: =IF(ISBLANK(O13),"",O13/$O$29) -> 0.024785977 | Q13: =+Progress!M8 -> -45319.2 | R13: =+Progress!N8 -> -24484.41 | S13: =IFERROR(IF(ISBLANK(Q13),"",Q13/O13),0) -> -1.9869173 | T13: =IFERROR(IF(ISBLANK(R13),"",R13/O13),0) -> -1.0734633 | U13: =+Progress!O8 -> 22808.8 | V13: =+Progress!P8 -> 21945.45 | W13: =IFERROR(IF(ISBLANK(U13),"",U13/O13),0) -> 1 | X13: =IFERROR(IF(ISBLANK(V13),"",V13/O13),0) -> 0.96214838 | Y13: =IFERROR(X13-W13,"") -> -0.037851619 | Z13: =IFERROR(X13/W13,"") -> 0.96214838
A14: =+Progress!A9 -> Sewerage Network | C14: =+Progress!C9 -> 5111121.8 | D14: =IF(ISBLANK(C14),"",C14/$C$29) -> 0.025696146 | E14: =+Progress!E9 -> 1624385 | F14: =+Progress!F9 -> -557865.16 | G14: =+Progress!G9 -> 4977488.4 | H14: =+Progress!H9 -> 4977488.4 | I14: =+Progress!I9 -> 4189784.5 | J14: =IFERROR(IF(ISBLANK(G14),"",G14/C14),0) -> 0.97385439 | K14: =IFERROR(IF(ISBLANK(H14),"",H14/C14),0) -> 0.97385439 | L14: =IFERROR(IF(ISBLANK(I14),"",I14/C14),0) -> 0.81973872 | M14: =IFERROR(L14-K14,"") -> -0.15411567 | N14: =IFERROR(L14/K14,"") -> 0.8417467 | O14: =+Progress!K9 -> 74260.44 | P14: =IF(ISBLANK(O14),"",O14/$O$29) -> 0.080697694 | Q14: =+Progress!M9 -> -6577.61 | R14: =+Progress!N9 -> -4703.31 | S14: =IFERROR(IF(ISBLANK(Q14),"",Q14/O14),0) -> -0.088574886 | T14: =IFERROR(IF(ISBLANK(R14),"",R14/O14),0) -> -0.063335337 | U14: =+Progress!O9 -> 61270.39 | V14: =+Progress!P9 -> 53207.64 | W14: =IFERROR(IF(ISBLANK(U14),"",U14/O14),0) -> 0.82507443 | X14: =IFERROR(IF(ISBLANK(V14),"",V14/O14),0) -> 0.71650047 | Y14: =IFERROR(X14-W14,"") -> -0.10857396 | Z14: =IFERROR(X14/W14,"") -> 0.86840707
A15: =+Progress!A14 -> Storm Water Network | C15: =+Progress!C14 -> 21808728 | D15: =IF(ISBLANK(C15),"",C15/$C$29) -> 0.1096433 | E15: =+Progress!E14 -> 2413306.5 | F15: =+Progress!F14 -> -87002.14 | G15: =+Progress!G14 -> 20044696 | H15: =+Progress!H14 -> 20044696 | I15: =+Progress!I14 -> 18078712 | J15: =IFERROR(IF(ISBLANK(G15),"",G15/C15),0) -> 0.91911344 | K15: =IFERROR(IF(ISBLANK(H15),"",H15/C15),0) -> 0.91911344 | L15: =IFERROR(IF(ISBLANK(I15),"",I15/C15),0) -> 0.8289668 | M15: =IFERROR(L15-K15,"") -> -0.090146642 | N15: =IFERROR(L15/K15,"") -> 0.90192 | O15: =+Progress!K14 -> 143781.21 | P15: =IF(ISBLANK(O15),"",O15/$O$29) -> 0.15624486 | Q15: =+Progress!M14 -> -17378.91 | R15: =+Progress!N14 -> -4682.1 | S15: =IFERROR(IF(ISBLANK(Q15),"",Q15/O15),0) -> -0.12087052 | T15: =IFERROR(IF(ISBLANK(R15),"",R15/O15),0) -> -0.03256406 | U15: =+Progress!O14 -> 122269.09 | V15: =+Progress!P14 -> 112215.05 | W15: =IFERROR(IF(ISBLANK(U15),"",U15/O15),0) -> 0.85038295 | X15: =IFERROR(IF(ISBLANK(V15),"",V15/O15),0) -> 0.78045699 | Y15: =IFERROR(X15-W15,"") -> -0.069925966 | Z15: =IFERROR(X15/W15,"") -> 0.9177712
A16: =+Progress!A19 -> Potable Water Network | C16: =+Progress!C19 -> 1954044.4 | D16: =IF(ISBLANK(C16),"",C16/$C$29) -> 0.0098239508 | E16: =+Progress!E19 -> 434690.58 | F16: =+Progress!F19 -> -484026.42 | G16: =+Progress!G19 -> 1690361 | H16: =+Progress!H19 -> 1690361 | I16: =+Progress!I19 -> 825178.44 | J16: =IFERROR(IF(ISBLANK(G16),"",G16/C16),0) -> 0.86505765 | K16: =IFERROR(IF(ISBLANK(H16),"",H16/C16),0) -> 0.86505765 | L16: =IFERROR(IF(ISBLANK(I16),"",I16/C16),0) -> 0.42229258 | M16: =IFERROR(L16-K16,"") -> -0.44276507 | N16: =IFERROR(L16/K16,"") -> 0.48816698 | O16: =+Progress!K19 -> 57934.51 | P16: =IF(ISBLANK(O16),"",O16/$O$29) -> 0.062956554 | Q16: =+Progress!M19 -> -5299.67 | R16: =+Progress!N19 -> -2333.46 | S16: =IFERROR(IF(ISBLANK(Q16),"",Q16/O16),0) -> -0.091476911 | T16: =IFERROR(IF(ISBLANK(R16),"",R16/O16),0) -> -0.040277548 | U16: =+Progress!O19 -> 42580.33 | V16: =+Progress!P19 -> 28245.61 | W16: =IFERROR(IF(ISBLANK(U16),"",U16/O16),0) -> 0.73497351 | X16: =IFERROR(IF(ISBLANK(V16),"",V16/O16),0) -> 0.48754378 | Y16: =IFERROR(X16-W16,"") -> -0.24742973 | Z16: =IFERROR(X16/W16,"") -> 0.66334878
A17: =+Progress!A24 -> Fire Fighting Network | C17: =+Progress!C24 -> 4678456.7 | D17: =IF(ISBLANK(C17),"",C17/$C$29) -> 0.023520924 | E17: =+Progress!E24 -> 728032.03 | F17: =+Progress!F24 -> -843901.22 | G17: =+Progress!G24 -> 3773268.9 | H17: =+Progress!H24 -> 3773268.9 | I17: =+Progress!I24 -> 2943158.8 | J17: =IFERROR(IF(ISBLANK(G17),"",G17/C17),0) -> 0.80651999 | K17: =IFERROR(IF(ISBLANK(I17),"",I17/C17),0) -> 0.62908752 | L17: =IFERROR(IF(ISBLANK(I17),"",I17/C17),0) -> 0.62908752 | M17: =IFERROR(L17-K17,"") -> 0 | N17: =IFERROR(L17/K17,"") -> 1 | O17: =+Progress!K24 -> 63346.29 | P17: =IF(ISBLANK(O17),"",O17/$O$29) -> 0.068837453 | Q17: =+Progress!M24 -> -10585.14 | R17: =+Progress!N24 -> -2914.99 | S17: =IFERROR(IF(ISBLANK(Q17),"",Q17/O17),0) -> -0.1670996 | T17: =IFERROR(IF(ISBLANK(R17),"",R17/O17),0) -> -0.046016744 | U17: =+Progress!O24 -> 44606.86 | V17: =+Progress!P24 -> 32601.72 | W17: =IFERROR(IF(ISBLANK(U17),"",U17/O17),0) -> 0.70417478 | X17: =IFERROR(IF(ISBLANK(V17),"",V17/O17),0) -> 0.51465871 | Y17: =IFERROR(X17-W17,"") -> -0.18951607 | Z17: =IFERROR(X17/W17,"") -> 0.73086785
A18: =+Progress!A29 -> TSE Network | C18: =+Progress!C29 -> 2995733.6 | D18: =IF(ISBLANK(C18),"",C18/$C$29) -> 0.01506104 | E18: =+Progress!E29 -> 1612431.1 | F18: =+Progress!F29 -> -1051657.2 | G18: =+Progress!G29 -> 2859193.2 | H18: =+Progress!H29 -> 2859193.2 | I18: =+Progress!I29 -> 510048.1 | J18: =IFERROR(IF(ISBLANK(G18),"",G18/C18),0) -> 0.95442169 | K18: =IFERROR(IF(ISBLANK(I18),"",I18/C18),0) -> 0.17025816 | L18: =IFERROR(IF(ISBLANK(I18),"",I18/C18),0) -> 0.17025816 | M18: =IFERROR(L18-K18,"") -> 0 | N18: =IFERROR(L18/K18,"") -> 1 | O18: =+Progress!K29 -> 48137.98 | P18: =IF(ISBLANK(O18),"",O18/$O$29) -> 0.052310813 | Q18: =+Progress!M29 -> -11878.07 | R18: =+Progress!N29 -> -6694.06 | S18: =IFERROR(IF(ISBLANK(Q18),"",Q18/O18),0) -> -0.24675049 | T18: =IFERROR(IF(ISBLANK(R18),"",R18/O18),0) -> -0.13905984 | U18: =+Progress!O29 -> 24761.93 | V18: =+Progress!P29 -> 12304.02 | W18: =IFERROR(IF(ISBLANK(U18),"",U18/O18),0) -> 0.51439487 | X18: =IFERROR(IF(ISBLANK(V18),"",V18/O18),0) -> 0.25559901 | Y18: =IFERROR(X18-W18,"") -> -0.25879586 | Z18: =IFERROR(X18/W18,"") -> 0.49689261
A19: =+Progress!A34 -> Potable Water Pump Station | C19: =+Progress!C34 -> 11076182 | D19: =IF(ISBLANK(C19),"",C19/$C$29) -> 0.055685463 | E19: =+Progress!E34 -> -6164181.1 | F19: =+Progress!F34 -> -1545112.6 | G19: =+Progress!G34 -> 4419392 | H19: =+Progress!H34 -> 4419392 | I19: =+Progress!I34 -> 1734353.2 | J19: =IFERROR(IF(ISBLANK(G19),"",G19/C19),0) -> 0.39899959 | K19: =IFERROR(IF(ISBLANK(H19),"",H19/C19),0) -> 0.39899959 | L19: =IFERROR(IF(ISBLANK(I19),"",I19/C19),0) -> 0.15658403 | M19: =IFERROR(L19-K19,"") -> -0.24241556 | N19: =IFERROR(L19/K19,"") -> 0.39244158 | O19: =+Progress!K34 -> 71778.26 | P19: =IF(ISBLANK(O19),"",O19/$O$29) -> 0.078000347 | Q19: =+Progress!M34 -> -10022.52 | R19: =+Progress!N34 -> 6439.69 | S19: =IFERROR(IF(ISBLANK(Q19),"",Q19/O19),0) -> -0.13963169 | T19: =IFERROR(IF(ISBLANK(R19),"",R19/O19),0) -> 0.089716441 | U19: =+Progress!O34 -> 45641.48 | V19: =+Progress!P34 -> 31071.69 | W19: =IFERROR(IF(ISBLANK(U19),"",U19/O19),0) -> 0.63586774 | X19: =IFERROR(IF(ISBLANK(V19),"",V19/O19),0) -> 0.43288441 | Y19: =IFERROR(X19-W19,"") -> -0.20298333 | Z19: =IFERROR(X19/W19,"") -> 0.68077744
A20: =+Progress!A39 -> Sewerage Lift Station | C20: =+Progress!C39 -> 4985124.7 | D20: =IF(ISBLANK(C20),"",C20/$C$29) -> 0.025062696 | E20: =+Progress!E39 -> -3538203.9 | F20: =+Progress!F39 -> -555628.72 | G20: =+Progress!G39 -> 276905.79 | H20: =+Progress!H39 -> 276905.79 | I20: =+Progress!I39 -> 36677.32 | J20: =IFERROR(IF(ISBLANK(G20),"",G20/C20),0) -> 0.055546412 | K20: =IFERROR(IF(ISBLANK(H20),"",H20/C20),0) -> 0.055546412 | L20: =IFERROR(IF(ISBLANK(I20),"",I20/C20),0) -> 0.0073573526 | M20: =IFERROR(L20-K20,"") -> -0.048189059 | N20: =IFERROR(L20/K20,"") -> 0.13245415 | O20: =+Progress!K39 -> 70758.97 | P20: =IF(ISBLANK(O20),"",O20/$O$29) -> 0.0768927 | Q20: =+Progress!M39 -> -8207.43 | R20: =+Progress!N39 -> 8009.38 | S20: =IFERROR(IF(ISBLANK(Q20),"",Q20/O20),0) -> -0.11599137 | T20: =IFERROR(IF(ISBLANK(R20),"",R20/O20),0) -> 0.11319243 | U20: =+Progress!O39 -> 43992.57 | V20: =+Progress!P39 -> 16566.86 | W20: =IFERROR(IF(ISBLANK(U20),"",U20/O20),0) -> 0.62172428 | X20: =IFERROR(IF(ISBLANK(V20),"",V20/O20),0) -> 0.23413088 | Y20: =IFERROR(X20-W20,"") -> -0.3875934 | Z20: =IFERROR(X20/W20,"") -> 0.37658314
A21: =+Progress!A44 -> Medium Voltage Network | C21: =+Progress!C44 -> 5452229.2 | D21: =IF(ISBLANK(C21),"",C21/$C$29) -> 0.027411062 | E21: =+Progress!E44 -> 544090.55 | F21: =+Progress!F44 -> -218032.33 | G21: =+Progress!G44 -> 4202411.7 | H21: =+Progress!H44 -> 4202411.7 | I21: =+Progress!I44 -> 1171998.1 | J21: =IFERROR(IF(ISBLANK(G21),"",G21/C21),0) -> 0.77076944 | K21: =IFERROR(IF(ISBLANK(I21),"",I21/C21),0) -> 0.2149576 | L21: =IFERROR(IF(ISBLANK(I21),"",I21/C21),0) -> 0.2149576 | M21: =IFERROR(L21-K21,"") -> 0 | N21: =IFERROR(L21/K21,"") -> 1 | O21: =+Progress!K44 -> 34290.88 | P21: =IF(ISBLANK(O21),"",O21/$O$29) -> 0.037263379 | Q21: =+Progress!M44 -> -12927.56 | R21: =+Progress!N44 -> 613.08 | S21: =IFERROR(IF(ISBLANK(Q21),"",Q21/O21),0) -> -0.37699703 | T21: =IFERROR(IF(ISBLANK(R21),"",R21/O21),0) -> 0.017878806 | U21: =+Progress!O44 -> 17112.44 | V21: =+Progress!P44 -> 11751.82 | W21: =IFERROR(IF(ISBLANK(U21),"",U21/O21),0) -> 0.49903764 | X21: =IFERROR(IF(ISBLANK(V21),"",V21/O21),0) -> 0.34270978 | Y21: =IFERROR(X21-W21,"") -> -0.15632786 | Z21: =IFERROR(X21/W21,"") -> 0.68674134
A22: =+Progress!A49 -> Low Voltage Network | C22: =+Progress!C49 -> 1876943.1 | D22: =IF(ISBLANK(C22),"",C22/$C$29) -> 0.0094363247 | E22: =+Progress!E49 -> -938830.07 | F22: =+Progress!F49 -> -239073.68 | G22: =+Progress!G49 -> 438370.8 | H22: =+Progress!H49 -> 438370.8 | I22: =+Progress!I49 -> 16626.84 | J22: =IFERROR(IF(ISBLANK(G22),"",G22/C22),0) -> 0.23355572 | K22: =IFERROR(IF(ISBLANK(I22),"",I22/C22),0) -> 0.0088584677 | L22: =IFERROR(IF(ISBLANK(I22),"",I22/C22),0) -> 0.0088584677 | M22: =IFERROR(L22-K22,"") -> 0 | N22: =IFERROR(L22/K22,"") -> 1 | O22: =+Progress!K49 -> 31587.58 | P22: =IF(ISBLANK(O22),"",O22/$O$29) -> 0.034325744 | Q22: =+Progress!M49 -> -13293.74 | R22: =+Progress!N49 -> 360.13 | S22: =IFERROR(IF(ISBLANK(Q22),"",Q22/O22),0) -> -0.42085339 | T22: =IFERROR(IF(ISBLANK(R22),"",R22/O22),0) -> 0.011401 | U22: =+Progress!O49 -> 12066.26 | V22: =+Progress!P49 -> 6547.2 | W22: =IFERROR(IF(ISBLANK(U22),"",U22/O22),0) -> 0.38199381 | X22: =IFERROR(IF(ISBLANK(V22),"",V22/O22),0) -> 0.20727134 | Y22: =IFERROR(X22-W22,"") -> -0.17472247 | Z22: =IFERROR(X22/W22,"") -> 0.54260392
A23: =+Progress!A54 -> Street Lighting Network | C23: =+Progress!C54 -> 8486130.6 | D23: =IF(ISBLANK(C23),"",C23/$C$29) -> 0.04266399 | E23: =+Progress!E54 -> -1475231 | F23: =+Progress!F54 -> -508605.97 | G23: =+Progress!G54 -> 3549231.9 | H23: =+Progress!H54 -> 3549231.9 | I23: =+Progress!I54 -> 1407366.6 | J23: =IFERROR(IF(ISBLANK(G23),"",G23/C23),0) -> 0.41823914 | K23: =IFERROR(IF(ISBLANK(I23),"",I23/C23),0) -> 0.16584314 | L23: =IFERROR(IF(ISBLANK(I23),"",I23/C23),0) -> 0.16584314 | M23: =IFERROR(L23-K23,"") -> 0 | N23: =IFERROR(L23/K23,"") -> 1 | O23: =+Progress!K54 -> 76760.06 | P23: =IF(ISBLANK(O23),"",O23/$O$29) -> 0.083413993 | Q23: =+Progress!M54 -> -38391.43 | R23: =+Progress!N54 -> 2909.95 | S23: =IFERROR(IF(ISBLANK(Q23),"",Q23/O23),0) -> -0.50014851 | T23: =IFERROR(IF(ISBLANK(R23),"",R23/O23),0) -> 0.037909689 | U23: =+Progress!O54 -> 32896.57 | V23: =+Progress!P54 -> 17438.08 | W23: =IFERROR(IF(ISBLANK(U23),"",U23/O23),0) -> 0.42856363 | X23: =IFERROR(IF(ISBLANK(V23),"",V23/O23),0) -> 0.22717648 | Y23: =IFERROR(X23-W23,"") -> -0.20138715 | Z23: =IFERROR(X23/W23,"") -> 0.53008809
A24: =+Progress!A59 -> Telecommunication Network | C24: =+Progress!C59 -> 4454965.6 | D24: =IF(ISBLANK(C24),"",C24/$C$29) -> 0.022397323 | E24: =+Progress!E59 -> -1170100.7 | F24: =+Progress!F59 -> -420209.79 | G24: =+Progress!G59 -> 1677088 | H24: =+Progress!H59 -> 1677088 | I24: =+Progress!I59 -> 965354.72 | J24: =IFERROR(IF(ISBLANK(G24),"",G24/C24),0) -> 0.37645363 | K24: =IFERROR(IF(ISBLANK(H24),"",H24/C24),0) -> 0.37645363 | L24: =IFERROR(IF(ISBLANK(I24),"",I24/C24),0) -> 0.21669185 | M24: =IFERROR(L24-K24,"") -> -0.15976178 | N24: =IFERROR(L24/K24,"") -> 0.57561365 | O24: =+Progress!K59 -> 62092.94 | P24: =IF(ISBLANK(O24),"",O24/$O$29) -> 0.067475456 | Q24: =+Progress!M59 -> -33174.44 | R24: =+Progress!N59 -> 3043.51 | S24: =IFERROR(IF(ISBLANK(Q24),"",Q24/O24),0) -> -0.53427072 | T24: =IFERROR(IF(ISBLANK(R24),"",R24/O24),0) -> 0.049015395 | U24: =+Progress!O59 -> 23457.56 | V24: =+Progress!P59 -> 15462.07 | W24: =IFERROR(IF(ISBLANK(U24),"",U24/O24),0) -> 0.37778144 | X24: =IFERROR(IF(ISBLANK(V24),"",V24/O24),0) -> 0.24901494 | Y24: =IFERROR(X24-W24,"") -> -0.12876649 | Z24: =IFERROR(X24/W24,"") -> 0.65915082
A25: =+Progress!A64 -> Road Works | C25: =+Progress!C64 -> 79068381 | D25: =IF(ISBLANK(C25),"",C25/$C$29) -> 0.39751599 | E25: =+Progress!E64 -> 4629678.6 | F25: =+Progress!F64 -> 11794897 | G25: =+Progress!G64 -> 63789840 | H25: =+Progress!H64 -> 63789840 | I25: =+Progress!I64 -> 40015001 | J25: =IFERROR(IF(ISBLANK(G25),"",G25/C25),0) -> 0.806768 | K25: =IFERROR(IF(ISBLANK(H25),"",H25/C25),0) -> 0.806768 | L25: =IFERROR(IF(ISBLANK(I25),"",I25/C25),0) -> 0.50608094 | M25: =IFERROR(L25-K25,"") -> -0.30068706 | N25: =IFERROR(L25/K25,"") -> 0.62729427 | O25: =+Progress!K64 -> 80303.58 | P25: =IF(ISBLANK(O25),"",O25/$O$29) -> 0.087264683 | Q25: =+Progress!M64 -> -36526.22 | R25: =+Progress!N64 -> 642.95 | S25: =IFERROR(IF(ISBLANK(Q25),"",Q25/O25),0) -> -0.4548517 | T25: =IFERROR(IF(ISBLANK(R25),"",R25/O25),0) -> 0.0080064924 | U25: =+Progress!O64 -> 38233.78 | V25: =+Progress!P64 -> 19355.5 | W25: =IFERROR(IF(ISBLANK(U25),"",U25/O25),0) -> 0.47611551 | X25: =IFERROR(IF(ISBLANK(V25),"",V25/O25),0) -> 0.2410291 | Y25: =IFERROR(X25-W25,"") -> -0.23508641 | Z25: =IFERROR(X25/W25,"") -> 0.50624082
A26: =+Progress!A68 -> Landscape | C26: =+Progress!C68 -> 14727630 | D26: =IF(ISBLANK(C26),"",C26/$C$29) -> 0.074043103 | E26: =+Progress!E68 -> -4388547.8 | F26: =+Progress!F68 -> -49702.42 | G26: =+Progress!G68 -> 570737.12 | H26: =+Progress!H68 -> 570737.12 | I26: =+Progress!I68 -> 98475.6 | J26: =IFERROR(IF(ISBLANK(G26),"",G26/C26),0) -> 0.038752816 | K26: =IFERROR(IF(ISBLANK(H26),"",H26/C26),0) -> 0.038752816 | L26: =IFERROR(IF(ISBLANK(I26),"",I26/C26),0) -> 0.0066864528 | M26: =IFERROR(L26-K26,"") -> -0.032066363 | N26: =IFERROR(L26/K26,"") -> 0.17254108 | O26: =+Progress!K68 -> 44855.31 | P26: =IF(ISBLANK(O26),"",O26/$O$29) -> 0.048743585 | Q26: =+Progress!M68 -> -27678.83 | R26: =+Progress!N68 -> 2488.35 | S26: =IFERROR(IF(ISBLANK(Q26),"",Q26/O26),0) -> -0.61706919 | T26: =IFERROR(IF(ISBLANK(R26),"",R26/O26),0) -> 0.055475037 | U26: =+Progress!O68 -> 7105.17 | V26: =+Progress!P68 -> 3081.95 | W26: =IFERROR(IF(ISBLANK(U26),"",U26/O26),0) -> 0.15840198 | X26: =IFERROR(IF(ISBLANK(V26),"",V26/O26),0) -> 0.068708699 | Y26: =IFERROR(X26-W26,"") -> -0.089693283 | Z26: =IFERROR(X26/W26,"") -> 0.43376161
A27: =+Progress!A72 -> Guard Rooms | C27: =+Progress!C72 -> 539598.47 | D27: =IF(ISBLANK(C27),"",C27/$C$29) -> 0.0027128293 | E27: =+Progress!E72 -> -420766.65 | F27: =+Progress!F72 -> -2951.99 | G27: =+Progress!G72 -> 92935.49 | H27: =+Progress!H72 -> 92935.49 | I27: =+Progress!I72 -> 41745.84 | J27: =IFERROR(IF(ISBLANK(G27),"",G27/C27),0) -> 0.17223083 | K27: =IFERROR(IF(ISBLANK(H27),"",H27/C27),0) -> 0.17223083 | L27: =IFERROR(IF(ISBLANK(I27),"",I27/C27),0) -> 0.077364637 | M27: =IFERROR(L27-K27,"") -> -0.094866188 | N27: =IFERROR(L27/K27,"") -> 0.44919158 | O27: =+Progress!K72 -> 34095.79 | P27: =IF(ISBLANK(O27),"",O27/$O$29) -> 0.037051378 | Q27: =+Progress!M72 -> -9242.69 | R27: =+Progress!N72 -> 4506.75 | S27: =IFERROR(IF(ISBLANK(Q27),"",Q27/O27),0) -> -0.2710801 | T27: =IFERROR(IF(ISBLANK(R27),"",R27/O27),0) -> 0.13217908 | U27: =+Progress!O72 -> 17965.31 | V27: =+Progress!P72 -> 5626.75 | W27: =IFERROR(IF(ISBLANK(U27),"",U27/O27),0) -> 0.52690699 | X27: =IFERROR(IF(ISBLANK(V27),"",V27/O27),0) -> 0.16502771 | Y27: =IFERROR(X27-W27,"") -> -0.36187928 | Z27: =IFERROR(X27/W27,"") -> 0.31320083
A28: =Progress!A76 -> Provisional Sum | C28: =Progress!C76 -> 192900.72 | D28: =IF(ISBLANK(C28),"",C28/$C$29) -> 0.00096980766 | E28: =Progress!E76 -> 0 | F28: =Progress!F76 -> 0 | G28: =Progress!G76 -> 0 | H28: =Progress!H76 -> 0 | I28: =Progress!I76 -> 0 | J28: =IFERROR(IF(ISBLANK(G28),"",G28/C28),0) -> 0 | K28: =IFERROR(IF(ISBLANK(I28),"",I28/C28),0) -> 0 | L28: =IFERROR(IF(ISBLANK(I28),"",I28/C28),0) -> 0 | M28: =IFERROR(L28-K28,"") -> 0 | N28: =IFERROR(L28/K28,"") | O28: =Progress!K76 -> 0 | P28: =IF(ISBLANK(O28),"",O28/$O$29) -> 0 | Q28: =Progress!M76 -> 0 | R28: =Progress!N76 -> 0 | S28: =IFERROR(IF(ISBLANK(Q28),"",Q28/O28),0) -> 0 | T28: =IFERROR(IF(ISBLANK(R28),"",R28/O28),0) -> 0 | U28: =Progress!O76 -> 0 | V28: =Progress!P76 -> 0 | W28: =IFERROR(IF(ISBLANK(U28),"",U28/O28),0) -> 0 | X28: =IFERROR(IF(ISBLANK(V28),"",V28/O28),0) -> 0 | Y28: =IFERROR(X28-W28,"") -> 0 | Z28: =IFERROR(X28/W28,"")
B29: Total | C29: =SUM(C12:C28) -> 1.9890616e+08 | D29: =SUM(D12:D28) -> 1 | E29: =SUM(E12:E28) -> -27037643 | F29: =SUM(F12:F28) -> -17134541 | G29: =SUM(G12:G28) -> 1.4385991e+08 | H29: =SUM(H12:H28) -> 1.4385991e+08 | I29: =SUM(I12:I28) -> 1.0241594e+08 | J29: =IFERROR(IF(ISBLANK(G29),"",G29/C29),0) -> 0.72325518 | K29: =IFERROR(IF(ISBLANK(H29),"",H29/C29),0) -> 0.72325518 | L29: =IFERROR(IF(ISBLANK(I29),"",I29/C29),0) -> 0.51489574 | M29: =+L29-K29 -> -0.20835944 | N29: =L29/K29 -> 0.71191434 | O29: =SUM(O12:O28) -> 920230.01 | P29: =SUM(P12:P28) -> 1 | Q29: =SUM(Q12:Q28) -> -283066.05 | R29: =SUM(R12:R28) -> -17241.13 | S29: =IFERROR(IF(ISBLANK(Q29),"",Q29/O29),0) -> -0.30760358 | T29: =IFERROR(IF(ISBLANK(R29),"",R29/O29),0) -> -0.018735675 | U29: =SUM(U12:U28) -> 560205.95 | V29: =SUM(V12:V28) -> 390858.82 | W29: =IFERROR(IF(ISBLANK(U29),"",U29/O29),0) -> 0.60876731 | X29: =IFERROR(IF(ISBLANK(V29),"",V29/O29),0) -> 0.42474035 | Y29: =+X29-W29 -> -0.18402696 | Z29: =X29/W29 -> 0.69770558
AA30: Construction Milestones
AA31: Item No. | AB31: Milestones | AD31: Original (Baseline) | AE31: Latest Plan | AF31: Forecast | AG31: Status | AH31: Days Change
AA32: =+Milestones!A4 -> 1 | AB32: =+Milestones!B4 -> Award Date | AD32: =+Milestones!C4 -> 45838 | AE32: =+Milestones!D4 -> 45838 | AF32: =+Milestones!E4 -> 45838 | AG32: =+Milestones!F4 -> A | AH32: =+Milestones!G4 -> 0
AA33: =+Milestones!A5 -> 2 | AB33: =+Milestones!B5 -> Contract Sign Date | AD33: =+Milestones!C5 -> 45852 | AE33: =+Milestones!D5 -> 45852 | AF33: =+Milestones!E5 -> 45852 | AG33: =+Milestones!F5 -> A | AH33: =+Milestones!G5 -> 0
AA34: =+Milestones!A6 -> 3 | AB34: =+Milestones!B6 -> Site Handover Date | AD34: =+Milestones!C6 -> 45868 | AE34: =+Milestones!D6 -> 45868 | AF34: =+Milestones!E6 -> 45868 | AG34: =+Milestones!F6 -> A | AH34: =+Milestones!G6 -> 0
AA35: =+Milestones!A7 -> 4 | AB35: =+Milestones!B7 -> Complete Mobilization | AD35: =+Milestones!C7 -> 45899 | AE35: =+Milestones!D7 -> 45899 | AF35: =+Milestones!E7 -> 45899 | AG35: =+Milestones!F7 -> A | AH35: =+Milestones!G7 -> 0
AA36: =+Milestones!A10 -> 7 | AB36: =+Milestones!B10 -> Complete Earthworks | AD36: =+Milestones!C10 -> 46280 | AE36: =+Milestones!D10 -> 46280 | AF36: =+Milestones!E10 -> 46319 | AG36: =+Milestones!F10 -> F | AH36: =+Milestones!G10 -> -39
AA37: =+Milestones!A11 -> 8 | AB37: =+Milestones!B11 -> Complete all Wet Networks | AD37: =+Milestones!C11 -> 46348 | AE37: =+Milestones!D11 -> 46348 | AF37: =+Milestones!E11 -> 46365 | AG37: =+Milestones!F11 -> F | AH37: =+Milestones!G11 -> -17
AA38: =+Milestones!A12 -> 9 | AB38: =+Milestones!B12 -> Complete Electrical Works | AD38: =+Milestones!C12 -> 46350 | AE38: =+Milestones!D12 -> 46350 | AF38: =+Milestones!E12 -> 46366 | AG38: =+Milestones!F12 -> F | AH38: =+Milestones!G12 -> -16
AA39: =+Milestones!A13 -> 10 | AB39: =+Milestones!B13 -> Complete all Works including Testing & Commissioning, Cleanup, Closeout Documentation and Ready for Initial Handover | AD39: =+Milestones!C13 -> 46401 | AE39: =+Milestones!D13 -> 46401 | AF39: =+Milestones!E13 -> 46418 | AG39: =+Milestones!F13 -> F | AH39: =+Milestones!G13 -> -17
AA40: =+Milestones!A14 -> 11 | AB40: =+Milestones!B14 -> Complete Demobilization | AD40: =+Milestones!C14 -> 46412 | AE40: =+Milestones!D14 -> 46412 | AF40: =+Milestones!E14 -> 46428 | AG40: =+Milestones!F14 -> F | AH40: =+Milestones!G14 -> -16
AA41: =+Milestones!A15 -> 12 | AB41: =+Milestones!B15 -> Project Handover | AD41: =+Milestones!C15 -> 46416 | AE41: =+Milestones!D15 -> 46416 | AF41: =+Milestones!E15 -> 46433 | AG41: =+Milestones!F15 -> F | AH41: =+Milestones!G15 -> -17
...

Sheet General Information
A1: Weekly Progress Report - Construction Projects | K1: Data Date | L1: 46301 | N1: =L1+7 -> 46308
A2: Contract General Information
A3: Project Name | C3: Development of Infrastructure for phase 1 of the Logistics area at the 2nd Industrial City in Dammam
A4: Project ID | C4: DAM2-02-009
A5: Contractor | C5: Shibh Aljazira Contracting Company
A6: Consultant | C6: Egis
A7: Stage | C7: Construction
A8: Status | C8: Active
A9: Modon PM | C9: Muhammad H Al-Essa
A11: Key Dates
A12: Contract Award Date | C12: =Milestones!C4 -> 45838
A13: Contract Sign Date | C13: =Milestones!C5 -> 45852
A14: Site Handover Date | C14: =Milestones!C6 -> 45868
A15: Original Completion | C15: =Milestones!C15 -> 46416
A16: Contract Award Date (Hijri) | C16: =C12 -> 45838
A17: Contract Sign Date (Hijri) | C17: =C13 -> 45852
A18: Site Handover Date (Hijri) | C18: =C14 -> 45868
A19: Original Completion (Hijri) | C19: =C15 -> 46416
A20: Revised Completion Date | C20: =Milestones!D15 -> 46416
A21: Committed Completion Date | C21: =Milestones!D15 -> 46416
A22: Forecast Completion | C22: =Milestones!E13 -> 46418
A23: Variance | C23: =C20-C22 -> -2
A25: Key Project Submittals | C25: Submission Date | D25: Days taken to approve orginal plan from site handover date
A26: Quality Plan submission | C26: 45344 | D26: =C26-C14 -> -524
A27: Quality Plan approval | C27: 45346
A28: Quality Plan Last Update | C28: 45346
A30: Safety Plan submission | C30: 45345 | D30: =C30-C14 -> -523
A31: Safety Plan approval | C31: 45350
A32: Safety Plan Last Update | C32: 45350
A34: Risk Management Plan submission | C34: 45345 | D34: =C34-C14 -> -523
A35: Risk Management Plan approval | C35: 45350
A36: Risk Management Plan Last Update | C36: 45350
A38: Baseline Schedule submission | C38: 45334 | D38: =C38-C14 -> -534
A39: Baseline Schedule approval | C39: 45361
A40: No of Schedule Versions | C40: 1
A41: Last Recovery Schedule Approval Date | C41: 45361
A43: BOQ submission | D43: =C43-C19 -> -46416
A44: BOQ approval
A45: No of Approved Version of BOQ | C45: 1
A47: Construction Plan submission | C47: 45346 | D47: =C47-C14 -> -522
...

Sheet Progress
A1: Project Scope Statement | B1: The project consists of the wet networks mainlines (Sewerage, Storm, Potable, Firefighting & TSE) including the force main line, in addition to the dry networks (Medium Voltage, Low Voltage, Street Lighting & Telecommunication) road crossings & main line connections, scope also included supply, install, testing & commissioning for the potable water pump station and the sewage lift station and implementation of guard rooms and applying all the road earth layers till the asphalt wearing coarse for the project scope area internal roads & finishing the landscape | S1: ='General Information'!$K$1 -> Data Date | T1: ='General Information'!L1 -> 46301
A4: Earned Value Progress (SAR) | K4: Physical Progress (Effort)
A5: WBS | C5: BOQ Value (SAR) | D5: % Wt. | E5: Weekly (SAR) | H5: To Date (SAR) | K5: Budgeted | L5: % Wt. | M5: Weekly Physical Progress | O5: To Date Physical Progress
E6: Planned | F6: Earned | G6: Original Plan | H6: Planned | I6: Earned | K6: (Manhours) | M6: Planned | N6: Earned | O6: Planned | P6: Earned
A7: =K88 -> Demolishing & Site Clearing | C7: =M88 -> 457401.18 | D7: =IF(ISBLANK(C7),"",C7/$C$78) -> 0.0022995827 | E7: =N88-W88 -> 457401.18 | F7: =O88-X88 -> 136666.96 | G7: =HLOOKUP('General Information'!$L$1,Progress!$T$160:$UV$232,ROW()-4,FALSE) -> 457401.18 | H7: =N88 -> 457401.18 | I7: =O88 -> 457401.18 | K7: =P88 -> 3437.41 | L7: =IF(ISBLANK(K7),"",K7/$K$78) -> 0.0037353813 | M7: =Q88-Z88 -> 3437.41 | N7: =R88-AA88 -> -442.59 | O7: =Q88 -> 3437.41 | P7: =R88 -> 3437.41
A8: =K89 -> Earthworks & Site Grading | C8: =M89 -> 31040592 | D8: =IF(ISBLANK(C8),"",C8/$C$78) -> 0.15605646 | E8: =N89-W89 -> -21385797 | F8: =O89-X89 -> -22502335 | G8: =HLOOKUP('General Information'!$L$1,Progress!$T$160:$UV$232,ROW()-4,FALSE) -> 31040592 | H8: =N89 -> 31040592 | I8: =O89 -> 29924053 | K8: =P89 -> 22808.8 | L8: =IF(ISBLANK(K8),"",K8/$K$78) -> 0.024785977 | M8: =Q89-Z89 -> -45319.2 | N8: =R89-AA89 -> -24484.41 | O8: =Q89 -> 22808.8 | P8: =R89 -> 21945.45
A9: =K90 -> Sewerage Network | C9: =M90 -> 5111121.8 | D9: =IF(ISBLANK(C9),"",C9/$C$78) -> 0.025696146 | E9: =N90-W90 -> 1624385 | F9: =O90-X90 -> -557865.16 | G9: =HLOOKUP('General Information'!$L$1,Progress!$T$160:$UV$232,ROW()-4,FALSE) -> 4977488.4 | H9: =N90 -> 4977488.4 | I9: =O90 -> 4189784.5 | K9: =P90 -> 74260.44 | L9: =IF(ISBLANK(K9),"",K9/$K$78) -> 0.080697694 | M9: =Q90-Z90 -> -6577.61 | N9: =R90-AA90 -> -4703.31 | O9: =Q90 -> 61270.39 | P9: =R90 -> 53207.64
A10: =K91 -> Engineering | C10: =M91 -> 0 | D10: =IF(ISBLANK(C10),"",C10/$C$78) -> 0 | E10: =N91-W91 -> -164912.76 | F10: =O91-X91 -> -164912.76 | G10: =HLOOKUP('General Information'!$L$1,Progress!$T$160:$UV$232,ROW()-4,FALSE) -> 0 | H10: =N91 -> 0 | I10: =O91 -> 0 | K10: =P91 -> 568.6 | L10: =IF(ISBLANK(K10),"",K10/$K$78) -> 0.000617889 | M10: =Q91-Z91 -> 568.6 | N10: =R91-AA91 -> 568.6 | O10: =Q91 -> 568.6 | P10: =R91 -> 568.6
A11: =K92 -> Procurement | C11: =M92 -> 0 | D11: =IF(ISBLANK(C11),"",C11/$C$78) -> 0 | E11: =N92-W92 -> -1088658.6 | F11: =O92-X92 -> -1074742.6 | G11: =HLOOKUP('General Information'!$L$1,Progress!$T$160:$UV$232,ROW()-4,FALSE) -> 0 | H11: =N92 -> 0 | I11: =O92 -> 0 | K11: =P92 -> 10403.33 | L11: =IF(ISBLANK(K11),"",K11/$K$78) -> 0.011305141 | M11: =Q92-Z92 -> 641.94 | N11: =R92-AA92 -> 1082.73 | O11: =Q92 -> 10209.94 | P11: =R92 -> 8522.73
A12: =K93 -> Construction | C12: =M93 -> 5111121.8 | D12: =IF(ISBLANK(C12),"",C12/$C$78) -> 0.025696146 | E12: =N93-W93 -> 2877956.3 | F12: =O93-X93 -> 681790.21 | G12: =HLOOKUP('General Information'!$L$1,Progress!$T$160:$UV$232,ROW()-4,FALSE) -> 4977488.4 | H12: =N93 -> 4977488.4 | I12: =O93 -> 4189784.5 | K12: =P93 -> 53551.26 | L12: =IF(ISBLANK(K12),"",K12/$K$78) -> 0.058193342 | M12: =Q93-Z93 -> -7788.15 | N12: =R93-AA93 -> -12846.14 | O12: =Q93 -> 50491.85 | P12: =R93 -> 37624.81
A13: =K94 -> Testing & Commissioning | C13: =M94 -> 0 | D13: =IF(ISBLANK(C13),"",C13/$C$78) -> 0 | E13: =N94-W94 -> 0 | F13: =O94-X94 -> 0 | G13: =HLOOKUP('General Information'!$L$1,Progress!$T$160:$UV$232,ROW()-4,FALSE) -> 0 | H13: =N94 -> 0 | I13: =O94 -> 0 | K13: =P94 -> 9737.25 | L13: =IF(ISBLANK(K13),"",K13/$K$78) -> 0.010581322 | M13: =Q94-Z94 -> 0 | N13: =R94-AA94 -> 6491.5 | O13: =Q94 -> 0 | P13: =R94 -> 6491.5
A14: =K95 -> Storm Water Network | C14: =M95 -> 21808728 | D14: =IF(ISBLANK(C14),"",C14/$C$78) -> 0.1096433 | E14: =N95-W95 -> 2413306.5 | F14: =O95-X95 -> -87002.14 | G14: =HLOOKUP('General Information'!$L$1,Progress!$T$160:$UV$232,ROW()-4,FALSE) -> 20044696 | H14: =N95 -> 20044696 | I14: =O95 -> 18078712 | K14: =P95 -> 143781.21 | L14: =IF(ISBLANK(K14),"",K14/$K$78) -> 0.15624486 | M14: =Q95-Z95 -> -17378.91 | N14: =R95-AA95 -> -4682.1 | O14: =Q95 -> 122269.09 | P14: =R95 -> 112215.05
A15: =K96 -> Engineering | C15: =M96 -> 0 | D15: =IF(ISBLANK(C15),"",C15/$C$78) -> 0 | E15: =N96-W96 -> -468720.89 | F15: =O96-X96 -> -468720.89 | G15: =HLOOKUP('General Information'!$L$1,Progress!$T$160:$UV$232,ROW()-4,FALSE) -> 0 | H15: =N96 -> 0 | I15: =O96 -> 0 | K15: =P96 -> 984.12 | L15: =IF(ISBLANK(K15),"",K15/$K$78) -> 0.0010694283 | M15: =Q96-Z96 -> 984.12 | N15: =R96-AA96 -> 984.12 | O15: =Q96 -> 984.12 | P15: =R96 -> 984.12
A16: =K97 -> Procurement | C16: =M97 -> 0 | D16: =IF(ISBLANK(C16),"",C16/$C$78) -> 0 | E16: =N97-W97 -> -3131749.8 | F16: =O97-X97 -> -3049254.2 | G16: =HLOOKUP('General Information'!$L$1,Progress!$T$160:$UV$232,ROW()-4,FALSE) -> 0 | H16: =N97 -> 0 | I16: =O97 -> 0 | K16: =P97 -> 14474.2 | L16: =IF(ISBLANK(K16),"",K16/$K$78) -> 0.015728894 | M16: =Q97-Z97 -> 903.41 | N16: =R97-AA97 -> 2620.65 | O16: =Q97 -> 14439.41 | P16: =R97 -> 13952.76
A17: =K98 -> Construction | C17: =M98 -> 21808728 | D17: =IF(ISBLANK(C17),"",C17/$C$78) -> 0.1096433 | E17: =N98-W98 -> 6013777.2 | F17: =O98-X98 -> 3430972.9 | G17: =HLOOKUP('General Information'!$L$1,Progress!$T$160:$UV$232,ROW()-4,FALSE) -> 20044696 | H17: =N98 -> 20044696 | I17: =O98 -> 18078712 | K17: =P98 -> 118164.9 | L17: =IF(ISBLANK(K17),"",K17/$K$78) -> 0.12840801 | M17: =Q98-Z98 -> -19266.43 | N17: =R98-AA98 -> -14778.36 | O17: =Q98 -> 106845.57 | P17: =R98 -> 90786.68
A18: =K99 -> Testing & Commissioning | C18: =M99 -> 0 | D18: =IF(ISBLANK(C18),"",C18/$C$78) -> 0 | E18: =N99-W99 -> 0 | F18: =O99-X99 -> 0 | G18: =HLOOKUP('General Information'!$L$1,Progress!$T$160:$UV$232,ROW()-4,FALSE) -> 0 | H18: =N99 -> 0 | I18: =O99 -> 0 | K18: =P99 -> 10157.99 | L18: =IF(ISBLANK(K18),"",K18/$K$78) -> 0.011038534 | M18: =Q99-Z99 -> 0 | N18: =R99-AA99 -> 6491.5 | O18: =Q99 -> 0 | P18: =R99 -> 6491.5
... A75: =K156 -> Construction | C75: =M156 -> 539598.47 | D75: =IF(ISBLANK(C75),"",C75/$C$78) -> 0.0027128293 | E75: =N156-W156 -> -420202.71 | F75: =O156-X156 -> -2388.05 | G75: =HLOOKUP('General Information'!$L$1,Progress!$T$160:$UV$232,ROW()-4,FALSE) -> 92935.49 | H75: =N156 -> 92935.49 | I75: =O156 -> 41745.84 | K75: =P156 -> 6017.94 | L75: =IF(ISBLANK(K75),"",K75/$K$78) -> 0.0065396042 | M75: =Q156-Z156 -> -4342.72 | N75: =R156-AA156 -> -255.33 | O75: =Q156 -> 2065.28 | P75: =R156 -> 864.67
A76: =K157 -> Provisional Sum | C76: =M157 -> 192900.72 | D76: =IF(ISBLANK(C76),"",C76/$C$78) -> 0.00096980766 | E76: =N157-W157 -> 0 | F76: =O157-X157 -> 0 | G76: =HLOOKUP('General Information'!$L$1,Progress!$T$160:$UV$232,ROW()-4,FALSE) -> 0 | H76: =N157 -> 0 | I76: =O157 -> 0
A77: =K158 -> Closeout | C77: =M158 -> 0 | D77: =IF(ISBLANK(C77),"",C77/$C$78) -> 0 | E77: =N158-W158 -> 0 | F77: =O158-X158 -> 0 | G77: =HLOOKUP('General Information'!$L$1,Progress!$T$160:$UV$232,ROW()-4,FALSE) -> 0 | H77: =N158 -> 0 | I77: =O158 -> 0 | K77: =P158 -> 0 | L77: =IF(ISBLANK(K77),"",K77/$K$78) -> 0 | M77: =Q158-Z158 -> 0 | N77: =R158-AA158 -> 0 | O77: =Q158 -> 0 | P77: =R158 -> 0
