Workbook
Name _1B.05.M.010.0010: #REF!
Name _1B.05.M.010.0010: #REF!
Name _1B.05.M.010.0050: #REF!
Name _1B.05.M.010.0050: #REF!
Name _1B.05.M.0100.0010: #REF!
Name _1B.05.M.020.0010: #REF!
Name _1B.05.M.020.0020: #REF!
Name _1B.05.M.020.0030: #REF!
Name _1B.05.M.020.0040: #REF!
Name _1B.05.M.030.0010: #REF!
Name _1B.05.M.030.0020: #REF!
Name _1B.05.M.040.0010: #REF!
Name _1B.05.M.050.0010: #REF!
Name _1B.05.M.050.0020: #REF!
Name _1B.05.M.050.0030: #REF!
Name _1B.05.M.060.0020: #REF!
Name _1B.05.M.060.0100: #REF!
Name _1B.05.M.070.0010: #REF!
Name _1B.05.M.070.0020: #REF!
Name _1B.05.M.070.0030: #REF!
Name _1B.05.M.070.0040: #REF!
Name _1B.05.M.070.0050: #REF!
Name _1B.05.M.080.0010: #REF!
Name _1B.05.M.090.0010: #REF!
Name _1B.09.P.010.0010: #REF!
Name _1B.09.P.010.0020: #REF!
Name _1B.09.P.010.0030: #REF!
Name _1B.09.P.010.0040: #REF!
Name _1B.09.P.010.0050: #REF!
Name _1B.09.P.010.0060: #REF!
Name _1B.09.P.010.0070: #REF!
Name _1B.09.P.020.0010: #REF!
Name _1B.09.P.020.0020: #REF!
Name _1B.09.P.020.0030: #REF!
Name _1B.09.P.020.0040: #REF!
Name _1B.09.P.020.0050: #REF!
Name _1B.09.P.020.0060: #REF!
Name _1B.09.P.020.0070: #REF!
Name _1B.09.P.020.0080: #REF!
Name _1B.09.P.020.0090: #REF!
Name _1B.09.P.020.0100: #REF!
Name _1B.09.P.020.0110: #REF!
Name _1B.09.P.020.0120: #REF!
Name _1B.09.P.020.0130: #REF!
Name _1B.09.P.020.0140: #REF!
Name _1B.09.P.020.0150: #REF!
Name _1B.09.P.030.0010: #REF!
Name _1B.09.P.030.0020: #REF!
Name _1B.09.P.030.0030: #REF!
Name _1B.09.P.030.0040: #REF!
Name _1B.09.P.030.0050: #REF!
Name _1B.09.P.030.0060: #REF!
Name _1B.09.P.040.0010: #REF!
Name _1B.09.P.040.0020: #REF!
Name _1B.09.P.040.0030: #REF!
Name _1B.09.P.050.0010: #REF!
Name _1B.09.P.050.0020: #REF!
Name _1B.09.P.060.0010: #REF!
Name _1B.09.P.060.0020: #REF!
Name _1B.09.P.060.0030: #REF!

Sheet DB
A1: ='Weekly Progress Report'!#REF! -> #REF!
B2: ='Weekly Progress Report'!#REF! -> #REF! | J2: ='Weekly Progress Report'!F2 -> Key Dates | U2: ='Weekly Progress Report'!$L$2 -> Cost Summary (SR) | AD2: ='Weekly Progress Report'!$T$2 -> Performance Summary | AP2: ='Weekly Progress Report'!#REF! -> #REF! | AT2: ='Weekly Progress Report'!#REF! -> #REF! | AW2: ='Weekly Progress Report'!#REF! -> #REF! | BD2: ='Weekly Progress Report'!K51 -> Quality Reports | BT2: ='Weekly Progress Report'!K59 -> Key Submittals Approval Status | CD2: ='Weekly Progress Report'!K65 -> Invoices Summary | CR2: ='Weekly Progress Report'!K73 -> Resources at Site | CY2: ='Weekly Progress Report'!V51 -> Safety Statistics | FK2: ='Weekly Progress Report'!#REF! -> #REF! | FS2: ='Weekly Progress Report'!#REF! -> #REF!
A3: ='Weekly Progress Report'!AE1 -> Data Date | B3: ='Weekly Progress Report'!#REF! -> #REF! | C3: ='Weekly Progress Report'!#REF! -> #REF! | D3: ='Weekly Progress Report'!#REF! -> #REF! | E3: ='Weekly Progress Report'!#REF! -> #REF! | F3: ='Weekly Progress Report'!C4 -> Stage | G3: ='Weekly Progress Report'!C5 -> Status | H3: ='Weekly Progress Report'!C6 -> Modon PM | I3: ='Weekly Progress Report'!Z2 -> Project Scope | J3: ='Weekly Progress Report'!F3 -> Contract Award | K3: ='Weekly Progress Report'!F4 -> Contract Sign | L3: ='Weekly Progress Report'!F5 -> Site Handover | M3: ='Weekly Progress Report'!F6 -> Original Completion | N3: ='Weekly Progress Report'!$H$3 -> Contract Award (Hijri) | O3: ='Weekly Progress Report'!$H$4 -> Contract Sign (Hijri) | P3: ='Weekly Progress Report'!$H$5 -> Site Handover (Hijri) | Q3: ='Weekly Progress Report'!$H$6 -> Original Completion (Hijri) | R3: ='Weekly Progress Report'!$J$3 -> Revised Completion | S3: ='Weekly Progress Report'!$J$4 -> Committed Completion | T3: ='Weekly Progress Report'!$J$5 -> Forecast Completion | U3: ='Weekly Progress Report'!$L$3 -> Original Contract Value | V3: ='Weekly Progress Report'!$L$4 -> Revised Contract Value | W3: ='Weekly Progress Report'!$L$5 -> Estimate At Completion Value | X3: ='Weekly Progress Report'!$L$6 -> Potential Changes | Y3: ='Weekly Progress Report'!$P$3 -> O&M Value (if any) | Z3: ='Weekly Progress Report'!$P$4 -> Submitted Invoices (Gross Value) | AA3: ='Weekly Progress Report'!$P$5 -> Penalities | AB3: ='Weekly Progress Report'!$P$6 -> FIR Value (Todate) | AC3: Original Plan Value | AD3: ='Weekly Progress Report'!$T$3 -> Plan Value | AE3: ='Weekly Progress Report'!$T$4 -> Earn Value | AF3: ='Weekly Progress Report'!$V$3 -> Phys. Plan Value | AG3: ='Weekly Progress Report'!$V$4 -> Phys. Earn Value | AH3: ='Weekly Progress Report'!$X$3 -> Quality Score | AI3: ='Weekly Progress Report'!$X$5 -> Safety Score | AJ3: Weekly PV (SAR) | AK3: Weekly EV (SAR) | AL3: Weekly PV % | AM3: Weekly PV % | AN3: Weekly Phys PV% | AO3: Weekly Phys PV% | AP3: Total SD Planned | AQ3: SD Remaining | AR3: SD Pending | AS3: Total SD Submittals | AT3: Planned Materials Approv | AU3: Material Pending Approval | AV3: Materila Total Submittals | AW3: ='Weekly Progress Report'!B70 -> Total Materials | AX3: ='Weekly Progress Report'!C70 -> Total Number of P.O. | AY3: ='Weekly Progress Report'!D70 -> Actual P.O. To Date | AZ3: ='Weekly Progress Report'!E70 -> Remaining P.O | BA3: ='Weekly Progress Report'!F70 -> Material on Site | BB3: ='Weekly Progress Report'!G70 -> Remaining Materials | BC3: ='Weekly Progress Report'!H70 -> Material Delivery Completion (Date) | BD3: ="NCR "&'Weekly Progress Report'!M52 -> NCR Issued | BE3: ="NCR "&'Weekly Progress Report'!N52 -> NCR Closed | BF3: ="NCR "&'Weekly Progress Report'!O52 -> NCR Pending | BG3: ="NCR "&'Weekly Progress Report'!P52 -> NCR Avg. Closing (Days) | BH3: ="SIR "&'Weekly Progress Report'!M52 -> SIR Issued | BI3: ="SIR "&'Weekly Progress Report'!N52 -> SIR Closed | BJ3: ="SIR "&'Weekly Progress Report'!O52 -> SIR Pending | BK3: ="SIR "&'Weekly Progress Report'!P52 -> SIR Avg. Closing (Days) | BL3: ="MIR "&'Weekly Progress Report'!M52 -> MIR Issued | BM3: ="MIR "&'Weekly Progress Report'!N52 -> MIR Closed | BN3: ="MIR "&'Weekly Progress Report'!O52 -> MIR Pending | BO3: ="MIR "&'Weekly Progress Report'!P52 -> MIR Avg. Closing (Days) | BP3: ="FIR "&'Weekly Progress Report'!M52 -> FIR Issued | BQ3: ="FIR "&'Weekly Progress Report'!N52 -> FIR Closed | BR3: ="FIR "&'Weekly Progress Report'!O52 -> FIR Pending | BS3: ="FIR "&'Weekly Progress Report'!P52 -> FIR Avg. Closing (Days) | BT3: ='Weekly Progress Report'!K60 -> 1 Quality Plan Approval | BU3: ='Weekly Progress Report'!K61 -> 2 Quality Plan Last Up | BV3: ='Weekly Progress Report'!K62 -> 3 Safety Plan Approval | BW3: ='Weekly Progress Report'!K63 -> 4 Safety Plan Last Up | BX3: ='Weekly Progress Report'!K64 -> 5 Execution Plan Approval | BY3: ='Weekly Progress Report'!P60 -> 6 Baseline Approval | BZ3: ='Weekly Progress Report'!P61 -> 7 No of Approved Version of Schedule | CA3: ='Weekly Progress Report'!P62 -> 8 Last Approved Schedule | CB3: ='Weekly Progress Report'!P63 -> 9 BOQ Approval Date | CC3: ='Weekly Progress Report'!P64 -> 10 No of Approved Version of BOQ | CD3: ='Weekly Progress Report'!K66 -> Total Submitted Invoices | CE3: ='Weekly Progress Report'!K67 -> PM Approved Invoices | CF3: ='Weekly Progress Report'!K68 -> No of Paid Invoices | CG3: ='Weekly Progress Report'!K69 -> No of Pending Invoices | CH3: ='Weekly Progress Report'!K70 -> Advance Payment % | CI3: ='Weekly Progress Report'!K71 -> Retention % | CJ3: ='Weekly Progress Report'!K72 -> Deduction / Penalties % | CK3: ='Weekly Progress Report'!N66 -> Submitted Invoices (SAR) | CL3: ='Weekly Progress Report'!N67 -> PM Approved Invoices (SAR) | CM3: ='Weekly Progress Report'!N68 -> Paid Invoices (SAR) | CN3: ='Weekly Progress Report'!N69 -> Last Submitted Period | CO3: ='Weekly Progress Report'!N70 -> Advance Payment (SAR) | CP3: ='Weekly Progress Report'!N71 -> Retention (SAR) | CQ3: ='Weekly Progress Report'!N72 -> Deduction / Penalties (SAR) | CR3: Planned Head Count | CS3: Actual Head Count | CT3: Saudi Staff | CU3: Labor Planned | CV3: Labor Actual | CW3: Equipment Planned | CX3: Equipment Actual | CY3: ="This Week "&'Weekly Progress Report'!W54 -> This Week Total Hours Worked | CZ3: ="This Week "&'Weekly Progress Report'!W55 -> This Week Safe Hours Worked | DA3: ="This Week "&'Weekly Progress Report'!W56 -> This Week LTI | DB3: ="This Week "&'Weekly Progress Report'!W57 -> This Week MTC (Healed w/o Disability) | DC3: ="This Week "&'Weekly Progress Report'!W58 -> This Week MTC (Healed w/ Disability) | DD3: ="This Week "&'Weekly Progress Report'!W59 -> This Week Near Miss | DE3: ="This Week "&'Weekly Progress Report'!W60 -> This Week First Aid Cases | DF3: ="This Week "&'Weekly Progress Report'!W61 -> This Week Fatality | DG3: ="This Week "&'Weekly Progress Report'!W62 -> This Week Fire Incident Cases | DH3: ="This Week "&'Weekly Progress Report'!W63 -> This Week Vehicle Incident | DI3: ="This Week "&'Weekly Progress Report'!W64 -> This Week Property Damages | DJ3: ="This Week "&'Weekly Progress Report'!W65 -> This Week Induction Training | DK3: ="This Week "&'Weekly Progress Report'!W66 -> This Week No.of Internal Training | DL3: ="This Week "&'Weekly Progress Report'!W67 -> This Week No.of Internal Audit | DM3: ="This Week "&'Weekly Progress Report'!W68 -> This Week No. of Toolbox Talks | DN3: ="This Week "&'Weekly Progress Report'!W69 -> This Week Safety Awards/Incentives | DO3: ="This Month "&'Weekly Progress Report'!W54 -> This Month Total Hours Worked | DP3: ="This Month "&'Weekly Progress Report'!W55 -> This Month Safe Hours Worked | DQ3: ="This Month "&'Weekly Progress Report'!W56 -> This Month LTI | DR3: ="This Month "&'Weekly Progress Report'!W57 -> This Month MTC (Healed w/o Disability) | DS3: ="This Month "&'Weekly Progress Report'!W58 -> This Month MTC (Healed w/ Disability) | DT3: ="This Month "&'Weekly Progress Report'!W59 -> This Month Near Miss | DU3: ="This Month "&'Weekly Progress Report'!W60 -> This Month First Aid Cases | DV3: ="This Month "&'Weekly Progress Report'!W61 -> This Month Fatality | DW3: ="This Month "&'Weekly Progress Report'!W62 -> This Month Fire Incident Cases | DX3: ="This Month "&'Weekly Progress Report'!W63 -> This Month Vehicle Incident | DY3: ="This Month "&'Weekly Progress Report'!W64 -> This Month Property Damages | DZ3: ="This Month "&'Weekly Progress Report'!W65 -> This Month Induction Training | EA3: ="This Month "&'Weekly Progress Report'!W66 -> This Month No.of Internal Training | EB3: ="This Month "&'Weekly Progress Report'!W67 -> This Month No.of Internal Audit | EC3: ="This Month "&'Weekly Progress Report'!W68 -> This Month No. of Toolbox Talks | ED3: ="This Month "&'Weekly Progress Report'!W69 -> This Month Safety Awards/Incentives | EE3: ="YTD "&'Weekly Progress Report'!W54 -> YTD Total Hours Worked | EF3: ="YTD "&'Weekly Progress Report'!W55 -> YTD Safe Hours Worked | EG3: ="YTD "&'Weekly Progress Report'!W56 -> YTD LTI | EH3: ="YTD "&'Weekly Progress Report'!W57 -> YTD MTC (Healed w/o Disability) | EI3: ="YTD "&'Weekly Progress Report'!W58 -> YTD MTC (Healed w/ Disability) | EJ3: ="YTD "&'Weekly Progress Report'!W59 -> YTD Near Miss | EK3: ="YTD "&'Weekly Progress Report'!W60 -> YTD First Aid Cases | EL3: ="YTD "&'Weekly Progress Report'!W61 -> YTD Fatality | EM3: ="YTD "&'Weekly Progress Report'!W62 -> YTD Fire Incident Cases | EN3: ="YTD "&'Weekly Progress Report'!W63 -> YTD Vehicle Incident | EO3: ="YTD "&'Weekly Progress Report'!W64 -> YTD Property Damages | EP3: ="YTD "&'Weekly Progress Report'!W65 -> YTD Induction Training | EQ3: ="YTD "&'Weekly Progress Report'!W66 -> YTD No.of Internal Training | ER3: ="YTD "&'Weekly Progress Report'!W67 -> YTD No.of Internal Audit | ES3: ="YTD "&'Weekly Progress Report'!W68 -> YTD No. of Toolbox Talks | ET3: ="YTD "&'Weekly Progress Report'!W69 -> YTD Safety Awards/Incentives | EU3: ="Cum "&'Weekly Progress Report'!W54 -> Cum Total Hours Worked | EV3: ="Cum "&'Weekly Progress Report'!W55 -> Cum Safe Hours Worked | EW3: ="Cum "&'Weekly Progress Report'!W56 -> Cum LTI | EX3: ="Cum "&'Weekly Progress Report'!W57 -> Cum MTC (Healed w/o Disability) | EY3: ="Cum "&'Weekly Progress Report'!W58 -> Cum MTC (Healed w/ Disability) | EZ3: ="Cum "&'Weekly Progress Report'!W59 -> Cum Near Miss | FA3: ="Cum "&'Weekly Progress Report'!W60 -> Cum First Aid Cases | FB3: ="Cum "&'Weekly Progress Report'!W61 -> Cum Fatality | FC3: ="Cum "&'Weekly Progress Report'!W62 -> Cum Fire Incident Cases | FD3: ="Cum "&'Weekly Progress Report'!W63 -> Cum Vehicle Incident | FE3: ="Cum "&'Weekly Progress Report'!W64 -> Cum Property Damages | FF3: ="Cum "&'Weekly Progress Report'!W65 -> Cum Induction Training | FG3: ="Cum "&'Weekly Progress Report'!W66 -> Cum No.of Internal Training | FH3: ="Cum "&'Weekly Progress Report'!W67 -> Cum No.of Internal Audit | FI3: ="Cum "&'Weekly Progress Report'!W68 -> Cum No. of Toolbox Talks | FJ3: ="Cum "&'Weekly Progress Report'!W69 -> Cum Safety Awards/Incentives | FK3: ='Weekly Progress Report'!#REF! -> #REF! | FL3: ='Weekly Progress Report'!A81 -> Not Started | FM3: ='Weekly Progress Report'!B81 -> In Progress | FN3: ='Weekly Progress Report'!C81 -> Completed | FO3: Critical Path Act.Last Week | FP3: Critical Path Act.This Week | FQ3: Failed start Last Week | FR3: Failed start This Week | FS3: ='Weekly Progress Report'!A89 -> 0 | FT3: ='Weekly Progress Report'!C89 -> 0 | FU3: ='Weekly Progress Report'!E89 -> 0 | FV3: ='Weekly Progress Report'!G89 -> 0 | FW3: ='Weekly Progress Report'!I89 -> 0 | FX3: ='Weekly Progress Report'!K89 -> 0 | FY3: ='Weekly Progress Report'!M89 -> 0 | FZ3: ='Weekly Progress Report'!N89 -> 0 | GA3: ='Weekly Progress Report'!O89 -> 0
A4: ='Weekly Progress Report'!AF1 -> 46301 | B4: ='Weekly Progress Report'!A3 -> Completion of Infrastructure Works in The Second Industrial City in Makkah Al-Mukarramah | C4: ='Weekly Progress Report'!A4 -> MKH2-02-003 | D4: ='Weekly Progress Report'!A5 -> Al Enjaz Trading & Contracting Co. | E4: ='Weekly Progress Report'!A6 -> Saudi Arabia Consulting Engineering Company "EGIS" | F4: ='Weekly Progress Report'!D4 -> Construction | G4: ='Weekly Progress Report'!D5 -> Active | H4: ='Weekly Progress Report'!D6 -> Engr. Abdallah Aljulaifi | I4: ='Weekly Progress Report'!Z3 -> Completion of Infrastruture in The Second Industrial City in Makkah (The project includes construction of Roads works ; Box Culvert ; Open Drain Channels and Dike Walls ; Street Lightings and Low Voltage Cables ,concrete ducts at road crossing) | J4: ='Weekly Progress Report'!G3 -> 46054 | K4: ='Weekly Progress Report'!G4 -> 46061 | L4: ='Weekly Progress Report'!G5 -> 46068 | M4: ='Weekly Progress Report'!G6 -> 46613 | N4: ='Weekly Progress Report'!$I$3 -> 01/02/1447 | O4: ='Weekly Progress Report'!$I$4 -> 08/02/1447 | P4: ='Weekly Progress Report'!$I$5 -> 15/02/1447 | Q4: ='Weekly Progress Report'!$I$6 -> 14/08/1447 | R4: ='Weekly Progress Report'!$K$3 -> 46613 | S4: ='Weekly Progress Report'!$K$4 -> 46613 | T4: ='Weekly Progress Report'!$K$5 -> 46656 | U4: ='Weekly Progress Report'!$N$3 -> 52025516 | V4: ='Weekly Progress Report'!$N$4 -> 52025516 | W4: ='Weekly Progress Report'!$N$5 -> 52025516 | X4: ='Weekly Progress Report'!$N$6 -> 0 | Y4: ='Weekly Progress Report'!$R$3 -> 0 | Z4: ='Weekly Progress Report'!$R$4 -> 29797667 | AA4: ='Weekly Progress Report'!$R$5 -> 2000 | AB4: ='Weekly Progress Report'!$R$6 -> 39126422 | AC4: ='Weekly Progress Report'!$I$21 -> 0.54006746 | AD4: ='Weekly Progress Report'!$U$3 -> 0.54006746 | AE4: ='Weekly Progress Report'!$U$4 -> 0.75315522 | AF4: ='Weekly Progress Report'!$W$3 -> 0.47063179 | AG4: ='Weekly Progress Report'!$W$4 -> 0.77964053 | AH4: ='Weekly Progress Report'!$Y$3 -> 0.89948276 | AI4: ='Weekly Progress Report'!$Y$5 -> 0.86363636 | AJ4: ='Weekly Progress Report'!$D$21 -> 744805.52 | AK4: ='Weekly Progress Report'!$E$21 -> 479130.67 | AL4: =AJ4/V4 -> 0.014316158 | AM4: =AK4/V4 -> 0.0092095323 | AN4: ='Weekly Progress Report'!R21 -> 0.016024373 | AO4: ='Weekly Progress Report'!S21 -> 0.0089553934 | AP4: ='Weekly Progress Report'!B59 -> 36 | AQ4: ='Weekly Progress Report'!H59 -> 0 | AR4: ='Weekly Progress Report'!I59 -> 0 | AS4: ='Weekly Progress Report'!J59 -> 36 | AT4: ='Weekly Progress Report'!B68 -> 65 | AU4: ='Weekly Progress Report'!I68 -> 0 | AV4: ='Weekly Progress Report'!J68 -> 65 | AW4: ='Weekly Progress Report'!B77 -> 18 | AX4: ='Weekly Progress Report'!C77 -> 18 | AY4: ='Weekly Progress Report'!D77 -> 18 | AZ4: ='Weekly Progress Report'!E77 -> 0 | BA4: ='Weekly Progress Report'!F77 -> 17 | BB4: ='Weekly Progress Report'!G77 -> 1 | BC4: ='Weekly Progress Report'!H77 -> 46325 | BD4: ='Weekly Progress Report'!M55 -> 9 | BE4: ='Weekly Progress Report'!N55 -> 9 | BF4: ='Weekly Progress Report'!O55 -> 0 | BG4: ='Weekly Progress Report'!P55 -> 3 | BH4: ='Weekly Progress Report'!M56 -> 24 | BI4: ='Weekly Progress Report'!N56 -> 22 | BJ4: ='Weekly Progress Report'!O56 -> 2 | BK4: ='Weekly Progress Report'!P56 -> 3 | BL4: ='Weekly Progress Report'!M57 -> 31 | BM4: ='Weekly Progress Report'!N57 -> 31 | BN4: ='Weekly Progress Report'!O57 -> 0 | BO4: ='Weekly Progress Report'!P57 -> 5 | BP4: ='Weekly Progress Report'!M58 -> 880 | BQ4: ='Weekly Progress Report'!N58 -> 863 | BR4: ='Weekly Progress Report'!O58 -> 17 | BS4: ='Weekly Progress Report'!P58 -> 4 | BT4: ='Weekly Progress Report'!N60 -> 46110 | BU4: ='Weekly Progress Report'!N61 -> 46110 | BV4: ='Weekly Progress Report'!N62 -> 46090 | BW4: ='Weekly Progress Report'!N63 -> 46090 | BX4: ='Weekly Progress Report'!N64 -> 46072 | BY4: ='Weekly Progress Report'!T60 -> 45717 | BZ4: ='Weekly Progress Report'!T61 -> 1 | CA4: ='Weekly Progress Report'!T62 -> 45717 | CB4: ='Weekly Progress Report'!T63 -> 0 | CC4: ='Weekly Progress Report'!T64 -> 0 | CD4: ='Weekly Progress Report'!M66 -> 0 | CE4: ='Weekly Progress Report'!M67 -> 7 | CF4: ='Weekly Progress Report'!M68 -> 6 | CG4: ='Weekly Progress Report'!M69 -> 1 | CH4: ='Weekly Progress Report'!M70 -> 0 | CI4: ='Weekly Progress Report'!M71 -> 0 | CJ4: ='Weekly Progress Report'!M72 -> 3.8442675e-05 | CK4: ='Weekly Progress Report'!Q66 -> 34267317 | CL4: ='Weekly Progress Report'!Q67 -> 34269317 | CM4: ='Weekly Progress Report'!Q68 -> 31459715 | CN4: ='Weekly Progress Report'!Q69 -> 0 | CO4: ='Weekly Progress Report'!Q70 -> 0 | CP4: ='Weekly Progress Report'!Q71 -> 0 | CQ4: ='Weekly Progress Report'!Q72 -> 2000 | CR4: ='Weekly Progress Report'!K76 -> 12 | CS4: ='Weekly Progress Report'!L76 -> 27 | CT4: ='Weekly Progress Report'!N76 -> 0 | CU4: ='Weekly Progress Report'!O76 -> 105 | CV4: ='Weekly Progress Report'!P76 -> 121 | CW4: ='Weekly Progress Report'!S86 -> 50 | CX4: ='Weekly Progress Report'!T86 -> 65 | CY4: ='Weekly Progress Report'!Y54 -> 7560 | CZ4: ='Weekly Progress Report'!Y55 -> 7560 | DA4: ='Weekly Progress Report'!Y56 -> 0 | DB4: ='Weekly Progress Report'!Y57 -> 0 | DC4: ='Weekly Progress Report'!Y58 -> 0 | DD4: ='Weekly Progress Report'!Y59 -> 1 | DE4: ='Weekly Progress Report'!Y60 -> 0 | DF4: ='Weekly Progress Report'!Y61 -> 0 | DG4: ='Weekly Progress Report'!Y62 -> 0 | DH4: ='Weekly Progress Report'!Y63 -> 0 | DI4: ='Weekly Progress Report'!Y64 -> 0 | DJ4: ='Weekly Progress Report'!Y65 -> 0 | DK4: ='Weekly Progress Report'!Y66 -> 1 | DL4: ='Weekly Progress Report'!Y67 -> 0 | DM4: ='Weekly Progress Report'!Y68 -> 1 | DN4: ='Weekly Progress Report'!Y69 -> 0 | DO4: ='Weekly Progress Report'!AA54 -> 7560 | DP4: ='Weekly Progress Report'!AA55 -> 7560 | DQ4: ='Weekly Progress Report'!AA56 -> 0 | DR4: ='Weekly Progress Report'!AA57 -> 0 | DS4: ='Weekly Progress Report'!AA58 -> 0 | DT4: ='Weekly Progress Report'!AA59 -> 1 | DU4: ='Weekly Progress Report'!AA60 -> 0 | DV4: ='Weekly Progress Report'!AA61 -> 0 | DW4: ='Weekly Progress Report'!AA62 -> 0 | DX4: ='Weekly Progress Report'!AA63 -> 0 | DY4: ='Weekly Progress Report'!AA64 -> 0 | DZ4: ='Weekly Progress Report'!AA65 -> 0 | EA4: ='Weekly Progress Report'!AA66 -> 1 | EB4: ='Weekly Progress Report'!AA67 -> 2 | EC4: ='Weekly Progress Report'!AA68 -> 1 | ED4: ='Weekly Progress Report'!AA69 -> 0 | EE4: ='Weekly Progress Report'!AB54 -> 184540 | EF4: ='Weekly Progress Report'!AB55 -> 184540 | EG4: ='Weekly Progress Report'!AB56 -> 0 | EH4: ='Weekly Progress Report'!AB57 -> 0 | EI4: ='Weekly Progress Report'!AB58 -> 0 | EJ4: ='Weekly Progress Report'!AB59 -> 1 | EK4: ='Weekly Progress Report'!AB60 -> 0 | EL4: ='Weekly Progress Report'!AB61 -> 0 | EM4: ='Weekly Progress Report'!AB62 -> 0 | EN4: ='Weekly Progress Report'!AB63 -> 0 | EO4: ='Weekly Progress Report'!AB64 -> 0 | EP4: ='Weekly Progress Report'!AB65 -> 12 | EQ4: ='Weekly Progress Report'!AB66 -> 36 | ER4: ='Weekly Progress Report'!AB67 -> 2 | ES4: ='Weekly Progress Report'!AB68 -> 49 | ET4: ='Weekly Progress Report'!AB69 -> 0 | EU4: ='Weekly Progress Report'!AC54 -> 184540 | EV4: ='Weekly Progress Report'!AC55 -> 184540 | EW4: ='Weekly Progress Report'!AC56 -> 0 | EX4: ='Weekly Progress Report'!AC57 -> 0 | EY4: ='Weekly Progress Report'!AC58 -> 0 | EZ4: ='Weekly Progress Report'!AC59 -> 1 | FA4: ='Weekly Progress Report'!AC60 -> 0 | FB4: ='Weekly Progress Report'!AC61 -> 0 | FC4: ='Weekly Progress Report'!AC62 -> 0 | FD4: ='Weekly Progress Report'!AC63 -> 0 | FE4: ='Weekly Progress Report'!AC64 -> 0 | FF4: ='Weekly Progress Report'!AC65 -> 12 | FG4: ='Weekly Progress Report'!AC66 -> 36 | FH4: ='Weekly Progress Report'!AC67 -> 2 | FI4: ='Weekly Progress Report'!AC68 -> 49 | FJ4: ='Weekly Progress Report'!AC69 -> 0 | FK4: ='Weekly Progress Report'!#REF! -> #REF! | FL4: ='Weekly Progress Report'!A82 -> 59 | FM4: ='Weekly Progress Report'!B82 -> 33 | FN4: ='Weekly Progress Report'!C82 -> 307 | FO4: ='Weekly Progress Report'!#REF! -> #REF! | FP4: ='Weekly Progress Report'!A86 -> 67 | FQ4: ='Weekly Progress Report'!G86 -> 9 | FR4: ='Weekly Progress Report'!H86 -> 8 | FS4: ='Weekly Progress Report'!A94 -> 0 | FT4: ='Weekly Progress Report'!C94 -> 0 | FU4: ='Weekly Progress Report'!E94 -> 0 | FV4: ='Weekly Progress Report'!G94 -> 0 | FW4: ='Weekly Progress Report'!I94 -> 0 | FX4: ='Weekly Progress Report'!K94 -> 0 | FY4: ='Weekly Progress Report'!M94 -> 0 | FZ4: ='Weekly Progress Report'!N94 -> 0 | GA4: ='Weekly Progress Report'!O94 -> 0

Sheet Weekly Progress Report
AC1: =+HSE!L4 -> Report No. | AD1: ='General Information'!O1 -> 34 | AE1: Data Date | AF1: ='General Information'!L1 -> 46301
F2: Key Dates | L2: Cost Summary (SR) | T2: Performance Summary | Z2: Project Scope
A3: ='General Information'!C3 -> Completion of Infrastructure Works in The Second Industrial City in Makkah Al-Mukarramah | F3: Contract Award | G3: ='General Information'!C12 -> 46054 | H3: Contract Award (Hijri) | I3: ='General Information'!C16 -> 01/02/1447 | J3: Revised Completion | K3: ='General Information'!C20 -> 46613 | L3: Original Contract Value | N3: ='Invoice Log'!E3 -> 52025516 | P3: O&M Value (if any) | R3: ='Invoice Log'!I3 -> 0 | S3: EAC | T3: Plan Value | U3: =J21 -> 0.54006746 | V3: Phys. Plan Value | W3: =V21 -> 0.47063179 | X3: Quality Score | Y3: =Quality!AC10 -> 0.89948276 | Z3: =+Progress!A1 -> Completion of Infrastruture in The Second Industrial City in Makkah (The project includes construction of Roads works ; Box Culvert ; Open Drain Channels and Dike Walls ; Street Lightings and Low Voltage Cables ,concrete ducts at road crossing)
A4: ='General Information'!C4 -> MKH2-02-003 | C4: Stage | D4: ='General Information'!C7 -> Construction | F4: Contract Sign | G4: ='General Information'!C13 -> 46061 | H4: Contract Sign (Hijri) | I4: ='General Information'!C17 -> 08/02/1447 | J4: Committed Completion | K4: ='General Information'!C21 -> 46613 | L4: Revised Contract Value | N4: ='Invoice Log'!E4 -> 52025516 | O4: EAC | P4: Submitted Invoices (Gross Value) | R4: =+'Invoice Log'!F59 -> 29797667 | T4: Earn Value | U4: =K21 -> 0.75315522 | V4: Phys. Earn Value | W4: =W21 -> 0.77964053 | Y4: =REPT("¢",IF(INT(+Y3*10)>5,5,INT(+Y3*10)))&REPT("£",IF(INT(+Y3*10)>5,0,5-INT(+Y3*10)))&CHAR(10)&REPT("¢",+IF(INT(+Y3*10)>5,-5+INT(+Y3*10),0))&REPT("£",IF(INT(+Y3*10)>5,10-INT(+Y3*10),5)) -> ¢¢¢¢¢ ¢¢¢££
A5: ='General Information'!C5 -> Al Enjaz Trading & Contracting Co. | C5: Status | D5: ='General Information'!C8 -> Active | F5: Site Handover | G5: ='General Information'!C14 -> 46068 | H5: Site Handover (Hijri) | I5: ='General Information'!C18 -> 15/02/1447 | J5: Forecast Completion | K5: ='General Information'!C22 -> 46656 | L5: Estimate At Completion Value | N5: ='Invoice Log'!E5 -> 52025516 | O5: =+#REF!+#REF!+N5 -> #REF! | P5: Penalities | R5: ='Invoice Log'!M6 -> 2000 | T5: Variance | U5: =U4-U3 -> 0.21308776 | V5: Variance | W5: =W4-W3 -> 0.30900874 | X5: Safety Score | Y5: ='HSE-Stat'!J23 -> 0.86363636
A6: ='General Information'!C6 -> Saudi Arabia Consulting Engineering Company "EGIS" | C6: Modon PM | D6: ='General Information'!C9 -> Engr. Abdallah Aljulaifi | F6: Original Completion | G6: ='General Information'!C15 -> 46613 | H6: Original Completion (Hijri) | I6: ='General Information'!C19 -> 14/08/1447 | J6: Variance | K6: ='General Information'!C23 -> -43 | L6: Potential Changes | N6: =N4-N5 -> 0 | P6: FIR Value (Todate) | R6: =+'FIR summary '!K2 -> 39126422 | T6: FIR % | U6: =R6/N4 -> 0.75206216 | V6: Invoiced % | W6: =R4/N4 -> 0.57275102 | Y6: =REPT("¢",IF(INT(+Y5*10)>5,5,INT(+Y5*10)))&REPT("£",IF(INT(+Y5*10)>5,0,5-INT(+Y5*10)))&CHAR(10)&REPT("¢",+IF(INT(+Y5*10)>5,-5+INT(+Y5*10),0))&REPT("£",IF(INT(+Y5*10)>5,10-INT(+Y5*10),5)) -> ¢¢¢¢¢ ¢¢¢££
N9: Physical Progress (Effort) | Z9: Earned Value Progress (%)
B10: BOQ Value (SAR) | C10: % Wt. | D10: Weekly (SAR) | F10: To Date (SAR) | N10: Budgeted | O10: % Wt. | P10: Weekly Physical Progress | T10: To Date Physical Progress
D11: Planned | E11: Earned | F11: Original Plan | G11: Revised Planned | H11: Earned | I11: Original Plan % | J11: Revised Planned % | K11: Earned % | L11: Variance | M11: SPI | N11: (Manhours) | P11: Planned | Q11: Earned | R11: Plan % | S11: Earned % | T11: Planned | U11: Earned | V11: Plan % | W11: Earned % | X11: Variance | Y11: SPI
B12: =+Progress!B7 -> 0 | C12: =IF(ISBLANK(B12),"",B12/$B$21) -> 0 | D12: =+Progress!D7 -> 0 | E12: =+Progress!E7 -> - | F12: =+Progress!F7 -> 0 | G12: =+Progress!G7 -> 0 | H12: =+Progress!H7 -> - | I12: =IFERROR(IF(ISBLANK(F12),"",F12/B12),0) -> 0 | J12: =IFERROR(IF(ISBLANK(G12),"",G12/B12),0) -> 0 | K12: =IFERROR(IF(ISBLANK(H12),"",H12/B12),0) -> 0 | L12: =IFERROR(K12-J12,"") -> 0 | M12: =IFERROR(K12/J12,"") | N12: =+Progress!J7 -> 14738 | O12: =IF(ISBLANK(N12),"",N12/$N$21) -> 0.029894584 | P12: =+Progress!L7 -> 0 | Q12: =+Progress!M7 -> 0 | R12: =IFERROR(IF(ISBLANK(P12),"",P12/N12),0) -> 0 | S12: =IFERROR(IF(ISBLANK(Q12),"",Q12/N12),0) -> 0 | T12: =+Progress!N7 -> 14738 | U12: =+Progress!O7 -> 14738 | V12: =IFERROR(IF(ISBLANK(T12),"",T12/N12),0) -> 1 | W12: =IFERROR(IF(ISBLANK(U12),"",U12/N12),0) -> 1 | X12: =IFERROR(W12-V12,"") -> 0 | Y12: =IFERROR(W12/V12,"") -> 1
B13: =+Progress!B9 -> 1560765.5 | C13: =IF(ISBLANK(B13),"",B13/$B$21) -> 0.03 | D13: =+Progress!D9 -> 0 | E13: =+Progress!E9 -> 0 | F13: =+Progress!F9 -> 1560765.5 | G13: =+Progress!G9 -> 1560765.5 | H13: =+Progress!H9 -> 1560765.5 | I13: =IFERROR(IF(ISBLANK(F13),"",F13/B13),0) -> 1 | J13: =IFERROR(IF(ISBLANK(G13),"",G13/B13),0) -> 1 | K13: =IFERROR(IF(ISBLANK(H13),"",H13/B13),0) -> 1 | L13: =IFERROR(K13-J13,"") -> 0 | M13: =IFERROR(K13/J13,"") -> 1 | N13: =+Progress!J9 -> 24562 | O13: =IF(ISBLANK(N13),"",N13/$N$21) -> 0.049821602 | P13: =+Progress!L9 -> 0 | Q13: =+Progress!M9 -> 0 | R13: =IFERROR(IF(ISBLANK(P13),"",P13/N13),0) -> 0 | S13: =IFERROR(IF(ISBLANK(Q13),"",Q13/N13),0) -> 0 | T13: =+Progress!N9 -> 24562 | U13: =+Progress!O9 -> 24562 | V13: =IFERROR(IF(ISBLANK(T13),"",T13/N13),0) -> 1 | W13: =IFERROR(IF(ISBLANK(U13),"",U13/N13),0) -> 1 | X13: =IFERROR(W13-V13,"") -> 0 | Y13: =IFERROR(W13/V13,"") -> 1
B14: =+Progress!B11 -> 10405103 | C14: =IF(ISBLANK(B14),"",B14/$B$21) -> 0.2 | D14: =+Progress!D11 -> 0 | E14: =+Progress!E11 -> 0 | F14: =+Progress!F11 -> 10405103 | G14: =+Progress!G11 -> 10405103 | H14: =+Progress!H11 -> 10035314 | I14: =IFERROR(IF(ISBLANK(F14),"",F14/B14),0) -> 1 | J14: =IFERROR(IF(ISBLANK(G14),"",G14/B14),0) -> 1 | K14: =IFERROR(IF(ISBLANK(H14),"",H14/B14),0) -> 0.96446079 | L14: =IFERROR(K14-J14,"") -> -0.03553921 | M14: =IFERROR(K14/J14,"") -> 0.96446079 | N14: =+Progress!J11 -> 58936 | O14: =IF(ISBLANK(N14),"",N14/$N$21) -> 0.11954588 | P14: =+Progress!L11 -> 0 | Q14: =+Progress!M11 -> 0 | R14: =IFERROR(IF(ISBLANK(P14),"",P14/N14),0) -> 0 | S14: =IFERROR(IF(ISBLANK(Q14),"",Q14/N14),0) -> 0 | T14: =+Progress!N11 -> 58936 | U14: =+Progress!O11 -> 53158 | V14: =IFERROR(IF(ISBLANK(T14),"",T14/N14),0) -> 1 | W14: =IFERROR(IF(ISBLANK(U14),"",U14/N14),0) -> 0.90196145 | X14: =IFERROR(W14-V14,"") -> -0.09803855 | Y14: =IFERROR(W14/V14,"") -> 0.90196145
B15: =+Progress!B13 -> 18062898 | C15: =IF(ISBLANK(B15),"",B15/$B$21) -> 0.34719305 | D15: =+Progress!D13 -> 572058.61 | E15: =+Progress!E13 -> 369719.67 | F15: =+Progress!F13 -> 9650325.4 | G15: =+Progress!G13 -> 9650325.4 | H15: =+Progress!H13 -> 12299083 | I15: =IFERROR(IF(ISBLANK(F15),"",F15/B15),0) -> 0.53426231 | J15: =IFERROR(IF(ISBLANK(G15),"",G15/B15),0) -> 0.53426231 | K15: =IFERROR(IF(ISBLANK(H15),"",H15/B15),0) -> 0.68090309 | L15: =IFERROR(K15-J15,"") -> 0.14664078 | M15: =IFERROR(K15/J15,"") -> 1.2744734 | N15: =+Progress!J13 -> 118380 | O15: =IF(ISBLANK(N15),"",N15/$N$21) -> 0.24012219 | P15: =+Progress!L13 -> 3400 | Q15: =+Progress!M13 -> 1471 | R15: =IFERROR(IF(ISBLANK(P15),"",P15/N15),0) -> 0.028721068 | S15: =IFERROR(IF(ISBLANK(Q15),"",Q15/N15),0) -> 0.012426085 | T15: =+Progress!N13 -> 52420 | U15: =+Progress!O13 -> 64158 | V15: =IFERROR(IF(ISBLANK(T15),"",T15/N15),0) -> 0.44281129 | W15: =IFERROR(IF(ISBLANK(U15),"",U15/N15),0) -> 0.54196655 | X15: =IFERROR(W15-V15,"") -> 0.099155263 | Y15: =IFERROR(W15/V15,"") -> 1.2239222
B16: =+Progress!B15 -> 2353781.9 | C16: =IF(ISBLANK(B16),"",B16/$B$21) -> 0.045242836 | D16: =+Progress!D15 -> 51053.04 | E16: =+Progress!E15 -> 99763 | F16: =+Progress!F15 -> 240201.22 | G16: =+Progress!G15 -> 240201.22 | H16: =+Progress!H15 -> 1841818.2 | I16: =IFERROR(IF(ISBLANK(F16),"",F16/B16),0) -> 0.10204906 | J16: =IFERROR(IF(ISBLANK(G16),"",G16/B16),0) -> 0.10204906 | K16: =IFERROR(IF(ISBLANK(H16),"",H16/B16),0) -> 0.78249314 | L16: =IFERROR(K16-J16,"") -> 0.68044408 | M16: =IFERROR(K16/J16,"") -> 7.6678136 | N16: =+Progress!J15 -> 41030 | O16: =IF(ISBLANK(N16),"",N16/$N$21) -> 0.083225321 | P16: =+Progress!L15 -> 1320 | Q16: =+Progress!M15 -> 1432 | R16: =IFERROR(IF(ISBLANK(P16),"",P16/N16),0) -> 0.032171582 | S16: =IFERROR(IF(ISBLANK(Q16),"",Q16/N16),0) -> 0.034901292 | T16: =+Progress!N15 -> 7780 | U16: =+Progress!O15 -> 27784 | V16: =IFERROR(IF(ISBLANK(T16),"",T16/N16),0) -> 0.18961735 | W16: =IFERROR(IF(ISBLANK(U16),"",U16/N16),0) -> 0.67716305 | X16: =IFERROR(W16-V16,"") -> 0.4875457 | Y16: =IFERROR(W16/V16,"") -> 3.5712082
B17: =+Progress!B17 -> 189275 | C17: =IF(ISBLANK(B17),"",B17/$B$21) -> 0.0036381186 | D17: =+Progress!D17 -> 0 | E17: =+Progress!E17 -> 0 | F17: =+Progress!F17 -> 189275 | G17: =+Progress!G17 -> 189275 | H17: =+Progress!H17 -> 155775 | I17: =IFERROR(IF(ISBLANK(F17),"",F17/B17),0) -> 1 | J17: =IFERROR(IF(ISBLANK(G17),"",G17/B17),0) -> 1 | K17: =IFERROR(IF(ISBLANK(H17),"",H17/B17),0) -> 0.82300885 | L17: =IFERROR(K17-J17,"") -> -0.17699115 | M17: =IFERROR(K17/J17,"") -> 0.82300885 | N17: =+Progress!J17 -> 6490 | O17: =IF(ISBLANK(N17),"",N17/$N$21) -> 0.013164327 | P17: =+Progress!L17 -> 0 | Q17: =+Progress!M17 -> 0 | R17: =IFERROR(IF(ISBLANK(P17),"",P17/N17),0) -> 0 | S17: =IFERROR(IF(ISBLANK(Q17),"",Q17/N17),0) -> 0 | T17: =+Progress!N17 -> 6490 | U17: =+Progress!O17 -> 4390 | V17: =IFERROR(IF(ISBLANK(T17),"",T17/N17),0) -> 1 | W17: =IFERROR(IF(ISBLANK(U17),"",U17/N17),0) -> 0.67642527 | X17: =IFERROR(W17-V17,"") -> -0.32357473 | Y17: =IFERROR(W17/V17,"") -> 0.67642527
B18: =+Progress!B19 -> 3959941.2 | C18: =IF(ISBLANK(B18),"",B18/$B$21) -> 0.076115366 | D18: =+Progress!D19 -> 0 | E18: =+Progress!E19 -> 0 | F18: =+Progress!F19 -> 3959941.2 | G18: =+Progress!G19 -> 3959941.2 | H18: =+Progress!H19 -> 3959941.2 | I18: =IFERROR(IF(ISBLANK(F18),"",F18/B18),0) -> 1 | J18: =IFERROR(IF(ISBLANK(G18),"",G18/B18),0) -> 1 | K18: =IFERROR(IF(ISBLANK(H18),"",H18/B18),0) -> 1 | L18: =IFERROR(K18-J18,"") -> 0 | M18: =IFERROR(K18/J18,"") -> 1 | N18: =+Progress!J19 -> 17395 | O18: =IF(ISBLANK(N18),"",N18/$N$21) -> 0.035284047 | P18: =+Progress!L19 -> 0 | Q18: =+Progress!M19 -> 0 | R18: =IFERROR(IF(ISBLANK(P18),"",P18/N18),0) -> 0 | S18: =IFERROR(IF(ISBLANK(Q18),"",Q18/N18),0) -> 0 | T18: =+Progress!N19 -> 17395 | U18: =+Progress!O19 -> 17395 | V18: =IFERROR(IF(ISBLANK(T18),"",T18/N18),0) -> 1 | W18: =IFERROR(IF(ISBLANK(U18),"",U18/N18),0) -> 1 | X18: =IFERROR(W18-V18,"") -> 0 | Y18: =IFERROR(W18/V18,"") -> 1
B19: =+Progress!B21 -> 10291200 | C19: =IF(ISBLANK(B19),"",B19/$B$21) -> 0.19781063 | D19: =+Progress!D21 -> 121693.87 | E19: =+Progress!E21 -> 9648 | F19: =+Progress!F21 -> 2091676.8 | G19: =+Progress!G21 -> 2091676.8 | H19: =+Progress!H21 -> 9330592.4 | I19: =IFERROR(IF(ISBLANK(F19),"",F19/B19),0) -> 0.20324907 | J19: =IFERROR(IF(ISBLANK(G19),"",G19/B19),0) -> 0.20324907 | K19: =IFERROR(IF(ISBLANK(H19),"",H19/B19),0) -> 0.90665737 | L19: =IFERROR(K19-J19,"") -> 0.70340831 | M19: =IFERROR(K19/J19,"") -> 4.4608193 | N19: =+Progress!J21 -> 185220 | O19: =IF(ISBLANK(N19),"",N19/$N$21) -> 0.37570056 | P19: =+Progress!L21 -> 3180 | Q19: =+Progress!M21 -> 1512 | R19: =IFERROR(IF(ISBLANK(P19),"",P19/N19),0) -> 0.017168772 | S19: =IFERROR(IF(ISBLANK(Q19),"",Q19/N19),0) -> 0.0081632653 | T19: =+Progress!N21 -> 49700 | U19: =+Progress!O21 -> 178177 | V19: =IFERROR(IF(ISBLANK(T19),"",T19/N19),0) -> 0.26832955 | W19: =IFERROR(IF(ISBLANK(U19),"",U19/N19),0) -> 0.96197495 | X19: =IFERROR(W19-V19,"") -> 0.69364539 | Y19: =IFERROR(W19/V19,"") -> 3.5850503
B20: =+Progress!B23 -> 5202551.6 | C20: =IF(ISBLANK(B20),"",B20/$B$21) -> 0.1 | D20: =+Progress!D23 -> 0 | E20: =+Progress!E23 -> 0 | F20: =+Progress!F23 -> 0 | G20: =+Progress!G23 -> 0 | H20: =+Progress!H23 -> 0 | I20: =IFERROR(IF(ISBLANK(F20),"",F20/B20),0) -> 0 | J20: =IFERROR(IF(ISBLANK(G20),"",G20/B20),0) -> 0 | K20: =IFERROR(IF(ISBLANK(H20),"",H20/B20),0) -> 0 | L20: =IFERROR(K20-J20,"") -> 0 | M20: =IFERROR(K20/J20,"") | N20: =+Progress!J23 -> 14740 | O20: =IF(ISBLANK(N20),"",N20/$N$21) -> 0.029898641 | P20: =+Progress!L23 -> 0 | Q20: =+Progress!M23 -> 0 | R20: =IFERROR(IF(ISBLANK(P20),"",P20/N20),0) -> 0 | S20: =IFERROR(IF(ISBLANK(Q20),"",Q20/N20),0) -> 0 | T20: =+Progress!N23 -> 0 | U20: =+Progress!O23 -> 0 | V20: =IFERROR(IF(ISBLANK(T20),"",T20/N20),0) -> 0 | W20: =IFERROR(IF(ISBLANK(U20),"",U20/N20),0) -> 0 | X20: =IFERROR(W20-V20,"") -> 0 | Y20: =IFERROR(W20/V20,"")
A21: Total | B21: =SUM(B12:B20) -> 52025516 | C21: =SUM(C12:C20) -> 1 | D21: =SUM(D12:D20) -> 744805.52 | E21: =SUM(E12:E20) -> 479130.67 | F21: =SUM(F12:F20) -> 28097288 | G21: =SUM(G12:G20) -> 28097288 | H21: =SUM(H12:H20) -> 39183289 | I21: =IFERROR(IF(ISBLANK(F21),"",F21/B21),0) -> 0.54006746 | J21: =IFERROR(IF(ISBLANK(G21),"",G21/B21),0) -> 0.54006746 | K21: =IFERROR(IF(ISBLANK(H21),"",H21/B21),0) -> 0.75315522 | L21: =+K21-J21 -> 0.21308776 | M21: =K21/J21 -> 1.3945577 | N21: 492999 | O21: =SUM(O12:O20) -> 0.97665715 | P21: =SUM(P12:P20) -> 7900 | Q21: =SUM(Q12:Q20) -> 4415 | R21: =IFERROR(IF(ISBLANK(P21),"",P21/N21),0) -> 0.016024373 | S21: =IFERROR(IF(ISBLANK(Q21),"",Q21/N21),0) -> 0.0089553934 | T21: =SUM(T12:T20) -> 232021 | U21: =SUM(U12:U20) -> 384362 | V21: =IFERROR(IF(ISBLANK(T21),"",T21/N21),0) -> 0.47063179 | W21: =IFERROR(IF(ISBLANK(U21),"",U21/N21),0) -> 0.77964053 | X21: =+W21-V21 -> 0.30900874 | Y21: =W21/V21 -> 1.6565828
Z22: Construction Milestones
Z23: Item No. | AA23: Milestones | AC23: Original (Baseline) | AD23: Latest Plan | AE23: Forecast | AF23: Status | AG23: Days Change
Z24: =+Milestones!A4 -> 1 | AA24: =+Milestones!B4 -> Project Commencement Date | AC24: =+Milestones!C4 -> 46068 | AD24: =+Milestones!D4 -> 46068 | AE24: =+Milestones!E4 -> 46068 | AF24: =+Milestones!F4 -> A | AG24: =+Milestones!G4 -> 0
Z25: =+Milestones!A5 -> 2 | AA25: =+Milestones!B5 -> Project Kick Off Meeting/NTP | AC25: =+Milestones!C5 -> 46068 | AD25: =+Milestones!D5 -> 46068 | AE25: =+Milestones!E5 -> 46068 | AF25: =+Milestones!F5 -> A | AG25: =+Milestones!G5 -> 0
Z26: =+Milestones!A6 -> 3 | AA26: =+Milestones!B6 -> Project Completion | AC26: =+Milestones!C6 -> 46613 | AD26: =+Milestones!D6 -> 46613 | AE26: =+Milestones!E6 -> 46656 | AF26: =+Milestones!F6 -> F | AG26: =+Milestones!G6 -> -43
Z27: =+Milestones!A7 -> 4 | AA27: =+Milestones!B7 -> Completion of Mobilization | AC27: =+Milestones!C7 -> 46095 | AD27: =+Milestones!D7 -> 46095 | AE27: =+Milestones!E7 -> 46179 | AF27: =+Milestones!F7 -> A | AG27: =+Milestones!G7 -> -84
Z28: =+Milestones!A10 -> 7 | AA28: =+Milestones!B10 -> Completion of Long lead Materials Delivery | AC28: =+Milestones!C10 -> 46250 | AD28: =+Milestones!D10 -> 46250 | AE28: =+Milestones!E10 -> 46263 | AF28: =+Milestones!F10 -> A | AG28: =+Milestones!G10 -> -13
Z29: =+Milestones!A11 -> 8 | AA29: =+Milestones!B11 -> Completion of Road Works | AC29: =+Milestones!C11 -> 46370 | AD29: =+Milestones!D11 -> 46370 | AE29: =+Milestones!E11 -> 46425 | AF29: =+Milestones!F11 -> F | AG29: =+Milestones!G11 -> -55
Z30: =+Milestones!A12 -> 9 | AA30: =+Milestones!B12 -> Completion of Open Drain Channel | AC30: =+Milestones!C12 -> 46552 | AD30: =+Milestones!D12 -> 46552 | AE30: =+Milestones!E12 -> 46594 | AF30: =+Milestones!F12 -> F | AG30: =+Milestones!G12 -> -42
Z31: =+Milestones!A13 -> 10 | AA31: =+Milestones!B13 -> Completion of All Works | AC31: =+Milestones!C13 -> 46613 | AD31: =+Milestones!D13 -> 46613 | AE31: =+Milestones!E13 -> 46656 | AF31: =+Milestones!F13 -> F | AG31: =+Milestones!G13 -> -43
Z32: =+Milestones!A14 -> 11 | AA32: =+Milestones!B14 -> Final Handover | AC32: =+Milestones!C14 -> 46613 | AD32: =+Milestones!D14 -> 46613 | AE32: =+Milestones!E14 -> 46656 | AF32: =+Milestones!F14 -> F | AG32: =+Milestones!G14 -> -43
K50: Quality | V50: Safety
K51: Quality Reports | V51: Safety Statistics | AD51: Proactive Vs Reactive Actions Taken
B52: Total | C52: Total Submitted Drawings | H52: Remaining | I52: Pending | J52: Total Submittals | K52: Quality Reports | M52: Issued | N52: Closed | O52: Pending | P52: Avg. Closing (Days) | Q52: Pending | V52: Category | W52: Item | Y52: This Week | AA52: This Month | AB52: Year to Date | AC52: Cumulative
C53: A | D53: B | E53: C | F53: D | G53: Processed | Q53: 0-10 Days | R53: 11-20 Days | S53: 21-30 Days | T53: 31-60 Days | U53: > 60 Days
B54: =IF('Quality-Stat'!D13="","",'Quality-Stat'!D13) -> 0 | C54: =IF('Quality-Stat'!E13="","",'Quality-Stat'!E13) -> 0 | D54: =IF('Quality-Stat'!F13="","",'Quality-Stat'!F13) -> 0 | E54: =IF('Quality-Stat'!G13="","",'Quality-Stat'!G13) -> 0 | F54: =IF('Quality-Stat'!H13="","",'Quality-Stat'!H13) -> 0 | G54: =IF('Quality-Stat'!I13="","",'Quality-Stat'!I13) -> 0 | H54: =IF('Quality-Stat'!J13="","",'Quality-Stat'!J13) -> 0 | I54: =IF('Quality-Stat'!K13="","",'Quality-Stat'!K13) -> 0 | J54: =IF('Quality-Stat'!L13="","",'Quality-Stat'!L13) -> 0 | V54: General | W54: ='HSE-Stat'!B4 -> Total Hours Worked | Y54: ='HSE-Stat'!D4 -> 7560 | AA54: ='HSE-Stat'!E4 -> 7560 | AB54: ='HSE-Stat'!F4 -> 184540 | AC54: ='HSE-Stat'!G4 -> 184540 | AF54: Proactive | AG54: =+SUM(AC65:AC69) -> 99
B55: =IF('Quality-Stat'!D14="","",'Quality-Stat'!D14) -> 25 | C55: =IF('Quality-Stat'!E14="","",'Quality-Stat'!E14) -> 0 | D55: =IF('Quality-Stat'!F14="","",'Quality-Stat'!F14) -> 25 | E55: =IF('Quality-Stat'!G14="","",'Quality-Stat'!G14) -> 0 | F55: =IF('Quality-Stat'!H14="","",'Quality-Stat'!H14) -> 0 | G55: =IF('Quality-Stat'!I14="","",'Quality-Stat'!I14) -> 25 | H55: =IF('Quality-Stat'!J14="","",'Quality-Stat'!J14) -> 0 | I55: =IF('Quality-Stat'!K14="","",'Quality-Stat'!K14) -> 0 | J55: =IF('Quality-Stat'!L14="","",'Quality-Stat'!L14) -> 25 | K55: Non Conformance (NCR) | M55: ='Quality-Stat'!D5 -> 9 | N55: ='Quality-Stat'!E5 -> 9 | O55: ='Quality-Stat'!F5 -> 0 | P55: ='Quality-Stat'!G5 -> 3 | Q55: ='Quality-Stat'!H5 -> 0 | R55: ='Quality-Stat'!I5 -> 0 | S55: ='Quality-Stat'!J5 -> 0 | T55: ='Quality-Stat'!K5 -> 0 | U55: ='Quality-Stat'!L5 -> 0 | W55: ='HSE-Stat'!B5 -> Safe Hours Worked | Y55: ='HSE-Stat'!D5 -> 7560 | AA55: ='HSE-Stat'!E5 -> 7560 | AB55: ='HSE-Stat'!F5 -> 184540 | AC55: ='HSE-Stat'!G5 -> 184540 | AF55: Reactive | AG55: =SUM(AC56:AC64) -> 1
B56: =IF('Quality-Stat'!D15="","",'Quality-Stat'!D15) -> 0 | C56: =IF('Quality-Stat'!E15="","",'Quality-Stat'!E15) -> 0 | D56: =IF('Quality-Stat'!F15="","",'Quality-Stat'!F15) -> 0 | E56: =IF('Quality-Stat'!G15="","",'Quality-Stat'!G15) -> 0 | F56: =IF('Quality-Stat'!H15="","",'Quality-Stat'!H15) -> 0 | G56: =IF('Quality-Stat'!I15="","",'Quality-Stat'!I15) -> 0 | H56: =IF('Quality-Stat'!J15="","",'Quality-Stat'!J15) -> 0 | I56: =IF('Quality-Stat'!K15="","",'Quality-Stat'!K15) -> 0 | J56: =IF('Quality-Stat'!L15="","",'Quality-Stat'!L15) -> 0 | K56: Site Instruction (SIR/SOR) | M56: ='Quality-Stat'!D6 -> 24 | N56: ='Quality-Stat'!E6 -> 22 | O56: ='Quality-Stat'!F6 -> 2 | P56: ='Quality-Stat'!G6 -> 3 | Q56: ='Quality-Stat'!H6 -> 1 | R56: ='Quality-Stat'!I6 -> 0 | S56: ='Quality-Stat'!J6 -> 0 | T56: ='Quality-Stat'!K6 -> 0 | U56: ='Quality-Stat'!L6 -> 0 | V56: Reactive | W56: ='HSE-Stat'!B6 -> LTI | Y56: ='HSE-Stat'!D6 -> 0 | AA56: ='HSE-Stat'!E6 -> 0 | AB56: ='HSE-Stat'!F6 -> 0 | AC56: ='HSE-Stat'!G6 -> 0
B57: =IF('Quality-Stat'!D16="","",'Quality-Stat'!D16) -> 0 | C57: =IF('Quality-Stat'!E16="","",'Quality-Stat'!E16) -> 0 | D57: =IF('Quality-Stat'!F16="","",'Quality-Stat'!F16) -> 0 | E57: =IF('Quality-Stat'!G16="","",'Quality-Stat'!G16) -> 0 | F57: =IF('Quality-Stat'!H16="","",'Quality-Stat'!H16) -> 0 | G57: =IF('Quality-Stat'!I16="","",'Quality-Stat'!I16) -> 0 | H57: =IF('Quality-Stat'!J16="","",'Quality-Stat'!J16) -> 0 | I57: =IF('Quality-Stat'!K16="","",'Quality-Stat'!K16) -> 0 | J57: =IF('Quality-Stat'!L16="","",'Quality-Stat'!L16) -> 0 | K57: Material Inspection (MRIR) | M57: ='Quality-Stat'!D7 -> 31 | N57: ='Quality-Stat'!E7 -> 31 | O57: ='Quality-Stat'!F7 -> 0 | P57: ='Quality-Stat'!G7 -> 5 | Q57: ='Quality-Stat'!H7 -> 0 | R57: ='Quality-Stat'!I7 -> 0 | S57: ='Quality-Stat'!J7 -> 0 | T57: ='Quality-Stat'!K7 -> 0 | U57: ='Quality-Stat'!L7 -> 0 | W57: ='HSE-Stat'!B7 -> MTC (Healed w/o Disability) | Y57: ='HSE-Stat'!D7 -> 0 | AA57: ='HSE-Stat'!E7 -> 0 | AB57: ='HSE-Stat'!F7 -> 0 | AC57: ='HSE-Stat'!G7 -> 0
B58: =IF('Quality-Stat'!D17="","",'Quality-Stat'!D17) -> 11 | C58: =IF('Quality-Stat'!E17="","",'Quality-Stat'!E17) -> 0 | D58: =IF('Quality-Stat'!F17="","",'Quality-Stat'!F17) -> 11 | E58: =IF('Quality-Stat'!G17="","",'Quality-Stat'!G17) -> 0 | F58: =IF('Quality-Stat'!H17="","",'Quality-Stat'!H17) -> 0 | G58: =IF('Quality-Stat'!I17="","",'Quality-Stat'!I17) -> 11 | H58: =IF('Quality-Stat'!J17="","",'Quality-Stat'!J17) -> 0 | I58: =IF('Quality-Stat'!K17="","",'Quality-Stat'!K17) -> 0 | J58: =IF('Quality-Stat'!L17="","",'Quality-Stat'!L17) -> 11 | K58: Field Inspection (FIR) | M58: ='Quality-Stat'!D8 -> 880 | N58: ='Quality-Stat'!E8 -> 863 | O58: ='Quality-Stat'!F8 -> 17 | P58: ='Quality-Stat'!G8 -> 4 | Q58: ='Quality-Stat'!H8 -> 13 | R58: ='Quality-Stat'!I8 -> 0 | S58: ='Quality-Stat'!J8 -> 0 | T58: ='Quality-Stat'!K8 -> 0 | U58: ='Quality-Stat'!L8 -> 0 | W58: ='HSE-Stat'!B8 -> MTC (Healed w/ Disability) | Y58: ='HSE-Stat'!D8 -> 0 | AA58: ='HSE-Stat'!E8 -> 0 | AB58: ='HSE-Stat'!F8 -> 0 | AC58: ='HSE-Stat'!G8 -> 0
B59: =SUM(B54:B58) -> 36 | C59: =SUM(C54:C58) -> 0 | D59: =SUM(D54:D58) -> 36 | E59: =SUM(E54:E58) -> 0 | F59: =SUM(F54:F58) -> 0 | G59: =SUM(G54:G58) -> 36 | H59: =SUM(H54:H58) -> 0 | I59: =SUM(I54:I58) -> 0 | J59: =SUM(J54:J58) -> 36 | K59: Key Submittals Approval Status | W59: ='HSE-Stat'!B9 -> Near Miss | Y59: ='HSE-Stat'!D9 -> 1 | AA59: ='HSE-Stat'!E9 -> 1 | AB59: ='HSE-Stat'!F9 -> 1 | AC59: ='HSE-Stat'!G9 -> 1
...

Sheet FIR summary 
A1: Project Name | C1: =+'General Information'!C3:I3 -> Completion of Infrastructure Works in The Second Industrial City in Makkah Al-Mukarramah | F1: Total FIR Amount | I1: =+Total -> 438397.58 | J1: Cum Previous FIR up to 29-09-2026 | K1: Cum up To Date FRI
A2: Project ID | C2: =+'General Information'!C4:I4 -> MKH2-02-003 | E2: Project Budget | F2: 52025516 | J2: 38688025 | K2: =J2+438397.58 -> 39126422
A3: Date Period | C3: =+F3-6 -> 46295 | E3: To | F3: ='General Information'!L1 -> 46301
A5: BOQ Item # | B5: BOQ Description | C5: FIR # | D5: FIR DATE | E5: FIR Description | F5: Unit | G5: Unit Rate | H5: Current Pariod Quantity | I5: Total (SR)
A6: ROAD WORKS | K6: =+K2/52025516 -> 0.75206216
A7: B1.31 05 05.01 | B7: Removal of existing curbstone | F7: m | G7: 30 | I7: =+H7*G7 -> 0
A8: B1.31 05 05.02 | B8: Milling of the existing asphalt layer | F8: m² | G8: 10 | I8: =+H8*G8 -> 0
A9: B1.31 05 05.03 | B9: Removal of the existing asphalt layers (up to base course layer) | F9: m² | G9: 35 | I9: =+H9*G9 -> 0
A10: B1.31 05 05.08 | B10: Removal of the existing signages | F10: nr | G10: 5000 | I10: =+H10*G10 -> 0
A11: B1.31 05 05.11 | B11: Removal of the existing Street Lighting Poles | F11: nr | G11: 2500 | I11: =+H11*G11 -> 0
A12: B1.31 22 00.01 | B12: Roadway Excavation for cuttings (all types of soil) | C12: MKH2-02-003-ENJ-TS9-1-CVL-FIR-0860-00 | D12: 30/09/2026 | E12: Field Inspection Request for CUTTING ARAE REPLACMENT AT ALGLOOD ROAD ( LOCAL 62 )STA 0+420 - 0+620 ( BSG 0.00 ) | F12: m3 | G12: 20 | H12: 3376.24 | I12: =+H12*G12 -> 67524.8
C13: MKH2-02-003-ENJ-TS9-1-CVL-FIR-0861-00 | D13: 28/09/2026 | E13: Field Inspection Request Survey & sampling at ALGLOOD ROAD ( LOCAL 62 )STA 0+420 - 0+620 BSG-30 CUT AREA | F13: m3 | G13: 20 | H13: 636 | I13: =+H13*G13 -> 12720
C14: MKH2-02-003-ENJ-TS9-1-CVL-FIR-0862-00 | D14: 28/09/2026 | E14: Field Inspection Request for RDT at ALGLOOD ROAD (LOCAL 62) IN STA 0+420 - 0+620 BSG-60 | F14: m3 | G14: 20 | H14: 636 | I14: =+H14*G14 -> 12720
F15: m3 | G15: 20 | I15: =+H15*G15 -> 0
A16: B1.31 22 00.02 | B16: Embankments to the ROW with common / suitable excavated material or with suitable imported material | C16: MKH2-02-003-ENJ-TS9-1-CVL-FIR-0846-00 | D16: 26/09/2026 | E16: Field Inspection Request for FDT REPLACMENT AT ALGLOUD ROAD - LOCAL 62 STA 0+620 - 0+830 (BSG -00) | F16: m3 | G16: 18 | H16: 667.8 | I16: =+H16*G16 -> 12020.4
C17: MKH2-02-003-ENJ-TS9-1-CVL-FIR-0852-00 | D17: 26/09/2026 | E17: Field Inspection Request for BACKFILLNG TOE at NUN-MUSLIM ROAD Station. 0+182 TO 0+350 | F17: m3 | G17: 18 | H17: 1561.31 | I17: =+H17*G17 -> 28103.58
A18: B1.31 22 00.03 | B18: Subgrade | C18: MKH2-02-003-ENJ-TS9-1-CVL-FIR-0863-00 | D18: 28/09/2026 | E18: Field Inspection Request for Subgrade 1(15 CM) at LOCAL 62 GLOUD ROAD FROM STA 0+620- 0+830 | F18: m3 | G18: 22 | H18: 200 | I18: =+H18*G18 -> 4400
C19: MKH2-02-003-ENJ-TS9-1-CVL-FIR-0864-00 | D19: 28/09/2026 | E19: Field Inspection Request for Subgrade 2(15 CM) at LOCAL 62 GLOUD ROAD FROM STA 0+620- 0+830 | F19: m3 | G19: 22 | H19: 200 | I19: =+H19*G19 -> 4400
C20: MKH2-02-003-ENJ-TS9-1-CVL-FIR-0866-00 | D20: 30/09/2026 | E20: Field Inspection Request for Subgrade 1(15 CM) at RAMP OUT FROM STA 0+180 TO 0+360 | F20: m3 | G20: 22 | H20: 280 | I20: =+H20*G20 -> 6160
C21: MKH2-02-003-ENJ-TS9-1-CVL-FIR-0867-00 | D21: 27/09/2026 | E21: Field Inspection Request for Subgrade 2(15 CM) at RAMP OUT FROM STA 0+180 TO 0+360 | F21: m3 | G21: 22 | H21: 280 | I21: =+H21*G21 -> 6160
F22: m3 | G22: 22 | I22: =+H22*G22 -> 0
A23: B1.32 11 23.01 | B23: Aggregate base course | F23: m3 | G23: 50 | I23: =+H23*G23 -> 0
F24: m3 | G24: 50 | I24: =+H24*G24 -> 0
A25: B1.32 11 26.01 | B25: Bituminous base course (Grading I - Class A), including Prime Coat (MC1) and tack coat (RC2) (if any) | C25: MKH2-02-003-ENJ-TS9-1-CVL-FIR-0853-00 | D25: 46032 | E25: Pavement of BBC at Sta 0+780 to 0+924 (Asphalt and Compaction) at COLL 09 | F25: m3 | G25: 560 | H25: 125.68 | I25: =+H25*G25 -> 70380.8
C26: MKH2-02-003-ENJ-TS9-1-CVL-FIR-0854-00 | D26: 46032 | E26: Pavement of BBC at Sta 0+000 to 0+200 (Asphalt and Compaction) at Road 52 | F26: m3 | G26: 560 | H26: 132.6 | I26: =+H26*G26 -> 74256
C27: MKH2-02-003-ENJ-TS9-1-CVL-FIR-0855-00 | D27: 46032 | E27: Pavement of BBC at Sta 0+520 to 0+960 (Asphalt and Compaction) at GLOUD Road | F27: m3 | G27: 560 | H27: 249.2 | I27: =+H27*G27 -> 139552
C28: MKH2-02-003-ENJ-TS9-1-CVL-FIR-0859-00 | D28: 46032 | E28: Pavement of BBC at Sta 0+00 to 0+520 (Asphalt and Compaction) at GLOUD Road | F28: m3 | G28: 560 | I28: =+H28*G28 -> 0
F29: m3 | G29: 560 | I29: =+H29*G29 -> 0
A30: B1.32 12 16.01 | B30: Bituminous concrete wearing course, (Grading I - Class A), including tack coat (RC2) | F30: m3 | G30: 580 | I30: =+H30*G30 -> 0
A31: B1.32 14 13.01 | B31: Precast Concrete Kerb, Type K1-A | F31: m | G31: 60 | I31: =+H31*G31 -> 0
F32: m | G32: 60 | I32: =+H32*G32 -> 0
A33: B1.32 14 13.02 | B33: Precast Concrete Kerb, Type K4 | F33: m | G33: 60 | I33: =+H33*G33 -> 0
A34: B1.32 14 13.03 | B34: Precast Concrete Kerb, Type K1-B | F34: m | G34: 55 | I34: =+H34*G34 -> 0
F35: m | G35: 55 | I35: =+H35*G35 -> 0
A36: B1.32 14 13.13.01 | B36: 60mm thick - Interlocking block pavers for sidewalk/footpath | F36: m2 | G36: 70 | I36: =+H36*G36 -> 0
F37: m2 | G37: 70 | I37: =+H37*G37 -> 0
A38: B1.32 17 23.01 | B38: Retroreflective Thermoplastic White paiting and traffic lines | F38: m² | G38: 36 | I38: =+H38*G38 -> 0
A39: B1.32 17 23.02 | B39: Retroreflective Thermoplastic Yellow paiting and traffic lines | F39: m² | G39: 36 | I39: =+H39*G39 -> 0
A40: B1.10 14 53.01 | B40: Traffic signs, ground mounted, Sheet Alumenium, (breakaway)Single post, with all accessories | F40: Unit | G40: 1700 | I40: =+H40*G40 -> 0
A41: B1.10 14 53.02 | B41: Set of traffic signals at intersection , the set include 4 signals,TSCP, controller, support and automatic traffic violation detection system (Saher) with all components and all necessary civil and electrical works to complete the works as per drawings and specifications. . | F41: Unit | G41: 750000 | I41: =+H41*G41 -> 0
...

Sheet General Information
A1: Weekly Progress Report - Construction Projects | K1: Data Date | L1: 46301 | N1: Report No. | O1: =ROUNDUP(((L1-C14)/7),0) -> 34
A2: Contract General Information
A3: Project Name | C3: Completion of Infrastructure Works in The Second Industrial City in Makkah Al-Mukarramah
A4: Project ID | C4: MKH2-02-003
A5: Contractor | C5: Al Enjaz Trading & Contracting Co.
A6: Consultant | C6: Saudi Arabia Consulting Engineering Company "EGIS"
A7: Stage | C7: Construction
A8: Status | C8: Active
A9: Modon PM | C9: Engr. Abdallah Aljulaifi
A11: Key Dates
A12: Contract Award Date | C12: 46054
A13: Contract Sign Date | C13: 46061
A14: Site Handover Date | C14: 46068
A15: Original Completion | C15: 46613
A16: Contract Award Date (Hijri) | C16: 01/02/1447
A17: Contract Sign Date (Hijri) | C17: 08/02/1447
A18: Site Handover Date (Hijri) | C18: 15/02/1447
A19: Original Completion (Hijri) | C19: 14/08/1447
A20: Revised Completion Date | C20: 46613
A21: Committed Completion Date | C21: 46613
A22: Forecast Completion | C22: 46656
A23: Variance | C23: =C20-C22 -> -43
A25: Key Project Submittals | C25: Submission Date | D25: Days taken to approve orginal plan from site handover date
A26: Quality Plan submission | C26: 46076 | D26: =C26-C14 -> 8
A27: Quality Plan approval | C27: 46110
A28: Quality Plan Last Update | C28: 46110
A30: Safety Plan submission | C30: 46085 | D30: =C30-C14 -> 17
A31: Safety Plan approval | C31: 46090
A32: Safety Plan Last Update | C32: 46090
A34: Risk Management Plan submission | C34: 46076 | D34: =C34-C14 -> 8
A35: Risk Management Plan approval | C35: 46078
A36: Risk Management Plan Last Update | C36: 46078
A38: Baseline Schedule submission | C38: 46070 | D38: =C38-C14 -> 2
A39: Baseline Schedule approval | C39: 45717
A40: No of Schedule Versions | C40: 1
A41: Last Recovery Schedule Approval Date | C41: 45717
A43: BOQ submission | C43: 46231 | D43: =C43-C14 -> 163
A44: BOQ approval
A45: No of Approved Version of BOQ
A47: Project Execution Plan submission | C47: 46072 | D47: =C47-C14 -> 4
...

Sheet Progress
A1: Completion of Infrastruture in The Second Industrial City in Makkah (The project includes construction of Roads works ; Box Culvert ; Open Drain Channels and Dike Walls ; Street Lightings and Low Voltage Cables ,concrete ducts at road crossing) | R1: ='General Information'!$K$1 -> Data Date | S1: ='General Information'!L1 -> 46301
A4: Earned Value Progress (SAR) | J4: Physical Progress (Effort)
B5: BOQ Value (SAR) | C5: % Wt. | D5: Weekly (SAR) | G5: To Date (SAR) | J5: Budgeted | K5: % Wt. | L5: Weekly Physical Progress | N5: To Date Physical Progress
D6: Planned | E6: Earned | F6: Original Plan | G6: Planned | H6: Earned | J6: (Manhours) | L6: Planned | M6: Earned | N6: Planned | O6: Earned
A7: Mobilization | B7: =SUBTOTAL(9,B8:B8) -> 0 | C7: =IF(ISBLANK(B7),"",B7/$B$27) -> 0 | D7: =SUBTOTAL(9,D8:D8) -> 0 | E7: - | F7: =SUBTOTAL(9,F8:F8) -> 0 | G7: =SUBTOTAL(9,G8:G8) -> 0 | H7: - | J7: =SUBTOTAL(9,J8:J8) -> 14738 | K7: =IF(ISBLANK(J7),"",J7/$J$27) -> 0.029894584 | L7: =SUBTOTAL(9,L8:L8) -> 0 | M7: =SUBTOTAL(9,M8:M8) -> 0 | N7: =SUBTOTAL(9,N8:N8) -> 14738 | O7: =SUBTOTAL(9,O8:O8) -> 14738
B8: 0 | C8: =IF(ISBLANK(B8),"",B8/$B$27) -> 0 | D8: =+'Progress (2)'!I4 -> 0 | E8: =+'Progress (2)'!J4 -> 479130.66 | F8: =+'Progress (2)'!K4 -> 0 | G8: =+'Progress (2)'!L4 -> 0 | H8: =+'Progress (2)'!M4 -> 39183289 | J8: 14738 | K8: =IF(ISBLANK(J8),"",J8/$J$27) -> 0.029894584 | L8: =+'Progress (2)'!O4 -> 0 | M8: =+'Progress (2)'!P4 -> 0 | N8: =+'Progress (2)'!Q4 -> 14738 | O8: =+'Progress (2)'!R4 -> 14738 | R8: 384361
A9: Engineering | B9: =SUBTOTAL(9,B10:B10) -> 1560765.5 | C9: =IF(ISBLANK(B9),"",B9/$B$27) -> 0.03 | D9: =SUBTOTAL(9,D10:D10) -> 0 | E9: =SUBTOTAL(9,E10:E10) -> 0 | F9: =SUBTOTAL(9,F10:F10) -> 1560765.5 | G9: =SUBTOTAL(9,G10:G10) -> 1560765.5 | H9: =SUBTOTAL(9,H10:H10) -> 1560765.5 | J9: =SUBTOTAL(9,J10:J10) -> 24562 | K9: =IF(ISBLANK(J9),"",J9/$J$27) -> 0.049821602 | L9: =SUBTOTAL(9,L10:L10) -> 0 | M9: =SUBTOTAL(9,M10:M10) -> 0 | N9: =SUBTOTAL(9,N10:N10) -> 24562 | O9: =SUBTOTAL(9,O10:O10) -> 24562 | R9: 0
B10: 1560765.5 | C10: =IF(ISBLANK(B10),"",B10/$B$27) -> 0.03 | D10: =+'Progress (2)'!I5 -> 0 | E10: =+'Progress (2)'!J5 -> 0 | F10: =+'Progress (2)'!K5 -> 1560765.5 | G10: =+'Progress (2)'!L5 -> 1560765.5 | H10: =+'Progress (2)'!M5 -> 1560765.5 | J10: 24562 | K10: =IF(ISBLANK(J10),"",J10/$J$27) -> 0.049821602 | L10: =+'Progress (2)'!O5 -> 0 | M10: =+'Progress (2)'!P5 -> 0 | N10: =+'Progress (2)'!Q5 -> 24562 | O10: =+'Progress (2)'!R5 -> 24562 | R10: 14738
A11: Procurement | B11: =SUBTOTAL(9,B12:B12) -> 10405103 | C11: =IF(ISBLANK(B11),"",B11/$B$27) -> 0.2 | D11: =SUBTOTAL(9,D12:D12) -> 0 | E11: =SUBTOTAL(9,E12:E12) -> 0 | F11: =SUBTOTAL(9,F12:F12) -> 10405103 | G11: =SUBTOTAL(9,G12:G12) -> 10405103 | H11: =SUBTOTAL(9,H12:H12) -> 10035314 | J11: =SUBTOTAL(9,J12:J12) -> 58936 | K11: =IF(ISBLANK(J11),"",J11/$J$27) -> 0.11954588 | L11: =SUBTOTAL(9,L12:L12) -> 0 | M11: =SUBTOTAL(9,M12:M12) -> 0 | N11: =SUBTOTAL(9,N12:N12) -> 58936 | O11: =SUBTOTAL(9,O12:O12) -> 53158 | R11: 24562
B12: 10405103 | C12: =IF(ISBLANK(B12),"",B12/$B$27) -> 0.2 | D12: =+'Progress (2)'!I6 -> 0 | E12: =+'Progress (2)'!J6 -> 0 | F12: =+'Progress (2)'!K6 -> 10405103 | G12: =+'Progress (2)'!L6 -> 10405103 | H12: =+'Progress (2)'!M6 -> 10035314 | J12: 58936 | K12: =IF(ISBLANK(J12),"",J12/$J$27) -> 0.11954588 | L12: =+'Progress (2)'!O6 -> 0 | M12: =+'Progress (2)'!P6 -> 0 | N12: =+'Progress (2)'!Q6 -> 58936 | O12: =+'Progress (2)'!R6 -> 53158 | R12: 53158
A13: Road Works | B13: =SUBTOTAL(9,B14:B14) -> 18062898 | C13: =IF(ISBLANK(B13),"",B13/$B$27) -> 0.34719305 | D13: =SUBTOTAL(9,D14:D14) -> 572058.61 | E13: =SUBTOTAL(9,E14:E14) -> 369719.67 | F13: =SUBTOTAL(9,F14:F14) -> 9650325.4 | G13: =SUBTOTAL(9,G14:G14) -> 9650325.4 | H13: =SUBTOTAL(9,H14:H14) -> 12299083 | J13: =SUBTOTAL(9,J14:J14) -> 118380 | K13: =IF(ISBLANK(J13),"",J13/$J$27) -> 0.24012219 | L13: =SUBTOTAL(9,L14:L14) -> 3400 | M13: =SUBTOTAL(9,M14:M14) -> 1471 | N13: =SUBTOTAL(9,N14:N14) -> 52420 | O13: =SUBTOTAL(9,O14:O14) -> 64158 | R13: 291903
B14: 18062898 | C14: =IF(ISBLANK(B14),"",B14/$B$27) -> 0.34719305 | D14: =+'Progress (2)'!I7 -> 572058.61 | E14: =+'Progress (2)'!J7 -> 369719.67 | F14: =+'Progress (2)'!K7 -> 9650325.4 | G14: =+'Progress (2)'!L7 -> 9650325.4 | H14: =+'Progress (2)'!M7 -> 12299083 | J14: 118380 | K14: =IF(ISBLANK(J14),"",J14/$J$27) -> 0.24012219 | L14: =+'Progress (2)'!O7 -> 3400 | M14: =+'Progress (2)'!P7 -> 1471 | N14: =+'Progress (2)'!Q7 -> 52420 | O14: =+'Progress (2)'!R7 -> 64158 | R14: 109336
A15: Electricity Works | B15: =SUBTOTAL(9,B16:B16) -> 2353781.9 | C15: =IF(ISBLANK(B15),"",B15/$B$27) -> 0.045242836 | D15: =SUBTOTAL(9,D16:D16) -> 51053.04 | E15: =SUBTOTAL(9,E16:E16) -> 99763 | F15: =SUBTOTAL(9,F16:F16) -> 240201.22 | G15: =SUBTOTAL(9,G16:G16) -> 240201.22 | H15: =SUBTOTAL(9,H16:H16) -> 1841818.2 | J15: =SUBTOTAL(9,J16:J16) -> 41030 | K15: =IF(ISBLANK(J15),"",J15/$J$27) -> 0.083225321 | L15: =SUBTOTAL(9,L16:L16) -> 1320 | M15: =SUBTOTAL(9,M16:M16) -> 1432 | N15: =SUBTOTAL(9,N16:N16) -> 7780 | O15: =SUBTOTAL(9,O16:O16) -> 27784 | R15: 56082
B16: 2353781.9 | C16: =IF(ISBLANK(B16),"",B16/$B$27) -> 0.045242836 | D16: =+'Progress (2)'!I8 -> 51053.04 | E16: =+'Progress (2)'!J8 -> 99763 | F16: =+'Progress (2)'!K8 -> 240201.22 | G16: =+'Progress (2)'!L8 -> 240201.22 | H16: =+'Progress (2)'!M8 -> 1841818.2 | J16: 41030 | K16: =IF(ISBLANK(J16),"",J16/$J$27) -> 0.083225321 | L16: =+'Progress (2)'!O8 -> 1320 | M16: =+'Progress (2)'!P8 -> 1432 | N16: =+'Progress (2)'!Q8 -> 7780 | O16: =+'Progress (2)'!R8 -> 27784 | R16: 13850
A17: Demolision | B17: =SUBTOTAL(9,B18:B18) -> 189275 | C17: =IF(ISBLANK(B17),"",B17/$B$27) -> 0.0036381186 | D17: =SUBTOTAL(9,D18:D18) -> 0 | E17: =SUBTOTAL(9,E18:E18) -> 0 | F17: =SUBTOTAL(9,F18:F18) -> 189275 | G17: =SUBTOTAL(9,G18:G18) -> 189275 | H17: =SUBTOTAL(9,H18:H18) -> 155775 | J17: =SUBTOTAL(9,J18:J18) -> 6490 | K17: =IF(ISBLANK(J17),"",J17/$J$27) -> 0.013164327 | L17: =SUBTOTAL(9,L18:L18) -> 0 | M17: =SUBTOTAL(9,M18:M18) -> 0 | N17: =SUBTOTAL(9,N18:N18) -> 6490 | O17: =SUBTOTAL(9,O18:O18) -> 4390 | R17: 42232
B18: 189275 | C18: =IF(ISBLANK(B18),"",B18/$B$27) -> 0.0036381186 | D18: =+'Progress (2)'!I9 -> 0 | E18: =+'Progress (2)'!J9 -> 0 | F18: =+'Progress (2)'!K9 -> 189275 | G18: =+'Progress (2)'!L9 -> 189275 | H18: =+'Progress (2)'!M9 -> 155775 | J18: 6490 | K18: =IF(ISBLANK(J18),"",J18/$J$27) -> 0.013164327 | L18: =+'Progress (2)'!O9 -> 0 | M18: =+'Progress (2)'!P9 -> 0 | N18: =+'Progress (2)'!Q9 -> 6490 | O18: =+'Progress (2)'!R9 -> 4390 | R18: 27120
A19: Box Culvert | B19: =SUBTOTAL(9,B20:B20) -> 3959941.2 | C19: =IF(ISBLANK(B19),"",B19/$B$27) -> 0.076115366 | D19: =SUBTOTAL(9,D20:D20) -> 0 | E19: =SUBTOTAL(9,E20:E20) -> 0 | F19: =SUBTOTAL(9,F20:F20) -> 3959941.2 | G19: =SUBTOTAL(9,G20:G20) -> 3959941.2 | H19: =SUBTOTAL(9,H20:H20) -> 3959941.2 | J19: =SUBTOTAL(9,J20:J20) -> 17395 | K19: =IF(ISBLANK(J19),"",J19/$J$27) -> 0.035284047 | L19: =SUBTOTAL(9,L20:L20) -> 0 | M19: =SUBTOTAL(9,M20:M20) -> 0 | N19: =SUBTOTAL(9,N20:N20) -> 17395 | O19: =SUBTOTAL(9,O20:O20) -> 17395 | R19: 15112
B20: 3959941.2 | C20: =IF(ISBLANK(B20),"",B20/$B$27) -> 0.076115366 | D20: =+'Progress (2)'!I10 -> 0 | E20: =+'Progress (2)'!J10 -> 0 | F20: =+'Progress (2)'!K10 -> 3959941.2 | G20: =+'Progress (2)'!L10 -> 3959941.2 | H20: =+'Progress (2)'!M10 -> 3959941.2 | J20: 17395 | K20: =IF(ISBLANK(J20),"",J20/$J$27) -> 0.035284047 | L20: =+'Progress (2)'!O10 -> 0 | M20: =+'Progress (2)'!P10 -> 0 | N20: =+'Progress (2)'!Q10 -> 17395 | O20: =+'Progress (2)'!R10 -> 17395 | R20: 30758
