Workbook
Name _1B.05.M.010.0010: #REF!
Name _1B.05.M.010.0010: #REF!
Name _1B.05.M.010.0010: #REF!
Name _1B.05.M.010.0050: #REF!
Name _1B.05.M.010.0050: #REF!
Name _1B.05.M.0100.0010: #REF!
Name _1B.05.M.0100.0010: #REF!
Name _1B.05.M.020.0010: #REF!
Name _1B.05.M.020.0010: #REF!
Name _1B.05.M.020.0020: #REF!
Name _1B.05.M.020.0020: #REF!
Name _1B.05.M.020.0030: #REF!
Name _1B.05.M.020.0030: #REF!
Name _1B.05.M.020.0040: #REF!
Name _1B.05.M.020.0040: #REF!
Name _1B.05.M.030.0010: #REF!
Name _1B.05.M.030.0010: #REF!
Name _1B.05.M.030.0020: #REF!
Name _1B.05.M.030.0020: #REF!
Name _1B.05.M.040.0010: #REF!
Name _1B.05.M.040.0010: #REF!
Name _1B.05.M.050.0010: #REF!
Name _1B.05.M.050.0010: #REF!
Name _1B.05.M.050.0020: #REF!
Name _1B.05.M.050.0020: #REF!
Name _1B.05.M.050.0030: #REF!
Name _1B.05.M.050.0030: #REF!
Name _1B.05.M.060.0020: #REF!
Name _1B.05.M.060.0020: #REF!
Name _1B.05.M.060.0100: #REF!
Name _1B.05.M.060.0100: #REF!
Name _1B.05.M.070.0010: #REF!
Name _1B.05.M.070.0010: #REF!
Name _1B.05.M.070.0020: #REF!
Name _1B.05.M.070.0020: #REF!
Name _1B.05.M.070.0030: #REF!
Name _1B.05.M.070.0030: #REF!
Name _1B.05.M.070.0040: #REF!
Name _1B.05.M.070.0040: #REF!
Name _1B.05.M.070.0050: #REF!
Name _1B.05.M.070.0050: #REF!
Name _1B.05.M.080.0010: #REF!
Name _1B.05.M.080.0010: #REF!
Name _1B.05.M.090.0010: #REF!
Name _1B.05.M.090.0010: #REF!
Name _1B.09.P.010.0010: #REF!
Name _1B.09.P.010.0010: #REF!
Name _1B.09.P.010.0020: #REF!
Name _1B.09.P.010.0020: #REF!
Name _1B.09.P.010.0030: #REF!
Name _1B.09.P.010.0030: #REF!
Name _1B.09.P.010.0040: #REF!
Name _1B.09.P.010.0040: #REF!
Name _1B.09.P.010.0050: #REF!
Name _1B.09.P.010.0050: #REF!
Name _1B.09.P.010.0060: #REF!
Name _1B.09.P.010.0060: #REF!
Name _1B.09.P.010.0070: #REF!
Name _1B.09.P.010.0070: #REF!
Name _1B.09.P.020.0010: #REF!

Sheet Weekly Progress Report
A1: MODON - Weekly Progress Report - Construction Projects | AF1: Data Date | AH1: ='General Information'!L1 -> 46293
A2: Contract General Information | G2: Key Dates | M2: Cost Summary (SR) | U2: Performance Summary | AA2: Project Scope
A3: Project Name | B3: ='General Information'!C3 -> Infrastructure Network Development Project in Sudair City for Industry and Business - Phase Two - Part Two | G3: Contract Award | H3: ='General Information'!C12 -> 45998 | I3: Contract Award (Hijri) | J3: ='General Information'!C16 -> 16/6/1447 | K3: Revised Completion | L3: ='General Information'!C20 -> 0 | M3: Original Contract Value | O3: ='Invoice Log'!F3 -> 168629520 | Q3: O&M Value | S3: ='Invoice Log'!J3 -> 0 | T3: EAC | U3: Plan Value | V3: =Progress!H47 -> 0.32072541 | W3: Phys. Plan Value | X3: =W43 -> 0.3565935 | Y3: Quality Score | Z3: =Quality.!AC10 -> 0.81344828 | AA3: =Progress!B1 -> The scope of work of the project includes the implementation of the entire works subject to the contract, including the following: Road and paving works, Potable Water Network Works, Treatment Water Network Works, Sewer network works, Rainwater drainage network works, Irrigation and landscaping network works, Electrical network works including (medium voltage, communications, road lighting), Camera surveillance work
A4: Project ID | B4: ='General Information'!C4 -> SUD1-02-011 | D4: Stage | E4: ='General Information'!C7 -> Construction | G4: Contract Sign | H4: ='General Information'!C13 -> 46020 | I4: Contract Sign (Hijri) | J4: ='General Information'!C17 -> 9/7/1447 | K4: Committed Completion | L4: ='General Information'!C21 -> 46573 | M4: Revised Contract Value | O4: ='Invoice Log'!F4 -> 0 | P4: EAC | Q4: Revised O&M Value | S4: ='Invoice Log'!J4 -> 0 | T4: =+#REF!+#REF!+S4 -> #REF! | U4: Earn Value | V4: =L43 -> 0.43378716 | W4: Phys. Earn Value | X4: =X43 -> 0.39232947 | Z4: =REPT("¢",IF(INT(+Z3*10)>5,5,INT(+Z3*10)))&REPT("£",IF(INT(+Z3*10)>5,0,5-INT(+Z3*10)))&CHAR(10)&REPT("¢",+IF(INT(+Z3*10)>5,-5+INT(+Z3*10),0))&REPT("£",IF(INT(+Z3*10)>5,10-INT(+Z3*10),5)) -> ¢¢¢¢¢ ¢¢¢££
A5: Contractor | B5: ='General Information'!C5 -> Technical Dvelopment Co. "TDC" | D5: Status | E5: ='General Information'!C8 -> Active | G5: Site Handover | H5: ='General Information'!C14 -> 46028 | I5: Site Handover (Hijri) | J5: ='General Information'!C18 -> 17/7/1447 | K5: Forecast Completion | L5: ='General Information'!C22 -> 46573 | M5: Estimate At Completion Value | O5: ='Invoice Log'!F5 -> 168629520 | P5: =+#REF!+#REF!+O5 -> #REF! | Q5: Submitted Invoices (Gross Value) | S5: ='Invoice Log'!J5 -> 16773813 | U5: Variance | V5: =V4-V3 -> 0.11306175 | W5: Variance | X5: =X4-X3 -> 0.035735979 | Y5: Safety Score | Z5: ='HSE. '!AE6 -> 0.81818182
A6: Consultant | B6: ='General Information'!C6 -> Saudi Arabia Consulting Engineering Company "EGIS" | D6: Modon PM | E6: ='General Information'!C9 -> Engr.Zyad Al Shabat | G6: Original Completion | H6: ='General Information'!C15 -> 46573 | I6: Original Completion (Hijri) | J6: ='General Information'!C19 -> 30/1/1449 | K6: Variance | L6: ='General Information'!C23 -> 0 | M6: Potential Changes | O6: ='Invoice Log'!F6 -> 0 | Q6: Total Deduction | S6: ='Invoice Log'!J6 -> -720596.12 | U6: SPI | V6: =V4/V3 -> 1.3525189 | W6: SPI | X6: =X4/X3 -> 1.1002149 | Z6: =REPT("¢",IF(INT(+Z5*10)>5,5,INT(+Z5*10)))&REPT("£",IF(INT(+Z5*10)>5,0,5-INT(+Z5*10)))&CHAR(10)&REPT("¢",+IF(INT(+Z5*10)>5,-5+INT(+Z5*10),0))&REPT("£",IF(INT(+Z5*10)>5,10-INT(+Z5*10),5)) -> ¢¢¢¢¢ ¢¢¢££
A8: Progress Overview
A9: Earned Value Progress (SAR) | O9: =Progress!K4 -> Physical Progress (Effort) | AA9: Earned Value Progress (%)
A10: WBS | C10: BOQ Value (SAR) | D10: % Wt. | E10: Weekly (SAR) | G10: To Date (SAR) | O10: =Progress!K5 -> Budgeted | P10: =Progress!L5 -> % Wt. | Q10: Weekly Physical Progress | U10: To Date Physical Progress
E11: Planned | F11: Earned | G11: Original Plan | H11: =Progress!H6 -> Planned | I11: =Progress!I6 -> Earned | J11: Original Plan % | K11: Cum. Planned % | L11: Cum.Earned % | M11: Variance | N11: SPI | O11: (Manhours) | Q11: Planned | R11: Earned | S11: Plan % | T11: Earned % | U11: Planned | V11: Earned | W11: Plan % | X11: Earned % | Y11: Variance | Z11: SPI
C12: =Progress!C7 -> 0 | D12: =Progress!D7 -> 0 | E12: =Progress!E39 -> 0 | F12: =Progress!F39 -> 0 | G12: =Progress!G39 -> 0 | I12: =I55 -> 0 | J12: =IFERROR(IF(ISBLANK(G12),"",G12/C12),0) -> 0 | K12: =IFERROR(IF(ISBLANK(H12),"",H12/C12),0) | L12: =IFERROR(IF(ISBLANK(I12),"",I12/C12),0) -> 0 | M12: =IFERROR(L12-K12,"") | N12: =IFERROR(L12/K12,"") | P12: =Progress!L7 -> 0 | Q12: =Progress!M7 -> 0 | R12: =Progress!N7 -> 0 | S12: =IFERROR(IF(ISBLANK(Q12),"",Q12/O12),0) -> 0 | T12: =IFERROR(IF(ISBLANK(R12),"",R12/O12),0) -> 0 | U12: =Progress!O7 -> 0 | V12: =Progress!P7 -> 0 | W12: =IFERROR(IF(ISBLANK(U12),"",U12/O12),0) -> 0 | X12: =IFERROR(IF(ISBLANK(V12),"",V12/O12),0) -> 0 | Y12: =IFERROR(X12-W12,"") -> 0 | Z12: =IFERROR(X12/W12,"")
A13: =Progress!A8 -> Mobilization | C13: =Progress!C8 -> 0 | D13: =Progress!D8 -> 0 | E13: =Progress!E40 -> 0 | F13: =Progress!F8 -> 0 | G13: =Progress!G8 -> 0 | H13: =Progress!H8 -> 0 | I13: =Progress!I8 -> 0 | J13: =IFERROR(IF(ISBLANK(G13),"",G13/C13),0) -> 0 | K13: =IFERROR(IF(ISBLANK(H13),"",H13/C13),0) -> 0 | L13: =IFERROR(IF(ISBLANK(I13),"",I13/C13),0) -> 0 | M13: =IFERROR(L13-K13,"") -> 0 | N13: =IFERROR(L13/K13,"") | O13: =Progress!K8 -> 34177 | P13: =Progress!L8 -> 0.029999719 | Q13: =Progress!M8 -> 0 | R13: =Progress!N8 -> 0 | S13: =IFERROR(IF(ISBLANK(Q13),"",Q13/O13),0) -> 0 | T13: =IFERROR(IF(ISBLANK(R13),"",R13/O13),0) -> 0 | U13: =Progress!O8 -> 34177 | V13: =Progress!P8 -> 34177 | W13: =IFERROR(IF(ISBLANK(U13),"",U13/O13),0) -> 1 | X13: =IFERROR(IF(ISBLANK(V13),"",V13/O13),0) -> 1 | Y13: =IFERROR(X13-W13,"") -> 0 | Z13: =IFERROR(X13/W13,"") -> 1
A14: =Progress!A9 -> Engineering | C14: =Progress!C9 -> 0 | D14: =Progress!D9 -> 0 | E14: =Progress!E9 -> 0 | F14: =Progress!F9 -> 0 | G14: =Progress!G9 -> 0 | H14: =Progress!H9 -> 0 | I14: =Progress!I9 -> 0 | J14: =IFERROR(IF(ISBLANK(G14),"",G14/C14),0) -> 0 | K14: =IFERROR(IF(ISBLANK(H14),"",H14/C14),0) -> 0 | L14: =IFERROR(IF(ISBLANK(I14),"",I14/C14),0) -> 0 | M14: =IFERROR(L14-K14,"") -> 0 | N14: =IFERROR(L14/K14,"") | O14: =Progress!K9 -> 56962 | P14: =Progress!L9 -> 0.049999824 | Q14: =Progress!M9 -> 0 | R14: =Progress!N9 -> 0 | S14: =IFERROR(IF(ISBLANK(Q14),"",Q14/O14),0) -> 0 | T14: =IFERROR(IF(ISBLANK(R14),"",R14/O14),0) -> 0 | U14: =Progress!O9 -> 56962 | V14: =Progress!P9 -> 53211 | W14: =IFERROR(IF(ISBLANK(U14),"",U14/O14),0) -> 1 | X14: =IFERROR(IF(ISBLANK(V14),"",V14/O14),0) -> 0.93414908 | Y14: =IFERROR(X14-W14,"") -> -0.065850918 | Z14: =IFERROR(X14/W14,"") -> 0.93414908
A15: =Progress!A10 -> Procurement | C15: =Progress!C10 -> 0 | D15: =Progress!D10 -> 0 | E15: =Progress!E10 -> 0 | F15: =Progress!F10 -> 0 | G15: =Progress!G10 -> 0 | H15: =Progress!H10 -> 0 | I15: =Progress!I10 -> 0 | J15: =IFERROR(IF(ISBLANK(G15),"",G15/C15),0) -> 0 | K15: =IFERROR(IF(ISBLANK(H15),"",H15/C15),0) -> 0 | L15: =IFERROR(IF(ISBLANK(I15),"",I15/C15),0) -> 0 | M15: =IFERROR(L15-K15,"") -> 0 | N15: =IFERROR(L15/K15,"") | O15: =Progress!K10 -> 148102 | P15: =Progress!L10 -> 0.13000025 | Q15: =Progress!M10 -> 1511 | R15: =Progress!N10 -> 0 | S15: =IFERROR(IF(ISBLANK(Q15),"",Q15/O15),0) -> 0.010202428 | T15: =IFERROR(IF(ISBLANK(R15),"",R15/O15),0) -> 0 | U15: =Progress!O10 -> 143233 | V15: =Progress!P10 -> 48418 | W15: =IFERROR(IF(ISBLANK(U15),"",U15/O15),0) -> 0.96712401 | X15: =IFERROR(IF(ISBLANK(V15),"",V15/O15),0) -> 0.32692334 | Y15: =IFERROR(X15-W15,"") -> -0.64020067 | Z15: =IFERROR(X15/W15,"") -> 0.33803663
A16: =Progress!A11 -> Construction | C16: =Progress!C11 -> 1.6862952e+08 | D16: =Progress!D11 -> 1 | E16: =Progress!E11 -> 3995420.2 | F16: =Progress!F11 -> 1709872.9 | G16: =Progress!G11 -> 0 | H16: =Progress!H11 -> 54083772 | I16: =Progress!I11 -> 73149321 | J16: =IFERROR(IF(ISBLANK(G16),"",G16/C16),0) -> 0 | K16: =IFERROR(IF(ISBLANK(H16),"",H16/C16),0) -> 0.32072541 | L16: =IFERROR(IF(ISBLANK(I16),"",I16/C16),0) -> 0.43378716 | M16: =IFERROR(L16-K16,"") -> 0.11306175 | N16: =IFERROR(L16/K16,"") -> 1.3525189 | O16: =Progress!K11 -> 854433 | P16: =Progress!L11 -> 0.75 | Q16: =Progress!M11 -> 13886 | R16: =Progress!N11 -> 3659 | S16: =IFERROR(IF(ISBLANK(Q16),"",Q16/O16),0) -> 0.016251713 | T16: =IFERROR(IF(ISBLANK(R16),"",R16/O16),0) -> 0.0042823721 | U16: =Progress!O11 -> 171875 | V16: =Progress!P11 -> 311153 | W16: =IFERROR(IF(ISBLANK(U16),"",U16/O16),0) -> 0.20115679 | X16: =IFERROR(IF(ISBLANK(V16),"",V16/O16),0) -> 0.36416314 | Y16: =IFERROR(X16-W16,"") -> 0.16300634 | Z16: =IFERROR(X16/W16,"") -> 1.8103447
A17: =Progress!A12 -> ROAD WORKS | C17: =Progress!C12 -> 87969997 | D17: =Progress!D12 -> 0.52167614 | E17: =Progress!E12 -> 3032198.6 | F17: =Progress!F12 -> 1648128 | G17: =Progress!G12 -> 0 | H17: =Progress!H12 -> 45806827 | I17: =Progress!I12 -> 52657041 | J17: =IFERROR(IF(ISBLANK(G17),"",G17/C17),0) -> 0 | K17: =IFERROR(IF(ISBLANK(H17),"",H17/C17),0) -> 0.52070966 | L17: =IFERROR(IF(ISBLANK(I17),"",I17/C17),0) -> 0.59857955 | M17: =IFERROR(L17-K17,"") -> 0.077869883 | N17: =IFERROR(L17/K17,"") -> 1.1495457 | O17: =Progress!K12 -> 186393 | P17: =Progress!L12 -> 0.16361113 | Q17: =Progress!M12 -> 5506 | R17: =Progress!N12 -> 1552 | S17: =IFERROR(IF(ISBLANK(Q17),"",Q17/O17),0) -> 0.029539736 | T17: =IFERROR(IF(ISBLANK(R17),"",R17/O17),0) -> 0.0083264929 | U17: =Progress!O12 -> 115703 | V17: =Progress!P12 -> 139255 | W17: =IFERROR(IF(ISBLANK(U17),"",U17/O17),0) -> 0.62074756 | X17: =IFERROR(IF(ISBLANK(V17),"",V17/O17),0) -> 0.74710424 | Y17: =IFERROR(X17-W17,"") -> 0.12635668 | Z17: =IFERROR(X17/W17,"") -> 1.2035557
A18: =Progress!A13 -> ZONE A | C18: =Progress!C13 -> 54469013 | D18: =Progress!D13 -> 0.32300995 | E18: =Progress!E13 -> 2443662 | F18: =Progress!F13 -> 421282.11 | G18: =Progress!G13 -> 0 | H18: =Progress!H13 -> 24340936 | I18: =Progress!I13 -> 28656488 | J18: =IFERROR(IF(ISBLANK(G18),"",G18/C18),0) -> 0 | K18: =IFERROR(IF(ISBLANK(H18),"",H18/C18),0) -> 0.44687677 | L18: =IFERROR(IF(ISBLANK(I18),"",I18/C18),0) -> 0.52610626 | M18: =IFERROR(L18-K18,"") -> 0.079229487 | N18: =IFERROR(L18/K18,"") -> 1.1772961 | O18: =Progress!K13 -> 121795 | P18: =Progress!L13 -> 0.10690862 | Q18: =Progress!M13 -> 3080 | R18: =Progress!N13 -> 544 | S18: =IFERROR(IF(ISBLANK(Q18),"",Q18/O18),0) -> 0.025288394 | T18: =IFERROR(IF(ISBLANK(R18),"",R18/O18),0) -> 0.0044665216 | U18: =Progress!O13 -> 74862 | V18: =Progress!P13 -> 90010 | W18: =IFERROR(IF(ISBLANK(U18),"",U18/O18),0) -> 0.61465577 | X18: =IFERROR(IF(ISBLANK(V18),"",V18/O18),0) -> 0.7390287 | Y18: =IFERROR(X18-W18,"") -> 0.12437292 | Z18: =IFERROR(X18/W18,"") -> 1.2023456
A19: =Progress!A14 -> ZONE G | C19: =Progress!C14 -> 33500984 | D19: =Progress!D14 -> 0.19866619 | E19: =Progress!E14 -> 588536.68 | F19: =Progress!F14 -> 1226845.9 | G19: =Progress!G14 -> 0 | H19: =Progress!H14 -> 21465891 | I19: =Progress!I14 -> 24000552 | J19: =IFERROR(IF(ISBLANK(G19),"",G19/C19),0) -> 0 | K19: =IFERROR(IF(ISBLANK(H19),"",H19/C19),0) -> 0.64075404 | L19: =IFERROR(IF(ISBLANK(I19),"",I19/C19),0) -> 0.71641335 | M19: =IFERROR(L19-K19,"") -> 0.075659314 | N19: =IFERROR(L19/K19,"") -> 1.1180786 | O19: =Progress!K14 -> 64598 | P19: =Progress!L14 -> 0.056702515 | Q19: =Progress!M14 -> 2425 | R19: =Progress!N14 -> 1009 | S19: =IFERROR(IF(ISBLANK(Q19),"",Q19/O19),0) -> 0.037539862 | T19: =IFERROR(IF(ISBLANK(R19),"",R19/O19),0) -> 0.015619679 | U19: =Progress!O14 -> 40841 | V19: =Progress!P14 -> 49245 | W19: =IFERROR(IF(ISBLANK(U19),"",U19/O19),0) -> 0.6322332 | X19: =IFERROR(IF(ISBLANK(V19),"",V19/O19),0) -> 0.7623301 | Y19: =IFERROR(X19-W19,"") -> 0.13009691 | Z19: =IFERROR(X19/W19,"") -> 1.2057736
A20: =Progress!A15 -> Storm Water Drainage Network | C20: =Progress!C15 -> 25407829 | D20: =Progress!D15 -> 0.15067249 | E20: =Progress!E15 -> 323770.63 | F20: =Progress!F15 -> 0 | G20: =Progress!G15 -> 0 | H20: =Progress!H15 -> 5607920.6 | I20: =Progress!I15 -> 9325845.2 | J20: =IFERROR(IF(ISBLANK(G20),"",G20/C20),0) -> 0 | K20: =IFERROR(IF(ISBLANK(H20),"",H20/C20),0) -> 0.22071624 | L20: =IFERROR(IF(ISBLANK(I20),"",I20/C20),0) -> 0.36704612 | M20: =IFERROR(L20-K20,"") -> 0.14632988 | N20: =IFERROR(L20/K20,"") -> 1.6629774 | O20: =Progress!K15 -> 187421 | P20: =Progress!L15 -> 0.16451348 | Q20: =Progress!M15 -> 3091 | R20: =Progress!N15 -> 0 | S20: =IFERROR(IF(ISBLANK(Q20),"",Q20/O20),0) -> 0.016492282 | T20: =IFERROR(IF(ISBLANK(R20),"",R20/O20),0) -> 0 | U20: =Progress!O15 -> 29500 | V20: =Progress!P15 -> 75282 | W20: =IFERROR(IF(ISBLANK(U20),"",U20/O20),0) -> 0.15739965 | X20: =IFERROR(IF(ISBLANK(V20),"",V20/O20),0) -> 0.40167324 | Y20: =IFERROR(X20-W20,"") -> 0.24427359 | Z20: =IFERROR(X20/W20,"") -> 2.5519322
A21: =Progress!A16 -> ZONE A | C21: =Progress!C16 -> 22856155 | D21: =Progress!D16 -> 0.13554065 | E21: =Progress!E16 -> 292630.25 | F21: =Progress!F16 -> 0 | G21: =Progress!G16 -> 0 | H21: =Progress!H17 -> 282827.44 | I21: =Progress!I16 -> 6792269.6 | J21: =IFERROR(IF(ISBLANK(G21),"",G21/C21),0) -> 0 | K21: =IFERROR(IF(ISBLANK(H21),"",H21/C21),0) -> 0.012374235 | L21: =IFERROR(IF(ISBLANK(I21),"",I21/C21),0) -> 0.29717464 | M21: =IFERROR(L21-K21,"") -> 0.2848004 | N21: =IFERROR(L21/K21,"") -> 24.015596 | O21: =Progress!K16 -> 131130 | P21: =Progress!L16 -> 0.11510265 | Q21: =Progress!M16 -> 2166 | R21: =Progress!N16 -> 0 | S21: =IFERROR(IF(ISBLANK(Q21),"",Q21/O21),0) -> 0.016517959 | T21: =IFERROR(IF(ISBLANK(R21),"",R21/O21),0) -> 0 | U21: =Progress!O16 -> 20841 | V21: =Progress!P16 -> 19664 | W21: =IFERROR(IF(ISBLANK(U21),"",U21/O21),0) -> 0.15893388 | X21: =IFERROR(IF(ISBLANK(V21),"",V21/O21),0) -> 0.14995806 | Y21: =IFERROR(X21-W21,"") -> -0.0089758255 | Z21: =IFERROR(X21/W21,"") -> 0.94352478
A22: =Progress!A17 -> ZONE G | C22: =Progress!C17 -> 2551674.2 | D22: =Progress!D17 -> 0.015131836 | E22: =Progress!E17 -> 0 | F22: =Progress!F17 -> 0 | G22: =Progress!G17 -> 0 | H22: =Progress!H17 -> 282827.44 | I22: =Progress!I17 -> 2533575.5 | J22: =IFERROR(IF(ISBLANK(G22),"",G22/C22),0) -> 0 | K22: =IFERROR(IF(ISBLANK(H22),"",H22/C22),0) -> 0.11083995 | L22: =IFERROR(IF(ISBLANK(I22),"",I22/C22),0) -> 0.99290714 | M22: =IFERROR(L22-K22,"") -> 0.88206719 | N22: =IFERROR(L22/K22,"") -> 8.9580259 | O22: =Progress!K17 -> 56291 | P22: =Progress!L17 -> 0.049410837 | Q22: =Progress!M17 -> 0 | R22: =Progress!N17 -> 0 | S22: =IFERROR(IF(ISBLANK(Q22),"",Q22/O22),0) -> 0 | T22: =IFERROR(IF(ISBLANK(R22),"",R22/O22),0) -> 0 | U22: =Progress!O17 -> 8660 | V22: =Progress!P17 -> 55618 | W22: =IFERROR(IF(ISBLANK(U22),"",U22/O22),0) -> 0.15384342 | X22: =IFERROR(IF(ISBLANK(V22),"",V22/O22),0) -> 0.98804427 | Y22: =IFERROR(X22-W22,"") -> 0.83420085 | Z22: =IFERROR(X22/W22,"") -> 6.4224018
A23: =Progress!A18 -> Sewerage Network | C23: =Progress!C18 -> 7071026.8 | D23: =Progress!D18 -> 0.041932319 | E23: =Progress!E51 -> 0 | F23: =Progress!F18 -> 0 | G23: =Progress!G18 -> 0 | H23: =Progress!H18 -> 16569.23 | I23: =Progress!I18 -> 5356988.8 | O23: =Progress!K18 -> 62221 | P23: =Progress!L18 -> 0.054616044 | Q23: =Progress!M18 -> 221 | R23: =Progress!N18 -> 0 | S23: =IFERROR(IF(ISBLANK(Q23),"",Q23/O23),0) -> 0.0035518555 | T23: =IFERROR(IF(ISBLANK(R23),"",R23/O23),0) -> 0 | U23: =Progress!O18 -> 221 | V23: =Progress!P18 -> 44444 | W23: =IFERROR(IF(ISBLANK(U23),"",U23/O23),0) -> 0.0035518555 | X23: =IFERROR(IF(ISBLANK(V23),"",V23/O23),0) -> 0.7142926 | Y23: =IFERROR(X23-W23,"") -> 0.71074075 | Z23: =IFERROR(X23/W23,"") -> 201.10407
A24: =Progress!A19 -> ZONE A | C24: =Progress!C19 -> 4499744.2 | D24: =Progress!D19 -> 0.026684202 | F24: =Progress!F19 -> 0 | G24: =Progress!G19 -> 0 | H24: =Progress!H19 -> 8297.86 | I24: =Progress!I19 -> 2912490.8 | O24: =Progress!K19 -> 40161 | P24: =Progress!L19 -> 0.035252325 | Q24: =Progress!M19 -> 85 | R24: =Progress!N19 -> 0 | S24: =IFERROR(IF(ISBLANK(Q24),"",Q24/O24),0) -> 0.0021164812 | T24: =IFERROR(IF(ISBLANK(R24),"",R24/O24),0) -> 0 | U24: =Progress!O19 -> 85 | V24: =Progress!P19 -> 23456 | W24: =IFERROR(IF(ISBLANK(U24),"",U24/O24),0) -> 0.0021164812 | X24: =IFERROR(IF(ISBLANK(V24),"",V24/O24),0) -> 0.5840492 | Y24: =IFERROR(X24-W24,"") -> 0.58193272 | Z24: =IFERROR(X24/W24,"") -> 275.95294
A25: =Progress!A20 -> ZONE G | C25: =Progress!C20 -> 2571282.6 | D25: =Progress!D20 -> 0.015248117 | F25: =Progress!F20 -> 0 | G25: =Progress!G20 -> 0 | H25: =Progress!H20 -> 8271.37 | I25: =Progress!I20 -> 2444498.1 | O25: =Progress!K20 -> 22061 | P25: =Progress!L20 -> 0.019364596 | Q25: =Progress!M20 -> 0 | R25: =Progress!N20 -> 0 | S25: =IFERROR(IF(ISBLANK(Q25),"",Q25/O25),0) -> 0 | T25: =IFERROR(IF(ISBLANK(R25),"",R25/O25),0) -> 0 | U25: =Progress!O20 -> 136 | V25: =Progress!P20 -> 20987 | W25: =IFERROR(IF(ISBLANK(U25),"",U25/O25),0) -> 0.0061647251 | X25: =IFERROR(IF(ISBLANK(V25),"",V25/O25),0) -> 0.9513168 | Y25: =IFERROR(X25-W25,"") -> 0.94515208 | Z25: =IFERROR(X25/W25,"") -> 154.31618
A26: =Progress!A21 -> TSE Network | C26: =Progress!C21 -> 4147696.1 | D26: =Progress!D21 -> 0.024596501 | F26: =Progress!F21 -> 13961.66 | G26: =Progress!G21 -> 0 | I26: =Progress!I21 -> 581492.39 | O26: =Progress!K21 -> 87808 | P26: =Progress!L21 -> 0.077075675 | Q26: =Progress!M21 -> 0 | R26: =Progress!N21 -> 455 | S26: =IFERROR(IF(ISBLANK(Q26),"",Q26/O26),0) -> 0 | T26: =IFERROR(IF(ISBLANK(R26),"",R26/O26),0) -> 0.0051817602 | U26: =Progress!O21 -> 0 | V26: =Progress!P21 -> 3248 | W26: =IFERROR(IF(ISBLANK(U26),"",U26/O26),0) -> 0 | X26: =IFERROR(IF(ISBLANK(V26),"",V26/O26),0) -> 0.036989796 | Y26: =IFERROR(X26-W26,"") -> 0.036989796 | Z26: =IFERROR(X26/W26,"")
A27: =Progress!A22 -> ZONE A | C27: =Progress!C22 -> 3158469.4 | D27: =Progress!D22 -> 0.018730228 | E27: =Progress!E43 -> 0 | F27: =Progress!F22 -> 13089.57 | G27: =Progress!G22 -> 0 | H27: =Progress!H35 -> 44969.06 | I27: =Progress!I22 -> 518004.64 | J27: =IFERROR(IF(ISBLANK(G27),"",G27/C27),0) -> 0 | K27: =IFERROR(IF(ISBLANK(H27),"",I27/C27),0) -> 0.16400496 | L27: =IFERROR(IF(ISBLANK(I27),"",I27/C27),0) -> 0.16400496 | M27: =IFERROR(L27-K27,"") -> 0 | N27: =IFERROR(L27/K27,"") -> 1 | O27: =Progress!K22 -> 64717 | P27: =Progress!L22 -> 0.05680697 | Q27: =Progress!M22 -> 0 | R27: =Progress!N43 -> 0 | S27: =IFERROR(IF(ISBLANK(Q27),"",Q27/O27),0) -> 0 | T27: =IFERROR(IF(ISBLANK(R27),"",R27/O27),0) -> 0 | U27: =Progress!O35 -> 1141 | V27: =Progress!P22 -> 1995 | W27: =IFERROR(IF(ISBLANK(U27),"",U27/O27),0) -> 0.017630607 | X27: =IFERROR(IF(ISBLANK(V27),"",V27/O27),0) -> 0.030826522 | Y27: =IFERROR(X27-W27,"") -> 0.013195915 | Z27: =IFERROR(X27/W27,"") -> 1.7484663
A28: =Progress!A23 -> ZONE G | C28: =Progress!C23 -> 989226.71 | D28: =Progress!D23 -> 0.0058662725 | F28: =Progress!F23 -> 872.1 | G28: =Progress!G23 -> 0 | I28: =Progress!I23 -> 63487.76 | O28: =Progress!K23 -> 23091 | P28: =Progress!L23 -> 0.020268705 | Q28: =Progress!M23 -> 0 | R28: =Progress!N44 -> 0 | S28: =IFERROR(IF(ISBLANK(Q28),"",Q28/O28),0) -> 0 | T28: =IFERROR(IF(ISBLANK(R28),"",R28/O28),0) -> 0 | U28: =Progress!O36 -> 0 | V28: =Progress!P23 -> 1252 | W28: =IFERROR(IF(ISBLANK(U28),"",U28/O28),0) -> 0 | X28: =IFERROR(IF(ISBLANK(V28),"",V28/O28),0) -> 0.054220259 | Y28: =IFERROR(X28-W28,"") -> 0.054220259 | Z28: =IFERROR(X28/W28,"")
A29: =Progress!A24 -> Portable Water | C29: =Progress!C24 -> 7780467.6 | D29: =Progress!D24 -> 0.046139416 | F29: =Progress!F24 -> 16207.71 | G29: =Progress!G24 -> 0 | H29: =Progress!H24 -> 0 | I29: =Progress!I24 -> 1517663.9 | J29: =IFERROR(IF(ISBLANK(G29),"",G29/C29),0) -> 0 | K29: =IFERROR(IF(ISBLANK(H29),"",H29/C29),0) -> 0 | L29: =IFERROR(IF(ISBLANK(I29),"",I29/C29),0) -> 0.19506076 | M29: =IFERROR(L29-K29,"") -> 0.19506076 | O29: =Progress!K24 -> 139722 | P29: =Progress!L24 -> 0.12264449 | Q29: =Progress!M24 -> 0 | R29: =Progress!N24 -> 540 | S29: =IFERROR(IF(ISBLANK(Q29),"",Q29/O29),0) -> 0 | T29: =IFERROR(IF(ISBLANK(R29),"",R29/O29),0) -> 0.0038648173 | U29: =Progress!O37 -> 0 | V29: =Progress!P24 -> 14747 | W29: =IFERROR(IF(ISBLANK(U29),"",U29/O29),0) -> 0 | X29: =IFERROR(IF(ISBLANK(V29),"",V29/O29),0) -> 0.1055453 | Y29: =IFERROR(X29-W29,"") -> 0.1055453 | Z29: =IFERROR(X29/W29,"")
A30: =Progress!A25 -> ZONE A | C30: =Progress!C25 -> 4936252.6 | D30: =Progress!D25 -> 0.029272767 | F30: =Progress!F25 -> 16207.71 | G30: =Progress!G25 -> 0 | I30: =Progress!I25 -> 295925.92 | O30: =Progress!K25 -> 99650 | P30: =Progress!L25 -> 0.087470287 | Q30: =Progress!M25 -> 0 | R30: =Progress!N25 -> 540 | S30: =IFERROR(IF(ISBLANK(Q30),"",Q30/O30),0) -> 0 | T30: =IFERROR(IF(ISBLANK(R30),"",R30/O30),0) -> 0.0054189664 | U30: =Progress!O38 -> 0 | V30: =Progress!P25 -> 4061 | W30: =IFERROR(IF(ISBLANK(U30),"",U30/O30),0) -> 0 | X30: =IFERROR(IF(ISBLANK(V30),"",V30/O30),0) -> 0.040752634 | Y30: =IFERROR(X30-W30,"") -> 0.040752634 | Z30: =IFERROR(X30/W30,"")
A31: =Progress!A26 -> ZONE G | C31: =Progress!C26 -> 2844215 | D31: =Progress!D26 -> 0.016866649 | F31: =Progress!F26 -> 0 | G31: =Progress!G26 -> 0 | H31: =Progress!H26 -> 0 | I31: =Progress!I26 -> 1221738 | J31: =IFERROR(IF(ISBLANK(G31),"",G31/C31),0) -> 0 | K31: =IFERROR(IF(ISBLANK(H31),"",H31/C31),0) -> 0 | L31: =IFERROR(IF(ISBLANK(I31),"",I31/C31),0) -> 0.42955192 | M31: =IFERROR(L31-K31,"") -> 0.42955192 | O31: =Progress!K26 -> 40072 | P31: =Progress!L26 -> 0.035174203 | Q31: =Progress!M26 -> 0 | R31: =Progress!N26 -> 0 | S31: =IFERROR(IF(ISBLANK(Q31),"",Q31/O31),0) -> 0 | T31: =IFERROR(IF(ISBLANK(R31),"",R31/O31),0) -> 0 | U31: =Progress!O39 -> 0 | V31: =Progress!P26 -> 10686 | W31: =IFERROR(IF(ISBLANK(U31),"",U31/O31),0) -> 0 | X31: =IFERROR(IF(ISBLANK(V31),"",V31/O31),0) -> 0.26666999 | Y31: =IFERROR(X31-W31,"") -> 0.26666999 | Z31: =IFERROR(X31/W31,"")
A32: =Progress!A27 -> Electrical Works | C32: =Progress!C27 -> 20111193 | D32: =Progress!D27 -> 0.11926259 | F32: =Progress!F27 -> 23290.44 | G32: =Progress!G27 -> 0 | O32: =Progress!K27 -> 99033 | P32: =Progress!L27 -> 0.0869287
A33: =Progress!A28 -> ZONE A | C33: =Progress!C28 -> 13562632 | D33: =Progress!D28 -> 0.080428575 | G33: =Progress!G28 -> 0 | O33: =Progress!K28 -> 63660 | P33: =Progress!L28 -> 0.055879162
A34: =Progress!A29 -> ZONE G | C34: =Progress!C29 -> 6548561.2 | D34: =Progress!D29 -> 0.038834014 | G34: =Progress!G29 -> 0 | O34: =Progress!K29 -> 35373 | P34: =Progress!L29 -> 0.031049538
A35: =Progress!A30 -> Landscape & Irrigation Works | C35: =Progress!C30 -> 6835460.6 | D35: =Progress!D30 -> 0.040535373 | G35: =Progress!G30 -> 0 | O35: =Progress!K30 -> 77656 | P35: =Progress!L30 -> 0.068164502
A36: =Progress!A31 -> ZONE A | C36: =Progress!C31 -> 3801841.7 | D36: =Progress!D31 -> 0.022545529 | G36: =Progress!G31 -> 0 | O36: =Progress!K31 -> 65750 | P36: =Progress!L31 -> 0.057713712
A37: =Progress!A32 -> ZONE G | C37: =Progress!C32 -> 3033618.9 | D37: =Progress!D32 -> 0.017989845 | G37: =Progress!G32 -> 0 | O37: =Progress!K32 -> 11907 | P37: =Progress!L32 -> 0.010451668
A38: =Progress!A33 -> CCTV Works | C38: =Progress!C33 -> 9305849.6 | D38: =Progress!D33 -> 0.055185175 | G38: =Progress!G33 -> 0 | O38: =Progress!K33 -> 14178 | P38: =Progress!L33 -> 0.012445095
A39: =Progress!A34 -> ZONE A | C39: 46056 | D39: =Progress!D34 -> 0.038629034 | G39: =Progress!G34 -> 0 | O39: =Progress!K34 -> 7062 | P39: =Progress!L34 -> 0.0061988477
A40: =Progress!A35 -> ZONE G | C40: 2 | D40: =Progress!D35 -> 0.016556141 | G40: =Progress!G35 -> 0 | O40: =Progress!K35 -> 7116 | P40: =Progress!L35 -> 0.0062462475
A41: =Progress!A36 -> Testing and commissioning | C41: =Progress!C36 -> 0 | D41: =Progress!D36 -> 0 | E41: =Progress!E44 -> 0 | F41: =Progress!F44 -> 0 | G41: =Progress!G36 -> 0 | H41: =Progress!H36 -> 0 | I41: =Progress!I36 -> 0 | J41: =IFERROR(IF(ISBLANK(G41),"",G41/C41),0) -> 0 | K41: =IFERROR(IF(ISBLANK(I41),"",I41/C41),0) -> 0 | L41: =IFERROR(IF(ISBLANK(I41),"",I41/C41),0) -> 0 | M41: =IFERROR(L41-K41,"") -> 0 | N41: =IFERROR(L41/K41,"") | O41: =Progress!K36 -> 22785 | P41: =Progress!L36 -> 0.020000105 | Q41: =Progress!M44 -> 0 | R41: =Progress!N44 -> 0 | S41: =IFERROR(IF(ISBLANK(Q41),"",Q41/O41),0) -> 0 | T41: =IFERROR(IF(ISBLANK(R41),"",R41/O41),0) -> 0 | U41: =Progress!O36 -> 0 | V41: =Progress!P36 -> 0 | W41: =IFERROR(IF(ISBLANK(U41),"",U41/O41),0) -> 0 | X41: =IFERROR(IF(ISBLANK(V41),"",V41/O41),0) -> 0 | Y41: =IFERROR(X41-W41,"") -> 0 | Z41: =IFERROR(X41/W41,"")
...

Sheet Sheet1

Sheet Sheet2

Sheet Sheet3

Sheet Sheet4

Sheet Sheet5

Sheet Sheet6

Sheet General Information
A1: Weekly Progress Report - Construction Projects | K1: Data Date | L1: 46293
A2: Contract General Information
A3: Project Name | C3: Infrastructure Network Development Project in Sudair City for Industry and Business - Phase Two - Part Two
A4: Project ID | C4: SUD1-02-011
A5: Contractor | C5: Technical Dvelopment Co. "TDC"
A6: Consultant | C6: Saudi Arabia Consulting Engineering Company "EGIS"
A7: Stage | C7: Construction
A8: Status | C8: Active
A9: Modon PM | C9: Engr.Zyad Al Shabat
H10: =H53 -> 0 | I10: =I53 -> 0
A11: Key Dates | H11: =H54 -> 0 | I11: =I54 -> 0
A12: Contract Award Date | C12: 45998
A13: Contract Sign Date | C13: 46020
A14: Site Handover Date | C14: 46028
A15: Original Completion | C15: 46573
A16: Contract Award Date (Hijri) | C16: 16/6/1447
A17: Contract Sign Date (Hijri) | C17: 9/7/1447
A18: Site Handover Date (Hijri) | C18: 17/7/1447
A19: Original Completion (Hijri) | C19: 30/1/1449
A20: Revised Completion Date | C20: 0
A21: Committed Completion Date | C21: 46573
A22: Forecast Completion | C22: 46573
A23: Variance | C23: =C22-C15 -> 0
A25: Key Project Submittals | C25: Submission Date | D25: Days taken to approve orginal plan from site handover date
A26: Quality Plan submission | C26: 46057 | D26: =C26-C14 -> 29
A27: Quality Plan approval | C27: 46112
A28: Quality Plan Last Update | C28: 46112
A30: Safety Plan submission | C30: 46044 | D30: =C30-C14 -> 16
A31: Safety Plan approval | C31: 46049
A32: Safety Plan Last Update | C32: 46049
A34: Risk Management Plan submission | C34: 46050 | D34: =C34-C14 -> 22
A35: Risk Management Plan approval | C35: 46056
A36: Risk Management Plan Last Update | C36: 46056
A38: Baseline Schedule submission | C38: 46053 | D38: =C38-C14 -> 25
A39: Baseline Schedule approval | C39: 46120
A40: No of Schedule Versions | C40: 1
A41: Last Revised Schedule Approval Date | C41: -
A43: BOQ submission | C43: - | D43: -
A44: BOQ approval | C44: -
A45: No of Approved Version of BOQ | C45: -
...

Sheet Progress
A1: Project Scope Statement | B1: The scope of work of the project includes the implementation of the entire works subject to the contract, including the following: Road and paving works, Potable Water Network Works, Treatment Water Network Works, Sewer network works, Rainwater drainage network works, Irrigation and landscaping network works, Electrical network works including (medium voltage, communications, road lighting), Camera surveillance work
A4: Earned Value Progress (SAR) | K4: Physical Progress (Effort)
A5: WBS | C5: BOQ Value (SAR) | D5: % Wt. | E5: Weekly (SAR) | H5: To Date (SAR) | K5: Budgeted | L5: % Wt. | M5: Weekly Physical Progress | O5: To Date Physical Progress
E6: Planned | F6: Earned | G6: Original Plan | H6: Planned | I6: Earned | K6: (Manhours) | M6: Planned | N6: Earned | O6: Planned | P6: Earned
A7: Milestones | C7: 0 | H7: 0 | I7: 0 | K7: 0 | L7: =K7/$K$46 -> 0 | O7: 0 | P7: 0
A8: Mobilization | C8: 0 | H8: 0 | I8: 0 | K8: 34177 | L8: =K8/$K$46 -> 0.029999719 | M8: =O8-O51 -> 0 | N8: =P8-P51 -> 0 | O8: 34177 | P8: 34177
A9: Engineering | C9: 0 | D9: =C9/$C$46 -> 0 | E9: =H9-H52 -> 0 | F9: =I9-I52 -> 0 | G9: 0 | H9: 0 | I9: 0 | K9: 56962 | L9: =K9/$K$46 -> 0.049999824 | M9: =O9-O52 -> 0 | N9: =P9-P52 -> 0 | O9: 56962 | P9: 53211
A10: Procurement | C10: 0 | D10: =C10/$C$46 -> 0 | E10: =H10-H53 -> 0 | F10: =I10-I53 -> 0 | G10: 0 | H10: 0 | I10: 0 | K10: 148102 | L10: =K10/$K$46 -> 0.13000025 | M10: =O10-O53 -> 1511 | N10: =P10-P53 -> 0 | O10: 143233 | P10: 48418
A11: Construction | C11: 1.6862952e+08 | D11: =C11/$C$46 -> 1 | E11: =H11-H54 -> 3995420.2 | F11: =I11-I54 -> 1709872.9 | G11: 0 | H11: 54083772 | I11: 73149321 | K11: 854433 | L11: =K11/$K$46 -> 0.75 | M11: =O11-O54 -> 13886 | N11: =P11-P54 -> 3659 | O11: 171875 | P11: 311153
A12: ROAD WORKS | C12: 87969997 | D12: =C12/$C$11 -> 0.52167614 | E12: =H12-H55 -> 3032198.6 | F12: =I12-I55 -> 1648128 | G12: 0 | H12: 45806827 | I12: 52657041 | K12: 186393 | L12: =K12/$K$46 -> 0.16361113 | M12: =O12-O55 -> 5506 | N12: =P12-P55 -> 1552 | O12: 115703 | P12: 139255
A13: ZONE A | C13: 54469013 | D13: =C13/$C$11 -> 0.32300995 | E13: =H13-H56 -> 2443662 | F13: =I13-I56 -> 421282.11 | G13: 0 | H13: 24340936 | I13: 28656488 | K13: 121795 | L13: =K13/$K$46 -> 0.10690862 | M13: =O13-O56 -> 3080 | N13: =P13-P56 -> 544 | O13: 74862 | P13: 90010
A14: ZONE G | C14: 33500984 | D14: =C14/$C$11 -> 0.19866619 | E14: =H14-H57 -> 588536.68 | F14: =I14-I57 -> 1226845.9 | G14: 0 | H14: 21465891 | I14: 24000552 | K14: 64598 | L14: =K14/$K$46 -> 0.056702515 | M14: =O14-O57 -> 2425 | N14: =P14-P57 -> 1009 | O14: 40841 | P14: 49245
A15: Storm Water Drainage Network | C15: 25407829 | D15: =C15/$C$11 -> 0.15067249 | E15: =H15-H58 -> 323770.63 | F15: =I15-I58 -> 0 | G15: 0 | H15: 5607920.6 | I15: 9325845.2 | K15: 187421 | L15: =K15/$K$46 -> 0.16451348 | M15: =O15-O58 -> 3091 | N15: =P15-P58 -> 0 | O15: 29500 | P15: 75282
A16: ZONE A | C16: 22856155 | D16: =C16/$C$11 -> 0.13554065 | E16: =H16-H59 -> 292630.25 | F16: =I16-I59 -> 0 | G16: 0 | H16: 5325093.1 | I16: 6792269.6 | K16: 131130 | L16: =K16/$K$46 -> 0.11510265 | M16: =O16-O59 -> 2166 | N16: =P16-P59 -> 0 | O16: 20841 | P16: 19664
A17: ZONE G | C17: 2551674.2 | D17: =C17/$C$11 -> 0.015131836 | F17: =I17-I60 -> 0 | G17: 0 | H17: 282827.44 | I17: 2533575.5 | K17: 56291 | L17: =K17/$K$46 -> 0.049410837 | N17: =P17-P60 -> 0 | O17: 8660 | P17: 55618
A18: Sewerage Network | C18: 7071026.8 | D18: =C18/$C$11 -> 0.041932319 | E18: =H18-H61 -> 16569.23 | F18: =I18-I61 -> 0 | G18: 0 | H18: 16569.23 | I18: 5356988.8 | K18: 62221 | L18: =K18/$K$46 -> 0.054616044 | M18: =O18-O61 -> 221 | N18: =P18-P61 -> 0 | O18: 221 | P18: 44444
A19: ZONE A | C19: 4499744.2 | D19: =C19/$C$11 -> 0.026684202 | E19: =H19-H62 -> 8297.86 | F19: =I19-I62 -> 0 | G19: 0 | H19: 8297.86 | I19: 2912490.8 | K19: 40161 | L19: =K19/$K$46 -> 0.035252325 | M19: =O19-O62 -> 85 | N19: =P19-P62 -> 0 | O19: 85 | P19: 23456
A20: ZONE G | C20: 2571282.6 | D20: =C20/$C$11 -> 0.015248117 | E20: =H20-H63 -> 8271.37 | F20: =I20-I63 -> 0 | G20: 0 | H20: 8271.37 | I20: 2444498.1 | K20: 22061 | L20: =K20/$K$46 -> 0.019364596 | N20: =P20-P63 -> 0 | O20: 136 | P20: 20987
A21: TSE Network | C21: 4147696.1 | D21: =C21/$C$11 -> 0.024596501 | E21: =H21-H64 -> 0 | F21: =I21-I64 -> 13961.66 | G21: 0 | H21: 0 | I21: 581492.39 | K21: 87808 | L21: =K21/$K$46 -> 0.077075675 | M21: =O21-O64 -> 0 | N21: =P21-P64 -> 455 | O21: 0 | P21: 3248
A22: ZONE A | C22: 3158469.4 | D22: =C22/$C$11 -> 0.018730228 | E22: =H22-H65 -> 0 | F22: =I22-I65 -> 13089.57 | G22: 0 | H22: 0 | I22: 518004.64 | K22: 64717 | L22: =K22/$K$46 -> 0.05680697 | M22: =O22-O65 -> 0 | N22: =P22-P65 -> 380 | O22: 0 | P22: 1995
A23: ZONE G | C23: 989226.71 | D23: =C23/$C$11 -> 0.0058662725 | E23: =H23-H66 -> 0 | F23: =I23-I66 -> 872.1 | G23: 0 | H23: 0 | I23: 63487.76 | K23: 23091 | L23: =K23/$K$46 -> 0.020268705 | M23: =O23-O66 -> 0 | N23: =P23-P66 -> 74 | O23: 0 | P23: 1252
A24: Portable Water | C24: 7780467.6 | D24: =C24/$C$11 -> 0.046139416 | E24: =H24-H67 -> 0 | F24: =I24-I67 -> 16207.71 | G24: 0 | H24: 0 | I24: 1517663.9 | K24: 139722 | L24: =K24/$K$46 -> 0.12264449 | M24: =O24-O67 -> 0 | N24: =P24-P67 -> 540 | O24: 0 | P24: 14747
A25: ZONE A | C25: 4936252.6 | D25: =C25/$C$11 -> 0.029272767 | E25: =H25-H68 -> 0 | F25: =I25-I68 -> 16207.71 | G25: 0 | H25: 0 | I25: 295925.92 | K25: 99650 | L25: =K25/$K$46 -> 0.087470287 | M25: =O25-O68 -> 0 | N25: =P25-P68 -> 540 | O25: 0 | P25: 4061
A26: ZONE G | C26: 2844215 | D26: =C26/$C$11 -> 0.016866649 | E26: =H26-H69 -> 0 | F26: =I26-I69 -> 0 | G26: 0 | H26: 0 | I26: 1221738 | K26: 40072 | L26: =K26/$K$46 -> 0.035174203 | M26: =O26-O69 -> 0 | N26: =P26-P69 -> 0 | O26: 0 | P26: 10686
A27: Electrical Works | C27: 20111193 | D27: =C27/$C$11 -> 0.11926259 | E27: =H27-H70 -> 587192 | F27: =I27-I70 -> 23290.44 | G27: 0 | H27: 2517547.2 | I27: 3252560.1 | K27: 99033 | L27: =K27/$K$46 -> 0.0869287 | M27: =O27-O70 -> 4096 | N27: =P27-P70 -> 756 | O27: 23528 | P27: 31405
A28: ZONE A | C28: 13562632 | D28: =C28/$C$11 -> 0.080428575 | E28: =H28-H71 -> 380968.12 | F28: =I28-I71 -> 19086.25 | G28: 0 | H28: 1907363.8 | I28: 1970463.2 | K28: 63660 | L28: =K28/$K$46 -> 0.055879162 | M28: =O28-O71 -> 2626 | N28: =P28-P71 -> 637 | O28: 19316 | P28: 17636
A29: ZONE G | C29: 6548561.2 | D29: =C29/$C$11 -> 0.038834014 | E29: =H29-H72 -> 206223.88 | F29: =I29-I72 -> 4204.19 | G29: 0 | H29: 610183.42 | I29: 1282096.9 | K29: 35373 | L29: =K29/$K$46 -> 0.031049538 | M29: =O29-O72 -> 1469 | N29: =P29-P72 -> 120 | O29: 4211 | P29: 13769
A30: Landscape & Irrigation Works | C30: 6835460.6 | D30: =C30/$C$11 -> 0.040535373 | E30: =H30-H73 -> 0 | F30: =I30-I73 -> 8285.05 | G30: 0 | H30: 0 | I30: 20712.61 | K30: 77656 | L30: =K30/$K$46 -> 0.068164502 | M30: =O30-O73 -> 0 | N30: =P30-P73 -> 354 | O30: 0 | P30: 1047
A31: ZONE A | C31: 3801841.7 | D31: =C31/$C$11 -> 0.022545529 | E31: =H31-H74 -> 0 | F31: =I31-I74 -> 8285.05 | G31: 0 | H31: 0 | I31: 20712.61 | K31: 65750 | L31: =K31/$K$46 -> 0.057713712 | M31: =O31-O74 -> 0 | N31: =P31-P74 -> 354 | O31: 0 | P31: 1047
A32: ZONE G | C32: 3033618.9 | D32: =C32/$C$11 -> 0.017989845 | E32: =H32-H75 -> 0 | F32: =I32-I75 -> 0 | G32: 0 | H32: 0 | I32: 0 | K32: 11907 | L32: =K32/$K$46 -> 0.010451668 | M32: =O32-O75 -> 0 | N32: =P32-P75 -> 0 | O32: 0 | P32: 0
... A35: ZONE G | C35: 2791854.1 | D35: =C35/$C$11 -> 0.016556141 | E35: =H35-H78 -> 10706.92 | F35: =I35-I78 -> 0 | G35: 0 | H35: 44969.06 | I35: 95874.69 | K35: 7116 | L35: =K35/$K$46 -> 0.0062462475 | M35: =O35-O78 -> 194 | N35: =P35-P78 -> 0 | O35: 1141 | P35: 730
A36: Testing and commissioning | C36: 0 | D36: =C36/$C$46 -> 0 | E36: =H36-H79 -> 0 | F36: =I36-I79 -> 0 | G36: 0 | H36: 0 | I36: 0 | K36: 22785 | L36: =K36/$K$46 -> 0.020000105 | M36: =O36-O79 -> 0 | N36: =P36-P79 -> 0 | O36: 0 | P36: 0
A37: Close out | C37: 0 | D37: =C37/$C$46 -> 0 | E37: =H37-H80 -> 0 | F37: =I37-I80 -> 0 | H37: 0 | I37: 0 | K37: 22785 | L37: =K37/$K$46 -> 0.020000105 | M37: =O37-O80 -> 0 | N37: =P37-P80 -> 0 | O37: 0 | P37: 0
P38: 0
P39: 0
P40: 0
P41: 0
B46: Total | C46: =SUM(C9+C10+C11+C36+C37) -> 1.6862952e+08 | D46: =D9+D10+D11+D36+D37 -> 1 | E46: =E9+E10+E11+E36 -> 3995420.2 | F46: =F9+F10+F11+F36 -> 1709872.9 | G46: =G9+G10+G11+G37+G38+G36 -> 0 | H46: =H9+H10+H11+H36+H37 -> 54083772 | I46: =+I37+I36+I11+I10+I9 -> 73149321 | K46: =K8+K9+K10+K11+K36+K37 -> 1139244 | L46: =L7+L8+L9+L10+L11+L36+L37 -> 1 | M46: =M8+M9+M10+M11+M36+M37 -> 15397 | N46: =N8+N9+N10+N11+N36+N37 -> 3659 | O46: =O8+O9+O10+O11+O36+O37 -> 406247 | P46: =P8+P9+P10+P11+P36+P37 -> 446959
G47: =G46/C46 -> 0 | H47: =H46/C46 -> 0.32072541 | I47: =I46/C46 -> 0.43378716 | O47: =O46/K46 -> 0.3565935 | P47: =P46/K46 -> 0.39232947
O49: PW Planned | P49: PW Actuals
...

Sheet Weekly Photos
B1: WEEKLY PROGRESS PHOTOS | V1: ='[37]General Information'!K1 -> Data Date | W1: ='General Information'!L1 -> 46293
B21: Compaction for base course layer works at MC20 Zone A | L21: Grading for base course layer works at MC20 Zone A
B40: Zone G, Asphalt works at road MCE0. 1ST Layer | L40: Zone G, Compaction for asphalt works at road MCE0. 1ST Layer
B59: Fire hydrant 6" delivered to site store- 58 pcs | L59: Asphalt base course cutting core works at Road MCF0, ZONE G.

Sheet Quality.
B2: QC OBSERVATIONS CHECKLIST
BB4: 45377
B6: Project No. | E6: SUD1-02-011 | K6: OBS No. | U6: Inspection Day: | X6: ='General Information'!L1 -> 46293
B8: Project | E8: Infrastructure Networks Development Project in Sudir City for Industry and Business Phase II – Part II | O8: =O52 -> 0 | U8: Technical Development Company Egis Engineering cunsultancy
B10: 4 | D10: Excellent | G10: Quality Management System is being practiced and applies to MODON System | Z10: 90 - 100 | AB10: QC Overall Score | AC10: =Q49 -> 0.81344828 | AN10: =SUM(Z10:Z13) -> 0 | AO10: 100 | AP10: 0.22883295
B11: 3 | D11: Good | G11: Evidence of compliance with plans and procedures. | Z11: 80 - 89 | AN11: =SUM(Y10:Y14) -> 0 | AO11: 89 | AP11: 0.20366133
B12: 2 | D12: Average | G12: Indication level of compliance with standards but there is room for improvement | Z12: 70 - 79 | AO12: 79 | AP12: 0.18077803
B13: 1 | D13: Improve | G13: Quality and Control is NOT being managed effectively. Needs Improvement | Z13: ≤ 69 | AO13: 69 | AP13: 0.15789474
B14: 0 | D14: N/A | G14: Item was not applicable or this item was not reviewed during the inspection. | Z14: Zero | AO14: 100 | AP14: 0.22883295
B16: No. | C16: Topic | K16: E (4) | L16: G (3) | M16: A (2) | N16: I (1) | O16: N/A (0) | P16: =P61 -> 0 | Q16: No. | R16: Topic | Z16: E (4) | AA16: G (3) | AB16: A (2) | AC16: I (1) | AD16: N/A (0) | AO16: =SUM(AO10:AO15) -> 437
K17: 1 | L17: 0.89 | M17: 0.79 | N17: 0.69 | O17: =O62 -> 0 | Z17: 1 | AA17: 0.89 | AB17: 0.79 | AC17: 0.69 | AD17: 1 | AF17: =SUM(AF18:AG46)/COUNT(AF18:AG46) -> 0.81344828
B18: 1 | C18: Control of Access to Site/Office | L18: 1 | Q18: 30 | R18: QC of Excavation | Z18: 0 | AB18: 1 | AC18: 0 | AD18: 0 | AF18: =SUMPRODUCT($K$17:$O$17,K18:O18) -> 0.89 | AG18: =SUMPRODUCT($Z$17:$AD$17,Z18:AD18) -> 0.79 | AV18: Item Count | AW18: Score | AX18: Distributtion
B19: 2 | C19: Document Control Administration | K19: 1 | M19: 0 | Q19: 31 | R19: QC of Roads/Round about | AB19: 1 | AC19: 0 | AF19: =SUMPRODUCT($K$17:$O$17,K19:O19) -> 1 | AG19: =SUMPRODUCT($Z$17:$AD$17,Z19:AD19) -> 0.79 | AX19: Overall | AY19: Relevant
B20: 3 | C20: Project Documents and Progress | K20: 1 | Q20: 32 | R20: QC of Interlock & Curbstone | AB20: 0 | AC20: 0 | AD20: 1 | AF20: =SUMPRODUCT($K$17:$O$17,K20:O20) -> 1 | AG20: =SUMPRODUCT($Z$17:$AD$17,Z20:AD20) -> 1 | AM20: 4 | AN20: =58 -> 58 | AO20: counts | AQ20: 4 | AR20: Excellent | AV20: =SUM(Z18:Z46,K18:K46) -> 3 | AW20: =AQ20*AV20 -> 12 | AX20: =AV20/$AV$25 -> 0.052631579 | AY20: =AV20/SUM($AV$20:$AV$23) -> 0.085714286
B21: 4 | C21: Contractor's Quality Plan/CM (Updated and Reviewed) | K21: 0 | M21: 1 | Q21: 33 | R21: Layers/Backfilling Sampling | Z21: 0 | AA21: 1 | AB21: 0 | AC21: 0 | AD21: 0 | AF21: =SUMPRODUCT($K$17:$O$17,K21:O21) -> 0.79 | AG21: =SUMPRODUCT($Z$17:$AD$17,Z21:AD21) -> 0.89 | AM21: 3 | AN21: =58 -> 58 | AO21: counts | AQ21: 3 | AR21: Good | AV21: =SUM(L18:L46,AA18:AA46) -> 12 | AW21: =AQ21*AV21 -> 36 | AX21: =AV21/$AV$25 -> 0.21052632 | AY21: =AV21/SUM($AV$20:$AV$23) -> 0.34285714
B22: 5 | C22: MS Log and Paperwork | L22: 1 | Q22: 34 | R22: Pump Stations Units | AD22: 1 | AF22: =SUMPRODUCT($K$17:$O$17,K22:O22) -> 0.89 | AG22: =SUMPRODUCT($Z$17:$AD$17,Z22:AD22) -> 1 | AM22: 2 | AN22: =58 -> 58 | AO22: counts | AQ22: 2 | AR22: Average | AV22: =SUM(M18:M46,AB18:AB46) -> 17 | AW22: =AQ22*AV22 -> 34 | AX22: =AV22/$AV$25 -> 0.29824561 | AY22: =AV22/SUM($AV$20:$AV$23) -> 0.48571429
B23: 6 | C23: RFI, FIR, & MIR Procedure | M23: 1 | Q23: 35 | R23: Quality of Form Work | AA23: 0 | AB23: 1 | AC23: 0 | AD23: 0 | AF23: =SUMPRODUCT($K$17:$O$17,K23:O23) -> 0.79 | AG23: =SUMPRODUCT($Z$17:$AD$17,Z23:AD23) -> 0.79 | AM23: 1 | AN23: =58 -> 58 | AO23: counts | AQ23: 1 | AR23: Improve | AV23: =SUM(N18:N46,AC18:AC46) -> 3 | AW23: =AQ23*AV23 -> 3 | AX23: =AV23/$AV$25 -> 0.052631579 | AY23: =AV23/SUM($AV$20:$AV$23) -> 0.085714286
B24: 7 | C24: RFI, FIR, & MIR Inventory system | L24: 1 | Q24: 36 | R24: Design Change List | AD24: 1 | AF24: =SUMPRODUCT($K$17:$O$17,K24:O24) -> 0.89 | AG24: =SUMPRODUCT($Z$17:$AD$17,Z24:AD24) -> 1 | AM24: 0 | AN24: =58 -> 58 | AO24: counts | AQ24: 0 | AR24: N/A | AV24: =SUM(O18:O46,AD18:AD46) -> 22 | AW24: =AQ24*AV24 -> 0 | AX24: =AV24/$AV$25 -> 0.38596491 | AY24: -
B25: 8 | C25: NCRs Control & Procedure | L25: 1 | M25: 0 | N25: 0 | Q25: 37 | R25: Quality of Concrete Placing | AA25: 0 | AB25: 0 | AC25: 0 | AD25: 1 | AF25: =SUMPRODUCT($K$17:$O$17,K25:O25) -> 0.89 | AG25: =SUMPRODUCT($Z$17:$AD$17,Z25:AD25) -> 1 | AR25: Total | AV25: =SUM(AV20:AV24) -> 57 | AW25: =SUM(AW20:AW24) -> 85 | AX25: =SUM(AX20:AX24) -> 1 | AY25: =SUM(AY20:AY24) -> 1
B26: 9 | C26: NCR Log | M26: 1 | Q26: 38 | R26: Concrete Surface Finishing | AA26: 0 | AB26: 0 | AC26: 0 | AD26: 1 | AF26: =SUMPRODUCT($K$17:$O$17,K26:O26) -> 0.79 | AG26: =SUMPRODUCT($Z$17:$AD$17,Z26:AD26) -> 1
B27: 10 | C27: MODON Standard* | K27: 0 | L27: 1 | Q27: 39 | R27: Pedestals/Columns/Beams Alignment | AA27: 0 | AD27: 1 | AF27: =SUMPRODUCT($K$17:$O$17,K27:O27) -> 0.89 | AG27: =SUMPRODUCT($Z$17:$AD$17,Z27:AD27) -> 1 | AV27: Maz Score Available: | AW27: =SUM(AV20:AV23)*AQ20 -> 140 | AX27: <- Excludes N/A items
B28: 11 | C28: Project Risk Plan/Management* | M28: 1 | Q28: 40 | R28: Siporex Lifting & Unloading | AD28: 1 | AF28: =SUMPRODUCT($K$17:$O$17,K28:O28) -> 0.79 | AG28: =SUMPRODUCT($Z$17:$AD$17,Z28:AD28) -> 1
B29: 12 | C29: Monthly Quality Reports* | L29: 0 | M29: 1 | O29: 0 | Q29: 41 | R29: Siporex Quality Pre-installation | AD29: 1 | AF29: =SUMPRODUCT($K$17:$O$17,K29:O29) -> 0.79 | AG29: =SUMPRODUCT($Z$17:$AD$17,Z29:AD29) -> 1
B30: 13 | C30: ITP | L30: 1 | O30: 0 | Q30: 42 | R30: Siporex Finishing Quality | AD30: 1 | AF30: =SUMPRODUCT($K$17:$O$17,K30:O30) -> 0.89 | AG30: =SUMPRODUCT($Z$17:$AD$17,Z30:AD30) -> 1 | AR30: Total Score | AW30: Percentage (%)
B31: 14 | C31: MODON Weekly Report | M31: 1 | N31: 0 | Q31: 43 | R31: Roads / Parking Markings | AC31: 0 | AD31: 1 | AF31: =SUMPRODUCT($K$17:$O$17,K31:O31) -> 0.79 | AG31: =SUMPRODUCT($Z$17:$AD$17,Z31:AD31) -> 1 | AN31: =MAX(AN20:AN24) -> 58 | AR31: =AW25 -> 85 | AW31: =SUM(100/AR33*AR31) -> 60.714286 | AY31: %
B32: 15 | C32: Design Change Official Paperwork* | O32: 1 | Q32: 44 | R32: QC of Finishing Outdoors | AC32: 0 | AD32: 1 | AF32: =SUMPRODUCT($K$17:$O$17,K32:O32) -> 0 | AG32: =SUMPRODUCT($Z$17:$AD$17,Z32:AD32) -> 1 | AR32: Max Score Available | BP32: 31
B33: 16 | C33: Design Change was Applied* | O33: 1 | Q33: 45 | R33: Quality of Finishing Indoors | AD33: 1 | AF33: =SUMPRODUCT($K$17:$O$17,K33:O33) -> 0 | AG33: =SUMPRODUCT($Z$17:$AD$17,Z33:AD33) -> 1 | AR33: =AW27 -> 140 | BP33: 32
B34: 17 | C34: Material List | K34: 0 | L34: 1 | O34: 0 | Q34: 46 | R34: Stairs Quality | AD34: 1 | AF34: =SUMPRODUCT($K$17:$O$17,K34:O34) -> 0.89 | AG34: =SUMPRODUCT($Z$17:$AD$17,Z34:AD34) -> 1 | BP34: 33
B35: 18 | C35: Pending Material Status | L35: 0 | M35: 0 | N35: 1 | O35: 0 | Q35: 47 | R35: Tanks Method Statement Work | AB35: 0 | AC35: 0 | AD35: 1 | AF35: =SUMPRODUCT($K$17:$O$17,K35:O35) -> 0.69 | AG35: =SUMPRODUCT($Z$17:$AD$17,Z35:AD35) -> 1 | BP35: 34
B36: 19 | C36: Lifting Plan* | K36: 0 | L36: 0 | M36: 1 | O36: 0 | Q36: 48 | R36: Electric Rooms | AD36: 1 | AF36: =SUMPRODUCT($K$17:$O$17,K36:O36) -> 0.79 | AG36: =SUMPRODUCT($Z$17:$AD$17,Z36:AD36) -> 1 | BP36: 35
B37: 20 | C37: DWG Log | L37: 1 | Q37: 49 | R37: QC of MCC/ATS Plant Units | AD37: 1 | AF37: =SUMPRODUCT($K$17:$O$17,K37:O37) -> 0.89 | AG37: =SUMPRODUCT($Z$17:$AD$17,Z37:AD37) -> 1 | BP37: 36
B38: 21 | C38: Invoice Status | K38: 0 | L38: 0 | O38: 1 | Q38: 50 | R38: Qualified Subcontractor | AB38: 1 | AD38: 0 | AF38: =SUMPRODUCT($K$17:$O$17,K38:O38) -> 0 | AG38: =SUMPRODUCT($Z$17:$AD$17,Z38:AD38) -> 0.79 | BP38: 37
B39: 22 | C39: Site Handover Letter | K39: 1 | O39: 0 | Q39: 51 | R39: Scaffold/Ladders/Slope/Bridge Compliance | AD39: 1 | AF39: =SUMPRODUCT($K$17:$O$17,K39:O39) -> 1 | AG39: =SUMPRODUCT($Z$17:$AD$17,Z39:AD39) -> 1 | BP39: 38
B40: 23 | C40: Material Testing Results & Certification | L40: 1 | N40: 0 | Q40: 52 | R40: Protection Applied to Completed Work | AA40: 0 | AB40: 1 | AC40: 0 | AD40: 0 | AF40: =SUMPRODUCT($K$17:$O$17,K40:O40) -> 0.89 | AG40: =SUMPRODUCT($Z$17:$AD$17,Z40:AD40) -> 0.79
B41: 24 | C41: As Build Drawings Status* | N41: 0 | O41: 1 | Q41: 53 | R41: Storage Management in/out Control | AA41: 1 | AC41: 0 | AF41: =SUMPRODUCT($K$17:$O$17,K41:O41) -> 0 | AG41: =SUMPRODUCT($Z$17:$AD$17,Z41:AD41) -> 0.89
B42: 25 | C42: Calibrated Lab Tools & Equipment | L42: 1 | M42: 0 | N42: 0 | O42: 0 | Q42: 54 | R42: Material Control | AC42: 0 | AD42: 0 | AF42: =SUMPRODUCT($K$17:$O$17,K42:O42) -> 0.89 | AG42: =SUMPRODUCT($Z$17:$AD$17,Z42:AD42) -> 0
B43: 26 | C43: Storage Inventory System | L43: 0 | N43: 1 | O43: 0 | Q43: 55 | R43: Manholes Storing and Quality | AB43: 1 | AF43: =SUMPRODUCT($K$17:$O$17,K43:O43) -> 0.69 | AG43: =SUMPRODUCT($Z$17:$AD$17,Z43:AD43) -> 0.79
B44: 27 | C44: Logistics Plan | M44: 1 | O44: 0 | Q44: 56 | R44: Reinforced Steel Quality | AB44: 0 | AC44: 0 | AD44: 1 | AF44: =SUMPRODUCT($K$17:$O$17,K44:O44) -> 0.79 | AG44: =SUMPRODUCT($Z$17:$AD$17,Z44:AD44) -> 1
B45: 28 | C45: Project Progress Planview | M45: 1 | N45: 0 | O45: 0 | Q45: 57 | R45: Safety Overview | Z45: 0 | AA45: 0 | AB45: 1 | AC45: 0 | AF45: =SUMPRODUCT($K$17:$O$17,K45:O45) -> 0.79 | AG45: =SUMPRODUCT($Z$17:$AD$17,Z45:AD45) -> 0.79
B46: 29 | C46: Sufficient Number of QC Inspectors | L46: 0 | N46: 1 | O46: 0 | Q46: 58 | R46: Waste Management Control | Z46: 0 | AB46: 1 | AD46: 0 | AF46: =SUMPRODUCT($K$17:$O$17,K46:O46) -> 0.69 | AG46: =SUMPRODUCT($Z$17:$AD$17,Z46:AD46) -> 0.79
...

Sheet Quality-Stat
A1: Quality -Stat
A2: Quality Reports
A3: Item | C3: Issued | D3: Closed | E3: Pending | F3: Avg. Closing (Days) | G3: Pending
G4: 0-10 Days | H4: 11-20 Days | I4: 21-30 Days | J4: 31-60 Days | K4: > 60 Days
A6: Non Conforomance Report (NCR) | C6: 16 | D6: 13 | E6: 3 | G6: 3 | Q6: 34
A7: Site Instruction (SI) | C7: 5 | D7: 5 | E7: 0 | G7: 0 | H7: 0
A8: Material Inspection Report (MIR) | C8: 196 | D8: 190 | E8: 6 | G8: 6
A9: Field Inspection Request (FIR) | C9: 3182 | D9: 3080 | E9: 102 | G9: 102 | H9: 0 | I9: -
A11: Shop Drawings
A12: Item Per WBS | D12: Total Drawings | E12: Total Drawings Submitted | H12: =H55 -> 0 | I12: =I55 -> 0 | J12: Remaining Drawings | K12: Pending | L12: Total Submittals
E13: A | F13: B | G13: C | H13: D | I13: Processed | J13: with Designer | K13: Submittals With Consultant
A14: Road work/Structural | D14: 130 | E14: 28 | F14: 102 | G14: 0 | H14: 0 | I14: =E14+F14 -> 130 | J14: 0 | K14: 0 | L14: =SUM(E14:F14)+K14 -> 130
A15: wet network(sewer,storm,potable,irrigation) | D15: 140 | E15: 22 | F15: 118 | G15: 0 | H15: 0 | I15: =E15+F15 -> 140 | J15: 0 | K15: 4 | L15: =SUM(E15:F15)+K15 -> 144
A16: Telecom,Street light | D16: 107 | E16: 4 | F16: 103 | G16: 0 | H16: 0 | I16: =E16+F16 -> 107 | J16: =D16-L16 -> 0 | K16: 0 | L16: =SUM(E16:F16)+K16 -> 107
A17: Landscape | C17: Mechanical | D17: 22 | E17: 3 | F17: 4 | G17: 15 | H17: 0 | I17: =E17+F17 -> 7 | K17: 0 | L17: =SUM(E17:F17)+K17 -> 7
A18: CCTV | C18: Electrical | D18: 12 | E18: 0 | F18: 12 | G18: 0 | H18: 0 | I18: =E18+F18 -> 12 | J18: =D18-L18 -> 0 | K18: 0 | L18: =SUM(E18:F18)+K18 -> 12
A19: TOTAL | D19: =SUM(D14:D18) -> 411 | E19: =SUM(E14:E18) -> 57 | F19: =SUM(F14:F18) -> 339 | G19: =SUM(G14:G18) -> 15 | H19: =SUM(H14:H18) -> 0 | I19: =SUM(I14:I18) -> 396 | J19: =SUM(J14:J18) -> 0 | K19: =SUM(K14:K18) -> 4 | L19: =SUM(L14:L18) -> 400
A22: Material Approval
A23: Item Per WBS | D23: Total | E23: Total Materials Submitted | J23: Remaining to approve | K23: Pending | L23: Total Submittals
E24: A | F24: B | G24: C | H24: D | I24: Processed | J24: with Designer | K24: Submittals With Consultant
A25: Civil /Structural /Architectural | D25: 25 | E25: 0 | F25: 20 | G25: 0 | H25: 1 | I25: 20 | J25: 4 | K25: 0 | L25: =SUM(E25:H25)+K25 -> 21 | N25: 34162 | O25: =N25*0.95 -> 32453.9
A26: Mechanical | C26: Mechanical | D26: 14 | E26: 0 | F26: 14 | G26: 0 | H26: 0 | I26: =E26+F26+G26+H26 -> 14 | J26: 0 | K26: - | L26: =E26+F26+G26+J26 -> 14 | N26: 22140 | O26: =N26*0.95 -> 21033
A27: Electrical | C27: Electrical | D27: 21 | E27: 1 | F27: 17 | G27: 0 | H27: 3 | I27: =E27+F27+G27+H27 -> 21 | J27: 0 | K27: 0 | L27: {=E27+F27+G27:H27+J27} -> 18 | M27: 21 | N27: 4500 | O27: =N27*0.95 -> 4275
A28: TOTAL | D28: =SUM(D25:D27) -> 60 | E28: =SUM(E25:E27) -> 1 | F28: =SUM(F25:F27) -> 51 | G28: =SUM(G25:G27) -> 0 | H28: =SUM(H25:H27) -> 4 | I28: =SUM(I25:I27) -> 55 | J28: =SUM(J25:J27) -> 4 | K28: =SUM(K25:K27) -> 0 | L28: =SUM(L25:L27) -> 53 | N28: 51500 | O28: =N28*0.95 -> 48925
A30: Procurement Summary
A31: Item Per WBS | D31: Total Materials | E31: Total Number of P.O. | F31: Actual P.O. To Date | G31: Remaining P.O | H31: Actual Material on Site | I31: Remaining Materials | J31: Material Delivery Completion (Date)
E32: A | F32: B | G32: C | H32: D | I32: Processed
A33: Civil /Structural /Architectural | D33: 16 | E33: 16 | F33: 10 | G33: =E33-F33 -> 6 | H33: 7 | I33: =D33-H33 -> 9 | J33: -
A34: Mechanical | C34: Mechanical | D34: 75 | E34: 59 | F34: 59 | G34: 17 | H34: 23 | I34: =D34-H34 -> 52 | J34: -
A35: Electrical | C35: Electrical | D35: 20 | E35: 14 | F35: 14 | G35: 6 | H35: 4 | I35: 16 | J35: -
A36: TOTAL | D36: =SUM(D33:D35) -> 111 | E36: =SUM(E33:E35) -> 89 | F36: =SUM(F33:F35) -> 83 | G36: =SUM(G33:G35) -> 29 | H36: =SUM(H33:H35) -> 34 | I36: =SUM(I33:I35) -> 77
A38: Consultant Quality Inspections / Observations (Weekly Basis) | I38: Overall Average | J38: - | L38: Average Closing | M38: -
A39: Week Number | B39: Date of Audit | C39: 46056 | D39: Numbers Of Comments | E39: Quality Score | F39: Date Closed | G39: Closure Duration | I39: This Week Score | J39: - | L39: Average Number of Comments Per Audit | M39: -

Sheet HSE-Stat 
A1: Safety Statistics
A3: Category | B3: Item | D3: This Week | E3: This Month | F3: Year to Date | G3: Cumulative
A4: Category | B4: Total Hours Worked | D4: 36000 | E4: 122940 | F4: 790456 | G4: 490456
B5: Safe Hours Worked | D5: 36000 | E5: 122940 | F5: 790456 | G5: 490456
B6: No.of Internal Training | D6: 1 | E6: 4 | F6: 52 | G6: 52
B7: No.of Internal Audit
B8: No. of Toolbox Talks | D8: 1 | E8: 4 | F8: 38 | G8: 38
B9: Safety Awards/Incentives
I10: Category | J10: Item | L10: This Week | M10: This Month | N10: Year to Date | O10: Cumulative
A12: Consultant Safety Inspection (Weekly Basis) | I12: Overall Average | J12: =E24 -> 0.807
A13: Week Number | B13: Date of Audit | C13: Date Issued | D13: Numbers Of Comments | E13: Overall Score | F13: Date Closed | G13: Closure Duration | I13: This Week Score | J13: =E24 -> 0.807
A14: Week-1 | B14: 46084 | C14: 46084 | D14: 6 | E14: 0.78 | F14: 46088 | G14: 4
A15: Week-2 | B15: 46091 | C15: 46091 | D15: 5 | E15: 0.78 | F15: 46095 | G15: 4
A16: Week-3 | B16: 46098 | C16: 46098 | D16: 5 | E16: 0.8 | F16: 46101 | G16: 3
A17: Week-4 | B17: 46105 | C17: 46105 | D17: 7 | E17: 0.8 | F17: 46107 | G17: 2
A18: Week-5 | B18: 46112 | C18: 46112 | D18: 5 | E18: 0.8 | F18: 46114 | G18: 2
A19: Week-6 | B19: 46119 | C19: 46119 | D19: 5 | E19: 0.8 | F19: 46121 | G19: 2
A20: Week-7 | B20: 46126 | C20: 46126 | D20: 6 | E20: 0.8 | F20: 46128 | G20: 0
A21: Week-8 | B21: 46133 | C21: 46133 | D21: 6 | E21: 0.8 | F21: 46136 | G21: 0
A22: Week-9 | B22: 46133 | C22: 46140 | D22: 0 | E22: 0.807 | F22: 46144 | G22: 0
A23: Week-10 | B23: 46174 | C23: 46179 | D23: 0 | E23: 0.807 | F23: 46179 | G23: 0
A24: Week-11 | B24: 46182 | C24: 46182 | D24: 0 | E24: 0.807 | F24: 46182 | G24: 0
A25: Week-12 | B25: 46188 | C25: 46188 | D25: 0 | E25: 0.807 | F25: 46188 | G25: 0
... A40: Week-27 | B40: 46293 | C40: 46293 | D40: 0 | E40: 0.807 | F40: 46293 | G40: 0
A41: Week-28 | D41: 0 | E41: 0 | G41: 0
A42: Week-29 | D42: 0 | E42: 0 | G42: 0

Sheet HSE. 
B1: MODON HSE Site Inspection Report
B2: Date | E2: ='General Information'!L1 -> 46293 | L2: Inspected By: | T2: Engr Ayman Sabry
B4: Project ID. | E4: SUD1-02-011 | L4: Report No. | W4: MODON PM Name | Y4: Engr.Ziyad Al Shabbat
B6: Project Name: | E6: Infrastructure Network Development Project in Sudair City for Industry and Business - Phase Two - Part Two | L6: Contractor: | R6: TECHNICAL DEVELOPMENT CONTRACTING CO. | X6: Safety Performance | AA6: =IF(W29>0,3,IF(L29>6,2,IF(D29>0,2,1)*1)*1) -> 2 | AE6: =(((COUNTIF(L13:Q25,"1")+COUNTIF(AC13:AH25,"1"))*AR13)+(COUNTIF(L13:Q25,"2")+COUNTIF(AC13:AH25,"2"))*AR14+(COUNTIF(L13:Q25,"3")+COUNTIF(AC13:AH25,"3"))*AR15)/((COUNT(L13:Q25)+COUNT(AC13:AH25))*100) -> 0.81818182
B8: Inspections are a snapshot in time and refer only to the practices and documentation observed at the time of the Inspection. It remains the responsibility of the Consultant and Contractor to ensure that all aspects of Health & Safety are suitably managed.
B9: 1 | D9: Good Practice | H9: 2 | I9: Need Improvement | T9: 3 | U9: Fail (Life Threatening Activity) / Comliance with Plan & Procedures | X9: N/A | Y9: Atcitty Not Applicable for this Site Inspection Report
B11: No. | C11: Topic | K11: Wt. | L11: HSE Compliance | S11: No. | T11: Topic | AB11: Wt. | AC11: HSE Compliance
B13: 1 | C13: Access and Egress - (General access to site, segregated from vehicles, / Overhead protection, while entering into the building /Adequate lighting provided when dark or overnight work) | K13: 0.05 | L13: 2 | S13: 14 | T13: Work at Height - (PPE/Fall Protection(Same level, above and blow) / Training / Fall restraint / competency /Safe access & egress to and from work at height / Ladders / Openings (floor/shafts/Provision of emergency rescue) | AB13: 0.05 | AC13: N/A | AP13: 1 | AR13: 100 | AU13: 1
B14: 2 | C14: Traffic Management - (Loading/unloading/sheeting/temp. routes/speed/parking/competence) | K14: 0.03 | L14: 2 | S14: 15 | T14: Scaffolding - (Temp. Scaffolding Work-platform (All types) - qualified scaffolder / Inspection / Tagged / Safe Access/egress / PTW/Falsework & Formwork) | AB14: 0.04 | AC14: N/A | AP14: 2 | AR14: 75 | AU14: 2
B15: 3 | C15: Site Signage - (Project Notice Board & General Signage) | K15: 0.02 | L15: 2 | S15: 16 | T15: Mobile Elevated Work platform (MEWP) - (PTW/competence requirements/conditions/inspections/tagged/training/Full-body harness) | AB15: 0.04 | AC15: N/A | AP15: 3 | AR15: 0 | AU15: 3
B16: 4 | C16: PPE Compliance - (Use, storage, stock, handling & checks - Head, Foot, Eye, Hearing) | K16: 0.05 | L16: 2 | S16: 17 | T16: Excavation & Trenches - (PTW/Edge protection/buffer zone/Slope/Benching/Shoring/Geo-tech report/Atmospheric hazards/Acess&egress/Emergency management / MS&RA/H.E) | AB16: 0.03 | AC16: 2 | AU16: N/A
B17: 5 | C17: Housekeeping - (Material correctly stored/Rubbish cleaned & removed daily/slips & trips hazards) | K17: 0.03 | L17: 2 | S17: 18 | T17: Confined Space - (PTW/Training/competence/Emergency Management/MS & RA/Safe access/egress) | AB17: 0.05 | AC17: 2
B18: 6 | C18: Storage of Materials - (Transporting, storage, training and use - Combustible / Flammable / Hazardous substances (COSHH) | L18: 1 | S18: 19 | T18: Fire Protection - (Flammable/Oxy. LPG /Combustible separated/FE's/Flashback arrestor/Sparks & slags/Smoking area/PTW/Generators/MS & RA/Emergency Management) | AC18: 2 | AL18: Red | AM18: Serious injury or death (immediately)
B19: 7 | C19: Site Waste Management - (Hazardous waste /Combustible waste / Human waste / Construction waste - asphalt, cable, timber, paving roof sheeting tiles, plastic & bricks) | L19: 1 | S19: 20 | T19: Health & Welfare - (Adequate drinking water/shaded - eating & rest area/washing & sanitary facilities/Certified FA/FA Box & Stock/adequate toilets/Ambulance) | AC19: 2 | AL19: Yellow | AM19: Minor or near miss (3 days to comply)
B20: 8 | C20: Health Surveillance - (Expose to excessive noise/vibration/dust/silica/CO/cement/radiation/extreme weather condition) | K20: 0.03 | L20: 1 | S20: 21 | T20: Environmental Incident Measures - (Spill/ Leakage / Concrete wash / vehicle & eqpts. wash / waste disposal/Sewers and drains/emissions/Emergency Management/Training/site run-off water) | AB20: 0.05 | AC20: 2 | AL20: Green | AM20: No issues
B21: 9 | C21: Electrical Safety - (Electrical qualified /RCD/GFCI/Industrial Cocket/LOTO/Cable-overhung or buried/Cords in good condition/current inspection tag) | K21: 0.05 | L21: 1 | S21: 22 | T21: HSE Communications & Meetings - (Schedule HSE Meetings/Safety Committee meetings/Alerts / Lesson learned/Safety Bulletin contains latest HSE KPI) | AB21: 0.05 | AC21: 2
B22: 10 | C22: Tools & Equipment - (Includes, powered, hydraulic & pneumatic/Guards in place/Properly stored/RCD Protection/Earthed/Good condition & tagged) | K22: 0.03 | L22: 1 | S22: 23 | T22: HSE Plan & Associated Procedures - (Approved updated HSE Plan/ CEMP/HAZComm/Procedures/Standards/Project Safety Risk Register) | AB22: 0.03 | AC22: 2 | AL22: 26 points > 4 minors then is it’s a serious issue
B23: 11 | C23: Manual Handling - (Lifting/loading/pulling/pushing/twisting/awkward posture/repetitive task/frequent and prolong physical effort/Reasonable practicable use of mechanical aid) | K23: 0.03 | L23: 1 | S23: 24 | T23: Health, Safety & Environment Incident reporting - (Review of HSE Statistics, Reporting of Unsafe Act & Conditions/ Reporting of Near Miss incident/Reporting of FA cases/Record MT cases) | AB23: 0.03 | AC23: 2
B24: 12 | C24: Vehicle and mobile equipment / Plant - (dumpers; excavators, cranes, piling rigs, grader, roller, loaders/condition/KSA License/certification) | K24: 0.05 | L24: 2 | S24: 25 | T24: HSE Awareness, Training & Competence - (Policy /Objective & targets/Information, training/Climatic condition awareness/Reponses in emergency situation/ Safety Behavior Observation) | AB24: 0.04 | AC24: 2
B25: 13 | C25: Lifting Operations & Rigging - (Lifting Plan/Lifting devices & gears/PTW/Condition/3rd party certification/bank-man/rigger/slingers/man-basket/inspection record/tagged) | L25: N/A | S25: 26 | T25: Project Leadership Site Tours - (Provide evidence of proactive safety performance/Deficient discovered discussed/Positive feedback/Workers resolving safety issues) | AC25: 2
B27: Prepared by: | G27: Abdul kalim | S27: Sent to MODON PM: | X27: Engr.Ziyad Al Shabbat
B28: Safety Results
B29: 1 | D29: =COUNTIF(L13:Q26,"1")+COUNTIF(AB13:AG26,"1") -> 6 | I29: 2 | L29: =COUNTIF(L13:Q26,"2")+COUNTIF(AB13:AG26,"2") -> 16 | U29: 3 | W29: =COUNTIF(L13:Q26,"3")+COUNTIF(AB13:AG26,"3") -> 0

