Workbook
Name _1B.05.M.010.0010: #REF!
Name _1B.05.M.010.0010: #REF!
Name _1B.05.M.010.0010: #REF!
Name _1B.05.M.010.0050: #REF!
Name _1B.05.M.010.0050: #REF!
Name _1B.05.M.010.0050: #REF!
Name _1B.05.M.0100.0010: #REF!
Name _1B.05.M.0100.0010: #REF!
Name _1B.05.M.020.0010: #REF!
Name _1B.05.M.020.0010: #REF!
Name _1B.05.M.020.0020: #REF!
Name _1B.05.M.020.0020: #REF!
Name _1B.05.M.020.0030: #REF!
Name _1B.05.M.020.0030: #REF!
Name _1B.05.M.020.0040: #REF!
Name _1B.05.M.020.0040: #REF!
Name _1B.05.M.030.0010: #REF!
Name _1B.05.M.030.0010: #REF!
Name _1B.05.M.030.0020: #REF!
Name _1B.05.M.030.0020: #REF!
Name _1B.05.M.040.0010: #REF!
Name _1B.05.M.040.0010: #REF!
Name _1B.05.M.050.0010: #REF!
Name _1B.05.M.050.0010: #REF!
Name _1B.05.M.050.0020: #REF!
Name _1B.05.M.050.0020: #REF!
Name _1B.05.M.050.0030: #REF!
Name _1B.05.M.050.0030: #REF!
Name _1B.05.M.060.0020: #REF!
Name _1B.05.M.060.0020: #REF!
Name _1B.05.M.060.0100: #REF!
Name _1B.05.M.060.0100: #REF!
Name _1B.05.M.070.0010: #REF!
Name _1B.05.M.070.0010: #REF!
Name _1B.05.M.070.0020: #REF!
Name _1B.05.M.070.0020: #REF!
Name _1B.05.M.070.0030: #REF!
Name _1B.05.M.070.0030: #REF!
Name _1B.05.M.070.0040: #REF!
Name _1B.05.M.070.0040: #REF!
Name _1B.05.M.070.0050: #REF!
Name _1B.05.M.070.0050: #REF!
Name _1B.05.M.080.0010: #REF!
Name _1B.05.M.080.0010: #REF!
Name _1B.05.M.090.0010: #REF!
Name _1B.05.M.090.0010: #REF!
Name _1B.09.P.010.0010: #REF!
Name _1B.09.P.010.0010: #REF!
Name _1B.09.P.010.0020: #REF!
Name _1B.09.P.010.0020: #REF!
Name _1B.09.P.010.0030: #REF!
Name _1B.09.P.010.0030: #REF!
Name _1B.09.P.010.0040: #REF!
Name _1B.09.P.010.0040: #REF!
Name _1B.09.P.010.0050: #REF!
Name _1B.09.P.010.0050: #REF!
Name _1B.09.P.010.0060: #REF!
Name _1B.09.P.010.0060: #REF!
Name _1B.09.P.010.0070: #REF!
Name _1B.09.P.010.0070: #REF!

Sheet DB
A1: ='Weekly Progress Report'!$A$1 -> MODON - Weekly Progress Report - Construction Projects
B2: ='Weekly Progress Report'!$A$2 -> Contract General Information | J2: ='Weekly Progress Report'!G2 -> Key Dates | U2: ='Weekly Progress Report'!$M$2 -> Cost Summary (SR) | AD2: ='Weekly Progress Report'!$U$2 -> Performance Summary | AP2: ='Weekly Progress Report'!A52 -> Shop Drawings | AT2: ='Weekly Progress Report'!A62 -> Material Approval | AW2: ='Weekly Progress Report'!A71 -> Procurement Summary | BD2: ='Weekly Progress Report'!L52 -> Quality Reports | BT2: ='Weekly Progress Report'!L61 -> Key Submittals Approval Status | CD2: ='Weekly Progress Report'!L67 -> Invoices Summary | CR2: ='Weekly Progress Report'!L75 -> Resources at Site | CY2: ='Weekly Progress Report'!W52 -> Safety Statistics | FK2: ='Weekly Progress Report'!A80 -> Primavera P6 Schedule Status | FS2: ='Weekly Progress Report'!A93 -> Weekly Prgoress Photos
A3: ='Weekly Progress Report'!AF1 -> Data Date | B3: ='Weekly Progress Report'!A3 -> Project Name | C3: ='Weekly Progress Report'!A4 -> Project ID | D3: ='Weekly Progress Report'!A5 -> Contractor | E3: ='Weekly Progress Report'!A6 -> Consultant | F3: ='Weekly Progress Report'!D4 -> Stage | G3: ='Weekly Progress Report'!D5 -> Status | H3: ='Weekly Progress Report'!D6 -> Modon PM | I3: ='Weekly Progress Report'!AA2 -> Project Scope | J3: ='Weekly Progress Report'!G3 -> Contract Award | K3: ='Weekly Progress Report'!G4 -> Contract Sign | L3: ='Weekly Progress Report'!G5 -> Site Handover | M3: ='Weekly Progress Report'!G6 -> Original Completion | N3: ='Weekly Progress Report'!$I$3 -> Contract Award (Hijri) | O3: ='Weekly Progress Report'!$I$4 -> Contract Sign (Hijri) | P3: ='Weekly Progress Report'!$I$5 -> Site Handover (Hijri) | Q3: ='Weekly Progress Report'!$I$6 -> Original Completion (Hijri) | R3: ='Weekly Progress Report'!$K$3 -> Revised Completion | S3: ='Weekly Progress Report'!$K$4 -> Committed Completion | T3: ='Weekly Progress Report'!$K$5 -> Forecast Completion | U3: ='Weekly Progress Report'!$M$3 -> Original Contract Value | V3: ='Weekly Progress Report'!$M$4 -> Revised Contract Value | W3: ='Weekly Progress Report'!$M$5 -> Estimate At Completion Value | X3: ='Weekly Progress Report'!$M$6 -> Potential Changes | Y3: ='Weekly Progress Report'!$Q$3 -> O&M Value (if any) | Z3: ='Weekly Progress Report'!$Q$4 -> Submitted Invoices (Gross Value) | AA3: ='Weekly Progress Report'!$Q$5 -> Penalities | AB3: ='Weekly Progress Report'!$Q$6 -> FIR Value (THIS WEEK) | AC3: Original Plan Value | AD3: ='Weekly Progress Report'!$U$3 -> Plan Value | AE3: ='Weekly Progress Report'!$U$4 -> Earn Value | AF3: ='Weekly Progress Report'!$W$3 -> Phys. Plan Value | AG3: ='Weekly Progress Report'!$W$4 -> Phys. Earn Value | AH3: ='Weekly Progress Report'!$Y$3 -> Quality Score | AI3: ='Weekly Progress Report'!$Y$5 -> Safety Score | AJ3: Weekly PV (SAR) | AK3: Weekly EV (SAR) | AL3: Weekly PV % | AM3: Weekly PV % | AN3: Weekly Phys PV% | AO3: Weekly Phys PV% | AP3: Total SD Planned | AQ3: SD Remaining | AR3: SD Pending | AS3: Total SD Submittals | AT3: Planned Materials Approv | AU3: Material Pending Approval | AV3: Materila Total Submittals | AW3: ='Weekly Progress Report'!C72 -> Total Materials | AX3: ='Weekly Progress Report'!D72 -> Total Number of P.O. | AY3: ='Weekly Progress Report'!E72 -> Actual P.O. To Date | AZ3: ='Weekly Progress Report'!F72 -> Remaining P.O | BA3: ='Weekly Progress Report'!G72 -> Material on Site | BB3: ='Weekly Progress Report'!H72 -> Remaining Materials | BC3: ='Weekly Progress Report'!I72 -> Material Delivery Completion (Date) | BD3: ="NCR "&'Weekly Progress Report'!N53 -> NCR Issued | BE3: ="NCR "&'Weekly Progress Report'!O53 -> NCR Closed | BF3: ="NCR "&'Weekly Progress Report'!P53 -> NCR Pending | BG3: ="NCR "&'Weekly Progress Report'!Q53 -> NCR Avg. Closing (Days) | BH3: ="SIR "&'Weekly Progress Report'!N53 -> SIR Issued | BI3: ="SIR "&'Weekly Progress Report'!O53 -> SIR Closed | BJ3: ="SIR "&'Weekly Progress Report'!P53 -> SIR Pending | BK3: ="SIR "&'Weekly Progress Report'!Q53 -> SIR Avg. Closing (Days) | BL3: ="MIR "&'Weekly Progress Report'!N53 -> MIR Issued | BM3: ="MIR "&'Weekly Progress Report'!O53 -> MIR Closed | BN3: ="MIR "&'Weekly Progress Report'!P53 -> MIR Pending | BO3: ="MIR "&'Weekly Progress Report'!Q53 -> MIR Avg. Closing (Days) | BP3: ="FIR "&'Weekly Progress Report'!N53 -> FIR Issued | BQ3: ="FIR "&'Weekly Progress Report'!O53 -> FIR Closed | BR3: ="FIR "&'Weekly Progress Report'!P53 -> FIR Pending | BS3: ="FIR "&'Weekly Progress Report'!Q53 -> FIR Avg. Closing (Days) | BT3: ='Weekly Progress Report'!L62 -> 1 Quality Plan Approval | BU3: ='Weekly Progress Report'!L63 -> 2 Quality Plan Last Up | BV3: ='Weekly Progress Report'!L64 -> 3 Safety Plan Approval | BW3: ='Weekly Progress Report'!L65 -> 4 Safety Plan Last Up | BX3: ='Weekly Progress Report'!L66 -> 5 Construction Plan Approval | BY3: ='Weekly Progress Report'!Q62 -> 6 Baseline Approval | BZ3: ='Weekly Progress Report'!Q63 -> 7 No of Approved Version of Schedule | CA3: ='Weekly Progress Report'!Q64 -> 8 Last Approved Schedule | CB3: ='Weekly Progress Report'!Q65 -> 9 BOQ Approval Date | CC3: ='Weekly Progress Report'!Q66 -> 10 No of Approved Version of BOQ | CD3: ='Weekly Progress Report'!L68 -> Total Submitted Invoices | CE3: ='Weekly Progress Report'!L69 -> PM Approved Invoices | CF3: ='Weekly Progress Report'!L70 -> No of Paid Invoices | CG3: ='Weekly Progress Report'!L71 -> No of Pending Invoices | CH3: ='Weekly Progress Report'!L72 -> Advance Payment % | CI3: ='Weekly Progress Report'!L73 -> Retention % | CJ3: ='Weekly Progress Report'!L74 -> Deduction / Penalties % | CK3: ='Weekly Progress Report'!O68 -> Submitted Invoices (SAR) | CL3: ='Weekly Progress Report'!O69 -> PM Approved Invoices (SAR) | CM3: ='Weekly Progress Report'!O70 -> Paid Invoices (SAR) | CN3: ='Weekly Progress Report'!O71 -> Last Submitted Period | CO3: ='Weekly Progress Report'!O72 -> Advance Payment (SAR) | CP3: ='Weekly Progress Report'!O73 -> Retention (SAR) | CQ3: ='Weekly Progress Report'!O74 -> Deduction / Penalties (SAR) | CR3: Planned Head Count | CS3: Actual Head Count | CT3: Saudi Staff | CU3: Labor Planned | CV3: Labor Actual | CW3: Equipment Planned | CX3: Equipment Actual | CY3: ="This Week "&'Weekly Progress Report'!X55 -> This Week Total Hours Worked | CZ3: ="This Week "&'Weekly Progress Report'!X56 -> This Week Safe Hours Worked | DA3: ="This Week "&'Weekly Progress Report'!X57 -> This Week LTI | DB3: ="This Week "&'Weekly Progress Report'!X58 -> This Week MTC (Healed w/o Disability) | DC3: ="This Week "&'Weekly Progress Report'!X60 -> This Week MTC (Healed w/ Disability) | DD3: ="This Week "&'Weekly Progress Report'!X61 -> This Week Near Miss | DE3: ="This Week "&'Weekly Progress Report'!X62 -> This Week First Aid Cases | DF3: ="This Week "&'Weekly Progress Report'!X63 -> This Week Fatality | DG3: ="This Week "&'Weekly Progress Report'!X64 -> This Week Fire Incident Cases | DH3: ="This Week "&'Weekly Progress Report'!X65 -> This Week Vehicle Incident | DI3: ="This Week "&'Weekly Progress Report'!X66 -> This Week Property Damages | DJ3: ="This Week "&'Weekly Progress Report'!X67 -> This Week Induction Training | DK3: ="This Week "&'Weekly Progress Report'!X68 -> This Week No.of Internal Training | DL3: ="This Week "&'Weekly Progress Report'!X69 -> This Week No.of Internal Audit | DM3: ="This Week "&'Weekly Progress Report'!X70 -> This Week No. of Toolbox Talks | DN3: ="This Week "&'Weekly Progress Report'!X71 -> This Week Safety Awards/Incentives | DO3: ="This Month "&'Weekly Progress Report'!X55 -> This Month Total Hours Worked | DP3: ="This Month "&'Weekly Progress Report'!X56 -> This Month Safe Hours Worked | DQ3: ="This Month "&'Weekly Progress Report'!X57 -> This Month LTI | DR3: ="This Month "&'Weekly Progress Report'!X58 -> This Month MTC (Healed w/o Disability) | DS3: ="This Month "&'Weekly Progress Report'!X60 -> This Month MTC (Healed w/ Disability) | DT3: ="This Month "&'Weekly Progress Report'!X61 -> This Month Near Miss | DU3: ="This Month "&'Weekly Progress Report'!X62 -> This Month First Aid Cases | DV3: ="This Month "&'Weekly Progress Report'!X63 -> This Month Fatality | DW3: ="This Month "&'Weekly Progress Report'!X64 -> This Month Fire Incident Cases | DX3: ="This Month "&'Weekly Progress Report'!X65 -> This Month Vehicle Incident | DY3: ="This Month "&'Weekly Progress Report'!X66 -> This Month Property Damages | DZ3: ="This Month "&'Weekly Progress Report'!X67 -> This Month Induction Training | EA3: ="This Month "&'Weekly Progress Report'!X68 -> This Month No.of Internal Training | EB3: ="This Month "&'Weekly Progress Report'!X69 -> This Month No.of Internal Audit | EC3: ="This Month "&'Weekly Progress Report'!X70 -> This Month No. of Toolbox Talks | ED3: ="This Month "&'Weekly Progress Report'!X71 -> This Month Safety Awards/Incentives | EE3: ="YTD "&'Weekly Progress Report'!X55 -> YTD Total Hours Worked | EF3: ="YTD "&'Weekly Progress Report'!X56 -> YTD Safe Hours Worked | EG3: ="YTD "&'Weekly Progress Report'!X57 -> YTD LTI | EH3: ="YTD "&'Weekly Progress Report'!X58 -> YTD MTC (Healed w/o Disability) | EI3: ="YTD "&'Weekly Progress Report'!X60 -> YTD MTC (Healed w/ Disability) | EJ3: ="YTD "&'Weekly Progress Report'!X61 -> YTD Near Miss | EK3: ="YTD "&'Weekly Progress Report'!X62 -> YTD First Aid Cases | EL3: ="YTD "&'Weekly Progress Report'!X63 -> YTD Fatality | EM3: ="YTD "&'Weekly Progress Report'!X64 -> YTD Fire Incident Cases | EN3: ="YTD "&'Weekly Progress Report'!X65 -> YTD Vehicle Incident | EO3: ="YTD "&'Weekly Progress Report'!X66 -> YTD Property Damages | EP3: ="YTD "&'Weekly Progress Report'!X67 -> YTD Induction Training | EQ3: ="YTD "&'Weekly Progress Report'!X68 -> YTD No.of Internal Training | ER3: ="YTD "&'Weekly Progress Report'!X69 -> YTD No.of Internal Audit | ES3: ="YTD "&'Weekly Progress Report'!X70 -> YTD No. of Toolbox Talks | ET3: ="YTD "&'Weekly Progress Report'!X71 -> YTD Safety Awards/Incentives | EU3: ="Cum "&'Weekly Progress Report'!X55 -> Cum Total Hours Worked | EV3: ="Cum "&'Weekly Progress Report'!X56 -> Cum Safe Hours Worked | EW3: ="Cum "&'Weekly Progress Report'!X57 -> Cum LTI | EX3: ="Cum "&'Weekly Progress Report'!X58 -> Cum MTC (Healed w/o Disability) | EY3: ="Cum "&'Weekly Progress Report'!X60 -> Cum MTC (Healed w/ Disability) | EZ3: ="Cum "&'Weekly Progress Report'!X61 -> Cum Near Miss | FA3: ="Cum "&'Weekly Progress Report'!X62 -> Cum First Aid Cases | FB3: ="Cum "&'Weekly Progress Report'!X63 -> Cum Fatality | FC3: ="Cum "&'Weekly Progress Report'!X64 -> Cum Fire Incident Cases | FD3: ="Cum "&'Weekly Progress Report'!X65 -> Cum Vehicle Incident | FE3: ="Cum "&'Weekly Progress Report'!X66 -> Cum Property Damages | FF3: ="Cum "&'Weekly Progress Report'!X67 -> Cum Induction Training | FG3: ="Cum "&'Weekly Progress Report'!X68 -> Cum No.of Internal Training | FH3: ="Cum "&'Weekly Progress Report'!X69 -> Cum No.of Internal Audit | FI3: ="Cum "&'Weekly Progress Report'!X70 -> Cum No. of Toolbox Talks | FJ3: ="Cum "&'Weekly Progress Report'!X71 -> Cum Safety Awards/Incentives | FK3: ='Weekly Progress Report'!A83 -> Total Act. | FL3: ='Weekly Progress Report'!B83 -> Not Started | FM3: ='Weekly Progress Report'!C83 -> In Progress | FN3: ='Weekly Progress Report'!D83 -> Completed | FO3: Critical Path Act.Last Week | FP3: Critical Path Act.This Week | FQ3: Failed start Last Week | FR3: Failed start This Week | FS3: ='Weekly Progress Report'!B95 -> 0 | FT3: ='Weekly Progress Report'!D95 -> 0 | FU3: ='Weekly Progress Report'!F95 -> 0 | FV3: ='Weekly Progress Report'!H95 -> 0 | FW3: ='Weekly Progress Report'!J95 -> 0 | FX3: ='Weekly Progress Report'!L95 -> 0 | FY3: ='Weekly Progress Report'!N95 -> 0 | FZ3: ='Weekly Progress Report'!O95 -> 0 | GA3: ='Weekly Progress Report'!P95 -> 0
A4: ='Weekly Progress Report'!AG1 -> 46307 | B4: ='Weekly Progress Report'!B3 -> ADDITIONAL DEVELOPMENT IN TABOUK INDUSTRIAL CITY | C4: ='Weekly Progress Report'!B4 -> TAB1-02-003 | D4: ='Weekly Progress Report'!B5 -> ASAS for Developing & Operating Industrial Cities | E4: ='Weekly Progress Report'!B6 -> EGIS | F4: ='Weekly Progress Report'!E4 -> INFRASTRUCTURE & UTILITIES | G4: ='Weekly Progress Report'!E5 -> Active | H4: ='Weekly Progress Report'!E6 -> ENG/ YAZEED ALRAGABAH | I4: ='Weekly Progress Report'!AA3 -> The project consists of roads works and the POND A which works as a downstream for the storm water wet utility piping network including manholes and catch basins, continued project wet utilities also sewerage GRP piping network with manholes, potable water and firefighting compound HDPE piping network including the installation of valves and fire hydrants and the irrigation water (TSE) network with all valves and the flow meter, dry utility represented in electrical road lighting network - the installation of poles and the LV cables which is connected to the panel board and the 13.8/0.4 K V unit substation. | J4: ='Weekly Progress Report'!H3 -> 45882 | K4: ='Weekly Progress Report'!H4 -> 45900 | L4: ='Weekly Progress Report'!H5 -> 45904 | M4: ='Weekly Progress Report'!H6 -> 46633 | N4: ='Weekly Progress Report'!$J$3 -> 45882 | O4: ='Weekly Progress Report'!$J$4 -> 45900 | P4: ='Weekly Progress Report'!$J$5 -> 45904 | Q4: ='Weekly Progress Report'!$J$6 -> 46633 | R4: ='Weekly Progress Report'!$L$3 -> 46633 | S4: ='Weekly Progress Report'!$L$4 -> 46633 | T4: ='Weekly Progress Report'!$L$5 -> 46662 | U4: ='Weekly Progress Report'!$O$3 -> 140467862 | V4: ='Weekly Progress Report'!$O$4 -> 140467862 | W4: ='Weekly Progress Report'!$O$5 -> 140467862 | X4: ='Weekly Progress Report'!$O$6 -> 0 | Y4: ='Weekly Progress Report'!$S$3 -> 0 | Z4: ='Weekly Progress Report'!$S$4 -> 43497867 | AA4: ='Weekly Progress Report'!$S$5 -> 58000 | AB4: ='Weekly Progress Report'!$S$6 -> 51776131 | AC4: ='Weekly Progress Report'!$J$22 -> 0.63558139 | AD4: ='Weekly Progress Report'!$V$3 -> 0.37308716 | AE4: ='Weekly Progress Report'!$V$4 -> 0.47569888 | AF4: ='Weekly Progress Report'!$X$3 -> 0.3461685 | AG4: ='Weekly Progress Report'!$X$4 -> 0.4987258 | AH4: ='Weekly Progress Report'!$Z$3 -> 0.92982759 | AI4: ='Weekly Progress Report'!$Z$5 -> 0.94565217 | AJ4: ='Weekly Progress Report'!$E$22 -> 504274.59 | AK4: ='Weekly Progress Report'!$F$22 -> 950868.63 | AL4: =AJ4/V4 -> 0.0035899642 | AM4: =AK4/V4 -> 0.0067692967 | AN4: ='Weekly Progress Report'!S22 -> 0.0059462831 | AO4: ='Weekly Progress Report'!T22 -> 0.013252845 | AP4: ='Weekly Progress Report'!C61 -> 300 | AQ4: ='Weekly Progress Report'!I61 -> 0 | AR4: ='Weekly Progress Report'!J61 -> 0 | AS4: ='Weekly Progress Report'!K61 -> 428 | AT4: ='Weekly Progress Report'!C70 -> 0 | AU4: ='Weekly Progress Report'!J70 -> 1 | AV4: ='Weekly Progress Report'!K70 -> 52 | AW4: ='Weekly Progress Report'!C79 -> 29 | AX4: ='Weekly Progress Report'!D79 -> 29 | AY4: ='Weekly Progress Report'!E79 -> 27 | AZ4: ='Weekly Progress Report'!F79 -> 2 | BA4: ='Weekly Progress Report'!G79 -> 45142 | BB4: ='Weekly Progress Report'!H79 -> 12907 | BC4: ='Weekly Progress Report'!I79 -> 0 | BD4: ='Weekly Progress Report'!N56 -> 11 | BE4: ='Weekly Progress Report'!O56 -> 11 | BF4: ='Weekly Progress Report'!P56 -> 0 | BG4: ='Weekly Progress Report'!Q56 -> 5 | BH4: ='Weekly Progress Report'!N57 -> 20 | BI4: ='Weekly Progress Report'!O57 -> 20 | BJ4: ='Weekly Progress Report'!P57 -> 0 | BK4: ='Weekly Progress Report'!Q57 -> 6 | BL4: ='Weekly Progress Report'!N58 -> 223 | BM4: ='Weekly Progress Report'!O58 -> 221 | BN4: ='Weekly Progress Report'!P58 -> 2 | BO4: ='Weekly Progress Report'!Q58 -> 2 | BP4: ='Weekly Progress Report'!N60 -> 6764 | BQ4: ='Weekly Progress Report'!O60 -> 6526 | BR4: ='Weekly Progress Report'!P60 -> 238 | BS4: ='Weekly Progress Report'!Q60 -> 1 | BT4: ='Weekly Progress Report'!O62 -> 45963 | BU4: ='Weekly Progress Report'!O63 -> 45963 | BV4: ='Weekly Progress Report'!O64 -> 45950 | BW4: ='Weekly Progress Report'!O65 -> 45950 | BX4: ='Weekly Progress Report'!O66 -> #REF! | BY4: ='Weekly Progress Report'!U62 -> 45964 | BZ4: ='Weekly Progress Report'!U63 -> 2 | CA4: ='Weekly Progress Report'!U64 -> 45964 | CB4: ='Weekly Progress Report'!U65 -> 0 | CC4: ='Weekly Progress Report'!U66 -> 0 | CD4: ='Weekly Progress Report'!N68 -> 13 | CE4: ='Weekly Progress Report'!N69 -> 9 | CF4: ='Weekly Progress Report'!N70 -> 9 | CG4: ='Weekly Progress Report'!N71 -> 0 | CH4: ='Weekly Progress Report'!N72 -> 0.1 | CI4: ='Weekly Progress Report'!N73 -> 0 | CJ4: ='Weekly Progress Report'!N74 -> 0.00041290584 | CK4: ='Weekly Progress Report'!R68 -> 43497867 | CL4: ='Weekly Progress Report'!R69 -> 29853856 | CM4: ='Weekly Progress Report'!R70 -> 34389935 | CN4: ='Weekly Progress Report'!R71 -> 46295 | CO4: ='Weekly Progress Report'!R72 -> 14046786 | CP4: ='Weekly Progress Report'!R73 -> 0 | CQ4: ='Weekly Progress Report'!R74 -> 58000 | CR4: ='Weekly Progress Report'!L78 -> 28 | CS4: ='Weekly Progress Report'!M78 -> 32 | CT4: ='Weekly Progress Report'!O78 -> 4 | CU4: ='Weekly Progress Report'!P78 -> 141 | CV4: ='Weekly Progress Report'!Q78 -> 358 | CW4: ='Weekly Progress Report'!T92 -> 38 | CX4: ='Weekly Progress Report'!U92 -> 52 | CY4: ='Weekly Progress Report'!Z55 -> 9660 | CZ4: ='Weekly Progress Report'!Z56 -> 6360 | DA4: ='Weekly Progress Report'!Z57 -> 0 | DB4: ='Weekly Progress Report'!Z58 -> 0 | DC4: ='Weekly Progress Report'!Z60 -> 0 | DD4: ='Weekly Progress Report'!Z61 -> 0 | DE4: ='Weekly Progress Report'!Z62 -> 0 | DF4: ='Weekly Progress Report'!Z63 -> 0 | DG4: ='Weekly Progress Report'!Z64 -> 0 | DH4: ='Weekly Progress Report'!Z65 -> 0 | DI4: ='Weekly Progress Report'!Z66 -> 0 | DJ4: ='Weekly Progress Report'!Z67 -> 0 | DK4: ='Weekly Progress Report'!Z68 -> 0 | DL4: ='Weekly Progress Report'!Z69 -> 0 | DM4: ='Weekly Progress Report'!Z70 -> 1 | DN4: ='Weekly Progress Report'!Z71 -> 0 | DO4: ='Weekly Progress Report'!AB55 -> 20640 | DP4: ='Weekly Progress Report'!AB56 -> 20640 | DQ4: ='Weekly Progress Report'!AB57 -> 0 | DR4: ='Weekly Progress Report'!AB58 -> 0 | DS4: ='Weekly Progress Report'!AB60 -> 0 | DT4: ='Weekly Progress Report'!AB61 -> 0 | DU4: ='Weekly Progress Report'!AB62 -> 0 | DV4: ='Weekly Progress Report'!AB63 -> 0 | DW4: ='Weekly Progress Report'!AB64 -> 0 | DX4: ='Weekly Progress Report'!AB65 -> 0 | DY4: ='Weekly Progress Report'!AB66 -> 0 | DZ4: ='Weekly Progress Report'!AB67 -> 0 | EA4: ='Weekly Progress Report'!AB68 -> 1 | EB4: ='Weekly Progress Report'!AB69 -> 0 | EC4: ='Weekly Progress Report'!AB70 -> 2 | ED4: ='Weekly Progress Report'!AB71 -> 0 | EE4: ='Weekly Progress Report'!AC55 -> 371624 | EF4: ='Weekly Progress Report'!AC56 -> 371624 | EG4: ='Weekly Progress Report'!AC57 -> 0 | EH4: ='Weekly Progress Report'!AC58 -> 0 | EI4: ='Weekly Progress Report'!AC60 -> 0 | EJ4: ='Weekly Progress Report'!AC61 -> 0 | EK4: ='Weekly Progress Report'!AC62 -> 0 | EL4: ='Weekly Progress Report'!AC63 -> 0 | EM4: ='Weekly Progress Report'!AC64 -> 0 | EN4: ='Weekly Progress Report'!AC65 -> 0 | EO4: ='Weekly Progress Report'!AC66 -> 0 | EP4: ='Weekly Progress Report'!AC67 -> 7 | EQ4: ='Weekly Progress Report'!AC68 -> 18 | ER4: ='Weekly Progress Report'!AC69 -> 0 | ES4: ='Weekly Progress Report'!AC70 -> 36 | ET4: ='Weekly Progress Report'!AC71 -> 0 | EU4: ='Weekly Progress Report'!AD55 -> 371624 | EV4: ='Weekly Progress Report'!AD56 -> 371624 | EW4: ='Weekly Progress Report'!AD57 -> 0 | EX4: ='Weekly Progress Report'!AD58 -> 0 | EY4: ='Weekly Progress Report'!AD60 -> 0 | EZ4: ='Weekly Progress Report'!AD61 -> 0 | FA4: ='Weekly Progress Report'!AD62 -> 0 | FB4: ='Weekly Progress Report'!AD63 -> 0 | FC4: ='Weekly Progress Report'!AD64 -> 0 | FD4: ='Weekly Progress Report'!AD65 -> 0 | FE4: ='Weekly Progress Report'!AD66 -> 0 | FF4: ='Weekly Progress Report'!AD67 -> 8 | FG4: ='Weekly Progress Report'!AD68 -> 18 | FH4: ='Weekly Progress Report'!AD69 -> 0 | FI4: ='Weekly Progress Report'!AD70 -> 36 | FJ4: ='Weekly Progress Report'!AD71 -> 0 | FK4: ='Weekly Progress Report'!A84 -> 1492 | FL4: ='Weekly Progress Report'!B84 -> 712 | FM4: ='Weekly Progress Report'!C84 -> 205 | FN4: ='Weekly Progress Report'!D84 -> 575 | FO4: ='Weekly Progress Report'!A89 -> 188 | FP4: ='Weekly Progress Report'!B89 -> 200 | FQ4: ='Weekly Progress Report'!H89 -> 24 | FR4: ='Weekly Progress Report'!I89 -> 24 | FS4: ='Weekly Progress Report'!B100 -> 0 | FT4: ='Weekly Progress Report'!D100 -> 0 | FU4: ='Weekly Progress Report'!F100 -> 0 | FV4: ='Weekly Progress Report'!H100 -> 0 | FW4: ='Weekly Progress Report'!J100 -> 0 | FX4: ='Weekly Progress Report'!L100 -> 0 | FY4: ='Weekly Progress Report'!N100 -> 0 | FZ4: ='Weekly Progress Report'!O100 -> 0 | GA4: ='Weekly Progress Report'!P100 -> 0

Sheet Procurement (2)
C1: =+_xlfn.SINGLE('Weekly Progress Report'!B4) -> TAB1-02-003 | E1: Procurement Log- Long Lead Items | X1: =+'General Information'!L1 -> 46307
A2: Sr. NO. | B2: Project ID | C2: ACT#inP6 | D2: Item Description | E2: Discipline | F2: (Long \Short) Lead Items | G2: BOQ. No. | H2: Unit | I2: Quantity | J2: Proc. Qty | K2: Required P.O Date | L2: Date of Pur. Order Issued | M2: Purchase Order No. | N2: Supplier | O2: Supplier Phone | P2: Method of Shipping | Q2: Required on Job | R2: E.D.A. to Site | S2: A.D.A. to Site | T2: Lead Time | U2: Approval Status | V2: Completion Rate | W2: The Impact (BOQ Cost) | X2: Remarks
C3: SHORT-LEAD
A4: 1 | C4: ROADS | D4: ROADS | F4: Short
A5: 1 | B5: TAB1-01-009 | C5: TAPQDVRD0001 | D5: ABC | E5: ROADS | F5: LONG | H5: m3 | I5: 48485 | J5: 48485 | K5: 45962 | L5: 46105 | M5: SL103026 | N5: شركة خبير المستقبل للاسفلت | P5: Local | Q5: 46121 | R5: 46102 | S5: 46102 | U5: Accepted As Material | V5: 0.32 | X5: po issued
A6: 2 | B6: TAB1-01-009 | C6: TAPQDVRD0002 | D6: BBC Base Course | E6: ROADS | F6: LONG | H6: m3 | I6: 24510 | J6: 24510 | K6: 45962 | L6: 46105 | M6: SL103026 | N6: شركة خبير المستقبل للاسفلت | P6: Local | Q6: 46110 | R6: 46110 | S6: 46110 | U6: Accepted As Material | V6: 0.16 | X6: DELIVERY ONGOING
A7: 3 | B7: TAB1-01-009 | C7: TAPQDVRD0003 | D7: BWC Asphalt Wearing Course | E7: ROADS | F7: LONG | H7: m3 | I7: 14195 | J7: 14195 | K7: 45962 | L7: 46105 | M7: SL103027 | N7: شركة خبير المستقبل للاسفلت | P7: Local | Q7: 46582 | U7: Accepted As Material | X7: po issued
A8: 4 | B8: TAB1-01-009 | C8: TAPQDVRD0004 | D8: Precast Concrete Curbstone | E8: ROADS | F8: LONG | H8: m | I8: 74370 | J8: 74370 | K8: 45962 | L8: 46208 | M8: PO-02156 | N8: جسور المستقبل | P8: Local | Q8: 46119 | R8: 46124 | S8: 46124 | U8: Accepted As Material | V8: 0.05 | X8: DELIVERY ONGOING
A9: 5 | B9: TAB1-01-009 | C9: TAPQDVRD0005 | D9: Precast Concrete Interlocking | E9: ROADS | F9: LONG | H9: m2 | I9: 62075 | J9: 62075 | K9: 45962 | L9: 46208 | M9: PO-02156 | N9: جسور المستقبل | P9: Local | Q9: 46586 | U9: Accepted As Material | X9: po issued
A10: 6 | B10: TAB1-01-009 | C10: TAPQDVRD0008 | D10: Marking for Road | E10: ROADS | F10: LONG | K10: 45962 | L10: 46131 | M10: SL1942026 | N10: شركة أضواء طي الشمال | P10: Local | Q10: 46134 | R10: 46138 | S10: 46138 | U10: Accepted As Material | V10: 0.19 | X10: DELIVERY ONGOING
A11: 7 | B11: TAB1-01-009 | C11: TAPQDVRD0009 | D11: Trafic Sinage | E11: ROADS | F11: LONG | H11: Unit | I11: 246 | J11: 246 | K11: 45962 | P11: Local | Q11: 46140 | U11: Accepted As Material | V11: 0.02 | X11: DELIVERY ONGOING
A12: 2 | C12: ELECTRICAL | D12: ELECTRICAL
A13: 8 | B13: TAB1-01-009 | C13: TAPQDVEL0001 | D13: Pipes ,Fittings | E13: ELECTRICAL | F13: LONG | H13: m | I13: 2145 | J13: 2145 | K13: 46135 | L13: 46134 | M13: SL2242026 | N13: الشركة العربية لصناعة البلاستك | P13: Local | Q13: 46141 | R13: 46141 | S13: 46141 | U13: Accepted As Material | V13: 0.7 | X13: DELIVERY ONGOING | AA13: =13000/48485 -> 0.26812416
A14: 9 | D14: cables (LV ) | K14: 46135 | L14: 46205 | M14: PO-02162 | N14: بحرة | Q14: 46254 | X14: po issued
A15: 10 | B15: TAB1-01-009 | C15: TAPQDVEL0002 | D15: SCOPE MV | E15: ELECTRICAL | F15: LONG | H15: m | I15: 115400 | J15: 115400 | K15: 46135 | L15: 46126 | M15: PO-014255 | N15: شركة ايتيا | P15: Local | Q15: 46254 | R15: 46183 | S15: 46183 | U15: Accepted As Material | V15: 0.12 | X15: DELIVERY ONGOING
A16: 11 | B16: TAB1-01-009 | C16: TAPQDVEL0003 | D16: Poles & Luminares | E16: ELECTRICAL | F16: LONG | H16: Unit | I16: 957 | J16: 957 | K16: 46135 | L16: 46182 | M16: PO-012069 | N16: شركة جلنتي | P16: Local | Q16: 46324 | U16: Accepted As Material | X16: po issued
A17: 13 | B17: TAB1-01-009 | C17: TAPQDVEL0004 | D17: Substations ,ets.. | E17: ELECTRICAL | F17: LONG | H17: Unit | I17: 5 | J17: 5 | K17: 46135 | L17: 46126 | M17: PO-014255 | N17: شركة ايتيا | P17: Local | Q17: 46394 | U17: Accepted As Material | X17: po issued
A18: 14 | B18: TAB1-01-009 | C18: TAPQDVEL0004 | D18: RMU ,ets.. | E18: ELECTRICAL | F18: LONG | H18: Unit | I18: 5 | J18: 5 | K18: 46135 | L18: 46126 | M18: PO-014255 | N18: شركة ايتيا | P18: Local | Q18: 46394 | U18: Accepted As Material | X18: po issued
A19: 16 | D19: Pole Foundation | K19: 46135 | Q19: 46401 | X19: po not issued
A20: 3 | C20: TELECOMMUNICATION | D20: TELECOMMUNICATION
A21: 17 | B21: TAB1-01-009 | C21: TAPQDVTC0001 | D21: Telecommunication Material (Pipes,,ets) | E21: TELECOMMUNICATION | F21: LONG | H21: m | I21: 16522 | J21: 16522 | K21: 46176 | P21: Local | Q21: 46219 | U21: Accepted As Material | V21: 0.01 | X21: po not issued
A22: 4 | C22: CCTV NETWORK | D22: CCTV NETWORK
A23: 18 | B23: TAB1-01-009 | C23: TAPQDVCC0001 | D23: CCTV NETWORK | E23: CCTV NETWORK | F23: LONG | H23: m | I23: 24430 | J23: 24430 | K23: 46202 | L23: 46209 | P23: Local | Q23: 46289 | U23: Accepted As Material | X23: po issued
A24: 5 | C24: POTABLE WATER | D24: POTABLE WATER
A25: 19 | B25: TAB1-01-009 | C25: TAPQDVPT0001 | D25: PE Pipes | E25: POTABLE WATER | F25: LONG | H25: m | I25: 13221 | J25: 13221 | K25: 46025 | L25: 46021 | M25: PO-01613 | N25: UNION PIPES | P25: Local | Q25: 46040 | R25: 46043 | S25: 46043 | U25: Accepted As Material | V25: 0.89 | X25: DELIVERY ONGOING
A26: 20 | B26: TAB1-01-009 | C26: TAPQDVPT0002 | D26: Valves | E26: POTABLE WATER | F26: LONG | H26: Nr | I26: 146 | J26: 146 | K26: 46025 | L26: 46016 | M26: PO-01520 | N26: SPC | P26: Local | Q26: 46063 | R26: 46063 | S26: 46063 | U26: Accepted As Material | V26: 0.78 | X26: DELIVERY ONGOING
A27: 21 | B27: TAB1-01-009 | C27: TAPQDVPT0003 | D27: Fire Hydrent | E27: POTABLE WATER | F27: LONG | H27: Nr | I27: 152 | J27: 152 | K27: 46025 | L27: 46016 | M27: PO-1520 | N27: SPC | P27: Local | Q27: 46073 | R27: 46073 | S27: 46073 | U27: Accepted As Material | V27: 0.68 | X27: DELIVERY ONGOING
A28: 6 | C28: TSE NETWORK | D28: TSE NETWORK
A29: 22 | B29: TAB1-01-009 | C29: TAPQDVTS0001 | D29: PE Pipes | E29: TSE NETWORK | F29: LONG | H29: m | I29: 12223 | J29: 12223 | K29: 46025 | L29: 46021 | M29: PO-01613 | N29: UNION PIPES | P29: Local | Q29: 46044 | R29: 46043 | S29: 46043 | U29: Accepted As Material | V29: 0.89 | X29: DELIVERY ONGOING
A30: 23 | B30: TAB1-01-009 | C30: TAPQDVTS0002 | D30: Valves | E30: TSE NETWORK | F30: LONG | H30: Nr | I30: 141 | J30: 141 | K30: 46025 | L30: 46016 | M30: PO-01520 | N30: SPC | P30: Local | Q30: 46073 | R30: 46063 | S30: 46063 | U30: Accepted As Material | V30: 0.78 | X30: DELIVERY ONGOING
A31: 7 | C31: SEWERAGE NETWORK | D31: SEWERAGE NETWORK
A32: 24 | B32: TAB1-01-009 | C32: TAPQDVSW0001 | D32: GRP Pipes | E32: SEWERAGE NETWORK | F32: LONG | H32: m | I32: 8370 | J32: 8370 | K32: 45980 | L32: 45985 | M32: PO-01437 | N32: TAREQ NAQADI | O32: 533365029 | P32: Local | Q32: 46000 | R32: 46000 | S32: 46000 | U32: Accepted As Material | V32: 0.84 | X32: DELIVERY ONGOING
A33: 25 | B33: TAB1-01-009 | C33: TAPQDVSW0002 | D33: Fiberglass Manholes,ets) | E33: SEWERAGE NETWORK | F33: LONG | H33: Nr | I33: 142 | J33: 142 | K33: 45980 | L33: 46040 | M33: PO-1662 | N33: TAREQ NAQADI | P33: Local | Q33: 46051 | R33: 46055 | S33: 46055 | U33: Accepted As Material | V33: 1 | X33: DONE
A34: 8 | C34: STORM NETWORK | D34: STORM NETWORK
A35: 26 | B35: TAB1-01-009 | C35: TAPQDVST0001 | D35: UPVC Pipes with Fittings | E35: STORM NETWORK | F35: LONG | H35: m | I35: 6621 | J35: 6621 | K35: 46359 | L35: 46019 | M35: PO-01580 | N35: الخام الوطني للصناعات | P35: Local | Q35: 46040 | R35: 46043 | S35: 46043 | U35: Accepted As Material | V35: 1 | X35: DONE
A36: 27 | B36: TAB1-01-009 | C36: TAPQDVST0002 | D36: GRP Pipes with Fittings | E36: STORM NETWORK | F36: LONG | H36: m | I36: 9017 | J36: 9017 | K36: 45982 | L36: 45985 | M36: PO-01437 | N36: TAREQ NAQADI | O36: 533365029 | P36: Local | Q36: 46000 | R36: 46000 | S36: 46000 | U36: Accepted As Material | V36: 0.88 | X36: DELIVERY ONGOING
A37: 28 | B37: TAB1-01-009 | C37: TAPQDVST0005 | D37: Box Culvert | E37: STORM NETWORK | F37: LONG | H37: m3 | I37: 4100 | J37: 4100 | K37: 45982 | L37: 46054 | M37: PO-01183 | N37: TAREQ NAQADI | P37: Local | Q37: 46085 | R37: 46086 | S37: 46086 | U37: Accepted As Material | V37: 0.98 | X37: DELIVERY ONGOING
A38: 29 | B38: TAB1-01-009 | C38: TAPQDVST0006 | D38: Manholes,ets | E38: STORM NETWORK | F38: LONG | H38: Nr | I38: 155 | J38: 155 | K38: 45982 | L38: 46043 | M38: PO -01700 | N38: JOSOR ELMOSTAKBEL | P38: Local | Q38: 46060 | R38: 46086 | S38: 46086 | U38: Accepted As Material | V38: 0.99 | X38: DELIVERY ONGOING
A39: 30 | D39: CATCH BASIN | E39: STORM NETWORK | M39: PO-01886 | N39: TAREQ NAQADI | Q39: 46188 | R39: 46134 | S39: 46134 | U39: Accepted As Material | V39: 0.68 | X39: DELIVERY ONGOING
A40: 31 | B40: TAB1-01-009 | C40: TAPQDVST0007 | D40: RIprab for Ponds | E40: STORM NETWORK | F40: LONG | H40: m2 | I40: 15345 | J40: 15345 | K40: 45982 | L40: 46133 | M40: SL1942027 | N40: SALALEM ELYAMAMAH | P40: Local | Q40: 46134 | R40: 46134 | S40: 46134 | U40: Accepted As Material | V40: 0.3 | X40: DELIVERY ONGOING
...

Sheet Weekly Progress Report
A1: MODON - Weekly Progress Report - Construction Projects | AF1: Data Date | AG1: ='General Information'!L1 -> 46307
A2: Contract General Information | G2: Key Dates | M2: Cost Summary (SR) | U2: Performance Summary | AA2: Project Scope
A3: Project Name | B3: ='General Information'!C3 -> ADDITIONAL DEVELOPMENT IN TABOUK INDUSTRIAL CITY | G3: Contract Award | H3: ='General Information'!C12 -> 45882 | I3: Contract Award (Hijri) | J3: ='General Information'!C16 -> 45882 | K3: Revised Completion | L3: ='General Information'!C20 -> 46633 | M3: Original Contract Value | O3: ='Invoice Log'!E3 -> 140467862 | Q3: O&M Value (if any) | S3: ='Invoice Log'!I3 -> 0 | T3: EAC | U3: Plan Value | V3: =K22 -> 0.37308716 | W3: Phys. Plan Value | X3: =W22 -> 0.3461685 | Y3: Quality Score | Z3: =Quality!AC10 -> 0.92982759 | AA3: =+Progress!B1 -> The project consists of roads works and the POND A which works as a downstream for the storm water wet utility piping network including manholes and catch basins, continued project wet utilities also sewerage GRP piping network with manholes, potable water and firefighting compound HDPE piping network including the installation of valves and fire hydrants and the irrigation water (TSE) network with all valves and the flow meter, dry utility represented in electrical road lighting network - the installation of poles and the LV cables which is connected to the panel board and the 13.8/0.4 K V unit substation.
A4: Project ID | B4: ='General Information'!C4 -> TAB1-02-003 | D4: Stage | E4: ='General Information'!C7 -> INFRASTRUCTURE & UTILITIES | G4: Contract Sign | H4: ='General Information'!C13 -> 45900 | I4: Contract Sign (Hijri) | J4: ='General Information'!C17 -> 45900 | K4: Committed Completion | L4: ='General Information'!C21 -> 46633 | M4: Revised Contract Value | O4: ='Invoice Log'!E4 -> 140467862 | P4: EAC | Q4: Submitted Invoices (Gross Value) | S4: ='Invoice Log'!I5 -> 43497867 | U4: Earn Value | V4: =L22 -> 0.47569888 | W4: Phys. Earn Value | X4: =X22 -> 0.4987258 | Z4: =REPT("¢",IF(INT(+Z3*10)>5,5,INT(+Z3*10)))&REPT("£",IF(INT(+Z3*10)>5,0,5-INT(+Z3*10)))&CHAR(10)&REPT("¢",+IF(INT(+Z3*10)>5,-5+INT(+Z3*10),0))&REPT("£",IF(INT(+Z3*10)>5,10-INT(+Z3*10),5)) -> ¢¢¢¢¢ ¢¢¢¢£
A5: Contractor | B5: ='General Information'!C5 -> ASAS for Developing & Operating Industrial Cities | D5: Status | E5: ='General Information'!C8 -> Active | G5: Site Handover | H5: ='General Information'!C14 -> 45904 | I5: Site Handover (Hijri) | J5: ='General Information'!C18 -> 45904 | K5: Forecast Completion | L5: ='General Information'!C22 -> 46662 | M5: Estimate At Completion Value | O5: ='Invoice Log'!E5 -> 140467862 | P5: =+#REF!+#REF!+O5 -> #REF! | Q5: Penalities | S5: ='Invoice Log'!I6 -> 58000 | U5: Variance | V5: =V4-V3 -> 0.10261172 | W5: Variance | X5: =Y22 -> 0.1525573 | Y5: Safety Score | Z5: ='HSE-Stat'!J23 -> 0.94565217
A6: Consultant | B6: ='General Information'!C6 -> EGIS | D6: Modon PM | E6: ='General Information'!C9 -> ENG/ YAZEED ALRAGABAH | G6: Original Completion | H6: ='General Information'!C15 -> 46633 | I6: Original Completion (Hijri) | J6: ='General Information'!C19 -> 46633 | K6: Variance | L6: =H6-L5 -> -29 | M6: Potential Changes | O6: =O4-O5 -> 0 | Q6: FIR Value (THIS WEEK) | S6: ='FIR Summary'!F3 -> 51776131 | U6: FIR % | V6: =S6/O4 -> 0.3685977 | W6: Invoiced % | X6: =S4/O4 -> 0.3096642 | Z6: =REPT("¢",IF(INT(+Z5*10)>5,5,INT(+Z5*10)))&REPT("£",IF(INT(+Z5*10)>5,0,5-INT(+Z5*10)))&CHAR(10)&REPT("¢",+IF(INT(+Z5*10)>5,-5+INT(+Z5*10),0))&REPT("£",IF(INT(+Z5*10)>5,10-INT(+Z5*10),5)) -> ¢¢¢¢¢ ¢¢¢¢£
A8: Progress Overview
A9: Earned Value Progress (SAR) | O9: Physical Progress (Effort) | AA9: Earned Value Progress (%)
A10: WBS | C10: BOQ Value (SAR) | D10: % Wt. | E10: Weekly (SAR) | G10: To Date (SAR) | O10: Budgeted | P10: % Wt. | Q10: Weekly Physical Progress | U10: To Date Physical Progress
E11: Planned | F11: Earned | G11: Original Plan | H11: Revised Planned | I11: Earned | J11: Original Plan % | K11: Revised Planned % | L11: Earned % | M11: Variance | N11: SPI | O11: (Manhours) | Q11: Planned | R11: Earned | S11: Plan % | T11: Earned % | U11: Planned | V11: Earned | W11: Plan % | X11: Earned % | Y11: Variance | Z11: SPI
A12: =Progress!A7 -> MILESTONS | C12: =+Progress!C7 -> 0 | D12: =IF(ISBLANK(C12),"",C12/$C$22) -> 0 | E12: =+Progress!E7 -> 0 | F12: =+Progress!F7 -> 0 | G12: =+Progress!G7 -> 0 | H12: =+Progress!H7 -> 0 | I12: =+Progress!I7 -> 0 | J12: =IFERROR(IF(ISBLANK(G12),"",G12/C12),0) -> 0 | K12: =IFERROR(IF(ISBLANK(H12),"",H12/C12),0) -> 0 | L12: =IFERROR(IF(ISBLANK(I12),"",I12/C12),0) -> 0 | M12: =IFERROR(L12-K12,"") -> 0 | N12: =IFERROR(L12/K12,"") | O12: =+Progress!K7 -> 0 | P12: =IF(ISBLANK(O12),"",O12/$O$22) -> 0 | Q12: =+Progress!M7 -> 0 | R12: =+Progress!N7 -> 0 | S12: =IFERROR(IF(ISBLANK(Q12),"",Q12/O12),0) -> 0 | T12: =IFERROR(IF(ISBLANK(R12),"",R12/O12),0) -> 0 | U12: =+Progress!O7 -> 0 | V12: =+Progress!P7 -> 0 | W12: =IFERROR(IF(ISBLANK(U12),"",U12/O12),0) -> 0 | X12: =IFERROR(IF(ISBLANK(V12),"",V12/O12),0) -> 0 | Y12: =IFERROR(X12-W12,"") -> 0 | Z12: =IFERROR(X12/W12,"")
A13: =Progress!A8 -> MOBILIZATION | C13: =+Progress!C8 -> 0 | D13: =IF(ISBLANK(C13),"",C13/$C$22) -> 0 | E13: =+Progress!E8 -> 0 | F13: =+Progress!F8 -> 0 | G13: =+Progress!G8 -> 0 | H13: =+Progress!H8 -> 0 | I13: =+Progress!I8 -> 0 | J13: =IFERROR(IF(ISBLANK(G13),"",G13/C13),0) -> 0 | K13: =IFERROR(IF(ISBLANK(H13),"",H13/C13),0) -> 0 | L13: =IFERROR(IF(ISBLANK(I13),"",I13/C13),0) -> 0 | M13: =IFERROR(L13-K13,"") -> 0 | N13: =IFERROR(L13/K13,"") | O13: =+Progress!K8 -> 1600 | P13: =IF(ISBLANK(O13),"",O13/$O$22) -> 0.0045154499 | Q13: =+Progress!M8 -> 0 | R13: =+Progress!N8 -> 0 | S13: =IFERROR(IF(ISBLANK(Q13),"",Q13/O13),0) -> 0 | T13: =IFERROR(IF(ISBLANK(R13),"",R13/O13),0) -> 0 | U13: =+Progress!O8 -> 1600 | V13: =+Progress!P8 -> 1600 | W13: =IFERROR(IF(ISBLANK(U13),"",U13/O13),0) -> 1 | X13: =IFERROR(IF(ISBLANK(V13),"",V13/O13),0) -> 1 | Y13: =IFERROR(X13-W13,"") -> 0 | Z13: =IFERROR(X13/W13,"") -> 1
A14: =Progress!A9 -> ENGINEERING | C14: =+Progress!C9 -> 4214035 | D14: =IF(ISBLANK(C14),"",C14/$C$22) -> 0.029999994 | E14: =+Progress!E9 -> 0 | F14: =+Progress!F9 -> 0 | G14: =+Progress!G9 -> 4214035 | H14: =+Progress!H9 -> 4214035 | I14: =+Progress!I9 -> 4214035.9 | J14: =IFERROR(IF(ISBLANK(G14),"",G14/C14),0) -> 1 | K14: =IFERROR(IF(ISBLANK(H14),"",H14/C14),0) -> 1 | L14: =IFERROR(IF(ISBLANK(I14),"",I14/C14),0) -> 1.0000002 | M14: =IFERROR(L14-K14,"") -> 2.0407994e-07 | N14: =IFERROR(L14/K14,"") -> 1.0000002 | O14: =+Progress!K9 -> 0 | P14: =IF(ISBLANK(O14),"",O14/$O$22) -> 0 | Q14: =+Progress!M9 -> 0 | R14: =+Progress!N9 -> 0 | S14: =IFERROR(IF(ISBLANK(Q14),"",Q14/O14),0) -> 0 | T14: =IFERROR(IF(ISBLANK(R14),"",R14/O14),0) -> 0 | U14: =+Progress!O9 -> 0 | V14: =+Progress!P9 -> 0 | W14: =IFERROR(IF(ISBLANK(U14),"",U14/O14),0) -> 0 | X14: =IFERROR(IF(ISBLANK(V14),"",V14/O14),0) -> 0 | Y14: =IFERROR(X14-W14,"") -> 0 | Z14: =IFERROR(X14/W14,"")
A15: =Progress!A10 -> PROCUREMENT | C15: =+Progress!C10 -> 28093572 | D15: =IF(ISBLANK(C15),"",C15/$C$22) -> 0.2 | E15: =+Progress!E10 -> 205448.67 | F15: =+Progress!F10 -> 141539.04 | G15: =+Progress!G10 -> 21377402 | H15: =+Progress!H10 -> 15068661 | I15: =+Progress!I10 -> 17171855 | J15: =IFERROR(IF(ISBLANK(G15),"",G15/C15),0) -> 0.76093569 | K15: =IFERROR(IF(ISBLANK(H15),"",H15/C15),0) -> 0.53637397 | L15: =IFERROR(IF(ISBLANK(I15),"",I15/C15),0) -> 0.61123786 | M15: =IFERROR(L15-K15,"") -> 0.074863882 | N15: =IFERROR(L15/K15,"") -> 1.139574 | O15: =+Progress!K10 -> 0 | P15: =IF(ISBLANK(O15),"",O15/$O$22) -> 0 | Q15: =+Progress!M10 -> 0 | R15: =+Progress!N10 -> 0 | S15: =IFERROR(IF(ISBLANK(Q15),"",Q15/O15),0) -> 0 | T15: =IFERROR(IF(ISBLANK(R15),"",R15/O15),0) -> 0 | U15: =+Progress!O10 -> 0 | V15: =+Progress!P10 -> 0 | W15: =IFERROR(IF(ISBLANK(U15),"",U15/O15),0) -> 0 | X15: =IFERROR(IF(ISBLANK(V15),"",V15/O15),0) -> 0 | Y15: =IFERROR(X15-W15,"") -> 0 | Z15: =IFERROR(X15/W15,"")
A16: =Progress!A11 -> CONSTRUCTION WORKS | C16: =+Progress!C11 -> 94113469 | D16: =IF(ISBLANK(C16),"",C16/$C$22) -> 0.67000001 | E16: =+Progress!E11 -> 298825.92 | F16: =+Progress!F11 -> 809329.59 | G16: =+Progress!G11 -> 58798243 | H16: =+Progress!H11 -> 33124060 | I16: =+Progress!I11 -> 45434514 | J16: =IFERROR(IF(ISBLANK(G16),"",G16/C16),0) -> 0.62475907 | K16: =IFERROR(IF(ISBLANK(H16),"",H16/C16),0) -> 0.35195877 | L16: =IFERROR(IF(ISBLANK(I16),"",I16/C16),0) -> 0.48276314 | M16: =IFERROR(L16-K16,"") -> 0.13080438 | N16: =IFERROR(L16/K16,"") -> 1.3716469 | O16: =+Progress!K11 -> 347187 | P16: =IF(ISBLANK(O16),"",O16/$O$22) -> 0.97981594 | Q16: =+Progress!M11 -> 2107 | R16: =+Progress!N11 -> 4696 | S16: =IFERROR(IF(ISBLANK(Q16),"",Q16/O16),0) -> 0.0060687756 | T16: =IFERROR(IF(ISBLANK(R16),"",R16/O16),0) -> 0.013525852 | U16: =+Progress!O11 -> 121061 | V16: =+Progress!P11 -> 175118 | W16: =IFERROR(IF(ISBLANK(U16),"",U16/O16),0) -> 0.34869105 | X16: =IFERROR(IF(ISBLANK(V16),"",V16/O16),0) -> 0.50439101 | Y16: =IFERROR(X16-W16,"") -> 0.15569995 | Z16: =IFERROR(X16/W16,"") -> 1.446527
A17: =Progress!A12 -> ZONE 01 | C17: =+Progress!C12 -> 18023708 | D17: =IF(ISBLANK(C17),"",C17/$C$22) -> 0.12831197 | E17: =+Progress!E12 -> 47598.42 | F17: =+Progress!F12 -> 56655.1 | G17: =+Progress!G12 -> 16301672 | H17: =+Progress!H12 -> 10109128 | I17: =+Progress!I12 -> 11813165 | J17: =IFERROR(IF(ISBLANK(G17),"",G17/C17),0) -> 0.90445714 | K17: =IFERROR(IF(ISBLANK(H17),"",H17/C17),0) -> 0.56087947 | L17: =IFERROR(IF(ISBLANK(I17),"",I17/C17),0) -> 0.65542368 | M17: =IFERROR(L17-K17,"") -> 0.094544203 | N17: =IFERROR(L17/K17,"") -> 1.1685642 | O17: =Progress!K12 -> 74705 | P17: =Progress!L12 -> 0.21082918 | Q17: =Progress!M12 -> 1105 | R17: =Progress!N12 -> 953 | S17: =IFERROR(IF(ISBLANK(Q17),"",Q17/O17),0) -> 0.014791513 | T17: =IFERROR(IF(ISBLANK(R17),"",R17/O17),0) -> 0.012756844 | U17: =Progress!O12 -> 29328 | V17: =Progress!P12 -> 42378 | W17: =IFERROR(IF(ISBLANK(U17),"",U17/O17),0) -> 0.39258416 | X17: =IFERROR(IF(ISBLANK(V17),"",V17/O17),0) -> 0.56727127 | Y17: =IFERROR(X17-W17,"") -> 0.1746871 | Z17: =IFERROR(X17/W17,"") -> 1.4449673
A18: =Progress!A13 -> ZONE 02 | C18: =+Progress!C13 -> 24418268 | D18: =IF(ISBLANK(C18),"",C18/$C$22) -> 0.17383526 | E18: =+Progress!E13 -> 92411.99 | F18: =+Progress!F13 -> 411400.45 | G18: =+Progress!G13 -> 16533727 | H18: =+Progress!H13 -> 9329697.4 | I18: =+Progress!I13 -> 14890926 | J18: =IFERROR(IF(ISBLANK(G18),"",G18/C18),0) -> 0.67710481 | K18: =IFERROR(IF(ISBLANK(H18),"",H18/C18),0) -> 0.38207859 | L18: =IFERROR(IF(ISBLANK(I18),"",I18/C18),0) -> 0.60982729 | M18: =IFERROR(L18-K18,"") -> 0.2277487 | N18: =IFERROR(L18/K18,"") -> 1.5960781 | O18: =Progress!K13 -> 89699 | P18: =Progress!L13 -> 0.25314459 | Q18: =Progress!M13 -> 743 | R18: =Progress!N13 -> 2189 | S18: =IFERROR(IF(ISBLANK(Q18),"",Q18/O18),0) -> 0.0082832585 | T18: =IFERROR(IF(ISBLANK(R18),"",R18/O18),0) -> 0.02440384 | U18: =Progress!O13 -> 40282 | V18: =Progress!P13 -> 63809 | W18: =IFERROR(IF(ISBLANK(U18),"",U18/O18),0) -> 0.4490797 | X18: =IFERROR(IF(ISBLANK(V18),"",V18/O18),0) -> 0.71136802 | Y18: =IFERROR(X18-W18,"") -> 0.26228832 | Z18: =IFERROR(X18/W18,"") -> 1.5840574
A19: =Progress!A14 -> ZONE 03 | C19: =+Progress!C14 -> 51671493 | D19: =IF(ISBLANK(C19),"",C19/$C$22) -> 0.36785278 | E19: =+Progress!E14 -> 158815.5 | F19: =+Progress!F14 -> 341274.03 | G19: =+Progress!G14 -> 25962845 | H19: =+Progress!H14 -> 13685235 | I19: =+Progress!I14 -> 18730423 | J19: =IFERROR(IF(ISBLANK(G19),"",G19/C19),0) -> 0.50245974 | K19: =IFERROR(IF(ISBLANK(H19),"",H19/C19),0) -> 0.26485077 | L19: =IFERROR(IF(ISBLANK(I19),"",I19/C19),0) -> 0.36249045 | M19: =IFERROR(L19-K19,"") -> 0.097639678 | N19: =IFERROR(L19/K19,"") -> 1.3686592 | O19: =Progress!K14 -> 182783 | P19: =Progress!L14 -> 0.51584217 | Q19: =Progress!M14 -> 258 | R19: =Progress!N14 -> 1554 | S19: =IFERROR(IF(ISBLANK(Q19),"",Q19/O19),0) -> 0.0014115098 | T19: =IFERROR(IF(ISBLANK(R19),"",R19/O19),0) -> 0.0085018847 | U19: =Progress!O14 -> 51451 | V19: =Progress!P14 -> 68931 | W19: =IFERROR(IF(ISBLANK(U19),"",U19/O19),0) -> 0.28148679 | X19: =IFERROR(IF(ISBLANK(V19),"",V19/O19),0) -> 0.37711932 | Y19: =IFERROR(X19-W19,"") -> 0.095632526 | Z19: =IFERROR(X19/W19,"") -> 1.3397407
A20: =Progress!A15 -> CLOSE OUT | C20: =+Progress!C15 -> 14046786 | D20: =IF(ISBLANK(C20),"",C20/$C$22) -> 0.1 | E20: =+Progress!E15 -> 0 | G20: =+Progress!G15 -> 4889079 | H20: =+Progress!H15 -> 0 | I20: =+Progress!I15 -> 0 | J20: =IFERROR(IF(ISBLANK(G20),"",G20/C20),0) -> 0.34805677 | K20: =IFERROR(IF(ISBLANK(I20),"",I20/C20),0) -> 0 | L20: =IFERROR(IF(ISBLANK(I20),"",I20/C20),0) -> 0 | M20: =IFERROR(L20-K20,"") -> 0 | N20: =IFERROR(L20/K20,"") | O20: =Progress!K15 -> 5552 | P20: =IF(ISBLANK(O20),"",O20/$O$22) -> 0.015668611 | Q20: =Progress!M15 -> 0 | R20: =Progress!N15 -> 0 | S20: =IFERROR(IF(ISBLANK(Q20),"",Q20/O20),0) -> 0 | T20: =IFERROR(IF(ISBLANK(R20),"",R20/O20),0) -> 0 | U20: =Progress!O15 -> 0 | V20: =Progress!P15 -> 0 | W20: =IFERROR(IF(ISBLANK(U20),"",U20/O20),0) -> 0 | X20: =IFERROR(IF(ISBLANK(V20),"",V20/O20),0) -> 0 | Y20: =IFERROR(X20-W20,"") -> 0 | Z20: =IFERROR(X20/W20,"")
A21: =Progress!A16 -> 0 | D21: =IF(ISBLANK(C21),"",C21/$C$22) | J21: =IFERROR(IF(ISBLANK(G21),"",G21/C21),0) | K21: =IFERROR(IF(ISBLANK(I21),"",I21/C21),0) | L21: =IFERROR(IF(ISBLANK(I21),"",I21/C21),0) | M21: =IFERROR(L21-K21,"") | N21: =IFERROR(L21/K21,"") | P21: =IF(ISBLANK(O21),"",O21/$O$22) | S21: =IFERROR(IF(ISBLANK(Q21),"",Q21/O21),0) | T21: =IFERROR(IF(ISBLANK(R21),"",R21/O21),0) | W21: =IFERROR(IF(ISBLANK(U21),"",U21/O21),0) | X21: =IFERROR(IF(ISBLANK(V21),"",V21/O21),0) | Y21: =IFERROR(X21-W21,"") | Z21: =IFERROR(X21/W21,"")
B22: Total | C22: =C14+C12+C13+C16+C20+C15 -> 140467862 | D22: =D12+D13+D14+D15+D16+D20 -> 1 | E22: =Progress!E41 -> 504274.59 | F22: =Progress!F41 -> 950868.63 | G22: =Progress!G41 -> 89278759 | H22: =Progress!H41 -> 52406756 | I22: =Progress!I41 -> 66820405 | J22: =IFERROR(IF(ISBLANK(G22),"",G22/C22),0) -> 0.63558139 | K22: =IFERROR(IF(ISBLANK(H22),"",H22/C22),0) -> 0.37308716 | L22: =IFERROR(IF(ISBLANK(I22),"",I22/C22),0) -> 0.47569888 | M22: =+L22-K22 -> 0.10261172 | N22: =L22/K22 -> 1.2750342 | O22: =Progress!K41 -> 354339 | P22: =Progress!L41 -> 1 | Q22: =Progress!M41 -> 2107 | R22: =Progress!N41 -> 4696 | S22: =IFERROR(IF(ISBLANK(Q22),"",Q22/O22),0) -> 0.0059462831 | T22: =IFERROR(IF(ISBLANK(R22),"",R22/O22),0) -> 0.013252845 | U22: =Progress!O41 -> 122661 | V22: =Progress!P41 -> 176718 | W22: =IFERROR(IF(ISBLANK(U22),"",U22/O22),0) -> 0.3461685 | X22: =IFERROR(IF(ISBLANK(V22),"",V22/O22),0) -> 0.4987258 | Y22: =+X22-W22 -> 0.1525573 | Z22: =X22/W22 -> 1.4407024
AA23: Construction Milestones
AA24: Item No. | AB24: Milestones | AD24: Original (Baseline) | AE24: Latest Plan | AF24: Forecast | AG24: Status | AH24: Days Change
AA25: =+Milestones!A4 -> 1 | AB25: =+Milestones!B4 -> Award Date | AD25: =+Milestones!C4 -> 45882 | AE25: =+Milestones!D4 -> 45882 | AF25: =+Milestones!E4 -> 45882 | AG25: =+Milestones!F4 -> A | AH25: =+Milestones!G4 -> 0
AA26: =+Milestones!A5 -> 2 | AB26: =+Milestones!B5 -> Contract Sign Date | AD26: =+Milestones!C5 -> 45900 | AE26: =+Milestones!D5 -> 45900 | AF26: =+Milestones!E5 -> 45900 | AG26: =+Milestones!F5 -> A | AH26: =+Milestones!G5 -> 0
AA27: =+Milestones!A6 -> 3 | AB27: =+Milestones!B6 -> Site Handover Date | AD27: =+Milestones!C6 -> 45904 | AE27: =+Milestones!D6 -> 45904 | AF27: =+Milestones!E6 -> 45904 | AG27: =+Milestones!F6 -> A | AH27: =+Milestones!G6 -> 0
AA28: =+Milestones!A7 -> 4 | AB28: =+Milestones!B7 -> Complete Mobilization | AD28: =+Milestones!C7 -> 46609 | AE28: =+Milestones!D7 -> 46629 | AF28: =+Milestones!E7 -> 46623 | AG28: =+Milestones!F7 -> F | AH28: =+Milestones!G7 -> 6
AA29: =+Milestones!A10 -> 7 | AB29: =+Milestones!B10 -> Complete ZONE 1 | AD29: =+Milestones!C10 -> 46427 | AE29: =+Milestones!D10 -> 46662 | AF29: =+Milestones!E10 -> 46659 | AG29: =+Milestones!F10 -> F | AH29: =+Milestones!G10 -> 3
AA30: =+Milestones!A11 -> 8 | AB30: =+Milestones!B11 -> Complete ZONE 2 | AD30: =+Milestones!C11 -> 46601 | AE30: =+Milestones!D11 -> 46615 | AF30: =+Milestones!E11 -> 46622 | AG30: =+Milestones!F11 -> F | AH30: =+Milestones!G11 -> -7
AA31: =+Milestones!A12 -> 9 | AB31: =+Milestones!B12 -> Complete ZONE 3 | AD31: =+Milestones!C12 -> 46601 | AE31: =+Milestones!D12 -> 46657 | AF31: =+Milestones!E12 -> 46655 | AG31: =+Milestones!F12 -> F | AH31: =+Milestones!G12 -> 2
AA32: =+Milestones!A13 -> 10 | AB32: =+Milestones!B13 -> Complete all Works including Testing & Commissioning, Cleanup, Closeout Documentation and Ready for Initial Handover | AD32: =+Milestones!C13 -> 46609 | AE32: =+Milestones!D13 -> 46643 | AF32: =+Milestones!E13 -> 46643 | AG32: =+Milestones!F13 -> F | AH32: =+Milestones!G13 -> 0
AA33: =+Milestones!A14 -> 11 | AB33: =+Milestones!B14 -> Complete Demobilization | AD33: =+Milestones!C14 -> 46633 | AE33: =+Milestones!D14 -> 46662 | AF33: =+Milestones!E14 -> 46662 | AG33: =+Milestones!F14 -> F | AH33: =+Milestones!G14 -> 0
AA34: =+Milestones!A15 -> 12 | AB34: =+Milestones!B15 -> Project Handover | AD34: =+Milestones!C15 -> 46633 | AE34: =+Milestones!D15 -> 46662 | AF34: =+Milestones!E15 -> 46662 | AG34: =+Milestones!F15 -> F | AH34: =+Milestones!G15 -> 0
A50: Performance overview
A51: Submittals Status | L51: Quality | W51: Safety
A52: Shop Drawings | L52: Quality Reports | W52: Safety Statistics | AE52: Proactive Vs Reactive Actions Taken
A53: Item Per WBS | C53: Total | D53: Total Submitted Drawings | I53: Remaining | J53: Pending | K53: Total Submittals | L53: Quality Reports | N53: Issued | O53: Closed | P53: Pending | Q53: Avg. Closing (Days) | R53: Pending | W53: Category | X53: Item | Z53: This Week | AB53: This Month | AC53: Year to Date | AD53: Cumulative
D54: A | E54: B | F54: C | G54: D | H54: Processed | R54: 0-10 Days | S54: 11-20 Days | T54: 21-30 Days | U54: 31-60 Days | V54: > 60 Days
A55: ='Quality-Stat'!$A$13 -> Electrical Network - Road Lighting | C55: =IF('Quality-Stat'!D13="","",'Quality-Stat'!D13) -> 102 | D55: =IF('Quality-Stat'!E13="","",'Quality-Stat'!E13) -> 33 | E55: =IF('Quality-Stat'!F13="","",'Quality-Stat'!F13) -> 69 | F55: =IF('Quality-Stat'!G13="","",'Quality-Stat'!G13) -> 0 | G55: =IF('Quality-Stat'!H13="","",'Quality-Stat'!H13) -> 0 | H55: =IF('Quality-Stat'!I13="","",'Quality-Stat'!I13) -> 102 | I55: =IF('Quality-Stat'!J13="","",'Quality-Stat'!J13) | J55: =IF('Quality-Stat'!K13="","",'Quality-Stat'!K13) | K55: =IF('Quality-Stat'!L13="","",'Quality-Stat'!L13) -> 102 | W55: General | X55: ='HSE-Stat'!B4 -> Total Hours Worked | Z55: ='HSE-Stat'!D4 -> 9660 | AB55: ='HSE-Stat'!E4 -> 20640 | AC55: ='HSE-Stat'!F4 -> 371624 | AD55: ='HSE-Stat'!G4 -> 371624 | AG55: Proactive | AH55: =+SUM(AD67:AD71) -> 62
A56: ='Quality-Stat'!$A$14 -> Potable Water Network | C56: =IF('Quality-Stat'!D14="","",'Quality-Stat'!D14) -> 53 | D56: =IF('Quality-Stat'!E14="","",'Quality-Stat'!E14) -> 50 | E56: =IF('Quality-Stat'!F14="","",'Quality-Stat'!F14) -> 3 | F56: =IF('Quality-Stat'!G14="","",'Quality-Stat'!G14) -> 0 | G56: =IF('Quality-Stat'!H14="","",'Quality-Stat'!H14) -> 0 | H56: =IF('Quality-Stat'!I14="","",'Quality-Stat'!I14) -> 53 | I56: =IF('Quality-Stat'!J14="","",'Quality-Stat'!J14) | J56: =IF('Quality-Stat'!K14="","",'Quality-Stat'!K14) | K56: =IF('Quality-Stat'!L14="","",'Quality-Stat'!L14) -> 53 | L56: Non Conformance (NCR) | N56: ='Quality-Stat'!C5 -> 11 | O56: ='Quality-Stat'!D5 -> 11 | P56: ='Quality-Stat'!E5 -> 0 | Q56: ='Quality-Stat'!F5 -> 5 | R56: ='Quality-Stat'!G5 -> 0 | S56: ='Quality-Stat'!H5 -> 0 | T56: ='Quality-Stat'!I5 -> 0 | U56: ='Quality-Stat'!J5 -> 0 | V56: ='Quality-Stat'!K5 -> 0 | X56: ='HSE-Stat'!B5 -> Safe Hours Worked | Z56: 6360 | AB56: ='HSE-Stat'!E5 -> 20640 | AC56: ='HSE-Stat'!F5 -> 371624 | AD56: ='HSE-Stat'!G5 -> 371624 | AG56: Reactive | AH56: =SUM(AD57:AD66) -> 0
...

Sheet General Information
A1: Weekly Progress Report - Construction Projects | K1: Data Date | L1: 46307
A2: Contract General Information
A3: Project Name | C3: ADDITIONAL DEVELOPMENT IN TABOUK INDUSTRIAL CITY
A4: Project ID | C4: =Quality!E6 -> TAB1-02-003
A5: Contractor | C5: ASAS for Developing & Operating Industrial Cities
A6: Consultant | C6: EGIS
A7: Stage | C7: INFRASTRUCTURE & UTILITIES
A8: Status | C8: Active
A9: Modon PM | C9: ENG/ YAZEED ALRAGABAH
A11: Key Dates
A12: Contract Award Date | C12: =Milestones!C4 -> 45882
A13: Contract Sign Date | C13: =Milestones!C5 -> 45900
A14: Site Handover Date | C14: =Milestones!C6 -> 45904
A15: Original Completion | C15: =Milestones!C15 -> 46633
A16: Contract Award Date (Hijri) | C16: =C12 -> 45882
A17: Contract Sign Date (Hijri) | C17: =C13 -> 45900
A18: Site Handover Date (Hijri) | C18: =C14 -> 45904
A19: Original Completion (Hijri) | C19: =C15 -> 46633
A20: Revised Completion Date | C20: =C15 -> 46633
A21: Committed Completion Date | C21: =C15 -> 46633
A22: Forecast Completion | C22: =Milestones!E15 -> 46662
A23: Variance | C23: =C20-C22 -> -29
A25: Key Project Submittals | C25: Submission Date | D25: Days taken to approve orginal plan from site handover date
A26: Quality Plan submission | C26: 45931 | D26: =C26-C14 -> 27
A27: Quality Plan approval | C27: 45963
A28: Quality Plan Last Update | C28: 45963
A29: NO OF REVESION | C29: 3
A30: Safety Plan submission | C30: 45934 | D30: =C30-C14 -> 30
A31: Safety Plan approval | C31: 45950
A32: Safety Plan Last Update | C32: 45950
A33: NO OF REVESION | C33: 1
A34: Risk Management Plan submission
A35: Risk Management Plan approval
A36: Risk Management Plan Last Update
A38: Baseline Schedule submission | C38: 45944 | D38: =C38-C14 -> 40
A39: Baseline Schedule approval | C39: 45964
A40: No of Schedule Versions | C40: 2
A41: Last Recovery Schedule Approval Date | C41: 45964
A43: BOQ submission
A44: BOQ approval
...

Sheet Weekly Photos
B1: Date | C1: ='Weekly Progress Report'!AG1 -> 46307
B4: KERBSTONE | L4: ABC
B23: excavation | L23: bbc

Sheet Progress
A1: Project Scope Statement | B1: The project consists of roads works and the POND A which works as a downstream for the storm water wet utility piping network including manholes and catch basins, continued project wet utilities also sewerage GRP piping network with manholes, potable water and firefighting compound HDPE piping network including the installation of valves and fire hydrants and the irrigation water (TSE) network with all valves and the flow meter, dry utility represented in electrical road lighting network - the installation of poles and the LV cables which is connected to the panel board and the 13.8/0.4 K V unit substation. | S1: ='General Information'!$K$1 -> Data Date | T1: ='General Information'!L1 -> 46307
A4: Earned Value Progress (SAR) | K4: Physical Progress (Effort)
A5: WBS | C5: BOQ Value (SAR) | D5: % Wt. | E5: Weekly (SAR) | H5: To Date (SAR) | K5: Budgeted | L5: % Wt. | M5: Weekly Physical Progress | O5: To Date Physical Progress
E6: Planned | F6: Earned | G6: Original Plan | H6: Planned | I6: Earned | K6: (Manhours) | M6: Planned | N6: Earned | O6: Planned | P6: Earned
A7: MILESTONS | C7: =M51 -> 0 | D7: =IF(ISBLANK(C7),"",C7/$C$41) -> 0 | E7: =N51-W51 -> 0 | F7: =O51-X51 -> 0 | G7: =H7 -> 0 | H7: =I7 -> 0 | I7: =O51 -> 0 | K7: 0 | L7: =IF(ISBLANK(K7),"",K7/$K$41) -> 0 | M7: =D91 -> 0 | N7: =C91 -> 0 | O7: =G91 -> 0 | P7: =F91 -> 0
A8: MOBILIZATION | C8: 0 | D8: =IF(ISBLANK(C8),"",C8/$C$41) -> 0 | E8: 0 | F8: =O52-X52 -> 0 | G8: 0 | H8: 0 | I8: 0 | K8: 1600 | L8: =IF(ISBLANK(K8),"",K8/$K$41) -> 0.0045154499 | M8: =D92 -> 0 | N8: =C92 -> 0 | O8: =G92 -> 1600 | P8: =F92 -> 1600
A9: ENGINEERING | C9: 4214035 | D9: =IF(ISBLANK(C9),"",C9/$C$41) -> 0.029999994 | E9: =D48 -> 0 | F9: =C48 -> 0 | G9: =G48 -> 4214035 | H9: =G48 -> 4214035 | I9: =F48 -> 4214035.9 | K9: 0 | L9: =IF(ISBLANK(K9),"",K9/$K$41) -> 0 | M9: =D93 -> 0 | N9: =C93 -> 0 | O9: =G93 -> 0 | P9: =F93 -> 0
A10: PROCUREMENT | C10: 28093572 | D10: =IF(ISBLANK(C10),"",C10/$C$41) -> 0.2 | E10: =D49 -> 205448.67 | F10: =C49 -> 141539.04 | G10: 21377402 | H10: =G49 -> 15068661 | I10: =F49 -> 17171855 | K10: 0 | L10: =IF(ISBLANK(K10),"",K10/$K$41) -> 0 | M10: =D94 -> 0 | N10: =C94 -> 0 | O10: =G94 -> 0 | P10: =F94 -> 0
A11: CONSTRUCTION WORKS | C11: 94113469 | D11: =D12+D13+D14 -> 0.67000001 | E11: =D86 -> 298825.92 | F11: =C86 -> 809329.59 | G11: 58798243 | H11: =G86 -> 33124060 | I11: =F86 -> 45434514 | K11: 347187 | L11: =IF(ISBLANK(K11),"",K11/$K$41) -> 0.97981594 | M11: =D95 -> 2107 | N11: =C95 -> 4696 | O11: =G95 -> 121061 | P11: =F95 -> 175118
A12: ZONE 01 | C12: 18023708 | D12: 0.12831197 | E12: =D100 -> 47598.42 | F12: =C100 -> 56655.1 | G12: 16301672 | H12: =G100 -> 10109128 | I12: =F100 -> 11813165 | K12: 74705 | L12: =IF(ISBLANK(K12),"",K12/$K$41) -> 0.21082918 | M12: =D104 -> 1105 | N12: =C104 -> 953 | O12: =G104 -> 29328 | P12: =F104 -> 42378
A13: ZONE 02 | C13: 24418268 | D13: 0.17383526 | E13: =D101 -> 92411.99 | F13: =C101 -> 411400.45 | G13: 16533727 | H13: =G101 -> 9329697.4 | I13: =F101 -> 14890926 | K13: 89699 | L13: =IF(ISBLANK(K13),"",K13/$K$41) -> 0.25314459 | M13: =D105 -> 743 | N13: =C105 -> 2189 | O13: =G105 -> 40282 | P13: =F105 -> 63809
A14: ZONE 03 | C14: 51671493 | D14: 0.36785278 | E14: =D102 -> 158815.5 | F14: =C102 -> 341274.03 | G14: 25962845 | H14: =G102 -> 13685235 | I14: =F102 -> 18730423 | K14: 182783 | L14: =IF(ISBLANK(K14),"",K14/$K$41) -> 0.51584217 | M14: =D106 -> 258 | N14: =C106 -> 1554 | O14: =G106 -> 51451 | P14: =F106 -> 68931
A15: CLOSE OUT | C15: 14046786 | D15: =IF(ISBLANK(C15),"",C15/$C$41) -> 0.1 | E15: 0 | F15: =C87 -> 0 | G15: 4889079 | H15: =G87 -> 0 | I15: =F87 -> 0 | K15: 5552 | L15: =IF(ISBLANK(K15),"",K15/$K$41) -> 0.015668611 | N15: =C96 -> 0 | O15: =G96 -> 0 | P15: =F96 -> 0
D16: =IF(ISBLANK(C16),"",C16/$C$41)
D17: =IF(ISBLANK(C17),"",C17/$C$41)
D18: =IF(ISBLANK(C18),"",C18/$C$41)
D19: =IF(ISBLANK(C19),"",C19/$C$41)
D20: =IF(ISBLANK(C20),"",C20/$C$41)
D21: =IF(ISBLANK(C21),"",C21/$C$41)
D22: =IF(ISBLANK(C22),"",C22/$C$41)
D23: =IF(ISBLANK(C23),"",C23/$C$41)
D24: =IF(ISBLANK(C24),"",C24/$C$41)
D25: =IF(ISBLANK(C25),"",C25/$C$41)
D26: =IF(ISBLANK(C26),"",C26/$C$41)
D27: =IF(ISBLANK(C27),"",C27/$C$41)
... D40: =IF(ISBLANK(C40),"",C40/$C$41)
B41: Total | C41: =C7+C8+C9+C10+C11+C15 -> 140467862 | D41: =D7+D8+D9+D10+D11+D15 -> 1 | E41: =E7+E8+E9+E10+E15+E11 -> 504274.59 | F41: =F7+F8+F9+F10+F15+F11 -> 950868.63 | G41: =G9+G10+G7+G8+G11+G15 -> 89278759 | H41: =H9+H10+H7+H8+H11+H15 -> 52406756 | I41: =I9+I10+I7+I8+I11+I15 -> 66820405 | K41: =K7+K8+K9+K10+K11+K15 -> 354339 | L41: =L7+L8+L9+L10+L11+L15 -> 1 | M41: =M7+M8+M9+M10+M11+M15 -> 2107 | N41: =N7+N8+N9+N10+N11+N15 -> 4696 | O41: =O7+O8+O9+O10+O11+O15 -> 122661 | P41: =P7+P8+P9+P10+P11+P15 -> 176718
E42: =E41/$C$41 -> 0.0035899642 | F42: =F41/$C$41 -> 0.0067692967 | G42: =G41/$C$41 -> 0.63558139 | H42: =H41/$C$41 -> 0.37308716 | I42: =I41/$C$41 -> 0.47569888 | M42: =M41/$K$41 -> 0.0059462831 | N42: =N41/$K$41 -> 0.013252845 | O42: =O41/$K$41 -> 0.3461685 | P42: =P41/$K$41 -> 0.4987258
A46: 18023708 | B46: =A46/C41 -> 0.12831197 | D46: THIS WEEK | F46: TO DATE | I46: LAST WEEK | M46: `
A47: 24418268 | B47: =A47/C41 -> 0.17383526 | C47: EARNED | D47: PLANNED | F47: EARNED | G47: PLANNED | H47: EARNED | I47: PLANNED
A48: 51671493 | B48: =A48/C41 -> 0.36785278 | C48: =F48-H48 -> 0 | D48: =G48-I48 -> 0 | F48: 4214035.9 | G48: 4214035 | H48: 4214035.9 | I48: 4214035
C49: =F49-H49 -> 141539.04 | D49: =G49-I49 -> 205448.67 | F49: 17171855 | G49: 15068661 | H49: 17030316 | I49: 14863212 | L49: 3034784.2
D50: =G50-H11 -> -33124060 | H50: 44625185 | I50: 32825234 | K50: Activity ID | L50: Activity Name | M50: Budgeted Total Cost | N50: Planned Value Cost | O50: Earned Value Cost | P50: Budgeted Labor Units | Q50: Planned Value Labor Units | R50: Earned Value Labor Units | T50: Activity ID | U50: Activity Name | V50: Budgeted Total Cost | W50: Planned Value Cost | X50: Earned Value Cost | Y50: Budgeted Labor Units | Z50: Planned Value Labor Units | AA50: Earned Value Labor Units
D51: =G51-H15 -> 0 | H51: 4214035.9 | I51: 4214035 | K51: Mobilization | M51: 0 | N51: 0 | O51: 0 | P51: 73264 | Q51: 24824 | R51: 24818.56 | T51: Mobilization | V51: 0 | W51: 0 | X51: 0 | Y51: 73264 | Z51: 24152 | AA51: 24146.63
