Workbook
Name _1B.05.M.010.0010: #REF!
Name _1B.05.M.010.0010: #REF!
Name _1B.05.M.010.0010: #REF!
Name _1B.05.M.010.0010: #REF!
Name _1B.05.M.010.0050: #REF!
Name _1B.05.M.010.0050: #REF!
Name _1B.05.M.010.0050: #REF!
Name _1B.05.M.010.0050: #REF!
Name _1B.05.M.0100.0010: #REF!
Name _1B.05.M.0100.0010: #REF!
Name _1B.05.M.0100.0010: #REF!
Name _1B.05.M.020.0010: #REF!
Name _1B.05.M.020.0010: #REF!
Name _1B.05.M.020.0010: #REF!
Name _1B.05.M.020.0020: #REF!
Name _1B.05.M.020.0020: #REF!
Name _1B.05.M.020.0020: #REF!
Name _1B.05.M.020.0030: #REF!
Name _1B.05.M.020.0030: #REF!
Name _1B.05.M.020.0030: #REF!
Name _1B.05.M.020.0040: #REF!
Name _1B.05.M.020.0040: #REF!
Name _1B.05.M.020.0040: #REF!
Name _1B.05.M.030.0010: #REF!
Name _1B.05.M.030.0010: #REF!
Name _1B.05.M.030.0010: #REF!
Name _1B.05.M.030.0020: #REF!
Name _1B.05.M.030.0020: #REF!
Name _1B.05.M.030.0020: #REF!
Name _1B.05.M.040.0010: #REF!
Name _1B.05.M.040.0010: #REF!
Name _1B.05.M.040.0010: #REF!
Name _1B.05.M.050.0010: #REF!
Name _1B.05.M.050.0010: #REF!
Name _1B.05.M.050.0010: #REF!
Name _1B.05.M.050.0020: #REF!
Name _1B.05.M.050.0020: #REF!
Name _1B.05.M.050.0020: #REF!
Name _1B.05.M.050.0030: #REF!
Name _1B.05.M.050.0030: #REF!
Name _1B.05.M.050.0030: #REF!
Name _1B.05.M.060.0020: #REF!
Name _1B.05.M.060.0020: #REF!
Name _1B.05.M.060.0020: #REF!
Name _1B.05.M.060.0100: #REF!
Name _1B.05.M.060.0100: #REF!
Name _1B.05.M.060.0100: #REF!
Name _1B.05.M.070.0010: #REF!
Name _1B.05.M.070.0010: #REF!
Name _1B.05.M.070.0010: #REF!
Name _1B.05.M.070.0020: #REF!
Name _1B.05.M.070.0020: #REF!
Name _1B.05.M.070.0020: #REF!
Name _1B.05.M.070.0030: #REF!
Name _1B.05.M.070.0030: #REF!
Name _1B.05.M.070.0030: #REF!
Name _1B.05.M.070.0040: #REF!
Name _1B.05.M.070.0040: #REF!
Name _1B.05.M.070.0040: #REF!
Name _1B.05.M.070.0050: #REF!

Sheet DB
A1: ='[47]Weekly Progress Report'!$A$1 -> MODON - Weekly Progress Report - Construction Projects
B2: ='[47]Weekly Progress Report'!$A$2 -> Contract General Information | J2: ='[47]Weekly Progress Report'!G2 -> Key Dates | U2: ='[47]Weekly Progress Report'!$M$2 -> Cost Summary (SR) | AD2: ='[47]Weekly Progress Report'!$U$2 -> Performance Summary | AP2: ='[47]Weekly Progress Report'!A52 -> Shop Drawings | AT2: ='[47]Weekly Progress Report'!A61 -> Material Approval | AW2: ='[47]Weekly Progress Report'!A70 -> Procurement Summary | BD2: ='[47]Weekly Progress Report'!L52 -> Quality Reports | BT2: ='[47]Weekly Progress Report'!L60 -> Key Submittals Approval Status | CD2: ='[47]Weekly Progress Report'!L66 -> Invoices Summary | CR2: ='[47]Weekly Progress Report'!L74 -> Resources at Site | CY2: ='[47]Weekly Progress Report'!W52 -> Safety Statistics | FK2: ='[47]Weekly Progress Report'!A79 -> Primavera P6 Schedule Status | FS2: ='[47]Weekly Progress Report'!A88 -> Weekly Prgoress Photos
A3: ='[47]Weekly Progress Report'!AF1 -> Data Date | B3: ='[47]Weekly Progress Report'!A3 -> Project Name | C3: ='[47]Weekly Progress Report'!A4 -> Project ID | D3: ='[47]Weekly Progress Report'!A5 -> Contractor | E3: ='[47]Weekly Progress Report'!A6 -> Consultant | F3: ='[47]Weekly Progress Report'!D4 -> Stage | G3: ='[47]Weekly Progress Report'!D5 -> Status | H3: ='[47]Weekly Progress Report'!D6 -> Modon PM | I3: ='[47]Weekly Progress Report'!AA2 -> Project Scope | J3: ='[47]Weekly Progress Report'!G3 -> Contract Award | K3: ='[47]Weekly Progress Report'!G4 -> Contract Sign | L3: ='[47]Weekly Progress Report'!G5 -> Site Handover | M3: ='[47]Weekly Progress Report'!G6 -> Original Completion | N3: ='[47]Weekly Progress Report'!$I$3 -> Contract Award (Hijri) | O3: ='[47]Weekly Progress Report'!$I$4 -> Contract Sign (Hijri) | P3: ='[47]Weekly Progress Report'!$I$5 -> Site Handover (Hijri) | Q3: ='[47]Weekly Progress Report'!$I$6 -> Original Completion (Hijri) | R3: ='[47]Weekly Progress Report'!$K$3 -> Revised Completion | S3: ='[47]Weekly Progress Report'!$K$4 -> Committed Completion | T3: ='[47]Weekly Progress Report'!$K$5 -> Forecast Completion | U3: ='[47]Weekly Progress Report'!$M$3 -> Original Contract Value | V3: ='[47]Weekly Progress Report'!$M$4 -> Revised Contract Value | W3: ='[47]Weekly Progress Report'!$M$5 -> Estimate At Completion Value | X3: ='[47]Weekly Progress Report'!$M$6 -> Potential Changes | Y3: ='[47]Weekly Progress Report'!$Q$3 -> O&M Value (if any) | Z3: ='[47]Weekly Progress Report'!$Q$4 -> Submitted Invoices (Gross Value) | AA3: ='[47]Weekly Progress Report'!$Q$5 -> Penalities | AB3: ='[47]Weekly Progress Report'!$Q$6 -> FIR Value (Todate) | AC3: Original Plan Value | AD3: ='[47]Weekly Progress Report'!$U$3 -> Plan Value | AE3: ='[47]Weekly Progress Report'!$U$4 -> Earn Value | AF3: ='[47]Weekly Progress Report'!$W$3 -> Phys. Plan Value | AG3: ='[47]Weekly Progress Report'!$W$4 -> Phys. Earn Value | AH3: ='[47]Weekly Progress Report'!$Y$3 -> Quality Score | AI3: ='[47]Weekly Progress Report'!$Y$5 -> Safety Score | AJ3: Weekly PV (SAR) | AK3: Weekly EV (SAR) | AL3: Weekly PV % | AM3: Weekly PV % | AN3: Weekly Phys PV% | AO3: Weekly Phys PV% | AP3: Total SD Planned | AQ3: SD Remaining | AR3: SD Pending | AS3: Total SD Submittals | AT3: Planned Materials Approv | AU3: Material Pending Approval | AV3: Materila Total Submittals | AW3: ='[47]Weekly Progress Report'!C71 -> Total Materials | AX3: ='[47]Weekly Progress Report'!D71 -> Total Number of P.O. | AY3: ='[47]Weekly Progress Report'!E71 -> Actual P.O. To Date | AZ3: ='[47]Weekly Progress Report'!F71 -> Remaining P.O | BA3: ='[47]Weekly Progress Report'!G71 -> Material on Site | BB3: ='[47]Weekly Progress Report'!H71 -> Remaining Materials | BC3: ='[47]Weekly Progress Report'!I71 -> Material Delivery Completion (Date) | BD3: ="NCR "&'[47]Weekly Progress Report'!N53 -> NCR Issued | BE3: ="NCR "&'[47]Weekly Progress Report'!O53 -> NCR Closed | BF3: ="NCR "&'[47]Weekly Progress Report'!P53 -> NCR Pending | BG3: ="NCR "&'[47]Weekly Progress Report'!Q53 -> NCR Avg. Closing (Days) | BH3: ="SIR "&'[47]Weekly Progress Report'!N53 -> SIR Issued | BI3: ="SIR "&'[47]Weekly Progress Report'!O53 -> SIR Closed | BJ3: ="SIR "&'[47]Weekly Progress Report'!P53 -> SIR Pending | BK3: ="SIR "&'[47]Weekly Progress Report'!Q53 -> SIR Avg. Closing (Days) | BL3: ="MIR "&'[47]Weekly Progress Report'!N53 -> MIR Issued | BM3: ="MIR "&'[47]Weekly Progress Report'!O53 -> MIR Closed | BN3: ="MIR "&'[47]Weekly Progress Report'!P53 -> MIR Pending | BO3: ="MIR "&'[47]Weekly Progress Report'!Q53 -> MIR Avg. Closing (Days) | BP3: ="FIR "&'[47]Weekly Progress Report'!N53 -> FIR Issued | BQ3: ="FIR "&'[47]Weekly Progress Report'!O53 -> FIR Closed | BR3: ="FIR "&'[47]Weekly Progress Report'!P53 -> FIR Pending | BS3: ="FIR "&'[47]Weekly Progress Report'!Q53 -> FIR Avg. Closing (Days) | BT3: ='[47]Weekly Progress Report'!L61 -> 1 Quality Plan Approval | BU3: ='[47]Weekly Progress Report'!L62 -> 2 Quality Plan Last Up | BV3: ='[47]Weekly Progress Report'!L63 -> 3 Safety Plan Approval | BW3: ='[47]Weekly Progress Report'!L64 -> 4 Safety Plan Last Up | BX3: ='[47]Weekly Progress Report'!L65 -> 5 Construction Plan Approval | BY3: ='[47]Weekly Progress Report'!Q61 -> 6 Baseline Approval | BZ3: ='[47]Weekly Progress Report'!Q62 -> 7 No of Approved Version of Schedule | CA3: ='[47]Weekly Progress Report'!Q63 -> 8 Last Approved Schedule | CB3: ='[47]Weekly Progress Report'!Q64 -> 9 BOQ Approval Date | CC3: ='[47]Weekly Progress Report'!Q65 -> 10 No of Approved Version of BOQ | CD3: ='[47]Weekly Progress Report'!L67 -> Total Submitted Invoices | CE3: ='[47]Weekly Progress Report'!L68 -> PM Approved Invoices | CF3: ='[47]Weekly Progress Report'!L69 -> No of Paid Invoices | CG3: ='[47]Weekly Progress Report'!L70 -> No of Pending Invoices | CH3: ='[47]Weekly Progress Report'!L71 -> Advance Payment % | CI3: ='[47]Weekly Progress Report'!L72 -> Retention % | CJ3: ='[47]Weekly Progress Report'!L73 -> Deduction / Penalties % | CK3: ='[47]Weekly Progress Report'!O67 -> Submitted Invoices (SAR) | CL3: ='[47]Weekly Progress Report'!O68 -> PM Approved Invoices (SAR) | CM3: ='[47]Weekly Progress Report'!O69 -> Paid Invoices (SAR) | CN3: ='[47]Weekly Progress Report'!O70 -> Last Submitted Period | CO3: ='[47]Weekly Progress Report'!O71 -> Advance Payment (SAR) | CP3: ='[47]Weekly Progress Report'!O72 -> Retention (SAR) | CQ3: ='[47]Weekly Progress Report'!O73 -> Deduction / Penalties (SAR) | CR3: Planned Head Count | CS3: Actual Head Count | CT3: Saudi Staff | CU3: Labor Planned | CV3: Labor Actual | CW3: Equipment Planned | CX3: Equipment Actual | CY3: ="This Week "&'[47]Weekly Progress Report'!X55 -> This Week Total Hours Worked | CZ3: ="This Week "&'[47]Weekly Progress Report'!X56 -> This Week Safe Hours Worked | DA3: ="This Week "&'[47]Weekly Progress Report'!X57 -> This Week LTI | DB3: ="This Week "&'[47]Weekly Progress Report'!X58 -> This Week MTC (Healed w/o Disability) | DC3: ="This Week "&'[47]Weekly Progress Report'!X59 -> This Week MTC (Healed w/ Disability) | DD3: ="This Week "&'[47]Weekly Progress Report'!X60 -> This Week Near Miss | DE3: ="This Week "&'[47]Weekly Progress Report'!X61 -> This Week First Aid Cases | DF3: ="This Week "&'[47]Weekly Progress Report'!X62 -> This Week Fatality | DG3: ="This Week "&'[47]Weekly Progress Report'!X63 -> This Week Fire Incident Cases | DH3: ="This Week "&'[47]Weekly Progress Report'!X64 -> This Week Vehicle Incident | DI3: ="This Week "&'[47]Weekly Progress Report'!X65 -> This Week Property Damages | DJ3: ="This Week "&'[47]Weekly Progress Report'!X66 -> This Week Induction Training | DK3: ="This Week "&'[47]Weekly Progress Report'!X67 -> This Week No.of Internal Training | DL3: ="This Week "&'[47]Weekly Progress Report'!X68 -> This Week No.of Internal Audit | DM3: ="This Week "&'[47]Weekly Progress Report'!X69 -> This Week No. of Toolbox Talks | DN3: ="This Week "&'[47]Weekly Progress Report'!X70 -> This Week Safety Awards/Incentives | DO3: ="This Month "&'[47]Weekly Progress Report'!X55 -> This Month Total Hours Worked | DP3: ="This Month "&'[47]Weekly Progress Report'!X56 -> This Month Safe Hours Worked | DQ3: ="This Month "&'[47]Weekly Progress Report'!X57 -> This Month LTI | DR3: ="This Month "&'[47]Weekly Progress Report'!X58 -> This Month MTC (Healed w/o Disability) | DS3: ="This Month "&'[47]Weekly Progress Report'!X59 -> This Month MTC (Healed w/ Disability) | DT3: ="This Month "&'[47]Weekly Progress Report'!X60 -> This Month Near Miss | DU3: ="This Month "&'[47]Weekly Progress Report'!X61 -> This Month First Aid Cases | DV3: ="This Month "&'[47]Weekly Progress Report'!X62 -> This Month Fatality | DW3: ="This Month "&'[47]Weekly Progress Report'!X63 -> This Month Fire Incident Cases | DX3: ="This Month "&'[47]Weekly Progress Report'!X64 -> This Month Vehicle Incident | DY3: ="This Month "&'[47]Weekly Progress Report'!X65 -> This Month Property Damages | DZ3: ="This Month "&'[47]Weekly Progress Report'!X66 -> This Month Induction Training | EA3: ="This Month "&'[47]Weekly Progress Report'!X67 -> This Month No.of Internal Training | EB3: ="This Month "&'[47]Weekly Progress Report'!X68 -> This Month No.of Internal Audit | EC3: ="This Month "&'[47]Weekly Progress Report'!X69 -> This Month No. of Toolbox Talks | ED3: ="This Month "&'[47]Weekly Progress Report'!X70 -> This Month Safety Awards/Incentives | EE3: ="YTD "&'[47]Weekly Progress Report'!X55 -> YTD Total Hours Worked | EF3: ="YTD "&'[47]Weekly Progress Report'!X56 -> YTD Safe Hours Worked | EG3: ="YTD "&'[47]Weekly Progress Report'!X57 -> YTD LTI | EH3: ="YTD "&'[47]Weekly Progress Report'!X58 -> YTD MTC (Healed w/o Disability) | EI3: ="YTD "&'[47]Weekly Progress Report'!X59 -> YTD MTC (Healed w/ Disability) | EJ3: ="YTD "&'[47]Weekly Progress Report'!X60 -> YTD Near Miss | EK3: ="YTD "&'[47]Weekly Progress Report'!X61 -> YTD First Aid Cases | EL3: ="YTD "&'[47]Weekly Progress Report'!X62 -> YTD Fatality | EM3: ="YTD "&'[47]Weekly Progress Report'!X63 -> YTD Fire Incident Cases | EN3: ="YTD "&'[47]Weekly Progress Report'!X64 -> YTD Vehicle Incident | EO3: ="YTD "&'[47]Weekly Progress Report'!X65 -> YTD Property Damages | EP3: ="YTD "&'[47]Weekly Progress Report'!X66 -> YTD Induction Training | EQ3: ="YTD "&'[47]Weekly Progress Report'!X67 -> YTD No.of Internal Training | ER3: ="YTD "&'[47]Weekly Progress Report'!X68 -> YTD No.of Internal Audit | ES3: ="YTD "&'[47]Weekly Progress Report'!X69 -> YTD No. of Toolbox Talks | ET3: ="YTD "&'[47]Weekly Progress Report'!X70 -> YTD Safety Awards/Incentives | EU3: ="Cum "&'[47]Weekly Progress Report'!X55 -> Cum Total Hours Worked | EV3: ="Cum "&'[47]Weekly Progress Report'!X56 -> Cum Safe Hours Worked | EW3: ="Cum "&'[47]Weekly Progress Report'!X57 -> Cum LTI | EX3: ="Cum "&'[47]Weekly Progress Report'!X58 -> Cum MTC (Healed w/o Disability) | EY3: ="Cum "&'[47]Weekly Progress Report'!X59 -> Cum MTC (Healed w/ Disability) | EZ3: ="Cum "&'[47]Weekly Progress Report'!X60 -> Cum Near Miss | FA3: ="Cum "&'[47]Weekly Progress Report'!X61 -> Cum First Aid Cases | FB3: ="Cum "&'[47]Weekly Progress Report'!X62 -> Cum Fatality | FC3: ="Cum "&'[47]Weekly Progress Report'!X63 -> Cum Fire Incident Cases | FD3: ="Cum "&'[47]Weekly Progress Report'!X64 -> Cum Vehicle Incident | FE3: ="Cum "&'[47]Weekly Progress Report'!X65 -> Cum Property Damages | FF3: ="Cum "&'[47]Weekly Progress Report'!X66 -> Cum Induction Training | FG3: ="Cum "&'[47]Weekly Progress Report'!X67 -> Cum No.of Internal Training | FH3: ="Cum "&'[47]Weekly Progress Report'!X68 -> Cum No.of Internal Audit | FI3: ="Cum "&'[47]Weekly Progress Report'!X69 -> Cum No. of Toolbox Talks | FJ3: ="Cum "&'[47]Weekly Progress Report'!X70 -> Cum Safety Awards/Incentives | FK3: ='[47]Weekly Progress Report'!A82 -> Total Act. | FL3: ='[47]Weekly Progress Report'!B82 -> Not Started | FM3: ='[47]Weekly Progress Report'!C82 -> In Progress | FN3: ='[47]Weekly Progress Report'!D82 -> Completed | FO3: Critical Path Act.Last Week | FP3: Critical Path Act.This Week | FQ3: Failed start Last Week | FR3: Failed start This Week | FS3: ='[47]Weekly Progress Report'!B90 -> 0 | FT3: ='[47]Weekly Progress Report'!D90 -> 0 | FU3: ='[47]Weekly Progress Report'!F90 -> 0 | FV3: ='[47]Weekly Progress Report'!H90 -> 0 | FW3: ='[47]Weekly Progress Report'!J90 -> 0 | FX3: ='[47]Weekly Progress Report'!L90 -> 0 | FY3: ='[47]Weekly Progress Report'!N90 -> 0 | FZ3: ='[47]Weekly Progress Report'!O90 -> 0 | GA3: ='[47]Weekly Progress Report'!P90 -> 0
A4: ='[47]Weekly Progress Report'!AG1 -> 45503 | B4: ='[47]Weekly Progress Report'!B3 -> Hail - Developing of Infrastructure Hail industrial city PHASE II - Eastern side Project | C4: ='[47]Weekly Progress Report'!B4 -> HAL1-02-005 | D4: ='[47]Weekly Progress Report'!B5 -> Shibh Aljazira Contracting Company | E4: ='[47]Weekly Progress Report'!B6 -> JASARA Program Managemant Company | F4: ='[47]Weekly Progress Report'!E4 -> Construction | G4: ='[47]Weekly Progress Report'!E5 -> Active | H4: ='[47]Weekly Progress Report'!E6 -> Abdulaziz M. Al-Musallam | I4: ='[47]Weekly Progress Report'!AA3 -> The project consists of the POND A which works as a downstream for the storm water wet utility piping network including manholes and catch basins, continued project wet utilities also sewerage GRP piping network with manholes, potable water and firefighting compound HDPE piping network including the installation of valves and fire hydrants and the irrigation water (TSE) network with all valves and the flow meter, dry utility represented in electrical road lighting network - the installation of poles and the LV cables which is connected to the panel board and the 13.8/0.4 K V unit substation. | J4: ='[47]Weekly Progress Report'!H3 -> 45186 | K4: ='[47]Weekly Progress Report'!H4 -> 45280 | L4: ='[47]Weekly Progress Report'!H5 -> 45298 | M4: ='[47]Weekly Progress Report'!H6 -> 46028 | N4: ='[47]Weekly Progress Report'!$J$3 -> 45186 | O4: ='[47]Weekly Progress Report'!$J$4 -> 45280 | P4: ='[47]Weekly Progress Report'!$J$5 -> 45298 | Q4: ='[47]Weekly Progress Report'!$J$6 -> 46028 | R4: ='[47]Weekly Progress Report'!$L$3 -> 46028 | S4: ='[47]Weekly Progress Report'!$L$4 -> 46028 | T4: ='[47]Weekly Progress Report'!$L$5 -> 46051 | U4: ='[47]Weekly Progress Report'!$O$3 -> 45093675 | V4: ='[47]Weekly Progress Report'!$O$4 -> 45093675 | W4: ='[47]Weekly Progress Report'!$O$5 -> 45093675 | X4: ='[47]Weekly Progress Report'!$O$6 -> 0 | Y4: ='[47]Weekly Progress Report'!$S$3 -> 0 | Z4: ='[47]Weekly Progress Report'!$S$4 -> 5707774.5 | AA4: ='[47]Weekly Progress Report'!$S$5 -> -579777.45 | AB4: ='[47]Weekly Progress Report'!$S$6 -> 450291.6 | AC4: ='[47]Weekly Progress Report'!$J$22 -> 0.16837174 | AD4: ='[47]Weekly Progress Report'!$V$3 -> 0.16837174 | AE4: ='[47]Weekly Progress Report'!$V$4 -> 0.32293379 | AF4: ='[47]Weekly Progress Report'!$X$3 -> 0.18753642 | AG4: ='[47]Weekly Progress Report'!$X$4 -> 0.29839637 | AH4: ='[47]Weekly Progress Report'!$Z$3 -> 0.9087931 | AI4: ='[47]Weekly Progress Report'!$Z$5 -> 0.875 | AJ4: ='[47]Weekly Progress Report'!$E$22 -> 480506.96 | AK4: ='[47]Weekly Progress Report'!$F$22 -> 439683.4 | AL4: =AJ4/V4 -> 0.010655751 | AM4: =AK4/V4 -> 0.009750445 | AN4: ='[47]Weekly Progress Report'!S22 -> 0.010957581 | AO4: ='[47]Weekly Progress Report'!T22 -> 0.014106639 | AP4: ='[47]Weekly Progress Report'!C60 -> 85 | AQ4: ='[47]Weekly Progress Report'!I60 -> 6 | AR4: ='[47]Weekly Progress Report'!J60 -> 0 | AS4: ='[47]Weekly Progress Report'!K60 -> 79 | AT4: ='[47]Weekly Progress Report'!C69 -> 102 | AU4: ='[47]Weekly Progress Report'!J69 -> 1 | AV4: ='[47]Weekly Progress Report'!K69 -> 39 | AW4: ='[47]Weekly Progress Report'!C78 -> 31 | AX4: ='[47]Weekly Progress Report'!D78 -> 28 | AY4: ='[47]Weekly Progress Report'!E78 -> 5 | AZ4: ='[47]Weekly Progress Report'!F78 -> 23 | BA4: ='[47]Weekly Progress Report'!G78 -> 4 | BB4: ='[47]Weekly Progress Report'!H78 -> 27 | BC4: ='[47]Weekly Progress Report'!I78 -> 45533 | BD4: ='[47]Weekly Progress Report'!N56 -> 3 | BE4: ='[47]Weekly Progress Report'!O56 -> 3 | BF4: ='[47]Weekly Progress Report'!P56 -> 0 | BG4: ='[47]Weekly Progress Report'!Q56 -> 0 | BH4: ='[47]Weekly Progress Report'!N57 -> 3 | BI4: ='[47]Weekly Progress Report'!O57 -> 3 | BJ4: ='[47]Weekly Progress Report'!P57 -> 0 | BK4: ='[47]Weekly Progress Report'!Q57 -> 0 | BL4: ='[47]Weekly Progress Report'!N58 -> 30 | BM4: ='[47]Weekly Progress Report'!O58 -> 29 | BN4: ='[47]Weekly Progress Report'!P58 -> 1 | BO4: ='[47]Weekly Progress Report'!Q58 -> 0 | BP4: ='[47]Weekly Progress Report'!N59 -> 489 | BQ4: ='[47]Weekly Progress Report'!O59 -> 460 | BR4: ='[47]Weekly Progress Report'!P59 -> 29 | BS4: ='[47]Weekly Progress Report'!Q59 -> 0 | BT4: ='[47]Weekly Progress Report'!O61 -> 45346 | BU4: ='[47]Weekly Progress Report'!O62 -> 45346 | BV4: ='[47]Weekly Progress Report'!O63 -> 45350 | BW4: ='[47]Weekly Progress Report'!O64 -> 45350 | BX4: ='[47]Weekly Progress Report'!O65 -> 45348 | BY4: ='[47]Weekly Progress Report'!U61 -> 45361 | BZ4: ='[47]Weekly Progress Report'!U62 -> 1 | CA4: ='[47]Weekly Progress Report'!U63 -> 45361 | CB4: ='[47]Weekly Progress Report'!U64 -> 0 | CC4: ='[47]Weekly Progress Report'!U65 -> 1 | CD4: ='[47]Weekly Progress Report'!N67 -> 4 | CE4: ='[47]Weekly Progress Report'!N68 -> 0 | CF4: ='[47]Weekly Progress Report'!N69 -> 0 | CG4: ='[47]Weekly Progress Report'!N70 -> 0 | CH4: ='[47]Weekly Progress Report'!N71 -> 0.1 | CI4: ='[47]Weekly Progress Report'!N72 -> 0 | CJ4: ='[47]Weekly Progress Report'!N73 -> 0.00019958453 | CK4: ='[47]Weekly Progress Report'!R67 -> 5707774.5 | CL4: ='[47]Weekly Progress Report'!R68 -> 0 | CM4: ='[47]Weekly Progress Report'!R69 -> 0 | CN4: ='[47]Weekly Progress Report'!R70 -> 45473 | CO4: ='[47]Weekly Progress Report'!R71 -> 4509367.5 | CP4: ='[47]Weekly Progress Report'!R72 -> 0 | CQ4: ='[47]Weekly Progress Report'!R73 -> -9000 | CR4: ='[47]Weekly Progress Report'!L77 -> 30 | CS4: ='[47]Weekly Progress Report'!M77 -> 26 | CT4: ='[47]Weekly Progress Report'!O77 -> 4 | CU4: ='[47]Weekly Progress Report'!P77 -> 86 | CV4: ='[47]Weekly Progress Report'!Q77 -> 90 | CW4: ='[47]Weekly Progress Report'!T87 -> 37 | CX4: ='[47]Weekly Progress Report'!U87 -> 45 | CY4: ='[47]Weekly Progress Report'!Z55 -> 5568 | CZ4: ='[47]Weekly Progress Report'!Z56 -> 5568 | DA4: ='[47]Weekly Progress Report'!Z57 -> 0 | DB4: ='[47]Weekly Progress Report'!Z58 -> 0 | DC4: ='[47]Weekly Progress Report'!Z59 -> 0 | DD4: ='[47]Weekly Progress Report'!Z60 -> 0 | DE4: ='[47]Weekly Progress Report'!Z61 -> 0 | DF4: ='[47]Weekly Progress Report'!Z62 -> 0 | DG4: ='[47]Weekly Progress Report'!Z63 -> 0 | DH4: ='[47]Weekly Progress Report'!Z64 -> 0 | DI4: ='[47]Weekly Progress Report'!Z65 -> 0 | DJ4: ='[47]Weekly Progress Report'!Z66 -> 0 | DK4: ='[47]Weekly Progress Report'!Z67 -> 0 | DL4: ='[47]Weekly Progress Report'!Z68 -> 0 | DM4: ='[47]Weekly Progress Report'!Z69 -> 1(50) | DN4: ='[47]Weekly Progress Report'!Z70 -> 0 | DO4: ='[47]Weekly Progress Report'!AB55 -> 26288 | DP4: ='[47]Weekly Progress Report'!AB56 -> 26288 | DQ4: ='[47]Weekly Progress Report'!AB57 -> 0 | DR4: ='[47]Weekly Progress Report'!AB58 -> 0 | DS4: ='[47]Weekly Progress Report'!AB59 -> 0 | DT4: ='[47]Weekly Progress Report'!AB60 -> 0 | DU4: ='[47]Weekly Progress Report'!AB61 -> 2 | DV4: ='[47]Weekly Progress Report'!AB62 -> 0 | DW4: ='[47]Weekly Progress Report'!AB63 -> 0 | DX4: ='[47]Weekly Progress Report'!AB64 -> 0 | DY4: ='[47]Weekly Progress Report'!AB65 -> 0 | DZ4: ='[47]Weekly Progress Report'!AB66 -> 22(28) | EA4: ='[47]Weekly Progress Report'!AB67 -> 1 (4) | EB4: ='[47]Weekly Progress Report'!AB68 -> 0 | EC4: ='[47]Weekly Progress Report'!AB69 -> 3(122) | ED4: ='[47]Weekly Progress Report'!AB70 -> 0 | EE4: ='[47]Weekly Progress Report'!AC55 -> 86904 | EF4: ='[47]Weekly Progress Report'!AC56 -> 86904 | EG4: ='[47]Weekly Progress Report'!AC57 -> 0 | EH4: ='[47]Weekly Progress Report'!AC58 -> 0 | EI4: ='[47]Weekly Progress Report'!AC59 -> 0 | EJ4: ='[47]Weekly Progress Report'!AC60 -> 2 | EK4: ='[47]Weekly Progress Report'!AC61 -> 2 | EL4: ='[47]Weekly Progress Report'!AC62 -> 0 | EM4: ='[47]Weekly Progress Report'!AC63 -> 0 | EN4: ='[47]Weekly Progress Report'!AC64 -> 0 | EO4: ='[47]Weekly Progress Report'!AC65 -> 1 | EP4: ='[47]Weekly Progress Report'!AC66 -> 43(106) | EQ4: ='[47]Weekly Progress Report'!AC67 -> 8(56) | ER4: ='[47]Weekly Progress Report'!AC68 -> 3 | ES4: ='[47]Weekly Progress Report'!AC69 -> 17(592) | ET4: ='[47]Weekly Progress Report'!AC70 -> 4 | EU4: ='[47]Weekly Progress Report'!AD55 -> 86904 | EV4: ='[47]Weekly Progress Report'!AD56 -> 86904 | EW4: ='[47]Weekly Progress Report'!AD57 -> 0 | EX4: ='[47]Weekly Progress Report'!AD58 -> 0 | EY4: ='[47]Weekly Progress Report'!AD59 -> 0 | EZ4: ='[47]Weekly Progress Report'!AD60 -> 2 | FA4: ='[47]Weekly Progress Report'!AD61 -> 2 | FB4: ='[47]Weekly Progress Report'!AD62 -> 0 | FC4: ='[47]Weekly Progress Report'!AD63 -> 0 | FD4: ='[47]Weekly Progress Report'!AD64 -> 0 | FE4: ='[47]Weekly Progress Report'!AD65 -> 1 | FF4: ='[47]Weekly Progress Report'!AD66 -> 43(106) | FG4: ='[47]Weekly Progress Report'!AD67 -> 8(56) | FH4: ='[47]Weekly Progress Report'!AD68 -> 3 | FI4: ='[47]Weekly Progress Report'!AD69 -> 17(592) | FJ4: ='[47]Weekly Progress Report'!AD70 -> 4 | FK4: ='[47]Weekly Progress Report'!A83 -> 1116 | FL4: ='[47]Weekly Progress Report'!B83 -> 750 | FM4: ='[47]Weekly Progress Report'!C83 -> 167 | FN4: ='[47]Weekly Progress Report'!D83 -> 199 | FO4: ='[47]Weekly Progress Report'!A87 -> 170 | FP4: ='[47]Weekly Progress Report'!B87 -> 149 | FQ4: ='[47]Weekly Progress Report'!H87 -> 27 | FR4: ='[47]Weekly Progress Report'!I87 -> 20 | FS4: ='[47]Weekly Progress Report'!B95 -> 0 | FT4: ='[47]Weekly Progress Report'!D95 -> 0 | FU4: ='[47]Weekly Progress Report'!F95 -> 0 | FV4: ='[47]Weekly Progress Report'!H95 -> 0 | FW4: ='[47]Weekly Progress Report'!J95 -> 0 | FX4: ='[47]Weekly Progress Report'!L95 -> 0 | FY4: ='[47]Weekly Progress Report'!N95 -> 0 | FZ4: ='[47]Weekly Progress Report'!O95 -> 0 | GA4: ='[47]Weekly Progress Report'!P95 -> 0

Sheet Sheet3
A1: ='Weekly Progress Report'!$A$1 -> MODON - Weekly Progress Report - Construction Projects
B2: ='Weekly Progress Report'!$A$2 -> Contract General Information
A3: ='Weekly Progress Report'!AF1 -> Data Date | B3: ='Weekly Progress Report'!A3 -> Project Name | C3: ='Weekly Progress Report'!A4 -> Project ID | D3: ='Weekly Progress Report'!A5 -> Contractor | E3: ='Weekly Progress Report'!A6 -> Consultant | F3: ='Weekly Progress Report'!D4 -> Stage | G3: ='Weekly Progress Report'!D5 -> Status | H3: ='Weekly Progress Report'!D6 -> Modon PM | I3: ='Weekly Progress Report'!AA2 -> Project Scope | J3: ='Weekly Progress Report'!G3 -> Contract Award | K3: ='Weekly Progress Report'!G4 -> Contract Sign | L3: ='Weekly Progress Report'!G5 -> Site Handover | M3: ='Weekly Progress Report'!G6 -> Original Completion | N3: ='Weekly Progress Report'!I3 -> Contract Award (Hijri) | O3: ='Weekly Progress Report'!I4 -> Contract Sign (Hijri) | P3: ='Weekly Progress Report'!I5 -> Site Handover (Hijri) | Q3: ='Weekly Progress Report'!I6 -> Original Completion (Hijri) | R3: ='Weekly Progress Report'!K3 -> Revised Completion | S3: ='Weekly Progress Report'!K4 -> Committed Completion | T3: ='Weekly Progress Report'!K5 -> Forecast Completion | U3: ='Weekly Progress Report'!M3 -> Original Contract Value | V3: ='Weekly Progress Report'!M4 -> Revised Contract Value | W3: ='Weekly Progress Report'!M5 -> Estimate At Completion Value | X3: ='Weekly Progress Report'!M6 -> Potential Changes | Y3: ='Weekly Progress Report'!Q3 -> O&M Value (if any) | Z3: ='Weekly Progress Report'!Q4 -> Submitted Invoices (Gross Value) | AA3: ='Weekly Progress Report'!Q5 -> Penalities | AB3: ='Weekly Progress Report'!Q6 -> FIR Value (Todate) | AC3: Original Plan Value | AD3: ='Weekly Progress Report'!U3 -> Plan Value | AE3: ='Weekly Progress Report'!U4 -> Earn Value | AF3: ='Weekly Progress Report'!W3 -> Phys. Plan Value | AG3: ='Weekly Progress Report'!W4 -> Phys. Earn Value | AH3: ='Weekly Progress Report'!Y3 -> Quality Score | AI3: ='Weekly Progress Report'!Y5 -> Safety Score | AJ3: Weekly PV (SAR) | AK3: Weekly EV (SAR) | AL3: Weekly PV % | AM3: Weekly PV % | AN3: Weekly Phys PV% | AO3: Weekly Phys PV% | AP3: Total SD Planned | AQ3: SD Remaining | AR3: SD Pending | AS3: Total SD Submittals | AT3: Planned Materials Approv | AU3: Material Pending Approval | AV3: Materila Total Submittals | AW3: ='[47]Weekly Progress Report'!C71 -> Total Materials | AX3: ='[47]Weekly Progress Report'!D71 -> Total Number of P.O. | AY3: ='[47]Weekly Progress Report'!E71 -> Actual P.O. To Date | AZ3: ='[47]Weekly Progress Report'!F71 -> Remaining P.O | BA3: ='[47]Weekly Progress Report'!G71 -> Material on Site | BB3: ='[47]Weekly Progress Report'!H71 -> Remaining Materials | BC3: ='[47]Weekly Progress Report'!I71 -> Material Delivery Completion (Date) | BD3: ="NCR "&'[47]Weekly Progress Report'!N53 -> NCR Issued | BE3: ="NCR "&'[47]Weekly Progress Report'!O53 -> NCR Closed | BF3: ="NCR "&'[47]Weekly Progress Report'!P53 -> NCR Pending | BG3: ="NCR "&'[47]Weekly Progress Report'!Q53 -> NCR Avg. Closing (Days) | BH3: ="SIR "&'[47]Weekly Progress Report'!N53 -> SIR Issued | BI3: ="SIR "&'[47]Weekly Progress Report'!O53 -> SIR Closed | BJ3: ="SIR "&'[47]Weekly Progress Report'!P53 -> SIR Pending | BK3: ="SIR "&'[47]Weekly Progress Report'!Q53 -> SIR Avg. Closing (Days) | BL3: ="MIR "&'[47]Weekly Progress Report'!N53 -> MIR Issued | BM3: ="MIR "&'[47]Weekly Progress Report'!O53 -> MIR Closed | BN3: ="MIR "&'[47]Weekly Progress Report'!P53 -> MIR Pending | BO3: ="MIR "&'[47]Weekly Progress Report'!Q53 -> MIR Avg. Closing (Days) | BP3: ="FIR "&'[47]Weekly Progress Report'!N53 -> FIR Issued | BQ3: ="FIR "&'[47]Weekly Progress Report'!O53 -> FIR Closed | BR3: ="FIR "&'[47]Weekly Progress Report'!P53 -> FIR Pending | BS3: ="FIR "&'[47]Weekly Progress Report'!Q53 -> FIR Avg. Closing (Days) | BT3: ='[47]Weekly Progress Report'!L61 -> 1 Quality Plan Approval | BU3: ='[47]Weekly Progress Report'!L62 -> 2 Quality Plan Last Up | BV3: ='[47]Weekly Progress Report'!L63 -> 3 Safety Plan Approval | BW3: ='[47]Weekly Progress Report'!L64 -> 4 Safety Plan Last Up | BX3: ='[47]Weekly Progress Report'!L65 -> 5 Construction Plan Approval | BY3: ='[47]Weekly Progress Report'!Q61 -> 6 Baseline Approval | BZ3: ='[47]Weekly Progress Report'!Q62 -> 7 No of Approved Version of Schedule | CA3: ='[47]Weekly Progress Report'!Q63 -> 8 Last Approved Schedule | CB3: ='[47]Weekly Progress Report'!Q64 -> 9 BOQ Approval Date | CC3: ='[47]Weekly Progress Report'!Q65 -> 10 No of Approved Version of BOQ | CD3: ='[47]Weekly Progress Report'!L67 -> Total Submitted Invoices | CE3: ='[47]Weekly Progress Report'!L68 -> PM Approved Invoices | CF3: ='[47]Weekly Progress Report'!L69 -> No of Paid Invoices | CG3: ='[47]Weekly Progress Report'!L70 -> No of Pending Invoices | CH3: ='[47]Weekly Progress Report'!L71 -> Advance Payment % | CI3: ='[47]Weekly Progress Report'!L72 -> Retention % | CJ3: ='[47]Weekly Progress Report'!L73 -> Deduction / Penalties % | CK3: ='[47]Weekly Progress Report'!O67 -> Submitted Invoices (SAR) | CL3: ='[47]Weekly Progress Report'!O68 -> PM Approved Invoices (SAR) | CM3: ='[47]Weekly Progress Report'!O69 -> Paid Invoices (SAR) | CN3: ='[47]Weekly Progress Report'!O70 -> Last Submitted Period | CO3: ='[47]Weekly Progress Report'!O71 -> Advance Payment (SAR) | CP3: ='[47]Weekly Progress Report'!O72 -> Retention (SAR) | CQ3: ='[47]Weekly Progress Report'!O73 -> Deduction / Penalties (SAR) | CR3: Planned Head Count | CS3: Actual Head Count | CT3: Saudi Staff | CU3: Labor Planned | CV3: Labor Actual | CW3: Equipment Planned | CX3: Equipment Actual | CY3: ="This Week "&'[47]Weekly Progress Report'!X55 -> This Week Total Hours Worked | CZ3: ="This Week "&'[47]Weekly Progress Report'!X56 -> This Week Safe Hours Worked | DA3: ="This Week "&'[47]Weekly Progress Report'!X57 -> This Week LTI | DB3: ="This Week "&'[47]Weekly Progress Report'!X58 -> This Week MTC (Healed w/o Disability) | DC3: ="This Week "&'[47]Weekly Progress Report'!X59 -> This Week MTC (Healed w/ Disability) | DD3: ="This Week "&'[47]Weekly Progress Report'!X60 -> This Week Near Miss | DE3: ="This Week "&'[47]Weekly Progress Report'!X61 -> This Week First Aid Cases | DF3: ="This Week "&'[47]Weekly Progress Report'!X62 -> This Week Fatality | DG3: ="This Week "&'[47]Weekly Progress Report'!X63 -> This Week Fire Incident Cases | DH3: ="This Week "&'[47]Weekly Progress Report'!X64 -> This Week Vehicle Incident | DI3: ="This Week "&'[47]Weekly Progress Report'!X65 -> This Week Property Damages | DJ3: ="This Week "&'[47]Weekly Progress Report'!X66 -> This Week Induction Training | DK3: ="This Week "&'[47]Weekly Progress Report'!X67 -> This Week No.of Internal Training | DL3: ="This Week "&'[47]Weekly Progress Report'!X68 -> This Week No.of Internal Audit | DM3: ="This Week "&'[47]Weekly Progress Report'!X69 -> This Week No. of Toolbox Talks | DN3: ="This Week "&'[47]Weekly Progress Report'!X70 -> This Week Safety Awards/Incentives | DO3: ="This Month "&'[47]Weekly Progress Report'!X55 -> This Month Total Hours Worked | DP3: ="This Month "&'[47]Weekly Progress Report'!X56 -> This Month Safe Hours Worked | DQ3: ="This Month "&'[47]Weekly Progress Report'!X57 -> This Month LTI | DR3: ="This Month "&'[47]Weekly Progress Report'!X58 -> This Month MTC (Healed w/o Disability) | DS3: ="This Month "&'[47]Weekly Progress Report'!X59 -> This Month MTC (Healed w/ Disability) | DT3: ="This Month "&'[47]Weekly Progress Report'!X60 -> This Month Near Miss | DU3: ="This Month "&'[47]Weekly Progress Report'!X61 -> This Month First Aid Cases | DV3: ="This Month "&'[47]Weekly Progress Report'!X62 -> This Month Fatality | DW3: ="This Month "&'[47]Weekly Progress Report'!X63 -> This Month Fire Incident Cases | DX3: ="This Month "&'[47]Weekly Progress Report'!X64 -> This Month Vehicle Incident | DY3: ="This Month "&'[47]Weekly Progress Report'!X65 -> This Month Property Damages | DZ3: ="This Month "&'[47]Weekly Progress Report'!X66 -> This Month Induction Training | EA3: ="This Month "&'[47]Weekly Progress Report'!X67 -> This Month No.of Internal Training | EB3: ="This Month "&'[47]Weekly Progress Report'!X68 -> This Month No.of Internal Audit | EC3: ="This Month "&'[47]Weekly Progress Report'!X69 -> This Month No. of Toolbox Talks | ED3: ="This Month "&'[47]Weekly Progress Report'!X70 -> This Month Safety Awards/Incentives | EE3: ="YTD "&'[47]Weekly Progress Report'!X55 -> YTD Total Hours Worked | EF3: ="YTD "&'[47]Weekly Progress Report'!X56 -> YTD Safe Hours Worked | EG3: ="YTD "&'[47]Weekly Progress Report'!X57 -> YTD LTI | EH3: ="YTD "&'[47]Weekly Progress Report'!X58 -> YTD MTC (Healed w/o Disability) | EI3: ="YTD "&'[47]Weekly Progress Report'!X59 -> YTD MTC (Healed w/ Disability) | EJ3: ="YTD "&'[47]Weekly Progress Report'!X60 -> YTD Near Miss | EK3: ="YTD "&'[47]Weekly Progress Report'!X61 -> YTD First Aid Cases | EL3: ="YTD "&'[47]Weekly Progress Report'!X62 -> YTD Fatality | EM3: ="YTD "&'[47]Weekly Progress Report'!X63 -> YTD Fire Incident Cases | EN3: ="YTD "&'[47]Weekly Progress Report'!X64 -> YTD Vehicle Incident | EO3: ="YTD "&'[47]Weekly Progress Report'!X65 -> YTD Property Damages | EP3: ="YTD "&'[47]Weekly Progress Report'!X66 -> YTD Induction Training | EQ3: ="YTD "&'[47]Weekly Progress Report'!X67 -> YTD No.of Internal Training | ER3: ="YTD "&'[47]Weekly Progress Report'!X68 -> YTD No.of Internal Audit | ES3: ="YTD "&'[47]Weekly Progress Report'!X69 -> YTD No. of Toolbox Talks | ET3: ="YTD "&'[47]Weekly Progress Report'!X70 -> YTD Safety Awards/Incentives | EU3: ="Cum "&'[47]Weekly Progress Report'!X55 -> Cum Total Hours Worked | EV3: ="Cum "&'[47]Weekly Progress Report'!X56 -> Cum Safe Hours Worked | EW3: ="Cum "&'[47]Weekly Progress Report'!X57 -> Cum LTI | EX3: ="Cum "&'[47]Weekly Progress Report'!X58 -> Cum MTC (Healed w/o Disability) | EY3: ="Cum "&'[47]Weekly Progress Report'!X59 -> Cum MTC (Healed w/ Disability) | EZ3: ="Cum "&'[47]Weekly Progress Report'!X60 -> Cum Near Miss | FA3: ="Cum "&'[47]Weekly Progress Report'!X61 -> Cum First Aid Cases | FB3: ="Cum "&'[47]Weekly Progress Report'!X62 -> Cum Fatality | FC3: ="Cum "&'[47]Weekly Progress Report'!X63 -> Cum Fire Incident Cases | FD3: ="Cum "&'[47]Weekly Progress Report'!X64 -> Cum Vehicle Incident | FE3: ="Cum "&'[47]Weekly Progress Report'!X65 -> Cum Property Damages | FF3: ="Cum "&'[47]Weekly Progress Report'!X66 -> Cum Induction Training | FG3: ="Cum "&'[47]Weekly Progress Report'!X67 -> Cum No.of Internal Training | FH3: ="Cum "&'[47]Weekly Progress Report'!X68 -> Cum No.of Internal Audit | FI3: ="Cum "&'[47]Weekly Progress Report'!X69 -> Cum No. of Toolbox Talks | FJ3: ="Cum "&'[47]Weekly Progress Report'!X70 -> Cum Safety Awards/Incentives | FK3: ='[47]Weekly Progress Report'!A82 -> Total Act. | FL3: ='[47]Weekly Progress Report'!B82 -> Not Started | FM3: ='[47]Weekly Progress Report'!C82 -> In Progress | FN3: ='[47]Weekly Progress Report'!D82 -> Completed | FO3: Critical Path Act.Last Week | FP3: Critical Path Act.This Week | FQ3: Failed start Last Week | FR3: Failed start This Week | FS3: ='[47]Weekly Progress Report'!B90 -> 0 | FT3: ='[47]Weekly Progress Report'!D90 -> 0 | FU3: ='[47]Weekly Progress Report'!F90 -> 0 | FV3: ='[47]Weekly Progress Report'!H90 -> 0 | FW3: ='[47]Weekly Progress Report'!J90 -> 0 | FX3: ='[47]Weekly Progress Report'!L90 -> 0 | FY3: ='[47]Weekly Progress Report'!N90 -> 0 | FZ3: ='[47]Weekly Progress Report'!O90 -> 0 | GA3: ='[47]Weekly Progress Report'!P90 -> 0
A4: ='Weekly Progress Report'!AG1 -> 46313 | B4: ='Weekly Progress Report'!B3 -> Playgrounds Initiative - Qassim, Hail & Tabuk | C4: ='Weekly Progress Report'!B4 -> MLTX-02-003 | D4: ='Weekly Progress Report'!B5 -> Advanced Construction & Contracting Company | E4: ='Weekly Progress Report'!B6 -> Egis | F4: ='Weekly Progress Report'!E4 -> Construction | G4: ='Weekly Progress Report'!E5 -> Active | H4: ='Weekly Progress Report'!E6 -> Bader Alrowaidan | I4: ='Weekly Progress Report'!AA3 -> Construction of Playgrounds Initiatives at 03 Location(Qassim, Hail, Tabuk). The project includes civil, architectural, electrical, mechanical and landscape works, as well as general site works, according to the plans and technical specifications. | J4: ='Weekly Progress Report'!H3 -> 46028 | K4: ='Weekly Progress Report'!H4 -> 46070 | L4: ='Weekly Progress Report'!H5 -> 46070 | M4: ='Weekly Progress Report'!H6 -> 46372 | N4: ='Weekly Progress Report'!J3 -> 46028 | O4: ='Weekly Progress Report'!J4 -> 46070 | P4: ='Weekly Progress Report'!J5 -> 46070 | Q4: ='Weekly Progress Report'!J6 -> 46372 | R4: ='Weekly Progress Report'!L3 -> 46372 | S4: ='Weekly Progress Report'!L4 -> 46372 | T4: ='Weekly Progress Report'!L5 -> 46425 | U4: ='Weekly Progress Report'!O3 -> 35709993 | V4: ='Weekly Progress Report'!O4 -> 35709993 | W4: ='Weekly Progress Report'!O5 -> 35709993 | X4: ='Weekly Progress Report'!O6 -> 0 | Y4: ='Weekly Progress Report'!S3 -> 0 | Z4: ='Weekly Progress Report'!S4 -> 2317493.3 | AA4: ='Weekly Progress Report'!S5 -> -250749.33 | AB4: ='Weekly Progress Report'!S6 -> 3298582.9 | AC4: ='Weekly Progress Report'!J18 -> 0.80317475 | AD4: ='Weekly Progress Report'!V3 -> 0.80317475 | AE4: ='Weekly Progress Report'!V4 -> 0.69001808 | AF4: ='Weekly Progress Report'!X3 -> 0.8024895 | AG4: ='Weekly Progress Report'!X4 -> 0.74790042 | AH4: ='Weekly Progress Report'!Z3 -> 0.91310345 | AI4: ='Weekly Progress Report'!Z5 -> 0.91304348 | AJ4: ='Weekly Progress Report'!E18 -> 28512896 | AK4: ='Weekly Progress Report'!F18 -> 24528613 | AL4: =AJ4/V4 -> 0.79845707 | AM4: =AK4/V4 -> 0.68688372 | AN4: ='Weekly Progress Report'!S18 -> 0.7194961 | AO4: ='Weekly Progress Report'!T18 -> 0.66946611 | AP4: ='Weekly Progress Report'!C57 -> 393 | AQ4: ='Weekly Progress Report'!I57 -> 0 | AR4: ='Weekly Progress Report'!J57 -> 44 | AS4: ='Weekly Progress Report'!K57 -> 393 | AT4: ='Weekly Progress Report'!C67 -> 141 | AU4: ='Weekly Progress Report'!J67 -> 12 | AV4: ='Weekly Progress Report'!K67 -> 141 | AW4: ='Weekly Progress Report'!C76 -> 57 | AX4: ='Weekly Progress Report'!D76 -> 57 | AY4: ='Weekly Progress Report'!E76 -> 33 | AZ4: ='Weekly Progress Report'!F76 -> 25 | BA4: ='Weekly Progress Report'!G76 -> 8 | BB4: ='Weekly Progress Report'!H76 -> 0 | BC4: ='Weekly Progress Report'!I76 | BD4: ='[47]Weekly Progress Report'!N56 -> 3 | BE4: ='[47]Weekly Progress Report'!O56 -> 3 | BF4: ='[47]Weekly Progress Report'!P56 -> 0 | BG4: ='[47]Weekly Progress Report'!Q56 -> 0 | BH4: ='[47]Weekly Progress Report'!N57 -> 3 | BI4: ='[47]Weekly Progress Report'!O57 -> 3 | BJ4: ='[47]Weekly Progress Report'!P57 -> 0 | BK4: ='[47]Weekly Progress Report'!Q57 -> 0 | BL4: ='[47]Weekly Progress Report'!N58 -> 30 | BM4: ='[47]Weekly Progress Report'!O58 -> 29 | BN4: ='[47]Weekly Progress Report'!P58 -> 1 | BO4: ='[47]Weekly Progress Report'!Q58 -> 0 | BP4: ='[47]Weekly Progress Report'!N59 -> 489 | BQ4: ='[47]Weekly Progress Report'!O59 -> 460 | BR4: ='[47]Weekly Progress Report'!P59 -> 29 | BS4: ='[47]Weekly Progress Report'!Q59 -> 0 | BT4: ='[47]Weekly Progress Report'!O61 -> 45346 | BU4: ='[47]Weekly Progress Report'!O62 -> 45346 | BV4: ='[47]Weekly Progress Report'!O63 -> 45350 | BW4: ='[47]Weekly Progress Report'!O64 -> 45350 | BX4: ='[47]Weekly Progress Report'!O65 -> 45348 | BY4: ='[47]Weekly Progress Report'!U61 -> 45361 | BZ4: ='[47]Weekly Progress Report'!U62 -> 1 | CA4: ='[47]Weekly Progress Report'!U63 -> 45361 | CB4: ='[47]Weekly Progress Report'!U64 -> 0 | CC4: ='[47]Weekly Progress Report'!U65 -> 1 | CD4: ='[47]Weekly Progress Report'!N67 -> 4 | CE4: ='[47]Weekly Progress Report'!N68 -> 0 | CF4: ='[47]Weekly Progress Report'!N69 -> 0 | CG4: ='[47]Weekly Progress Report'!N70 -> 0 | CH4: ='[47]Weekly Progress Report'!N71 -> 0.1 | CI4: ='[47]Weekly Progress Report'!N72 -> 0 | CJ4: ='[47]Weekly Progress Report'!N73 -> 0.00019958453 | CK4: ='[47]Weekly Progress Report'!R67 -> 5707774.5 | CL4: ='[47]Weekly Progress Report'!R68 -> 0 | CM4: ='[47]Weekly Progress Report'!R69 -> 0 | CN4: ='[47]Weekly Progress Report'!R70 -> 45473 | CO4: ='[47]Weekly Progress Report'!R71 -> 4509367.5 | CP4: ='[47]Weekly Progress Report'!R72 -> 0 | CQ4: ='[47]Weekly Progress Report'!R73 -> -9000 | CR4: ='[47]Weekly Progress Report'!L77 -> 30 | CS4: ='[47]Weekly Progress Report'!M77 -> 26 | CT4: ='[47]Weekly Progress Report'!O77 -> 4 | CU4: ='[47]Weekly Progress Report'!P77 -> 86 | CV4: ='[47]Weekly Progress Report'!Q77 -> 90 | CW4: ='[47]Weekly Progress Report'!T87 -> 37 | CX4: ='[47]Weekly Progress Report'!U87 -> 45 | CY4: ='[47]Weekly Progress Report'!Z55 -> 5568 | CZ4: ='[47]Weekly Progress Report'!Z56 -> 5568 | DA4: ='[47]Weekly Progress Report'!Z57 -> 0 | DB4: ='[47]Weekly Progress Report'!Z58 -> 0 | DC4: ='[47]Weekly Progress Report'!Z59 -> 0 | DD4: ='[47]Weekly Progress Report'!Z60 -> 0 | DE4: ='[47]Weekly Progress Report'!Z61 -> 0 | DF4: ='[47]Weekly Progress Report'!Z62 -> 0 | DG4: ='[47]Weekly Progress Report'!Z63 -> 0 | DH4: ='[47]Weekly Progress Report'!Z64 -> 0 | DI4: ='[47]Weekly Progress Report'!Z65 -> 0 | DJ4: ='[47]Weekly Progress Report'!Z66 -> 0 | DK4: ='[47]Weekly Progress Report'!Z67 -> 0 | DL4: ='[47]Weekly Progress Report'!Z68 -> 0 | DM4: ='[47]Weekly Progress Report'!Z69 -> 1(50) | DN4: ='[47]Weekly Progress Report'!Z70 -> 0 | DO4: ='[47]Weekly Progress Report'!AB55 -> 26288 | DP4: ='[47]Weekly Progress Report'!AB56 -> 26288 | DQ4: ='[47]Weekly Progress Report'!AB57 -> 0 | DR4: ='[47]Weekly Progress Report'!AB58 -> 0 | DS4: ='[47]Weekly Progress Report'!AB59 -> 0 | DT4: ='[47]Weekly Progress Report'!AB60 -> 0 | DU4: ='[47]Weekly Progress Report'!AB61 -> 2 | DV4: ='[47]Weekly Progress Report'!AB62 -> 0 | DW4: ='[47]Weekly Progress Report'!AB63 -> 0 | DX4: ='[47]Weekly Progress Report'!AB64 -> 0 | DY4: ='[47]Weekly Progress Report'!AB65 -> 0 | DZ4: ='[47]Weekly Progress Report'!AB66 -> 22(28) | EA4: ='[47]Weekly Progress Report'!AB67 -> 1 (4) | EB4: ='[47]Weekly Progress Report'!AB68 -> 0 | EC4: ='[47]Weekly Progress Report'!AB69 -> 3(122) | ED4: ='[47]Weekly Progress Report'!AB70 -> 0 | EE4: ='[47]Weekly Progress Report'!AC55 -> 86904 | EF4: ='[47]Weekly Progress Report'!AC56 -> 86904 | EG4: ='[47]Weekly Progress Report'!AC57 -> 0 | EH4: ='[47]Weekly Progress Report'!AC58 -> 0 | EI4: ='[47]Weekly Progress Report'!AC59 -> 0 | EJ4: ='[47]Weekly Progress Report'!AC60 -> 2 | EK4: ='[47]Weekly Progress Report'!AC61 -> 2 | EL4: ='[47]Weekly Progress Report'!AC62 -> 0 | EM4: ='[47]Weekly Progress Report'!AC63 -> 0 | EN4: ='[47]Weekly Progress Report'!AC64 -> 0 | EO4: ='[47]Weekly Progress Report'!AC65 -> 1 | EP4: ='[47]Weekly Progress Report'!AC66 -> 43(106) | EQ4: ='[47]Weekly Progress Report'!AC67 -> 8(56) | ER4: ='[47]Weekly Progress Report'!AC68 -> 3 | ES4: ='[47]Weekly Progress Report'!AC69 -> 17(592) | ET4: ='[47]Weekly Progress Report'!AC70 -> 4 | EU4: ='[47]Weekly Progress Report'!AD55 -> 86904 | EV4: ='[47]Weekly Progress Report'!AD56 -> 86904 | EW4: ='[47]Weekly Progress Report'!AD57 -> 0 | EX4: ='[47]Weekly Progress Report'!AD58 -> 0 | EY4: ='[47]Weekly Progress Report'!AD59 -> 0 | EZ4: ='[47]Weekly Progress Report'!AD60 -> 2 | FA4: ='[47]Weekly Progress Report'!AD61 -> 2 | FB4: ='[47]Weekly Progress Report'!AD62 -> 0 | FC4: ='[47]Weekly Progress Report'!AD63 -> 0 | FD4: ='[47]Weekly Progress Report'!AD64 -> 0 | FE4: ='[47]Weekly Progress Report'!AD65 -> 1 | FF4: ='[47]Weekly Progress Report'!AD66 -> 43(106) | FG4: ='[47]Weekly Progress Report'!AD67 -> 8(56) | FH4: ='[47]Weekly Progress Report'!AD68 -> 3 | FI4: ='[47]Weekly Progress Report'!AD69 -> 17(592) | FJ4: ='[47]Weekly Progress Report'!AD70 -> 4 | FK4: ='[47]Weekly Progress Report'!A83 -> 1116 | FL4: ='[47]Weekly Progress Report'!B83 -> 750 | FM4: ='[47]Weekly Progress Report'!C83 -> 167 | FN4: ='[47]Weekly Progress Report'!D83 -> 199 | FO4: ='[47]Weekly Progress Report'!A87 -> 170 | FP4: ='[47]Weekly Progress Report'!B87 -> 149 | FQ4: ='[47]Weekly Progress Report'!H87 -> 27 | FR4: ='[47]Weekly Progress Report'!I87 -> 20 | FS4: ='[47]Weekly Progress Report'!B95 -> 0 | FT4: ='[47]Weekly Progress Report'!D95 -> 0 | FU4: ='[47]Weekly Progress Report'!F95 -> 0 | FV4: ='[47]Weekly Progress Report'!H95 -> 0 | FW4: ='[47]Weekly Progress Report'!J95 -> 0 | FX4: ='[47]Weekly Progress Report'!L95 -> 0 | FY4: ='[47]Weekly Progress Report'!N95 -> 0 | FZ4: ='[47]Weekly Progress Report'!O95 -> 0 | GA4: ='[47]Weekly Progress Report'!P95 -> 0

Sheet Weekly Progress Report
A1: MODON - Weekly Progress Report - Construction Projects | AF1: Data Date | AG1: ='General Information'!M1 -> 46313
A2: Contract General Information | G2: Key Dates | M2: Cost Summary (SR) | U2: Performance Summary | AA2: Project Scope
A3: Project Name | B3: ='General Information'!D3 -> Playgrounds Initiative - Qassim, Hail & Tabuk | G3: Contract Award | H3: ='General Information'!D12 -> 46028 | I3: Contract Award (Hijri) | J3: ='General Information'!D16 -> 46028 | K3: Revised Completion | L3: ='General Information'!D20 -> 46372 | M3: Original Contract Value | O3: ='Invoice Log'!E3 -> 35709993 | Q3: O&M Value (if any) | S3: ='Invoice Log'!I3 -> 0 | T3: EAC | U3: Plan Value | V3: =K18 -> 0.80317475 | W3: Phys. Plan Value | X3: =W18 -> 0.8024895 | Y3: Quality Score | Z3: =Quality!AC10 -> 0.91310345 | AA3: =Progress!B1 -> Construction of Playgrounds Initiatives at 03 Location(Qassim, Hail, Tabuk). The project includes civil, architectural, electrical, mechanical and landscape works, as well as general site works, according to the plans and technical specifications.
A4: Project ID | B4: ='General Information'!D4 -> MLTX-02-003 | D4: Stage | E4: ='General Information'!D7 -> Construction | G4: Contract Sign | H4: ='General Information'!D13 -> 46070 | I4: Contract Sign (Hijri) | J4: ='General Information'!D17 -> 46070 | K4: Committed Completion | L4: ='General Information'!D21 -> 46372 | M4: Revised Contract Value | O4: ='Invoice Log'!E4 -> 35709993 | Q4: Submitted Invoices (Gross Value) | S4: ='Invoice Log'!I5 -> 2317493.3 | T4: EAC | U4: Earn Value | V4: =L18 -> 0.69001808 | W4: Phys. Earn Value | X4: =X18 -> 0.74790042 | Z4: =REPT("¢",IF(INT(+Z3*10)>5,5,INT(+Z3*10)))&REPT("£",IF(INT(+Z3*10)>5,0,5-INT(+Z3*10)))&CHAR(10)&REPT("¢",+IF(INT(+Z3*10)>5,-5+INT(+Z3*10),0))&REPT("£",IF(INT(+Z3*10)>5,10-INT(+Z3*10),5)) -> ¢¢¢¢¢ ¢¢¢¢£
A5: Contractor | B5: ='General Information'!D5 -> Advanced Construction & Contracting Company | D5: Status | E5: ='General Information'!D8 -> Active | G5: Site Handover | H5: ='General Information'!D14 -> 46070 | I5: Site Handover (Hijri) | J5: ='General Information'!D18 -> 46070 | K5: Forecast Completion | L5: ='General Information'!D22 -> 46425 | M5: Estimate At Completion Value | O5: ='Invoice Log'!E5 -> 35709993 | Q5: Penalities | S5: ='Invoice Log'!I6 -> -250749.33 | T5: EAC | U5: Variance | V5: =V4-V3 -> -0.11315666 | W5: Variance | X5: =Y18 -> -0.054589082 | Y5: Safety Score | Z5: ='HSE-Stat'!J23 -> 0.91304348
A6: Consultant | B6: ='General Information'!D6 -> Egis | D6: Modon PM | E6: ='General Information'!D9 -> Bader Alrowaidan | G6: Original Completion | H6: ='General Information'!D15 -> 46372 | I6: Original Completion (Hijri) | J6: ='General Information'!D19 -> 46372 | K6: Variance | L6: ='General Information'!D23 -> -53 | M6: Potential Changes | O6: =O4-O5 -> 0 | Q6: FIR Value (Todate) | S6: ='FIR Summary'!I3 -> 3298582.9 | U6: FIR % | V6: =S6/O4 -> 0.092371423 | W6: Invoiced % | X6: =S4/O4 -> 0.064897613 | Z6: =REPT("¢",IF(INT(+Z5*10)>5,5,INT(+Z5*10)))&REPT("£",IF(INT(+Z5*10)>5,0,5-INT(+Z5*10)))&CHAR(10)&REPT("¢",+IF(INT(+Z5*10)>5,-5+INT(+Z5*10),0))&REPT("£",IF(INT(+Z5*10)>5,10-INT(+Z5*10),5)) -> ¢¢¢¢¢ ¢¢¢¢£
A8: Progress Overview
A9: Earned Value Progress (SAR) | O9: Physical Progress (Effort) | AA9: Earned Value Progress (%)
A10: WBS | C10: BOQ Value (SAR) | D10: % Wt. | E10: Weekly (SAR) | G10: To Date (SAR) | O10: Budgeted | P10: % Wt. | Q10: Weekly Physical Progress | U10: To Date Physical Progress
E11: Planned | F11: Earned | G11: Original Plan | H11: Revised Planned | I11: Earned | J11: Original Plan % | K11: Revised Planned % | L11: Earned % | M11: Variance | N11: SPI | O11: (Manhours) | Q11: Planned | R11: Earned | S11: Plan % | T11: Earned % | U11: Planned | V11: Earned | W11: Plan % | X11: Earned % | Y11: Variance | Z11: SPI
A12: =Progress!A7 -> PROJECT MILESTONE | C12: =Progress!B7 -> 0 | D12: =IF(ISBLANK(C12),"",C12/$C$18) -> 0 | E12: =Progress!D7 -> 0 | F12: =Progress!E7 -> 0 | G12: =Progress!F7 -> 0 | H12: =Progress!G7 -> 0 | I12: =Progress!H7 -> 0 | J12: =IFERROR(IF(ISBLANK(G12),"",G12/C12),0) -> 0 | K12: =IFERROR(IF(ISBLANK(H12),"",H12/C12),0) -> 0 | L12: =IFERROR(IF(ISBLANK(I12),"",I12/C12),0) -> 0 | M12: =IFERROR(L12-K12,"") -> 0 | N12: =IFERROR(L12/K12,"") | O12: =Progress!J7 -> 10000 | P12: =IF(ISBLANK(O12),"",O12/$O$18) -> 0.29994001 | Q12: =Progress!L7 -> 227 | R12: =Progress!M7 -> 885 | S12: =IFERROR(IF(ISBLANK(Q12),"",Q12/O12),0) -> 0.0227 | T12: =IFERROR(IF(ISBLANK(R12),"",R12/O12),0) -> 0.0885 | U12: =Progress!N7 -> 7927 | V12: =Progress!O7 -> 7935 | W12: =IFERROR(IF(ISBLANK(U12),"",U12/O12),0) -> 0.7927 | X12: =IFERROR(IF(ISBLANK(V12),"",V12/O12),0) -> 0.7935 | Y12: =IFERROR(X12-W12,"") -> 0.0008 | Z12: =IFERROR(X12/W12,"") -> 1.0010092
A13: =Progress!A8 -> MOBILIZATION | C13: =Progress!B8 -> 0 | D13: =IF(ISBLANK(C13),"",C13/$C$18) -> 0 | E13: =Progress!D8 -> 0 | F13: =Progress!E8 -> 0 | G13: =Progress!F8 -> 0 | H13: =Progress!G8 -> 0 | I13: =Progress!H8 -> 0 | J13: =IFERROR(IF(ISBLANK(G13),"",G13/C13),0) -> 0 | K13: =IFERROR(IF(ISBLANK(H13),"",H13/C13),0) -> 0 | L13: =IFERROR(IF(ISBLANK(I13),"",I13/C13),0) -> 0 | M13: =IFERROR(L13-K13,"") -> 0 | N13: =IFERROR(L13/K13,"") | O13: =Progress!J8 -> 0 | P13: =IF(ISBLANK(O13),"",O13/$O$18) -> 0 | Q13: =Progress!L8 -> 0 | R13: =Progress!M8 -> 0 | S13: =IFERROR(IF(ISBLANK(Q13),"",Q13/O13),0) -> 0 | T13: =IFERROR(IF(ISBLANK(R13),"",R13/O13),0) -> 0 | U13: =Progress!N8 -> 0 | V13: =Progress!O8 -> 0 | W13: =IFERROR(IF(ISBLANK(U13),"",U13/O13),0) -> 0 | X13: =IFERROR(IF(ISBLANK(V13),"",V13/O13),0) -> 0 | Y13: =IFERROR(X13-W13,"") -> 0 | Z13: =IFERROR(X13/W13,"")
A14: =Progress!A9 -> ENGINEERING | C14: =Progress!B9 -> 1071299.8 | D14: =IF(ISBLANK(C14),"",C14/$C$18) -> 0.03 | E14: =Progress!D9 -> 1090347.2 | F14: =Progress!E9 -> 1090347.2 | G14: =Progress!F9 -> 1071299.8 | H14: =Progress!G9 -> 1071299.8 | I14: =Progress!H9 -> 1071299.8 | J14: =IFERROR(IF(ISBLANK(G14),"",G14/C14),0) -> 1 | K14: =IFERROR(IF(ISBLANK(H14),"",H14/C14),0) -> 1 | L14: =IFERROR(IF(ISBLANK(I14),"",I14/C14),0) -> 1 | M14: =IFERROR(L14-K14,"") -> 0 | N14: =IFERROR(L14/K14,"") -> 1 | O14: =Progress!J9 -> 0 | P14: =IF(ISBLANK(O14),"",O14/$O$18) -> 0 | Q14: =Progress!L9 -> 0 | R14: =Progress!M9 -> 0 | S14: =IFERROR(IF(ISBLANK(Q14),"",Q14/O14),0) -> 0 | T14: =IFERROR(IF(ISBLANK(R14),"",R14/O14),0) -> 0 | U14: =Progress!N9 -> 0 | V14: =Progress!O9 -> 0 | W14: =IFERROR(IF(ISBLANK(U14),"",U14/O14),0) -> 0 | X14: =IFERROR(IF(ISBLANK(V14),"",V14/O14),0) -> 0 | Y14: =IFERROR(X14-W14,"") -> 0 | Z14: =IFERROR(X14/W14,"")
A15: =Progress!A19 -> PROCUREMENT | C15: =Progress!B19 -> 9641698.1 | D15: =IF(ISBLANK(C15),"",C15/$C$18) -> 0.27 | E15: =Progress!D19 -> 9813124.6 | F15: =Progress!E19 -> 8945474.8 | G15: =Progress!F19 -> 9641698.1 | H15: =Progress!G19 -> 9641698.1 | I15: =Progress!H19 -> 8769229.7 | J15: =IFERROR(IF(ISBLANK(G15),"",G15/C15),0) -> 1 | K15: =IFERROR(IF(ISBLANK(H15),"",H15/C15),0) -> 1 | L15: =IFERROR(IF(ISBLANK(I15),"",I15/C15),0) -> 0.90951092 | M15: =IFERROR(L15-K15,"") -> -0.090489082 | N15: =IFERROR(L15/K15,"") -> 0.90951092 | O15: =Progress!J19 -> 0 | P15: =IF(ISBLANK(O15),"",O15/$O$18) -> 0 | Q15: =Progress!L19 -> 0 | R15: =Progress!M19 -> 0 | S15: =IFERROR(IF(ISBLANK(Q15),"",Q15/O15),0) -> 0 | T15: =IFERROR(IF(ISBLANK(R15),"",R15/O15),0) -> 0 | U15: =Progress!N19 -> 0 | V15: =Progress!O19 -> 0 | W15: =IFERROR(IF(ISBLANK(U15),"",U15/O15),0) -> 0 | X15: =IFERROR(IF(ISBLANK(V15),"",V15/O15),0) -> 0 | Y15: =IFERROR(X15-W15,"") -> 0 | Z15: =IFERROR(X15/W15,"")
A16: =Progress!A29 -> CONSTRUCTION | C16: =Progress!B29 -> 21425996 | D16: =IF(ISBLANK(C16),"",C16/$C$18) -> 0.6 | E16: =Progress!D29 -> 17500390 | F16: =Progress!E29 -> 13921267 | G16: =Progress!F29 -> 17861237 | H16: =Progress!G29 -> 17861237 | I16: =Progress!H29 -> 14189805 | J16: =IFERROR(IF(ISBLANK(G16),"",G16/C16),0) -> 0.83362458 | K16: =IFERROR(IF(ISBLANK(H16),"",H16/C16),0) -> 0.83362458 | L16: =IFERROR(IF(ISBLANK(I16),"",I16/C16),0) -> 0.6622705 | M16: =IFERROR(L16-K16,"") -> -0.17135408 | N16: =IFERROR(L16/K16,"") -> 0.79444695 | O16: =Progress!J29 -> 22188 | P16: =IF(ISBLANK(O16),"",O16/$O$18) -> 0.6655069 | Q16: =Progress!L29 -> 23717 | R16: =Progress!M29 -> 21229 | S16: =IFERROR(IF(ISBLANK(Q16),"",Q16/O16),0) -> 1.0689111 | T16: =IFERROR(IF(ISBLANK(R16),"",R16/O16),0) -> 0.95677844 | U16: =Progress!N29 -> 18795 | V16: =Progress!O29 -> 16835 | W16: =IFERROR(IF(ISBLANK(U16),"",U16/O16),0) -> 0.8470795 | X16: =IFERROR(IF(ISBLANK(V16),"",V16/O16),0) -> 0.75874346 | Y16: =IFERROR(X16-W16,"") -> -0.088336037 | Z16: =IFERROR(X16/W16,"") -> 0.89571695
A17: =Progress!A41 -> CLOSEOUT | C17: =Progress!B41 -> 3570999.3 | D17: =IF(ISBLANK(C17),"",C17/$C$18) -> 0.1 | E17: =Progress!D41 -> 109034.72 | F17: =Progress!E41 -> 571523.92 | G17: =Progress!F41 -> 107129.98 | H17: =Progress!G41 -> 107129.98 | I17: =Progress!H41 -> 610206.45 | J17: =IFERROR(IF(ISBLANK(G17),"",G17/C17),0) -> 0.03 | K17: =IFERROR(IF(ISBLANK(H17),"",H17/C17),0) -> 0.03 | L17: =IFERROR(IF(ISBLANK(I17),"",I17/C17),0) -> 0.17087834 | M17: =IFERROR(L17-K17,"") -> 0.14087834 | N17: =IFERROR(L17/K17,"") -> 5.6959448 | O17: =Progress!J41 -> 1152 | P17: =IF(ISBLANK(O17),"",O17/$O$18) -> 0.034553089 | Q17: =Progress!L41 -> 44 | R17: =Progress!M41 -> 206 | S17: =IFERROR(IF(ISBLANK(Q17),"",Q17/O17),0) -> 0.038194444 | T17: =IFERROR(IF(ISBLANK(R17),"",R17/O17),0) -> 0.17881944 | U17: =Progress!N41 -> 33 | V17: =Progress!O41 -> 165 | W17: =IFERROR(IF(ISBLANK(U17),"",U17/O17),0) -> 0.028645833 | X17: =IFERROR(IF(ISBLANK(V17),"",V17/O17),0) -> 0.14322917 | Y17: =IFERROR(X17-W17,"") -> 0.11458333 | Z17: =IFERROR(X17/W17,"") -> 5
B18: Total | C18: =SUM(C13:C17) -> 35709993 | D18: =SUM(D13:D17) -> 1 | E18: =SUM(E12:E17) -> 28512896 | F18: =SUM(F12:F17) -> 24528613 | G18: =SUM(G12:G17) -> 28681365 | H18: =SUM(H12:H17) -> 28681365 | I18: =SUM(I12:I17) -> 24640541 | J18: =IFERROR(IF(ISBLANK(G18),"",G18/C18),0) -> 0.80317475 | K18: =IFERROR(IF(ISBLANK(H18),"",H18/C18),0) -> 0.80317475 | L18: =IFERROR(IF(ISBLANK(I18),"",I18/C18),0) -> 0.69001808 | M18: =+L18-K18 -> -0.11315666 | N18: =L18/K18 -> 0.85911327 | O18: =SUM(O12:O17) -> 33340 | P18: =SUM(P12:P17) -> 1 | Q18: =SUM(Q12:Q17) -> 23988 | R18: =SUM(R12:R17) -> 22320 | S18: =IFERROR(IF(ISBLANK(Q18),"",Q18/O18),0) -> 0.7194961 | T18: =IFERROR(IF(ISBLANK(R18),"",R18/O18),0) -> 0.66946611 | U18: =SUM(U12:U17) -> 26755 | V18: =SUM(V12:V17) -> 24935 | W18: =IFERROR(IF(ISBLANK(U18),"",U18/O18),0) -> 0.8024895 | X18: =IFERROR(IF(ISBLANK(V18),"",V18/O18),0) -> 0.74790042 | Y18: =+X18-W18 -> -0.054589082 | Z18: =X18/W18 -> 0.93197533
AA19: Construction Milestones
AA20: Item No. | AB20: Milestones | AD20: Original (Baseline) | AE20: Latest Plan | AF20: Forecast | AG20: Status | AH20: Days Change
AA21: =+Milestones!B5 -> 1 | AB21: =+Milestones!C5 -> Award Date | AD21: =+Milestones!D5 -> 46028 | AE21: =+Milestones!E5 -> 46028 | AF21: =+Milestones!F5 -> 46028 | AG21: =+Milestones!G5 -> A | AH21: =+Milestones!H5 -> 0
AA22: =+Milestones!B6 -> 2 | AB22: =+Milestones!C6 -> Contract Sign Date | AD22: =+Milestones!D6 -> 46070 | AE22: =+Milestones!E6 -> 46070 | AF22: =+Milestones!F6 -> 46070 | AG22: =+Milestones!G6 -> A | AH22: =+Milestones!H6 -> 0
AA23: =+Milestones!B7 -> 3 | AB23: =+Milestones!C7 -> Site Handover Date | AD23: =+Milestones!D7 -> 46070 | AE23: =+Milestones!E7 -> 46070 | AF23: =+Milestones!F7 -> 46070 | AG23: =+Milestones!G7 -> A | AH23: =+Milestones!H7 -> 0
AA24: =+Milestones!B8 -> 4 | AB24: =+Milestones!C8 -> Complete Mobilization | AD24: =+Milestones!D8 -> 46099 | AE24: =+Milestones!E8 -> 46099 | AF24: =+Milestones!F8 -> 46126 | AG24: =+Milestones!G8 -> A | AH24: =+Milestones!H8 -> 0
AA25: =+Milestones!B11 -> 7 | AB25: =+Milestones!C11 -> Complete Construction | AD25: =+Milestones!D11 -> 46370 | AE25: =+Milestones!E11 -> 46370 | AF25: =+Milestones!F11 -> 46410 | AG25: =+Milestones!G11 -> F | AH25: =+Milestones!H11 -> -40
AA26: =+Milestones!B12 -> 8 | AB26: =+Milestones!C12 -> Complete all Works including Testing & Commissioning, Cleanup, Closeout Documentation and Ready for Initial Handover | AD26: =+Milestones!D12 -> 46372 | AE26: =+Milestones!E12 -> 46372 | AF26: =+Milestones!F12 -> 46420 | AG26: =+Milestones!G12 -> F | AH26: =+Milestones!H12 -> -48
AA27: =+Milestones!B13 -> 9 | AB27: =+Milestones!C13 -> Complete Demobilization | AD27: =+Milestones!D13 -> 46372 | AE27: =+Milestones!E13 -> 46372 | AF27: =+Milestones!F13 -> 46424 | AG27: =+Milestones!G13 -> F | AH27: =+Milestones!H13 -> -52
AA28: =+Milestones!B14 -> 10 | AB28: =+Milestones!C14 -> Project Handover | AD28: =+Milestones!D14 -> 46372 | AE28: =+Milestones!E14 -> 46372 | AF28: =+Milestones!F14 -> 46425 | AG28: =+Milestones!G14 -> F | AH28: =+Milestones!H14 -> -53
A46: Performance overview
A47: Submittals Status | L47: Quality | W47: Safety
A48: Shop Drawings | L48: Quality Reports | W48: Safety Statistics | AE48: Proactive Vs Reactive Actions Taken
A49: Item Per WBS | C49: Total | D49: Total Submitted Drawings | I49: Remaining | J49: Pending | K49: Total Submittals | L49: Quality Reports | N49: Issued | O49: Closed | P49: Pending | Q49: Avg. Closing (Days) | R49: Pending | W49: Category | X49: Item | Z49: This Week | AB49: This Month | AC49: Year to Date | AD49: Cumulative
D50: A | E50: B | F50: C | G50: D | H50: Processed | R50: 0-10 Days | S50: 11-20 Days | T50: 21-30 Days | U50: 31-60 Days | V50: > 60 Days
A51: ='Quality-Stat'!A13 -> Architectural | C51: =IF('Quality-Stat'!D13=0,"",'Quality-Stat'!D13) -> 58 | D51: =IF('Quality-Stat'!E13=0,"",'Quality-Stat'!E13) -> 6 | E51: =IF('Quality-Stat'!F13=0,"",'Quality-Stat'!F13) -> 33 | F51: =IF('Quality-Stat'!G13=0,"",'Quality-Stat'!G13) -> 2 | G51: =IF('Quality-Stat'!H13=0,"",'Quality-Stat'!H13) | H51: =IF('Quality-Stat'!I13=0,"",'Quality-Stat'!I13) -> 39 | I51: =IF('Quality-Stat'!J13=0,"",'Quality-Stat'!J13) | J51: =IF('Quality-Stat'!K13=0,"",'Quality-Stat'!K13) -> 17 | K51: =IF('Quality-Stat'!L13=0,"",'Quality-Stat'!L13) -> 58 | W51: General | X51: ='HSE-Stat'!B4 -> Total Hours Worked | Z51: ='HSE-Stat'!D4 -> 8160 | AB51: ='HSE-Stat'!E4 -> 15240 | AC51: ='HSE-Stat'!F4 -> 97870 | AD51: ='HSE-Stat'!G4 -> 97870 | AG51: Proactive | AH51: =+SUM(AD63:AD68) -> 531
