Workbook
Name _1B.05.M.010.0010: #REF!
Name _1B.05.M.010.0010: #REF!
Name _1B.05.M.010.0050: #REF!
Name _1B.05.M.010.0050: #REF!
Name _1B.05.M.0100.0010: #REF!
Name _1B.05.M.020.0010: #REF!
Name _1B.05.M.020.0020: #REF!
Name _1B.05.M.020.0030: #REF!
Name _1B.05.M.020.0040: #REF!
Name _1B.05.M.030.0010: #REF!
Name _1B.05.M.030.0020: #REF!
Name _1B.05.M.040.0010: #REF!
Name _1B.05.M.050.0010: #REF!
Name _1B.05.M.050.0020: #REF!
Name _1B.05.M.050.0030: #REF!
Name _1B.05.M.060.0020: #REF!
Name _1B.05.M.060.0100: #REF!
Name _1B.05.M.070.0010: #REF!
Name _1B.05.M.070.0020: #REF!
Name _1B.05.M.070.0030: #REF!
Name _1B.05.M.070.0040: #REF!
Name _1B.05.M.070.0050: #REF!
Name _1B.05.M.080.0010: #REF!
Name _1B.05.M.090.0010: #REF!
Name _1B.09.P.010.0010: #REF!
Name _1B.09.P.010.0020: #REF!
Name _1B.09.P.010.0030: #REF!
Name _1B.09.P.010.0040: #REF!
Name _1B.09.P.010.0050: #REF!
Name _1B.09.P.010.0060: #REF!
Name _1B.09.P.010.0070: #REF!
Name _1B.09.P.020.0010: #REF!
Name _1B.09.P.020.0020: #REF!
Name _1B.09.P.020.0030: #REF!
Name _1B.09.P.020.0040: #REF!
Name _1B.09.P.020.0050: #REF!
Name _1B.09.P.020.0060: #REF!
Name _1B.09.P.020.0070: #REF!
Name _1B.09.P.020.0080: #REF!
Name _1B.09.P.020.0090: #REF!
Name _1B.09.P.020.0100: #REF!
Name _1B.09.P.020.0110: #REF!
Name _1B.09.P.020.0120: #REF!
Name _1B.09.P.020.0130: #REF!
Name _1B.09.P.020.0140: #REF!
Name _1B.09.P.020.0150: #REF!
Name _1B.09.P.030.0010: #REF!
Name _1B.09.P.030.0020: #REF!
Name _1B.09.P.030.0030: #REF!
Name _1B.09.P.030.0040: #REF!
Name _1B.09.P.030.0050: #REF!
Name _1B.09.P.030.0060: #REF!
Name _1B.09.P.040.0010: #REF!
Name _1B.09.P.040.0020: #REF!
Name _1B.09.P.040.0030: #REF!
Name _1B.09.P.050.0010: #REF!
Name _1B.09.P.050.0020: #REF!
Name _1B.09.P.060.0010: #REF!
Name _1B.09.P.060.0020: #REF!
Name _1B.09.P.060.0030: #REF!

Sheet DB
A1: ='Weekly Progress Report'!$A$1 -> MODON - Weekly Progress Report - Construction Projects
B2: ='Weekly Progress Report'!$A$2 -> Contract General Information | J2: ='Weekly Progress Report'!G2 -> Key Dates | U2: ='Weekly Progress Report'!$M$2 -> Cost Summary (SR) | AD2: ='Weekly Progress Report'!$U$2 -> Performance Summary | AP2: ='Weekly Progress Report'!A58 -> Shop Drawings | AT2: ='Weekly Progress Report'!A67 -> Material Approval | AW2: ='Weekly Progress Report'!A76 -> Procurement Summary | BD2: ='Weekly Progress Report'!L58 -> Quality Reports | BT2: ='Weekly Progress Report'!L66 -> Key Submittals Approval Status | CD2: ='Weekly Progress Report'!L72 -> Invoices Summary | CR2: ='Weekly Progress Report'!L80 -> Resources at Site | CY2: ='Weekly Progress Report'!W58 -> Safety Statistics | FK2: ='Weekly Progress Report'!A85 -> Primavera P6 Schedule Status | FS2: ='Weekly Progress Report'!A94 -> Weekly Prgoress Photos
A3: ='Weekly Progress Report'!AF1 -> Data Date | B3: ='Weekly Progress Report'!A3 -> Project Name | C3: ='Weekly Progress Report'!A4 -> Project ID | D3: ='Weekly Progress Report'!A5 -> Contractor | E3: ='Weekly Progress Report'!A6 -> Consultant | F3: ='Weekly Progress Report'!D4 -> Stage | G3: ='Weekly Progress Report'!D5 -> Status | H3: ='Weekly Progress Report'!D6 -> Modon PM | I3: ='Weekly Progress Report'!AA2 -> Project Scope | J3: ='Weekly Progress Report'!G3 -> Contract Award | K3: ='Weekly Progress Report'!G4 -> Contract Sign | L3: ='Weekly Progress Report'!G5 -> Site Handover | M3: ='Weekly Progress Report'!G6 -> Original Completion | N3: ='Weekly Progress Report'!$I$3 -> Contract Award (Hijri) | O3: ='Weekly Progress Report'!$I$4 -> Contract Sign (Hijri) | P3: ='Weekly Progress Report'!$I$5 -> Site Handover (Hijri) | Q3: ='Weekly Progress Report'!$I$6 -> Original Completion (Hijri) | R3: ='Weekly Progress Report'!$K$3 -> Revised Completion | S3: ='Weekly Progress Report'!$K$4 -> Committed Completion | T3: ='Weekly Progress Report'!$K$5 -> Forecast Completion | U3: ='Weekly Progress Report'!$M$3 -> Original Contract Value | V3: ='Weekly Progress Report'!$M$4 -> Revised Contract Value | W3: ='Weekly Progress Report'!$M$5 -> Estimate At Completion Value | X3: ='Weekly Progress Report'!$M$6 -> Potential Changes | Y3: ='Weekly Progress Report'!$Q$3 -> O&M Value (if any) | Z3: ='Weekly Progress Report'!$Q$4 -> Submitted Invoices (Gross Value) | AA3: ='Weekly Progress Report'!$Q$5 -> Penalities | AB3: ='Weekly Progress Report'!$Q$6 -> FIR Value (Todate) | AC3: Original Plan Value | AD3: ='Weekly Progress Report'!$U$3 -> Plan Value | AE3: ='Weekly Progress Report'!$U$4 -> Earn Value | AF3: ='Weekly Progress Report'!$W$3 -> Phys. Plan Value | AG3: ='Weekly Progress Report'!$W$4 -> Phys. Earn Value | AH3: ='Weekly Progress Report'!$Y$3 -> Quality Score | AI3: ='Weekly Progress Report'!$Y$5 -> Safety Score | AJ3: Weekly PV (SAR) | AK3: Weekly EV (SAR) | AL3: Weekly PV % | AM3: Weekly PV % | AN3: Weekly Phys PV% | AO3: Weekly Phys PV% | AP3: Total SD Planned | AQ3: SD Remaining | AR3: SD Pending | AS3: Total SD Submittals | AT3: Planned Materials Approv | AU3: Material Pending Approval | AV3: Materila Total Submittals | AW3: ='Weekly Progress Report'!C77 -> Total Materials | AX3: ='Weekly Progress Report'!D77 -> Total Number of P.O. | AY3: ='Weekly Progress Report'!E77 -> Actual P.O. To Date | AZ3: ='Weekly Progress Report'!F77 -> Remaining P.O | BA3: ='Weekly Progress Report'!G77 -> Material on Site | BB3: ='Weekly Progress Report'!H77 -> Remaining Materials | BC3: ='Weekly Progress Report'!I77 -> Material Delivery Completion (Date) | BD3: ="NCR "&'Weekly Progress Report'!N59 -> NCR Issued | BE3: ="NCR "&'Weekly Progress Report'!O59 -> NCR Closed | BF3: ="NCR "&'Weekly Progress Report'!P59 -> NCR Pending | BG3: ="NCR "&'Weekly Progress Report'!Q59 -> NCR Avg. Closing (Days) | BH3: ="SIR "&'Weekly Progress Report'!N59 -> SIR Issued | BI3: ="SIR "&'Weekly Progress Report'!O59 -> SIR Closed | BJ3: ="SIR "&'Weekly Progress Report'!P59 -> SIR Pending | BK3: ="SIR "&'Weekly Progress Report'!Q59 -> SIR Avg. Closing (Days) | BL3: ="MIR "&'Weekly Progress Report'!N59 -> MIR Issued | BM3: ="MIR "&'Weekly Progress Report'!O59 -> MIR Closed | BN3: ="MIR "&'Weekly Progress Report'!P59 -> MIR Pending | BO3: ="MIR "&'Weekly Progress Report'!Q59 -> MIR Avg. Closing (Days) | BP3: ="FIR "&'Weekly Progress Report'!N59 -> FIR Issued | BQ3: ="FIR "&'Weekly Progress Report'!O59 -> FIR Closed | BR3: ="FIR "&'Weekly Progress Report'!P59 -> FIR Pending | BS3: ="FIR "&'Weekly Progress Report'!Q59 -> FIR Avg. Closing (Days) | BT3: ='Weekly Progress Report'!L67 -> 1 Quality Plan Approval | BU3: ='Weekly Progress Report'!L68 -> 2 Quality Plan Last Up | BV3: ='Weekly Progress Report'!L69 -> 3 Safety Plan Approval | BW3: ='Weekly Progress Report'!L70 -> 4 Safety Plan Last Up | BX3: ='Weekly Progress Report'!L71 -> 5 Execution Plan Approval | BY3: ='Weekly Progress Report'!Q67 -> 6 Baseline Approval | BZ3: ='Weekly Progress Report'!Q68 -> 7 No of Approved Version of Schedule | CA3: ='Weekly Progress Report'!Q69 -> 8 Last Approved Schedule | CB3: ='Weekly Progress Report'!Q70 -> 9 BOQ Approval Date | CC3: ='Weekly Progress Report'!Q71 -> 10 No of Approved Version of BOQ | CD3: ='Weekly Progress Report'!L73 -> Total Submitted Invoices | CE3: ='Weekly Progress Report'!L74 -> PM Approved Invoices | CF3: ='Weekly Progress Report'!L75 -> No of Paid Invoices | CG3: ='Weekly Progress Report'!L76 -> No of Pending Invoices | CH3: ='Weekly Progress Report'!L77 -> Advance Payment % | CI3: ='Weekly Progress Report'!L78 -> Retention % | CJ3: ='Weekly Progress Report'!L79 -> Deduction / Penalties % | CK3: ='Weekly Progress Report'!O73 -> Submitted Invoices (SAR) | CL3: ='Weekly Progress Report'!O74 -> PM Approved Invoices (SAR) | CM3: ='Weekly Progress Report'!O75 -> Paid Invoices (SAR) | CN3: ='Weekly Progress Report'!O76 -> Last Submitted Period | CO3: ='Weekly Progress Report'!O77 -> Advance Payment (SAR) | CP3: ='Weekly Progress Report'!O78 -> Retention (SAR) | CQ3: ='Weekly Progress Report'!O79 -> Deduction / Penalties (SAR) | CR3: Planned Head Count | CS3: Actual Head Count | CT3: Saudi Staff | CU3: Labor Planned | CV3: Labor Actual | CW3: Equipment Planned | CX3: Equipment Actual | CY3: ="This Week "&'Weekly Progress Report'!X61 -> This Week Total Hours Worked | CZ3: ="This Week "&'Weekly Progress Report'!X62 -> This Week Safe Hours Worked | DA3: ="This Week "&'Weekly Progress Report'!X63 -> This Week LTI | DB3: ="This Week "&'Weekly Progress Report'!X64 -> This Week MTC (Healed w/o Disability) | DC3: ="This Week "&'Weekly Progress Report'!X65 -> This Week MTC (Healed w/ Disability) | DD3: ="This Week "&'Weekly Progress Report'!X66 -> This Week Near Miss | DE3: ="This Week "&'Weekly Progress Report'!X67 -> This Week First Aid Cases | DF3: ="This Week "&'Weekly Progress Report'!X68 -> This Week Fatality | DG3: ="This Week "&'Weekly Progress Report'!X69 -> This Week Fire Incident Cases | DH3: ="This Week "&'Weekly Progress Report'!X70 -> This Week Vehicle Incident | DI3: ="This Week "&'Weekly Progress Report'!X71 -> This Week Property Damages | DJ3: ="This Week "&'Weekly Progress Report'!X72 -> This Week Induction Training | DK3: ="This Week "&'Weekly Progress Report'!X73 -> This Week No.of Internal Training | DL3: ="This Week "&'Weekly Progress Report'!X74 -> This Week No.of Internal Audit | DM3: ="This Week "&'Weekly Progress Report'!X75 -> This Week No. of Toolbox Talks | DN3: ="This Week "&'Weekly Progress Report'!X76 -> This Week Safety Awards/Incentives | DO3: ="This Month "&'Weekly Progress Report'!X61 -> This Month Total Hours Worked | DP3: ="This Month "&'Weekly Progress Report'!X62 -> This Month Safe Hours Worked | DQ3: ="This Month "&'Weekly Progress Report'!X63 -> This Month LTI | DR3: ="This Month "&'Weekly Progress Report'!X64 -> This Month MTC (Healed w/o Disability) | DS3: ="This Month "&'Weekly Progress Report'!X65 -> This Month MTC (Healed w/ Disability) | DT3: ="This Month "&'Weekly Progress Report'!X66 -> This Month Near Miss | DU3: ="This Month "&'Weekly Progress Report'!X67 -> This Month First Aid Cases | DV3: ="This Month "&'Weekly Progress Report'!X68 -> This Month Fatality | DW3: ="This Month "&'Weekly Progress Report'!X69 -> This Month Fire Incident Cases | DX3: ="This Month "&'Weekly Progress Report'!X70 -> This Month Vehicle Incident | DY3: ="This Month "&'Weekly Progress Report'!X71 -> This Month Property Damages | DZ3: ="This Month "&'Weekly Progress Report'!X72 -> This Month Induction Training | EA3: ="This Month "&'Weekly Progress Report'!X73 -> This Month No.of Internal Training | EB3: ="This Month "&'Weekly Progress Report'!X74 -> This Month No.of Internal Audit | EC3: ="This Month "&'Weekly Progress Report'!X75 -> This Month No. of Toolbox Talks | ED3: ="This Month "&'Weekly Progress Report'!X76 -> This Month Safety Awards/Incentives | EE3: ="YTD "&'Weekly Progress Report'!X61 -> YTD Total Hours Worked | EF3: ="YTD "&'Weekly Progress Report'!X62 -> YTD Safe Hours Worked | EG3: ="YTD "&'Weekly Progress Report'!X63 -> YTD LTI | EH3: ="YTD "&'Weekly Progress Report'!X64 -> YTD MTC (Healed w/o Disability) | EI3: ="YTD "&'Weekly Progress Report'!X65 -> YTD MTC (Healed w/ Disability) | EJ3: ="YTD "&'Weekly Progress Report'!X66 -> YTD Near Miss | EK3: ="YTD "&'Weekly Progress Report'!X67 -> YTD First Aid Cases | EL3: ="YTD "&'Weekly Progress Report'!X68 -> YTD Fatality | EM3: ="YTD "&'Weekly Progress Report'!X69 -> YTD Fire Incident Cases | EN3: ="YTD "&'Weekly Progress Report'!X70 -> YTD Vehicle Incident | EO3: ="YTD "&'Weekly Progress Report'!X71 -> YTD Property Damages | EP3: ="YTD "&'Weekly Progress Report'!X72 -> YTD Induction Training | EQ3: ="YTD "&'Weekly Progress Report'!X73 -> YTD No.of Internal Training | ER3: ="YTD "&'Weekly Progress Report'!X74 -> YTD No.of Internal Audit | ES3: ="YTD "&'Weekly Progress Report'!X75 -> YTD No. of Toolbox Talks | ET3: ="YTD "&'Weekly Progress Report'!X76 -> YTD Safety Awards/Incentives | EU3: ="Cum "&'Weekly Progress Report'!X61 -> Cum Total Hours Worked | EV3: ="Cum "&'Weekly Progress Report'!X62 -> Cum Safe Hours Worked | EW3: ="Cum "&'Weekly Progress Report'!X63 -> Cum LTI | EX3: ="Cum "&'Weekly Progress Report'!X64 -> Cum MTC (Healed w/o Disability) | EY3: ="Cum "&'Weekly Progress Report'!X65 -> Cum MTC (Healed w/ Disability) | EZ3: ="Cum "&'Weekly Progress Report'!X66 -> Cum Near Miss | FA3: ="Cum "&'Weekly Progress Report'!X67 -> Cum First Aid Cases | FB3: ="Cum "&'Weekly Progress Report'!X68 -> Cum Fatality | FC3: ="Cum "&'Weekly Progress Report'!X69 -> Cum Fire Incident Cases | FD3: ="Cum "&'Weekly Progress Report'!X70 -> Cum Vehicle Incident | FE3: ="Cum "&'Weekly Progress Report'!X71 -> Cum Property Damages | FF3: ="Cum "&'Weekly Progress Report'!X72 -> Cum Induction Training | FG3: ="Cum "&'Weekly Progress Report'!X73 -> Cum No.of Internal Training | FH3: ="Cum "&'Weekly Progress Report'!X74 -> Cum No.of Internal Audit | FI3: ="Cum "&'Weekly Progress Report'!X75 -> Cum No. of Toolbox Talks | FJ3: ="Cum "&'Weekly Progress Report'!X76 -> Cum Safety Awards/Incentives | FK3: ='Weekly Progress Report'!A88 -> Total Act. | FL3: ='Weekly Progress Report'!B88 -> Not Started | FM3: ='Weekly Progress Report'!C88 -> In Progress | FN3: ='Weekly Progress Report'!D88 -> Completed | FO3: Critical Path Act.Last Week | FP3: Critical Path Act.This Week | FQ3: Failed start Last Week | FR3: Failed start This Week | FS3: ='Weekly Progress Report'!B96 -> 0 | FT3: ='Weekly Progress Report'!D96 -> 0 | FU3: ='Weekly Progress Report'!F96 -> 0 | FV3: ='Weekly Progress Report'!H96 -> 0 | FW3: ='Weekly Progress Report'!J96 -> 0 | FX3: ='Weekly Progress Report'!L96 -> 0 | FY3: ='Weekly Progress Report'!N96 -> 0 | FZ3: ='Weekly Progress Report'!O96 -> 0 | GA3: ='Weekly Progress Report'!P96 -> 0
A4: ='Weekly Progress Report'!AG1 -> 46308 | B4: ='Weekly Progress Report'!B3 -> LAND DEVELOPMENT OF JEDDAH OASIS | C4: ='Weekly Progress Report'!B4 -> JHD4-02-007 | D4: ='Weekly Progress Report'!B5 -> AL-ENJAZ TRADING AND CONTRACTING COMPANY | E4: ='Weekly Progress Report'!B6 -> SAUDI ARABIA CONSULTING ENGINEERING COMPANY "EGIS" | F4: ='Weekly Progress Report'!E4 -> Construction | G4: ='Weekly Progress Report'!E5 -> Active | H4: ='Weekly Progress Report'!E6 -> Mohammed Alshunaifi | I4: ='Weekly Progress Report'!AA3 -> Land development of jeddah oasis (The project includes construction of Roads works ; Storm water piping network with catch basins and manholes, Box Culvert ;Sewerage piping network with manhole ; Potable water piping network with fitting , valves and fire hydrant ;TSE Network ; Sewerage pump stations ;Channels ;36 KV medium voltage cable with Ring Main Unit ; Street Lighting with Unit Sub-stations , Ring Main Units and Low Voltage Cables ,concrete ducts at road crossing) | J4: ='Weekly Progress Report'!H3 -> 45970 | K4: ='Weekly Progress Report'!H4 -> 45977 | L4: ='Weekly Progress Report'!H5 -> 45985 | M4: ='Weekly Progress Report'!H6 -> 46530 | N4: ='Weekly Progress Report'!$J$3 -> 45970 | O4: ='Weekly Progress Report'!$J$4 -> 45977 | P4: ='Weekly Progress Report'!$J$5 -> 45985 | Q4: ='Weekly Progress Report'!$J$6 -> 46530 | R4: ='Weekly Progress Report'!$L$3 -> 46530 | S4: ='Weekly Progress Report'!$L$4 -> 46530 | T4: ='Weekly Progress Report'!$L$5 -> 46406 | U4: ='Weekly Progress Report'!$O$3 -> 57304348 | V4: ='Weekly Progress Report'!$O$4 -> 57304348 | W4: ='Weekly Progress Report'!$O$5 -> 57304348 | X4: ='Weekly Progress Report'!$O$6 -> 0 | Y4: ='Weekly Progress Report'!$S$3 -> 0 | Z4: ='Weekly Progress Report'!$S$4 -> 35217377 | AA4: ='Weekly Progress Report'!$S$5 -> 0 | AB4: ='Weekly Progress Report'!$S$6 -> 53231723 | AC4: ='Weekly Progress Report'!$J$28 -> 0.74182849 | AD4: ='Weekly Progress Report'!$V$3 -> 0.5984533 | AE4: ='Weekly Progress Report'!$V$4 -> 0.93306282 | AF4: ='Weekly Progress Report'!$X$3 -> 0.76402226 | AG4: ='Weekly Progress Report'!$X$4 -> 0.96133708 | AH4: ='Weekly Progress Report'!$Z$3 -> 0.85303793 | AI4: ='Weekly Progress Report'!$Z$5 -> 0.88 | AJ4: ='Weekly Progress Report'!$E$28 -> 706912.69 | AK4: ='Weekly Progress Report'!$F$28 -> 1259332.5 | AL4: =AJ4/V4 -> 0.012336109 | AM4: =AK4/V4 -> 0.021976213 | AN4: ='Weekly Progress Report'!S28 -> 0.012335407 | AO4: ='Weekly Progress Report'!T28 -> 0.010316841 | AP4: ='Weekly Progress Report'!C66 -> 393 | AQ4: ='Weekly Progress Report'!I66 -> 0 | AR4: ='Weekly Progress Report'!J66 -> 4 | AS4: ='Weekly Progress Report'!K66 -> 393 | AT4: ='Weekly Progress Report'!C75 -> 146 | AU4: ='Weekly Progress Report'!J75 -> 0 | AV4: ='Weekly Progress Report'!K75 -> 146 | AW4: ='Weekly Progress Report'!C84 -> 34 | AX4: ='Weekly Progress Report'!D84 -> 34 | AY4: ='Weekly Progress Report'!E84 -> 34 | AZ4: ='Weekly Progress Report'!F84 -> 0 | BA4: ='Weekly Progress Report'!G84 -> 27 | BB4: ='Weekly Progress Report'!H84 -> 7 | BC4: ='Weekly Progress Report'!I84 -> 46280 | BD4: ='Weekly Progress Report'!N62 -> 43 | BE4: ='Weekly Progress Report'!O62 -> 43 | BF4: ='Weekly Progress Report'!P62 -> 0 | BG4: ='Weekly Progress Report'!Q62 -> 0 | BH4: ='Weekly Progress Report'!N63 -> 10 | BI4: ='Weekly Progress Report'!O63 -> 10 | BJ4: ='Weekly Progress Report'!P63 -> 0 | BK4: ='Weekly Progress Report'!Q63 -> 0 | BL4: ='Weekly Progress Report'!N64 -> 116 | BM4: ='Weekly Progress Report'!O64 -> 116 | BN4: ='Weekly Progress Report'!P64 -> 0 | BO4: ='Weekly Progress Report'!Q64 -> 0 | BP4: ='Weekly Progress Report'!N65 -> 1571 | BQ4: ='Weekly Progress Report'!O65 -> 1551 | BR4: ='Weekly Progress Report'!P65 -> 20 | BS4: ='Weekly Progress Report'!Q65 -> 0 | BT4: ='Weekly Progress Report'!O67 -> 46039 | BU4: ='Weekly Progress Report'!O68 -> 1 | BV4: ='Weekly Progress Report'!O69 -> 46019 | BW4: ='Weekly Progress Report'!O70 -> 1 | BX4: ='Weekly Progress Report'!O71 -> 46034 | BY4: ='Weekly Progress Report'!U67 -> 46012 | BZ4: ='Weekly Progress Report'!U68 -> 1 | CA4: ='Weekly Progress Report'!U69 -> 46012 | CB4: ='Weekly Progress Report'!U70 -> 45985 | CC4: ='Weekly Progress Report'!U71 -> 1 | CD4: ='Weekly Progress Report'!N73 -> 8 | CE4: ='Weekly Progress Report'!N74 -> 7 | CF4: ='Weekly Progress Report'!N75 -> 3 | CG4: ='Weekly Progress Report'!N76 -> 4 | CH4: ='Weekly Progress Report'!N77 -> 0 | CI4: ='Weekly Progress Report'!N78 -> 0 | CJ4: ='Weekly Progress Report'!N79 -> 0 | CK4: ='Weekly Progress Report'!R73 -> 40499983 | CL4: ='Weekly Progress Report'!R74 -> 33617268 | CM4: ='Weekly Progress Report'!R75 -> 27469389 | CN4: ='Weekly Progress Report'!R76 -> 0 | CO4: ='Weekly Progress Report'!R77 -> 0 | CP4: ='Weekly Progress Report'!R78 -> 0 | CQ4: ='Weekly Progress Report'!R79 -> 0 | CR4: ='Weekly Progress Report'!L83 -> 12 | CS4: ='Weekly Progress Report'!M83 -> 49 | CT4: ='Weekly Progress Report'!O83 -> 0 | CU4: ='Weekly Progress Report'!P83 -> 61 | CV4: ='Weekly Progress Report'!Q83 -> 181 | CW4: ='Weekly Progress Report'!T93 -> 30 | CX4: ='Weekly Progress Report'!U93 -> 113 | CY4: ='Weekly Progress Report'!Z61 -> 11376 | CZ4: ='Weekly Progress Report'!Z62 -> 11376 | DA4: ='Weekly Progress Report'!Z63 -> 0 | DB4: ='Weekly Progress Report'!Z64 -> 0 | DC4: ='Weekly Progress Report'!Z65 -> 0 | DD4: ='Weekly Progress Report'!Z66 -> 0 | DE4: ='Weekly Progress Report'!Z67 -> 0 | DF4: ='Weekly Progress Report'!Z68 -> 0 | DG4: ='Weekly Progress Report'!Z69 -> 0 | DH4: ='Weekly Progress Report'!Z70 -> 0 | DI4: ='Weekly Progress Report'!Z71 -> 0 | DJ4: ='Weekly Progress Report'!Z72 -> 0 | DK4: ='Weekly Progress Report'!Z73 -> 5 | DL4: ='Weekly Progress Report'!Z74 -> 0 | DM4: ='Weekly Progress Report'!Z75 -> 1 | DN4: ='Weekly Progress Report'!Z76 -> 0 | DO4: ='Weekly Progress Report'!AB61 -> 22752 | DP4: ='Weekly Progress Report'!AB62 -> 22752 | DQ4: ='Weekly Progress Report'!AB63 -> 0 | DR4: ='Weekly Progress Report'!AB64 -> 0 | DS4: ='Weekly Progress Report'!AB65 -> 0 | DT4: ='Weekly Progress Report'!AB66 -> 0 | DU4: ='Weekly Progress Report'!AB67 -> 0 | DV4: ='Weekly Progress Report'!AB68 -> 0 | DW4: ='Weekly Progress Report'!AB69 -> 0 | DX4: ='Weekly Progress Report'!AB70 -> 0 | DY4: ='Weekly Progress Report'!AB71 -> 0 | DZ4: ='Weekly Progress Report'!AB72 -> 0 | EA4: ='Weekly Progress Report'!AB73 -> 12 | EB4: ='Weekly Progress Report'!AB74 -> 0 | EC4: ='Weekly Progress Report'!AB75 -> 2 | ED4: ='Weekly Progress Report'!AB76 -> 0 | EE4: ='Weekly Progress Report'!AC61 -> 491606 | EF4: ='Weekly Progress Report'!AC62 -> 491606 | EG4: ='Weekly Progress Report'!AC63 -> 0 | EH4: ='Weekly Progress Report'!AC64 -> 0 | EI4: ='Weekly Progress Report'!AC65 -> 0 | EJ4: ='Weekly Progress Report'!AC66 -> 0 | EK4: ='Weekly Progress Report'!AC67 -> 0 | EL4: ='Weekly Progress Report'!AC68 -> 0 | EM4: ='Weekly Progress Report'!AC69 -> 0 | EN4: ='Weekly Progress Report'!AC70 -> 0 | EO4: ='Weekly Progress Report'!AC71 -> 0 | EP4: ='Weekly Progress Report'!AC72 -> 69 | EQ4: ='Weekly Progress Report'!AC73 -> 264 | ER4: ='Weekly Progress Report'!AC74 -> 0 | ES4: ='Weekly Progress Report'!AC75 -> 42 | ET4: ='Weekly Progress Report'!AC76 -> 0 | EU4: ='Weekly Progress Report'!AD61 -> 504766 | EV4: ='Weekly Progress Report'!AD62 -> 504766 | EW4: ='Weekly Progress Report'!AD63 -> 0 | EX4: ='Weekly Progress Report'!AD64 -> 0 | EY4: ='Weekly Progress Report'!AD65 -> 0 | EZ4: ='Weekly Progress Report'!AD66 -> 0 | FA4: ='Weekly Progress Report'!AD67 -> 0 | FB4: ='Weekly Progress Report'!AD68 -> 0 | FC4: ='Weekly Progress Report'!AD69 -> 0 | FD4: ='Weekly Progress Report'!AD70 -> 0 | FE4: ='Weekly Progress Report'!AD71 -> 0 | FF4: ='Weekly Progress Report'!AD72 -> 80 | FG4: ='Weekly Progress Report'!AD73 -> 269 | FH4: ='Weekly Progress Report'!AD74 -> 0 | FI4: ='Weekly Progress Report'!AD75 -> 43 | FJ4: ='Weekly Progress Report'!AD76 -> 0 | FK4: ='Weekly Progress Report'!A89 -> 1218 | FL4: ='Weekly Progress Report'!B89 -> 24 | FM4: ='Weekly Progress Report'!C89 -> 21 | FN4: ='Weekly Progress Report'!D89 -> 1164 | FO4: ='Weekly Progress Report'!A93 -> 0 | FP4: ='Weekly Progress Report'!B93 -> 0 | FQ4: ='Weekly Progress Report'!H93 -> 4 | FR4: ='Weekly Progress Report'!I93 -> 2 | FS4: ='Weekly Progress Report'!B101 -> 0 | FT4: ='Weekly Progress Report'!D101 -> 0 | FU4: ='Weekly Progress Report'!F101 -> 0 | FV4: ='Weekly Progress Report'!H101 -> 0 | FW4: ='Weekly Progress Report'!J101 -> 0 | FX4: ='Weekly Progress Report'!L101 -> 0 | FY4: ='Weekly Progress Report'!N101 -> 0 | FZ4: ='Weekly Progress Report'!O101 -> 0 | GA4: ='Weekly Progress Report'!P101 -> 0

Sheet Weekly Progress Report
A1: MODON - Weekly Progress Report - Construction Projects | AD1: =+HSE!L4 -> Report No. | AE1: =+HSE!P4 -> 47 | AF1: Data Date | AG1: ='General Information'!L1 -> 46308
A2: Contract General Information | G2: Key Dates | M2: Cost Summary (SR) | U2: Performance Summary | AA2: Project Scope
A3: Project Name | B3: ='General Information'!C3 -> LAND DEVELOPMENT OF JEDDAH OASIS | G3: Contract Award | H3: ='General Information'!C12 -> 45970 | I3: Contract Award (Hijri) | J3: ='General Information'!C16 -> 45970 | K3: Revised Completion | L3: ='General Information'!C20 -> 46530 | M3: Original Contract Value | O3: ='Invoice Log'!E3 -> 57304348 | Q3: O&M Value (if any) | S3: ='Invoice Log'!I3 -> 0 | T3: EAC | U3: Plan Value | V3: =K28 -> 0.5984533 | W3: Phys. Plan Value | X3: =W28 -> 0.76402226 | Y3: Quality Score | Z3: =Quality!AC10 -> 0.85303793 | AA3: =+Progress!B1 -> Land development of jeddah oasis (The project includes construction of Roads works ; Storm water piping network with catch basins and manholes, Box Culvert ;Sewerage piping network with manhole ; Potable water piping network with fitting , valves and fire hydrant ;TSE Network ; Sewerage pump stations ;Channels ;36 KV medium voltage cable with Ring Main Unit ; Street Lighting with Unit Sub-stations , Ring Main Units and Low Voltage Cables ,concrete ducts at road crossing)
A4: Project ID | B4: ='General Information'!C4 -> JHD4-02-007 | D4: Stage | E4: ='General Information'!C7 -> Construction | G4: Contract Sign | H4: ='General Information'!C13 -> 45977 | I4: Contract Sign (Hijri) | J4: ='General Information'!C17 -> 45977 | K4: Committed Completion | L4: ='General Information'!C21 -> 46530 | M4: Revised Contract Value | O4: ='Invoice Log'!E4 -> 57304348 | P4: EAC | Q4: Submitted Invoices (Gross Value) | S4: =+'Invoice Log'!F59 -> 35217377 | U4: Earn Value | V4: =L28 -> 0.93306282 | W4: Phys. Earn Value | X4: =X28 -> 0.96133708 | Z4: =REPT("¢",IF(INT(+Z3*10)>5,5,INT(+Z3*10)))&REPT("£",IF(INT(+Z3*10)>5,0,5-INT(+Z3*10)))&CHAR(10)&REPT("¢",+IF(INT(+Z3*10)>5,-5+INT(+Z3*10),0))&REPT("£",IF(INT(+Z3*10)>5,10-INT(+Z3*10),5)) -> ¢¢¢¢¢ ¢¢¢££
A5: Contractor | B5: ='General Information'!C5 -> AL-ENJAZ TRADING AND CONTRACTING COMPANY | D5: Status | E5: ='General Information'!C8 -> Active | G5: Site Handover | H5: ='General Information'!C14 -> 45985 | I5: Site Handover (Hijri) | J5: ='General Information'!C18 -> 45985 | K5: Forecast Completion | L5: ='General Information'!C22 -> 46406 | M5: Estimate At Completion Value | O5: ='Invoice Log'!E5 -> 57304348 | P5: =+#REF!+#REF!+O5 -> #REF! | Q5: Penalities | S5: ='Invoice Log'!M6 -> 0 | U5: Variance | V5: =V4-V3 -> 0.33460951 | W5: Variance | X5: =X4-X3 -> 0.19731482 | Y5: Safety Score | Z5: ='HSE-Stat'!J23 -> 0.88
A6: Consultant | B6: ='General Information'!C6 -> SAUDI ARABIA CONSULTING ENGINEERING COMPANY "EGIS" | D6: Modon PM | E6: ='General Information'!C9 -> Mohammed Alshunaifi | G6: Original Completion | H6: ='General Information'!C15 -> 46530 | I6: Original Completion (Hijri) | J6: ='General Information'!C19 -> 46530 | K6: Variance | L6: ='General Information'!C23 -> 124 | M6: Potential Changes | O6: =O4-O5 -> 0 | Q6: FIR Value (Todate) | S6: =+'FIR summary '!K2 -> 53231723 | U6: FIR % | V6: =S6/O4 -> 0.92892992 | W6: Invoiced % | X6: =S4/O4 -> 0.61456728 | Z6: =REPT("¢",IF(INT(+Z5*10)>5,5,INT(+Z5*10)))&REPT("£",IF(INT(+Z5*10)>5,0,5-INT(+Z5*10)))&CHAR(10)&REPT("¢",+IF(INT(+Z5*10)>5,-5+INT(+Z5*10),0))&REPT("£",IF(INT(+Z5*10)>5,10-INT(+Z5*10),5)) -> ¢¢¢¢¢ ¢¢¢££
A8: Progress Overview
A9: Earned Value Progress (SAR) | O9: Physical Progress (Effort) | AA9: Earned Value Progress (%)
A10: WBS | C10: BOQ Value (SAR) | D10: % Wt. | E10: Weekly (SAR) | G10: To Date (SAR) | O10: Budgeted | P10: % Wt. | Q10: Weekly Physical Progress | U10: To Date Physical Progress
E11: Planned | F11: Earned | G11: Original Plan | H11: Revised Planned | I11: Earned | J11: Original Plan % | K11: Revised Planned % | L11: Earned % | M11: Variance | N11: SPI | O11: (Manhours) | Q11: Planned | R11: Earned | S11: Plan % | T11: Earned % | U11: Planned | V11: Earned | W11: Plan % | X11: Earned % | Y11: Variance | Z11: SPI
A12: =+Progress!A7 -> Preliminaries | C12: =+Progress!C7 -> 0 | D12: =IF(ISBLANK(C12),"",C12/$C$28) -> 0 | E12: =+Progress!E7 -> 0 | F12: =+Progress!F7 -> 0 | G12: =+Progress!G7 -> 0 | H12: =+Progress!H7 -> 0 | I12: =+Progress!I7 -> 0 | J12: =IFERROR(IF(ISBLANK(G12),"",G12/C12),0) -> 0 | K12: =IFERROR(IF(ISBLANK(H12),"",H12/C12),0) -> 0 | L12: =IFERROR(IF(ISBLANK(I12),"",I12/C12),0) -> 0 | M12: =IFERROR(L12-K12,"") -> 0 | N12: =IFERROR(L12/K12,"") | O12: =+Progress!K7 -> 8492 | P12: =IF(ISBLANK(O12),"",O12/$O$28) -> 0.020904465 | Q12: =+Progress!M7 -> 0 | R12: =+Progress!N7 -> 0 | S12: =IFERROR(IF(ISBLANK(Q12),"",Q12/O12),0) -> 0 | T12: =IFERROR(IF(ISBLANK(R12),"",R12/O12),0) -> 0 | U12: =+Progress!O7 -> 8492 | V12: =+Progress!P7 -> 8492 | W12: =IFERROR(IF(ISBLANK(U12),"",U12/O12),0) -> 1 | X12: =IFERROR(IF(ISBLANK(V12),"",V12/O12),0) -> 1 | Y12: =IFERROR(X12-W12,"") -> 0 | Z12: =IFERROR(X12/W12,"") -> 1
A13: =+Progress!A9 -> Engineering | C13: =+Progress!C9 -> 1719130.4 | D13: =IF(ISBLANK(C13),"",C13/$C$28) -> 0.03 | E13: =+Progress!E9 -> 0 | F13: =+Progress!F9 -> 0 | G13: =+Progress!G9 -> 1719130.4 | H13: =+Progress!H9 -> 1690948 | I13: =+Progress!I9 -> 1719130.4 | J13: =IFERROR(IF(ISBLANK(G13),"",G13/C13),0) -> 1 | K13: =IFERROR(IF(ISBLANK(H13),"",H13/C13),0) -> 0.98360656 | L13: =IFERROR(IF(ISBLANK(I13),"",I13/C13),0) -> 1 | M13: =IFERROR(L13-K13,"") -> 0.016393445 | N13: =IFERROR(L13/K13,"") -> 1.0166667 | O13: =+Progress!K9 -> 18263 | P13: =IF(ISBLANK(O13),"",O13/$O$28) -> 0.044957401 | Q13: =+Progress!M9 -> 108 | R13: =+Progress!N9 -> 0 | S13: =IFERROR(IF(ISBLANK(Q13),"",Q13/O13),0) -> 0.0059135958 | T13: =IFERROR(IF(ISBLANK(R13),"",R13/O13),0) -> 0 | U13: =+Progress!O9 -> 18189 | V13: =+Progress!P9 -> 18270 | W13: =IFERROR(IF(ISBLANK(U13),"",U13/O13),0) -> 0.99594809 | X13: =IFERROR(IF(ISBLANK(V13),"",V13/O13),0) -> 1.0003833 | Y13: =IFERROR(X13-W13,"") -> 0.0044351968 | Z13: =IFERROR(X13/W13,"") -> 1.0044532
A14: =+Progress!A11 -> Procuments | C14: =+Progress!C11 -> 11460870 | D14: =IF(ISBLANK(C14),"",C14/$C$28) -> 0.2 | E14: =+Progress!E11 -> 393541.03 | F14: =+Progress!F11 -> 0 | G14: =+Progress!G11 -> 10712587 | H14: =+Progress!H11 -> 9731079.8 | I14: =+Progress!I11 -> 11460870 | J14: =IFERROR(IF(ISBLANK(G14),"",G14/C14),0) -> 0.93470982 | K14: =IFERROR(IF(ISBLANK(H14),"",H14/C14),0) -> 0.84906994 | L14: =IFERROR(IF(ISBLANK(I14),"",I14/C14),0) -> 1 | M14: =IFERROR(L14-K14,"") -> 0.15093006 | N14: =IFERROR(L14/K14,"") -> 1.1777593 | O14: =+Progress!K11 -> 82180 | P14: =IF(ISBLANK(O14),"",O14/$O$28) -> 0.20229969 | Q14: =+Progress!M11 -> 1086 | R14: =+Progress!N11 -> 0 | S14: =IFERROR(IF(ISBLANK(Q14),"",Q14/O14),0) -> 0.013214894 | T14: =IFERROR(IF(ISBLANK(R14),"",R14/O14),0) -> 0 | U14: =+Progress!O11 -> 79551 | V14: =+Progress!P11 -> 83973 | W14: =IFERROR(IF(ISBLANK(U14),"",U14/O14),0) -> 0.96800925 | X14: =IFERROR(IF(ISBLANK(V14),"",V14/O14),0) -> 1.021818 | Y14: =IFERROR(X14-W14,"") -> 0.053808713 | Z14: =IFERROR(X14/W14,"") -> 1.055587
A15: =+Progress!A13 -> ROAD WORKS | C15: =+Progress!C13 -> 13221675 | D15: =IF(ISBLANK(C15),"",C15/$C$28) -> 0.23072726 | E15: =+Progress!E13 -> 116746.48 | F15: =+Progress!F13 -> 201466.73 | G15: =+Progress!G13 -> 8086622.7 | H15: =+Progress!H13 -> 7989416.3 | I15: =+Progress!I13 -> 14417397 | J15: =IFERROR(IF(ISBLANK(G15),"",G15/C15),0) -> 0.61161862 | K15: =IFERROR(IF(ISBLANK(H15),"",H15/C15),0) -> 0.60426657 | L15: =IFERROR(IF(ISBLANK(I15),"",I15/C15),0) -> 1.0904365 | M15: =IFERROR(L15-K15,"") -> 0.48616991 | N15: =IFERROR(L15/K15,"") -> 1.804562 | O15: =+Progress!K13 -> 53186 | P15: =IF(ISBLANK(O15),"",O15/$O$28) -> 0.13092615 | Q15: =+Progress!M13 -> 540 | R15: =+Progress!N13 -> 1563 | S15: =IFERROR(IF(ISBLANK(Q15),"",Q15/O15),0) -> 0.010153048 | T15: =IFERROR(IF(ISBLANK(R15),"",R15/O15),0) -> 0.029387433 | U15: =+Progress!O13 -> 39667 | V15: =+Progress!P13 -> 56207 | W15: =IFERROR(IF(ISBLANK(U15),"",U15/O15),0) -> 0.74581657 | X15: =IFERROR(IF(ISBLANK(V15),"",V15/O15),0) -> 1.0568007 | Y15: =IFERROR(X15-W15,"") -> 0.31098409 | Z15: =IFERROR(X15/W15,"") -> 1.4169713
A16: =+Progress!A15 -> Electrical Works | C16: =+Progress!C15 -> 3953631.6 | D16: =IF(ISBLANK(C16),"",C16/$C$28) -> 0.068993572 | E16: =+Progress!E15 -> 90863.03 | F16: =+Progress!F15 -> 113449.56 | G16: =+Progress!G15 -> 2790664.9 | H16: =+Progress!H15 -> 1529434.3 | I16: =+Progress!I15 -> 4232139.5 | J16: =IFERROR(IF(ISBLANK(G16),"",G16/C16),0) -> 0.70584847 | K16: =IFERROR(IF(ISBLANK(H16),"",H16/C16),0) -> 0.3868429 | L16: =IFERROR(IF(ISBLANK(I16),"",I16/C16),0) -> 1.0704436 | M16: =IFERROR(L16-K16,"") -> 0.68360065 | N16: =IFERROR(L16/K16,"") -> 2.7671273 | O16: =+Progress!K15 -> 58660 | P16: =IF(ISBLANK(O16),"",O16/$O$28) -> 0.14440131 | Q16: =+Progress!M15 -> 1272 | R16: =+Progress!N15 -> 1009 | S16: =IFERROR(IF(ISBLANK(Q16),"",Q16/O16),0) -> 0.021684282 | T16: =IFERROR(IF(ISBLANK(R16),"",R16/O16),0) -> 0.017200818 | U16: =+Progress!O15 -> 22808 | V16: =+Progress!P15 -> 49140 | W16: =IFERROR(IF(ISBLANK(U16),"",U16/O16),0) -> 0.38881691 | X16: =IFERROR(IF(ISBLANK(V16),"",V16/O16),0) -> 0.83770883 | Y16: =IFERROR(X16-W16,"") -> 0.44889192 | Z16: =IFERROR(X16/W16,"") -> 2.1545072
A17: =+Progress!A17 -> Demolition Works | C17: =+Progress!C17 -> 506619.53 | D17: =IF(ISBLANK(C17),"",C17/$C$28) -> 0.0088408567 | E17: =+Progress!E17 -> 0 | F17: =+Progress!F17 -> 0 | G17: =+Progress!G17 -> 506619.53 | H17: =+Progress!H17 -> 505616.54 | I17: =+Progress!I17 -> 505616.54 | J17: =IFERROR(IF(ISBLANK(G17),"",G17/C17),0) -> 1 | K17: =IFERROR(IF(ISBLANK(H17),"",H17/C17),0) -> 0.99802023 | L17: =IFERROR(IF(ISBLANK(I17),"",I17/C17),0) -> 0.99802023 | M17: =IFERROR(L17-K17,"") -> 0 | N17: =IFERROR(L17/K17,"") -> 1 | O17: =+Progress!K17 -> 14710 | P17: =IF(ISBLANK(O17),"",O17/$O$28) -> 0.036211103 | Q17: =+Progress!M17 -> 0 | R17: =+Progress!N17 -> 0 | S17: =IFERROR(IF(ISBLANK(Q17),"",Q17/O17),0) -> 0 | T17: =IFERROR(IF(ISBLANK(R17),"",R17/O17),0) -> 0 | U17: =+Progress!O17 -> 16105 | V17: =+Progress!P17 -> 16105 | W17: =IFERROR(IF(ISBLANK(U17),"",U17/O17),0) -> 1.0948334 | X17: =IFERROR(IF(ISBLANK(V17),"",V17/O17),0) -> 1.0948334 | Y17: =IFERROR(X17-W17,"") -> 0 | Z17: =IFERROR(X17/W17,"") -> 1
A18: =+Progress!A19 -> Storm Water Network | C18: =+Progress!C19 -> 3336320.6 | D18: =IF(ISBLANK(C18),"",C18/$C$28) -> 0.058221073 | E18: =+Progress!E19 -> 59901.47 | F18: =+Progress!F19 -> 0 | G18: =+Progress!G19 -> 3336320.6 | H18: =+Progress!H19 -> 2238976.9 | I18: =+Progress!I19 -> 2558110.5 | J18: =IFERROR(IF(ISBLANK(G18),"",G18/C18),0) -> 1 | K18: =IFERROR(IF(ISBLANK(H18),"",H18/C18),0) -> 0.67109163 | L18: =IFERROR(IF(ISBLANK(I18),"",I18/C18),0) -> 0.76674599 | M18: =IFERROR(L18-K18,"") -> 0.095654356 | N18: =IFERROR(L18/K18,"") -> 1.1425355 | O18: =+Progress!K19 -> 29100 | P18: =IF(ISBLANK(O18),"",O18/$O$28) -> 0.071634472 | Q18: =+Progress!M19 -> 270 | R18: =+Progress!N19 -> 0 | S18: =IFERROR(IF(ISBLANK(Q18),"",Q18/O18),0) -> 0.0092783505 | T18: =IFERROR(IF(ISBLANK(R18),"",R18/O18),0) -> 0 | U18: =+Progress!O19 -> 26800 | V18: =+Progress!P19 -> 29900 | W18: =IFERROR(IF(ISBLANK(U18),"",U18/O18),0) -> 0.9209622 | X18: =IFERROR(IF(ISBLANK(V18),"",V18/O18),0) -> 1.0274914 | Y18: =IFERROR(X18-W18,"") -> 0.10652921 | Z18: =IFERROR(X18/W18,"") -> 1.1156716
A19: =+Progress!A21 -> Plots | C19: =+Progress!C21 -> 7378530.4 | D19: =IF(ISBLANK(C19),"",C19/$C$28) -> 0.12876039 | E19: =+Progress!E21 -> 0 | F19: =+Progress!F21 -> 152056.15 | G19: =+Progress!G21 -> 7378530.4 | H19: =+Progress!H21 -> 4337407.5 | I19: =+Progress!I21 -> 6820991.2 | J19: =IFERROR(IF(ISBLANK(G19),"",G19/C19),0) -> 1 | K19: =IFERROR(IF(ISBLANK(H19),"",H19/C19),0) -> 0.58784166 | L19: =IFERROR(IF(ISBLANK(I19),"",I19/C19),0) -> 0.92443764 | M19: =IFERROR(L19-K19,"") -> 0.33659598 | N19: =IFERROR(L19/K19,"") -> 1.5725963 | O19: =+Progress!K21 -> 12640 | P19: =IF(ISBLANK(O19),"",O19/$O$28) -> 0.031115455 | Q19: =+Progress!M21 -> 0 | R19: =+Progress!N21 -> 215 | S19: =IFERROR(IF(ISBLANK(Q19),"",Q19/O19),0) -> 0 | T19: =IFERROR(IF(ISBLANK(R19),"",R19/O19),0) -> 0.017009494 | U19: =+Progress!O21 -> 10430 | V19: =+Progress!P21 -> 13856 | W19: =IFERROR(IF(ISBLANK(U19),"",U19/O19),0) -> 0.82515823 | X19: =IFERROR(IF(ISBLANK(V19),"",V19/O19),0) -> 1.0962025 | Y19: =IFERROR(X19-W19,"") -> 0.2710443 | Z19: =IFERROR(X19/W19,"") -> 1.3284756
A20: =+Progress!A23 -> Sewer Water Network | C20: =+Progress!C23 -> 2156250.5 | D20: =IF(ISBLANK(C20),"",C20/$C$28) -> 0.037628043 | E20: =+Progress!E23 -> 0 | F20: =+Progress!F23 -> 0 | G20: =+Progress!G23 -> 2156250.5 | H20: =+Progress!H23 -> 1505981 | I20: =+Progress!I23 -> 1505981 | J20: =IFERROR(IF(ISBLANK(G20),"",G20/C20),0) -> 1 | K20: =IFERROR(IF(ISBLANK(H20),"",H20/C20),0) -> 0.69842581 | L20: =IFERROR(IF(ISBLANK(I20),"",I20/C20),0) -> 0.69842581 | M20: =IFERROR(L20-K20,"") -> 0 | N20: =IFERROR(L20/K20,"") -> 1 | O20: =+Progress!K23 -> 24496 | P20: =IF(ISBLANK(O20),"",O20/$O$28) -> 0.060300963 | Q20: =+Progress!M23 -> 0 | R20: =+Progress!N23 -> 0 | S20: =IFERROR(IF(ISBLANK(Q20),"",Q20/O20),0) -> 0 | T20: =IFERROR(IF(ISBLANK(R20),"",R20/O20),0) -> 0 | U20: =+Progress!O23 -> 20616 | V20: =+Progress!P23 -> 20616 | W20: =IFERROR(IF(ISBLANK(U20),"",U20/O20),0) -> 0.84160679 | X20: =IFERROR(IF(ISBLANK(V20),"",V20/O20),0) -> 0.84160679 | Y20: =IFERROR(X20-W20,"") -> 0 | Z20: =IFERROR(X20/W20,"") -> 1
A21: =+Progress!A25 -> TSE Network | C21: =+Progress!C25 -> 1589264.4 | D21: =IF(ISBLANK(C21),"",C21/$C$28) -> 0.027733749 | E21: =+Progress!E25 -> 34853.63 | F21: =+Progress!F25 -> 0 | G21: =+Progress!G25 -> 1433580.4 | H21: =+Progress!H25 -> 1162894.8 | I21: =+Progress!I25 -> 1342832 | J21: =IFERROR(IF(ISBLANK(G21),"",G21/C21),0) -> 0.90204023 | K21: =IFERROR(IF(ISBLANK(H21),"",H21/C21),0) -> 0.73171889 | L21: =IFERROR(IF(ISBLANK(I21),"",I21/C21),0) -> 0.84493933 | M21: =IFERROR(L21-K21,"") -> 0.11322044 | N21: =IFERROR(L21/K21,"") -> 1.1547321 | O21: =+Progress!K25 -> 39495 | P21: =IF(ISBLANK(O21),"",O21/$O$28) -> 0.097223487 | Q21: =+Progress!M25 -> 480 | R21: =+Progress!N25 -> 0 | S21: =IFERROR(IF(ISBLANK(Q21),"",Q21/O21),0) -> 0.012153437 | T21: =IFERROR(IF(ISBLANK(R21),"",R21/O21),0) -> 0 | U21: =+Progress!O25 -> 32200 | V21: =+Progress!P25 -> 37150 | W21: =IFERROR(IF(ISBLANK(U21),"",U21/O21),0) -> 0.81529308 | X21: =IFERROR(IF(ISBLANK(V21),"",V21/O21),0) -> 0.9406254 | Y21: =IFERROR(X21-W21,"") -> 0.12533232 | Z21: =IFERROR(X21/W21,"") -> 1.1537267
A22: =+Progress!A27 -> Potable Water Network | C22: =+Progress!C27 -> 2200624.9 | D22: =IF(ISBLANK(C22),"",C22/$C$28) -> 0.038402407 | E22: =+Progress!E27 -> 9817.23 | F22: =+Progress!F27 -> 0 | G22: =+Progress!G27 -> 2140576.5 | H22: =+Progress!H27 -> 1775528.8 | I22: =+Progress!I27 -> 2005333.6 | J22: =IFERROR(IF(ISBLANK(G22),"",G22/C22),0) -> 0.97271301 | K22: =IFERROR(IF(ISBLANK(H22),"",H22/C22),0) -> 0.80682935 | L22: =IFERROR(IF(ISBLANK(I22),"",I22/C22),0) -> 0.91125642 | M22: =IFERROR(L22-K22,"") -> 0.10442707 | N22: =IFERROR(L22/K22,"") -> 1.1294289 | O22: =+Progress!K27 -> 31247 | P22: =IF(ISBLANK(O22),"",O22/$O$28) -> 0.076919668 | Q22: =+Progress!M27 -> 958 | R22: =+Progress!N27 -> 0 | S22: =IFERROR(IF(ISBLANK(Q22),"",Q22/O22),0) -> 0.030658943 | T22: =IFERROR(IF(ISBLANK(R22),"",R22/O22),0) -> 0 | U22: =+Progress!O27 -> 22760 | V22: =+Progress!P27 -> 27107 | W22: =IFERROR(IF(ISBLANK(U22),"",U22/O22),0) -> 0.72838993 | X22: =IFERROR(IF(ISBLANK(V22),"",V22/O22),0) -> 0.86750728 | Y22: =IFERROR(X22-W22,"") -> 0.13911736 | Z22: =IFERROR(X22/W22,"") -> 1.190993
A23: =+Progress!A29 -> Sewage Lift Station | C23: =+Progress!C29 -> 3049343.4 | D23: =IF(ISBLANK(C23),"",C23/$C$28) -> 0.053213125 | E23: =+Progress!E29 -> 1189.82 | F23: =+Progress!F29 -> 628633.39 | G23: =+Progress!G29 -> 0 | H23: =+Progress!H29 -> 5992.14 | I23: =+Progress!I29 -> 1845852.3 | J23: =IFERROR(IF(ISBLANK(G23),"",G23/C23),0) -> 0 | K23: =IFERROR(IF(ISBLANK(H23),"",H23/C23),0) -> 0.0019650591 | L23: =IFERROR(IF(ISBLANK(I23),"",I23/C23),0) -> 0.6053278 | M23: =IFERROR(L23-K23,"") -> 0.60336274 | N23: =IFERROR(L23/K23,"") -> 308.0456 | O23: =+Progress!K29 -> 15410 | P23: =IF(ISBLANK(O23),"",O23/$O$28) -> 0.037934269 | Q23: =+Progress!M29 -> 297 | R23: =+Progress!N29 -> 1164 | S23: =IFERROR(IF(ISBLANK(Q23),"",Q23/O23),0) -> 0.019273199 | T23: =IFERROR(IF(ISBLANK(R23),"",R23/O23),0) -> 0.075535367 | U23: =+Progress!O29 -> 1107 | V23: =+Progress!P29 -> 13114 | W23: =IFERROR(IF(ISBLANK(U23),"",U23/O23),0) -> 0.07183647 | X23: =IFERROR(IF(ISBLANK(V23),"",V23/O23),0) -> 0.85100584 | Y23: =IFERROR(X23-W23,"") -> 0.77916937 | Z23: =IFERROR(X23/W23,"") -> 11.846432
A24: =+Progress!A31 -> Box Culvert | C24: =+Progress!C31 -> 499321.73 | D24: =IF(ISBLANK(C24),"",C24/$C$28) -> 0.0087135051 | E24: =+Progress!E31 -> 0 | F24: =+Progress!F31 -> 0 | G24: =+Progress!G31 -> 499321.73 | H24: =+Progress!H31 -> 499735.96 | I24: =+Progress!I31 -> 499735.96 | J24: =IFERROR(IF(ISBLANK(G24),"",G24/C24),0) -> 1 | K24: =IFERROR(IF(ISBLANK(H24),"",H24/C24),0) -> 1.0008296 | L24: =IFERROR(IF(ISBLANK(I24),"",I24/C24),0) -> 1.0008296 | M24: =IFERROR(L24-K24,"") -> 0 | N24: =IFERROR(L24/K24,"") -> 1 | O24: =+Progress!K31 -> 2200 | P24: =IF(ISBLANK(O24),"",O24/$O$28) -> 0.0054156646 | Q24: =+Progress!M31 -> 0 | R24: =+Progress!N31 -> 0 | S24: =IFERROR(IF(ISBLANK(Q24),"",Q24/O24),0) -> 0 | T24: =IFERROR(IF(ISBLANK(R24),"",R24/O24),0) -> 0 | U24: =+Progress!O31 -> 2515 | V24: =+Progress!P31 -> 2515 | W24: =IFERROR(IF(ISBLANK(U24),"",U24/O24),0) -> 1.1431818 | X24: =IFERROR(IF(ISBLANK(V24),"",V24/O24),0) -> 1.1431818 | Y24: =IFERROR(X24-W24,"") -> 0 | Z24: =IFERROR(X24/W24,"") -> 1
A25: =+Progress!A33 -> Open Drain Channel | C25: =+Progress!C33 -> 389804.75 | D25: =IF(ISBLANK(C25),"",C25/$C$28) -> 0.0068023591 | E25: =+Progress!E33 -> 0 | F25: =+Progress!F33 -> 0 | G25: =+Progress!G33 -> 0 | H25: =+Progress!H33 -> 389804.76 | I25: =+Progress!I33 -> 389804.76 | J25: =IFERROR(IF(ISBLANK(G25),"",G25/C25),0) -> 0 | K25: =IFERROR(IF(ISBLANK(H25),"",H25/C25),0) -> 1 | L25: =IFERROR(IF(ISBLANK(I25),"",I25/C25),0) -> 1 | M25: =IFERROR(L25-K25,"") -> 0 | N25: =IFERROR(L25/K25,"") -> 1 | O25: =+Progress!K33 -> 5040 | P25: =IF(ISBLANK(O25),"",O25/$O$28) -> 0.012406795 | Q25: =+Progress!M33 -> 0 | R25: =+Progress!N33 -> 0 | S25: =IFERROR(IF(ISBLANK(Q25),"",Q25/O25),0) -> 0 | T25: =IFERROR(IF(ISBLANK(R25),"",R25/O25),0) -> 0 | U25: =+Progress!O33 -> 6458 | V25: =+Progress!P33 -> 6458 | W25: =IFERROR(IF(ISBLANK(U25),"",U25/O25),0) -> 1.2813492 | X25: =IFERROR(IF(ISBLANK(V25),"",V25/O25),0) -> 1.2813492 | Y25: =IFERROR(X25-W25,"") -> 0 | Z25: =IFERROR(X25/W25,"") -> 1
A26: =+Progress!A35 -> Under Pass | C26: =+Progress!C35 -> 112526.05 | D26: =IF(ISBLANK(C26),"",C26/$C$28) -> 0.0019636564 | E26: =+Progress!E35 -> 0 | F26: =+Progress!F35 -> 0 | G26: =+Progress!G35 -> 112526.05 | H26: =+Progress!H35 -> 112526.05 | I26: =+Progress!I35 -> 112526.05 | J26: =IFERROR(IF(ISBLANK(G26),"",G26/C26),0) -> 1 | K26: =IFERROR(IF(ISBLANK(H26),"",H26/C26),0) -> 1 | L26: =IFERROR(IF(ISBLANK(I26),"",I26/C26),0) -> 1 | M26: =IFERROR(L26-K26,"") -> 0 | N26: =IFERROR(L26/K26,"") -> 1 | O26: =+Progress!K35 -> 1400 | P26: =IF(ISBLANK(O26),"",O26/$O$28) -> 0.003446332 | Q26: =+Progress!M35 -> 0 | R26: =+Progress!N35 -> 0 | S26: =IFERROR(IF(ISBLANK(Q26),"",Q26/O26),0) -> 0 | T26: =IFERROR(IF(ISBLANK(R26),"",R26/O26),0) -> 0 | U26: =+Progress!O35 -> 1400 | V26: =+Progress!P35 -> 1400 | W26: =IFERROR(IF(ISBLANK(U26),"",U26/O26),0) -> 1 | X26: =IFERROR(IF(ISBLANK(V26),"",V26/O26),0) -> 1 | Y26: =IFERROR(X26-W26,"") -> 0 | Z26: =IFERROR(X26/W26,"") -> 1
A27: =+Progress!A37 -> Testing and Commissioning | C27: =+Progress!C37 -> 5730434.8 | D27: =IF(ISBLANK(C27),"",C27/$C$28) -> 0.1 | E27: =+Progress!E37 -> 0 | F27: =+Progress!F37 -> 163726.7 | G27: =+Progress!G37 -> 1637267.1 | H27: =+Progress!H37 -> 818633.54 | I27: =+Progress!I37 -> 4052236 | J27: =IFERROR(IF(ISBLANK(G27),"",G27/C27),0) -> 0.28571429 | K27: =IFERROR(IF(ISBLANK(H27),"",H27/C27),0) -> 0.14285714 | L27: =IFERROR(IF(ISBLANK(I27),"",I27/C27),0) -> 0.70714286 | M27: =IFERROR(L27-K27,"") -> 0.56428571 | N27: =IFERROR(L27/K27,"") -> 4.95 | O27: =+Progress!K37 -> 9710 | P27: =IF(ISBLANK(O27),"",O27/$O$28) -> 0.023902774 | Q27: =+Progress!M37 -> 0 | R27: =+Progress!N37 -> 240 | S27: =IFERROR(IF(ISBLANK(Q27),"",Q27/O27),0) -> 0 | T27: =IFERROR(IF(ISBLANK(R27),"",R27/O27),0) -> 0.024716787 | U27: =+Progress!O37 -> 1270 | V27: =+Progress!P37 -> 6220 | W27: =IFERROR(IF(ISBLANK(U27),"",U27/O27),0) -> 0.130793 | X27: =IFERROR(IF(ISBLANK(V27),"",V27/O27),0) -> 0.64057673 | Y27: =IFERROR(X27-W27,"") -> 0.50978373 | Z27: =IFERROR(X27/W27,"") -> 4.8976378
B28: Total | C28: =SUM(C12:C27) -> 57304348 | D28: =SUM(D12:D27) -> 1 | E28: =SUM(E12:E27) -> 706912.69 | F28: =SUM(F12:F27) -> 1259332.5 | G28: =SUM(G12:G27) -> 42509998 | H28: =SUM(H12:H27) -> 34293976 | I28: =SUM(I12:I27) -> 53468556 | J28: =IFERROR(IF(ISBLANK(G28),"",G28/C28),0) -> 0.74182849 | K28: =IFERROR(IF(ISBLANK(H28),"",H28/C28),0) -> 0.5984533 | L28: =IFERROR(IF(ISBLANK(I28),"",I28/C28),0) -> 0.93306282 | M28: =+L28-K28 -> 0.33460951 | N28: =L28/K28 -> 1.5591238 | O28: =SUM(O12:O27) -> 406229 | P28: =SUM(P12:P27) -> 1 | Q28: =SUM(Q12:Q27) -> 5011 | R28: =SUM(R12:R27) -> 4191 | S28: =IFERROR(IF(ISBLANK(Q28),"",Q28/O28),0) -> 0.012335407 | T28: =IFERROR(IF(ISBLANK(R28),"",R28/O28),0) -> 0.010316841 | U28: =SUM(U12:U27) -> 310368 | V28: =SUM(V12:V27) -> 390523 | W28: =IFERROR(IF(ISBLANK(U28),"",U28/O28),0) -> 0.76402226 | X28: =IFERROR(IF(ISBLANK(V28),"",V28/O28),0) -> 0.96133708 | Y28: =+X28-W28 -> 0.19731482 | Z28: =X28/W28 -> 1.2582579
AA29: Construction Milestones
AA30: Item No. | AB30: Milestones | AD30: Original (Baseline) | AE30: Latest Plan | AF30: Forecast | AG30: Status | AH30: Days Change
AA31: =+Milestones!A4 -> 1 | AB31: =+Milestones!B4 -> Award Date | AD31: =+Milestones!C4 -> 45970 | AE31: =+Milestones!D4 -> 45970 | AF31: =+Milestones!E4 -> 45970 | AG31: =+Milestones!F4 -> A | AH31: =+Milestones!G4 -> 0
AA32: =+Milestones!A5 -> 2 | AB32: =+Milestones!B5 -> Contract Sign Date | AD32: =+Milestones!C5 -> 45977 | AE32: =+Milestones!D5 -> 45977 | AF32: =+Milestones!E5 -> 45977 | AG32: =+Milestones!F5 -> A | AH32: =+Milestones!G5 -> 0
AA33: =+Milestones!A6 -> 3 | AB33: =+Milestones!B6 -> Site Handover Date | AD33: =+Milestones!C6 -> 45985 | AE33: =+Milestones!D6 -> 45985 | AF33: =+Milestones!E6 -> 45985 | AG33: =+Milestones!F6 -> A | AH33: =+Milestones!G6 -> 0
AA34: =+Milestones!A7 -> 4 | AB34: =+Milestones!B7 -> Complete Mobilization | AD34: =+Milestones!C7 -> 46014 | AE34: =+Milestones!D7 -> 46014 | AF34: =+Milestones!E7 -> 46014 | AG34: =+Milestones!F7 -> A | AH34: =+Milestones!G7 -> 0
AA35: =+Milestones!A10 -> 7 | AB35: =+Milestones!B10 -> Complete delivery of all equipment and materials | AD35: =+Milestones!C10 -> 46387 | AE35: =+Milestones!D10 -> 46393 | AF35: =+Milestones!E10 -> 46301 | AG35: =+Milestones!F10 -> A | AH35: =+Milestones!G10 -> 92
AA36: =+Milestones!A11 -> 8 | AB36: =+Milestones!B11 -> Complete Road Works | AD36: =+Milestones!C11 -> 46287 | AE36: =+Milestones!D11 -> 46373 | AF36: =+Milestones!E11 -> 46308 | AG36: =+Milestones!F11 | AH36: =+Milestones!G11 -> 65
AA37: =+Milestones!A12 -> 9 | AB37: =+Milestones!B12 -> Complete Electrical – Mv Distribution Network | AD37: =+Milestones!C12 -> 46513 | AE37: =+Milestones!D12 -> 46433 | AF37: =+Milestones!E12 -> 46308 | AG37: =+Milestones!F12 | AH37: =+Milestones!G12 -> 125
AA38: =+Milestones!A13 -> 10 | AB38: =+Milestones!B13 -> Completion of Potable Water Network | AD38: =+Milestones!C13 -> 46349 | AE38: =+Milestones!D13 -> 46406 | AF38: =+Milestones!E13 -> 46270 | AG38: =+Milestones!F13 -> A | AH38: =+Milestones!G13 -> 136
AA39: =+Milestones!A14 -> 11 | AB39: =+Milestones!B14 -> Complete all Works including Testing & Commissioning, Cleanup, Closeout Documentation and Ready for Initial Handover | AD39: =+Milestones!C14 -> 46530 | AE39: =+Milestones!D14 -> 46539 | AF39: =+Milestones!E14 -> 46393 | AG39: =+Milestones!F14 | AH39: =+Milestones!G14 -> 146
AA40: =+Milestones!A15 -> 12 | AB40: =+Milestones!B15 -> Complete Demobilization | AD40: =+Milestones!C15 -> 46530 | AE40: =+Milestones!D15 -> 46552 | AF40: =+Milestones!E15 -> 46406 | AG40: =+Milestones!F15 | AH40: =+Milestones!G15 -> 146
A56: Performance overview
...

Sheet FIR summary 
A1: Project Name | C1: =+'General Information'!C3:I3 -> LAND DEVELOPMENT OF JEDDAH OASIS | F1: Total FIR Amount | I1: =+Total -> 1103431.6 | J1: Cum Previous FIR | K1: Cum up To Date FRI
A2: Project ID | C2: =+'General Information'!C4:I4 -> JHD4-02-007 | E2: Project Budget | F2: 57304348 | J2: 42652526 | K2: ='FIR sum'!C49 -> 53231723
A3: Date Period | C3: =+F3-6 -> 46302 | E3: To | F3: =+'General Information'!L1 -> 46308
A5: BOQ Item # | B5: BOQ Description | C5: FIR # | D5: FIR DATE | E5: FIR Description | F5: Unit | G5: Unit Rate | H5: Current Pariod Quantity | I5: Total (SR)
A7: B4.33 14 13.02 | B7: Chamber at pipe 400 mm Dia, Depth 1.5 - 4.0 m | C7: JDH4-02-007-ENJ-TS9-1-CVL-FIR-1052 | D7: 46257 | E7: INSPECTION REQUEST FOR EXCAVATION & LEAN CONCRETE & REINFORCED CONCRETE BASE OF BUTTERFLY VALVE ROOM DIA 400 MM FOR IRRIGATION LINE -02 DIA 400 MM , ROAD (1) AT STATION (00+060) NUMBER (101) | G7: 56485.2 | H7: 0.2 | I7: 11297.04
A8: B4.33 14 13.02 | B8: Chamber at pipe 400 mm Dia, Depth 1.5 - 4.0 m | C8: JDH4-02-007-ENJ-TS9-1-CVL-FIR-1053 | D8: 46257 | E8: INSPECTION REQUEST FOR REINFORCED CONCRETE WALL OF BUTTERFLY VALVE ROOM DIA 400 MM FOR IRRIGATION LINE -02 DIA 400 MM , ROAD (1) AT STATION (00+060) NUMBER (101) | G8: 56485.2 | H8: 0.2 | I8: 11297.04
A9: B4.33 14 13.02 | B9: Chamber at pipe 400 mm Dia, Depth 1.5 - 4.0 m | C9: JDH4-02-007-ENJ-TS9-1-CVL-FIR-1054 | D9: 46166 | E9: INSPECTION REQUEST FOR REINFORCED CONCRETE SLAB OF BUTTERFLY VALVE ROOM DIA 400 MM FOR IRRIGATION LINE -02 DIA 400 MM , ROAD (1) AT STATION (00+060) NUMBER (101) | G9: 56485.2 | H9: 0.2 | I9: 11297.04
A10: B4.33 14 13.02 | B10: Chamber at pipe 400 mm Dia, Depth 1.5 - 4.0 m | C10: JDH4-02-007-ENJ-TS9-1-CVL-FIR-1055 | D10: 46166 | E10: INSPECTION REQUEST FOR Bitumin Insulation , BACKFILLING , Installation and finishing Cover Frames FOR BUTTERFLY VALVE ROOM DIA 400 MM FOR IRRIGATION LINE -02 DIA 400 MM , ROAD (1) AT STATION (00+060) NUMBER (101) | G10: 56485.2 | H10: 0.4 | I10: 22594.08
A11: B7.7.2 | B11: 2 Coats of Bituminous Paint | C11: JDH4-02-007-ENJ-TS9-1-CVL-FIR-1056 | D11: 46166 | E11: Inspection Request for Application of 2 Coats of Bituminous Paint for Remaining of pumping station control foundation , Under Ground fuel tank and oddor Inside Lift Station | G11: 28.2426 | H11: 97.78 | I11: 2761.5614
A12: B1.32 14 13.03 | B12: Precast Concrete curb, Type (K4) | C12: JDH4-02-007-ENJ-TS9-1-CVL-FIR-1057 | D12: 45893 | E12: INSPECTION REQUEST FOR CASTING ( Curbstone K4 ) AT (ROAD 5 LEFT) RIGHT & LEFT SIDE FROM STATION 0+00 TO 0+400 | G12: 56.49 | H12: 783.36 | I12: 44252.006
A13: B1.31 22 00.04 | B13: Plots backfilling | C13: JDH4-02-007-ENJ-TS9-1-CVL-FIR-1058 | D13: 59408 | E13: INSPECTION REQUEST FOR BACKFILING SELECTED MATERIAL FOR 30 CM OVER ROCK FILL AT PLOT 1 AS PER SHOP DRAWING | G13: 23.54 | H13: 8199.19 | I13: 193008.93
A14: B1.32 14 13.02 | B14: Precast Concrete curb, Type (K2) | C14: JDH4-02-007-ENJ-TS9-1-CVL-FIR-1059 | D14: 46261 | E14: INSPECTION REQUEST FOR CASTING ( Curbstone K2 ) AT ROAD 5 LEFT FROM STATION 0+00 TO 0+400 | G14: 56.4852 | H14: 12 | I14: 677.8224
A15: B1.32 14 13.02 | B15: Precast Concrete curb, Type (K2) | C15: JDH4-02-007-ENJ-TS9-1-CVL-FIR-1060 | D15: 46261 | E15: INSPECTION REQUEST FOR CASTINIG ( Curbstone K2 ) AT NTERSECTION BETWEEN ROAD 04R & 07N | G15: 56.4852 | H15: 12 | I15: 677.8224
A16: B1.32 14 13.13.01 | B16: Interlocking block pavers for sidewalk/footpath | C16: JDH4-02-007-ENJ-TS9-1-CVL-FIR-1061 | D16: 46261 | E16: INSPECTION REQUEST FOR PRECAST INTERLCOKING BLOCK PAVERS AT (ROAD 5 LEFT) RIGHT & LEFT SIDE FROM STATION 0+000 TO 0+400 | G16: 70.61 | H16: 885.13 | I16: 62499.029
A17: B1.31 22 00.03 | B17: Road backfilling | C17: JDH4-02-007-ENJ-TS9-1-CVL-FIR-1062 | D17: 46261 | E17: INSPECTION REQUEST FOR N.G.L FOR TENT ROAD FROM STATION 0+00 TO 0+241 | G17: 23.54 | H17: 0 | I17: 0
A18: B1.31 22 00.01 | B18: Road excavation | C18: JDH4-02-007-ENJ-TS9-1-CVL-FIR-1063 | D18: 46261 | E18: INSPECTION REQUEST FOR EXCAVATION AT ROAD 1 FROM STATION 0+030 TO 0+604 | G18: 26.36 | H18: 3699.99 | I18: 97531.736
... A27: B2.31 23 00.01 | B27: Excavation for Trench size 40cm wide and 80cm deep (for 1 cable) | C27: JDH4-02-007-ENJ-TS9-1-ELE-FIR-0063 | D27: 46260 | E27: Inspection Request for Medium Voltage Cable Trench Excavation Size 40cm wide and 80cm deep for ( 1 Cable ) At Road 03 & 01 & 04L & 05L & 07S & EXISTING ROAD | G27: 37.66 | H27: 803.2 | I27: 30248.512
A43: Total Pariod Amount | I43: 1103431.6
A104: MEC | B104: 140
A105: CIVIL | B105: 539
A106: TEL | B106: 8
A107: ELEC | B107: 6

Sheet FIR sum
A1: S.NO | B1: FIR Date | C1: FIR Amount | D1: FIR % | E1: FIR Cum % | H1: 57304348
A2: 1
A3: 2
A4: 3
A5: 4
A6: 5 | B6: 46014 | C6: 0 | D6: =C6/$H$1 -> 0 | E6: =D6 -> 0
A7: 6 | B7: 46021 | C7: 0 | D7: =C7/$H$1 -> 0 | E7: =D7+E6 -> 0
A8: 7 | B8: 46028 | C8: 1077571.9 | D8: =C8/$H$1 -> 0.018804365 | E8: =D8+E7 -> 0.018804365
A9: 8 | B9: 46035 | C9: 542607.01 | D9: =C9/$H$1 -> 0.0094688628 | E9: =D9+E8 -> 0.028273228
A10: 9 | B10: 46042 | C10: 582575.96 | D10: =C10/$H$1 -> 0.010166348 | E10: =D10+E9 -> 0.038439576
A11: 10 | B11: 46049 | C11: 637735.66 | D11: =C11/$H$1 -> 0.011128923 | E11: =D11+E10 -> 0.049568499
A12: 11 | B12: 46055 | C12: 645396.07 | D12: =C12/$H$1 -> 0.011262602 | E12: =D12+E11 -> 0.060831101
A13: 12 | B13: 46063 | C13: 1281198.6 | D13: =C13/$H$1 -> 0.022357791 | E13: =D13+E12 -> 0.083188892
A14: 13 | B14: 46070 | C14: 2381311.4 | D14: =C14/$H$1 -> 0.041555511 | E14: =D14+E13 -> 0.1247444
A15: 14 | B15: 46077 | C15: 1191399.1 | D15: =C15/$H$1 -> 0.020790728 | E15: =D15+E14 -> 0.14553513
A16: 15 | B16: 46084 | C16: 867347.91 | D16: =C16/$H$1 -> 0.015135813 | E16: =D16+E15 -> 0.16067094
A17: 16 | B17: 46091 | C17: 999995.21 | D17: =C17/$H$1 -> 0.017450599 | E17: =D17+E16 -> 0.17812154
A18: 17 | B18: 46098 | C18: 1218608.1 | D18: =C18/$H$1 -> 0.021265543 | E18: =D18+E17 -> 0.19938709
... A25: 24 | B25: 46147 | C25: 1322147.5 | D25: =C25/$H$1 -> 0.023072377 | E25: =D25+E24 -> 0.37000294
A26: 25 | B26: =B25+7 -> 46154 | C26: 980131.33 | D26: =C26/$H$1 -> 0.017103961 | E26: =D26+E25 -> 0.3871069
A27: 26 | B27: =B26+7 -> 46161 | C27: 1205942.3 | D27: =C27/$H$1 -> 0.021044517 | E27: =D27+E26 -> 0.40815142
A28: 27 | B28: =B27+7 -> 46168 | C28: 1449798.2 | D28: =C28/$H$1 -> 0.025299968 | E28: =D28+E27 -> 0.43345139
A29: 28 | B29: =B28+7 -> 46175 | C29: 738582.78 | D29: =C29/$H$1 -> 0.012888774 | E29: =D29+E28 -> 0.44634016
A30: 29 | B30: =B29+7 -> 46182 | C30: 1189112 | D30: =C30/$H$1 -> 0.020750816 | E30: =D30+E29 -> 0.46709098
A31: 30 | B31: =B30+7 -> 46189 | C31: 1772610.9 | D31: =C31/$H$1 -> 0.03093327 | E31: =D31+E30 -> 0.49802425
A32: 31 | B32: =B31+7 -> 46196 | C32: 1439350.6 | D32: =C32/$H$1 -> 0.025117651 | E32: =D32+E31 -> 0.5231419
A33: 32 | B33: =B32+7 -> 46203 | C33: 1082355.1 | D33: =C33/$H$1 -> 0.018887835 | E33: =D33+E32 -> 0.54202973
A34: 33 | B34: =B33+7 -> 46210 | C34: 1805213.4 | D34: =C34/$H$1 -> 0.031502207 | E34: =D34+E33 -> 0.57353194
A35: 34 | B35: =B34+7 -> 46217 | C35: 1180368.6 | D35: =C35/$H$1 -> 0.020598239 | E35: =D35+E34 -> 0.59413018
A36: 35 | B36: =B35+7 -> 46224 | C36: 2095216.2 | D36: =C36/$H$1 -> 0.036562954 | E36: =D36+E35 -> 0.63069313
A37: 36 | B37: =B36+7 -> 46231 | C37: 1687000.7 | D37: =C37/$H$1 -> 0.029439315 | E37: =D37+E36 -> 0.66013245
... A48: 47 | B48: =B47+7 -> 46308 | C48: 1103431.6 | D48: =C48/$H$1 -> 0.019255636 | E48: =D48+E47 -> 0.92892992
B49: Total | C49: =SUM(C6:C48) -> 53231723

Sheet Progress
A1: Project Scope Statement | B1: Land development of jeddah oasis (The project includes construction of Roads works ; Storm water piping network with catch basins and manholes, Box Culvert ;Sewerage piping network with manhole ; Potable water piping network with fitting , valves and fire hydrant ;TSE Network ; Sewerage pump stations ;Channels ;36 KV medium voltage cable with Ring Main Unit ; Street Lighting with Unit Sub-stations , Ring Main Units and Low Voltage Cables ,concrete ducts at road crossing) | S1: ='General Information'!$K$1 -> Data Date | T1: ='General Information'!L1 -> 46308
A4: Earned Value Progress (SAR) | K4: Physical Progress (Effort)
A5: WBS | C5: BOQ Value (SAR) | D5: % Wt. | E5: Weekly (SAR) | H5: To Date (SAR) | K5: Budgeted | L5: % Wt. | M5: Weekly Physical Progress | O5: To Date Physical Progress
E6: Planned | F6: Earned | G6: Original Plan | H6: Planned | I6: Earned | K6: (Manhours) | M6: Planned | N6: Earned | O6: Planned | P6: Earned
A7: Preliminaries | C7: =SUBTOTAL(9,C8:C8) -> 0 | D7: =IF(ISBLANK(C7),"",C7/$C$41) -> 0 | E7: =SUBTOTAL(9,E8:E8) -> 0 | F7: =SUBTOTAL(9,F8:F8) -> 0 | G7: =SUBTOTAL(9,G8:G8) -> 0 | H7: =SUBTOTAL(9,H8:H8) -> 0 | I7: =SUBTOTAL(9,I8:I8) -> 0 | K7: =SUBTOTAL(9,K8:K8) -> 8492 | L7: =IF(ISBLANK(K7),"",K7/$K$41) -> 0.020904465 | M7: =SUBTOTAL(9,M8:M8) -> 0 | N7: =SUBTOTAL(9,N8:N8) -> 0 | O7: =SUBTOTAL(9,O8:O8) -> 8492 | P7: =SUBTOTAL(9,P8:P8) -> 8492
A8: Mobilization | C8: 0 | D8: =IF(ISBLANK(C8),"",C8/$C$41) -> 0 | E8: =+'Progress (2)'!I4 -> 0 | F8: =+'Progress (2)'!J4 -> 0 | G8: =+'Progress (2)'!K4 -> 0 | H8: =+'Progress (2)'!L4 -> 0 | I8: =+'Progress (2)'!M4 -> 0 | K8: 8492 | L8: =IF(ISBLANK(K8),"",K8/$K$41) -> 0.020904465 | M8: =+'Progress (2)'!O4 -> 0 | N8: =+'Progress (2)'!P4 -> 0 | O8: =+'Progress (2)'!Q4 -> 8492 | P8: =+'Progress (2)'!R4 -> 8492
A9: Engineering | C9: =SUBTOTAL(9,C10:C10) -> 1719130.4 | D9: =IF(ISBLANK(C9),"",C9/$C$41) -> 0.03 | E9: =SUBTOTAL(9,E10:E10) -> 0 | F9: =SUBTOTAL(9,F10:F10) -> 0 | G9: =SUBTOTAL(9,G10:G10) -> 1719130.4 | H9: =SUBTOTAL(9,H10:H10) -> 1690948 | I9: =SUBTOTAL(9,I10:I10) -> 1719130.4 | K9: =SUBTOTAL(9,K10:K10) -> 18263 | L9: =IF(ISBLANK(K9),"",K9/$K$41) -> 0.044957401 | M9: =SUBTOTAL(9,M10:M10) -> 108 | N9: =SUBTOTAL(9,N10:N10) -> 0 | O9: =SUBTOTAL(9,O10:O10) -> 18189 | P9: =SUBTOTAL(9,P10:P10) -> 18270
A10: Engineering | C10: 1719130.4 | D10: =IF(ISBLANK(C10),"",C10/$C$41) -> 0.03 | E10: =+'Progress (2)'!I5 -> 0 | F10: =+'Progress (2)'!J5 -> 0 | G10: =+'Progress (2)'!K5 -> 1719130.4 | H10: =+'Progress (2)'!L5 -> 1690948 | I10: =+'Progress (2)'!M5 -> 1719130.4 | K10: 18263 | L10: =IF(ISBLANK(K10),"",K10/$K$41) -> 0.044957401 | M10: =+'Progress (2)'!O5 -> 108 | N10: =+'Progress (2)'!P5 -> 0 | O10: =+'Progress (2)'!Q5 -> 18189 | P10: =+'Progress (2)'!R5 -> 18270
A11: Procuments | C11: =SUBTOTAL(9,C12:C12) -> 11460870 | D11: =IF(ISBLANK(C11),"",C11/$C$41) -> 0.2 | E11: =SUBTOTAL(9,E12:E12) -> 393541.03 | F11: =SUBTOTAL(9,F12:F12) -> 0 | G11: =SUBTOTAL(9,G12:G12) -> 10712587 | H11: =SUBTOTAL(9,H12:H12) -> 9731079.8 | I11: =SUBTOTAL(9,I12:I12) -> 11460870 | K11: =SUBTOTAL(9,K12:K12) -> 82180 | L11: =IF(ISBLANK(K11),"",K11/$K$41) -> 0.20229969 | M11: =SUBTOTAL(9,M12:M12) -> 1086 | N11: =SUBTOTAL(9,N12:N12) -> 0 | O11: =SUBTOTAL(9,O12:O12) -> 79551 | P11: =SUBTOTAL(9,P12:P12) -> 83973
A12: Procuments | C12: 11460870 | D12: =IF(ISBLANK(C12),"",C12/$C$41) -> 0.2 | E12: =+'Progress (2)'!I6 -> 393541.03 | F12: =+'Progress (2)'!J6 -> 0 | G12: =+'Progress (2)'!K6 -> 10712587 | H12: =+'Progress (2)'!L6 -> 9731079.8 | I12: =+'Progress (2)'!M6 -> 11460870 | K12: 82180 | L12: =IF(ISBLANK(K12),"",K12/$K$41) -> 0.20229969 | M12: =+'Progress (2)'!O6 -> 1086 | N12: =+'Progress (2)'!P6 -> 0 | O12: =+'Progress (2)'!Q6 -> 79551 | P12: =+'Progress (2)'!R6 -> 83973
A13: ROAD WORKS | C13: =SUBTOTAL(9,C14:C14) -> 13221675 | D13: =IF(ISBLANK(C13),"",C13/$C$41) -> 0.23072726 | E13: =SUBTOTAL(9,E14:E14) -> 116746.48 | F13: =SUBTOTAL(9,F14:F14) -> 201466.73 | G13: =SUBTOTAL(9,G14:G14) -> 8086622.7 | H13: =SUBTOTAL(9,H14:H14) -> 7989416.3 | I13: =SUBTOTAL(9,I14:I14) -> 14417397 | K13: =SUBTOTAL(9,K14:K14) -> 53186 | L13: =IF(ISBLANK(K13),"",K13/$K$41) -> 0.13092615 | M13: =SUBTOTAL(9,M14:M14) -> 540 | N13: =SUBTOTAL(9,N14:N14) -> 1563 | O13: =SUBTOTAL(9,O14:O14) -> 39667 | P13: =SUBTOTAL(9,P14:P14) -> 56207
A14: ROAD WORKS | C14: 13221675 | D14: =IF(ISBLANK(C14),"",C14/$C$41) -> 0.23072726 | E14: =+'Progress (2)'!I7 -> 116746.48 | F14: =+'Progress (2)'!J7 -> 201466.73 | G14: =+'Progress (2)'!K7 -> 8086622.7 | H14: =+'Progress (2)'!L7 -> 7989416.3 | I14: =+'Progress (2)'!M7 -> 14417397 | K14: 53186 | L14: =IF(ISBLANK(K14),"",K14/$K$41) -> 0.13092615 | M14: =+'Progress (2)'!O7 -> 540 | N14: =+'Progress (2)'!P7 -> 1563 | O14: =+'Progress (2)'!Q7 -> 39667 | P14: =+'Progress (2)'!R7 -> 56207
A15: Electrical Works | C15: =SUBTOTAL(9,C16:C16) -> 3953631.6 | D15: =IF(ISBLANK(C15),"",C15/$C$41) -> 0.068993572 | E15: =SUBTOTAL(9,E16:E16) -> 90863.03 | F15: =SUBTOTAL(9,F16:F16) -> 113449.56 | G15: =SUBTOTAL(9,G16:G16) -> 2790664.9 | H15: =SUBTOTAL(9,H16:H16) -> 1529434.3 | I15: =SUBTOTAL(9,I16:I16) -> 4232139.5 | K15: =SUBTOTAL(9,K16:K16) -> 58660 | L15: =IF(ISBLANK(K15),"",K15/$K$41) -> 0.14440131 | M15: =SUBTOTAL(9,M16:M16) -> 1272 | N15: =SUBTOTAL(9,N16:N16) -> 1009 | O15: =SUBTOTAL(9,O16:O16) -> 22808 | P15: =SUBTOTAL(9,P16:P16) -> 49140
