Workbook
Name _1B.05.M.010.0010: #REF!
Name _1B.05.M.010.0010: #REF!
Name _1B.05.M.010.0050: #REF!
Name _1B.05.M.010.0050: #REF!
Name _1B.05.M.0100.0010: #REF!
Name _1B.05.M.020.0010: #REF!
Name _1B.05.M.020.0020: #REF!
Name _1B.05.M.020.0030: #REF!
Name _1B.05.M.020.0040: #REF!
Name _1B.05.M.030.0010: #REF!
Name _1B.05.M.030.0020: #REF!
Name _1B.05.M.040.0010: #REF!
Name _1B.05.M.050.0010: #REF!
Name _1B.05.M.050.0020: #REF!
Name _1B.05.M.050.0030: #REF!
Name _1B.05.M.060.0020: #REF!
Name _1B.05.M.060.0100: #REF!
Name _1B.05.M.070.0010: #REF!
Name _1B.05.M.070.0020: #REF!
Name _1B.05.M.070.0030: #REF!
Name _1B.05.M.070.0040: #REF!
Name _1B.05.M.070.0050: #REF!
Name _1B.05.M.080.0010: #REF!
Name _1B.05.M.090.0010: #REF!
Name _1B.09.P.010.0010: #REF!
Name _1B.09.P.010.0020: #REF!
Name _1B.09.P.010.0030: #REF!
Name _1B.09.P.010.0040: #REF!
Name _1B.09.P.010.0050: #REF!
Name _1B.09.P.010.0060: #REF!
Name _1B.09.P.010.0070: #REF!
Name _1B.09.P.020.0010: #REF!
Name _1B.09.P.020.0020: #REF!
Name _1B.09.P.020.0030: #REF!
Name _1B.09.P.020.0040: #REF!
Name _1B.09.P.020.0050: #REF!
Name _1B.09.P.020.0060: #REF!
Name _1B.09.P.020.0070: #REF!
Name _1B.09.P.020.0080: #REF!
Name _1B.09.P.020.0090: #REF!
Name _1B.09.P.020.0100: #REF!
Name _1B.09.P.020.0110: #REF!
Name _1B.09.P.020.0120: #REF!
Name _1B.09.P.020.0130: #REF!
Name _1B.09.P.020.0140: #REF!
Name _1B.09.P.020.0150: #REF!
Name _1B.09.P.030.0010: #REF!
Name _1B.09.P.030.0020: #REF!
Name _1B.09.P.030.0030: #REF!
Name _1B.09.P.030.0040: #REF!
Name _1B.09.P.030.0050: #REF!
Name _1B.09.P.030.0060: #REF!
Name _1B.09.P.040.0010: #REF!
Name _1B.09.P.040.0020: #REF!
Name _1B.09.P.040.0030: #REF!
Name _1B.09.P.050.0010: #REF!
Name _1B.09.P.050.0020: #REF!
Name _1B.09.P.060.0010: #REF!
Name _1B.09.P.060.0020: #REF!
Name _1B.09.P.060.0030: #REF!

Sheet DB
A1: ='Weekly Progress Report'!#REF! -> #REF!
B2: ='Weekly Progress Report'!#REF! -> #REF! | J2: ='Weekly Progress Report'!F2 -> Key Dates | U2: ='Weekly Progress Report'!$L$2 -> Cost Summary (SR) | AD2: ='Weekly Progress Report'!$T$2 -> Performance Summary | AP2: ='Weekly Progress Report'!#REF! -> #REF! | AT2: ='Weekly Progress Report'!#REF! -> #REF! | AW2: ='Weekly Progress Report'!#REF! -> #REF! | BD2: ='Weekly Progress Report'!K51 -> Quality Reports | BT2: ='Weekly Progress Report'!K59 -> Key Submittals Approval Status | CD2: ='Weekly Progress Report'!K65 -> Invoices Summary | CR2: ='Weekly Progress Report'!K73 -> Resources at Site | CY2: ='Weekly Progress Report'!V51 -> Safety Statistics | FK2: ='Weekly Progress Report'!#REF! -> #REF! | FS2: ='Weekly Progress Report'!#REF! -> #REF!
A3: ='Weekly Progress Report'!AE1 -> Data Date | B3: ='Weekly Progress Report'!#REF! -> #REF! | C3: ='Weekly Progress Report'!#REF! -> #REF! | D3: ='Weekly Progress Report'!#REF! -> #REF! | E3: ='Weekly Progress Report'!#REF! -> #REF! | F3: ='Weekly Progress Report'!C4 -> Stage | G3: ='Weekly Progress Report'!C5 -> Status | H3: ='Weekly Progress Report'!C6 -> Modon PM | I3: ='Weekly Progress Report'!Z2 -> Project Scope | J3: ='Weekly Progress Report'!F3 -> Contract Award | K3: ='Weekly Progress Report'!F4 -> Contract Sign | L3: ='Weekly Progress Report'!F5 -> Site Handover | M3: ='Weekly Progress Report'!F6 -> Original Completion | N3: ='Weekly Progress Report'!$H$3 -> Contract Award (Hijri) | O3: ='Weekly Progress Report'!$H$4 -> Contract Sign (Hijri) | P3: ='Weekly Progress Report'!$H$5 -> Site Handover (Hijri) | Q3: ='Weekly Progress Report'!$H$6 -> Original Completion (Hijri) | R3: ='Weekly Progress Report'!$J$3 -> Revised Completion | S3: ='Weekly Progress Report'!$J$4 -> Committed Completion | T3: ='Weekly Progress Report'!$J$5 -> Forecast Completion | U3: ='Weekly Progress Report'!$L$3 -> Original Contract Value | V3: ='Weekly Progress Report'!$L$4 -> Revised Contract Value | W3: ='Weekly Progress Report'!$L$5 -> Estimate At Completion Value | X3: ='Weekly Progress Report'!$L$6 -> Potential Changes | Y3: ='Weekly Progress Report'!$P$3 -> O&M Value (if any) | Z3: ='Weekly Progress Report'!$P$4 -> Submitted Invoices (Gross Value) | AA3: ='Weekly Progress Report'!$P$5 -> Penalities | AB3: ='Weekly Progress Report'!$P$6 -> FIR Value (Todate) | AC3: Original Plan Value | AD3: ='Weekly Progress Report'!$T$3 -> Plan Value | AE3: ='Weekly Progress Report'!$T$4 -> Earn Value | AF3: ='Weekly Progress Report'!$V$3 -> Phys. Plan Value | AG3: ='Weekly Progress Report'!$V$4 -> Phys. Earn Value | AH3: ='Weekly Progress Report'!$X$3 -> Quality Score | AI3: ='Weekly Progress Report'!$X$5 -> Safety Score | AJ3: Weekly PV (SAR) | AK3: Weekly EV (SAR) | AL3: Weekly PV % | AM3: Weekly PV % | AN3: Weekly Phys PV% | AO3: Weekly Phys PV% | AP3: Total SD Planned | AQ3: SD Remaining | AR3: SD Pending | AS3: Total SD Submittals | AT3: Planned Materials Approv | AU3: Material Pending Approval | AV3: Materila Total Submittals | AW3: ='Weekly Progress Report'!B70 -> Total Materials | AX3: ='Weekly Progress Report'!C70 -> Total Number of P.O. | AY3: ='Weekly Progress Report'!D70 -> Actual P.O. To Date | AZ3: ='Weekly Progress Report'!E70 -> Remaining P.O | BA3: ='Weekly Progress Report'!F70 -> Material on Site | BB3: ='Weekly Progress Report'!G70 -> Remaining Materials | BC3: ='Weekly Progress Report'!H70 -> Material Delivery Completion (Date) | BD3: ="NCR "&'Weekly Progress Report'!M52 -> NCR Issued | BE3: ="NCR "&'Weekly Progress Report'!N52 -> NCR Closed | BF3: ="NCR "&'Weekly Progress Report'!O52 -> NCR Pending | BG3: ="NCR "&'Weekly Progress Report'!P52 -> NCR Avg. Closing (Days) | BH3: ="SIR "&'Weekly Progress Report'!M52 -> SIR Issued | BI3: ="SIR "&'Weekly Progress Report'!N52 -> SIR Closed | BJ3: ="SIR "&'Weekly Progress Report'!O52 -> SIR Pending | BK3: ="SIR "&'Weekly Progress Report'!P52 -> SIR Avg. Closing (Days) | BL3: ="MIR "&'Weekly Progress Report'!M52 -> MIR Issued | BM3: ="MIR "&'Weekly Progress Report'!N52 -> MIR Closed | BN3: ="MIR "&'Weekly Progress Report'!O52 -> MIR Pending | BO3: ="MIR "&'Weekly Progress Report'!P52 -> MIR Avg. Closing (Days) | BP3: ="FIR "&'Weekly Progress Report'!M52 -> FIR Issued | BQ3: ="FIR "&'Weekly Progress Report'!N52 -> FIR Closed | BR3: ="FIR "&'Weekly Progress Report'!O52 -> FIR Pending | BS3: ="FIR "&'Weekly Progress Report'!P52 -> FIR Avg. Closing (Days) | BT3: ='Weekly Progress Report'!K60 -> 1 Quality Plan Approval | BU3: ='Weekly Progress Report'!K61 -> 2 Quality Plan Last Up | BV3: ='Weekly Progress Report'!K62 -> 3 Safety Plan Approval | BW3: ='Weekly Progress Report'!K63 -> 4 Safety Plan Last Up | BX3: ='Weekly Progress Report'!K64 -> 5 Execution Plan Approval | BY3: ='Weekly Progress Report'!P60 -> 6 Baseline Approval | BZ3: ='Weekly Progress Report'!P61 -> 7 No of Approved Version of Schedule | CA3: ='Weekly Progress Report'!P62 -> 8 Last Approved Schedule | CB3: ='Weekly Progress Report'!P63 -> 9 BOQ Approval Date | CC3: ='Weekly Progress Report'!P64 -> 10 No of Approved Version of BOQ | CD3: ='Weekly Progress Report'!K66 -> Total Submitted Invoices | CE3: ='Weekly Progress Report'!K67 -> PM Approved Invoices | CF3: ='Weekly Progress Report'!K68 -> No of Paid Invoices | CG3: ='Weekly Progress Report'!K69 -> No of Pending Invoices | CH3: ='Weekly Progress Report'!K70 -> Advance Payment % | CI3: ='Weekly Progress Report'!K71 -> Retention % | CJ3: ='Weekly Progress Report'!K72 -> Deduction / Penalties % | CK3: ='Weekly Progress Report'!N66 -> Submitted Invoices (SAR) | CL3: ='Weekly Progress Report'!N67 -> PM Approved Invoices (SAR) | CM3: ='Weekly Progress Report'!N68 -> Paid Invoices (SAR) | CN3: ='Weekly Progress Report'!N69 -> Last Submitted Period | CO3: ='Weekly Progress Report'!N70 -> Advance Payment (SAR) | CP3: ='Weekly Progress Report'!N71 -> Retention (SAR) | CQ3: ='Weekly Progress Report'!N72 -> Deduction / Penalties (SAR) | CR3: Planned Head Count | CS3: Actual Head Count | CT3: Saudi Staff | CU3: Labor Planned | CV3: Labor Actual | CW3: Equipment Planned | CX3: Equipment Actual | CY3: ="This Week "&'Weekly Progress Report'!W54 -> This Week Total Hours Worked | CZ3: ="This Week "&'Weekly Progress Report'!W55 -> This Week Safe Hours Worked | DA3: ="This Week "&'Weekly Progress Report'!W56 -> This Week LTI | DB3: ="This Week "&'Weekly Progress Report'!W57 -> This Week MTC (Healed w/o Disability) | DC3: ="This Week "&'Weekly Progress Report'!W58 -> This Week MTC (Healed w/ Disability) | DD3: ="This Week "&'Weekly Progress Report'!W59 -> This Week Near Miss | DE3: ="This Week "&'Weekly Progress Report'!W60 -> This Week First Aid Cases | DF3: ="This Week "&'Weekly Progress Report'!W61 -> This Week Fatality | DG3: ="This Week "&'Weekly Progress Report'!W62 -> This Week Fire Incident Cases | DH3: ="This Week "&'Weekly Progress Report'!W63 -> This Week Vehicle Incident | DI3: ="This Week "&'Weekly Progress Report'!W64 -> This Week Property Damages | DJ3: ="This Week "&'Weekly Progress Report'!W65 -> This Week Induction Training | DK3: ="This Week "&'Weekly Progress Report'!W66 -> This Week No.of Internal Training | DL3: ="This Week "&'Weekly Progress Report'!W67 -> This Week No.of Internal Audit | DM3: ="This Week "&'Weekly Progress Report'!W68 -> This Week No. of Toolbox Talks | DN3: ="This Week "&'Weekly Progress Report'!W69 -> This Week Safety Awards/Incentives | DO3: ="This Month "&'Weekly Progress Report'!W54 -> This Month Total Hours Worked | DP3: ="This Month "&'Weekly Progress Report'!W55 -> This Month Safe Hours Worked | DQ3: ="This Month "&'Weekly Progress Report'!W56 -> This Month LTI | DR3: ="This Month "&'Weekly Progress Report'!W57 -> This Month MTC (Healed w/o Disability) | DS3: ="This Month "&'Weekly Progress Report'!W58 -> This Month MTC (Healed w/ Disability) | DT3: ="This Month "&'Weekly Progress Report'!W59 -> This Month Near Miss | DU3: ="This Month "&'Weekly Progress Report'!W60 -> This Month First Aid Cases | DV3: ="This Month "&'Weekly Progress Report'!W61 -> This Month Fatality | DW3: ="This Month "&'Weekly Progress Report'!W62 -> This Month Fire Incident Cases | DX3: ="This Month "&'Weekly Progress Report'!W63 -> This Month Vehicle Incident | DY3: ="This Month "&'Weekly Progress Report'!W64 -> This Month Property Damages | DZ3: ="This Month "&'Weekly Progress Report'!W65 -> This Month Induction Training | EA3: ="This Month "&'Weekly Progress Report'!W66 -> This Month No.of Internal Training | EB3: ="This Month "&'Weekly Progress Report'!W67 -> This Month No.of Internal Audit | EC3: ="This Month "&'Weekly Progress Report'!W68 -> This Month No. of Toolbox Talks | ED3: ="This Month "&'Weekly Progress Report'!W69 -> This Month Safety Awards/Incentives | EE3: ="YTD "&'Weekly Progress Report'!W54 -> YTD Total Hours Worked | EF3: ="YTD "&'Weekly Progress Report'!W55 -> YTD Safe Hours Worked | EG3: ="YTD "&'Weekly Progress Report'!W56 -> YTD LTI | EH3: ="YTD "&'Weekly Progress Report'!W57 -> YTD MTC (Healed w/o Disability) | EI3: ="YTD "&'Weekly Progress Report'!W58 -> YTD MTC (Healed w/ Disability) | EJ3: ="YTD "&'Weekly Progress Report'!W59 -> YTD Near Miss | EK3: ="YTD "&'Weekly Progress Report'!W60 -> YTD First Aid Cases | EL3: ="YTD "&'Weekly Progress Report'!W61 -> YTD Fatality | EM3: ="YTD "&'Weekly Progress Report'!W62 -> YTD Fire Incident Cases | EN3: ="YTD "&'Weekly Progress Report'!W63 -> YTD Vehicle Incident | EO3: ="YTD "&'Weekly Progress Report'!W64 -> YTD Property Damages | EP3: ="YTD "&'Weekly Progress Report'!W65 -> YTD Induction Training | EQ3: ="YTD "&'Weekly Progress Report'!W66 -> YTD No.of Internal Training | ER3: ="YTD "&'Weekly Progress Report'!W67 -> YTD No.of Internal Audit | ES3: ="YTD "&'Weekly Progress Report'!W68 -> YTD No. of Toolbox Talks | ET3: ="YTD "&'Weekly Progress Report'!W69 -> YTD Safety Awards/Incentives | EU3: ="Cum "&'Weekly Progress Report'!W54 -> Cum Total Hours Worked | EV3: ="Cum "&'Weekly Progress Report'!W55 -> Cum Safe Hours Worked | EW3: ="Cum "&'Weekly Progress Report'!W56 -> Cum LTI | EX3: ="Cum "&'Weekly Progress Report'!W57 -> Cum MTC (Healed w/o Disability) | EY3: ="Cum "&'Weekly Progress Report'!W58 -> Cum MTC (Healed w/ Disability) | EZ3: ="Cum "&'Weekly Progress Report'!W59 -> Cum Near Miss | FA3: ="Cum "&'Weekly Progress Report'!W60 -> Cum First Aid Cases | FB3: ="Cum "&'Weekly Progress Report'!W61 -> Cum Fatality | FC3: ="Cum "&'Weekly Progress Report'!W62 -> Cum Fire Incident Cases | FD3: ="Cum "&'Weekly Progress Report'!W63 -> Cum Vehicle Incident | FE3: ="Cum "&'Weekly Progress Report'!W64 -> Cum Property Damages | FF3: ="Cum "&'Weekly Progress Report'!W65 -> Cum Induction Training | FG3: ="Cum "&'Weekly Progress Report'!W66 -> Cum No.of Internal Training | FH3: ="Cum "&'Weekly Progress Report'!W67 -> Cum No.of Internal Audit | FI3: ="Cum "&'Weekly Progress Report'!W68 -> Cum No. of Toolbox Talks | FJ3: ="Cum "&'Weekly Progress Report'!W69 -> Cum Safety Awards/Incentives | FK3: ='Weekly Progress Report'!#REF! -> #REF! | FL3: ='Weekly Progress Report'!A81 -> Not Started | FM3: ='Weekly Progress Report'!B81 -> In Progress | FN3: ='Weekly Progress Report'!C81 -> Completed | FO3: Critical Path Act.Last Week | FP3: Critical Path Act.This Week | FQ3: Failed start Last Week | FR3: Failed start This Week | FS3: ='Weekly Progress Report'!A89 -> 0 | FT3: ='Weekly Progress Report'!C89 -> 0 | FU3: ='Weekly Progress Report'!E89 -> 0 | FV3: ='Weekly Progress Report'!G89 -> 0 | FW3: ='Weekly Progress Report'!I89 -> 0 | FX3: ='Weekly Progress Report'!K89 -> 0 | FY3: ='Weekly Progress Report'!M89 -> 0 | FZ3: ='Weekly Progress Report'!N89 -> 0 | GA3: ='Weekly Progress Report'!O89 -> 0
A4: ='Weekly Progress Report'!AF1 -> 46315 | B4: ='Weekly Progress Report'!A3 -> Road Development for the Support Services Area at the Second Industrial City in Makkah (Al-Akayshiyah) | C4: ='Weekly Progress Report'!A4 -> MKH2-02-004 | D4: ='Weekly Progress Report'!A5 -> Al Enjaz Trading & Contracting Co. | E4: ='Weekly Progress Report'!A6 -> Saudi Arabia Consulting Engineering Company "EGIS" | F4: ='Weekly Progress Report'!D4 -> Construction | G4: ='Weekly Progress Report'!D5 -> Active | H4: ='Weekly Progress Report'!D6 -> Engr. Abdallah Aljulaifi | I4: ='Weekly Progress Report'!Z3 -> Road Development for the Services Area at the Second Industrial City in Makkah, Al-Akayshiah (The project includes construction of Roads works & Storm Water Drainage Network) | J4: ='Weekly Progress Report'!G3 -> 46153 | K4: ='Weekly Progress Report'!G4 -> 46198 | L4: ='Weekly Progress Report'!G5 -> 46198 | M4: ='Weekly Progress Report'!G6 -> 46623 | N4: ='Weekly Progress Report'!$I$3 -> 11/05/1447 | O4: ='Weekly Progress Report'!$I$4 -> 25/06/1447 | P4: ='Weekly Progress Report'!$I$5 -> 25/06/1447 | Q4: ='Weekly Progress Report'!$I$6 -> 24/08/1448 | R4: ='Weekly Progress Report'!$K$3 -> 46623 | S4: ='Weekly Progress Report'!$K$4 -> 46623 | T4: ='Weekly Progress Report'!$K$5 -> 46674 | U4: ='Weekly Progress Report'!$N$3 -> 33040004 | V4: ='Weekly Progress Report'!$N$4 -> 33040004 | W4: ='Weekly Progress Report'!$N$5 -> 33040004 | X4: ='Weekly Progress Report'!$N$6 -> 0 | Y4: ='Weekly Progress Report'!$R$3 -> 0 | Z4: ='Weekly Progress Report'!$R$4 -> 6754935.1 | AA4: ='Weekly Progress Report'!$R$5 -> 2000 | AB4: ='Weekly Progress Report'!$R$6 -> 9511214.6 | AC4: ='Weekly Progress Report'!$I$21 -> 0.19120944 | AD4: ='Weekly Progress Report'!$U$3 -> 0.19120944 | AE4: ='Weekly Progress Report'!$U$4 -> 0.33353984 | AF4: ='Weekly Progress Report'!$W$3 -> 0.32617229 | AG4: ='Weekly Progress Report'!$W$4 -> 0.45226223 | AH4: ='Weekly Progress Report'!$Y$3 -> 0.89086207 | AI4: ='Weekly Progress Report'!$Y$5 -> 0.875 | AJ4: ='Weekly Progress Report'!$D$21 -> 842582 | AK4: ='Weekly Progress Report'!$E$21 -> 1602838.6 | AL4: =AJ4/V4 -> 0.025501873 | AM4: =AK4/V4 -> 0.048512058 | AN4: ='Weekly Progress Report'!R21 -> 0.081998262 | AO4: ='Weekly Progress Report'!S21 -> 0.08528295 | AP4: ='Weekly Progress Report'!B59 -> 12 | AQ4: ='Weekly Progress Report'!H59 -> 0 | AR4: ='Weekly Progress Report'!I59 -> 0 | AS4: ='Weekly Progress Report'!J59 -> 12 | AT4: ='Weekly Progress Report'!B68 -> 42 | AU4: ='Weekly Progress Report'!I68 -> 0 | AV4: ='Weekly Progress Report'!J68 -> 42 | AW4: ='Weekly Progress Report'!B77 -> 9 | AX4: ='Weekly Progress Report'!C77 -> 9 | AY4: ='Weekly Progress Report'!D77 -> 4 | AZ4: ='Weekly Progress Report'!E77 -> 5 | BA4: ='Weekly Progress Report'!F77 -> 4 | BB4: ='Weekly Progress Report'!G77 -> 5 | BC4: ='Weekly Progress Report'!H77 -> 46356 | BD4: ='Weekly Progress Report'!M55 -> 0 | BE4: ='Weekly Progress Report'!N55 -> 0 | BF4: ='Weekly Progress Report'!O55 -> 0 | BG4: ='Weekly Progress Report'!P55 -> 0 | BH4: ='Weekly Progress Report'!M56 -> 1 | BI4: ='Weekly Progress Report'!N56 -> 1 | BJ4: ='Weekly Progress Report'!O56 -> 0 | BK4: ='Weekly Progress Report'!P56 -> 2 | BL4: ='Weekly Progress Report'!M57 -> 42 | BM4: ='Weekly Progress Report'!N57 -> 42 | BN4: ='Weekly Progress Report'!O57 -> 0 | BO4: ='Weekly Progress Report'!P57 -> 4 | BP4: ='Weekly Progress Report'!M58 -> 204 | BQ4: ='Weekly Progress Report'!N58 -> 175 | BR4: ='Weekly Progress Report'!O58 -> 29 | BS4: ='Weekly Progress Report'!P58 -> 4 | BT4: ='Weekly Progress Report'!N60 -> 46222 | BU4: ='Weekly Progress Report'!N61 -> 46222 | BV4: ='Weekly Progress Report'!N62 -> 46217 | BW4: ='Weekly Progress Report'!N63 -> 46217 | BX4: ='Weekly Progress Report'!N64 -> 46218 | BY4: ='Weekly Progress Report'!T60 -> 45851 | BZ4: ='Weekly Progress Report'!T61 -> 1 | CA4: ='Weekly Progress Report'!T62 -> 45851 | CB4: ='Weekly Progress Report'!T63 -> 0 | CC4: ='Weekly Progress Report'!T64 -> 0 | CD4: ='Weekly Progress Report'!M66 -> 0 | CE4: ='Weekly Progress Report'!M67 -> 3 | CF4: ='Weekly Progress Report'!M68 -> 2 | CG4: ='Weekly Progress Report'!M69 -> 1 | CH4: ='Weekly Progress Report'!M70 -> 0 | CI4: ='Weekly Progress Report'!M71 -> 0 | CJ4: ='Weekly Progress Report'!M72 -> 6.053268e-05 | CK4: ='Weekly Progress Report'!Q66 -> 7768175.4 | CL4: ='Weekly Progress Report'!Q67 -> 7770175.4 | CM4: ='Weekly Progress Report'!Q68 -> 3778784.9 | CN4: ='Weekly Progress Report'!Q69 -> 0 | CO4: ='Weekly Progress Report'!Q70 -> 0 | CP4: ='Weekly Progress Report'!Q71 -> 0 | CQ4: ='Weekly Progress Report'!Q72 -> 2000 | CR4: ='Weekly Progress Report'!K76 -> 13 | CS4: ='Weekly Progress Report'!L76 -> 27 | CT4: ='Weekly Progress Report'!N76 -> 0 | CU4: ='Weekly Progress Report'!O76 -> 15 | CV4: ='Weekly Progress Report'!P76 -> 67 | CW4: ='Weekly Progress Report'!S86 -> 9 | CX4: ='Weekly Progress Report'!T86 -> 61 | CY4: ='Weekly Progress Report'!Y54 -> 2976 | CZ4: ='Weekly Progress Report'!Y55 -> 2976 | DA4: ='Weekly Progress Report'!Y56 -> 0 | DB4: ='Weekly Progress Report'!Y57 -> 0 | DC4: ='Weekly Progress Report'!Y58 -> 0 | DD4: ='Weekly Progress Report'!Y59 -> 0 | DE4: ='Weekly Progress Report'!Y60 -> 0 | DF4: ='Weekly Progress Report'!Y61 -> 0 | DG4: ='Weekly Progress Report'!Y62 -> 0 | DH4: ='Weekly Progress Report'!Y63 -> 0 | DI4: ='Weekly Progress Report'!Y64 -> 0 | DJ4: ='Weekly Progress Report'!Y65 -> 0 | DK4: ='Weekly Progress Report'!Y66 -> 2 | DL4: ='Weekly Progress Report'!Y67 -> 0 | DM4: ='Weekly Progress Report'!Y68 -> 1 | DN4: ='Weekly Progress Report'!Y69 -> 0 | DO4: ='Weekly Progress Report'!AA54 -> 11136 | DP4: ='Weekly Progress Report'!AA55 -> 11136 | DQ4: ='Weekly Progress Report'!AA56 -> 0 | DR4: ='Weekly Progress Report'!AA57 -> 0 | DS4: ='Weekly Progress Report'!AA58 -> 0 | DT4: ='Weekly Progress Report'!AA59 -> 1 | DU4: ='Weekly Progress Report'!AA60 -> 0 | DV4: ='Weekly Progress Report'!AA61 -> 0 | DW4: ='Weekly Progress Report'!AA62 -> 0 | DX4: ='Weekly Progress Report'!AA63 -> 0 | DY4: ='Weekly Progress Report'!AA64 -> 0 | DZ4: ='Weekly Progress Report'!AA65 -> 1 | EA4: ='Weekly Progress Report'!AA66 -> 5 | EB4: ='Weekly Progress Report'!AA67 -> 0 | EC4: ='Weekly Progress Report'!AA68 -> 4 | ED4: ='Weekly Progress Report'!AA69 -> 0 | EE4: ='Weekly Progress Report'!AB54 -> 36989 | EF4: ='Weekly Progress Report'!AB55 -> 36989 | EG4: ='Weekly Progress Report'!AB56 -> 0 | EH4: ='Weekly Progress Report'!AB57 -> 0 | EI4: ='Weekly Progress Report'!AB58 -> 0 | EJ4: ='Weekly Progress Report'!AB59 -> 1 | EK4: ='Weekly Progress Report'!AB60 -> 0 | EL4: ='Weekly Progress Report'!AB61 -> 0 | EM4: ='Weekly Progress Report'!AB62 -> 0 | EN4: ='Weekly Progress Report'!AB63 -> 0 | EO4: ='Weekly Progress Report'!AB64 -> 0 | EP4: ='Weekly Progress Report'!AB65 -> 4 | EQ4: ='Weekly Progress Report'!AB66 -> 19 | ER4: ='Weekly Progress Report'!AB67 -> 1 | ES4: ='Weekly Progress Report'!AB68 -> 18 | ET4: ='Weekly Progress Report'!AB69 -> 0 | EU4: ='Weekly Progress Report'!AC54 -> 36989 | EV4: ='Weekly Progress Report'!AC55 -> 36989 | EW4: ='Weekly Progress Report'!AC56 -> 0 | EX4: ='Weekly Progress Report'!AC57 -> 0 | EY4: ='Weekly Progress Report'!AC58 -> 0 | EZ4: ='Weekly Progress Report'!AC59 -> 1 | FA4: ='Weekly Progress Report'!AC60 -> 0 | FB4: ='Weekly Progress Report'!AC61 -> 0 | FC4: ='Weekly Progress Report'!AC62 -> 0 | FD4: ='Weekly Progress Report'!AC63 -> 0 | FE4: ='Weekly Progress Report'!AC64 -> 0 | FF4: ='Weekly Progress Report'!AC65 -> 4 | FG4: ='Weekly Progress Report'!AC66 -> 19 | FH4: ='Weekly Progress Report'!AC67 -> 1 | FI4: ='Weekly Progress Report'!AC68 -> 18 | FJ4: ='Weekly Progress Report'!AC69 -> 0 | FK4: ='Weekly Progress Report'!#REF! -> #REF! | FL4: ='Weekly Progress Report'!A82 -> 199 | FM4: ='Weekly Progress Report'!B82 -> 34 | FN4: ='Weekly Progress Report'!C82 -> 148 | FO4: ='Weekly Progress Report'!#REF! -> #REF! | FP4: ='Weekly Progress Report'!A86 -> 168 | FQ4: ='Weekly Progress Report'!G86 -> 25 | FR4: ='Weekly Progress Report'!H86 -> 29 | FS4: ='Weekly Progress Report'!A94 -> 0 | FT4: ='Weekly Progress Report'!C94 -> 0 | FU4: ='Weekly Progress Report'!E94 -> 0 | FV4: ='Weekly Progress Report'!G94 -> 0 | FW4: ='Weekly Progress Report'!I94 -> 0 | FX4: ='Weekly Progress Report'!K94 -> 0 | FY4: ='Weekly Progress Report'!M94 -> 0 | FZ4: ='Weekly Progress Report'!N94 -> 0 | GA4: ='Weekly Progress Report'!O94 -> 0

Sheet Weekly Progress Report
AC1: =+HSE!L4 -> Report No. | AD1: =+HSE!P4 -> 17 | AE1: Data Date | AF1: ='General Information'!L1 -> 46315
F2: Key Dates | L2: Cost Summary (SR) | T2: Performance Summary | Z2: Project Scope
A3: ='General Information'!C3 -> Road Development for the Support Services Area at the Second Industrial City in Makkah (Al-Akayshiyah) | F3: Contract Award | G3: ='General Information'!C12 -> 46153 | H3: Contract Award (Hijri) | I3: ='General Information'!C16 -> 11/05/1447 | J3: Revised Completion | K3: ='General Information'!C20 -> 46623 | L3: Original Contract Value | N3: ='Invoice Log'!E3 -> 33040004 | P3: O&M Value (if any) | R3: ='Invoice Log'!I3 -> 0 | S3: EAC | T3: Plan Value | U3: =J21 -> 0.19120944 | V3: Phys. Plan Value | W3: =V21 -> 0.32617229 | X3: Quality Score | Y3: =Quality!AC10 -> 0.89086207 | Z3: =+Progress!A1 -> Road Development for the Services Area at the Second Industrial City in Makkah, Al-Akayshiah (The project includes construction of Roads works & Storm Water Drainage Network)
A4: ='General Information'!C4 -> MKH2-02-004 | C4: Stage | D4: ='General Information'!C7 -> Construction | F4: Contract Sign | G4: ='General Information'!C13 -> 46198 | H4: Contract Sign (Hijri) | I4: ='General Information'!C17 -> 25/06/1447 | J4: Committed Completion | K4: ='General Information'!C21 -> 46623 | L4: Revised Contract Value | N4: ='Invoice Log'!E4 -> 33040004 | O4: EAC | P4: Submitted Invoices (Gross Value) | R4: =+'Invoice Log'!F59 -> 6754935.1 | T4: Earn Value | U4: =K21 -> 0.33353984 | V4: Phys. Earn Value | W4: =W21 -> 0.45226223 | Y4: =REPT("¢",IF(INT(+Y3*10)>5,5,INT(+Y3*10)))&REPT("£",IF(INT(+Y3*10)>5,0,5-INT(+Y3*10)))&CHAR(10)&REPT("¢",+IF(INT(+Y3*10)>5,-5+INT(+Y3*10),0))&REPT("£",IF(INT(+Y3*10)>5,10-INT(+Y3*10),5)) -> ¢¢¢¢¢ ¢¢¢££
A5: ='General Information'!C5 -> Al Enjaz Trading & Contracting Co. | C5: Status | D5: ='General Information'!C8 -> Active | F5: Site Handover | G5: ='General Information'!C14 -> 46198 | H5: Site Handover (Hijri) | I5: ='General Information'!C18 -> 25/06/1447 | J5: Forecast Completion | K5: ='General Information'!C22 -> 46674 | L5: Estimate At Completion Value | N5: ='Invoice Log'!E5 -> 33040004 | O5: =+#REF!+#REF!+N5 -> #REF! | P5: Penalities | R5: ='Invoice Log'!M6 -> 2000 | T5: Variance | U5: =U4-U3 -> 0.1423304 | V5: Variance | W5: =W4-W3 -> 0.12608994 | X5: Safety Score | Y5: ='HSE-Stat'!J23 -> 0.875
A6: ='General Information'!C6 -> Saudi Arabia Consulting Engineering Company "EGIS" | C6: Modon PM | D6: ='General Information'!C9 -> Engr. Abdallah Aljulaifi | F6: Original Completion | G6: ='General Information'!C15 -> 46623 | H6: Original Completion (Hijri) | I6: ='General Information'!C19 -> 24/08/1448 | J6: Variance | K6: ='General Information'!C23 -> -51 | L6: Potential Changes | N6: =N4-N5 -> 0 | P6: FIR Value (Todate) | R6: =+'FIR summary '!K2 -> 9511214.6 | T6: FIR % | U6: =R6/N4 -> 0.28786966 | V6: Invoiced % | W6: =R4/N4 -> 0.20444716 | Y6: =REPT("¢",IF(INT(+Y5*10)>5,5,INT(+Y5*10)))&REPT("£",IF(INT(+Y5*10)>5,0,5-INT(+Y5*10)))&CHAR(10)&REPT("¢",+IF(INT(+Y5*10)>5,-5+INT(+Y5*10),0))&REPT("£",IF(INT(+Y5*10)>5,10-INT(+Y5*10),5)) -> ¢¢¢¢¢ ¢¢¢££
N9: Physical Progress (Effort) | Z9: Earned Value Progress (%)
B10: BOQ Value (SAR) | C10: % Wt. | D10: Weekly (SAR) | F10: To Date (SAR) | N10: Budgeted | O10: % Wt. | P10: Weekly Physical Progress | T10: To Date Physical Progress
D11: Planned | E11: Earned | F11: Original Plan | G11: Revised Planned | H11: Earned | I11: Original Plan % | J11: Revised Planned % | K11: Earned % | L11: Variance | M11: SPI | N11: (Manhours) | P11: Planned | Q11: Earned | R11: Plan % | S11: Earned % | T11: Planned | U11: Earned | V11: Plan % | W11: Earned % | X11: Variance | Y11: SPI
B12: =+Progress!B7 -> 0 | C12: =IF(ISBLANK(B12),"",B12/$B$21) -> 0 | D12: =+Progress!D7 -> 0 | E12: =+Progress!E7 -> - | F12: =+Progress!F7 -> 0 | G12: =+Progress!G7 -> 0 | H12: =+Progress!H7 -> - | I12: =IFERROR(IF(ISBLANK(F12),"",F12/B12),0) -> 0 | J12: =IFERROR(IF(ISBLANK(G12),"",G12/B12),0) -> 0 | K12: =IFERROR(IF(ISBLANK(H12),"",H12/B12),0) -> 0 | L12: =IFERROR(K12-J12,"") -> 0 | M12: =IFERROR(K12/J12,"") | N12: =+Progress!J7 -> 7892 | O12: =IF(ISBLANK(N12),"",N12/$N$21) -> 0.036104122 | P12: =+Progress!L7 -> 0 | Q12: =+Progress!M7 -> 0 | R12: =IFERROR(IF(ISBLANK(P12),"",P12/N12),0) -> 0 | S12: =IFERROR(IF(ISBLANK(Q12),"",Q12/N12),0) -> 0 | T12: =+Progress!N7 -> 7892 | U12: =+Progress!O7 -> 7892 | V12: =IFERROR(IF(ISBLANK(T12),"",T12/N12),0) -> 1 | W12: =IFERROR(IF(ISBLANK(U12),"",U12/N12),0) -> 1 | X12: =IFERROR(W12-V12,"") -> 0 | Y12: =IFERROR(W12/V12,"") -> 1
B13: =+Progress!B9 -> 0 | C13: =IF(ISBLANK(B13),"",B13/$B$21) -> 0 | D13: =+Progress!D9 -> 0 | E13: =+Progress!E9 -> 0 | F13: =+Progress!F9 -> 0 | G13: =+Progress!G9 -> 0 | H13: =+Progress!H9 -> 0 | I13: =IFERROR(IF(ISBLANK(F13),"",F13/B13),0) -> 0 | J13: =IFERROR(IF(ISBLANK(G13),"",G13/B13),0) -> 0 | K13: =IFERROR(IF(ISBLANK(H13),"",H13/B13),0) -> 0 | L13: =IFERROR(K13-J13,"") -> 0 | M13: =IFERROR(K13/J13,"") | N13: =+Progress!J9 -> 5832 | O13: =IF(ISBLANK(N13),"",N13/$N$21) -> 0.026680086 | P13: =+Progress!L9 -> 0 | Q13: =+Progress!M9 -> 0 | R13: =IFERROR(IF(ISBLANK(P13),"",P13/N13),0) -> 0 | S13: =IFERROR(IF(ISBLANK(Q13),"",Q13/N13),0) -> 0 | T13: =+Progress!N9 -> 5832 | U13: =+Progress!O9 -> 5832 | V13: =IFERROR(IF(ISBLANK(T13),"",T13/N13),0) -> 1 | W13: =IFERROR(IF(ISBLANK(U13),"",U13/N13),0) -> 1 | X13: =IFERROR(W13-V13,"") -> 0 | Y13: =IFERROR(W13/V13,"") -> 1
B14: =+Progress!B11 -> 0 | C14: =IF(ISBLANK(B14),"",B14/$B$21) -> 0 | D14: =+Progress!D11 -> 0 | E14: =+Progress!E11 -> 0 | F14: =+Progress!F11 -> 0 | G14: =+Progress!G11 -> 0 | H14: =+Progress!H11 -> 0 | I14: =IFERROR(IF(ISBLANK(F14),"",F14/B14),0) -> 0 | J14: =IFERROR(IF(ISBLANK(G14),"",G14/B14),0) -> 0 | K14: =IFERROR(IF(ISBLANK(H14),"",H14/B14),0) -> 0 | L14: =IFERROR(K14-J14,"") -> 0 | M14: =IFERROR(K14/J14,"") | N14: =+Progress!J11 -> 4916 | O14: =IF(ISBLANK(N14),"",N14/$N$21) -> 0.022489592 | P14: =+Progress!L11 -> 362 | Q14: =+Progress!M11 -> 0 | R14: =IFERROR(IF(ISBLANK(P14),"",P14/N14),0) -> 0.073637103 | S14: =IFERROR(IF(ISBLANK(Q14),"",Q14/N14),0) -> 0 | T14: =+Progress!N11 -> 3784 | U14: =+Progress!O11 -> 2918 | V14: =IFERROR(IF(ISBLANK(T14),"",T14/N14),0) -> 0.76973149 | W14: =IFERROR(IF(ISBLANK(U14),"",U14/N14),0) -> 0.59357201 | X14: =IFERROR(W14-V14,"") -> -0.17615948 | Y14: =IFERROR(W14/V14,"") -> 0.77114165
B15: =+Progress!B13 -> 19411954 | C15: =IF(ISBLANK(B15),"",B15/$B$21) -> 0.5875288 | D15: =+Progress!D13 -> 391828.36 | E15: =+Progress!E13 -> 481104.9 | F15: =+Progress!F13 -> 4517610.4 | G15: =+Progress!G13 -> 4517610.4 | H15: =+Progress!H13 -> 6884338.4 | I15: =IFERROR(IF(ISBLANK(F15),"",F15/B15),0) -> 0.23272311 | J15: =IFERROR(IF(ISBLANK(G15),"",G15/B15),0) -> 0.23272311 | K15: =IFERROR(IF(ISBLANK(H15),"",H15/B15),0) -> 0.35464428 | L15: =IFERROR(K15-J15,"") -> 0.12192117 | M15: =IFERROR(K15/J15,"") -> 1.5238894 | N15: 118680 | O15: =IF(ISBLANK(N15),"",N15/$N$21) -> 0.54293426 | P15: =+Progress!L13 -> 3780 | Q15: =+Progress!M13 -> 3333 | R15: =IFERROR(IF(ISBLANK(P15),"",P15/N15),0) -> 0.031850354 | S15: =IFERROR(IF(ISBLANK(Q15),"",Q15/N15),0) -> 0.028083923 | T15: =+Progress!N13 -> 37820 | U15: =+Progress!O13 -> 59417 | V15: =IFERROR(IF(ISBLANK(T15),"",T15/N15),0) -> 0.31867206 | W15: =IFERROR(IF(ISBLANK(U15),"",U15/N15),0) -> 0.5006488 | X15: =IFERROR(W15-V15,"") -> 0.18197674 | Y15: =IFERROR(W15/V15,"") -> 1.5710471
B16: =+Progress!B15 -> 13628050 | C16: =IF(ISBLANK(B16),"",B16/$B$21) -> 0.4124712 | D16: =+Progress!D15 -> 450753.64 | E16: =+Progress!E15 -> 1121733.7 | F16: =+Progress!F15 -> 1799950.3 | G16: =+Progress!G15 -> 1799950.3 | H16: =+Progress!H15 -> 4135819.2 | I16: =IFERROR(IF(ISBLANK(F16),"",F16/B16),0) -> 0.13207688 | J16: =IFERROR(IF(ISBLANK(G16),"",G16/B16),0) -> 0.13207688 | K16: =IFERROR(IF(ISBLANK(H16),"",H16/B16),0) -> 0.30347843 | L16: =IFERROR(K16-J16,"") -> 0.17140155 | M16: =IFERROR(K16/J16,"") -> 2.2977408 | N16: 77910 | O16: =IF(ISBLANK(N16),"",N16/$N$21) -> 0.3564207 | P16: =+Progress!L15 -> 4820 | Q16: =+Progress!M15 -> 5988 | R16: =IFERROR(IF(ISBLANK(P16),"",P16/N16),0) -> 0.061866256 | S16: =IFERROR(IF(ISBLANK(Q16),"",Q16/N16),0) -> 0.076857913 | T16: =+Progress!N15 -> 15970 | U16: =+Progress!O15 -> 22801 | V16: =IFERROR(IF(ISBLANK(T16),"",T16/N16),0) -> 0.20498011 | W16: =IFERROR(IF(ISBLANK(U16),"",U16/N16),0) -> 0.2926582 | X16: =IFERROR(W16-V16,"") -> 0.08767809 | Y16: =IFERROR(W16/V16,"") -> 1.4277395
B17: =+Progress!B17 -> 0 | C17: =IF(ISBLANK(B17),"",B17/$B$21) -> 0 | D17: =+Progress!D17 -> 0 | E17: =+Progress!E17 -> 0 | F17: =+Progress!F17 -> 0 | G17: =+Progress!G17 -> 0 | H17: =+Progress!H17 -> 0 | I17: =IFERROR(IF(ISBLANK(F17),"",F17/B17),0) -> 0 | J17: =IFERROR(IF(ISBLANK(G17),"",G17/B17),0) -> 0 | K17: =IFERROR(IF(ISBLANK(H17),"",H17/B17),0) -> 0 | L17: =IFERROR(K17-J17,"") -> 0 | M17: =IFERROR(K17/J17,"") | N17: =+Progress!J17 -> 2400 | O17: =IF(ISBLANK(N17),"",N17/$N$21) -> 0.010979459 | P17: =+Progress!L17 -> 0 | Q17: =+Progress!M17 -> 0 | R17: =IFERROR(IF(ISBLANK(P17),"",P17/N17),0) -> 0 | S17: =IFERROR(IF(ISBLANK(Q17),"",Q17/N17),0) -> 0 | T17: =+Progress!N17 -> 0 | U17: =+Progress!O17 -> 0 | V17: =IFERROR(IF(ISBLANK(T17),"",T17/N17),0) -> 0 | W17: =IFERROR(IF(ISBLANK(U17),"",U17/N17),0) -> 0 | X17: =IFERROR(W17-V17,"") -> 0 | Y17: =IFERROR(W17/V17,"")
C18: =IF(ISBLANK(B18),"",B18/$B$21) | I18: =IFERROR(IF(ISBLANK(F18),"",F18/B18),0) | J18: =IFERROR(IF(ISBLANK(G18),"",G18/B18),0) | K18: =IFERROR(IF(ISBLANK(H18),"",H18/B18),0) | L18: =IFERROR(K18-J18,"") | M18: =IFERROR(K18/J18,"") | N18: =+Progress!J19 -> 960 | O18: =IF(ISBLANK(N18),"",N18/$N$21) -> 0.0043917837 | P18: =+Progress!L19 -> 0 | Q18: =+Progress!M19 -> 0 | R18: =IFERROR(IF(ISBLANK(P18),"",P18/N18),0) -> 0 | S18: =IFERROR(IF(ISBLANK(Q18),"",Q18/N18),0) -> 0 | T18: =+Progress!N19 -> 0 | U18: =+Progress!O19 -> 0 | V18: =IFERROR(IF(ISBLANK(T18),"",T18/N18),0) -> 0 | W18: =IFERROR(IF(ISBLANK(U18),"",U18/N18),0) -> 0 | X18: =IFERROR(W18-V18,"") -> 0 | Y18: =IFERROR(W18/V18,"")
C19: =IF(ISBLANK(B19),"",B19/$B$21) | I19: =IFERROR(IF(ISBLANK(F19),"",F19/B19),0) | J19: =IFERROR(IF(ISBLANK(G19),"",G19/B19),0) | K19: =IFERROR(IF(ISBLANK(H19),"",H19/B19),0) | L19: =IFERROR(K19-J19,"") | M19: =IFERROR(K19/J19,"") | O19: =IF(ISBLANK(N19),"",N19/$N$21) | P19: =+Progress!L21 -> 8962 | Q19: =+Progress!M21 -> 9321 | R19: =IFERROR(IF(ISBLANK(P19),"",P19/N19),0) -> 0 | S19: =IFERROR(IF(ISBLANK(Q19),"",Q19/N19),0) -> 0 | V19: =IFERROR(IF(ISBLANK(T19),"",T19/N19),0) | W19: =IFERROR(IF(ISBLANK(U19),"",U19/N19),0) | X19: =IFERROR(W19-V19,"") | Y19: =IFERROR(W19/V19,"")
B20: =+Progress!B17 -> 0 | C20: =IF(ISBLANK(B20),"",B20/$B$21) -> 0 | D20: =+Progress!D17 -> 0 | E20: =+Progress!E17 -> 0 | F20: =+Progress!F17 -> 0 | G20: =+Progress!G17 -> 0 | H20: =+Progress!H17 -> 0 | I20: =IFERROR(IF(ISBLANK(F20),"",F20/B20),0) -> 0 | J20: =IFERROR(IF(ISBLANK(G20),"",G20/B20),0) -> 0 | K20: =IFERROR(IF(ISBLANK(H20),"",H20/B20),0) -> 0 | L20: =IFERROR(K20-J20,"") -> 0 | M20: =IFERROR(K20/J20,"") | O20: =IF(ISBLANK(N20),"",N20/$N$21) | P20: =+Progress!L17 -> 0 | Q20: =+Progress!M17 -> 0 | R20: =IFERROR(IF(ISBLANK(P20),"",P20/N20),0) -> 0 | S20: =IFERROR(IF(ISBLANK(Q20),"",Q20/N20),0) -> 0 | T20: =+Progress!N17 -> 0 | U20: =+Progress!O17 -> 0 | V20: =IFERROR(IF(ISBLANK(T20),"",T20/N20),0) -> 0 | W20: =IFERROR(IF(ISBLANK(U20),"",U20/N20),0) -> 0 | X20: =IFERROR(W20-V20,"") -> 0 | Y20: =IFERROR(W20/V20,"")
A21: Total | B21: =SUM(B12:B20) -> 33040004 | C21: =SUM(C12:C20) -> 1 | D21: =SUM(D12:D20) -> 842582 | E21: =SUM(E12:E20) -> 1602838.6 | F21: =SUM(F12:F20) -> 6317560.7 | G21: =SUM(G12:G20) -> 6317560.7 | H21: =SUM(H12:H20) -> 11020158 | I21: =IFERROR(IF(ISBLANK(F21),"",F21/B21),0) -> 0.19120944 | J21: =IFERROR(IF(ISBLANK(G21),"",G21/B21),0) -> 0.19120944 | K21: =IFERROR(IF(ISBLANK(H21),"",H21/B21),0) -> 0.33353984 | L21: =+K21-J21 -> 0.1423304 | M21: =K21/J21 -> 1.7443691 | N21: =SUM(N12:N20) -> 218590 | O21: =SUM(O12:O20) -> 1 | P21: =SUM(P12:P20) -> 17924 | Q21: =SUM(Q12:Q20) -> 18642 | R21: =IFERROR(IF(ISBLANK(P21),"",P21/N21),0) -> 0.081998262 | S21: =IFERROR(IF(ISBLANK(Q21),"",Q21/N21),0) -> 0.08528295 | T21: =SUM(T12:T20) -> 71298 | U21: =SUM(U12:U20) -> 98860 | V21: =IFERROR(IF(ISBLANK(T21),"",T21/N21),0) -> 0.32617229 | W21: =IFERROR(IF(ISBLANK(U21),"",U21/N21),0) -> 0.45226223 | X21: =+W21-V21 -> 0.12608994 | Y21: =W21/V21 -> 1.3865747
Z22: Construction Milestones
Z23: Item No. | AA23: Milestones | AC23: Original (Baseline) | AD23: Latest Plan | AE23: Forecast | AF23: Status | AG23: Days Change
Z24: =+Milestones!A4 -> 1 | AA24: =+Milestones!B4 -> Project Commencement Date | AC24: =+Milestones!C4 -> 46198 | AD24: =+Milestones!D4 -> 46198 | AE24: =+Milestones!E4 -> 46198 | AF24: =+Milestones!F4 -> A | AG24: =+Milestones!G4 -> 0
Z25: =+Milestones!A5 -> 2 | AA25: =+Milestones!B5 -> Project Completion | AC25: =+Milestones!C5 -> 46623 | AD25: =+Milestones!D5 -> 46623 | AE25: =+Milestones!E5 -> 46674 | AF25: =+Milestones!F5 -> F | AG25: =+Milestones!G5 -> -51
Z26: =+Milestones!A6 -> 3 | AA26: =+Milestones!B6 -> Completion of Mobilization | AC26: =+Milestones!C6 -> 46226 | AD26: =+Milestones!D6 -> 46226 | AE26: =+Milestones!E6 -> 46249 | AF26: =+Milestones!F6 -> A | AG26: =+Milestones!G6 -> -23
Z27: =+Milestones!A7 -> 4 | AA27: =+Milestones!B7 -> Baseline Programme Submission | AC27: =+Milestones!C7 -> 46215 | AD27: =+Milestones!D7 -> 46215 | AE27: =+Milestones!E7 -> 46215 | AF27: =+Milestones!F7 -> A | AG27: =+Milestones!G7 -> 0
Z28: =+Milestones!A8 -> 5 | AA28: =+Milestones!B8 -> Submission and Approval of drawings and Materials | AC28: =+Milestones!C8 -> 46257 | AD28: =+Milestones!D8 -> 46257 | AE28: =+Milestones!E8 -> 46284 | AF28: =+Milestones!F8 -> A | AG28: =+Milestones!G8 -> -27
Z29: =+Milestones!A9 -> 6 | AA29: =+Milestones!B9 -> Completion of Road Works | AC29: =+Milestones!C9 -> 46501 | AD29: =+Milestones!D9 -> 46501 | AE29: =+Milestones!E9 -> 46553 | AF29: =+Milestones!F9 -> F | AG29: =+Milestones!G9 -> -52
Z30: =+Milestones!A10 -> 7 | AA30: =+Milestones!B10 -> Completion of Storm Water Dranage | AC30: =+Milestones!C10 -> 46442 | AD30: =+Milestones!D10 -> 46442 | AE30: =+Milestones!E10 -> 46487 | AF30: =+Milestones!F10 -> F | AG30: =+Milestones!G10 -> -45
Z31: =+Milestones!A11 -> 8 | AA31: =+Milestones!B11 -> Completion of Entire Project | AC31: =+Milestones!C11 -> 46623 | AD31: =+Milestones!D11 -> 46623 | AE31: =+Milestones!E11 -> 46674 | AF31: =+Milestones!F11 -> F | AG31: =+Milestones!G11 -> -51
K50: Quality | V50: Safety
K51: Quality Reports | V51: Safety Statistics | AD51: Proactive Vs Reactive Actions Taken
B52: Total | C52: Total Submitted Drawings | H52: Remaining | I52: Pending | J52: Total Submittals | K52: Quality Reports | M52: Issued | N52: Closed | O52: Pending | P52: Avg. Closing (Days) | Q52: Pending | V52: Category | W52: Item | Y52: This Week | AA52: This Month | AB52: Year to Date | AC52: Cumulative
C53: A | D53: B | E53: C | F53: D | G53: Processed | Q53: 0-10 Days | R53: 11-20 Days | S53: 21-30 Days | T53: 31-60 Days | U53: > 60 Days
B54: =IF('Quality-Stat'!D13="","",'Quality-Stat'!D13) -> 1 | C54: =IF('Quality-Stat'!E13="","",'Quality-Stat'!E13) -> 0 | D54: =IF('Quality-Stat'!F13="","",'Quality-Stat'!F13) -> 1 | E54: =IF('Quality-Stat'!G13="","",'Quality-Stat'!G13) -> 0 | F54: =IF('Quality-Stat'!H13="","",'Quality-Stat'!H13) -> 0 | G54: =IF('Quality-Stat'!I13="","",'Quality-Stat'!I13) -> 1 | H54: =IF('Quality-Stat'!J13="","",'Quality-Stat'!J13) -> 0 | I54: =IF('Quality-Stat'!K13="","",'Quality-Stat'!K13) -> 0 | J54: =IF('Quality-Stat'!L13="","",'Quality-Stat'!L13) -> 1 | V54: General | W54: ='HSE-Stat'!B4 -> Total Hours Worked | Y54: ='HSE-Stat'!D4 -> 2976 | AA54: ='HSE-Stat'!E4 -> 11136 | AB54: ='HSE-Stat'!F4 -> 36989 | AC54: ='HSE-Stat'!G4 -> 36989 | AF54: Proactive | AG54: =+SUM(AC65:AC69) -> 42
B55: =IF('Quality-Stat'!D14="","",'Quality-Stat'!D14) -> 11 | C55: =IF('Quality-Stat'!E14="","",'Quality-Stat'!E14) -> 0 | D55: =IF('Quality-Stat'!F14="","",'Quality-Stat'!F14) -> 11 | E55: =IF('Quality-Stat'!G14="","",'Quality-Stat'!G14) -> 0 | F55: =IF('Quality-Stat'!H14="","",'Quality-Stat'!H14) -> 0 | G55: =IF('Quality-Stat'!I14="","",'Quality-Stat'!I14) -> 11 | H55: =IF('Quality-Stat'!J14="","",'Quality-Stat'!J14) -> 0 | I55: =IF('Quality-Stat'!K14="","",'Quality-Stat'!K14) -> 0 | J55: =IF('Quality-Stat'!L14="","",'Quality-Stat'!L14) -> 11 | K55: Non Conformance (NCR) | M55: ='Quality-Stat'!D5 -> 0 | N55: ='Quality-Stat'!E5 -> 0 | O55: ='Quality-Stat'!F5 -> 0 | P55: ='Quality-Stat'!G5 -> 0 | Q55: ='Quality-Stat'!H5 -> 0 | R55: ='Quality-Stat'!I5 -> 0 | S55: ='Quality-Stat'!J5 -> 0 | T55: ='Quality-Stat'!K5 -> 0 | U55: ='Quality-Stat'!L5 -> 0 | W55: ='HSE-Stat'!B5 -> Safe Hours Worked | Y55: ='HSE-Stat'!D5 -> 2976 | AA55: ='HSE-Stat'!E5 -> 11136 | AB55: ='HSE-Stat'!F5 -> 36989 | AC55: ='HSE-Stat'!G5 -> 36989 | AF55: Reactive | AG55: =SUM(AC56:AC64) -> 1
B56: =IF('Quality-Stat'!D15="","",'Quality-Stat'!D15) -> 0 | C56: =IF('Quality-Stat'!E15="","",'Quality-Stat'!E15) -> 0 | D56: =IF('Quality-Stat'!F15="","",'Quality-Stat'!F15) -> 0 | E56: =IF('Quality-Stat'!G15="","",'Quality-Stat'!G15) -> 0 | F56: =IF('Quality-Stat'!H15="","",'Quality-Stat'!H15) -> 0 | G56: =IF('Quality-Stat'!I15="","",'Quality-Stat'!I15) -> 0 | H56: =IF('Quality-Stat'!J15="","",'Quality-Stat'!J15) -> 0 | I56: =IF('Quality-Stat'!K15="","",'Quality-Stat'!K15) -> 0 | J56: =IF('Quality-Stat'!L15="","",'Quality-Stat'!L15) -> 0 | K56: Site Instruction (SIR/SOR) | M56: ='Quality-Stat'!D6 -> 1 | N56: ='Quality-Stat'!E6 -> 1 | O56: ='Quality-Stat'!F6 -> 0 | P56: ='Quality-Stat'!G6 -> 2 | Q56: ='Quality-Stat'!H6 -> 0 | R56: ='Quality-Stat'!I6 -> 0 | S56: ='Quality-Stat'!J6 -> 0 | T56: ='Quality-Stat'!K6 -> 0 | U56: ='Quality-Stat'!L6 -> 0 | V56: Reactive | W56: ='HSE-Stat'!B6 -> LTI | Y56: ='HSE-Stat'!D6 -> 0 | AA56: ='HSE-Stat'!E6 -> 0 | AB56: ='HSE-Stat'!F6 -> 0 | AC56: ='HSE-Stat'!G6 -> 0
B57: =IF('Quality-Stat'!D16="","",'Quality-Stat'!D16) -> 0 | C57: =IF('Quality-Stat'!E16="","",'Quality-Stat'!E16) -> 0 | D57: =IF('Quality-Stat'!F16="","",'Quality-Stat'!F16) -> 0 | E57: =IF('Quality-Stat'!G16="","",'Quality-Stat'!G16) -> 0 | F57: =IF('Quality-Stat'!H16="","",'Quality-Stat'!H16) -> 0 | G57: =IF('Quality-Stat'!I16="","",'Quality-Stat'!I16) -> 0 | H57: =IF('Quality-Stat'!J16="","",'Quality-Stat'!J16) -> 0 | I57: =IF('Quality-Stat'!K16="","",'Quality-Stat'!K16) -> 0 | J57: =IF('Quality-Stat'!L16="","",'Quality-Stat'!L16) -> 0 | K57: Material Inspection (MRIR) | M57: ='Quality-Stat'!D7 -> 42 | N57: ='Quality-Stat'!E7 -> 42 | O57: ='Quality-Stat'!F7 -> 0 | P57: ='Quality-Stat'!G7 -> 4 | Q57: ='Quality-Stat'!H7 -> 0 | R57: ='Quality-Stat'!I7 -> 0 | S57: ='Quality-Stat'!J7 -> 0 | T57: ='Quality-Stat'!K7 -> 0 | U57: ='Quality-Stat'!L7 -> 0 | W57: ='HSE-Stat'!B7 -> MTC (Healed w/o Disability) | Y57: ='HSE-Stat'!D7 -> 0 | AA57: ='HSE-Stat'!E7 -> 0 | AB57: ='HSE-Stat'!F7 -> 0 | AC57: ='HSE-Stat'!G7 -> 0
B58: =IF('Quality-Stat'!D17="","",'Quality-Stat'!D17) -> 0 | C58: =IF('Quality-Stat'!E17="","",'Quality-Stat'!E17) -> 0 | D58: =IF('Quality-Stat'!F17="","",'Quality-Stat'!F17) -> 0 | E58: =IF('Quality-Stat'!G17="","",'Quality-Stat'!G17) -> 0 | F58: =IF('Quality-Stat'!H17="","",'Quality-Stat'!H17) -> 0 | G58: =IF('Quality-Stat'!I17="","",'Quality-Stat'!I17) -> 0 | H58: =IF('Quality-Stat'!J17="","",'Quality-Stat'!J17) -> 0 | I58: =IF('Quality-Stat'!K17="","",'Quality-Stat'!K17) -> 0 | J58: =IF('Quality-Stat'!L17="","",'Quality-Stat'!L17) -> 0 | K58: Field Inspection (FIR) | M58: ='Quality-Stat'!D8 -> 204 | N58: ='Quality-Stat'!E8 -> 175 | O58: ='Quality-Stat'!F8 -> 29 | P58: ='Quality-Stat'!G8 -> 4 | Q58: ='Quality-Stat'!H8 -> 17 | R58: ='Quality-Stat'!I8 -> 0 | S58: ='Quality-Stat'!J8 -> 0 | T58: ='Quality-Stat'!K8 -> 0 | U58: ='Quality-Stat'!L8 -> 0 | W58: ='HSE-Stat'!B8 -> MTC (Healed w/ Disability) | Y58: ='HSE-Stat'!D8 -> 0 | AA58: ='HSE-Stat'!E8 -> 0 | AB58: ='HSE-Stat'!F8 -> 0 | AC58: ='HSE-Stat'!G8 -> 0
B59: =SUM(B54:B58) -> 12 | C59: =SUM(C54:C58) -> 0 | D59: =SUM(D54:D58) -> 12 | E59: =SUM(E54:E58) -> 0 | F59: =SUM(F54:F58) -> 0 | G59: =SUM(G54:G58) -> 12 | H59: =SUM(H54:H58) -> 0 | I59: =SUM(I54:I58) -> 0 | J59: =SUM(J54:J58) -> 12 | K59: Key Submittals Approval Status | W59: ='HSE-Stat'!B9 -> Near Miss | Y59: ='HSE-Stat'!D9 -> 0 | AA59: ='HSE-Stat'!E9 -> 1 | AB59: ='HSE-Stat'!F9 -> 1 | AC59: ='HSE-Stat'!G9 -> 1
K60: 1 Quality Plan Approval | N60: =+'General Information'!C27 -> 46222 | P60: 6 Baseline Approval | T60: ='General Information'!C39 -> 45851 | W60: ='HSE-Stat'!B10 -> First Aid Cases | Y60: ='HSE-Stat'!D10 -> 0 | AA60: ='HSE-Stat'!E10 -> 0 | AB60: ='HSE-Stat'!F10 -> 0 | AC60: ='HSE-Stat'!G10 -> 0 | AD60: Total Hours Worked Vs Safe Hours Worked
...

Sheet FIR summary 
A1: Project Name | C1: =+'General Information'!C3:I3 -> Road Development for the Support Services Area at the Second Industrial City in Makkah (Al-Akayshiyah) | F1: Total FIR Amount | I1: =+Total -> 178710 | J1: Cum Previous FIR up to 29-09-2026 | K1: Cum up To Date FRI
A2: Project ID | C2: =+'General Information'!C4:I4 -> MKH2-02-004 | E2: Project Budget | F2: 33040004 | J2: 7582918.3 | K2: =J2+778382.62+971203.72+178710 -> 9511214.6
A3: Date Period | C3: =+F3-6 -> 46309 | E3: To | F3: =+'General Information'!L1 -> 46315
A5: BOQ Item # | B5: BOQ Description | C5: FIR # | D5: FIR DATE | E5: FIR Description | F5: Unit | G5: Unit Rate | H5: Current Pariod Quantity | I5: Total (SR)
A6: ROAD WORKS | K6: =+K2/33040004 -> 0.28786966
A7: B1.31 22 00.01 | B7: Roadway Excavation for cuttings (all types of soil) | F7: m3 | G7: 22 | I7: =+H7*G7 -> 0
F8: m3 | G8: 22 | I8: =+H8*G8 -> 0
A9: B1.31 22 00.02 | B9: Embankments to the ROW with common / suitable excavated material or with suitable imported material | F9: m3 | G9: 16 | I9: =+H9*G9 -> 0
F10: m3 | G10: 16 | I10: =+H10*G10 -> 0
F11: m3 | G11: 16 | I11: =+H11*G11 -> 0
F12: m3 | G12: 16 | I12: =+H12*G12 -> 0
A13: B1.31 22 00.03 | B13: Subgrade | C13: MKH2-02-004-ENJ-TS9-1-CVL-FIR-0058-00 | D13: 15/10/2026 | E13: Inspection of Survey and Compaction test for subgrade 1st layer for local road 28 from st: 0+300 to 0+650 | F13: m3 | G13: 22 | H13: 1021.75 | I13: =+H13*G13 -> 22478.5
A14: B1.32 11 23.01 | B14: Aggregate base course | F14: m3 | G14: 52 | I14: =+H14*G14 -> 0
A15: B1.32 11 26.01 | B15: Bituminous base course (Grading I - Class A), including Prime Coat (MC1) and tack coat (RC2) (if any) | F15: m3 | G15: 560 | I15: =+H15*G15 -> 0
A16: B1.32 14 13.01 | B16: Precast Concrete Kerb, Type K1-A | F16: m | G16: 65 | I16: =+H16*G16 -> 0
A17: B1.32 14 13.02 | B17: Precast Concrete Kerb, Type K4 | F17: m | G17: 55 | I17: =+H17*G17 -> 0
A18: B1.32 14 13.03 | B18: Precast Concrete Kerb, Type K1-B | F18: m | G18: 55 | I18: =+H18*G18 -> 0
A19: B1.32 14 13.04 | B19: Depressed curbs Type K2 | F19: m | G19: 55 | I19: =+H19*G19 -> 0
A20: B1.32 14 13.13.01 | B20: 60mm thick - Interlocking block pavers for sidewalk/footpath | F20: m2 | G20: 70 | I20: =+H20*G20 -> 0
A21: B1.32 17 23.01 | B21: Retroreflective Thermoplastic White paiting and traffic lines | F21: m² | G21: 45 | I21: =+H21*G21 -> 0
A22: B1.32 17 23.02 | B22: Retroreflective Thermoplastic Yellow paiting and traffic lines | F22: m² | G22: 45 | I22: =+H22*G22 -> 0
A23: B1.32 17 23.06 | B23: (Speed Hump) with retroreflectiveThermoplastic yellow | F23: Unit | G23: 12000 | I23: =+H23*G23 -> 0
A24: B1.10 14 53.01 | B24: Traffic signs, ground mounted, Sheet Alumenium, (breakaway)Single post, with all accessories | F24: Unit | G24: 1800 | I24: =+H24*G24 -> 0
A25: STORM WATER DRAINAGE | I25: =+H25*G25 -> 0
A26: B6.33 42 11.07 | B26: Depth: 0.0m - 1.5m | F26: m | G26: 450 | I26: =+H26*G26 -> 0
A27: B6.33 42 11.08 | B27: Depth: 1.51m - 2.5m | F27: m | G27: 600 | I27: =+H27*G27 -> 0
A28: B6.33 42 11.09 | B28: Depth: > 2.5m | F28: m | G28: 1500 | I28: =+H28*G28 -> 0
A29: B6.33 42 11.10 | B29: Depth: 0.0m - 1.5m | C29: MKH2-02-004-ENJ-TS9-1-STR-FIR-0095-00 | D29: 13/10/2026 | E29: Relative Density Test (RDT) above Storm pipeline,local road ( 11 ) Line-M-8 ,GRP Pipe Dia(500),Depth (0.00:1.50), MH-M-8-5 TO MH-M-8-6 , MH-M-8-6 TO MH-M-8-7 . | F29: m | G29: 550 | H29: 39.53 | I29: =+H29*G29 -> 21741.5
F30: m | G30: 550 | I30: =+H30*G30 -> 0
F31: m | G31: 550 | I31: =+H31*G31 -> 0
A32: B6.33 42 11.11 | B32: Depth: 1.51m - 2.5m | F32: m | G32: 700 | I32: =+H32*G32 -> 0
A33: B6.33 42 11.12 | B33: Depth: more than 2.5m | F33: m | G33: 2000 | I33: =+H33*G33 -> 0
A34: B6.33 42 11.13 | B34: Depth: 0.0m - 1.5m | C34: MKH2-02-004-ENJ-TS9-1-STR-FIR-0094-00 | D34: 13/10/2026 | E34: Relative Density Test (RDT) above Storm pipeline,local road ( 11 ) Line-M-8 ,GRP Pipe Dia(600),Depth (0.00:1.50), MH-M-8-2 TO MH-M-8-3 , MH-M-8-3 TO MH-M-8-4 , MH-M-8-4 TO MH-M-8-5 | F34: m | G34: 650 | H34: 59.26 | I34: =+H34*G34 -> 38519
C35: MKH2-02-004-ENJ-TS9-1-STR-FIR-0099-00 | D35: 14/10/2026 | E35: Excavation & Relative Density Test (RDT) for bedding under for storm pipeline of local road ( 29 ) Line-M-13 ,GRP Pipe Dia(600),Depth (0.00:1.50), MH-M-13-2 TO MH-M-13-3 , MH-M-13-3 TO MH-M-13-4 , MH-M-13-4 TO MH-M-13-5 | F35: m | G35: 650 | H35: 59.02 | I35: =+H35*G35 -> 38363
A36: B6.33 42 11.16 | B36: Depth: 0.0m - 1.5m | C36: MKH2-02-004-ENJ-TS9-1-STR-FIR-0097-00 | D36: 13/10/2026 | E36: Survey for top of pipe and installation of Storm pipeline,local road ( 29 ) Line-M-13 ,GRP Pipe Dia(700),Depth (1.51:2.50), MH-M-13 TO MH-M-13-1 | F36: m | G36: 750 | H36: 8.54 | I36: =+H36*G36 -> 6405
F37: m | G37: 750 | I37: =+H37*G37 -> 0
F38: m | G38: 750 | I38: =+H38*G38 -> 0
F39: m | G39: 750 | I39: =+H39*G39 -> 0
F40: m | G40: 750 | I40: =+H40*G40 -> 0
F41: m | G41: 750 | I41: =+H41*G41 -> 0
...

Sheet General Information
A1: Weekly Progress Report - Construction Projects | K1: Data Date | L1: 46315 | N1: Report No. | O1: =ROUNDUP(((L1-C14)/7),0) -> 17
A2: Contract General Information
A3: Project Name | C3: Road Development for the Support Services Area at the Second Industrial City in Makkah (Al-Akayshiyah)
A4: Project ID | C4: MKH2-02-004
A5: Contractor | C5: Al Enjaz Trading & Contracting Co.
A6: Consultant | C6: Saudi Arabia Consulting Engineering Company "EGIS"
A7: Stage | C7: Construction
A8: Status | C8: Active
A9: Modon PM | C9: Engr. Abdallah Aljulaifi
A11: Key Dates
A12: Contract Award Date | C12: 46153
A13: Contract Sign Date | C13: 46198
A14: Site Handover Date | C14: 46198
A15: Original Completion | C15: 46623
A16: Contract Award Date (Hijri) | C16: 11/05/1447
A17: Contract Sign Date (Hijri) | C17: 25/06/1447
A18: Site Handover Date (Hijri) | C18: 25/06/1447
A19: Original Completion (Hijri) | C19: 24/08/1448
A20: Revised Completion Date | C20: 46623
A21: Committed Completion Date | C21: 46623
A22: Forecast Completion | C22: 46674
A23: Variance | C23: =C20-C22 -> -51
A25: Key Project Submittals | C25: Submission Date | D25: Days taken to approve orginal plan from site handover date
A26: Quality Plan submission | C26: 46217 | D26: =C26-C14 -> 19
A27: Quality Plan approval | C27: 46222
A28: Quality Plan Last Update | C28: 46222
A30: Safety Plan submission | C30: 46217 | D30: =C30-C14 -> 19
A31: Safety Plan approval | C31: 46217
A32: Safety Plan Last Update | C32: 46217
A34: Risk Management Plan submission | C34: 46217 | D34: =C34-C14 -> 19
A35: Risk Management Plan approval | C35: 46217
A36: Risk Management Plan Last Update | C36: 46217
A38: Baseline Schedule submission | C38: 46208 | D38: =C38-C14 -> 10
A39: Baseline Schedule approval | C39: 45851
A40: No of Schedule Versions | C40: 1
A41: Last Recovery Schedule Approval Date | C41: 45851
A43: BOQ submission | C43: 46254 | D43: =C43-C14 -> 56
A44: BOQ approval
A45: No of Approved Version of BOQ
A47: Project Execution Plan submission | C47: 46218 | D47: =C47-C14 -> 20
...

Sheet Progress
A1: Road Development for the Services Area at the Second Industrial City in Makkah, Al-Akayshiah (The project includes construction of Roads works & Storm Water Drainage Network) | R1: ='General Information'!$K$1 -> Data Date | S1: ='General Information'!L1 -> 46315
A4: Earned Value Progress (SAR) | J4: Physical Progress (Effort)
B5: BOQ Value (SAR) | C5: % Wt. | D5: Weekly (SAR) | G5: To Date (SAR) | J5: Budgeted | K5: % Wt. | L5: Weekly Physical Progress | N5: To Date Physical Progress
D6: Planned | E6: Earned | F6: Original Plan | G6: Planned | H6: Earned | J6: (Manhours) | L6: Planned | M6: Earned | N6: Planned | O6: Earned
A7: Mobilization | B7: =SUBTOTAL(9,B8:B8) -> 0 | C7: =IF(ISBLANK(B7),"",B7/$B$21) -> 0 | D7: =SUBTOTAL(9,D8:D8) -> 0 | E7: - | F7: =SUBTOTAL(9,F8:F8) -> 0 | G7: =SUBTOTAL(9,G8:G8) -> 0 | H7: - | J7: =SUBTOTAL(9,J8:J8) -> 7892 | K7: =IF(ISBLANK(J7),"",J7/$J$21) -> 0.043503666 | L7: =SUBTOTAL(9,L8:L8) -> 0 | M7: =SUBTOTAL(9,M8:M8) -> 0 | N7: =SUBTOTAL(9,N8:N8) -> 7892 | O7: =SUBTOTAL(9,O8:O8) -> 7892
B8: 0 | C8: =IF(ISBLANK(B8),"",B8/$B$21) -> 0 | D8: =+'Progress (2)'!I4 -> 0 | E8: =+'Progress (2)'!J4 -> 1602838.6 | F8: =+'Progress (2)'!K4 -> 0 | G8: =+'Progress (2)'!L4 -> 0 | H8: =+'Progress (2)'!M4 -> 11020158 | J8: 7892 | K8: =IF(ISBLANK(J8),"",J8/$J$21) -> 0.043503666 | L8: =+'Progress (2)'!O4 -> 0 | M8: =+'Progress (2)'!P4 -> 0 | N8: =+'Progress (2)'!Q4 -> 7892 | O8: =+'Progress (2)'!R4 -> 7892
A9: Engineering | B9: =SUBTOTAL(9,B10:B10) -> 0 | C9: =IF(ISBLANK(B9),"",B9/$B$21) -> 0 | D9: =SUBTOTAL(9,D10:D10) -> 0 | E9: =SUBTOTAL(9,E10:E10) -> 0 | F9: =SUBTOTAL(9,F10:F10) -> 0 | G9: =SUBTOTAL(9,G10:G10) -> 0 | H9: =SUBTOTAL(9,H10:H10) -> 0 | J9: =SUBTOTAL(9,J10:J10) -> 5832 | K9: =IF(ISBLANK(J9),"",J9/$J$21) -> 0.032148173 | L9: =SUBTOTAL(9,L10:L10) -> 0 | M9: =SUBTOTAL(9,M10:M10) -> 0 | N9: =SUBTOTAL(9,N10:N10) -> 5832 | O9: =SUBTOTAL(9,O10:O10) -> 5832
B10: 0 | C10: =IF(ISBLANK(B10),"",B10/$B$21) -> 0 | D10: =+'Progress (2)'!I5 -> 0 | E10: =+'Progress (2)'!J5 -> 0 | F10: =+'Progress (2)'!K5 -> 0 | G10: =+'Progress (2)'!L5 -> 0 | H10: =+'Progress (2)'!M5 -> 0 | J10: 5832 | K10: =IF(ISBLANK(J10),"",J10/$J$21) -> 0.032148173 | L10: =+'Progress (2)'!O5 -> 0 | M10: =+'Progress (2)'!P5 -> 0 | N10: =+'Progress (2)'!Q5 -> 5832 | O10: =+'Progress (2)'!R5 -> 5832
A11: Procurement | B11: =SUBTOTAL(9,B12:B12) -> 0 | C11: =IF(ISBLANK(B11),"",B11/$B$21) -> 0 | D11: =SUBTOTAL(9,D12:D12) -> 0 | E11: =SUBTOTAL(9,E12:E12) -> 0 | F11: =SUBTOTAL(9,F12:F12) -> 0 | G11: =SUBTOTAL(9,G12:G12) -> 0 | H11: =SUBTOTAL(9,H12:H12) -> 0 | J11: =SUBTOTAL(9,J12:J12) -> 4916 | K11: =IF(ISBLANK(J11),"",J11/$J$21) -> 0.027098837 | L11: =SUBTOTAL(9,L12:L12) -> 362 | M11: =SUBTOTAL(9,M12:M12) -> 0 | N11: =SUBTOTAL(9,N12:N12) -> 3784 | O11: =SUBTOTAL(9,O12:O12) -> 2918
B12: 0 | C12: =IF(ISBLANK(B12),"",B12/$B$21) -> 0 | D12: =+'Progress (2)'!I6 -> 0 | E12: =+'Progress (2)'!J6 -> 0 | F12: =+'Progress (2)'!K6 -> 0 | G12: =+'Progress (2)'!L6 -> 0 | H12: =+'Progress (2)'!M6 -> 0 | J12: 4916 | K12: =IF(ISBLANK(J12),"",J12/$J$21) -> 0.027098837 | L12: =+'Progress (2)'!O6 -> 362 | M12: =+'Progress (2)'!P6 -> 0 | N12: =+'Progress (2)'!Q6 -> 3784 | O12: =+'Progress (2)'!R6 -> 2918
A13: Road Works | B13: =SUBTOTAL(9,B14:B14) -> 19411954 | C13: =IF(ISBLANK(B13),"",B13/$B$21) -> 0.5875288 | D13: =SUBTOTAL(9,D14:D14) -> 391828.36 | E13: =SUBTOTAL(9,E14:E14) -> 481104.9 | F13: =SUBTOTAL(9,F14:F14) -> 4517610.4 | G13: =SUBTOTAL(9,G14:G14) -> 4517610.4 | H13: =SUBTOTAL(9,H14:H14) -> 6884338.4 | J13: =SUBTOTAL(9,J14:J14) -> 118380 | K13: =IF(ISBLANK(J13),"",J13/$J$21) -> 0.65255499 | L13: =SUBTOTAL(9,L14:L14) -> 3780 | M13: =SUBTOTAL(9,M14:M14) -> 3333 | N13: =SUBTOTAL(9,N14:N14) -> 37820 | O13: =SUBTOTAL(9,O14:O14) -> 59417
B14: 19411954 | C14: =IF(ISBLANK(B14),"",B14/$B$21) -> 0.5875288 | D14: =+'Progress (2)'!I7 -> 391828.36 | E14: =+'Progress (2)'!J7 -> 481104.9 | F14: =+'Progress (2)'!K7 -> 4517610.4 | G14: =+'Progress (2)'!L7 -> 4517610.4 | H14: =+'Progress (2)'!M7 -> 6884338.4 | J14: 118380 | K14: =IF(ISBLANK(J14),"",J14/$J$21) -> 0.65255499 | L14: =+'Progress (2)'!O7 -> 3780 | M14: =+'Progress (2)'!P7 -> 3333 | N14: =+'Progress (2)'!Q7 -> 37820 | O14: =+'Progress (2)'!R7 -> 59417
A15: Storm Drainage Works | B15: =SUBTOTAL(9,B16:B16) -> 13628050 | C15: =IF(ISBLANK(B15),"",B15/$B$21) -> 0.4124712 | D15: =SUBTOTAL(9,D16:D16) -> 450753.64 | E15: =SUBTOTAL(9,E16:E16) -> 1121733.7 | F15: =SUBTOTAL(9,F16:F16) -> 1799950.3 | G15: =SUBTOTAL(9,G16:G16) -> 1799950.3 | H15: =SUBTOTAL(9,H16:H16) -> 4135819.2 | J15: =SUBTOTAL(9,J16:J16) -> 41030 | K15: =IF(ISBLANK(J15),"",J15/$J$21) -> 0.22617276 | L15: =SUBTOTAL(9,L16:L16) -> 4820 | M15: =SUBTOTAL(9,M16:M16) -> 5988 | N15: =SUBTOTAL(9,N16:N16) -> 15970 | O15: =SUBTOTAL(9,O16:O16) -> 22801
B16: 13628050 | C16: =IF(ISBLANK(B16),"",B16/$B$21) -> 0.4124712 | D16: ='Progress (2)'!I8 -> 450753.64 | E16: ='Progress (2)'!J8 -> 1121733.7 | F16: ='Progress (2)'!K8 -> 1799950.3 | G16: ='Progress (2)'!L8 -> 1799950.3 | H16: ='Progress (2)'!M8 -> 4135819.2 | J16: 41030 | K16: =IF(ISBLANK(J16),"",J16/$J$21) -> 0.22617276 | L16: ='Progress (2)'!O8 -> 4820 | M16: ='Progress (2)'!P8 -> 5988 | N16: ='Progress (2)'!Q8 -> 15970 | O16: ='Progress (2)'!R8 -> 22801
A17: Testing and Commissioning | B17: =SUBTOTAL(9,B18:B18) -> 0 | C17: =IF(ISBLANK(B17),"",B17/$B$21) -> 0 | D17: =SUBTOTAL(9,D18:D18) -> 0 | E17: =SUBTOTAL(9,E18:E18) -> 0 | F17: =SUBTOTAL(9,F18:F18) -> 0 | G17: =SUBTOTAL(9,G18:G18) -> 0 | H17: =SUBTOTAL(9,H18:H18) -> 0 | J17: =SUBTOTAL(9,J18:J18) -> 2400 | K17: =IF(ISBLANK(J17),"",J17/$J$21) -> 0.013229701 | L17: =SUBTOTAL(9,L18:L18) -> 0 | M17: =SUBTOTAL(9,M18:M18) -> 0 | N17: =SUBTOTAL(9,N18:N18) -> 0 | O17: =SUBTOTAL(9,O18:O18) -> 0
B18: 0 | C18: =IF(ISBLANK(B18),"",B18/$B$21) -> 0 | D18: =+'Progress (2)'!I9 -> 0 | E18: =+'Progress (2)'!J9 -> 0 | F18: =+'Progress (2)'!K9 -> 0 | G18: =+'Progress (2)'!L9 -> 0 | H18: =+'Progress (2)'!M9 -> 0 | J18: 2400 | K18: =IF(ISBLANK(J18),"",J18/$J$21) -> 0.013229701 | L18: =+'Progress (2)'!O9 -> 0 | M18: =+'Progress (2)'!P9 -> 0 | N18: =+'Progress (2)'!Q9 -> 0 | O18: =+'Progress (2)'!R9 -> 0
B19: - | D19: =SUBTOTAL(9,D20:D20) -> 0 | E19: =SUBTOTAL(9,E20:E20) -> 0 | F19: =SUBTOTAL(9,F20:F20) -> 0 | G19: =SUBTOTAL(9,G20:G20) -> 0 | H19: =SUBTOTAL(9,H20:H20) -> 0 | J19: =SUBTOTAL(9,J20:J20) -> 960 | K19: =IF(ISBLANK(J19),"",J19/$J$21) -> 0.0052918803 | L19: =SUBTOTAL(9,L20:L20) -> 0 | M19: =SUBTOTAL(9,M20:M20) -> 0 | N19: =SUBTOTAL(9,N20:N20) -> 0 | O19: =SUBTOTAL(9,O20:O20) -> 0
B20: - | D20: =+'Progress (2)'!I11 -> 0 | E20: =+'Progress (2)'!J11 -> 0 | F20: =+'Progress (2)'!K11 -> 0 | G20: =+'Progress (2)'!L11 -> 0 | H20: =+'Progress (2)'!M11 -> 0 | J20: 960 | K20: =IF(ISBLANK(J20),"",J20/$J$21) -> 0.0052918803 | L20: =+'Progress (2)'!O11 -> 0 | M20: =+'Progress (2)'!P11 -> 0 | N20: =+'Progress (2)'!Q11 -> 0 | O20: =+'Progress (2)'!R11 -> 0
A21: Total | B21: =+SUM(B9,B11,B13,B15,B17) -> 33040004 | C21: =+SUM(C9,C11,C13,C15,C17) -> 1 | D21: =+SUM(D7,D9,D11,D13,D15,D17) -> 842582 | E21: =+SUM(E7,E9,E11,E13,E15,E17) -> 1602838.6 | F21: =+SUM(F7,F9,F11,F13,F15,F17) -> 6317560.7 | G21: =+SUM(G7,G9,G11,G13,G15,G17) -> 6317560.7 | H21: =+SUM(H7,H9,H11,H13,H15,H17) -> 11020158 | I21: =+SUM(I9,I11,I13,I15,#REF!,#REF!,#REF!,I17) -> #REF! | J21: =+SUM(J9,J11,J13,J15,J17,J7,J19) -> 181410 | K21: =+SUM(K7,K9,K11,K13,K15,K17,K19) -> 1 | L21: =+SUM(L7,L9,L11,L13,L15,L17,L19) -> 8962 | M21: =+SUM(M7,M9,M11,M13,M15,M17,M19) -> 9321 | N21: =+SUM(N7,N9,N11,N13,N15,N17,N19) -> 71298 | O21: =+SUM(O7,O9,O11,O13,O15,O17,O19) -> 98860 | P21: =+O8+O10+O12+O14 -> 76059
D22: =D21/$B$21 -> 0.025501873 | E22: =E21/$B$21 -> 0.048512058 | F22: =F21/$B$21 -> 0.19120944 | G22: =G21/$B$21 -> 0.19120944 | H22: =H21/$B$21 -> 0.33353984 | L22: =L21/$J$21 -> 0.049401907 | M22: =M21/$J$21 -> 0.05138085 | N22: =N21/$J$21 -> 0.39302133 | O22: =O21/$J$21 -> 0.54495342

Sheet Progress (2)
A1: CM This Week | I1: This Week | K1: CM | O1: This Week | Q1: CM
A2: Activity ID | B2: Planned Value Cost | C2: Earned Value Cost | D2: Planned Value Labor Units | E2: Earned Value Labor Units | F2: Schedule % Complete | G2: Performance % Complete | H2: Activity ID | I2: Planned Value Cost | J2: Earned Value Cost | K2: CM Original Plan | L2: CM Planned | M2: CM Earned | O2: Planned Value Labor Units | P2: Earned Value Labor Units | Q2: CM Planned Value Labor Units | R2: CM Earned Value Labor Units
A3: Total | B3: =+B29 -> 6317560.7 | C3: 2319038.9 | D3: =+D29 -> 71298 | E3: =+E29 -> 98859 | F3: =+F29 -> 0.1912 | G3: =+G29 -> 0.3335 | H3: Total | I3: =+B3-B13 -> 842582.01 | J3: =+C3-C13 -> 0 | K3: =B29 -> 6317560.7 | L3: =+B3 -> 6317560.7 | M3: =+C3 -> 2319038.9 | O3: =+D3-D13 -> 8963 | P3: =+E3-E13 -> 9320 | Q3: =+D3 -> 71298 | R3: =+E3 -> 98859
A4: Mobilization | B4: =+B30 -> 0 | C4: =+C29 -> 11020158 | D4: =+D30 -> 7892 | E4: =+E30 -> 7892 | F4: =+F30 -> 0 | G4: =+G30 -> 0 | H4: Mobilization | I4: =+B4-B14 -> 0 | J4: =+C4-C14 -> 1602838.6 | K4: =B30 -> 0 | L4: =+B4 -> 0 | M4: =+C4 -> 11020158 | O4: =+D4-D14 -> 0 | P4: =+E4-E14 -> 0 | Q4: =+D4 -> 7892 | R4: =+E4 -> 7892
A5: Engineering | B5: =+B31 -> 0 | C5: =+C31 -> 0 | D5: =+D31 -> 5832 | E5: =+E31 -> 5832 | F5: =+F31 -> 0 | G5: =+G31 -> 0 | H5: Engineering | I5: =+B5-B15 -> 0 | J5: =+C5-C15 -> 0 | K5: =B31 -> 0 | L5: =+B5 -> 0 | M5: =+C5 -> 0 | O5: =+D5-D15 -> 0 | P5: =+E5-E15 -> 0 | Q5: =+D5 -> 5832 | R5: =+E5 -> 5832
A6: Procuments | B6: =+B32 -> 0 | C6: =+C32 -> 0 | D6: =+D32 -> 3784 | E6: =+E32 -> 2918 | F6: =+F32 -> 0 | G6: =+G32 -> 0 | H6: Procuments | I6: =+B6-B16 -> 0 | J6: =+C6-C16 -> 0 | K6: =B32 -> 0 | L6: =+B6 -> 0 | M6: =+C6 -> 0 | O6: =+D6-D16 -> 362 | P6: =+E6-E16 -> 0 | Q6: =+D6 -> 3784 | R6: =+E6 -> 2918
A7: Road Works | B7: =+B33 -> 4517610.4 | C7: =+C33 -> 6884338.4 | D7: =+D33 -> 37820 | E7: =+E33 -> 59417 | F7: =+F33 -> 1.4024 | G7: =+G33 -> 2.9065 | H7: Road Works | I7: =+B7-B17 -> 391828.36 | J7: =+C7-C17 -> 481104.9 | K7: =B33 -> 4517610.4 | L7: =+B7 -> 4517610.4 | M7: =+C7 -> 6884338.4 | O7: =+D7-D17 -> 3780 | P7: =+E7-E17 -> 3333 | Q7: =+D7 -> 37820 | R7: =+E7 -> 59417
