Workbook

Sheet Tracking Progress
A1: ActivityID | B1: Activity ID | C1: Activity Name | D1: BL Project Total Cost | E1: Previous Percentage ( % ) | F1: Progress Variance ( % ) | G1: Total Progress % | H1: Cumulative Amount | I1: Curent Amount
A2: Infrastructure Development for Madinah Industrial city Phase 1-A | B2: JDH4-02-007 - Land Development of Jeddah Oasis | D2: 57304348 | E2: =+'Previous week'!F2 -> 0.9331 | F2: =G2-E2 -> 0.0186 | G2: =+'Current week'!F2 -> 0.9517 | H2: =+'Current week'!G2 -> 54534355 | I2: =+F2*D2 -> 1065860.9
A3: Key Milestones | B3: Key Milestones | D3: 0 | F3: =G3-E3 -> 0
A4: General Milestone | B4: General Milestone | D4: 0 | F4: =G4-E4 -> 0
A5: JDH4-02-007-MS-1000 | B5: JDH4-02-007-MS-1000 | C5: Project Commencement Date | D5: 0 | E5: =VLOOKUP(A5,'Previous week'!$A$3:$F$1765,6,FALSE) -> 1 | F5: =G5-E5 -> 0 | G5: =VLOOKUP(A5,'Current week'!$A$3:$F$1765,6,0) -> 1 | H5: =G5*D5 -> 0 | I5: =F5*D5 -> 0
A6: JDH4-02-007-MS-1010 | B6: JDH4-02-007-MS-1010 | C6: Project Completion Date | D6: 0 | E6: =VLOOKUP(A6,'Previous week'!$A$3:$F$1765,6,FALSE) -> 0 | F6: =G6-E6 -> 0 | G6: =VLOOKUP(A6,'Current week'!$A$3:$F$1765,6,0) -> 0 | H6: =G6*D6 -> 0 | I6: =F6*D6 -> 0
A7: Contractual Milestone | B7: Contractual Milestone | D7: 0 | F7: =G7-E7 -> 0
A8: Engineering & Mobilization | B8: Engineering & Mobilization | D8: 0 | F8: =G8-E8 -> 0
A9: JDH4-02-007-MS-1020 | B9: JDH4-02-007-MS-1020 | C9: Completion of Mobilization | D9: 0 | E9: =VLOOKUP(A9,'Previous week'!$A$3:$F$1765,6,FALSE) -> 1 | F9: =G9-E9 -> 0 | G9: =VLOOKUP(A9,'Current week'!$A$3:$F$1765,6,0) -> 1 | H9: =G9*D9 -> 0 | I9: =F9*D9 -> 0
A10: JDH4-02-007-MS-1030 | B10: JDH4-02-007-MS-1030 | C10: Submission of the Work Plan (Baseline Programme) | D10: 0 | E10: =VLOOKUP(A10,'Previous week'!$A$3:$F$1765,6,FALSE) -> 1 | F10: =G10-E10 -> 0 | G10: =VLOOKUP(A10,'Current week'!$A$3:$F$1765,6,0) -> 1 | H10: =G10*D10 -> 0 | I10: =F10*D10 -> 0
A11: JDH4-02-007-MS-1040 | B11: JDH4-02-007-MS-1040 | C11: Submission and Approval of Drawings and Materials | D11: 0 | F11: =G11-E11 -> 0
A12: Construction | B12: Construction | D12: 0 | E12: =VLOOKUP(A12,'Previous week'!$A$3:$F$1765,6,FALSE) -> 0 | F12: =G12-E12 -> 0 | G12: =VLOOKUP(A12,'Current week'!$A$3:$F$1765,6,0) -> 0 | H12: =G12*D12 -> 0 | I12: =F12*D12 -> 0
A13: JDH4-02-007-MS-1050 | B13: JDH4-02-007-MS-1050 | C13: Completion of Earthworks & Site Grading For Plots | D13: 0 | E13: =VLOOKUP(A13,'Previous week'!$A$3:$F$1765,6,FALSE) -> 0 | F13: =G13-E13 -> 0 | G13: =VLOOKUP(A13,'Current week'!$A$3:$F$1765,6,0) -> 0 | H13: =G13*D13 -> 0 | I13: =F13*D13 -> 0
A14: JDH4-02-007-MS-1060 | B14: JDH4-02-007-MS-1060 | C14: Completion of Sewerage networks | D14: 0 | F14: =G14-E14 -> 0
A15: JDH4-02-007-MS-1070 | B15: JDH4-02-007-MS-1070 | C15: Completion of Road Works | D15: 0 | E15: =VLOOKUP(A15,'Previous week'!$A$3:$F$1765,6,FALSE) -> 0 | F15: =G15-E15 -> 0 | G15: =VLOOKUP(A15,'Current week'!$A$3:$F$1765,6,0) -> 0 | H15: =G15*D15 -> 0 | I15: =F15*D15 -> 0
A16: JDH4-02-007-MS-1080 | B16: JDH4-02-007-MS-1080 | C16: Completion of Potable Water Network | D16: 0 | E16: =VLOOKUP(A16,'Previous week'!$A$3:$F$1765,6,FALSE) -> 1 | F16: =G16-E16 -> 0 | G16: =VLOOKUP(A16,'Current week'!$A$3:$F$1765,6,0) -> 1 | H16: =G16*D16 -> 0 | I16: =F16*D16 -> 0
A17: JDH4-02-007-MS-1090 | B17: JDH4-02-007-MS-1090 | C17: Completion of TSE Network | D17: 0 | F17: =G17-E17 -> 0
A18: JDH4-02-007-MS-1100 | B18: JDH4-02-007-MS-1100 | C18: Completion of Electrical Networks | D18: 0 | E18: =VLOOKUP(A18,'Previous week'!$A$3:$F$1765,6,FALSE) -> 0 | F18: =G18-E18 -> 0 | G18: =VLOOKUP(A18,'Current week'!$A$3:$F$1765,6,0) -> 0 | H18: =G18*D18 -> 0 | I18: =F18*D18 -> 0
A19: JDH4-02-007-MS-1110 | B19: JDH4-02-007-MS-1110 | C19: Completion of Entire Project | D19: 0 | E19: =VLOOKUP(A19,'Previous week'!$A$3:$F$1765,6,FALSE) -> 0 | F19: =G19-E19 -> 0 | G19: =VLOOKUP(A19,'Current week'!$A$3:$F$1765,6,0) -> 0 | H19: =G19*D19 -> 0 | I19: =F19*D19 -> 0
A20: Monitoring & Controlling Milestone | B20: Monitoring & Controlling Milestone | D20: 0 | E20: =VLOOKUP(A20,'Previous week'!$A$3:$F$1765,6,FALSE) -> 0 | F20: =G20-E20 -> 0 | G20: =VLOOKUP(A20,'Current week'!$A$3:$F$1765,6,0) -> 0 | H20: =G20*D20 -> 0 | I20: =F20*D20 -> 0
A21: JDH4-02-007-MS-1130 | B21: JDH4-02-007-MS-1130 | C21: Approval of Electrical Network Materials By SEC | D21: 0 | E21: =VLOOKUP(A21,'Previous week'!$A$3:$F$1765,6,FALSE) -> 1 | F21: =G21-E21 -> 0 | G21: =VLOOKUP(A21,'Current week'!$A$3:$F$1765,6,0) -> 1 | H21: =G21*D21 -> 0 | I21: =F21*D21 -> 0
A22: JDH4-02-007-MS-1120 | B22: JDH4-02-007-MS-1120 | C22: Approval of Electrical Network Shop DWGs By SEC | D22: 0 | E22: =VLOOKUP(A22,'Previous week'!$A$3:$F$1765,6,FALSE) -> 1 | F22: =G22-E22 -> 0 | G22: =VLOOKUP(A22,'Current week'!$A$3:$F$1765,6,0) -> 1 | H22: =G22*D22 -> 0 | I22: =F22*D22 -> 0
A23: Mobilization | B23: Mobilization | D23: 0 | E23: =VLOOKUP(A23,'Previous week'!$A$3:$F$1765,6,FALSE) -> 0 | F23: =G23-E23 -> 0 | G23: =VLOOKUP(A23,'Current week'!$A$3:$F$1765,6,0) -> 0 | H23: =G23*D23 -> 0 | I23: =F23*D23 -> 0
A24: Site Facilities & Offices | B24: Site Facilities & Offices | D24: 0 | F24: =G24-E24 -> 0
A25: JDH4-02-007-MB-1000 | B25: JDH4-02-007-MB-1000 | C25: Site Layout Plan | D25: 0 | F25: =G25-E25 -> 0
A26: JDH4-02-007-MB-1010 | B26: JDH4-02-007-MB-1010 | C26: Clear & Grub for Offices & Access Road | D26: 0 | E26: =VLOOKUP(A26,'Previous week'!$A$3:$F$1765,6,FALSE) -> 1 | F26: =G26-E26 -> 0 | G26: =VLOOKUP(A26,'Current week'!$A$3:$F$1765,6,0) -> 1 | H26: =G26*D26 -> 0 | I26: =F26*D26 -> 0
A27: JDH4-02-007-MB-1020 | B27: JDH4-02-007-MB-1020 | C27: Construct Site Access Roads | D27: 0 | E27: =VLOOKUP(A27,'Previous week'!$A$3:$F$1765,6,FALSE) -> 1 | F27: =G27-E27 -> 0 | G27: =VLOOKUP(A27,'Current week'!$A$3:$F$1765,6,0) -> 1 | H27: =G27*D27 -> 0 | I27: =F27*D27 -> 0
A28: JDH4-02-007-MB-1040 | B28: JDH4-02-007-MB-1040 | C28: Construct Site Offices & Storage | D28: 0 | E28: =VLOOKUP(A28,'Previous week'!$A$3:$F$1765,6,FALSE) -> 1 | F28: =G28-E28 -> 0 | G28: =VLOOKUP(A28,'Current week'!$A$3:$F$1765,6,0) -> 1 | H28: =G28*D28 -> 0 | I28: =F28*D28 -> 0
A29: JDH4-02-007-MB-1030 | B29: JDH4-02-007-MB-1030 | C29: Construct Temporary Fence | D29: 0 | E29: =VLOOKUP(A29,'Previous week'!$A$3:$F$1765,6,FALSE) -> 1 | F29: =G29-E29 -> 0 | G29: =VLOOKUP(A29,'Current week'!$A$3:$F$1765,6,0) -> 1 | H29: =G29*D29 -> 0 | I29: =F29*D29 -> 0
A30: JDH4-02-007-MB-1060 | B30: JDH4-02-007-MB-1060 | C30: Install Site Facilities | D30: 0 | E30: =VLOOKUP(A30,'Previous week'!$A$3:$F$1765,6,FALSE) -> 1 | F30: =G30-E30 -> 0 | G30: =VLOOKUP(A30,'Current week'!$A$3:$F$1765,6,0) -> 1 | H30: =G30*D30 -> 0 | I30: =F30*D30 -> 0
A31: JDH4-02-007-MB-1070 | B31: JDH4-02-007-MB-1070 | C31: Electrical Works & Connections | D31: 0 | E31: =VLOOKUP(A31,'Previous week'!$A$3:$F$1765,6,FALSE) -> 1 | F31: =G31-E31 -> 0 | G31: =VLOOKUP(A31,'Current week'!$A$3:$F$1765,6,0) -> 1 | H31: =G31*D31 -> 0 | I31: =F31*D31 -> 0
A32: JDH4-02-007-MB-1090 | B32: JDH4-02-007-MB-1090 | C32: Mobilization of Equipment | D32: 0 | E32: =VLOOKUP(A32,'Previous week'!$A$3:$F$1765,6,FALSE) -> 1 | F32: =G32-E32 -> 0 | G32: =VLOOKUP(A32,'Current week'!$A$3:$F$1765,6,0) -> 1 | H32: =G32*D32 -> 0 | I32: =F32*D32 -> 0
A33: JDH4-02-007-MB-1100 | B33: JDH4-02-007-MB-1100 | C33: Mobilization of Manpower | D33: 0 | E33: =VLOOKUP(A33,'Previous week'!$A$3:$F$1765,6,FALSE) -> 1 | F33: =G33-E33 -> 0 | G33: =VLOOKUP(A33,'Current week'!$A$3:$F$1765,6,0) -> 1 | H33: =G33*D33 -> 0 | I33: =F33*D33 -> 0
A34: JDH4-02-007-MB-1080 | B34: JDH4-02-007-MB-1080 | C34: Construct Parking Sheds | D34: 0 | E34: =VLOOKUP(A34,'Previous week'!$A$3:$F$1765,6,FALSE) -> 1 | F34: =G34-E34 -> 0 | G34: =VLOOKUP(A34,'Current week'!$A$3:$F$1765,6,0) -> 1 | H34: =G34*D34 -> 0 | I34: =F34*D34 -> 0
A35: JDH4-02-007-MB-1050 | B35: JDH4-02-007-MB-1050 | C35: Install Project Signs | D35: 0 | E35: =VLOOKUP(A35,'Previous week'!$A$3:$F$1765,6,FALSE) -> 1 | F35: =G35-E35 -> 0 | G35: =VLOOKUP(A35,'Current week'!$A$3:$F$1765,6,0) -> 1 | H35: =G35*D35 -> 0 | I35: =F35*D35 -> 0
A36: Topographic Survey | B36: Topographic Survey | D36: 0 | E36: =VLOOKUP(A36,'Previous week'!$A$3:$F$1765,6,FALSE) -> 0 | F36: =G36-E36 -> 0 | G36: =VLOOKUP(A36,'Current week'!$A$3:$F$1765,6,0) -> 0 | H36: =G36*D36 -> 0 | I36: =F36*D36 -> 0
A37: JDH4-02-007-TP-1000 | B37: JDH4-02-007-TP-1000 | C37: Site Survey Works | D37: 0 | F37: =G37-E37 -> 0
A38: Permit's and Authority Approvals | B38: Permit's and Authority Approvals | D38: 0 | E38: =VLOOKUP(A38,'Previous week'!$A$3:$F$1765,6,FALSE) -> 0 | F38: =G38-E38 -> 0 | G38: =VLOOKUP(A38,'Current week'!$A$3:$F$1765,6,0) -> 0 | H38: =G38*D38 -> 0 | I38: =F38*D38 -> 0
A39: JDH4-02-007-PA-1000 | B39: JDH4-02-007-PA-1000 | C39: Excavation & Backfilling Permit Permit | D39: 0 | F39: =G39-E39 -> 0
A40: JDH4-02-007-PA-1010 | B40: JDH4-02-007-PA-1010 | C40: Saudi Electricity Company Permit | D40: 0 | E40: =VLOOKUP(A40,'Previous week'!$A$3:$F$1765,6,FALSE) -> 1 | F40: =G40-E40 -> 0 | G40: =VLOOKUP(A40,'Current week'!$A$3:$F$1765,6,0) -> 1 | H40: =G40*D40 -> 0 | I40: =F40*D40 -> 0
...

Sheet Current week
A1: Activity ID | B1: Activity ID | C1: Activity Name | D1: Budgeted Total Cost | E1: Activity % Complete | F1: Performance % Complete | G1: Earned Value Cost
A2: Infrastructure Development for Madinah Industrial city Phase 1-A | B2: JDH4-02-007-R-UP-Land Development of Jeddah Oasis- 20 Oct 2026 | D2: 57304348 | F2: 0.9517 | G2: 54534355
A3: =TRIM(B3) -> Key Milestones | B3: Key Milestones | D3: 0 | F3: 0 | G3: 0
A4: =TRIM(B4) -> General Milestone | B4: General Milestone | D4: 0 | F4: 0 | G4: 0
A5: =TRIM(B5) -> JDH4-02-007-MS-1000 | B5: JDH4-02-007-MS-1000 | C5: Project Commencement Date | D5: 0 | E5: 1 | F5: 1 | G5: 0
A6: =TRIM(B6) -> JDH4-02-007-MS-1010 | B6: JDH4-02-007-MS-1010 | C6: Project Completion Date | D6: 0 | E6: 0 | F6: 0 | G6: 0
A7: =TRIM(B7) -> Contractual Milestone | B7: Contractual Milestone | D7: 0 | F7: 0 | G7: 0
A8: =TRIM(B8) -> Engineering & Mobilization | B8: Engineering & Mobilization | D8: 0 | F8: 0 | G8: 0
A9: =TRIM(B9) -> JDH4-02-007-MS-1020 | B9: JDH4-02-007-MS-1020 | C9: Completion of Mobilization | D9: 0 | E9: 1 | F9: 1 | G9: 0
A10: =TRIM(B10) -> JDH4-02-007-MS-1030 | B10: JDH4-02-007-MS-1030 | C10: Submission of the Work Plan (Baseline Programme) | D10: 0 | E10: 1 | F10: 1 | G10: 0
A11: =TRIM(B11) -> JDH4-02-007-MS-1040 | B11: JDH4-02-007-MS-1040 | C11: Submission and Approval of Drawings and Materials | D11: 0 | E11: 1 | F11: 1 | G11: 0
A12: =TRIM(B12) -> Construction | B12: Construction | D12: 0 | F12: 0 | G12: 0
A13: =TRIM(B13) -> JDH4-02-007-MS-1060 | B13: JDH4-02-007-MS-1060 | C13: Completion of Sewerage networks | D13: 0 | E13: 1 | F13: 1 | G13: 0
A14: =TRIM(B14) -> JDH4-02-007-MS-1090 | B14: JDH4-02-007-MS-1090 | C14: Completion of TSE Network | D14: 0 | E14: 1 | F14: 1 | G14: 0
A15: =TRIM(B15) -> JDH4-02-007-MS-1080 | B15: JDH4-02-007-MS-1080 | C15: Completion of Potable Water Network | D15: 0 | E15: 1 | F15: 1 | G15: 0
A16: =TRIM(B16) -> JDH4-02-007-MS-1050 | B16: JDH4-02-007-MS-1050 | C16: Completion of Earthworks & Site Grading For Plots | D16: 0 | E16: 0 | F16: 0 | G16: 0
A17: =TRIM(B17) -> JDH4-02-007-MS-1070 | B17: JDH4-02-007-MS-1070 | C17: Completion of Road Works | D17: 0 | E17: 0 | F17: 0 | G17: 0
A18: =TRIM(B18) -> JDH4-02-007-MS-1100 | B18: JDH4-02-007-MS-1100 | C18: Completion of Electrical Networks | D18: 0 | E18: 0 | F18: 0 | G18: 0
A19: =TRIM(B19) -> JDH4-02-007-MS-1110 | B19: JDH4-02-007-MS-1110 | C19: Completion of Entire Project | D19: 0 | E19: 0 | F19: 0 | G19: 0
A20: =TRIM(B20) -> Monitoring & Controlling Milestone | B20: Monitoring & Controlling Milestone | D20: 0 | F20: 0 | G20: 0
A21: =TRIM(B21) -> JDH4-02-007-MS-1120 | B21: JDH4-02-007-MS-1120 | C21: Approval of Electrical Network Shop DWGs By SEC | D21: 0 | E21: 1 | F21: 1 | G21: 0
A22: =TRIM(B22) -> JDH4-02-007-MS-1130 | B22: JDH4-02-007-MS-1130 | C22: Approval of Electrical Network Materials By SEC | D22: 0 | E22: 1 | F22: 1 | G22: 0
A23: =TRIM(B23) -> Mobilization | B23: Mobilization | D23: 0 | F23: 0 | G23: 0
A24: =TRIM(B24) -> Site Facilities & Offices | B24: Site Facilities & Offices | D24: 0 | F24: 0 | G24: 0
A25: =TRIM(B25) -> JDH4-02-007-MB-1000 | B25: JDH4-02-007-MB-1000 | C25: Site Layout Plan | D25: 0 | E25: 1 | F25: 1 | G25: 0
A26: =TRIM(B26) -> JDH4-02-007-MB-1010 | B26: JDH4-02-007-MB-1010 | C26: Clear & Grub for Offices & Access Road | D26: 0 | E26: 1 | F26: 1 | G26: 0
A27: =TRIM(B27) -> JDH4-02-007-MB-1020 | B27: JDH4-02-007-MB-1020 | C27: Construct Site Access Roads | D27: 0 | E27: 1 | F27: 1 | G27: 0
A28: =TRIM(B28) -> JDH4-02-007-MB-1040 | B28: JDH4-02-007-MB-1040 | C28: Construct Site Offices & Storage | D28: 0 | E28: 1 | F28: 1 | G28: 0
A29: =TRIM(B29) -> JDH4-02-007-MB-1030 | B29: JDH4-02-007-MB-1030 | C29: Construct Temporary Fence | D29: 0 | E29: 1 | F29: 1 | G29: 0
A30: =TRIM(B30) -> JDH4-02-007-MB-1060 | B30: JDH4-02-007-MB-1060 | C30: Install Site Facilities | D30: 0 | E30: 1 | F30: 1 | G30: 0
A31: =TRIM(B31) -> JDH4-02-007-MB-1070 | B31: JDH4-02-007-MB-1070 | C31: Electrical Works & Connections | D31: 0 | E31: 1 | F31: 1 | G31: 0
A32: =TRIM(B32) -> JDH4-02-007-MB-1090 | B32: JDH4-02-007-MB-1090 | C32: Mobilization of Equipment | D32: 0 | E32: 1 | F32: 1 | G32: 0
A33: =TRIM(B33) -> JDH4-02-007-MB-1100 | B33: JDH4-02-007-MB-1100 | C33: Mobilization of Manpower | D33: 0 | E33: 1 | F33: 1 | G33: 0
A34: =TRIM(B34) -> JDH4-02-007-MB-1050 | B34: JDH4-02-007-MB-1050 | C34: Install Project Signs | D34: 0 | E34: 1 | F34: 1 | G34: 0
A35: =TRIM(B35) -> JDH4-02-007-MB-1080 | B35: JDH4-02-007-MB-1080 | C35: Construct Parking Sheds | D35: 0 | E35: 1 | F35: 1 | G35: 0
A36: =TRIM(B36) -> Topographic Survey | B36: Topographic Survey | D36: 0 | F36: 0 | G36: 0
A37: =TRIM(B37) -> JDH4-02-007-TP-1000 | B37: JDH4-02-007-TP-1000 | C37: Site Survey Works | D37: 0 | E37: 1 | F37: 1 | G37: 0
A38: =TRIM(B38) -> Permit's and Authority Approvals | B38: Permit's and Authority Approvals | D38: 0 | F38: 0 | G38: 0
A39: =TRIM(B39) -> JDH4-02-007-PA-1000 | B39: JDH4-02-007-PA-1000 | C39: Excavation & Backfilling Permit Permit | D39: 0 | E39: 1 | F39: 1 | G39: 0
A40: =TRIM(B40) -> JDH4-02-007-PA-1010 | B40: JDH4-02-007-PA-1010 | C40: Saudi Electricity Company Permit | D40: 0 | E40: 1 | F40: 1 | G40: 0
...

Sheet Previous week
A1: Activity ID | B1: Activity ID | C1: Activity Name | D1: Budgeted Total Cost | E1: Activity % Complete | F1: Performance % Complete | G1: Earned Value Cost
A2: Infrastructure Development for Madinah Industrial city Phase 1-A | B2: JDH4-02-007-R-UP-Land Development of Jeddah Oasis- 13 Oct 2026 | D2: 57304348 | F2: 0.9331 | G2: 53468556
A3: =TRIM(B3) -> Key Milestones | B3: Key Milestones | D3: 0 | F3: 0 | G3: 0
A4: =TRIM(B4) -> General Milestone | B4: General Milestone | D4: 0 | F4: 0 | G4: 0
A5: =TRIM(B5) -> JDH4-02-007-MS-1000 | B5: JDH4-02-007-MS-1000 | C5: Project Commencement Date | D5: 0 | E5: 1 | F5: 1 | G5: 0
A6: =TRIM(B6) -> JDH4-02-007-MS-1010 | B6: JDH4-02-007-MS-1010 | C6: Project Completion Date | D6: 0 | E6: 0 | F6: 0 | G6: 0
A7: =TRIM(B7) -> Contractual Milestone | B7: Contractual Milestone | D7: 0 | F7: 0 | G7: 0
A8: =TRIM(B8) -> Engineering & Mobilization | B8: Engineering & Mobilization | D8: 0 | F8: 0 | G8: 0
A9: =TRIM(B9) -> JDH4-02-007-MS-1020 | B9: JDH4-02-007-MS-1020 | C9: Completion of Mobilization | D9: 0 | E9: 1 | F9: 1 | G9: 0
A10: =TRIM(B10) -> JDH4-02-007-MS-1030 | B10: JDH4-02-007-MS-1030 | C10: Submission of the Work Plan (Baseline Programme) | D10: 0 | E10: 1 | F10: 1 | G10: 0
A11: =TRIM(B11) -> JDH4-02-007-MS-1040 | B11: JDH4-02-007-MS-1040 | C11: Submission and Approval of Drawings and Materials | D11: 0 | E11: 1 | F11: 1 | G11: 0
A12: =TRIM(B12) -> Construction | B12: Construction | D12: 0 | F12: 0 | G12: 0
A13: =TRIM(B13) -> JDH4-02-007-MS-1060 | B13: JDH4-02-007-MS-1060 | C13: Completion of Sewerage networks | D13: 0 | E13: 1 | F13: 1 | G13: 0
A14: =TRIM(B14) -> JDH4-02-007-MS-1090 | B14: JDH4-02-007-MS-1090 | C14: Completion of TSE Network | D14: 0 | E14: 1 | F14: 1 | G14: 0
A15: =TRIM(B15) -> JDH4-02-007-MS-1080 | B15: JDH4-02-007-MS-1080 | C15: Completion of Potable Water Network | D15: 0 | E15: 1 | F15: 1 | G15: 0
A16: =TRIM(B16) -> JDH4-02-007-MS-1050 | B16: JDH4-02-007-MS-1050 | C16: Completion of Earthworks & Site Grading For Plots | D16: 0 | E16: 0 | F16: 0 | G16: 0
A17: =TRIM(B17) -> JDH4-02-007-MS-1070 | B17: JDH4-02-007-MS-1070 | C17: Completion of Road Works | D17: 0 | E17: 0 | F17: 0 | G17: 0
A18: =TRIM(B18) -> JDH4-02-007-MS-1100 | B18: JDH4-02-007-MS-1100 | C18: Completion of Electrical Networks | D18: 0 | E18: 0 | F18: 0 | G18: 0
A19: =TRIM(B19) -> JDH4-02-007-MS-1110 | B19: JDH4-02-007-MS-1110 | C19: Completion of Entire Project | D19: 0 | E19: 0 | F19: 0 | G19: 0
A20: =TRIM(B20) -> Monitoring & Controlling Milestone | B20: Monitoring & Controlling Milestone | D20: 0 | F20: 0 | G20: 0
A21: =TRIM(B21) -> JDH4-02-007-MS-1120 | B21: JDH4-02-007-MS-1120 | C21: Approval of Electrical Network Shop DWGs By SEC | D21: 0 | E21: 1 | F21: 1 | G21: 0
A22: =TRIM(B22) -> JDH4-02-007-MS-1130 | B22: JDH4-02-007-MS-1130 | C22: Approval of Electrical Network Materials By SEC | D22: 0 | E22: 1 | F22: 1 | G22: 0
A23: =TRIM(B23) -> Mobilization | B23: Mobilization | D23: 0 | F23: 0 | G23: 0
A24: =TRIM(B24) -> Site Facilities & Offices | B24: Site Facilities & Offices | D24: 0 | F24: 0 | G24: 0
A25: =TRIM(B25) -> JDH4-02-007-MB-1000 | B25: JDH4-02-007-MB-1000 | C25: Site Layout Plan | D25: 0 | E25: 1 | F25: 1 | G25: 0
A26: =TRIM(B26) -> JDH4-02-007-MB-1010 | B26: JDH4-02-007-MB-1010 | C26: Clear & Grub for Offices & Access Road | D26: 0 | E26: 1 | F26: 1 | G26: 0
A27: =TRIM(B27) -> JDH4-02-007-MB-1020 | B27: JDH4-02-007-MB-1020 | C27: Construct Site Access Roads | D27: 0 | E27: 1 | F27: 1 | G27: 0
A28: =TRIM(B28) -> JDH4-02-007-MB-1040 | B28: JDH4-02-007-MB-1040 | C28: Construct Site Offices & Storage | D28: 0 | E28: 1 | F28: 1 | G28: 0
A29: =TRIM(B29) -> JDH4-02-007-MB-1030 | B29: JDH4-02-007-MB-1030 | C29: Construct Temporary Fence | D29: 0 | E29: 1 | F29: 1 | G29: 0
A30: =TRIM(B30) -> JDH4-02-007-MB-1060 | B30: JDH4-02-007-MB-1060 | C30: Install Site Facilities | D30: 0 | E30: 1 | F30: 1 | G30: 0
A31: =TRIM(B31) -> JDH4-02-007-MB-1070 | B31: JDH4-02-007-MB-1070 | C31: Electrical Works & Connections | D31: 0 | E31: 1 | F31: 1 | G31: 0
A32: =TRIM(B32) -> JDH4-02-007-MB-1090 | B32: JDH4-02-007-MB-1090 | C32: Mobilization of Equipment | D32: 0 | E32: 1 | F32: 1 | G32: 0
A33: =TRIM(B33) -> JDH4-02-007-MB-1100 | B33: JDH4-02-007-MB-1100 | C33: Mobilization of Manpower | D33: 0 | E33: 1 | F33: 1 | G33: 0
A34: =TRIM(B34) -> JDH4-02-007-MB-1050 | B34: JDH4-02-007-MB-1050 | C34: Install Project Signs | D34: 0 | E34: 1 | F34: 1 | G34: 0
A35: =TRIM(B35) -> JDH4-02-007-MB-1080 | B35: JDH4-02-007-MB-1080 | C35: Construct Parking Sheds | D35: 0 | E35: 1 | F35: 1 | G35: 0
A36: =TRIM(B36) -> Topographic Survey | B36: Topographic Survey | D36: 0 | F36: 0 | G36: 0
A37: =TRIM(B37) -> JDH4-02-007-TP-1000 | B37: JDH4-02-007-TP-1000 | C37: Site Survey Works | D37: 0 | E37: 1 | F37: 1 | G37: 0
A38: =TRIM(B38) -> Permit's and Authority Approvals | B38: Permit's and Authority Approvals | D38: 0 | F38: 0 | G38: 0
A39: =TRIM(B39) -> JDH4-02-007-PA-1000 | B39: JDH4-02-007-PA-1000 | C39: Excavation & Backfilling Permit Permit | D39: 0 | E39: 1 | F39: 1 | G39: 0
A40: =TRIM(B40) -> JDH4-02-007-PA-1010 | B40: JDH4-02-007-PA-1010 | C40: Saudi Electricity Company Permit | D40: 0 | E40: 1 | F40: 1 | G40: 0
...
