Workbook
Name At_risk: #REF!
Name atrisk_total_net_rent_for_cashflow: #REF!
Name Audit_Category: #REF!
Name BC: #REF!
Name BCTemp: #REF!
Name BQ: #REF!
Name car_park_cash_flow: #REF!
Name CEMP_Category: #REF!
Name CESMM3rdDiv: #REF!
Name Channel_Template: #REF!
Name ChannelSched: #REF!
Name complete: #REF!
Name completion_date: #REF!
Name Conc_01: #REF!
Name CONC_06: #REF!
Name CONC_09: #REF!
Name CONC_11: #REF!
Name CONC_16: #REF!
Name CONC_23: #REF!
Name CulType: #REF!
Name CulvertSched: #REF!
Name CUlvertType: #REF!
Name CulvSched: #REF!
Name Date: #REF!
Name EMP_Category: #REF!
Name Exclusions: #REF!
Name GG: #REF!
Name Incident_Tier: #REF!
Name Incident_Type: #REF!
Name Inside_Dia__ID: #REF!
Name IssEscStatus1: #REF!
Name IssEscStatus1: #REF!
Name IssEscStatus1: #REF!
Name IssEscStatus1: #REF!
Name K9B_1: #REF!
Name K9B_2: #REF!
Name KK: #REF!
Name kpi: #REF!
Name LAB_PART: #REF!
Name LAB_UPLIFT: #REF!
Name Manhole: #REF!
Name MATL_PART: #REF!
Name MS_DW_1: #REF!
Name MS_DW_10: #REF!
Name MS_DW_13: #REF!
Name MS_DW_14: #REF!
Name MS_DW_15: #REF!
Name MS_DW_16: #REF!
Name MS_DW_2: #REF!
Name MS_DW_3: #REF!
Name MS_DW_4: #REF!
Name MS_DW_5: #REF!
Name MS_DW_6: #REF!
Name MS_DW_7: #REF!
Name MS_DW_8: #REF!
Name MS_DW_9: #REF!
Name Pavement_Type: #REF!
Name PhaseCode: #REF!
Name PILE_1_MOOR: #REF!
Name PILE_10_Moor: #REF!

Sheet DB
A1: ='Weekly Progress Report'!$A$1 -> MODON - Weekly Progress Report - Construction Projects
B2: ='Weekly Progress Report'!$A$2 -> Contract General Information | J2: ='Weekly Progress Report'!G2 -> Key Dates | U2: ='Weekly Progress Report'!$M$2 -> Cost Summary (SR) | AD2: ='Weekly Progress Report'!$U$2 -> Performance Summary | AP2: ='Weekly Progress Report'!A67 -> Shop Drawings | AT2: ='Weekly Progress Report'!A76 -> Material Approval | AW2: ='Weekly Progress Report'!A85 -> Procurement Summary | BD2: ='Weekly Progress Report'!L67 -> Quality Reports | BT2: ='Weekly Progress Report'!L75 -> Key Submittals Approval Status | CD2: ='Weekly Progress Report'!L81 -> Invoices Summary | CR2: ='Weekly Progress Report'!L89 -> Resources at Site | CY2: ='Weekly Progress Report'!W67 -> Safety Statistics | FK2: ='Weekly Progress Report'!A94 -> Primavera P6 Schedule Status | FS2: ='Weekly Progress Report'!A103 -> Testing And Commissioning
A3: ='Weekly Progress Report'!AF1 -> Data Date | B3: ='Weekly Progress Report'!A3 -> Project Name | C3: ='Weekly Progress Report'!A4 -> Project ID | D3: ='Weekly Progress Report'!A5 -> Contractor | E3: ='Weekly Progress Report'!A6 -> Consultant | F3: ='Weekly Progress Report'!D4 -> Stage | G3: ='Weekly Progress Report'!D5 -> Status | H3: ='Weekly Progress Report'!D6 -> Modon PM | I3: ='Weekly Progress Report'!AA2 -> Project Scope | J3: ='Weekly Progress Report'!G3 -> Contract Award | K3: ='Weekly Progress Report'!G4 -> Contract Sign | L3: ='Weekly Progress Report'!G5 -> Site Handover | M3: ='Weekly Progress Report'!G6 -> Original Completion | N3: ='Weekly Progress Report'!$I$3 -> Contract Award (Hijri) | O3: ='Weekly Progress Report'!$I$4 -> Contract Sign (Hijri) | P3: ='Weekly Progress Report'!$I$5 -> Site Handover (Hijri) | Q3: ='Weekly Progress Report'!$I$6 -> Original Completion (Hijri) | R3: ='Weekly Progress Report'!$K$3 -> Revised Completion | S3: ='Weekly Progress Report'!$K$4 -> Committed Completion | T3: ='Weekly Progress Report'!$K$5 -> Forecast Completion | U3: ='Weekly Progress Report'!$M$3 -> Original Contract Value | V3: ='Weekly Progress Report'!$M$4 -> Revised Contract Value | W3: ='Weekly Progress Report'!$M$5 -> Estimate At Completion Value | X3: ='Weekly Progress Report'!$M$6 -> Potential Changes | Y3: ='Weekly Progress Report'!$Q$3 -> O&M Value | Z3: ='Weekly Progress Report'!$Q$4 -> Revised O&M Value | AA3: ='Weekly Progress Report'!$Q$5 -> Submitted Invoices (Gross Value) | AB3: ='Weekly Progress Report'!$Q$6 -> Total Deduction | AC3: Original Plan Value | AD3: ='Weekly Progress Report'!$U$3 -> Plan Value | AE3: ='Weekly Progress Report'!$U$4 -> Earn Value | AF3: ='Weekly Progress Report'!$W$3 -> Phys. Plan Value | AG3: ='Weekly Progress Report'!$W$4 -> Phys. Earn Value | AH3: ='Weekly Progress Report'!$Y$3 -> Quality Score | AI3: ='Weekly Progress Report'!$Y$5 -> Safety Score | AJ3: Weekly PV (SAR) | AK3: Weekly EV (SAR) | AL3: Weekly PV % | AM3: Weekly PV % | AN3: Weekly Phys PV% | AO3: Weekly Phys PV% | AP3: Total SD Planned | AQ3: SD Remaining | AR3: SD Pending | AS3: Total SD Submittals | AT3: Planned Materials Approv | AU3: Material Pending Approval | AV3: Materila Total Submittals | AW3: ='Weekly Progress Report'!C86 -> Total Materials | AX3: ='Weekly Progress Report'!D86 -> Total Number of P.O. | AY3: ='Weekly Progress Report'!E86 -> Actual P.O. To Date | AZ3: ='Weekly Progress Report'!F86 -> Remaining P.O | BA3: ='Weekly Progress Report'!G86 -> Material on Site | BB3: ='Weekly Progress Report'!H86 -> Remaining Materials | BC3: ='Weekly Progress Report'!I86 -> Material Delivery Completion (Date) | BD3: ="NCR "&'Weekly Progress Report'!N68 -> NCR Issued | BE3: ="NCR "&'Weekly Progress Report'!O68 -> NCR Closed | BF3: ="NCR "&'Weekly Progress Report'!P68 -> NCR Pending | BG3: ="NCR "&'Weekly Progress Report'!Q68 -> NCR Avg. Closing (Days) | BH3: ="SIR "&'Weekly Progress Report'!N68 -> SIR Issued | BI3: ="SIR "&'Weekly Progress Report'!O68 -> SIR Closed | BJ3: ="SIR "&'Weekly Progress Report'!P68 -> SIR Pending | BK3: ="SIR "&'Weekly Progress Report'!Q68 -> SIR Avg. Closing (Days) | BL3: ="MIR "&'Weekly Progress Report'!N68 -> MIR Issued | BM3: ="MIR "&'Weekly Progress Report'!O68 -> MIR Closed | BN3: ="MIR "&'Weekly Progress Report'!P68 -> MIR Pending | BO3: ="MIR "&'Weekly Progress Report'!Q68 -> MIR Avg. Closing (Days) | BP3: ="FIR "&'Weekly Progress Report'!N68 -> FIR Issued | BQ3: ="FIR "&'Weekly Progress Report'!O68 -> FIR Closed | BR3: ="FIR "&'Weekly Progress Report'!P68 -> FIR Pending | BS3: ="FIR "&'Weekly Progress Report'!Q68 -> FIR Avg. Closing (Days) | BT3: ='Weekly Progress Report'!L76 -> 1 Quality Plan Approval | BU3: ='Weekly Progress Report'!L77 -> 2 Quality Plan Last Up | BV3: ='Weekly Progress Report'!L78 -> 3 Safety Plan Approval | BW3: ='Weekly Progress Report'!L79 -> 4 Safety Plan Last Up | BX3: ='Weekly Progress Report'!L80 -> 5 Construction Plan Approval | BY3: ='Weekly Progress Report'!Q76 -> 6 Baseline Approval | BZ3: ='Weekly Progress Report'!Q77 -> 7 No of Approved Version of Schedule | CA3: ='Weekly Progress Report'!Q78 -> 8 Last Approved Schedule | CB3: ='Weekly Progress Report'!Q79 -> 9 BOQ Approval Date | CC3: ='Weekly Progress Report'!Q80 -> 10 No of Approved Version of BOQ | CD3: ='Weekly Progress Report'!L82 -> Total Submitted Invoices | CE3: ='Weekly Progress Report'!L83 -> PM Approved Invoices | CF3: ='Weekly Progress Report'!L84 -> No of Paid Invoices | CG3: ='Weekly Progress Report'!L85 -> No of Pending Invoices | CH3: ='Weekly Progress Report'!L86 -> Advance Payment % | CI3: ='Weekly Progress Report'!L87 -> Retention % | CJ3: ='Weekly Progress Report'!L88 -> Deduction / Penalties % | CK3: ='Weekly Progress Report'!O82 -> Submitted Invoices (SAR) | CL3: ='Weekly Progress Report'!O83 -> PM Approved Invoices (SAR) | CM3: ='Weekly Progress Report'!O84 -> Paid Invoices (SAR) | CN3: ='Weekly Progress Report'!O85 -> Last Submitted Period | CO3: ='Weekly Progress Report'!O86 -> Advance Payment (SAR) | CP3: ='Weekly Progress Report'!O87 -> Retention (SAR) | CQ3: ='Weekly Progress Report'!O88 -> Deduction / Penalties (SAR) | CR3: Planned Head Count | CS3: Actual Head Count | CT3: Saudi Staff | CU3: Labor Planned | CV3: Labor Actual | CW3: Equipment Planned | CX3: Equipment Actual | CY3: ="This Week "&'Weekly Progress Report'!X70 -> This Week Total Hours Worked | CZ3: ="This Week "&'Weekly Progress Report'!X71 -> This Week Safe Hours Worked | DA3: ="This Week "&'Weekly Progress Report'!X72 -> This Week LTI | DB3: ="This Week "&'Weekly Progress Report'!X73 -> This Week MTC (Healed w/o Disability) | DC3: ="This Week "&'Weekly Progress Report'!X74 -> This Week MTC (Healed w/ Disability) | DD3: ="This Week "&'Weekly Progress Report'!X75 -> This Week Near Miss | DE3: ="This Week "&'Weekly Progress Report'!X76 -> This Week First Aid Cases | DF3: ="This Week "&'Weekly Progress Report'!X77 -> This Week Fatality | DG3: ="This Week "&'Weekly Progress Report'!X78 -> This Week Fire Incident Cases | DH3: ="This Week "&'Weekly Progress Report'!X79 -> This Week Vehicle Incident | DI3: ="This Week "&'Weekly Progress Report'!X80 -> This Week Property Damages | DJ3: ="This Week "&'Weekly Progress Report'!X81 -> This Week Induction Training | DK3: ="This Week "&'Weekly Progress Report'!X82 -> This Week No.of Internal Training | DL3: ="This Week "&'Weekly Progress Report'!X83 -> This Week No.of Internal Audit | DM3: ="This Week "&'Weekly Progress Report'!X84 -> This Week No. of Toolbox Talks | DN3: ="This Week "&'Weekly Progress Report'!X85 -> This Week Safety Awards/Incentives | DO3: ="This Month "&'Weekly Progress Report'!X70 -> This Month Total Hours Worked | DP3: ="This Month "&'Weekly Progress Report'!X71 -> This Month Safe Hours Worked | DQ3: ="This Month "&'Weekly Progress Report'!X72 -> This Month LTI | DR3: ="This Month "&'Weekly Progress Report'!X73 -> This Month MTC (Healed w/o Disability) | DS3: ="This Month "&'Weekly Progress Report'!X74 -> This Month MTC (Healed w/ Disability) | DT3: ="This Month "&'Weekly Progress Report'!X75 -> This Month Near Miss | DU3: ="This Month "&'Weekly Progress Report'!X76 -> This Month First Aid Cases | DV3: ="This Month "&'Weekly Progress Report'!X77 -> This Month Fatality | DW3: ="This Month "&'Weekly Progress Report'!X78 -> This Month Fire Incident Cases | DX3: ="This Month "&'Weekly Progress Report'!X79 -> This Month Vehicle Incident | DY3: ="This Month "&'Weekly Progress Report'!X80 -> This Month Property Damages | DZ3: ="This Month "&'Weekly Progress Report'!X81 -> This Month Induction Training | EA3: ="This Month "&'Weekly Progress Report'!X82 -> This Month No.of Internal Training | EB3: ="This Month "&'Weekly Progress Report'!X83 -> This Month No.of Internal Audit | EC3: ="This Month "&'Weekly Progress Report'!X84 -> This Month No. of Toolbox Talks | ED3: ="This Month "&'Weekly Progress Report'!X85 -> This Month Safety Awards/Incentives | EE3: ="YTD "&'Weekly Progress Report'!X70 -> YTD Total Hours Worked | EF3: ="YTD "&'Weekly Progress Report'!X71 -> YTD Safe Hours Worked | EG3: ="YTD "&'Weekly Progress Report'!X72 -> YTD LTI | EH3: ="YTD "&'Weekly Progress Report'!X73 -> YTD MTC (Healed w/o Disability) | EI3: ="YTD "&'Weekly Progress Report'!X74 -> YTD MTC (Healed w/ Disability) | EJ3: ="YTD "&'Weekly Progress Report'!X75 -> YTD Near Miss | EK3: ="YTD "&'Weekly Progress Report'!X76 -> YTD First Aid Cases | EL3: ="YTD "&'Weekly Progress Report'!X77 -> YTD Fatality | EM3: ="YTD "&'Weekly Progress Report'!X78 -> YTD Fire Incident Cases | EN3: ="YTD "&'Weekly Progress Report'!X79 -> YTD Vehicle Incident | EO3: ="YTD "&'Weekly Progress Report'!X80 -> YTD Property Damages | EP3: ="YTD "&'Weekly Progress Report'!X81 -> YTD Induction Training | EQ3: ="YTD "&'Weekly Progress Report'!X82 -> YTD No.of Internal Training | ER3: ="YTD "&'Weekly Progress Report'!X83 -> YTD No.of Internal Audit | ES3: ="YTD "&'Weekly Progress Report'!X84 -> YTD No. of Toolbox Talks | ET3: ="YTD "&'Weekly Progress Report'!X85 -> YTD Safety Awards/Incentives | EU3: ="Cum "&'Weekly Progress Report'!X70 -> Cum Total Hours Worked | EV3: ="Cum "&'Weekly Progress Report'!X71 -> Cum Safe Hours Worked | EW3: ="Cum "&'Weekly Progress Report'!X72 -> Cum LTI | EX3: ="Cum "&'Weekly Progress Report'!X73 -> Cum MTC (Healed w/o Disability) | EY3: ="Cum "&'Weekly Progress Report'!X74 -> Cum MTC (Healed w/ Disability) | EZ3: ="Cum "&'Weekly Progress Report'!X75 -> Cum Near Miss | FA3: ="Cum "&'Weekly Progress Report'!X76 -> Cum First Aid Cases | FB3: ="Cum "&'Weekly Progress Report'!X77 -> Cum Fatality | FC3: ="Cum "&'Weekly Progress Report'!X78 -> Cum Fire Incident Cases | FD3: ="Cum "&'Weekly Progress Report'!X79 -> Cum Vehicle Incident | FE3: ="Cum "&'Weekly Progress Report'!X80 -> Cum Property Damages | FF3: ="Cum "&'Weekly Progress Report'!X81 -> Cum Induction Training | FG3: ="Cum "&'Weekly Progress Report'!X82 -> Cum No.of Internal Training | FH3: ="Cum "&'Weekly Progress Report'!X83 -> Cum No.of Internal Audit | FI3: ="Cum "&'Weekly Progress Report'!X84 -> Cum No. of Toolbox Talks | FJ3: ="Cum "&'Weekly Progress Report'!X85 -> Cum Safety Awards/Incentives | FK3: ='Weekly Progress Report'!A97 -> Total Act. | FL3: ='Weekly Progress Report'!B97 -> Not Started | FM3: ='Weekly Progress Report'!C97 -> In Progress | FN3: ='Weekly Progress Report'!D97 -> Completed | FO3: Critical Path Act.Last Week | FP3: Critical Path Act.This Week | FQ3: Failed start Last Week | FR3: Failed start This Week | FS3: ='Weekly Progress Report'!B105 -> Planned Start Date | FT3: ='Weekly Progress Report'!D105 -> Planned Finish Date | FU3: ='Weekly Progress Report'!F105 -> Forecast Start Date | FV3: ='Weekly Progress Report'!H105 -> Forecast Finish Date | FW3: ='Weekly Progress Report'!J105 -> Actual Start Date | FX3: ='Weekly Progress Report'!L105 -> Actual Finish Date | FY3: ='Weekly Progress Report'!N105 -> % Completed | FZ3: ='Weekly Progress Report'!O105 -> Open Comments | GA3: ='Weekly Progress Report'!P105 -> Closed Comments
A4: ='Weekly Progress Report'!AG1 -> 11-10-2026 | B4: ='Weekly Progress Report'!B3 -> Completion Of The Infrastructure Development Of The First Phase In The Third Industrial City In Jeddah | C4: ='Weekly Progress Report'!B4 -> JDH3 - 02 - 008 | D4: ='Weekly Progress Report'!B5 -> ALRAWAF CONTRACTING | E4: ='Weekly Progress Report'!B6 -> egis | F4: ='Weekly Progress Report'!E4 -> Construction | G4: ='Weekly Progress Report'!E5 -> Active | H4: ='Weekly Progress Report'!E6 -> Shuaib A.Alshuaibi | I4: ='Weekly Progress Report'!AA3 -> The project includes Completion of works construction of Sewage piping network with manhole Construction.Construction of a Stormwater piping network with catch basins and manholes which will be connected to pond. Construction of Irrigation Network, inculding pipes, valve chambers. Potable water piping network including pipes and valve chambers. 13.8 KV medium voltage cable. Installation of street lighting poles along main roads.Execution of the communication network, including the installation of underground ducts and the extension of communication cables to provide telecom and data services to the site. Completion and preparation of internal and external roads, including asphalt layers and sidewalks. | J4: ='Weekly Progress Report'!H3 -> 45469 | K4: ='Weekly Progress Report'!H4 -> 45495 | L4: ='Weekly Progress Report'!H5 -> 45502 | M4: ='Weekly Progress Report'!H6 -> 46231 | N4: ='Weekly Progress Report'!$J$3 -> 20-12-1445 | O4: ='Weekly Progress Report'!$J$4 -> 16-1-1446 | P4: ='Weekly Progress Report'!$J$5 -> 23-1-1446 | Q4: ='Weekly Progress Report'!$J$6 -> 14-2-1448 | R4: ='Weekly Progress Report'!$L$3 -> 46291 | S4: ='Weekly Progress Report'!$L$4 -> 46291 | T4: ='Weekly Progress Report'!$L$5 -> 46341 | U4: ='Weekly Progress Report'!$O$3 -> 3.1974488e+08 | V4: ='Weekly Progress Report'!$O$4 -> 3.1974488e+08 | W4: ='Weekly Progress Report'!$O$5 -> 3.1974488e+08 | X4: ='Weekly Progress Report'!$O$6 -> 0 | Y4: ='Weekly Progress Report'!$S$3 -> 0 | Z4: ='Weekly Progress Report'!$S$4 -> 0 | AA4: ='Weekly Progress Report'!$S$5 -> 2.5021413e+08 | AB4: ='Weekly Progress Report'!$S$6 -> -25281413 | AC4: ='Weekly Progress Report'!$J$38 -> 1 | AD4: ='Weekly Progress Report'!$V$3 -> 1 | AE4: ='Weekly Progress Report'!$V$4 -> 0.98755924 | AF4: ='Weekly Progress Report'!$X$3 -> 0.99931314 | AG4: ='Weekly Progress Report'!$X$4 -> 0.98911437 | AH4: ='Weekly Progress Report'!$Z$3 -> 0.90551724 | AI4: ='Weekly Progress Report'!$Z$5 -> 0.81818182 | AJ4: ='Weekly Progress Report'!$E$38 -> 0 | AK4: ='Weekly Progress Report'!$F$38 -> 467114.68 | AL4: =AJ4/V4 -> 0 | AM4: =AK4/V4 -> 0.0014608981 | AN4: ='Weekly Progress Report'!S38 -> 0 | AO4: ='Weekly Progress Report'!T38 -> 0.00081173899 | AP4: ='Weekly Progress Report'!C75 -> 2539 | AQ4: ='Weekly Progress Report'!I75 -> 24 | AR4: ='Weekly Progress Report'!J75 -> 14 | AS4: ='Weekly Progress Report'!K75 -> 2518 | AT4: ='Weekly Progress Report'!C84 -> 78 | AU4: ='Weekly Progress Report'!J84 -> 36 | AV4: ='Weekly Progress Report'!K84 -> 78 | AW4: ='Weekly Progress Report'!C93 -> 20 | AX4: ='Weekly Progress Report'!D93 -> 20 | AY4: ='Weekly Progress Report'!E93 -> 12 | AZ4: ='Weekly Progress Report'!F93 -> 8 | BA4: ='Weekly Progress Report'!G93 -> 10 | BB4: ='Weekly Progress Report'!H93 -> 0 | BC4: ='Weekly Progress Report'!I93 -> 0 | BD4: ='Weekly Progress Report'!N71 -> 102 | BE4: ='Weekly Progress Report'!O71 -> 99 | BF4: ='Weekly Progress Report'!P71 -> 3 | BG4: ='Weekly Progress Report'!Q71 -> 7 | BH4: ='Weekly Progress Report'!N72 -> 187 | BI4: ='Weekly Progress Report'!O72 -> 177 | BJ4: ='Weekly Progress Report'!P72 -> 10 | BK4: ='Weekly Progress Report'!Q72 -> 5 | BL4: ='Weekly Progress Report'!N73 -> 357 | BM4: ='Weekly Progress Report'!O73 -> 355 | BN4: ='Weekly Progress Report'!P73 -> 2 | BO4: ='Weekly Progress Report'!Q73 -> 0 | BP4: ='Weekly Progress Report'!N74 -> 30963 | BQ4: ='Weekly Progress Report'!O74 -> 30863 | BR4: ='Weekly Progress Report'!P74 -> 100 | BS4: ='Weekly Progress Report'!Q74 -> 0 | BT4: ='Weekly Progress Report'!O76 -> 45654 | BU4: ='Weekly Progress Report'!O77 -> 45654 | BV4: ='Weekly Progress Report'!O78 -> 45523 | BW4: ='Weekly Progress Report'!O79 -> 45582 | BX4: ='Weekly Progress Report'!O80 -> 45743 | BY4: ='Weekly Progress Report'!U76 -> 45533 | BZ4: ='Weekly Progress Report'!U77 -> 3 | CA4: ='Weekly Progress Report'!U78 -> 45586 | CB4: ='Weekly Progress Report'!U79 -> 45538 | CC4: ='Weekly Progress Report'!U80 -> 1 | CD4: ='Weekly Progress Report'!N82 -> 0 | CE4: ='Weekly Progress Report'!N83 -> 23 | CF4: ='Weekly Progress Report'!N84 -> 0 | CG4: ='Weekly Progress Report'!N85 -> 0 | CH4: ='Weekly Progress Report'!N86 -> 0.1 | CI4: ='Weekly Progress Report'!N87 -> 0 | CJ4: ='Weekly Progress Report'!N88 -> 0.00081314829 | CK4: ='Weekly Progress Report'!R82 -> 2.5021413e+08 | CL4: ='Weekly Progress Report'!R83 -> 2.465379e+08 | CM4: ='Weekly Progress Report'!R84 -> 0 | CN4: ='Weekly Progress Report'!R85 -> 46265 | CO4: ='Weekly Progress Report'!R86 -> 31974488 | CP4: ='Weekly Progress Report'!R87 -> 0 | CQ4: ='Weekly Progress Report'!R88 -> -260000 | CR4: ='Weekly Progress Report'!L92 -> 0 | CS4: ='Weekly Progress Report'!M92 -> 1092 | CT4: ='Weekly Progress Report'!O92 -> 0 | CU4: ='Weekly Progress Report'!P92 -> 0 | CV4: ='Weekly Progress Report'!Q92 -> 92 | CW4: ='Weekly Progress Report'!T102 -> 167 | CX4: ='Weekly Progress Report'!U102 -> 135 | CY4: ='Weekly Progress Report'!Z70 -> 22920 | CZ4: ='Weekly Progress Report'!Z71 -> 22920 | DA4: ='Weekly Progress Report'!Z72 -> 0 | DB4: ='Weekly Progress Report'!Z73 -> 0 | DC4: ='Weekly Progress Report'!Z74 -> 0 | DD4: ='Weekly Progress Report'!Z75 -> 0 | DE4: ='Weekly Progress Report'!Z76 -> 0 | DF4: ='Weekly Progress Report'!Z77 -> 0 | DG4: ='Weekly Progress Report'!Z78 -> 0 | DH4: ='Weekly Progress Report'!Z79 -> 0 | DI4: ='Weekly Progress Report'!Z80 -> 0 | DJ4: ='Weekly Progress Report'!Z81 -> 0 | DK4: ='Weekly Progress Report'!Z82 -> 2 | DL4: ='Weekly Progress Report'!Z83 -> 0 | DM4: ='Weekly Progress Report'!Z84 -> 8 | DN4: ='Weekly Progress Report'!Z85 -> 0 | DO4: ='Weekly Progress Report'!AB70 -> 97050 | DP4: ='Weekly Progress Report'!AB71 -> 97050 | DQ4: ='Weekly Progress Report'!AB72 -> 0 | DR4: ='Weekly Progress Report'!AB73 -> 0 | DS4: ='Weekly Progress Report'!AB74 -> 0 | DT4: ='Weekly Progress Report'!AB75 -> 0 | DU4: ='Weekly Progress Report'!AB76 -> 0 | DV4: ='Weekly Progress Report'!AB77 -> 0 | DW4: ='Weekly Progress Report'!AB78 -> 0 | DX4: ='Weekly Progress Report'!AB79 -> 0 | DY4: ='Weekly Progress Report'!AB80 -> 0 | DZ4: ='Weekly Progress Report'!AB81 -> 0 | EA4: ='Weekly Progress Report'!AB82 -> 7 | EB4: ='Weekly Progress Report'!AB83 -> 0 | EC4: ='Weekly Progress Report'!AB84 -> 34 | ED4: ='Weekly Progress Report'!AB85 -> 0 | EE4: ='Weekly Progress Report'!AC70 -> 1866079 | EF4: ='Weekly Progress Report'!AC71 -> 1866079 | EG4: ='Weekly Progress Report'!AC72 -> 0 | EH4: ='Weekly Progress Report'!AC73 -> 0 | EI4: ='Weekly Progress Report'!AC74 -> 0 | EJ4: ='Weekly Progress Report'!AC75 -> 9 | EK4: ='Weekly Progress Report'!AC76 -> 0 | EL4: ='Weekly Progress Report'!AC77 -> 0 | EM4: ='Weekly Progress Report'!AC78 -> 0 | EN4: ='Weekly Progress Report'!AC79 -> 1 | EO4: ='Weekly Progress Report'!AC80 -> 0 | EP4: ='Weekly Progress Report'!AC81 -> 96 | EQ4: ='Weekly Progress Report'!AC82 -> 145 | ER4: ='Weekly Progress Report'!AC83 -> 0 | ES4: ='Weekly Progress Report'!AC84 -> 3181 | ET4: ='Weekly Progress Report'!AC85 -> 0 | EU4: ='Weekly Progress Report'!AD70 -> 2210362 | EV4: ='Weekly Progress Report'!AD71 -> 2210362 | EW4: ='Weekly Progress Report'!AD72 -> 0 | EX4: ='Weekly Progress Report'!AD73 -> 0 | EY4: ='Weekly Progress Report'!AD74 -> 0 | EZ4: ='Weekly Progress Report'!AD75 -> 11 | FA4: ='Weekly Progress Report'!AD76 -> 0 | FB4: ='Weekly Progress Report'!AD77 -> 0 | FC4: ='Weekly Progress Report'!AD78 -> 0 | FD4: ='Weekly Progress Report'!AD79 -> 1 | FE4: ='Weekly Progress Report'!AD80 -> 0 | FF4: ='Weekly Progress Report'!AD81 -> 223 | FG4: ='Weekly Progress Report'!AD82 -> 178 | FH4: ='Weekly Progress Report'!AD83 -> 0 | FI4: ='Weekly Progress Report'!AD84 -> 3335 | FJ4: ='Weekly Progress Report'!AD85 -> 0 | FK4: ='Weekly Progress Report'!A98 -> 9236 | FL4: ='Weekly Progress Report'!B98 -> 141 | FM4: ='Weekly Progress Report'!C98 -> 75 | FN4: ='Weekly Progress Report'!D98 -> 9020 | FO4: ='Weekly Progress Report'!A102 -> 215 | FP4: ='Weekly Progress Report'!B102 -> 216 | FQ4: ='Weekly Progress Report'!H102 -> 366 | FR4: ='Weekly Progress Report'!I102 -> 324 | FS4: ='Weekly Progress Report'!B110 | FT4: ='Weekly Progress Report'!D110 | FU4: ='Weekly Progress Report'!F110 | FV4: ='Weekly Progress Report'!H110 | FW4: ='Weekly Progress Report'!J110 | FX4: ='Weekly Progress Report'!L110 | FY4: ='Weekly Progress Report'!N110 -> 0 | FZ4: ='Weekly Progress Report'!O110 -> 0 | GA4: ='Weekly Progress Report'!P110 -> 0

Sheet Weekly Progress Report
A1: MODON - Weekly Progress Report - Construction Projects | AF1: Data Date | AG1: ='General Information'!L1 -> 11-10-2026
A2: Contract General Information | G2: Key Dates | M2: Cost Summary (SR) | U2: Performance Summary | AA2: Project Scope
A3: Project Name | B3: ='General Information'!C3 -> Completion Of The Infrastructure Development Of The First Phase In The Third Industrial City In Jeddah | G3: Contract Award | H3: ='General Information'!C12 -> 45469 | I3: Contract Award (Hijri) | J3: ='General Information'!C16 -> 20-12-1445 | K3: Revised Completion | L3: ='General Information'!C20 -> 46291 | M3: Original Contract Value | O3: ='Invoice Log'!F3 -> 3.1974488e+08 | Q3: O&M Value | S3: ='Invoice Log'!J3 -> 0 | T3: EAC | U3: Plan Value | V3: =J38 -> 1 | W3: Phys. Plan Value | X3: =W38 -> 0.99931314 | Y3: Quality Score | Z3: =Quality!AC10 -> 0.90551724 | AA3: =Progress!B1 -> The project includes Completion of works construction of Sewage piping network with manhole Construction.Construction of a Stormwater piping network with catch basins and manholes which will be connected to pond. Construction of Irrigation Network, inculding pipes, valve chambers. Potable water piping network including pipes and valve chambers. 13.8 KV medium voltage cable. Installation of street lighting poles along main roads.Execution of the communication network, including the installation of underground ducts and the extension of communication cables to provide telecom and data services to the site. Completion and preparation of internal and external roads, including asphalt layers and sidewalks.
A4: Project ID | B4: ='General Information'!C4 -> JDH3 - 02 - 008 | D4: Stage | E4: ='General Information'!C7 -> Construction | G4: Contract Sign | H4: ='General Information'!C13 -> 45495 | I4: Contract Sign (Hijri) | J4: ='General Information'!C17 -> 16-1-1446 | K4: Committed Completion | L4: ='General Information'!C21 -> 46291 | M4: Revised Contract Value | O4: ='Invoice Log'!F4 -> 3.1974488e+08 | P4: EAC | Q4: Revised O&M Value | S4: ='Invoice Log'!J4 -> 0 | T4: =+#REF!+#REF!+S4 -> #REF! | U4: Earn Value | V4: =L38 -> 0.98755924 | W4: Phys. Earn Value | X4: =X38 -> 0.98911437 | Z4: =REPT("¢",IF(INT(+Z3*10)>5,5,INT(+Z3*10)))&REPT("£",IF(INT(+Z3*10)>5,0,5-INT(+Z3*10)))&CHAR(10)&REPT("¢",+IF(INT(+Z3*10)>5,-5+INT(+Z3*10),0))&REPT("£",IF(INT(+Z3*10)>5,10-INT(+Z3*10),5)) -> ¢¢¢¢¢ ¢¢¢¢£
A5: Contractor | B5: ='General Information'!C5 -> ALRAWAF CONTRACTING | D5: Status | E5: ='General Information'!C8 -> Active | G5: Site Handover | H5: ='General Information'!C14 -> 45502 | I5: Site Handover (Hijri) | J5: ='General Information'!C18 -> 23-1-1446 | K5: Forecast Completion | L5: ='General Information'!C22 -> 46341 | M5: Estimate At Completion Value | O5: ='Invoice Log'!F5 -> 3.1974488e+08 | P5: =+#REF!+#REF!+O5 -> #REF! | Q5: Submitted Invoices (Gross Value) | S5: ='Invoice Log'!J5 -> 2.5021413e+08 | U5: Variance | V5: =V4-V3 -> -0.012440759 | W5: Variance | X5: =X4-X3 -> -0.010198772 | Y5: Safety Score | Z5: ='HSE-Stat'!J23 -> 0.81818182
A6: Consultant | B6: ='General Information'!C6 -> egis | D6: Modon PM | E6: ='General Information'!C9 -> Shuaib A.Alshuaibi | G6: Original Completion | H6: ='General Information'!C15 -> 46231 | I6: Original Completion (Hijri) | J6: ='General Information'!C19 -> 14-2-1448 | K6: Variance | L6: ='General Information'!C23 -> -50 | M6: Potential Changes | O6: =O4-O5 -> 0 | Q6: Total Deduction | S6: ='Invoice Log'!J6 -> -25281413 | U6: SPI | V6: =V4/V3 -> 0.98755924 | W6: SPI | X6: =X4/X3 -> 0.98979422 | Z6: =REPT("¢",IF(INT(+Z5*10)>5,5,INT(+Z5*10)))&REPT("£",IF(INT(+Z5*10)>5,0,5-INT(+Z5*10)))&CHAR(10)&REPT("¢",+IF(INT(+Z5*10)>5,-5+INT(+Z5*10),0))&REPT("£",IF(INT(+Z5*10)>5,10-INT(+Z5*10),5)) -> ¢¢¢¢¢ ¢¢¢££
A8: Progress Overview
A9: Earned Value Progress (SAR) | O9: Physical Progress (Effort) | AA9: Earned Value Progress (%)
A10: WBS | C10: BOQ Value (SAR) | D10: % Wt. | E10: Weekly (SAR) | G10: To Date (SAR) | O10: Budgeted | P10: % Wt. | Q10: Weekly Physical Progress | U10: To Date Physical Progress
E11: Planned | F11: Earned | G11: Revised Plan | H11: Revised Plan | I11: Earned | J11: =Progress!G6 -> Revised Plan | K11: =Progress!H6 -> Revised Plan | L11: Earned % | M11: Variance | N11: SPI | O11: (Manhours) | Q11: Planned | R11: Earned | S11: Plan % | T11: Earned % | U11: Planned | V11: Earned | W11: Plan % | X11: Earned % | Y11: Variance | Z11: SPI
A12: =Progress!A7 -> JDH3-02-008-Authorities Permits & Approval - AT | C12: =Progress!C7 -> 0 | D12: =Progress!D7 -> 0 | E12: =Progress!E7 -> 0 | F12: =Progress!F7 -> 0 | G12: =Progress!G7 -> 0 | H12: =Progress!H7 -> 0 | I12: =Progress!I7 -> 0 | J12: =IFERROR(IF(ISBLANK(G12),"",G12/C12),0) -> 0 | K12: =IFERROR(IF(ISBLANK(H12),"",H12/C12),0) -> 0 | L12: =IFERROR(IF(ISBLANK(I12),"",I12/C12),0) -> 0 | M12: =IFERROR(L12-K12,"") -> 0 | N12: =IFERROR(L12/J12,"") | O12: =+Progress!K7 -> 0 | P12: =IF(ISBLANK(O12),"",O12/$O$38) -> 0 | Q12: =Progress!M7 -> 0 | R12: =Progress!N7 -> 0 | S12: =IFERROR(IF(ISBLANK(Q12),"",Q12/O12),0) -> 0 | T12: =IFERROR(IF(ISBLANK(R12),"",R12/O12),0) -> 0 | U12: =Progress!O7 -> 0 | V12: =Progress!P7 -> 0 | W12: =IFERROR(IF(ISBLANK(U12),"",U12/O12),0) -> 0 | X12: =IFERROR(IF(ISBLANK(V12),"",V12/O12),0) -> 0 | Y12: =IFERROR(X12-W12,"") -> 0 | Z12: =IFERROR(X12/W12,"")
A13: =Progress!A8 -> JDH3-02-008-Engineering | C13: =Progress!C8 -> 9592346.3 | D13: =Progress!D8 -> 0.03 | E13: =Progress!E8 -> 0 | F13: =Progress!F8 -> 0 | G13: =Progress!G8 -> 9592346.3 | H13: =Progress!H8 -> 9592346.3 | I13: =Progress!I8 -> 9592346.3 | J13: =IFERROR(IF(ISBLANK(G13),"",G13/C13),0) -> 1 | K13: =IFERROR(IF(ISBLANK(H13),"",H13/C13),0) -> 1 | L13: =IFERROR(IF(ISBLANK(I13),"",I13/C13),0) -> 1 | M13: =IFERROR(L13-K13,"") -> 0 | N13: =IFERROR(L13/J13,"") -> 1 | O13: =+Progress!K8 -> 0 | P13: =IF(ISBLANK(O13),"",O13/$O$38) -> 0 | Q13: =Progress!M8 -> 0 | R13: =Progress!N8 -> 0 | S13: =IFERROR(IF(ISBLANK(Q13),"",Q13/O13),0) -> 0 | T13: =IFERROR(IF(ISBLANK(R13),"",R13/O13),0) -> 0 | U13: =Progress!O8 -> 0 | V13: =Progress!P8 -> 0 | W13: =IFERROR(IF(ISBLANK(U13),"",U13/O13),0) -> 0 | X13: =IFERROR(IF(ISBLANK(V13),"",V13/O13),0) -> 0 | Y13: =IFERROR(X13-W13,"") -> 0 | Z13: =IFERROR(X13/W13,"")
A14: =Progress!A9 -> JDH3-02-008-Procurement | C14: =Progress!C9 -> 63948975 | D14: =Progress!D9 -> 0.2 | E14: =Progress!E9 -> 0 | F14: =Progress!F9 -> 0 | G14: =Progress!G9 -> 63948975 | H14: =Progress!H9 -> 63948975 | I14: =Progress!I9 -> 63948975 | J14: =IFERROR(IF(ISBLANK(G14),"",G14/C14),0) -> 1 | K14: =IFERROR(IF(ISBLANK(H14),"",H14/C14),0) -> 1 | L14: =IFERROR(IF(ISBLANK(I14),"",I14/C14),0) -> 1 | M14: =IFERROR(L14-K14,"") -> 0 | N14: =IFERROR(L14/J14,"") -> 1 | O14: =+Progress!K9 -> 0 | P14: =IF(ISBLANK(O14),"",O14/$O$38) -> 0 | Q14: =Progress!M9 -> 0 | R14: =Progress!N9 -> 0 | S14: =IFERROR(IF(ISBLANK(Q14),"",Q14/O14),0) -> 0 | T14: =IFERROR(IF(ISBLANK(R14),"",R14/O14),0) -> 0 | U14: =Progress!O9 -> 0 | V14: =Progress!P9 -> 0 | W14: =IFERROR(IF(ISBLANK(U14),"",U14/O14),0) -> 0 | X14: =IFERROR(IF(ISBLANK(V14),"",V14/O14),0) -> 0 | Y14: =IFERROR(X14-W14,"") -> 0 | Z14: =IFERROR(X14/W14,"")
A15: =Progress!A10 -> JDH3-02-008-Construction | C15: =Progress!C10 -> 2.1422907e+08 | D15: =Progress!D10 -> 0.67 | E15: =Progress!E10 -> 0 | F15: =Progress!F10 -> 245364.71 | G15: =Progress!G10 -> 2.1422907e+08 | H15: =Progress!H10 -> 2.1422907e+08 | I15: =Progress!I10 -> 2.1186851e+08 | J15: =IFERROR(IF(ISBLANK(G15),"",G15/C15),0) -> 1 | K15: =IFERROR(IF(ISBLANK(H15),"",H15/C15),0) -> 1 | L15: =IFERROR(IF(ISBLANK(I15),"",I15/C15),0) -> 0.98898117 | M15: =IFERROR(L15-K15,"") -> -0.011018835 | N15: =IFERROR(L15/J15,"") -> 0.98898117 | O15: =+Progress!K10 -> 48045 | P15: =IF(ISBLANK(O15),"",O15/$O$38) -> 1 | Q15: =Progress!M10 -> 0 | R15: =Progress!N10 -> 39 | S15: =IFERROR(IF(ISBLANK(Q15),"",Q15/O15),0) -> 0 | T15: =IFERROR(IF(ISBLANK(R15),"",R15/O15),0) -> 0.00081173899 | U15: =Progress!O10 -> 48012 | V15: =Progress!P10 -> 47522 | W15: =IFERROR(IF(ISBLANK(U15),"",U15/O15),0) -> 0.99931314 | X15: =IFERROR(IF(ISBLANK(V15),"",V15/O15),0) -> 0.98911437 | Y15: =IFERROR(X15-W15,"") -> -0.010198772 | Z15: =IFERROR(X15/W15,"") -> 0.98979422
A16: =Progress!A11 -> Pond and Swales - PS | C16: =Progress!C11 -> 27026698 | D16: =Progress!D11 -> 0.084525819 | E16: =Progress!E11 -> 0 | F16: =Progress!F11 -> 0 | G16: =Progress!G11 -> 27026698 | H16: =Progress!H11 -> 27026698 | I16: =Progress!I11 -> 27026698 | J16: =IFERROR(IF(ISBLANK(G16),"",G16/C16),0) -> 1 | K16: =IFERROR(IF(ISBLANK(H16),"",H16/C16),0) -> 1 | L16: =IFERROR(IF(ISBLANK(I16),"",I16/C16),0) -> 1 | M16: =IFERROR(L16-K16,"") -> 0 | N16: =IFERROR(L16/J16,"") -> 1 | O16: =+Progress!K11 -> 3720 | P16: =IF(ISBLANK(O16),"",O16/$O$38) -> 0.077427412 | Q16: =Progress!M11 -> 0 | R16: =Progress!N11 -> 0 | S16: =IFERROR(IF(ISBLANK(Q16),"",Q16/O16),0) -> 0 | T16: =IFERROR(IF(ISBLANK(R16),"",R16/O16),0) -> 0 | U16: =Progress!O11 -> 3720 | V16: =Progress!P11 -> 3720 | W16: =IFERROR(IF(ISBLANK(U16),"",U16/O16),0) -> 1 | X16: =IFERROR(IF(ISBLANK(V16),"",V16/O16),0) -> 1 | Y16: =IFERROR(X16-W16,"") -> 0 | Z16: =IFERROR(X16/W16,"") -> 1
A17: =Progress!A12 -> High Mast | C17: =Progress!C12 -> 2003227.7 | D17: =Progress!D12 -> 0.0062650814 | E17: =Progress!E12 -> 0 | F17: =Progress!F12 -> 0 | G17: =Progress!G12 -> 2003227.7 | H17: =Progress!H12 -> 2003227.7 | I17: =Progress!I12 -> 2003227.7 | J17: =IFERROR(IF(ISBLANK(G17),"",G17/C17),0) -> 1 | K17: =IFERROR(IF(ISBLANK(H17),"",H17/C17),0) -> 1 | L17: =IFERROR(IF(ISBLANK(I17),"",I17/C17),0) -> 1 | M17: =IFERROR(L17-K17,"") -> 0 | N17: =IFERROR(L17/J17,"") -> 1 | O17: =+Progress!K12 -> 1222 | P17: =IF(ISBLANK(O17),"",O17/$O$38) -> 0.025434489 | Q17: =Progress!M12 -> 0 | R17: =Progress!N12 -> 0 | S17: =IFERROR(IF(ISBLANK(Q17),"",Q17/O17),0) -> 0 | T17: =IFERROR(IF(ISBLANK(R17),"",R17/O17),0) -> 0 | U17: =Progress!O12 -> 1222 | V17: =Progress!P12 -> 1222 | W17: =IFERROR(IF(ISBLANK(U17),"",U17/O17),0) -> 1 | X17: =IFERROR(IF(ISBLANK(V17),"",V17/O17),0) -> 1 | Y17: =IFERROR(X17-W17,"") -> 0 | Z17: =IFERROR(X17/W17,"") -> 1
A18: =Progress!A13 -> ELDREES | C18: =Progress!C13 -> 353857.85 | D18: =Progress!D13 -> 0.0011066881 | E18: =Progress!E13 -> 0 | F18: =Progress!F13 -> 0 | G18: =Progress!G13 -> 353857.85 | H18: =Progress!H13 -> 353857.85 | I18: =Progress!I13 -> 353857.85 | J18: =IFERROR(IF(ISBLANK(G18),"",G18/C18),0) -> 1 | K18: =IFERROR(IF(ISBLANK(H18),"",H18/C18),0) -> 1 | L18: =IFERROR(IF(ISBLANK(I18),"",I18/C18),0) -> 1 | M18: =IFERROR(L18-K18,"") -> 0 | N18: =IFERROR(L18/J18,"") -> 1 | O18: =+Progress!K13 -> 125 | P18: =IF(ISBLANK(O18),"",O18/$O$38) -> 0.0026017275 | Q18: =Progress!M13 -> 0 | R18: =Progress!N13 -> 0 | S18: =IFERROR(IF(ISBLANK(Q18),"",Q18/O18),0) -> 0 | T18: =IFERROR(IF(ISBLANK(R18),"",R18/O18),0) -> 0 | U18: =Progress!O13 -> 125 | V18: =Progress!P13 -> 125 | W18: =IFERROR(IF(ISBLANK(U18),"",U18/O18),0) -> 1 | X18: =IFERROR(IF(ISBLANK(V18),"",V18/O18),0) -> 1 | Y18: =IFERROR(X18-W18,"") -> 0 | Z18: =IFERROR(X18/W18,"") -> 1
A19: =Progress!A14 -> MR | C19: =Progress!C14 -> 73833427 | D19: =Progress!D14 -> 0.23091356 | E19: =Progress!E14 -> 0 | F19: =Progress!F14 -> 0 | G19: =Progress!G14 -> 73833427 | H19: =Progress!H14 -> 73833427 | I19: =Progress!I14 -> 73419907 | J19: =IFERROR(IF(ISBLANK(G19),"",G19/C19),0) -> 1 | K19: =IFERROR(IF(ISBLANK(H19),"",H19/C19),0) -> 1 | L19: =IFERROR(IF(ISBLANK(I19),"",I19/C19),0) -> 0.99439928 | M19: =IFERROR(L19-K19,"") -> -0.0056007251 | N19: =IFERROR(L19/J19,"") -> 0.99439927 | O19: =+Progress!K14 -> 17520 | P19: =IF(ISBLANK(O19),"",O19/$O$38) -> 0.36465813 | Q19: =Progress!M14 -> 0 | R19: =Progress!N14 -> 0 | S19: =IFERROR(IF(ISBLANK(Q19),"",Q19/O19),0) -> 0 | T19: =IFERROR(IF(ISBLANK(R19),"",R19/O19),0) -> 0 | U19: =Progress!O14 -> 17507 | V19: =Progress!P14 -> 17409 | W19: =IFERROR(IF(ISBLANK(U19),"",U19/O19),0) -> 0.99925799 | X19: =IFERROR(IF(ISBLANK(V19),"",V19/O19),0) -> 0.99366438 | Y19: =IFERROR(X19-W19,"") -> -0.0055936073 | Z19: =IFERROR(X19/W19,"") -> 0.99440224
A20: =Progress!A15 -> Z01 | C20: =Progress!C15 -> 12724319 | D20: =Progress!D15 -> 0.039795223 | E20: =Progress!E15 -> 0 | F20: =Progress!F15 -> 0 | G20: =Progress!G15 -> 12724319 | H20: =Progress!H15 -> 12724319 | I20: =Progress!I15 -> 12724319 | J20: =IFERROR(IF(ISBLANK(G20),"",G20/C20),0) -> 1 | K20: =IFERROR(IF(ISBLANK(H20),"",H20/C20),0) -> 1 | L20: =IFERROR(IF(ISBLANK(I20),"",I20/C20),0) -> 1 | M20: =IFERROR(L20-K20,"") -> 0 | N20: =IFERROR(L20/J20,"") -> 1 | O20: =+Progress!K15 -> 2771 | P20: =IF(ISBLANK(O20),"",O20/$O$38) -> 0.057675096 | Q20: =Progress!M15 -> 0 | R20: =Progress!N15 -> 0 | S20: =IFERROR(IF(ISBLANK(Q20),"",Q20/O20),0) -> 0 | T20: =IFERROR(IF(ISBLANK(R20),"",R20/O20),0) -> 0 | U20: =Progress!O15 -> 2770 | V20: =Progress!P15 -> 2771 | W20: =IFERROR(IF(ISBLANK(U20),"",U20/O20),0) -> 0.99963912 | X20: =IFERROR(IF(ISBLANK(V20),"",V20/O20),0) -> 1 | Y20: =IFERROR(X20-W20,"") -> 0.00036088055 | Z20: =IFERROR(X20/W20,"") -> 1.000361
A21: =Progress!A16 -> Z02 | C21: =Progress!C16 -> 1453405.8 | D21: =Progress!D16 -> 0.0045455172 | E21: =Progress!E16 -> 0 | F21: =Progress!F16 -> 74152.78 | G21: =Progress!G16 -> 1453405.8 | H21: =Progress!H16 -> 1453405.8 | I21: =Progress!I16 -> 1268023.9 | J21: =IFERROR(IF(ISBLANK(G21),"",G21/C21),0) -> 1 | K21: =IFERROR(IF(ISBLANK(H21),"",H21/C21),0) -> 1 | L21: =IFERROR(IF(ISBLANK(I21),"",I21/C21),0) -> 0.87244997 | M21: =IFERROR(L21-K21,"") -> -0.12755003 | N21: =IFERROR(L21/J21,"") -> 0.87244997 | O21: =+Progress!K16 -> 484 | P21: =IF(ISBLANK(O21),"",O21/$O$38) -> 0.010073889 | Q21: =Progress!M16 -> 0 | R21: =Progress!N16 -> 11 | S21: =IFERROR(IF(ISBLANK(Q21),"",Q21/O21),0) -> 0 | T21: =IFERROR(IF(ISBLANK(R21),"",R21/O21),0) -> 0.022727273 | U21: =Progress!O16 -> 484 | V21: =Progress!P16 -> 457 | W21: =IFERROR(IF(ISBLANK(U21),"",U21/O21),0) -> 1 | X21: =IFERROR(IF(ISBLANK(V21),"",V21/O21),0) -> 0.94421488 | Y21: =IFERROR(X21-W21,"") -> -0.055785124 | Z21: =IFERROR(X21/W21,"") -> 0.94421488
A22: =Progress!A17 -> Z02-1 | C22: =Progress!C17 -> 10584846 | D22: =Progress!D17 -> 0.033104036 | E22: 319 | F22: =Progress!F17 -> 0 | G22: =Progress!G17 -> 10584846 | H22: =Progress!H17 -> 10584846 | I22: =Progress!I17 -> 10584846 | J22: =IFERROR(IF(ISBLANK(G22),"",G22/C22),0) -> 1 | K22: =IFERROR(IF(ISBLANK(H22),"",H22/C22),0) -> 1 | L22: =IFERROR(IF(ISBLANK(I22),"",I22/C22),0) -> 1 | M22: =IFERROR(L22-K22,"") -> 0 | N22: =IFERROR(L22/J22,"") -> 1 | O22: =+Progress!K17 -> 2709 | P22: =IF(ISBLANK(O22),"",O22/$O$38) -> 0.056384639 | Q22: =Progress!M17 -> 0 | R22: =Progress!N17 -> 0 | S22: =IFERROR(IF(ISBLANK(Q22),"",Q22/O22),0) -> 0 | T22: =IFERROR(IF(ISBLANK(R22),"",R22/O22),0) -> 0 | U22: =Progress!O17 -> 2693 | V22: =Progress!P17 -> 2709 | W22: =IFERROR(IF(ISBLANK(U22),"",U22/O22),0) -> 0.99409376 | X22: =IFERROR(IF(ISBLANK(V22),"",V22/O22),0) -> 1 | Y22: =IFERROR(X22-W22,"") -> 0.0059062385 | Z22: =IFERROR(X22/W22,"") -> 1.0059413
A23: =Progress!A18 -> Z02-2 | C23: =Progress!C18 -> 11951477 | D23: =Progress!D18 -> 0.037378164 | E23: =Progress!E18 -> 0 | F23: =Progress!F18 -> 0 | G23: =Progress!G18 -> 11951477 | H23: =Progress!H18 -> 11951477 | I23: =Progress!I18 -> 11951477 | J23: =IFERROR(IF(ISBLANK(G23),"",G23/C23),0) -> 1 | K23: =IFERROR(IF(ISBLANK(H23),"",H23/C23),0) -> 1 | L23: =IFERROR(IF(ISBLANK(I23),"",I23/C23),0) -> 1 | M23: =IFERROR(L23-K23,"") -> 0 | N23: =IFERROR(L23/J23,"") -> 1 | O23: =+Progress!K18 -> 3089 | P23: =IF(ISBLANK(O23),"",O23/$O$38) -> 0.064293891 | Q23: =Progress!M18 -> 0 | R23: =Progress!N18 -> 0 | S23: =IFERROR(IF(ISBLANK(Q23),"",Q23/O23),0) -> 0 | T23: =IFERROR(IF(ISBLANK(R23),"",R23/O23),0) -> 0 | U23: =Progress!O18 -> 3089 | V23: =Progress!P18 -> 3089 | W23: =IFERROR(IF(ISBLANK(U23),"",U23/O23),0) -> 1 | X23: =IFERROR(IF(ISBLANK(V23),"",V23/O23),0) -> 1 | Y23: =IFERROR(X23-W23,"") -> 0 | Z23: =IFERROR(X23/W23,"") -> 1
A24: =Progress!A19 -> Z03 | C24: =Progress!C19 -> 709820.88 | D24: =Progress!D19 -> 0.0022199601 | E24: =Progress!E19 -> 0 | F24: =Progress!F19 -> 0 | G24: =Progress!G19 -> 709820.88 | H24: =Progress!H19 -> 709820.88 | I24: =Progress!I19 -> 709820.88 | J24: =IFERROR(IF(ISBLANK(G24),"",G24/C24),0) -> 1 | K24: =IFERROR(IF(ISBLANK(H24),"",H24/C24),0) -> 1 | L24: =IFERROR(IF(ISBLANK(I24),"",I24/C24),0) -> 1 | M24: =IFERROR(L24-K24,"") -> 0 | N24: =IFERROR(L24/J24,"") -> 1 | O24: =+Progress!K19 -> 378 | P24: =IF(ISBLANK(O24),"",O24/$O$38) -> 0.0078676241 | Q24: =Progress!M19 -> 0 | R24: =Progress!N19 -> 0 | S24: =IFERROR(IF(ISBLANK(Q24),"",Q24/O24),0) -> 0 | T24: =IFERROR(IF(ISBLANK(R24),"",R24/O24),0) -> 0 | U24: =Progress!O19 -> 378 | V24: =Progress!P19 -> 378 | W24: =IFERROR(IF(ISBLANK(U24),"",U24/O24),0) -> 1 | X24: =IFERROR(IF(ISBLANK(V24),"",V24/O24),0) -> 1 | Y24: =IFERROR(X24-W24,"") -> 0 | Z24: =IFERROR(X24/W24,"") -> 1
A25: =Progress!A20 -> Z04 | C25: =Progress!C20 -> 791520.69 | D25: =Progress!D20 -> 0.0024754758 | E25: =Progress!E20 -> 0 | F25: =Progress!F20 -> 0 | G25: =Progress!G20 -> 791520.69 | H25: =Progress!H20 -> 791520.69 | I25: =Progress!I20 -> 582653.1 | J25: =IFERROR(IF(ISBLANK(G25),"",G25/C25),0) -> 1 | K25: =IFERROR(IF(ISBLANK(H25),"",H25/C25),0) -> 1 | L25: =IFERROR(IF(ISBLANK(I25),"",I25/C25),0) -> 0.7361186 | M25: =IFERROR(L25-K25,"") -> -0.2638814 | N25: =IFERROR(L25/J25,"") -> 0.7361186 | O25: =+Progress!K20 -> 337 | P25: =IF(ISBLANK(O25),"",O25/$O$38) -> 0.0070142575 | Q25: =Progress!M20 -> 0 | R25: =Progress!N20 -> 0 | S25: =IFERROR(IF(ISBLANK(Q25),"",Q25/O25),0) -> 0 | T25: =IFERROR(IF(ISBLANK(R25),"",R25/O25),0) -> 0 | U25: =Progress!O20 -> 337 | V25: =Progress!P20 -> 310 | W25: =IFERROR(IF(ISBLANK(U25),"",U25/O25),0) -> 1 | X25: =IFERROR(IF(ISBLANK(V25),"",V25/O25),0) -> 0.91988131 | Y25: =IFERROR(X25-W25,"") -> -0.080118694 | Z25: =IFERROR(X25/W25,"") -> 0.91988131
A26: =Progress!A21 -> Z05 | C26: =Progress!C21 -> 6381167 | D26: =Progress!D21 -> 0.019957058 | E26: =Progress!E21 -> 0 | F26: =Progress!F21 -> 102028.39 | G26: =Progress!G21 -> 6381167 | H26: =Progress!H21 -> 6381167 | I26: =Progress!I21 -> 5519896.3 | J26: =IFERROR(IF(ISBLANK(G26),"",G26/C26),0) -> 1 | K26: =IFERROR(IF(ISBLANK(H26),"",H26/C26),0) -> 1 | L26: =IFERROR(IF(ISBLANK(I26),"",I26/C26),0) -> 0.86502927 | M26: =IFERROR(L26-K26,"") -> -0.13497073 | N26: =IFERROR(L26/J26,"") -> 0.86502927 | O26: =+Progress!K21 -> 3703 | P26: =IF(ISBLANK(O26),"",O26/$O$38) -> 0.077073577 | Q26: =Progress!M21 -> 0 | R26: =Progress!N21 -> 13 | S26: =IFERROR(IF(ISBLANK(Q26),"",Q26/O26),0) -> 0 | T26: =IFERROR(IF(ISBLANK(R26),"",R26/O26),0) -> 0.003510667 | U26: =Progress!O21 -> 3703 | V26: =Progress!P21 -> 3458 | W26: =IFERROR(IF(ISBLANK(U26),"",U26/O26),0) -> 1 | X26: =IFERROR(IF(ISBLANK(V26),"",V26/O26),0) -> 0.93383743 | Y26: =IFERROR(X26-W26,"") -> -0.066162571 | Z26: =IFERROR(X26/W26,"") -> 0.93383743
A27: =Progress!A22 -> Z06 | B27: =B32/2 -> 1988934.4 | C27: =Progress!C22 -> 15215702 | D27: =Progress!D22 -> 0.047587008 | E27: =Progress!E22 -> 0 | F27: =Progress!F22 -> 43378.29 | G27: =Progress!G22 -> 15215702 | H27: =Progress!H22 -> 15215702 | I27: =Progress!I22 -> 15151456 | J27: =IFERROR(IF(ISBLANK(G27),"",G27/C27),0) -> 1 | K27: =IFERROR(IF(ISBLANK(H27),"",H27/C27),0) -> 1 | L27: =IFERROR(IF(ISBLANK(I27),"",I27/C27),0) -> 0.99577766 | M27: =IFERROR(L27-K27,"") -> -0.0042223402 | N27: =IFERROR(L27/J27,"") -> 0.99577766 | O27: =+Progress!K22 -> 3016 | P27: =IF(ISBLANK(O27),"",O27/$O$38) -> 0.062774482 | Q27: =Progress!M22 -> 0 | R27: =Progress!N22 -> 8 | S27: =IFERROR(IF(ISBLANK(Q27),"",Q27/O27),0) -> 0 | T27: =IFERROR(IF(ISBLANK(R27),"",R27/O27),0) -> 0.0026525199 | U27: =Progress!O22 -> 3016 | V27: =Progress!P22 -> 3004 | W27: =IFERROR(IF(ISBLANK(U27),"",U27/O27),0) -> 1 | X27: =IFERROR(IF(ISBLANK(V27),"",V27/O27),0) -> 0.99602122 | Y27: =IFERROR(X27-W27,"") -> -0.0039787798 | Z27: =IFERROR(X27/W27,"") -> 0.99602122
A28: =Progress!A23 -> Z07 | C28: =Progress!C23 -> 14082635 | D28: =Progress!D23 -> 0.044043347 | E28: =Progress!E23 -> 0 | F28: =Progress!F23 -> 0 | G28: =Progress!G23 -> 14082635 | H28: =Progress!H23 -> 14082635 | I28: =Progress!I23 -> 14082635 | J28: =IFERROR(IF(ISBLANK(G28),"",G28/C28),0) -> 1 | K28: =IFERROR(IF(ISBLANK(H28),"",H28/C28),0) -> 1 | L28: =IFERROR(IF(ISBLANK(I28),"",I28/C28),0) -> 1 | M28: =IFERROR(L28-K28,"") -> 0 | N28: =IFERROR(L28/J28,"") -> 1 | O28: =+Progress!K23 -> 2682 | P28: =IF(ISBLANK(O28),"",O28/$O$38) -> 0.055822666 | Q28: =Progress!M23 -> 0 | R28: =Progress!N23 -> 0 | S28: =IFERROR(IF(ISBLANK(Q28),"",Q28/O28),0) -> 0 | T28: =IFERROR(IF(ISBLANK(R28),"",R28/O28),0) -> 0 | U28: =Progress!O23 -> 2682 | V28: =Progress!P23 -> 2682 | W28: =IFERROR(IF(ISBLANK(U28),"",U28/O28),0) -> 1 | X28: =IFERROR(IF(ISBLANK(V28),"",V28/O28),0) -> 1 | Y28: =IFERROR(X28-W28,"") -> 0 | Z28: =IFERROR(X28/W28,"") -> 1
A29: =Progress!A24 -> Z07-1 | C29: =Progress!C24 -> 9569376.8 | D29: =Progress!D24 -> 0.029928163 | E29: =Progress!E24 -> 0 | F29: =Progress!F24 -> 0 | G29: =Progress!G24 -> 9569376.8 | H29: =Progress!H24 -> 9569376.8 | I29: =Progress!I24 -> 9569376.8 | J29: =IFERROR(IF(ISBLANK(G29),"",G29/C29),0) -> 1 | K29: =IFERROR(IF(ISBLANK(H29),"",H29/C29),0) -> 1 | L29: =IFERROR(IF(ISBLANK(I29),"",I29/C29),0) -> 1 | M29: =IFERROR(L29-K29,"") -> 0 | N29: =IFERROR(L29/J29,"") -> 1 | O29: =+Progress!K24 -> 2065 | P29: =IF(ISBLANK(O29),"",O29/$O$38) -> 0.042980539 | Q29: =Progress!M24 -> 0 | R29: =Progress!N24 -> 0 | S29: =IFERROR(IF(ISBLANK(Q29),"",Q29/O29),0) -> 0 | T29: =IFERROR(IF(ISBLANK(R29),"",R29/O29),0) -> 0 | U29: =Progress!O24 -> 2065 | V29: =Progress!P24 -> 2065 | W29: =IFERROR(IF(ISBLANK(U29),"",U29/O29),0) -> 1 | X29: =IFERROR(IF(ISBLANK(V29),"",V29/O29),0) -> 1 | Y29: =IFERROR(X29-W29,"") -> 0 | Z29: =IFERROR(X29/W29,"") -> 1
A30: =Progress!A25 -> Z08 | C30: =Progress!C25 -> 1069834.5 | D30: =Progress!D25 -> 0.0033459005 | E30: =Progress!E25 -> 0 | F30: =Progress!F25 -> 0 | G30: =Progress!G25 -> 1069834.5 | H30: =Progress!H25 -> 1069834.5 | I30: =Progress!I25 -> 744135.82 | J30: =IFERROR(IF(ISBLANK(G30),"",G30/C30),0) -> 1 | K30: =IFERROR(IF(ISBLANK(H30),"",H30/C30),0) -> 1 | L30: =IFERROR(IF(ISBLANK(I30),"",I30/C30),0) -> 0.6955616 | M30: =IFERROR(L30-K30,"") -> -0.3044384 | N30: =IFERROR(L30/J30,"") -> 0.6955616 | O30: =+Progress!K25 -> 339 | P30: =IF(ISBLANK(O30),"",O30/$O$38) -> 0.0070558851 | Q30: =Progress!M25 -> 0 | R30: =Progress!N25 -> 0 | S30: =IFERROR(IF(ISBLANK(Q30),"",Q30/O30),0) -> 0 | T30: =IFERROR(IF(ISBLANK(R30),"",R30/O30),0) -> 0 | U30: =Progress!O25 -> 339 | V30: =Progress!P25 -> 296 | W30: =IFERROR(IF(ISBLANK(U30),"",U30/O30),0) -> 1 | X30: =IFERROR(IF(ISBLANK(V30),"",V30/O30),0) -> 0.87315634 | Y30: =IFERROR(X30-W30,"") -> -0.12684366 | Z30: =IFERROR(X30/W30,"") -> 0.87315634
A31: =Progress!A26 -> Z09 | C31: =Progress!C26 -> 5049850.4 | D31: =Progress!D26 -> 0.015793374 | E31: =Progress!E26 -> 0 | F31: =Progress!F26 -> 16732.15 | G31: =Progress!G26 -> 5049850.4 | H31: =Progress!H26 -> 5049850.4 | I31: =Progress!I26 -> 4963978.2 | J31: =IFERROR(IF(ISBLANK(G31),"",G31/C31),0) -> 1 | K31: =IFERROR(IF(ISBLANK(H31),"",H31/C31),0) -> 1 | L31: =IFERROR(IF(ISBLANK(I31),"",I31/C31),0) -> 0.98299509 | M31: =IFERROR(L31-K31,"") -> -0.017004912 | N31: =IFERROR(L31/J31,"") -> 0.98299509 | O31: =+Progress!K26 -> 886 | P31: =IF(ISBLANK(O31),"",O31/$O$38) -> 0.018441045 | Q31: =Progress!M26 -> 0 | R31: =Progress!N26 -> 3 | S31: =IFERROR(IF(ISBLANK(Q31),"",Q31/O31),0) -> 0 | T31: =IFERROR(IF(ISBLANK(R31),"",R31/O31),0) -> 0.0033860045 | U31: =Progress!O26 -> 884 | V31: =Progress!P26 -> 872 | W31: =IFERROR(IF(ISBLANK(U31),"",U31/O31),0) -> 0.99774266 | X31: =IFERROR(IF(ISBLANK(V31),"",V31/O31),0) -> 0.98419865 | Y31: =IFERROR(X31-W31,"") -> -0.013544018 | Z31: =IFERROR(X31/W31,"") -> 0.98642534
A32: =Progress!A27 -> Z10 | B32: =C38-I38 -> 3977868.9 | C32: =Progress!C27 -> 8833596.8 | D32: =Progress!D27 -> 0.027627016 | E32: =Progress!E27 -> 0 | F32: =Progress!F27 -> 0 | G32: =Progress!G27 -> 8833596.8 | H32: =Progress!H27 -> 8833596.8 | I32: =Progress!I27 -> 8666952.3 | J32: =IFERROR(IF(ISBLANK(G32),"",G32/C32),0) -> 1 | K32: =IFERROR(IF(ISBLANK(H32),"",H32/C32),0) -> 1 | L32: =IFERROR(IF(ISBLANK(I32),"",I32/C32),0) -> 0.98113514 | M32: =IFERROR(L32-K32,"") -> -0.018864863 | N32: =IFERROR(L32/J32,"") -> 0.98113514 | O32: =+Progress!K27 -> 1532 | P32: =IF(ISBLANK(O32),"",O32/$O$38) -> 0.031886773 | Q32: =Progress!M27 -> 0 | R32: =Progress!N27 -> 0 | S32: =IFERROR(IF(ISBLANK(Q32),"",Q32/O32),0) -> 0 | T32: =IFERROR(IF(ISBLANK(R32),"",R32/O32),0) -> 0 | U32: =Progress!O27 -> 1532 | V32: =Progress!P27 -> 1511 | W32: =IFERROR(IF(ISBLANK(U32),"",U32/O32),0) -> 1 | X32: =IFERROR(IF(ISBLANK(V32),"",V32/O32),0) -> 0.98629243 | Y32: =IFERROR(X32-W32,"") -> -0.013707572 | Z32: =IFERROR(X32/W32,"") -> 0.98629243
A33: =Progress!A28 -> Z11 | C33: =Progress!C28 -> 201779.17 | D33: =Progress!D28 -> 0.00063106303 | E33: =Progress!E28 -> 0 | F33: =Progress!F28 -> 0 | G33: =Progress!G28 -> 201779.17 | H33: =Progress!H28 -> 201779.17 | I33: =Progress!I28 -> 192096.05 | J33: =IFERROR(IF(ISBLANK(G33),"",G33/C33),0) -> 1 | K33: =IFERROR(IF(ISBLANK(H33),"",H33/C33),0) -> 1 | L33: =IFERROR(IF(ISBLANK(I33),"",I33/C33),0) -> 0.9520113 | M33: =IFERROR(L33-K33,"") -> -0.0479887 | N33: =IFERROR(L33/J33,"") -> 0.9520113 | O33: =+Progress!K28 -> 314 | P33: =IF(ISBLANK(O33),"",O33/$O$38) -> 0.0065355396 | Q33: =Progress!M28 -> 0 | R33: =Progress!N28 -> 0 | S33: =IFERROR(IF(ISBLANK(Q33),"",Q33/O33),0) -> 0 | T33: =IFERROR(IF(ISBLANK(R33),"",R33/O33),0) -> 0 | U33: =Progress!O28 -> 314 | V33: =Progress!P28 -> 313 | W33: =IFERROR(IF(ISBLANK(U33),"",U33/O33),0) -> 1 | X33: =IFERROR(IF(ISBLANK(V33),"",V33/O33),0) -> 0.99681529 | Y33: =IFERROR(X33-W33,"") -> -0.0031847134 | Z33: =IFERROR(X33/W33,"") -> 0.99681529
A34: =Progress!A29 -> Z13 | C34: =Progress!C29 -> 5395935.5 | D34: =Progress!D29 -> 0.016875753 | E34: =Progress!E29 -> 0 | F34: =Progress!F29 -> 0 | G34: =Progress!G29 -> 5395935.5 | H34: =Progress!H29 -> 5395935.5 | I34: =Progress!I29 -> 5395935.5 | J34: =IFERROR(IF(ISBLANK(G34),"",G34/C34),0) -> 1 | K34: =IFERROR(IF(ISBLANK(H34),"",H34/C34),0) -> 1 | L34: =IFERROR(IF(ISBLANK(I34),"",I34/C34),0) -> 1 | M34: =IFERROR(L34-K34,"") -> 0 | N34: =IFERROR(L34/J34,"") -> 1 | O34: =+Progress!K29 -> 526 | P34: =IF(ISBLANK(O34),"",O34/$O$38) -> 0.01094807 | Q34: =Progress!M29 -> 0 | R34: =Progress!N29 -> 0 | S34: =IFERROR(IF(ISBLANK(Q34),"",Q34/O34),0) -> 0 | T34: =IFERROR(IF(ISBLANK(R34),"",R34/O34),0) -> 0 | U34: =Progress!O29 -> 526 | V34: =Progress!P29 -> 526 | W34: =IFERROR(IF(ISBLANK(U34),"",U34/O34),0) -> 1 | X34: =IFERROR(IF(ISBLANK(V34),"",V34/O34),0) -> 1 | Y34: =IFERROR(X34-W34,"") -> 0 | Z34: =IFERROR(X34/W34,"") -> 1
A35: =Progress!A30 -> CCTV | C35: =Progress!C30 -> 5075749.7 | D35: =Progress!D30 -> 0.015874374 | E35: =Progress!E30 -> 0 | F35: =Progress!F30 -> 0 | G35: =Progress!G30 -> 5075749.7 | H35: =Progress!H30 -> 5075749.7 | I35: =Progress!I30 -> 5075749.7 | J35: =IFERROR(IF(ISBLANK(G35),"",G35/C35),0) -> 1 | K35: =IFERROR(IF(ISBLANK(H35),"",H35/C35),0) -> 1 | L35: =IFERROR(IF(ISBLANK(I35),"",I35/C35),0) -> 1 | M35: =IFERROR(L35-K35,"") -> 0 | N35: =IFERROR(L35/J35,"") -> 1 | O35: =+Progress!K30 -> 9 | P35: =IF(ISBLANK(O35),"",O35/$O$38) -> 0.00018732438 | Q35: =Progress!M30 -> 0 | R35: =Progress!N30 -> 0 | S35: =IFERROR(IF(ISBLANK(Q35),"",Q35/O35),0) -> 0 | T35: =IFERROR(IF(ISBLANK(R35),"",R35/O35),0) -> 0 | U35: =Progress!O30 -> 9 | V35: =Progress!P30 -> 9 | W35: =IFERROR(IF(ISBLANK(U35),"",U35/O35),0) -> 1 | X35: =IFERROR(IF(ISBLANK(V35),"",V35/O35),0) -> 1 | Y35: =IFERROR(X35-W35,"") -> 0 | Z35: =IFERROR(X35/W35,"") -> 1
A36: =Progress!A31 -> New Scope | C36: =Progress!C31 -> 1920841.2 | D36: =Progress!D31 -> 0.0060074181 | E36: =Progress!E31 -> 0 | F36: =Progress!F31 -> 9073.11 | G36: =Progress!G31 -> 1920841.2 | H36: =Progress!H31 -> 1920841.2 | I36: =Progress!I31 -> 1881472.1 | J36: =IFERROR(IF(ISBLANK(G36),"",G36/C36),0) -> 1 | K36: =IFERROR(IF(ISBLANK(H36),"",H36/C36),0) -> 1 | L36: =IFERROR(IF(ISBLANK(I36),"",I36/C36),0) -> 0.97950423 | M36: =IFERROR(L36-K36,"") -> -0.020495766 | N36: =IFERROR(L36/J36,"") -> 0.97950423 | O36: =+Progress!K31 -> 617 | P36: =IF(ISBLANK(O36),"",O36/$O$38) -> 0.012842127 | Q36: =Progress!M31 -> 0 | R36: =Progress!N31 -> 3 | S36: =IFERROR(IF(ISBLANK(Q36),"",Q36/O36),0) -> 0 | T36: =IFERROR(IF(ISBLANK(R36),"",R36/O36),0) -> 0.0048622366 | U36: =Progress!O31 -> 617 | V36: =Progress!P31 -> 595 | W36: =IFERROR(IF(ISBLANK(U36),"",U36/O36),0) -> 1 | X36: =IFERROR(IF(ISBLANK(V36),"",V36/O36),0) -> 0.9643436 | Y36: =IFERROR(X36-W36,"") -> -0.035656402 | Z36: =IFERROR(X36/W36,"") -> 0.9643436
A37: =Progress!A32 -> JDH3-02-008-Close Out | C37: =Progress!C32 -> 31974488 | D37: =Progress!D32 -> 0.1 | E37: =Progress!E32 -> 0 | F37: =Progress!F32 -> 221749.97 | G37: =Progress!G32 -> 31974488 | H37: =Progress!H32 -> 31974488 | I37: =Progress!I32 -> 30357173 | J37: =IFERROR(IF(ISBLANK(G37),"",G37/C37),0) -> 1 | K37: =IFERROR(IF(ISBLANK(H37),"",H37/C37),0) -> 1 | L37: =IFERROR(IF(ISBLANK(I37),"",I37/C37),0) -> 0.9494186 | M37: =IFERROR(L37-K37,"") -> -0.050581395 | N37: =IFERROR(L37/J37,"") -> 0.9494186 | O37: =+Progress!K32 -> 0 | P37: =IF(ISBLANK(O37),"",O37/$O$38) -> 0 | Q37: =Progress!M32 -> 0 | R37: =Progress!N32 -> 0 | S37: =IFERROR(IF(ISBLANK(Q37),"",Q37/O37),0) -> 0 | T37: =IFERROR(IF(ISBLANK(R37),"",R37/O37),0) -> 0 | U37: =Progress!O32 -> 0 | V37: =Progress!P32 -> 0 | W37: =IFERROR(IF(ISBLANK(U37),"",U37/O37),0) -> 0 | X37: =IFERROR(IF(ISBLANK(V37),"",V37/O37),0) -> 0 | Y37: =IFERROR(X37-W37,"") -> 0 | Z37: =IFERROR(X37/W37,"")
B38: Total | C38: =C12+C13+C14+C15+C37 -> 3.1974488e+08 | D38: =D12+D13+D14+D15+D37 -> 1 | E38: =E12+E13+E14+E15+E37 -> 0 | F38: =F12+F13+F14+F15+F37 -> 467114.68 | G38: =G12+G13+G14+G15+G37 -> 3.1974488e+08 | H38: =H12+H13+H14+H15+H37 -> 3.1974488e+08 | I38: =I12+I13+I14+I15+I37 -> 3.1576701e+08 | J38: =G38/C38 -> 1 | K38: =H38/C38 -> 1 | L38: =I38/C38 -> 0.98755924 | M38: =+L38-J38 -> -0.012440759 | N38: =IFERROR(L38/J38,"") -> 0.98755924 | O38: =O12+O13+O14+O15+O37 -> 48045 | P38: =P12+P13+P14+P15+P37 -> 1 | Q38: =Q12+Q13+Q14+Q15+Q37 -> 0 | R38: =R12+R13+R14+R15+R37 -> 39 | S38: =IFERROR(IF(ISBLANK(Q38),"",Q38/O38),0) -> 0 | T38: =IFERROR(IF(ISBLANK(R38),"",R38/O38),0) -> 0.00081173899 | U38: =U12+U13+U14+U15+U37 -> 48012 | V38: =V12+V13+V14+V15+V37 -> 47522 | W38: =IFERROR(IF(ISBLANK(U38),"",U38/O38),0) -> 0.99931314 | X38: =IFERROR(IF(ISBLANK(V38),"",V38/O38),0) -> 0.98911437 | Y38: =+X38-W38 -> -0.010198772 | Z38: =X38/W38 -> 0.98979422
AA39: Construction Milestones
AA40: Item No. | AB40: Milestones | AD40: Original (Baseline) | AE40: Latest Plan | AF40: Forecast | AG40: Status | AH40: Days Change
AA41: =+Milestones!A4 -> 1 | AB41: =+Milestones!B4 -> Award Date | AD41: =+Milestones!C4 -> 45469 | AE41: =+Milestones!D4 -> 45469 | AF41: =+Milestones!E4 -> 45469 | AG41: =+Milestones!F4 -> A | AH41: =+Milestones!G4 -> 0
...

Sheet General Information
A1: Weekly Progress Report - Construction Projects | K1: Data Date | L1: {=_xlfn.TEXTBEFORE(_xlfn.TEXTAFTER(_xlfn.TEXTBEFORE(_xlfn.TEXTAFTER(CELL("filename",A1),"["),"]"),"Report "),".")} -> 11-10-2026
A2: Contract General Information
A3: Project Name | C3: Completion Of The Infrastructure Development Of The First Phase In The Third Industrial City In Jeddah | L3: {=_xlfn.TEXTBEFORE(_xlfn.TEXTAFTER(_xlfn.TEXTBEFORE(_xlfn.TEXTAFTER(CELL("filename",A1),"["),"]"),"Report "),".xlsx")} -> 11-10-2026
A4: Project ID | C4: JDH3 - 02 - 008
A5: Contractor | C5: ALRAWAF CONTRACTING | P5: =+L1-C14+1 -> 805 | Q5: =+C15-C14+1+60 -> 790
A6: Consultant | C6: egis
A7: Stage | C7: Construction | P7: =+P5/790 -> 1.0189873
A8: Status | C8: Active
A9: Modon PM | C9: Shuaib A.Alshuaibi
A11: Key Dates
A12: Contract Award Date | C12: =Milestones!E4 -> 45469 | M12: تاريخ تسليم الموقع | R12: تاريخ تسليم الموقع
A13: Contract Sign Date | C13: =Milestones!E5 -> 45495 | M13: إجمالي قيمة المصروف | R13: إجمالي قيمة المصروف
A14: Site Handover Date | C14: =Milestones!E6 -> 45502 | M14: شامل ضريبة القيمة المضافة | R14: شامل ضريبة القيمة المضافة
A15: Original Completion | C15: =Milestones!C13 -> 46231 | M15: الحاجة لأوامر تغيير | R15: الحاجة لأوامر تغيير
A16: Contract Award Date (Hijri) | C16: 20-12-1445 | M16: مدة المشروع المستهدفة | R16: مدة المشروع المستهدفة
A17: Contract Sign Date (Hijri) | C17: 16-1-1446 | M17: تاريخ نهاية المشروع المستهدفة | R17: تاريخ نهاية المشروع المستهدفة
A18: Site Handover Date (Hijri) | C18: 23-1-1446 | M18: نسبة المدة المنقضية المستهدفة | R18: نسبة المدة المنقضية المستهدفة
A19: Original Completion (Hijri) | C19: 14-2-1448 | M19: نسبة إنجاز المشروع الفعلية | R19: نسبة إنجاز المشروع الفعلية
A20: Revised Completion Date | C20: =C15+60 -> 46291 | M20: النسبة المستهدفة للربع القادم | R20: النسبة المستهدفة للربع القادم
A21: Committed Completion Date | C21: =C20 -> 46291
A22: Forecast Completion | C22: 46341 | O22: =Q22/1.15 -> 3.1974488e+08 | Q22: 3.6770661e+08
A23: Variance | C23: =C20-C22 -> -50 | Q23: =+Q22*0.85 -> 3.1255062e+08 | S23: 3.1974488e+08 | T23: =+S23*0.15 -> 47961731
Q24: 997065.03 | S24: =+T23+S23 -> 3.6770661e+08
A25: Key Project Submittals | C25: Submission Date | D25: Days taken to approve orginal plan from site handover date
A26: Quality Plan submission | C26: 45524 | D26: =C26-C14 -> 22
A27: Quality Plan approval | C27: 45654
A28: Quality Plan Last Update | C28: 45654
A30: Safety Plan submission | C30: 45509 | D30: =C30-C14 -> 7
A31: Safety Plan approval | C31: 45523
A32: Safety Plan Last Update | C32: 45582
A34: Risk Management Plan submission | C34: 45524 | D34: =C34-C14 -> 22
A35: Risk Management Plan approval | C35: 45538
A36: Risk Management Plan Last Update | C36: 45585
A38: Baseline Schedule submission | C38: 45521 | D38: =C38-C14 -> 19
A39: Baseline Schedule approval | C39: 45533
A40: No of Schedule Versions | C40: 3
A41: Last Revised Schedule Approval Date | C41: 45586
A43: BOQ submission | C43: 45524 | D43: =C43-C14 -> 22
A44: BOQ approval | C44: 45538
A45: No of Approved Version of BOQ | C45: 1
...

Sheet Progress
A1: Project Scope Statement | B1: The project includes Completion of works construction of Sewage piping network with manhole Construction.Construction of a Stormwater piping network with catch basins and manholes which will be connected to pond. Construction of Irrigation Network, inculding pipes, valve chambers. Potable water piping network including pipes and valve chambers. 13.8 KV medium voltage cable. Installation of street lighting poles along main roads.Execution of the communication network, including the installation of underground ducts and the extension of communication cables to provide telecom and data services to the site. Completion and preparation of internal and external roads, including asphalt layers and sidewalks.
AA3: Activity ID | AB3: Activity Name | AC3: Budgeted Total Cost | AD3: Earned Value Cost | AE3: Actual Labor Units | AF3: Budgeted Labor Units | AG3: Planned Value Labor Units | AH3: Planned Value Cost | AI3: Performance % Complete | AJ3: Schedule % Complete | AK3: Total Float | AL3: Start | AM3: Finish | AN3: BL Project Start | AO3: BL Project Finish
A4: Earned Value Progress (SAR) | K4: Physical Progress (Effort) | AA4: Completion of the Infrastructure development of the 1st phase in the 3rd industrial city in Jeddah | AC4: 3.1974488e+08 | AD4: 3.1529989e+08 | AE4: 47483 | AF4: 48045 | AG4: 48012 | AH4: 3.1974488e+08 | AI4: 0.9861 | AJ4: 1 | AK4: -59 | AL4: 29-Jul-24 A | AM4: 46350 | AN4: 45502 | AO4: 46291
A5: WBS | C5: BOQ Value (SAR) | D5: % Wt. | E5: Weekly (SAR) | H5: To Date (SAR) | K5: Budgeted | L5: % Wt. | M5: Weekly Physical Progress | O5: To Date Physical Progress | AA5: JDH3-02-008-Milestones - MI | AC5: 0 | AD5: 0 | AE5: 0 | AF5: 0 | AG5: 0 | AH5: 0 | AI5: 0 | AJ5: 0 | AK5: -59 | AL5: 29-Jul-24 A | AM5: 46350 | AN5: 45502 | AO5: 46291
E6: Planned | F6: Earned | G6: Revised Plan | H6: Revised Plan | I6: Earned | K6: (Manhours) | M6: Planned | N6: Earned | O6: Planned | P6: Earned | T6: 0 | U6: =Progress!AG7 -> 0 | V6: 0 | W6: =Progress!AE7 -> 0 | Y6: Planned Value Cost | Z6: Earned Value Cost | AA6: JDH3-02-008-Mobilization - Mob | AC6: 0 | AD6: 0 | AE6: 0 | AF6: 0 | AG6: 0 | AH6: 0 | AI6: 0 | AJ6: 0 | AL6: 29-Jul-24 A | AM6: 01-Feb-25 A | AN6: 45502 | AO6: 45689
A7: =Progress!W44 -> JDH3-02-008-Authorities Permits & Approval - AT | C7: =Progress!Y44 -> 0 | D7: =C7/$C$33 -> 0 | E7: =Progress!Y7 -> 0 | F7: =Progress!Z7 -> 0 | G7: =Progress!AD44 -> 0 | H7: =G7 -> 0 | I7: =Progress!Z44 -> 0 | K7: =Progress!AB44 -> 0 | L7: =K7/$K$33 -> 0 | M7: =Progress!T7 -> 0 | N7: =Progress!V7 -> 0 | O7: =Progress!AC44 -> 0 | P7: =Progress!AA44 -> 0 | R7: JDH3-02-008-Authorities Permits & Approval - AT | T7: =+O7-U7 -> 0 | U7: =Progress!AG8 -> 0 | V7: =+AA44-W7 -> 0 | W7: =Progress!AE8 -> 0 | Y7: =+AD44-AH7 -> 0 | Z7: =Z44-AD7 -> 0 | AA7: JDH3-02-008-Authorities Permits & Approval - AT | AC7: 0 | AD7: 0 | AE7: 0 | AF7: 0 | AG7: 0 | AH7: 0 | AI7: 0 | AJ7: 0 | AL7: 21-Oct-24 A | AM7: 19-Sep-26 A | AN7: 45586 | AO7: 46279
