Workbook
Name _____________ccr1: {#N/A,#N/A,TRUE,"Cover";#N/A,#N/A,TRUE,"Conts";#N/A,#N/A,TRUE,"VOS";#N/A,#N/A,TRUE,"Warrington";#N/A,#N/A,TRUE,"Widnes"}
Name _____________ccr1: {#N/A,#N/A,TRUE,"Cover";#N/A,#N/A,TRUE,"Conts";#N/A,#N/A,TRUE,"VOS";#N/A,#N/A,TRUE,"Warrington";#N/A,#N/A,TRUE,"Widnes"}
Name ___________ccr1: {#N/A,#N/A,TRUE,"Cover";#N/A,#N/A,TRUE,"Conts";#N/A,#N/A,TRUE,"VOS";#N/A,#N/A,TRUE,"Warrington";#N/A,#N/A,TRUE,"Widnes"}
Name ___________ccr1: {#N/A,#N/A,TRUE,"Cover";#N/A,#N/A,TRUE,"Conts";#N/A,#N/A,TRUE,"VOS";#N/A,#N/A,TRUE,"Warrington";#N/A,#N/A,TRUE,"Widnes"}
Name __________ccr1: {#N/A,#N/A,TRUE,"Cover";#N/A,#N/A,TRUE,"Conts";#N/A,#N/A,TRUE,"VOS";#N/A,#N/A,TRUE,"Warrington";#N/A,#N/A,TRUE,"Widnes"}
Name __________ccr1: {#N/A,#N/A,TRUE,"Cover";#N/A,#N/A,TRUE,"Conts";#N/A,#N/A,TRUE,"VOS";#N/A,#N/A,TRUE,"Warrington";#N/A,#N/A,TRUE,"Widnes"}
Name _________ccr1: {#N/A,#N/A,TRUE,"Cover";#N/A,#N/A,TRUE,"Conts";#N/A,#N/A,TRUE,"VOS";#N/A,#N/A,TRUE,"Warrington";#N/A,#N/A,TRUE,"Widnes"}
Name _________ccr1: {#N/A,#N/A,TRUE,"Cover";#N/A,#N/A,TRUE,"Conts";#N/A,#N/A,TRUE,"VOS";#N/A,#N/A,TRUE,"Warrington";#N/A,#N/A,TRUE,"Widnes"}
Name ________ccr1: {#N/A,#N/A,TRUE,"Cover";#N/A,#N/A,TRUE,"Conts";#N/A,#N/A,TRUE,"VOS";#N/A,#N/A,TRUE,"Warrington";#N/A,#N/A,TRUE,"Widnes"}
Name ________ccr1: {#N/A,#N/A,TRUE,"Cover";#N/A,#N/A,TRUE,"Conts";#N/A,#N/A,TRUE,"VOS";#N/A,#N/A,TRUE,"Warrington";#N/A,#N/A,TRUE,"Widnes"}
Name _______ccr1: {#N/A,#N/A,TRUE,"Cover";#N/A,#N/A,TRUE,"Conts";#N/A,#N/A,TRUE,"VOS";#N/A,#N/A,TRUE,"Warrington";#N/A,#N/A,TRUE,"Widnes"}
Name _______ccr1: {#N/A,#N/A,TRUE,"Cover";#N/A,#N/A,TRUE,"Conts";#N/A,#N/A,TRUE,"VOS";#N/A,#N/A,TRUE,"Warrington";#N/A,#N/A,TRUE,"Widnes"}
Name ______ccr1: {#N/A,#N/A,TRUE,"Cover";#N/A,#N/A,TRUE,"Conts";#N/A,#N/A,TRUE,"VOS";#N/A,#N/A,TRUE,"Warrington";#N/A,#N/A,TRUE,"Widnes"}
Name ______ccr1: {#N/A,#N/A,TRUE,"Cover";#N/A,#N/A,TRUE,"Conts";#N/A,#N/A,TRUE,"VOS";#N/A,#N/A,TRUE,"Warrington";#N/A,#N/A,TRUE,"Widnes"}
Name _____ccr1: {#N/A,#N/A,TRUE,"Cover";#N/A,#N/A,TRUE,"Conts";#N/A,#N/A,TRUE,"VOS";#N/A,#N/A,TRUE,"Warrington";#N/A,#N/A,TRUE,"Widnes"}
Name _____ccr1: {#N/A,#N/A,TRUE,"Cover";#N/A,#N/A,TRUE,"Conts";#N/A,#N/A,TRUE,"VOS";#N/A,#N/A,TRUE,"Warrington";#N/A,#N/A,TRUE,"Widnes"}
Name ____ccr1: {#N/A,#N/A,TRUE,"Cover";#N/A,#N/A,TRUE,"Conts";#N/A,#N/A,TRUE,"VOS";#N/A,#N/A,TRUE,"Warrington";#N/A,#N/A,TRUE,"Widnes"}
Name ____ccr1: {#N/A,#N/A,TRUE,"Cover";#N/A,#N/A,TRUE,"Conts";#N/A,#N/A,TRUE,"VOS";#N/A,#N/A,TRUE,"Warrington";#N/A,#N/A,TRUE,"Widnes"}
Name ____ccr2: {#N/A,#N/A,TRUE,"Cover";#N/A,#N/A,TRUE,"Conts";#N/A,#N/A,TRUE,"VOS";#N/A,#N/A,TRUE,"Warrington";#N/A,#N/A,TRUE,"Widnes"}
Name ____ccr2: {#N/A,#N/A,TRUE,"Cover";#N/A,#N/A,TRUE,"Conts";#N/A,#N/A,TRUE,"VOS";#N/A,#N/A,TRUE,"Warrington";#N/A,#N/A,TRUE,"Widnes"}
Name ___ccr1: {#N/A,#N/A,TRUE,"Cover";#N/A,#N/A,TRUE,"Conts";#N/A,#N/A,TRUE,"VOS";#N/A,#N/A,TRUE,"Warrington";#N/A,#N/A,TRUE,"Widnes"}
Name ___ccr1: {#N/A,#N/A,TRUE,"Cover";#N/A,#N/A,TRUE,"Conts";#N/A,#N/A,TRUE,"VOS";#N/A,#N/A,TRUE,"Warrington";#N/A,#N/A,TRUE,"Widnes"}
Name ___ccr2: {#N/A,#N/A,TRUE,"Cover";#N/A,#N/A,TRUE,"Conts";#N/A,#N/A,TRUE,"VOS";#N/A,#N/A,TRUE,"Warrington";#N/A,#N/A,TRUE,"Widnes"}
Name ___ccr2: {#N/A,#N/A,TRUE,"Cover";#N/A,#N/A,TRUE,"Conts";#N/A,#N/A,TRUE,"VOS";#N/A,#N/A,TRUE,"Warrington";#N/A,#N/A,TRUE,"Widnes"}
Name __ccr1: {#N/A,#N/A,TRUE,"Cover";#N/A,#N/A,TRUE,"Conts";#N/A,#N/A,TRUE,"VOS";#N/A,#N/A,TRUE,"Warrington";#N/A,#N/A,TRUE,"Widnes"}
Name __ccr1: {#N/A,#N/A,TRUE,"Cover";#N/A,#N/A,TRUE,"Conts";#N/A,#N/A,TRUE,"VOS";#N/A,#N/A,TRUE,"Warrington";#N/A,#N/A,TRUE,"Widnes"}
Name _1B.05.M.010.0010: #REF!
Name _1B.05.M.010.0010: #REF!
Name _1B.05.M.010.0010: #REF!
Name _1B.05.M.010.0010: #REF!
Name _1B.05.M.010.0050: #REF!
Name _1B.05.M.010.0050: #REF!
Name _1B.05.M.010.0050: #REF!
Name _1B.05.M.010.0050: #REF!
Name _1B.05.M.010.0050: #REF!
Name _1B.05.M.010.0050: #REF!
Name _1B.05.M.0100.0010: #REF!
Name _1B.05.M.0100.0010: #REF!
Name _1B.05.M.0100.0010: #REF!
Name _1B.05.M.0100.0010: #REF!
Name _1B.05.M.0100.0010: #REF!
Name _1B.05.M.020.0010: #REF!
Name _1B.05.M.020.0010: #REF!
Name _1B.05.M.020.0010: #REF!
Name _1B.05.M.020.0010: #REF!
Name _1B.05.M.020.0010: #REF!
Name _1B.05.M.020.0020: #REF!
Name _1B.05.M.020.0020: #REF!
Name _1B.05.M.020.0020: #REF!
Name _1B.05.M.020.0020: #REF!
Name _1B.05.M.020.0020: #REF!
Name _1B.05.M.020.0030: #REF!
Name _1B.05.M.020.0030: #REF!
Name _1B.05.M.020.0030: #REF!
Name _1B.05.M.020.0030: #REF!
Name _1B.05.M.020.0030: #REF!
Name _1B.05.M.020.0040: #REF!
Name _1B.05.M.020.0040: #REF!
Name _1B.05.M.020.0040: #REF!
Name _1B.05.M.020.0040: #REF!

Sheet DB
A1: ='Weekly Progress Report'!$A$1 -> MODON - Weekly Progress Report - Construction Projects
B2: ='Weekly Progress Report'!$A$2 -> Contract General Information | J2: ='Weekly Progress Report'!G2 -> Key Dates | U2: ='Weekly Progress Report'!$M$2 -> Cost Summary (SR) | AD2: ='Weekly Progress Report'!$U$2 -> Performance Summary | AP2: ='Weekly Progress Report'!A67 -> Shop Drawings | AT2: ='Weekly Progress Report'!A77 -> Material Approval | AW2: ='Weekly Progress Report'!A86 -> Procurement Summary | BD2: ='Weekly Progress Report'!L67 -> Quality Reports | BT2: ='Weekly Progress Report'!L75 -> Key Submittals Approval Status | CD2: ='Weekly Progress Report'!L81 -> Invoices Summary | CR2: ='Weekly Progress Report'!L89 -> Resources at Site | CY2: ='Weekly Progress Report'!W67 -> Safety Statistics | FK2: ='Weekly Progress Report'!A95 -> Primavera P6 Schedule Status | FS2: ='Weekly Progress Report'!A104 -> Testing And Commissioning
A3: ='Weekly Progress Report'!AF1 -> Data Date | B3: ='Weekly Progress Report'!A3 -> Project Name | C3: ='Weekly Progress Report'!A4 -> Project ID | D3: ='Weekly Progress Report'!A5 -> Contractor | E3: ='Weekly Progress Report'!A6 -> Consultant | F3: ='Weekly Progress Report'!D4 -> Stage | G3: ='Weekly Progress Report'!D5 -> Status | H3: ='Weekly Progress Report'!D6 -> Modon PM | I3: ='Weekly Progress Report'!AA2 -> Project Scope | J3: ='Weekly Progress Report'!G3 -> Contract Award | K3: ='Weekly Progress Report'!G4 -> Contract Sign | L3: ='Weekly Progress Report'!G5 -> Site Handover | M3: ='Weekly Progress Report'!G6 -> Original Completion | N3: ='Weekly Progress Report'!$I$3 -> Contract Award (Hijri) | O3: ='Weekly Progress Report'!$I$4 -> Contract Sign (Hijri) | P3: ='Weekly Progress Report'!$I$5 -> Site Handover (Hijri) | Q3: ='Weekly Progress Report'!$I$6 -> Original Completion (Hijri) | R3: ='Weekly Progress Report'!$K$3 -> Revised Completion | S3: ='Weekly Progress Report'!$K$4 -> Committed Completion | T3: ='Weekly Progress Report'!$K$5 -> Forecast Completion | U3: ='Weekly Progress Report'!$M$3 -> Original Contract Value | V3: ='Weekly Progress Report'!$M$4 -> Revised Contract Value | W3: ='Weekly Progress Report'!$M$5 -> Estimate At Completion Value | X3: ='Weekly Progress Report'!$M$6 -> Potential Changes | Y3: ='Weekly Progress Report'!$Q$3 -> O&M Value | Z3: ='Weekly Progress Report'!$Q$4 -> Revised O&M Value | AA3: ='Weekly Progress Report'!$Q$5 -> Submitted Invoices (Gross Value) | AB3: ='Weekly Progress Report'!$Q$6 -> Total Deduction | AC3: Original Plan Value | AD3: ='Weekly Progress Report'!$U$3 -> Plan Value | AE3: ='Weekly Progress Report'!$U$4 -> Earn Value | AF3: ='Weekly Progress Report'!$W$3 -> Phys. Plan Value | AG3: ='Weekly Progress Report'!$W$4 -> Phys. Earn Value | AH3: ='Weekly Progress Report'!$Y$3 -> Quality Score | AI3: ='Weekly Progress Report'!$Y$5 -> Safety Score | AJ3: Weekly PV (SAR) | AK3: Weekly EV (SAR) | AL3: Weekly PV % | AM3: Weekly PV % | AN3: Weekly Phys PV% | AO3: Weekly Phys PV% | AP3: Total SD Planned | AQ3: SD Remaining | AR3: SD Pending | AS3: Total SD Submittals | AT3: Planned Materials Approv | AU3: Material Pending Approval | AV3: Materila Total Submittals | AW3: ='Weekly Progress Report'!C87 -> Total Materials Planned | AX3: ='Weekly Progress Report'!D87 -> Total Number of P.O. | AY3: ='Weekly Progress Report'!E87 -> Actual P.O. To Date | AZ3: ='Weekly Progress Report'!F87 -> Remaining P.O | BA3: ='Weekly Progress Report'!G87 -> Actual Material on Site | BB3: ='Weekly Progress Report'!H87 -> Remaining Materials | BC3: ='Weekly Progress Report'!I87 -> Material Delivery Completion (Date) | BD3: ="NCR "&'Weekly Progress Report'!N68 -> NCR Issued | BE3: ="NCR "&'Weekly Progress Report'!O68 -> NCR Closed | BF3: ="NCR "&'Weekly Progress Report'!P68 -> NCR Pending | BG3: ="NCR "&'Weekly Progress Report'!Q68 -> NCR Avg. Closing (Days) | BH3: ="SIR "&'Weekly Progress Report'!N68 -> SIR Issued | BI3: ="SIR "&'Weekly Progress Report'!O68 -> SIR Closed | BJ3: ="SIR "&'Weekly Progress Report'!P68 -> SIR Pending | BK3: ="SIR "&'Weekly Progress Report'!Q68 -> SIR Avg. Closing (Days) | BL3: ="MIR "&'Weekly Progress Report'!N68 -> MIR Issued | BM3: ="MIR "&'Weekly Progress Report'!O68 -> MIR Closed | BN3: ="MIR "&'Weekly Progress Report'!P68 -> MIR Pending | BO3: ="MIR "&'Weekly Progress Report'!Q68 -> MIR Avg. Closing (Days) | BP3: ="FIR "&'Weekly Progress Report'!N68 -> FIR Issued | BQ3: ="FIR "&'Weekly Progress Report'!O68 -> FIR Closed | BR3: ="FIR "&'Weekly Progress Report'!P68 -> FIR Pending | BS3: ="FIR "&'Weekly Progress Report'!Q68 -> FIR Avg. Closing (Days) | BT3: ='Weekly Progress Report'!L76 -> 1 Quality Plan Approval | BU3: ='Weekly Progress Report'!L77 -> 2 Quality Plan Last Up | BV3: ='Weekly Progress Report'!L78 -> 3 Safety Plan Approval | BW3: ='Weekly Progress Report'!L79 -> 4 Safety Plan Last Up | BX3: ='Weekly Progress Report'!L80 -> 5 Construction Plan Approval | BY3: ='Weekly Progress Report'!Q76 -> 6 Baseline Approval | BZ3: ='Weekly Progress Report'!Q77 -> 7 No of Approved Version of Schedule | CA3: ='Weekly Progress Report'!Q78 -> 8 Last Approved Schedule | CB3: ='Weekly Progress Report'!Q79 -> 9 BOQ Approval Date | CC3: ='Weekly Progress Report'!Q80 -> 10 No of Approved Version of BOQ | CD3: ='Weekly Progress Report'!L82 -> Total Submitted Invoices | CE3: ='Weekly Progress Report'!L83 -> PM Approved Invoices | CF3: ='Weekly Progress Report'!L84 -> No of Paid Invoices | CG3: ='Weekly Progress Report'!L85 -> No of Pending Invoices | CH3: ='Weekly Progress Report'!L86 -> Advance Payment % | CI3: ='Weekly Progress Report'!L87 -> Retention % | CJ3: ='Weekly Progress Report'!L88 -> Deduction / Penalties % | CK3: ='Weekly Progress Report'!O82 -> Submitted Invoices (SAR) | CL3: ='Weekly Progress Report'!O83 -> PM Approved Invoices (SAR) | CM3: ='Weekly Progress Report'!O84 -> Paid Invoices (SAR) | CN3: ='Weekly Progress Report'!O85 -> Last Submitted Period | CO3: ='Weekly Progress Report'!O86 -> Advance Payment (SAR) | CP3: ='Weekly Progress Report'!O87 -> Retention (SAR) | CQ3: ='Weekly Progress Report'!O88 -> Deduction / Penalties (SAR) | CR3: Planned Head Count | CS3: Actual Head Count | CT3: Saudi Staff | CU3: Labor Planned | CV3: Labor Actual | CW3: Equipment Planned | CX3: Equipment Actual | CY3: ="This Week "&'Weekly Progress Report'!X70 -> This Week Total Hours Worked | CZ3: ="This Week "&'Weekly Progress Report'!X71 -> This Week Safe Hours Worked | DA3: ="This Week "&'Weekly Progress Report'!X72 -> This Week LTI | DB3: ="This Week "&'Weekly Progress Report'!X73 -> This Week MTC (Healed w/o Disability) | DC3: ="This Week "&'Weekly Progress Report'!X74 -> This Week MTC (Healed w/ Disability) | DD3: ="This Week "&'Weekly Progress Report'!X75 -> This Week Near Miss | DE3: ="This Week "&'Weekly Progress Report'!X76 -> This Week First Aid Cases | DF3: ="This Week "&'Weekly Progress Report'!X77 -> This Week Fatality | DG3: ="This Week "&'Weekly Progress Report'!X78 -> This Week Fire Incident Cases | DH3: ="This Week "&'Weekly Progress Report'!X79 -> This Week Vehicle Incident | DI3: ="This Week "&'Weekly Progress Report'!X80 -> This Week Property Damages | DJ3: ="This Week "&'Weekly Progress Report'!X81 -> This Week Induction Training | DK3: ="This Week "&'Weekly Progress Report'!X82 -> This Week No.of Internal Training | DL3: ="This Week "&'Weekly Progress Report'!X83 -> This Week No.of Internal Audit | DM3: ="This Week "&'Weekly Progress Report'!X84 -> This Week No. of Toolbox Talks | DN3: ="This Week "&'Weekly Progress Report'!X85 -> This Week Safety Awards/Incentives | DO3: ="This Month "&'Weekly Progress Report'!X70 -> This Month Total Hours Worked | DP3: ="This Month "&'Weekly Progress Report'!X71 -> This Month Safe Hours Worked | DQ3: ="This Month "&'Weekly Progress Report'!X72 -> This Month LTI | DR3: ="This Month "&'Weekly Progress Report'!X73 -> This Month MTC (Healed w/o Disability) | DS3: ="This Month "&'Weekly Progress Report'!X74 -> This Month MTC (Healed w/ Disability) | DT3: ="This Month "&'Weekly Progress Report'!X75 -> This Month Near Miss | DU3: ="This Month "&'Weekly Progress Report'!X76 -> This Month First Aid Cases | DV3: ="This Month "&'Weekly Progress Report'!X77 -> This Month Fatality | DW3: ="This Month "&'Weekly Progress Report'!X78 -> This Month Fire Incident Cases | DX3: ="This Month "&'Weekly Progress Report'!X79 -> This Month Vehicle Incident | DY3: ="This Month "&'Weekly Progress Report'!X80 -> This Month Property Damages | DZ3: ="This Month "&'Weekly Progress Report'!X81 -> This Month Induction Training | EA3: ="This Month "&'Weekly Progress Report'!X82 -> This Month No.of Internal Training | EB3: ="This Month "&'Weekly Progress Report'!X83 -> This Month No.of Internal Audit | EC3: ="This Month "&'Weekly Progress Report'!X84 -> This Month No. of Toolbox Talks | ED3: ="This Month "&'Weekly Progress Report'!X85 -> This Month Safety Awards/Incentives | EE3: ="YTD "&'Weekly Progress Report'!X70 -> YTD Total Hours Worked | EF3: ="YTD "&'Weekly Progress Report'!X71 -> YTD Safe Hours Worked | EG3: ="YTD "&'Weekly Progress Report'!X72 -> YTD LTI | EH3: ="YTD "&'Weekly Progress Report'!X73 -> YTD MTC (Healed w/o Disability) | EI3: ="YTD "&'Weekly Progress Report'!X74 -> YTD MTC (Healed w/ Disability) | EJ3: ="YTD "&'Weekly Progress Report'!X75 -> YTD Near Miss | EK3: ="YTD "&'Weekly Progress Report'!X76 -> YTD First Aid Cases | EL3: ="YTD "&'Weekly Progress Report'!X77 -> YTD Fatality | EM3: ="YTD "&'Weekly Progress Report'!X78 -> YTD Fire Incident Cases | EN3: ="YTD "&'Weekly Progress Report'!X79 -> YTD Vehicle Incident | EO3: ="YTD "&'Weekly Progress Report'!X80 -> YTD Property Damages | EP3: ="YTD "&'Weekly Progress Report'!X81 -> YTD Induction Training | EQ3: ="YTD "&'Weekly Progress Report'!X82 -> YTD No.of Internal Training | ER3: ="YTD "&'Weekly Progress Report'!X83 -> YTD No.of Internal Audit | ES3: ="YTD "&'Weekly Progress Report'!X84 -> YTD No. of Toolbox Talks | ET3: ="YTD "&'Weekly Progress Report'!X85 -> YTD Safety Awards/Incentives | EU3: ="Cum "&'Weekly Progress Report'!X70 -> Cum Total Hours Worked | EV3: ="Cum "&'Weekly Progress Report'!X71 -> Cum Safe Hours Worked | EW3: ="Cum "&'Weekly Progress Report'!X72 -> Cum LTI | EX3: ="Cum "&'Weekly Progress Report'!X73 -> Cum MTC (Healed w/o Disability) | EY3: ="Cum "&'Weekly Progress Report'!X74 -> Cum MTC (Healed w/ Disability) | EZ3: ="Cum "&'Weekly Progress Report'!X75 -> Cum Near Miss | FA3: ="Cum "&'Weekly Progress Report'!X76 -> Cum First Aid Cases | FB3: ="Cum "&'Weekly Progress Report'!X77 -> Cum Fatality | FC3: ="Cum "&'Weekly Progress Report'!X78 -> Cum Fire Incident Cases | FD3: ="Cum "&'Weekly Progress Report'!X79 -> Cum Vehicle Incident | FE3: ="Cum "&'Weekly Progress Report'!X80 -> Cum Property Damages | FF3: ="Cum "&'Weekly Progress Report'!X81 -> Cum Induction Training | FG3: ="Cum "&'Weekly Progress Report'!X82 -> Cum No.of Internal Training | FH3: ="Cum "&'Weekly Progress Report'!X83 -> Cum No.of Internal Audit | FI3: ="Cum "&'Weekly Progress Report'!X84 -> Cum No. of Toolbox Talks | FJ3: ="Cum "&'Weekly Progress Report'!X85 -> Cum Safety Awards/Incentives | FK3: ='Weekly Progress Report'!A98 -> Total Act. | FL3: ='Weekly Progress Report'!B98 -> Not Started | FM3: ='Weekly Progress Report'!C98 -> In Progress | FN3: ='Weekly Progress Report'!D98 -> Completed | FO3: Critical Path Act.Last Week | FP3: Critical Path Act.This Week | FQ3: Failed start Last Week | FR3: Failed start This Week | FS3: ='Weekly Progress Report'!B106 -> Planned Start Date | FT3: ='Weekly Progress Report'!D106 -> Planned Finish Date | FU3: ='Weekly Progress Report'!F106 -> Forecast Start Date | FV3: ='Weekly Progress Report'!H106 -> Forecast Finish Date | FW3: ='Weekly Progress Report'!J106 -> Actual Start Date | FX3: ='Weekly Progress Report'!L106 -> Actual Finish Date | FY3: ='Weekly Progress Report'!M106 -> % Completed | FZ3: ='Weekly Progress Report'!N106 -> Open Comments | GA3: ='Weekly Progress Report'!O106 -> Closed Comments
A4: ='Weekly Progress Report'!AG1 -> 46314 | B4: ='Weekly Progress Report'!B3 -> Playground Initiative for Western Region (Asir - Jazan - Jeddah) | C4: ='Weekly Progress Report'!B4 -> MLTX-02-004 | D4: ='Weekly Progress Report'!B5 -> Profast Company Ltd. | E4: ='Weekly Progress Report'!B6 -> Saudi Arabia Consulting Engineering Company "EGIS" | F4: ='Weekly Progress Report'!E4 -> Construction | G4: ='Weekly Progress Report'!E5 -> Active | H4: ='Weekly Progress Report'!E6 -> Engr.Yazeed Al Ragabh | I4: ='Weekly Progress Report'!AA3 -> The Scope of Works for the Playground Initiative for Western Region (ASIR - JAZAN – JEDDAH) according to the following contents. - Playground Area (Padel – Basketball – football) - Service & Toilet Building - Land Scape Works - Bike & Walking Paths - Parking | J4: ='Weekly Progress Report'!H3 -> 46057 | K4: ='Weekly Progress Report'!H4 -> 46085 | L4: ='Weekly Progress Report'!H5 -> 46107 | M4: ='Weekly Progress Report'!H6 -> 46412 | N4: ='Weekly Progress Report'!$J$3 -> 46057 | O4: ='Weekly Progress Report'!$J$4 -> 46085 | P4: ='Weekly Progress Report'!$J$5 -> 46107 | Q4: ='Weekly Progress Report'!$J$6 -> 46412 | R4: ='Weekly Progress Report'!$L$3 -> 46412 | S4: ='Weekly Progress Report'!$L$4 -> 46412 | T4: ='Weekly Progress Report'!$L$5 -> 46516 | U4: ='Weekly Progress Report'!$O$3 -> 33997787 | V4: ='Weekly Progress Report'!$O$4 -> 33793604 | W4: ='Weekly Progress Report'!$O$5 -> 33997787 | X4: ='Weekly Progress Report'!$O$6 -> -204182.66 | Y4: ='Weekly Progress Report'!$S$3 -> 0 | Z4: ='Weekly Progress Report'!$S$4 -> 0 | AA4: ='Weekly Progress Report'!$S$5 -> 4943710.6 | AB4: ='Weekly Progress Report'!$S$6 -> 11000 | AC4: ='Weekly Progress Report'!$J$28 -> 0.10537503 | AD4: ='Weekly Progress Report'!$V$3 -> 0.39130844 | AE4: ='Weekly Progress Report'!$V$4 -> 0.35390468 | AF4: ='Weekly Progress Report'!$X$3 -> 0.5102606 | AG4: ='Weekly Progress Report'!$X$4 -> 0.42411367 | AH4: ='Weekly Progress Report'!$Z$3 -> 0.85706897 | AI4: ='Weekly Progress Report'!$Z$5 -> 0.8375 | AJ4: ='Weekly Progress Report'!$E$28 -> 3299377 | AK4: ='Weekly Progress Report'!$F$28 -> 1643974.8 | AL4: =AJ4/V4 -> 0.097633177 | AM4: =AK4/V4 -> 0.048647512 | AN4: ='Weekly Progress Report'!S28 -> 0.040575427 | AO4: ='Weekly Progress Report'!T28 -> 0.034185672 | AP4: ='Weekly Progress Report'!C76 -> 140 | AQ4: ='Weekly Progress Report'!I76 -> 0 | AR4: ='Weekly Progress Report'!J76 -> 4 | AS4: ='Weekly Progress Report'!K76 -> 141 | AT4: ='Weekly Progress Report'!C85 -> 147 | AU4: ='Weekly Progress Report'!J85 -> 2 | AV4: ='Weekly Progress Report'!K85 -> 147 | AW4: ='Weekly Progress Report'!C94 -> 117 | AX4: ='Weekly Progress Report'!D94 -> 76 | AY4: ='Weekly Progress Report'!E94 -> 35 | AZ4: ='Weekly Progress Report'!F94 -> 41 | BA4: ='Weekly Progress Report'!G94 -> 22 | BB4: ='Weekly Progress Report'!H94 -> 54 | BC4: ='Weekly Progress Report'!I94 -> 0 | BD4: ='Weekly Progress Report'!N71 -> 20 | BE4: ='Weekly Progress Report'!O71 -> 20 | BF4: ='Weekly Progress Report'!P71 -> 0 | BG4: ='Weekly Progress Report'!Q71 -> 0 | BH4: ='Weekly Progress Report'!N72 -> 25 | BI4: ='Weekly Progress Report'!O72 -> 25 | BJ4: ='Weekly Progress Report'!P72 -> 0 | BK4: ='Weekly Progress Report'!Q72 -> 0 | BL4: ='Weekly Progress Report'!N73 -> 102 | BM4: ='Weekly Progress Report'!O73 -> 99 | BN4: ='Weekly Progress Report'!P73 -> 2 | BO4: ='Weekly Progress Report'!Q73 -> 0 | BP4: ='Weekly Progress Report'!N74 -> 657 | BQ4: ='Weekly Progress Report'!O74 -> 634 | BR4: ='Weekly Progress Report'!P74 -> 22 | BS4: ='Weekly Progress Report'!Q74 -> 0 | BT4: ='Weekly Progress Report'!O76 -> 46142 | BU4: ='Weekly Progress Report'!O77 -> - | BV4: ='Weekly Progress Report'!O78 -> 46184 | BW4: ='Weekly Progress Report'!O79 -> - | BX4: ='Weekly Progress Report'!O80 -> 46155 | BY4: ='Weekly Progress Report'!U76 -> 46140 | BZ4: ='Weekly Progress Report'!U77 -> - | CA4: ='Weekly Progress Report'!U78 -> - | CB4: ='Weekly Progress Report'!U79 -> 45918 | CC4: ='Weekly Progress Report'!U80 -> 0 | CD4: ='Weekly Progress Report'!N82 -> 5 | CE4: ='Weekly Progress Report'!N83 -> 0 | CF4: ='Weekly Progress Report'!N84 -> 0 | CG4: ='Weekly Progress Report'!N85 -> 5 | CH4: ='Weekly Progress Report'!N86 -> 0 | CI4: ='Weekly Progress Report'!N87 -> 0 | CJ4: ='Weekly Progress Report'!N88 -> 0.00032355047 | CK4: ='Weekly Progress Report'!R82 -> 4943710.6 | CL4: ='Weekly Progress Report'!R83 -> 0 | CM4: ='Weekly Progress Report'!R84 -> 0 | CN4: ='Weekly Progress Report'!R85 -> 46303 | CO4: ='Weekly Progress Report'!R86 -> 0 | CP4: ='Weekly Progress Report'!R87 -> 0 | CQ4: ='Weekly Progress Report'!R88 -> 11000 | CR4: ='Weekly Progress Report'!L92 -> 175 | CS4: ='Weekly Progress Report'!M92 -> 70 | CT4: ='Weekly Progress Report'!O92 -> 0 | CU4: ='Weekly Progress Report'!P92 -> 19 | CV4: ='Weekly Progress Report'!Q92 -> 30 | CW4: ='Weekly Progress Report'!T102 -> 9 | CX4: ='Weekly Progress Report'!U102 -> 5 | CY4: ='Weekly Progress Report'!Z70 -> 6480 | CZ4: ='Weekly Progress Report'!Z71 -> 6480 | DA4: ='Weekly Progress Report'!Z72 -> 0 | DB4: ='Weekly Progress Report'!Z73 -> 0 | DC4: ='Weekly Progress Report'!Z74 -> 0 | DD4: ='Weekly Progress Report'!Z75 -> 0 | DE4: ='Weekly Progress Report'!Z76 -> 0 | DF4: ='Weekly Progress Report'!Z77 -> 0 | DG4: ='Weekly Progress Report'!Z78 -> 0 | DH4: ='Weekly Progress Report'!Z79 -> 0 | DI4: ='Weekly Progress Report'!Z80 -> 0 | DJ4: ='Weekly Progress Report'!Z81 -> 0 | DK4: ='Weekly Progress Report'!Z82 -> 1 | DL4: ='Weekly Progress Report'!Z83 -> 0 | DM4: ='Weekly Progress Report'!Z84 -> 4 | DN4: ='Weekly Progress Report'!Z85 -> 0 | DO4: ='Weekly Progress Report'!AB70 -> 6480 | DP4: ='Weekly Progress Report'!AB71 -> 6480 | DQ4: ='Weekly Progress Report'!AB72 -> 0 | DR4: ='Weekly Progress Report'!AB73 -> 0 | DS4: ='Weekly Progress Report'!AB74 -> 0 | DT4: ='Weekly Progress Report'!AB75 -> 0 | DU4: ='Weekly Progress Report'!AB76 -> 0 | DV4: ='Weekly Progress Report'!AB77 -> 0 | DW4: ='Weekly Progress Report'!AB78 -> 0 | DX4: ='Weekly Progress Report'!AB79 -> 0 | DY4: ='Weekly Progress Report'!AB80 -> 0 | DZ4: ='Weekly Progress Report'!AB81 -> 18 | EA4: ='Weekly Progress Report'!AB82 -> 04 Session | EB4: ='Weekly Progress Report'!AB83 -> 0 | EC4: ='Weekly Progress Report'!AB84 -> 4 Sessions | ED4: ='Weekly Progress Report'!AB85 -> 0 | EE4: ='Weekly Progress Report'!AC70 -> 132050 | EF4: ='Weekly Progress Report'!AC71 -> 132050 | EG4: ='Weekly Progress Report'!AC72 -> 0 | EH4: ='Weekly Progress Report'!AC73 -> 0 | EI4: ='Weekly Progress Report'!AC74 -> 0 | EJ4: ='Weekly Progress Report'!AC75 -> 0 | EK4: ='Weekly Progress Report'!AC76 -> 0 | EL4: ='Weekly Progress Report'!AC77 -> 0 | EM4: ='Weekly Progress Report'!AC78 -> 0 | EN4: ='Weekly Progress Report'!AC79 -> 0 | EO4: ='Weekly Progress Report'!AC80 -> 0 | EP4: ='Weekly Progress Report'!AC81 -> 160 | EQ4: ='Weekly Progress Report'!AC82 -> 17 Session | ER4: ='Weekly Progress Report'!AC83 -> 0 | ES4: ='Weekly Progress Report'!AC84 -> 156 sessions | ET4: ='Weekly Progress Report'!AC85 -> 0 | EU4: ='Weekly Progress Report'!AD70 -> 132050 | EV4: ='Weekly Progress Report'!AD71 -> 132050 | EW4: ='Weekly Progress Report'!AD72 -> 0 | EX4: ='Weekly Progress Report'!AD73 -> 0 | EY4: ='Weekly Progress Report'!AD74 -> 0 | EZ4: ='Weekly Progress Report'!AD75 -> 0 | FA4: ='Weekly Progress Report'!AD76 -> 0 | FB4: ='Weekly Progress Report'!AD77 -> 0 | FC4: ='Weekly Progress Report'!AD78 -> 0 | FD4: ='Weekly Progress Report'!AD79 -> 0 | FE4: ='Weekly Progress Report'!AD80 -> 0 | FF4: ='Weekly Progress Report'!AD81 -> 160 | FG4: ='Weekly Progress Report'!AD82 -> 17 Session | FH4: ='Weekly Progress Report'!AD83 -> 0 | FI4: ='Weekly Progress Report'!AD84 -> 156 sessions | FJ4: ='Weekly Progress Report'!AD85 -> 0 | FK4: ='Weekly Progress Report'!A99 -> 2134 | FL4: ='Weekly Progress Report'!B99 -> 385 | FM4: ='Weekly Progress Report'!C99 -> 21 | FN4: ='Weekly Progress Report'!D99 -> 1728 | FO4: ='Weekly Progress Report'!A103 -> 373 | FP4: ='Weekly Progress Report'!B103 -> 331 | FQ4: ='Weekly Progress Report'!H103 -> 266 | FR4: ='Weekly Progress Report'!I103 -> 240 | FS4: ='Weekly Progress Report'!B111 -> 0 | FT4: ='Weekly Progress Report'!D111 -> 0 | FU4: ='Weekly Progress Report'!F111 -> 0 | FV4: ='Weekly Progress Report'!H111 -> 0 | FW4: ='Weekly Progress Report'!J111 -> 0 | FX4: ='Weekly Progress Report'!L111 -> 0 | FY4: ='Weekly Progress Report'!M111 -> 0 | FZ4: ='Weekly Progress Report'!N111 -> 0 | GA4: ='Weekly Progress Report'!O111 -> 0

Sheet Weekly Progress Report
A1: MODON - Weekly Progress Report - Construction Projects | AF1: Data Date | AG1: ='General Information'!L1 -> 46314
A2: Contract General Information | G2: Key Dates | M2: Cost Summary (SR) | U2: Performance Summary | AA2: Project Scope
A3: Project Name | B3: ='General Information'!C3 -> Playground Initiative for Western Region (Asir - Jazan - Jeddah) | G3: Contract Award | H3: ='General Information'!C12 -> 46057 | I3: Contract Award (Hijri) | J3: ='General Information'!C16 -> 46057 | K3: Revised Completion | L3: ='General Information'!C20 -> 46412 | M3: Original Contract Value | O3: ='Invoice Log'!F3 -> 33997787 | Q3: O&M Value | S3: ='Invoice Log'!J3 -> 0 | T3: EAC | U3: Plan Value | V3: =K28 -> 0.39130844 | W3: Phys. Plan Value | X3: =W28 -> 0.5102606 | Y3: Quality Score | Z3: =+[44]Quality!AC11 -> 0.85706897 | AA3: The Scope of Works for the Playground Initiative for Western Region (ASIR - JAZAN – JEDDAH) according to the following contents. - Playground Area (Padel – Basketball – football) - Service & Toilet Building - Land Scape Works - Bike & Walking Paths - Parking
A4: Project ID | B4: ='General Information'!C4 -> MLTX-02-004 | D4: Stage | E4: ='General Information'!C7 -> Construction | G4: Contract Sign | H4: ='General Information'!C13 -> 46085 | I4: Contract Sign (Hijri) | J4: ='General Information'!C17 -> 46085 | K4: Committed Completion | L4: ='General Information'!C21 -> 46412 | M4: Revised Contract Value | O4: ='Invoice Log'!F4 -> 33793604 | P4: EAC | Q4: Revised O&M Value | S4: ='Invoice Log'!J4 -> 0 | T4: =+#REF!+#REF!+S4 -> #REF! | U4: Earn Value | V4: =L28 -> 0.35390468 | W4: Phys. Earn Value | X4: =X28 -> 0.42411367 | Z4: =REPT("¢",IF(INT(+Z3*10)>5,5,INT(+Z3*10)))&REPT("£",IF(INT(+Z3*10)>5,0,5-INT(+Z3*10)))&CHAR(10)&REPT("¢",+IF(INT(+Z3*10)>5,-5+INT(+Z3*10),0))&REPT("£",IF(INT(+Z3*10)>5,10-INT(+Z3*10),5)) -> ¢¢¢¢¢ ¢¢¢££
A5: Contractor | B5: ='General Information'!C5 -> Profast Company Ltd. | D5: Status | E5: ='General Information'!C8 -> Active | G5: Site Handover | H5: ='General Information'!C14 -> 46107 | I5: Site Handover (Hijri) | J5: ='General Information'!C18 -> 46107 | K5: Forecast Completion | L5: ='General Information'!C22 -> 46516 | M5: Estimate At Completion Value | O5: ='Invoice Log'!F5 -> 33997787 | P5: =+#REF!+#REF!+O5 -> #REF! | Q5: Submitted Invoices (Gross Value) | S5: ='Invoice Log'!J5 -> 4943710.6 | U5: Variance | V5: =V4-V3 -> -0.037403761 | W5: Variance | X5: =X4-X3 -> -0.086146927 | Y5: Safety Score | Z5: =[44]HSE!$AE$6 -> 0.8375
A6: Consultant | B6: ='General Information'!C6 -> Saudi Arabia Consulting Engineering Company "EGIS" | D6: Modon PM | E6: ='General Information'!C9 -> Engr.Yazeed Al Ragabh | G6: Original Completion | H6: ='General Information'!C15 -> 46412 | I6: Original Completion (Hijri) | J6: ='General Information'!C19 -> 46412 | K6: Variance | L6: ='General Information'!C23 -> -104 | M6: Potential Changes | O6: =O4-O5 -> -204182.66 | Q6: Total Deduction | S6: ='Invoice Log'!J6 -> 11000 | U6: SPI | V6: =V4/V3 -> 0.90441361 | W6: SPI | X6: =X4/X3 -> 0.83117072 | Z6: =REPT("¢",IF(INT(+Z5*10)>5,5,INT(+Z5*10)))&REPT("£",IF(INT(+Z5*10)>5,0,5-INT(+Z5*10)))&CHAR(10)&REPT("¢",+IF(INT(+Z5*10)>5,-5+INT(+Z5*10),0))&REPT("£",IF(INT(+Z5*10)>5,10-INT(+Z5*10),5)) -> ¢¢¢¢¢ ¢¢¢££
A8: Progress Overview
A9: Earned Value Progress (SAR) | O9: Physical Progress (Effort) | AA9: Earned Value Progress (%)
A10: WBS | C10: BOQ Value (SAR) | D10: % Wt. | E10: Weekly (SAR) | G10: To Date (SAR) | O10: Budgeted | P10: % Wt. | Q10: Weekly Physical Progress | U10: To Date Physical Progress
E11: Planned | F11: Earned | G11: Original Plan | H11: Revised Planned | I11: Earned | J11: Original Plan % | K11: Revised Planned % | L11: Earned % | M11: Variance | N11: SPI | O11: (Manhours) | Q11: Planned | R11: Earned | S11: Plan % | T11: Earned % | U11: Planned | V11: Earned | W11: Plan % | X11: Earned % | Y11: Variance | Z11: SPI
C12: =Progress!C7 -> 0 | D12: =Progress!D7 -> 0 | E12: =Progress!E18 -> 0 | F12: =Progress!F18 -> 0 | G12: =Progress!G18 -> 0 | H12: =Progress!H18 -> 0 | I12: =Progress!I18 -> 0 | J12: =IFERROR(IF(ISBLANK(G12),"",G12/C12),0) -> 0 | K12: =IFERROR(IF(ISBLANK(H12),"",H12/C12),0) -> 0 | L12: =IFERROR(IF(ISBLANK(I12),"",I12/C12),0) -> 0 | M12: =IFERROR(L12-K12,"") -> 0 | N12: =IFERROR(L12/K12,"") | P12: =IF(ISBLANK(O12),"",O12/$O$28)
A13: =Progress!A7 -> Moblization | C13: =Progress!C7 -> 0 | D13: =Progress!D7 -> 0 | E13: =Progress!E7 -> 0 | F13: =Progress!F7 -> 0 | G13: =Progress!G7 -> 0 | H13: =Progress!H7 -> 0 | I13: =Progress!I7 -> 0 | J13: =IFERROR(IF(ISBLANK(G13),"",G13/C13),0) -> 0 | K13: =IFERROR(IF(ISBLANK(H13),"",H13/C13),0) -> 0 | L13: =IFERROR(IF(ISBLANK(I13),"",I13/C13),0) -> 0 | M13: =IFERROR(L13-K13,"") -> 0 | N13: =IFERROR(L13/K13,"") | O13: =Progress!L7 -> 12659 | P13: =IF(ISBLANK(O13),"",O13/$O$28) -> 0.031160232 | Q13: =Progress!N7 -> 0 | R13: =Progress!O7 -> 0 | S13: =IFERROR(IF(ISBLANK(Q13),"",Q13/O13),0) -> 0 | T13: =IFERROR(IF(ISBLANK(R13),"",R13/O13),0) -> 0 | U13: =Progress!P7 -> 12658.6 | V13: =Progress!Q7 -> 12658.6 | W13: =IFERROR(IF(ISBLANK(U13),"",U13/O13),0) -> 0.9999684 | X13: =IFERROR(IF(ISBLANK(V13),"",V13/O13),0) -> 0.9999684 | Y13: =IFERROR(X13-W13,"") -> 0 | Z13: =IFERROR(X13/W13,"") -> 1
A14: =Progress!A8 -> Engineering | C14: =Progress!C8 -> 0 | D14: =Progress!D8 -> 0 | E14: =Progress!E8 -> 0 | F14: =Progress!F8 -> 0 | G14: =Progress!G8 -> 0 | H14: =Progress!H8 -> 0 | I14: =Progress!I8 -> 0 | J14: =IFERROR(IF(ISBLANK(G14),"",G14/C14),0) -> 0 | K14: =IFERROR(IF(ISBLANK(H14),"",H14/C14),0) -> 0 | L14: =IFERROR(IF(ISBLANK(I14),"",I14/C14),0) -> 0 | M14: =IFERROR(L14-K14,"") -> 0 | N14: =IFERROR(L14/K14,"") | O14: =Progress!L8 -> 21299 | P14: =IF(ISBLANK(O14),"",O14/$O$28) -> 0.052427662 | Q14: =Progress!N8 -> 0 | R14: =Progress!O8 -> 80.5 | S14: =IFERROR(IF(ISBLANK(Q14),"",Q14/O14),0) -> 0 | T14: =IFERROR(IF(ISBLANK(R14),"",R14/O14),0) -> 0.0037795202 | U14: =Progress!P8 -> 21299.5 | V14: =Progress!Q8 -> 21009.7 | W14: =IFERROR(IF(ISBLANK(U14),"",U14/O14),0) -> 1.0000235 | X14: =IFERROR(IF(ISBLANK(V14),"",V14/O14),0) -> 0.9864172 | Y14: =IFERROR(X14-W14,"") -> -0.013606273 | Z14: =IFERROR(X14/W14,"") -> 0.98639405
A15: =Progress!A9 -> Procurment | C15: =Progress!C9 -> 0 | D15: =Progress!D9 -> 0 | E15: =Progress!E9 -> 0 | F15: =Progress!F9 -> 0 | G15: =Progress!G9 -> 0 | H15: =Progress!H9 -> 0 | I15: =Progress!I9 -> 0 | J15: =IFERROR(IF(ISBLANK(G15),"",G15/C15),0) -> 0 | K15: =IFERROR(IF(ISBLANK(H15),"",H15/C15),0) -> 0 | L15: =IFERROR(IF(ISBLANK(I15),"",I15/C15),0) -> 0 | M15: =IFERROR(L15-K15,"") -> 0 | N15: =IFERROR(L15/K15,"") | O15: =Progress!L9 -> 51273 | P15: =IF(ISBLANK(O15),"",O15/$O$28) -> 0.12620891 | Q15: =Progress!N9 -> 296.71 | R15: =Progress!O9 -> 5000 | S15: =IFERROR(IF(ISBLANK(Q15),"",Q15/O15),0) -> 0.0057868664 | T15: =IFERROR(IF(ISBLANK(R15),"",R15/O15),0) -> 0.097517212 | U15: =Progress!P9 -> 50732.3 | V15: =Progress!Q9 -> 31870.4 | W15: =IFERROR(IF(ISBLANK(U15),"",U15/O15),0) -> 0.98945449 | X15: =IFERROR(IF(ISBLANK(V15),"",V15/O15),0) -> 0.62158251 | Y15: =IFERROR(X15-W15,"") -> -0.36787198 | Z15: =IFERROR(X15/W15,"") -> 0.62820728
A16: =Progress!A10 -> Construction | C16: =Progress!C10 -> 33793604 | D16: =Progress!D10 -> 1 | E16: =Progress!E10 -> 1649688.5 | F16: =Progress!F10 -> 821987.39 | G16: =Progress!G10 -> 3561002.2 | H16: =Progress!H10 -> 13223723 | I16: =Progress!I10 -> 11959715 | J16: =IFERROR(IF(ISBLANK(G16),"",G16/C16),0) -> 0.10537503 | K16: =IFERROR(IF(ISBLANK(H16),"",H16/C16),0) -> 0.39130844 | L16: =IFERROR(IF(ISBLANK(I16),"",I16/C16),0) -> 0.35390468 | M16: =IFERROR(L16-K16,"") -> -0.037403761 | N16: =IFERROR(L16/K16,"") -> 0.90441361 | O16: =Progress!L10 -> 299660 | P16: =IF(ISBLANK(O16),"",O16/$O$28) -> 0.73761554 | Q16: =Progress!N10 -> 16187.26 | R16: =Progress!O10 -> 8807.6 | S16: =IFERROR(IF(ISBLANK(Q16),"",Q16/O16),0) -> 0.054018755 | T16: =IFERROR(IF(ISBLANK(R16),"",R16/O16),0) -> 0.029391978 | U16: =Progress!P10 -> 122605.52 | V16: =Progress!Q10 -> 106759.6 | W16: =IFERROR(IF(ISBLANK(U16),"",U16/O16),0) -> 0.40914877 | X16: =IFERROR(IF(ISBLANK(V16),"",V16/O16),0) -> 0.3562691 | Y16: =IFERROR(X16-W16,"") -> -0.052879664 | Z16: =IFERROR(X16/W16,"") -> 0.87075688
A17: =Progress!A11 -> Jazan Region | C17: =Progress!C11 -> 10680072 | D17: =Progress!D11 -> 0.31603825 | E17: =Progress!E11 -> 401113.04 | F17: =Progress!F11 -> 199957.72 | G17: =Progress!G11 -> 794325.94 | H17: =Progress!H11 -> 3951358.3 | I17: =Progress!I11 -> 2669083.7 | J17: =IFERROR(IF(ISBLANK(G17),"",G17/C17),0) -> 0.07437459 | K17: =IFERROR(IF(ISBLANK(H17),"",H17/C17),0) -> 0.36997489 | L17: =IFERROR(IF(ISBLANK(I17),"",I17/C17),0) -> 0.24991253 | M17: =IFERROR(L17-K17,"") -> -0.12006236 | N17: =IFERROR(L17/K17,"") -> 0.67548512 | O17: =Progress!L11 -> 102280 | P17: =IF(ISBLANK(O17),"",O17/$O$28) -> 0.25176306 | Q17: =Progress!N11 -> 5152.78 | R17: =Progress!O11 -> 4475.4 | S17: =IFERROR(IF(ISBLANK(Q17),"",Q17/O17),0) -> 0.050379155 | T17: =IFERROR(IF(ISBLANK(R17),"",R17/O17),0) -> 0.043756355 | U17: =Progress!P11 -> 45532.83 | V17: =Progress!Q11 -> 24825.4 | W17: =IFERROR(IF(ISBLANK(U17),"",U17/O17),0) -> 0.44517824 | X17: =IFERROR(IF(ISBLANK(V17),"",V17/O17),0) -> 0.24271998 | Y17: =IFERROR(X17-W17,"") -> -0.20245825 | Z17: =IFERROR(X17/W17,"") -> 0.54521979
A18: =Progress!A12 -> Asir Region | C18: =Progress!C12 -> 10578073 | D18: =Progress!D12 -> 0.31301997 | E18: =Progress!E12 -> 617430.85 | F18: =Progress!F12 -> 300428.38 | G18: =Progress!G12 -> 1310370.1 | H18: =Progress!H12 -> 3063276.7 | I18: =Progress!I12 -> 4049399.2 | J18: =IFERROR(IF(ISBLANK(G18),"",G18/C18),0) -> 0.12387607 | K18: =IFERROR(IF(ISBLANK(H18),"",H18/C18),0) -> 0.2895874 | L18: =IFERROR(IF(ISBLANK(I18),"",I18/C18),0) -> 0.38281067 | M18: =IFERROR(L18-K18,"") -> 0.093223271 | N18: =IFERROR(L18/K18,"") -> 1.3219176 | O18: =Progress!L12 -> 96810 | P18: =IF(ISBLANK(O18),"",O18/$O$28) -> 0.23829861 | Q18: =Progress!N12 -> 7222.43 | R18: =Progress!O12 -> 1151.2 | S18: =IFERROR(IF(ISBLANK(Q18),"",Q18/O18),0) -> 0.074604173 | T18: =IFERROR(IF(ISBLANK(R18),"",R18/O18),0) -> 0.011891334 | U18: =Progress!P12 -> 40471.12 | V18: =Progress!Q12 -> 39573.2 | W18: =IFERROR(IF(ISBLANK(U18),"",U18/O18),0) -> 0.4180469 | X18: =IFERROR(IF(ISBLANK(V18),"",V18/O18),0) -> 0.40877182 | Y18: =IFERROR(X18-W18,"") -> -0.0092750749 | Z18: =IFERROR(X18/W18,"") -> 0.97781331
A19: =Progress!A13 -> Jeddah Region | C19: =Progress!C13 -> 12535460 | D19: =Progress!D13 -> 0.37094178 | E19: =Progress!E13 -> 631144.59 | F19: =Progress!F13 -> 321601.29 | G19: =Progress!G13 -> 1456306.1 | H19: =Progress!H13 -> 6209087.6 | I19: =Progress!I13 -> 5241231.7 | J19: =IFERROR(IF(ISBLANK(G19),"",G19/C19),0) -> 0.11617493 | K19: =IFERROR(IF(ISBLANK(H19),"",H19/C19),0) -> 0.49532189 | L19: =IFERROR(IF(ISBLANK(I19),"",I19/C19),0) -> 0.41811244 | M19: =IFERROR(L19-K19,"") -> -0.077209447 | N19: =IFERROR(L19/K19,"") -> 0.84412268 | O19: =Progress!L13 -> 100570 | P19: =IF(ISBLANK(O19),"",O19/$O$28) -> 0.24755388 | Q19: =Progress!N13 -> 3812.05 | R19: =Progress!O13 -> 3181 | S19: =IFERROR(IF(ISBLANK(Q19),"",Q19/O19),0) -> 0.037904445 | T19: =IFERROR(IF(ISBLANK(R19),"",R19/O19),0) -> 0.031629711 | U19: =Progress!P13 -> 36601.57 | V19: =Progress!Q13 -> 42361 | W19: =IFERROR(IF(ISBLANK(U19),"",U19/O19),0) -> 0.36394123 | X19: =IFERROR(IF(ISBLANK(V19),"",V19/O19),0) -> 0.42120911 | Y19: =IFERROR(X19-W19,"") -> 0.057267873 | Z19: =IFERROR(X19/W19,"") -> 1.1573547
A20: =Progress!A14 -> Testing & Commissioning | C20: =Progress!C14 -> 0 | D20: =Progress!D14 -> 0 | E20: =Progress!E14 -> 0 | F20: =Progress!F14 -> 0 | G20: =Progress!G14 -> 0 | H20: =Progress!H14 -> 0 | I20: =Progress!I14 -> 0 | J20: =IFERROR(IF(ISBLANK(G20),"",G20/C20),0) -> 0 | K20: =IFERROR(IF(ISBLANK(H20),"",H20/C20),0) -> 0 | L20: =IFERROR(IF(ISBLANK(I20),"",I20/C20),0) -> 0 | M20: =IFERROR(L20-K20,"") -> 0 | N20: =IFERROR(L20/K20,"") | O20: =Progress!L14 -> 12818 | P20: =IF(ISBLANK(O20),"",O20/$O$28) -> 0.031551612 | Q20: =Progress!N14 -> 0 | R20: =Progress!O14 -> 0 | S20: =IFERROR(IF(ISBLANK(Q20),"",Q20/O20),0) -> 0 | T20: =IFERROR(IF(ISBLANK(R20),"",R20/O20),0) -> 0 | U20: =Progress!P14 -> 0 | V20: =Progress!Q14 -> 0 | W20: =IFERROR(IF(ISBLANK(U20),"",U20/O20),0) -> 0 | X20: =IFERROR(IF(ISBLANK(V20),"",V20/O20),0) -> 0 | Y20: =IFERROR(X20-W20,"") -> 0 | Z20: =IFERROR(X20/W20,"")
A21: =Progress!A15 -> Close-Out | C21: =Progress!C15 -> 0 | D21: =Progress!D15 -> 0 | E21: =Progress!E15 -> 0 | F21: =Progress!F15 -> 0 | G21: =Progress!G15 -> 0 | H21: =Progress!H15 -> 0 | I21: =Progress!I15 -> 0 | J21: =IFERROR(IF(ISBLANK(G21),"",G21/C21),0) -> 0 | K21: =IFERROR(IF(ISBLANK(H21),"",H21/C21),0) -> 0 | L21: =IFERROR(IF(ISBLANK(I21),"",I21/C21),0) -> 0 | M21: =IFERROR(L21-K21,"") -> 0 | N21: =IFERROR(L21/K21,"") | O21: =Progress!L15 -> 8546 | P21: =IF(ISBLANK(O21),"",O21/$O$28) -> 0.021036049 | Q21: =Progress!N15 -> 0 | R21: =Progress!O15 -> 0 | S21: =IFERROR(IF(ISBLANK(Q21),"",Q21/O21),0) -> 0 | T21: =IFERROR(IF(ISBLANK(R21),"",R21/O21),0) -> 0 | U21: =Progress!P15 -> 0 | V21: =Progress!Q15 -> 0 | W21: =IFERROR(IF(ISBLANK(U21),"",U21/O21),0) -> 0 | X21: =IFERROR(IF(ISBLANK(V21),"",V21/O21),0) -> 0 | Y21: =IFERROR(X21-W21,"") -> 0 | Z21: =IFERROR(X21/W21,"")
C22: =Progress!C16 -> 0 | D22: =Progress!D16 -> 0 | E22: =Progress!E16 -> 0 | F22: =Progress!F16 -> 0 | G22: =Progress!G16 -> 0 | H22: =Progress!H16 -> 0 | I22: =Progress!I16 -> 0 | J22: =IFERROR(IF(ISBLANK(G22),"",G22/C22),0) -> 0 | K22: =IFERROR(IF(ISBLANK(H22),"",H22/C22),0) -> 0 | L22: =IFERROR(IF(ISBLANK(I22),"",I22/C22),0) -> 0 | M22: =IFERROR(L22-K22,"") -> 0 | N22: =IFERROR(L22/K22,"") | O22: =Progress!L16 -> 0 | P22: =IF(ISBLANK(O22),"",O22/$O$28) -> 0 | Q22: =Progress!N16 -> 0 | R22: =Progress!O16 -> 0 | S22: =IFERROR(IF(ISBLANK(Q22),"",Q22/O22),0) -> 0 | T22: =IFERROR(IF(ISBLANK(R22),"",R22/O22),0) -> 0 | U22: =Progress!P16 -> 0 | V22: =Progress!Q16 -> 0 | W22: =IFERROR(IF(ISBLANK(U22),"",U22/O22),0) -> 0 | X22: =IFERROR(IF(ISBLANK(V22),"",V22/O22),0) -> 0 | Y22: =IFERROR(X22-W22,"") -> 0 | Z22: =IFERROR(X22/W22,"")
C23: =Progress!C17 -> 0 | D23: =Progress!D17 -> 0 | E23: =Progress!E17 -> 0 | F23: =Progress!F17 -> 0 | G23: =Progress!G17 -> 0 | H23: =Progress!H17 -> 0 | I23: =Progress!I17 -> 0 | J23: =IFERROR(IF(ISBLANK(G23),"",G23/C23),0) -> 0 | K23: =IFERROR(IF(ISBLANK(H23),"",H23/C23),0) -> 0 | L23: =IFERROR(IF(ISBLANK(I23),"",I23/C23),0) -> 0 | M23: =IFERROR(L23-K23,"") -> 0 | N23: =IFERROR(L23/K23,"") | O23: =Progress!L17 -> 0 | P23: =IF(ISBLANK(O23),"",O23/$O$28) -> 0 | Q23: =Progress!N17 -> 0 | R23: =Progress!O17 -> 0 | S23: =IFERROR(IF(ISBLANK(Q23),"",Q23/O23),0) -> 0 | T23: =IFERROR(IF(ISBLANK(R23),"",R23/O23),0) -> 0 | U23: =Progress!P17 -> 0 | V23: =Progress!Q17 -> 0 | W23: =IFERROR(IF(ISBLANK(U23),"",U23/O23),0) -> 0 | X23: =IFERROR(IF(ISBLANK(V23),"",V23/O23),0) -> 0 | Y23: =IFERROR(X23-W23,"") -> 0 | Z23: =IFERROR(X23/W23,"")
C24: =Progress!C18 -> 0 | D24: =Progress!D18 -> 0 | E24: =Progress!E18 -> 0 | F24: =Progress!F18 -> 0 | G24: =Progress!G18 -> 0 | H24: =Progress!H18 -> 0 | I24: =Progress!I18 -> 0 | J24: =IFERROR(IF(ISBLANK(G24),"",G24/C24),0) -> 0 | K24: =IFERROR(IF(ISBLANK(H24),"",H24/C24),0) -> 0 | L24: =IFERROR(IF(ISBLANK(I24),"",I24/C24),0) -> 0 | M24: =IFERROR(L24-K24,"") -> 0 | N24: =IFERROR(L24/K24,"") | O24: =Progress!L18 -> 0 | P24: =IF(ISBLANK(O24),"",O24/$O$28) -> 0 | Q24: =Progress!N18 -> 0 | R24: =Progress!O18 -> 0 | S24: =IFERROR(IF(ISBLANK(Q24),"",Q24/O24),0) -> 0 | T24: =IFERROR(IF(ISBLANK(R24),"",R24/O24),0) -> 0 | U24: =Progress!P18 -> 0 | V24: =Progress!Q18 -> 0 | W24: =IFERROR(IF(ISBLANK(U24),"",U24/O24),0) -> 0 | X24: =IFERROR(IF(ISBLANK(V24),"",V24/O24),0) -> 0 | Y24: =IFERROR(X24-W24,"") -> 0 | Z24: =IFERROR(X24/W24,"")
C25: =Progress!C19 -> 0 | D25: =Progress!D19 -> 0 | E25: =Progress!E19 -> 0 | F25: =Progress!F19 -> 0 | G25: =Progress!G19 -> 0 | H25: =Progress!H19 -> 0 | I25: =Progress!I19 -> 0 | J25: =IFERROR(IF(ISBLANK(G25),"",G25/C25),0) -> 0 | K25: =IFERROR(IF(ISBLANK(H25),"",H25/C25),0) -> 0 | L25: =IFERROR(IF(ISBLANK(I25),"",I25/C25),0) -> 0 | M25: =IFERROR(L25-K25,"") -> 0 | N25: =IFERROR(L25/K25,"") | O25: =Progress!L19 -> 0 | P25: =IF(ISBLANK(O25),"",O25/$O$28) -> 0 | Q25: =Progress!N19 -> 0 | R25: =Progress!O19 -> 0 | S25: =IFERROR(IF(ISBLANK(Q25),"",Q25/O25),0) -> 0 | T25: =IFERROR(IF(ISBLANK(R25),"",R25/O25),0) -> 0 | U25: =Progress!P19 -> 0 | V25: =Progress!Q19 -> 0 | W25: =IFERROR(IF(ISBLANK(U25),"",U25/O25),0) -> 0 | X25: =IFERROR(IF(ISBLANK(V25),"",V25/O25),0) -> 0 | Y25: =IFERROR(X25-W25,"") -> 0 | Z25: =IFERROR(X25/W25,"")
C26: =Progress!C20 -> 0 | D26: =Progress!D20 -> 0 | E26: =Progress!E20 -> 0 | F26: =Progress!F20 -> 0 | G26: =Progress!G20 -> 0 | H26: =Progress!H20 -> 0 | I26: =Progress!I20 -> 0 | J26: =IFERROR(IF(ISBLANK(G26),"",G26/C26),0) -> 0 | K26: =IFERROR(IF(ISBLANK(H26),"",H26/C26),0) -> 0 | L26: =IFERROR(IF(ISBLANK(I26),"",I26/C26),0) -> 0 | M26: =IFERROR(L26-K26,"") -> 0 | N26: =IFERROR(L26/K26,"") | O26: =Progress!L20 -> 0 | P26: =IF(ISBLANK(O26),"",O26/$O$28) -> 0 | Q26: =Progress!N20 -> 0 | R26: =Progress!O20 -> 0 | S26: =IFERROR(IF(ISBLANK(Q26),"",Q26/O26),0) -> 0 | T26: =IFERROR(IF(ISBLANK(R26),"",R26/O26),0) -> 0 | U26: =Progress!P20 -> 0 | V26: =Progress!Q20 -> 0 | W26: =IFERROR(IF(ISBLANK(U26),"",U26/O26),0) -> 0 | X26: =IFERROR(IF(ISBLANK(V26),"",V26/O26),0) -> 0 | Y26: =IFERROR(X26-W26,"") -> 0 | Z26: =IFERROR(X26/W26,"")
C27: =Progress!C21 -> 0 | D27: =Progress!D21 -> 0 | E27: =Progress!E21 -> 0 | F27: =Progress!F21 -> 0 | G27: =Progress!G21 -> 0 | H27: =Progress!H21 -> 0 | I27: =Progress!I21 -> 0 | J27: =IFERROR(IF(ISBLANK(G27),"",G27/C27),0) -> 0 | K27: =IFERROR(IF(ISBLANK(H27),"",H27/C27),0) -> 0 | L27: =IFERROR(IF(ISBLANK(I27),"",I27/C27),0) -> 0 | M27: =IFERROR(L27-K27,"") -> 0 | N27: =IFERROR(L27/K27,"") | O27: =Progress!L21 -> 0 | P27: =IF(ISBLANK(O27),"",O27/$O$28) -> 0 | Q27: =Progress!N21 -> 0 | R27: =Progress!O21 -> 0 | S27: =IFERROR(IF(ISBLANK(Q27),"",Q27/O27),0) -> 0 | T27: =IFERROR(IF(ISBLANK(R27),"",R27/O27),0) -> 0 | U27: =Progress!P21 -> 0 | V27: =Progress!Q21 -> 0 | W27: =IFERROR(IF(ISBLANK(U27),"",U27/O27),0) -> 0 | X27: =IFERROR(IF(ISBLANK(V27),"",V27/O27),0) -> 0 | Y27: =IFERROR(X27-W27,"") -> 0 | Z27: =IFERROR(X27/W27,"")
B28: Total | C28: =Progress!C25 -> 33793604 | D28: =Progress!D25 -> 1 | E28: =SUM(E12:E22) -> 3299377 | F28: =SUM(F12:F22) -> 1643974.8 | G28: =Progress!G25 -> 3561002.2 | H28: =Progress!H25 -> 13223723 | I28: =Progress!I25 -> 11959715 | J28: =IFERROR(IF(ISBLANK(G28),"",G28/C28),0) -> 0.10537503 | K28: =IFERROR(IF(ISBLANK(H28),"",H28/C28),0) -> 0.39130844 | L28: =IFERROR(IF(ISBLANK(I28),"",I28/C28),0) -> 0.35390468 | M28: =+L28-K28 -> -0.037403761 | N28: =L28/K28 -> 0.90441361 | O28: =Progress!L25 -> 406255 | P28: =Progress!M25 -> 1 | Q28: =Progress!N25 -> 16483.97 | R28: =Progress!O25 -> 13888.1 | S28: =IFERROR(IF(ISBLANK(Q28),"",Q28/O28),0) -> 0.040575427 | T28: =IFERROR(IF(ISBLANK(R28),"",R28/O28),0) -> 0.034185672 | U28: =Progress!P25 -> 207295.92 | V28: =Progress!Q25 -> 172298.3 | W28: =IFERROR(IF(ISBLANK(U28),"",U28/O28),0) -> 0.5102606 | X28: =IFERROR(IF(ISBLANK(V28),"",V28/O28),0) -> 0.42411367 | Y28: =+X28-W28 -> -0.086146927 | Z28: =X28/W28 -> 0.83117072
AA29: Construction Milestones
AA30: Item No. | AB30: Milestones | AD30: Original (Baseline) | AE30: Latest Plan | AF30: Forecast | AG30: Status | AH30: Days Change
AA31: =+Milestones!A4 -> 1 | AB31: =+Milestones!B4 -> Project Finish | AD31: =+Milestones!D4 -> 46412 | AE31: =+Milestones!E4 -> 46516 | AF31: =+Milestones!E4 -> 46516 | AG31: =+Milestones!F4 -> F | AH31: =+Milestones!G4 -> -104
Z32: =+Milestones!#REF! -> #REF! | AA32: =+Milestones!A5 -> 2 | AB32: =+Milestones!B5 -> Project Start | AD32: =+Milestones!D5 -> 46107 | AE32: =+Milestones!E5 -> 46107 | AF32: =+Milestones!E5 -> 46107 | AG32: =+Milestones!F5 -> A | AH32: =+Milestones!G5 -> 0
Z33: =+Milestones!#REF! -> #REF! | AA33: =+Milestones!A6 -> 3 | AB33: =+Milestones!B6 -> Baseline Programme Approval | AD33: =+Milestones!D6 -> 46141 | AE33: =+Milestones!E6 -> 46141 | AF33: =+Milestones!E6 -> 46141 | AG33: =+Milestones!F6 -> A | AH33: =+Milestones!G6 -> 0
Z34: =+Milestones!#REF! -> #REF! | AA34: =+Milestones!A7 -> 4 | AB34: =+Milestones!B7 -> Completion of Mobilization | AD34: =+Milestones!D7 -> 46175 | AE34: =+Milestones!E7 -> 46175 | AF34: =+Milestones!E7 -> 46175 | AG34: =+Milestones!F7 -> A | AH34: =+Milestones!G7 -> 0
Z35: =+Milestones!#REF! -> #REF! | AA35: =+Milestones!A8 -> 5 | AB35: =+Milestones!B8 -> Completion of Levelling Works | AD35: =+Milestones!D8 -> 46225 | AE35: =+Milestones!E8 -> 46315 | AF35: =+Milestones!E8 -> 46315 | AG35: =+Milestones!F8 -> F | AH35: =+Milestones!G8 -> -90
Z36: =+Milestones!#REF! -> #REF! | AA36: =+Milestones!A9 -> 6 | AB36: =+Milestones!B9 -> Completion of Engineering | AD36: =+Milestones!D9 -> 46406 | AE36: =+Milestones!E9 -> 46331 | AF36: =+Milestones!E9 -> 46331 | AG36: =+Milestones!F9 -> F | AH36: =+Milestones!G9 -> 75
G37: 20000000 | Z37: =+Milestones!#REF! -> #REF! | AA37: =+Milestones!A10 -> 7 | AB37: =+Milestones!B10 -> Completion of Toilet Building | AD37: =+Milestones!D10 -> 46243 | AE37: =+Milestones!E10 -> 46391 | AF37: =+Milestones!E10 -> 46391 | AG37: =+Milestones!F10 -> F | AH37: =+Milestones!G10 -> -148
AA38: =+Milestones!A11 -> 8 | AB38: =+Milestones!B11 -> Completion of Natural Landscape Works | AD38: =+Milestones!D11 -> 46403 | AE38: =+Milestones!E11 -> 46454 | AF38: =+Milestones!E11 -> 46454 | AG38: =+Milestones!F11 -> F | AH38: =+Milestones!G11 -> -51
AA39: =+Milestones!A12 -> 9 | AB39: =+Milestones!B12 -> Completion of Playground Area | AD39: =+Milestones!D12 -> 46356 | AE39: =+Milestones!E12 -> 46506 | AF39: =+Milestones!E12 -> 46506 | AG39: =+Milestones!F12 -> F | AH39: =+Milestones!G12 -> -150
Z40: =+Milestones!#REF! -> #REF! | AA40: =+Milestones!A13 -> 10 | AB40: =+Milestones!B13 -> Completion of Asir Works | AD40: =+Milestones!D13 -> 46369 | AE40: =+Milestones!E13 -> 46475 | AF40: =+Milestones!E13 -> 46475 | AG40: =+Milestones!F13 -> F | AH40: =+Milestones!G13 -> -106
Z41: =+Milestones!#REF! -> #REF!
...

Sheet General Information
A1: Weekly Progress Report - Construction Projects | K1: Data Date | L1: 46314
A2: Contract General Information
A3: Project Name | C3: Playground Initiative for Western Region (Asir - Jazan - Jeddah)
A4: Project ID | C4: MLTX-02-004
A5: Contractor | C5: Profast Company Ltd.
A6: Consultant | C6: Saudi Arabia Consulting Engineering Company "EGIS"
A7: Stage | C7: Construction
A8: Status | C8: Active
A9: Modon PM | C9: Engr.Yazeed Al Ragabh
A11: Key Dates
A12: Contract Award Date | C12: 46057
A13: Contract Sign Date | C13: 46085
A14: Site Handover Date | C14: 46107
A15: Original Completion | C15: 46412
A16: Contract Award Date (Hijri) | C16: =C12 -> 46057
A17: Contract Sign Date (Hijri) | C17: =C13 -> 46085
A18: Site Handover Date (Hijri) | C18: =C14 -> 46107
A19: Original Completion (Hijri) | C19: =C15 -> 46412
A20: Revised Completion Date | C20: 46412
A21: Committed Completion Date | C21: 46412
A22: Forecast Completion | C22: 46516
A23: Variance | C23: =C20-C22 -> -104
A25: Key Project Submittals | C25: Submission Date | D25: Days taken to approve orginal plan from site handover date
A26: Quality Plan submission | C26: 46123 | D26: =C26-C14 -> 16
A27: Quality Plan approval | C27: 46142
A28: Quality Plan Last Update | C28: -
A30: Safety Plan submission | C30: 46123 | D30: =C30-C14 -> 16
A31: Safety Plan approval | C31: 46184
A32: Safety Plan Last Update | C32: -
A34: Risk Management Plan submission | C34: 46141 | D34: =C34-C14 -> 34
A35: Risk Management Plan approval
A36: Risk Management Plan Last Update | C36: -
A38: Baseline Schedule submission | C38: 46140 | D38: =C38-C14 -> 33
A39: Baseline Schedule approval | C39: 46140
A40: No of Schedule Versions | C40: -
A41: Last Revised Schedule Approval Date | C41: -
A43: BOQ submission | C43: 45918 | D43: =C43-C14 -> -189
A44: BOQ approval | C44: 45918
A45: No of Approved Version of BOQ
A47: Execution Plan submission | C47: 46142 | D47: =C47-C14 -> 35
...

Sheet Milestones
A1: Project Name
A2: Item No. | B2: Milestones | C2: Original (Baseline) | D2: Latest | E2: Forecast | G2: Days Change
D3: =(D4-D5)/7 -> 43.571429 | E3: =(E4-E5)/7 -> 58.428571 | G3: =(D3-E3)*7 -> -104
A4: 1 | B4: Project Finish | C4: 46412 | D4: 46412 | E4: 46516 | F4: F | G4: =(D4-E4) -> -104
A5: 2 | B5: Project Start | C5: 46107 | D5: 46107 | E5: =D5 -> 46107 | F5: A | G5: =(D5-E5) -> 0
A6: 3 | B6: Baseline Programme Approval | C6: 46175 | D6: 46141 | E6: 46141 | F6: A | G6: =(D6-E6) -> 0
A7: 4 | B7: Completion of Mobilization | C7: 46412 | D7: 46175 | E7: 46175 | F7: A | G7: =D7-E7 -> 0
A8: 5 | B8: Completion of Levelling Works | C8: 46225 | D8: 46225 | E8: 46315 | F8: F | G8: =D8-E8 -> -90
A9: 6 | B9: Completion of Engineering | C9: 46406 | D9: 46406 | E9: 46331 | F9: F | G9: =D9-E9 -> 75
A10: 7 | B10: Completion of Toilet Building | C10: 46243 | D10: 46243 | E10: 46391 | F10: F | G10: =D10-E10 -> -148 | J10: 46141
A11: 8 | B11: Completion of Natural Landscape Works | C11: 46403 | D11: 46403 | E11: 46454 | F11: F | G11: =D11-E11 -> -51
A12: 9 | B12: Completion of Playground Area | C12: 46356 | D12: 46356 | E12: 46506 | F12: F | G12: =D12-E12 -> -150
A13: 10 | B13: Completion of Asir Works | C13: 46369 | D13: 46369 | E13: 46475 | F13: F | G13: =D13-E13 -> -106
A14: 11 | B14: Completion of Jazan Works | C14: 46406 | D14: 46406 | E14: 46516 | F14: F | G14: =D14-E14 -> -110
A15: 12 | B15: Completion of Jeddah Works | C15: 46412 | D15: 46412 | E15: 46471 | F15: F | G15: =D15-E15 -> -59
A16: 13 | B16: Completion of Testing & Commissioning | C16: 46141 | D16: 46141 | E16: 46488 | F16: F | G16: =D16-E16 -> -347
A24: Activity ID | B24: Activity Name | C24: Activity Status | D24: Original Duration | E24: Duration % Complete | F24: Schedule % Complete | G24: Performance % Complete | H24: Earned Value Cost | I24: Planned Value Cost | J24: Start | K24: Finish | L24: BL1 Start | M24: BL1 Finish | N24: Budgeted Total Cost
A25: MLTX-02-004 - Playground Initiative for Western Region (Asir - Jazan - Jeddah) - Updating 02-06-2026 | D25: 310 | E25: 0.1806 | F25: 0.0576 | G25: 0.0534 | H25: 1816335.3 | I25: 1958160.7 | J25: 26-Mar-26 A | K25: 46477 | L25: 46107 | M25: 46477 | N25: 33997787
A26: KEY MILESTONES | D26: 310 | E26: 0.2129 | F26: 0 | G26: 0 | H26: 0 | I26: 0 | J26: 26-Mar-26 A | K26: 46477 | L26: 46107 | M26: 46477 | N26: 0
A27: GENERAL MILESTONES | D27: 310 | E27: 1 | F27: 0 | G27: 0 | H27: 0 | I27: 0 | J27: 26-Mar-26 A | K27: 46477 | L27: 46107 | M27: 46477 | N27: 0
A28: MLTX-02-004-MS-1010 | B28: Project Commencement Date | C28: Completed | D28: 0 | E28: 1 | F28: 1 | G28: 1 | H28: 0 | I28: 0 | J28: 26-Mar-26 A | L28: 46107 | N28: 0
A29: MLTX-02-004-MS-1030 | B29: Project Completion | C29: Not Started | D29: 0 | E29: 0 | F29: 0 | G29: 0 | H29: 0 | I29: 0 | K29: 46477 | M29: 46477 | N29: 0
A30: CONTRACTUAL MILESTONE | D30: 271 | E30: 0.1328 | F30: 0 | G30: 0 | H30: 0 | I30: 0 | J30: 29-Apr-26 A | K30: 46467 | L30: 46141 | M30: 46467 | N30: 0
A31: MLTX-02-004-MS-1060 | B31: Baseline Programme Approval | C31: Completed | D31: 0 | E31: 1 | F31: 1 | G31: 1 | H31: 0 | I31: 0 | K31: 29-Apr-26 A | M31: 46141 | N31: 0
A32: MLTX-02-004-MS-1050 | B32: Completion of Mobilization | C32: Completed | D32: 0 | E32: 1 | F32: 1 | G32: 1 | H32: 0 | I32: 0 | K32: 02-Jun-26 A | M32: 46184 | N32: 0
A33: MLTX-02-004-MS-1120 | B33: Completion of Levelling Works | C33: Not Started | D33: 0 | E33: 0 | F33: 1 | G33: 0 | H33: 0 | I33: 0 | K33: 46187 | M33: 46187 | N33: 0
A34: MLTX-02-004-MS-1100 | B34: Completion of Engineering | C34: Not Started | D34: 0 | E34: 0 | F34: 1 | G34: 0 | H34: 0 | I34: 0 | K34: 46202 | M34: 46202 | N34: 0
A35: MLTX-02-004-MS-1130 | B35: Completion of Toilet Building | C35: Not Started | D35: 0 | E35: 0 | F35: 0 | G35: 0 | H35: 0 | I35: 0 | K35: 46292 | M35: 46292 | N35: 0
A36: MLTX-02-004-MS-1150 | B36: Completion of Natural Landscape Works | C36: Not Started | D36: 0 | E36: 0 | F36: 0 | G36: 0 | H36: 0 | I36: 0 | K36: 46413 | M36: 46413 | N36: 0
A37: MLTX-02-004-MS-1140 | B37: Completion of Playground Area | C37: Not Started | D37: 0 | E37: 0 | F37: 0 | G37: 0 | H37: 0 | I37: 0 | K37: 46445 | M37: 46445 | N37: 0
A38: MLTX-02-004-MS-1160 | B38: Completion of Asir Works | C38: Not Started | D38: 0 | E38: 0 | F38: 0 | G38: 0 | H38: 0 | I38: 0 | K38: 46467 | M38: 46467 | N38: 0
A39: MLTX-02-004-MS-1170 | B39: Completion of Jazan Works | C39: Not Started | D39: 0 | E39: 0 | F39: 0 | G39: 0 | H39: 0 | I39: 0 | K39: 46467 | M39: 46467 | N39: 0
A40: MLTX-02-004-MS-1180 | B40: Completion of Jeddah Works | C40: Not Started | D40: 0 | E40: 0 | F40: 0 | G40: 0 | H40: 0 | I40: 0 | K40: 46467 | M40: 46467 | N40: 0
A41: MLTX-02-004-MS-1070 | B41: Completion of Testing & Commissioning | C41: Not Started | D41: 0 | E41: 0 | F41: 0 | G41: 0 | H41: 0 | I41: 0 | K41: 46467 | M41: 46467 | N41: 0

Sheet Progress
A1: Project Scope Statement | B1: Playground Initiative for Western Region (Asir - Jazan - Jeddah)
A4: Earned Value Progress (SAR) | L4: Physical Progress (Effort)
A5: WBS | C5: BOQ Value (SAR) | D5: % Wt. | E5: Weekly (SAR) | H5: To Date (SAR) | J5: Actual % | L5: Budgeted | M5: % Wt. | N5: Weekly Physical Progress | P5: To Date Physical Progress | T5: Last Week Cost (SAR) | V5: Last Week Physical Progress
E6: Planned | F6: Earned | G6: Original Plan | H6: Planned | I6: Earned | L6: (Manhours) | N6: Planned | O6: Earned | P6: Planned | Q6: Earned | T6: Planned | U6: Earned | V6: Planned | W6: Earned
A7: Moblization | C7: 0 | E7: 0 | F7: =I7-U7 -> 0 | G7: 0 | H7: 0 | I7: 0 | J7: =I7/$C$25 -> 0 | L7: 12659 | M7: =L7/$L$25 -> 0.031160232 | N7: =P7-V7 -> 0 | O7: =Q7-W7 -> 0 | P7: =O48 -> 12658.6 | Q7: =N48 -> 12658.6 | T7: 0 | U7: 0 | V7: =O34 -> 12658.6 | W7: =N34 -> 12658.6
A8: Engineering | C8: 0 | D8: =C8/$C$25 -> 0 | E8: =H8-T8 -> 0 | F8: =I8-U8 -> 0 | G8: 0 | H8: 0 | I8: 0 | J8: =I8/$C$25 -> 0 | L8: 21299 | M8: =L8/$L$25 -> 0.052427662 | N8: =P8-V8 -> 0 | O8: =Q8-W8 -> 80.5 | P8: =O49 -> 21299.5 | Q8: =N49 -> 21009.7 | V8: =O35 -> 21299.5 | W8: =N35 -> 20929.2
A9: Procurment | C9: 0 | D9: =C9/$C$25 -> 0 | E9: =H9-T9 -> 0 | F9: =I9-U9 -> 0 | G9: 0 | H9: 0 | I9: 0 | J9: =I9/$C$25 -> 0 | L9: 51273 | M9: =L9/$L$25 -> 0.12620891 | N9: =P9-V9 -> 296.71 | O9: =Q9-W9 -> 5000 | P9: =O50 -> 50732.3 | Q9: =N50 -> 31870.4 | V9: =O36 -> 50435.59 | W9: =N36 -> 26870.4 | Z9: =W9-Q9 -> -5000
A10: Construction | C10: 33793604 | D10: =C10/$C$25 -> 1 | E10: =H10-T10 -> 1649688.5 | F10: =I10-U10 -> 821987.39 | G10: 3561002.2 | H10: =L51 -> 13223723 | I10: =K51 -> 11959715 | J10: =I10/$C$25 -> 0.35390468 | L10: 299660 | M10: =L10/$L$25 -> 0.73761554 | N10: =P10-V10 -> 16187.26 | O10: =Q10-W10 -> 8807.6 | P10: =O51 -> 122605.52 | Q10: =N51 -> 106759.6 | T10: =L37 -> 11574034 | U10: =K37 -> 11137727 | V10: =O37 -> 106418.26 | W10: =N37 -> 97952
A11: Jazan Region | C11: 10680072 | D11: =C11/$C$25 -> 0.31603825 | E11: =H11-T11 -> 401113.04 | F11: =I11-U11 -> 199957.72 | G11: 794325.94 | H11: =L52 -> 3951358.3 | I11: =K52 -> 2669083.7 | J11: =I11/$C$25 -> 0.07898192 | L11: 102280 | M11: =L11/$L$25 -> 0.25176306 | N11: =P11-V11 -> 5152.78 | O11: =Q11-W11 -> 4475.4 | P11: =O52 -> 45532.83 | Q11: =N52 -> 24825.4 | T11: =L38 -> 3550245.3 | U11: =K38 -> 2469126 | V11: =O38 -> 40380.05 | W11: =N38 -> 20350
A12: Asir Region | C12: 10578073 | D12: =C12/$C$25 -> 0.31301997 | E12: =H12-T12 -> 617430.85 | F12: =I12-U12 -> 300428.38 | G12: 1310370.1 | H12: =L53 -> 3063276.7 | I12: =K53 -> 4049399.2 | J12: =I12/$C$25 -> 0.11982738 | L12: 96810 | M12: =L12/$L$25 -> 0.23829861 | N12: =P12-V12 -> 7222.43 | O12: =Q12-W12 -> 1151.2 | P12: =O53 -> 40471.12 | Q12: =N53 -> 39573.2 | T12: =L39 -> 2445845.8 | U12: =K39 -> 3748970.9 | V12: =O39 -> 33248.69 | W12: =N39 -> 38422
A13: Jeddah Region | C13: 12535460 | D13: =C13/$C$25 -> 0.37094178 | E13: =H13-T13 -> 631144.59 | F13: =I13-U13 -> 321601.29 | G13: 1456306.1 | H13: =L54 -> 6209087.6 | I13: =K54 -> 5241231.7 | J13: =I13/$C$25 -> 0.15509537 | L13: 100570 | M13: =L13/$L$25 -> 0.24755388 | N13: =P13-V13 -> 3812.05 | O13: =Q13-W13 -> 3181 | P13: =O54 -> 36601.57 | Q13: =N54 -> 42361 | T13: =L40 -> 5577943 | U13: =K40 -> 4919630.4 | V13: =O40 -> 32789.52 | W13: =N40 -> 39180
A14: Testing & Commissioning | C14: 0 | D14: =C14/$C$25 -> 0 | E14: =H14-T14 -> 0 | F14: =I14-U14 -> 0 | G14: 0 | H14: 0 | I14: 0 | J14: =I14/$C$25 -> 0 | L14: 12818 | M14: =L14/$L$25 -> 0.031551612 | N14: =P14-V14 -> 0 | O14: =Q14-W14 -> 0 | P14: =O55 -> 0 | Q14: =N55 -> 0 | T14: 0 | V14: 0 | W14: 0
A15: Close-Out | C15: 0 | D15: =C15/$C$25 -> 0 | E15: =H15-T15 -> 0 | F15: =I15-U15 -> 0 | G15: 0 | H15: 0 | I15: 0 | J15: =I15/$C$25 -> 0 | L15: 8546 | M15: =L15/$L$25 -> 0.021036049 | N15: =P15-V15 -> 0 | O15: =Q15-W15 -> 0 | P15: =O56 -> 0 | Q15: =N56 -> 0 | V15: 0 | W15: 0
O16: =Q16-W16 -> 0 | P16: =O57 -> 0 | Q16: =N57 -> 0
O17: =Q17-W17 -> 0
O18: =Q18-W18 -> 0
O19: =Q19-W19 -> 0
O20: =Q20-W20 -> 0
O21: =Q21-W21 -> 0
E22: =H22-T22 -> 0 | F22: =I22-U22 -> 0 | N22: =P22-V22 -> 0 | O22: =Q22-W22 -> 0
E23: =H23-T23 -> 0 | F23: =I23-U23 -> 0 | N23: =P23-V23 -> 0 | O23: =Q23-W23 -> 0
E24: =H24-T24 -> 0 | F24: =I24-U24 -> 0 | N24: =P24-V24 -> 0 | O24: =Q24-W24 -> 0
B25: Total | C25: =C7+C8+C9+C11+C12+C13+C14+C15+C16+C17+C18+C19+C20+C21 -> 33793604 | D25: =D7+D8+D9+D11+D12+D13+D14+D15+D16+D17+D18+D19+D20+D21 -> 1 | E25: =E7+E8+E9+E11+E12+E13+E14+E15+E16+E17+E18+E19+E20+E21 -> 1649688.5 | F25: =F7+F8+F9+F11+F12+F13+F14+F15+F16+F17+F18+F19+F20+F21 -> 821987.39 | G25: =G7+G8+G9+G11+G12+G13+G14+G15+G16+G17+G18+G19+G20+G21 -> 3561002.2 | H25: =H7+H8+H9+H11+H12+H13+H14+H15+H16+H17+H18+H19+H20+H21 -> 13223723 | I25: =I7+I8+I9+I11+I12+I13+I14+I15+I16+I17+I18+I19+I20+I21 -> 11959715 | J25: =I25/$C$25 -> 0.35390468 | L25: =L7+L8+L9+L11+L12+L13+L14+L15+L16+L17+L18+L19+L20+L21 -> 406255 | M25: =M7+M8+M9+M11+M12+M13+M14+M15+M16+M17+M18+M19+M20+M21 -> 1 | N25: =N7+N8+N9+N11+N12+N13+N14+N15+N16+N17+N18+N19+N20+N21 -> 16483.97 | O25: =O7+O8+O9+O11+O12+O13+O14+O15+O16+O17+O18+O19+O20+O21 -> 13888.1 | P25: =P7+P8+P9+P11+P12+P13+P14+P15+P16+P17+P18+P19+P20+P21 -> 207295.92 | Q25: =Q7+Q8+Q9+Q11+Q12+Q13+Q14+Q15+Q16+Q17+Q18+Q19+Q20+Q21 -> 172298.3 | T25: =T7+T8+T9+T11+T12+T13+T14+T15+T16+T17+T18+T19+T20+T21 -> 11574034 | U25: =U7+U8+U9+U11+U12+U13+U14+U15+U16+U17+U18+U19+U20+U21 -> 11137727 | V25: =V7+V8+V9+V11+V12+V13+V14+V15+V16+V17+V18+V19+V20+V21 -> 190811.95 | W25: =W7+W8+W9+W11+W12+W13+W14+W15+W16+W17+W18+W19+W20+W21 -> 158410.2
G26: =G25/C25 -> 0.10537503 | H26: =H25/C25 -> 0.39130844 | I26: =I25/C25 -> 0.35390468 | P26: =P25/L25 -> 0.5102606 | Q26: =Q25/L25 -> 0.42411367
I27: =H26-I26 -> 0.037403761
