Workbook
Name \A: #REF!
Name \B: #REF!
Name \C: #REF!
Name \E: #REF!
Name \G: #REF!
Name \H: #REF!
Name \I: #REF!
Name \J: #REF!
Name \K: #REF!
Name \L: #REF!
Name \M: #REF!
Name \N: #REF!
Name \O: #REF!
Name \P: #REF!
Name \Q: #REF!
Name \S: #REF!
Name \T: #REF!
Name \U: #REF!
Name \V: #REF!
Name \W: #REF!
Name \X: #REF!
Name _________________________________HRS15: #REF!
Name _________________________________SUB15: #REF!
Name ________________________________HRS15: #REF!
Name ________________________________SUB15: #REF!
Name _______________________________HRS15: #REF!
Name _______________________________SUB15: #REF!
Name ______________________________HRS15: #REF!
Name ______________________________SUB15: #REF!
Name _____________________________HRS15: #REF!
Name _____________________________SUB15: #REF!
Name ____________________________HRS15: #REF!
Name ____________________________SUB15: #REF!
Name ___________________________HRS15: #REF!
Name ___________________________SUB15: #REF!
Name __________________________HRS15: #REF!
Name __________________________SUB15: #REF!
Name _________________________HRS15: #REF!
Name _________________________SUB15: #REF!
Name ________________________HRS15: #REF!
Name ________________________SUB15: #REF!
Name _______________________HRS15: #REF!
Name _______________________SUB15: #REF!
Name ______________________HRS15: #REF!
Name ______________________SUB15: #REF!
Name _____________________HRS15: #REF!
Name _____________________SUB15: #REF!
Name ____________________HRS15: #REF!
Name ____________________SUB15: #REF!
Name ___________________HRS15: #REF!
Name ___________________SUB15: #REF!
Name __________________HRS15: #REF!
Name __________________SUB15: #REF!
Name _________________HRS15: #REF!
Name _________________SUB15: #REF!
Name ________________HRS15: #REF!
Name ________________SUB15: #REF!
Name _______________HRS15: #REF!
Name _______________SUB15: #REF!
Name ______________HRS15: #REF!

Sheet General Information
C3: Weekly Progress Report - Construction Projects | E3: 46307
C4: Contract General Information
C5: Project Name | D5: Development Industrial City-Alkharj
C6: Project ID | D6: 3121
C7: Contractor | D7: Moffreh Group
C8: Consultant | D8: EGIS
C9: Stage | D9: 44th Week
C10: Modon PM | D10: Rakan Alotaibi
C11: Key Dates
C12: Contract Award Date | D12: 45970
C13: Contract Sign Date | D13: 45977
C14: Site Handover Date | D14: 45994
C15: Original Completion | D15: 46723
C16: Contract Award Date (Hijri) | D16: =D12 -> 45970
C17: Contract Sign Date (Hijri) | D17: =D13 -> 45977
C18: Site Handover Date (Hijri) | D18: =D14 -> 45994
C19: Original Completion (Hijri) | D19: =D15 -> 46723
C20: Revised Completion Date | D20: 46723
C21: Committed Completion Date | D21: 46723
C22: Forecast Completion | D22: 46723
C23: Variance | D23: =D20-D22 -> 0

Sheet Weekly Progress Report
C3: MODON - Weekly Progress Report - Construction Projects | AG3: Data Date | AH3: ='General Information'!E3 -> 46307
C4: Contract General Information | I4: Key Dates | O4: Cost Summary (SR) | W4: Performance Summary | AC4: Project Scope
C5: Project Name | D5: Development Industrial City-Alkharj | I5: Contract Award | J5: ='General Information'!D12 -> 45970 | K5: Contract Award (Hijri) | L5: ='General Information'!D16 -> 45970 | M5: Revised Completion | N5: ='General Information'!D20 -> 46723 | O5: Original Contract Value | Q5: ='Invoice Log'!G5 -> 307891320 | S5: O&M Value (if any) | U5: ='Invoice Log'!K5 -> 0 | V5: EAC | W5: Plan Value | X5: =M19 -> 0.3327 | Y5: Phys. Plan Value | Z5: =Y19 -> 0.5138 | AA5: Quality Score | AB5: =+Quality!AC10 -> 0.91 | AC5: =+Progress!D3 -> Development of infrastructure networks in Al-Kharj industrial city, which is located almost 100 kilometers southeast of Riyadh, The project is comprised of two zones (A , B and Labor Community Area ), which have a total area of approximately 3.50 square kilometers
C6: Project ID | D6: ='General Information'!D6 -> 3121 | F6: Stage | G6: 1 | I6: Contract Sign | J6: ='General Information'!D13 -> 45977 | K6: Contract Sign (Hijri) | L6: ='General Information'!D17 -> 45977 | M6: Committed Completion | N6: 46723 | O6: Revised Contract Value | Q6: ='Invoice Log'!G6 -> 307891320 | S6: Submitted Invoices (Gross Value) | U6: ='Invoice Log'!K7 -> 49710656 | W6: Earned Value | X6: =N19 -> 0.344 | Y6: Phys. Earn Value | Z6: =Z19 -> 0.4573
C7: Contractor | D7: ='General Information'!D7 -> Moffreh Group | F7: Status | G7: 32 | I7: Site Handover | J7: 45994 | K7: Site Handover (Hijri) | L7: ='General Information'!D18 -> 45994 | M7: Forecast Completion | N7: 46723 | O7: Estimate At Completion Value | Q7: ='Invoice Log'!G7 -> 307891320 | S7: Penalities & Retention | U7: ='Invoice Log'!K8 -> 5082066 | W7: Variance | X7: =X6-X5 -> 0.011 | Y7: Variance | Z7: =AA19 -> -0.057 | AA7: Safety Score | AB7: =HSE!AF6 -> 0.93
C8: Consultant | D8: ='General Information'!D8 -> EGIS | F8: Modon PM | G8: ='General Information'!D10 -> Rakan Alotaibi | I8: Original Completion | J8: 46723 | K8: Original Completion (Hijri) | L8: ='General Information'!D19 -> 46723 | M8: Variance | N8: =N6-N7 -> 0 | O8: Potential Changes | Q8: ='Invoice Log'!G8 -> 0 | S8: FIR Value (up To date) | U8: =U6+12000000 -> 61710656 | W8: FIR % | X8: =U8/Q5 -> 0.2 | Y8: Invoiced % | Z8: =U6/Q5 -> 0.16146
C10: Progress Overview
C11: Earned Value Progress (SAR) | Q11: Physical Progress (Effort) | AC11: Earned Value Progress (%)
C12: WBS | E12: BOQ Value (SAR) | F12: % Wt. | G12: Weekly (SAR) | I12: To Date (SAR) | Q12: Budgeted | R12: % Wt. | S12: Weekly Physical Progress | W12: To Date Physical Progress
G13: Planned | H13: Earned | I13: Original Plan | J13: Revised Planned | K13: Earned | L13: Original Plan % | M13: Revised Planned % | N13: Earned % | O13: Variance | P13: SPI | Q13: (Manhours) | S13: Planned | T13: Earned | U13: Plan % | V13: Earned % | W13: Planned | X13: Earned | Y13: Plan % | Z13: Earned % | AA13: Variance | AB13: SPI
C14: =+Progress!C9 -> Engineering | E14: =+Progress!D9 -> 0 | F14: =IF(ISBLANK(E14),"",E14/$E$19) -> 0 | G14: =+Progress!F9 -> 0 | H14: =+Progress!G9 -> 0 | I14: =Progress!H9 -> 0 | J14: =Progress!I9 -> 0 | K14: =+Progress!J9 -> 0 | L14: =IFERROR(IF(ISBLANK(I14),"",I14/E14),0) -> 0 | M14: =IFERROR(IF(ISBLANK(J14),"",J14/E14),0) -> 0 | N14: =IFERROR(IF(ISBLANK(K14),"",K14/E14),0) -> 0 | O14: =IFERROR(N14-M14,"") -> 0 | P14: =IFERROR(N14/M14,"") | Q14: =+Progress!K9 -> 8031948 | R14: =+Progress!L9 -> 0.03 | S14: =+Progress!M9 -> 0 | T14: =+Progress!N9 -> 0 | U14: =IFERROR(Progress!F9/Progress!D9,0) -> 0 | V14: =IFERROR(Progress!G9/Progress!D9,0) -> 0 | W14: =+Progress!O9 -> 8031948 | X14: =+Progress!P9 -> 8031948 | Y14: =IFERROR(IF(ISBLANK(W14),"",W14/Q14),0) -> 1 | Z14: =IFERROR(IF(ISBLANK(X14),"",X14/Q14),0) -> 1 | AA14: =Z14-Y14 -> 0 | AB14: =Z14/Y14 -> 1
C15: =+Progress!C10 -> Procurement | E15: =+Progress!D10 -> 0 | F15: =IF(ISBLANK(E15),"",E15/$E$19) -> 0 | G15: =+Progress!F10 -> 0 | H15: =+Progress!G10 -> 0 | I15: =Progress!H10 -> 0 | J15: =Progress!I10 -> 0 | K15: =+Progress!J10 -> 0 | L15: =IFERROR(IF(ISBLANK(I15),"",I15/E15),0) -> 0 | M15: =IFERROR(IF(ISBLANK(J15),"",J15/E15),0) -> 0 | N15: =IFERROR(IF(ISBLANK(K15),"",K15/E15),0) -> 0 | O15: =IFERROR(N15-M15,"") -> 0 | P15: =IFERROR(N15/M15,"") | Q15: =+Progress!K10 -> 53546316 | R15: =+Progress!L10 -> 0.2 | S15: =+Progress!M10 -> 1540097 | T15: =+Progress!N10 -> 4058810 | U15: =IFERROR(Progress!F10/Progress!D10,0) -> 0 | V15: =IFERROR(Progress!G10/Progress!D10,0) -> 0 | W15: =+Progress!O10 -> 46066045 | X15: =+Progress!P10 -> 35040709 | Y15: =IFERROR(IF(ISBLANK(W15),"",W15/Q15),0) -> 0.86 | Z15: =IFERROR(IF(ISBLANK(X15),"",X15/Q15),0) -> 0.654 | AA15: =Z15-Y15 -> -0.206 | AB15: =Z15/Y15 -> 0.76046512
C16: =+Progress!C11 -> Construction | E16: =+Progress!D11 -> 239411880 | F16: =IF(ISBLANK(E16),"",E16/$E$19) -> 0.778 | G16: =+Progress!F11 -> 2537765.9 | H16: =+Progress!G11 -> 2801119 | I16: =Progress!H11 -> 173573613 | J16: =Progress!I11 -> 1.0244434e+08 | K16: =+Progress!J11 -> 1.0591582e+08 | L16: =IFERROR(IF(ISBLANK(I16),"",I16/E16),0) -> 0.725 | M16: =IFERROR(IF(ISBLANK(J16),"",J16/E16),0) -> 0.428 | N16: =IFERROR(IF(ISBLANK(K16),"",K16/E16),0) -> 0.442 | O16: =IFERROR(N16-M16,"") -> 0.014 | P16: =IFERROR(N16/M16,"") -> 1.03 | Q16: =+Progress!K11 -> 179380160 | R16: =+Progress!L11 -> 0.67 | S16: =+Progress!M11 -> 1914427 | T16: =+Progress!N11 -> 2098748 | U16: =Progress!F11/Progress!D11 -> 0.011 | V16: =Progress!G11/Progress!D11 -> 0.012 | W16: =+Progress!O11 -> 76761914 | X16: =+Progress!P11 -> 79357783 | Y16: =IFERROR(IF(ISBLANK(W16),"",W16/Q16),0) -> 0.428 | Z16: =IFERROR(IF(ISBLANK(X16),"",X16/Q16),0) -> 0.442 | AA16: =Z16-Y16 -> 0.014 | AB16: =Z16/Y16 -> 1.0327103
C17: =+Progress!C12 -> Testing & Commissioning | E17: =+Progress!D12 -> 0 | F17: =IF(ISBLANK(E17),"",E17/$E$19) -> 0 | G17: =+Progress!F12 -> 0 | H17: =+Progress!G12 -> 0 | I17: =Progress!H12 -> 0 | J17: =Progress!I12 -> 0 | K17: =+Progress!J12 -> 0 | L17: =IFERROR(IF(ISBLANK(I17),"",I17/E17),0) -> 0 | M17: =IFERROR(IF(ISBLANK(J17),"",J17/E17),0) -> 0 | N17: =IFERROR(IF(ISBLANK(K17),"",K17/E17),0) -> 0 | O17: =IFERROR(N17-M17,"") -> 0 | P17: =IFERROR(N17/M17,"") | Q17: =+Progress!K12 -> 26773158 | R17: =+Progress!L12 -> 0.1 | S17: =+Progress!M12 -> 0 | T17: =+Progress!N12 -> 0 | U17: =IFERROR(Progress!F12/Progress!D12,0) -> 0 | V17: =IFERROR(Progress!G12/Progress!D12,0) -> 0 | W17: =+Progress!O12 -> 6693290 | X17: =+Progress!P12 -> 0 | Y17: =IFERROR(IF(ISBLANK(W17),"",W17/Q17),0) -> 0.25 | Z17: =IFERROR(IF(ISBLANK(X17),"",X17/Q17),0) -> 0 | AA17: =Z17-Y17 -> -0.25 | AB17: 0
C18: =+Progress!C13 -> Close Out | E18: =+Progress!D13 -> 68479440 | F18: =IF(ISBLANK(E18),"",E18/$E$19) -> 0.222 | G18: =+Progress!F13 -> 0 | H18: =+Progress!G13 -> 0 | I18: =Progress!H13 -> 0 | J18: =Progress!I13 -> 0 | K18: =+Progress!J13 -> 0 | L18: =IFERROR(IF(ISBLANK(I18),"",I18/E18),0) -> 0 | M18: =IFERROR(IF(ISBLANK(J18),"",J18/E18),0) -> 0 | N18: =IFERROR(IF(ISBLANK(K18),"",K18/E18),0) -> 0 | O18: =IFERROR(N18-M18,"") -> 0 | P18: =IFERROR(N18/M18,"") | Q18: =+Progress!K13 -> 0 | R18: =+Progress!L13 -> 0 | S18: =+Progress!M13 -> 0 | T18: =+Progress!N13 -> 0 | U18: 0 | V18: 0 | W18: =+Progress!O13 -> 0 | X18: =+Progress!P13 -> 0 | Y18: =IFERROR(IF(ISBLANK(W18),"",W18/Q18),0) -> 0 | Z18: =IFERROR(IF(ISBLANK(X18),"",X18/Q18),0) -> 0 | AA18: =Z18-Y18 -> 0 | AB18: 0
D19: Total | E19: =SUM(E14:E18) -> 307891320 | F19: =SUM(F14:F18) -> 1 | G19: =SUM(G14:G18) -> 2537765.9 | H19: =SUM(H14:H18) -> 2801119 | I19: =SUM(I14:I18) -> 173573613 | J19: =SUM(J14:J18) -> 1.0244434e+08 | K19: =SUM(K14:K18) -> 1.0591582e+08 | L19: =IFERROR(IF(ISBLANK(I19),"",I19/E19),0) -> 0.5637 | M19: =IFERROR(IF(ISBLANK(J19),"",J19/E19),0) -> 0.3327 | N19: =IFERROR(IF(ISBLANK(K19),"",K19/E19),0) -> 0.344 | O19: =+N19-M19 -> 0.0113 | P19: =N19/M19 -> 1.03 | Q19: =SUM(Q14:Q18) -> 267731582 | R19: =SUM(R14:R18) -> 1 | S19: =SUM(S14:S18) -> 3454524 | T19: =SUM(T14:T18) -> 6157558 | U19: =IFERROR(IF(ISBLANK(S19),"",S19/Q19),0) -> 0.0129 | V19: =IFERROR(IF(ISBLANK(T19),"",T19/Q19),0) -> 0.023 | W19: =SUM(W14:W18) -> 137553197 | X19: =SUM(X14:X18) -> 122430440 | Y19: =IFERROR(IF(ISBLANK(W19),"",W19/Q19),0) -> 0.5138 | Z19: =IFERROR(IF(ISBLANK(X19),"",X19/Q19),0) -> 0.4573 | AA19: =+Z19-Y19 -> -0.0565 | AB19: =Z19/Y19 -> 0.89
AC20: Construction Milestones
AC21: Item No. | AD21: Milestones | AF21: Original (Baseline) | AG21: Latest Plan | AH21: Forecast | AI21: Days Change
AC22: =+Milestones!C5 -> 1 | AD22: =+Milestones!D5 -> Site Handover Date | AF22: =+Milestones!E5 -> 45994 | AG22: =AF22 -> 45994 | AH22: =AF22 -> 45994 | AI22: =+Milestones!H5 -> 0
AC23: =+Milestones!C6 -> 2 | AD23: =+Milestones!D6 -> Complete Mobilization | AF23: =+Milestones!E6 -> 46024 | AG23: =AF23 -> 46024 | AH23: =AF23 -> 46024 | AI23: =+Milestones!H6 -> 0
AC24: =+Milestones!C7 -> 3 | AD24: =+Milestones!D7 -> Road works | AF24: =+Milestones!E7 -> 46297 | AG24: =AF24 -> 46297 | AH24: =AF24 -> 46297 | AI24: =+Milestones!H7 -> -36
AC25: =+Milestones!C8 -> 4 | AD25: =+Milestones!D8 -> Medium voltage network | AF25: =+Milestones!E8 -> 46297 | AG25: =AF25 -> 46297 | AH25: =AF25 -> 46297 | AI25: =+Milestones!H8 -> -29
AC26: =+Milestones!C9 -> 5 | AD26: =+Milestones!D9 -> All Networks | AF26: =+Milestones!E9 -> 46420 | AG26: =AF26 -> 46420 | AH26: =AF26 -> 46420 | AI26: =+Milestones!H9 -> 0
AC27: =+Milestones!C10 -> 6 | AD27: =+Milestones!D10 -> Project Handover | AF27: =+Milestones!E10 -> 46723 | AG27: =AF27 -> 46723 | AH27: =AF27 -> 46723 | AI27: =+Milestones!H10 -> 0
C43: Performance overview
C44: Submittals Status | N44: Quality | Y44: Safety
C45: Design | N45: Quality Reports | Y45: Safety Statistics | AG45: Proactive Vs Reactive Actions Taken
C46: Item Per WBS | E46: Total | F46: Total Submitted Drawings | K46: Remaining | L46: Pending | M46: Total Submittals | N46: Quality Reports | P46: Issued | Q46: Closed | R46: Pending | S46: Avg. Closing (Days) | T46: Pending | Y46: Category | Z46: Item | AB46: This Week | AD46: This Month | AE46: Year to Date | AF46: Cumulative
F47: A | G47: B | H47: C | I47: D | J47: Processed | T47: 0-10 Days | U47: 11-20 Days | V47: 21-30 Days | W47: 31-60 Days | X47: > 60 Days
C48: =#REF! -> #REF! | E48: =IF(#REF!="","",#REF!) -> #REF! | F48: =IF(#REF!="","",#REF!) -> #REF! | G48: =IF(#REF!="","",#REF!) -> #REF! | H48: =IF(#REF!="","",#REF!) -> #REF! | I48: =IF(#REF!="","",#REF!) -> #REF! | J48: =IF(#REF!="","",#REF!) -> #REF! | K48: =IF(#REF!="","",#REF!) -> #REF! | L48: =IF(#REF!="","",#REF!) -> #REF! | M48: =IF(#REF!="","",#REF!) -> #REF! | Y48: General | Z48: =#REF! -> #REF! | AB48: =#REF! -> #REF! | AD48: =#REF! -> #REF! | AE48: =#REF! -> #REF! | AF48: =#REF! -> #REF! | AI48: =+SUM(AF59:AF63) -> #REF!
C49: =#REF! -> #REF! | E49: =IF(#REF!="","",#REF!) -> #REF! | F49: =IF(#REF!="","",#REF!) -> #REF! | G49: =IF(#REF!="","",#REF!) -> #REF! | H49: =IF(#REF!="","",#REF!) -> #REF! | I49: =IF(#REF!="","",#REF!) -> #REF! | J49: =IF(#REF!="","",#REF!) -> #REF! | K49: =IF(#REF!="","",#REF!) -> #REF! | L49: =IF(#REF!="","",#REF!) -> #REF! | M49: =IF(#REF!="","",#REF!) -> #REF! | N49: Non Conformance (NCR) | P49: 3 | Q49: 3 | R49: 0 | S49: =#REF! -> #REF! | T49: 0 | U49: =#REF! -> #REF! | V49: =#REF! -> #REF! | W49: =#REF! -> #REF! | X49: =#REF! -> #REF! | Z49: =#REF! -> #REF! | AB49: =#REF! -> #REF! | AD49: =#REF! -> #REF! | AE49: =#REF! -> #REF! | AF49: =#REF! -> #REF! | AI49: =SUM(AF50:AF58) -> #REF!
C50: =#REF! -> #REF! | E50: =IF(#REF!="","",#REF!) -> #REF! | F50: =IF(#REF!="","",#REF!) -> #REF! | G50: =IF(#REF!="","",#REF!) -> #REF! | H50: =IF(#REF!="","",#REF!) -> #REF! | I50: =IF(#REF!="","",#REF!) -> #REF! | J50: =IF(#REF!="","",#REF!) -> #REF! | K50: =IF(#REF!="","",#REF!) -> #REF! | L50: =IF(#REF!="","",#REF!) -> #REF! | M50: =IF(#REF!="","",#REF!) -> #REF! | N50: Site Instruction (SIR) | P50: =#REF! -> #REF! | Q50: =#REF! -> #REF! | R50: =#REF! -> #REF! | S50: =#REF! -> #REF! | T50: =#REF! -> #REF! | U50: =#REF! -> #REF! | V50: =#REF! -> #REF! | W50: =#REF! -> #REF! | X50: =#REF! -> #REF! | Y50: Reactive | Z50: =#REF! -> #REF! | AB50: =#REF! -> #REF! | AD50: =#REF! -> #REF! | AE50: =#REF! -> #REF! | AF50: =#REF! -> #REF!
C51: =#REF! -> #REF! | E51: =IF(#REF!="","",#REF!) -> #REF! | F51: =IF(#REF!="","",#REF!) -> #REF! | G51: =IF(#REF!="","",#REF!) -> #REF! | H51: =IF(#REF!="","",#REF!) -> #REF! | I51: =IF(#REF!="","",#REF!) -> #REF! | J51: =IF(#REF!="","",#REF!) -> #REF! | K51: =IF(#REF!="","",#REF!) -> #REF! | L51: =IF(#REF!="","",#REF!) -> #REF! | M51: =IF(#REF!="","",#REF!) -> #REF! | N51: Material Inspection (MIR) | P51: =#REF! -> #REF! | Q51: =#REF! -> #REF! | R51: =#REF! -> #REF! | S51: =#REF! -> #REF! | T51: =#REF! -> #REF! | U51: =#REF! -> #REF! | V51: =#REF! -> #REF! | W51: =#REF! -> #REF! | X51: =#REF! -> #REF! | Z51: =#REF! -> #REF! | AB51: =#REF! -> #REF! | AD51: =#REF! -> #REF! | AE51: =#REF! -> #REF! | AF51: =#REF! -> #REF!
C52: =#REF! -> #REF! | E52: =IF(#REF!="","",#REF!) -> #REF! | F52: =IF(#REF!="","",#REF!) -> #REF! | G52: =IF(#REF!="","",#REF!) -> #REF! | H52: =IF(#REF!="","",#REF!) -> #REF! | I52: =IF(#REF!="","",#REF!) -> #REF! | J52: =IF(#REF!="","",#REF!) -> #REF! | K52: =IF(#REF!="","",#REF!) -> #REF! | L52: =IF(#REF!="","",#REF!) -> #REF! | M52: =IF(#REF!="","",#REF!) -> #REF! | N52: Field Inspection (FIR) | P52: =#REF! -> #REF! | Q52: =#REF! -> #REF! | R52: =#REF! -> #REF! | S52: =#REF! -> #REF! | T52: =#REF! -> #REF! | U52: =#REF! -> #REF! | V52: =#REF! -> #REF! | W52: =#REF! -> #REF! | X52: =#REF! -> #REF! | Z52: =#REF! -> #REF! | AB52: =#REF! -> #REF! | AD52: =#REF! -> #REF! | AE52: =#REF! -> #REF! | AF52: =#REF! -> #REF!
C53: TOTAL | E53: =SUM(E48:E52) -> #REF! | F53: =SUM(F48:F52) -> #REF! | G53: =SUM(G48:G52) -> #REF! | H53: =SUM(H48:H52) -> #REF! | I53: =SUM(I48:I52) -> #REF! | J53: =SUM(J48:J52) -> #REF! | K53: =SUM(K48:K52) -> #REF! | L53: =SUM(L48:L52) -> #REF! | M53: =SUM(M48:M52) -> #REF! | N53: Key Submittals Approval Status | Z53: =#REF! -> #REF! | AB53: =#REF! -> #REF! | AD53: =#REF! -> #REF! | AE53: =#REF! -> #REF! | AF53: =#REF! -> #REF!
C54: Material Approval | N54: 1 Quality Plan Approval | Q54: ='General Information'!#REF! -> #REF! | S54: 6 Baseline Approval | W54: ='General Information'!#REF! -> #REF! | Z54: =#REF! -> #REF! | AB54: =#REF! -> #REF! | AD54: =#REF! -> #REF! | AE54: =#REF! -> #REF! | AF54: =#REF! -> #REF! | AG54: Total Hours Worked Vs Safe Hours Worked
C55: Item Per WBS | E55: Total | F55: Total Submitted Material | K55: Remaining to approve | L55: Pending | M55: Total Submittals | N55: 2 Quality Plan Last Up | Q55: ='General Information'!#REF! -> #REF! | S55: 7 No of Approved Version of Schedule | W55: ='General Information'!#REF! -> #REF! | Z55: =#REF! -> #REF! | AB55: =#REF! -> #REF! | AD55: =#REF! -> #REF! | AE55: =#REF! -> #REF! | AF55: =#REF! -> #REF!
F56: A | G56: B | H56: C | I56: D | J56: Processed | K56: with Designer | N56: 3 Safety Plan Approval | Q56: ='General Information'!#REF! -> #REF! | S56: 8 Last Approved Schedule | W56: ='General Information'!#REF! -> #REF! | Z56: =#REF! -> #REF! | AB56: =#REF! -> #REF! | AD56: =#REF! -> #REF! | AE56: =#REF! -> #REF! | AF56: =#REF! -> #REF!
C57: =#REF! -> #REF! | E57: =IF(#REF!="","",#REF!) -> #REF! | F57: =IF(#REF!="","",#REF!) -> #REF! | G57: =IF(#REF!="","",#REF!) -> #REF! | H57: =IF(#REF!="","",#REF!) -> #REF! | I57: =IF(#REF!="","",#REF!) -> #REF! | J57: =IF(#REF!="","",#REF!) -> #REF! | K57: =IF(#REF!="","",#REF!) -> #REF! | L57: =IF(#REF!="","",#REF!) -> #REF! | M57: =IF(#REF!="","",#REF!) -> #REF! | N57: 4 Safety Plan Last Up | Q57: ='General Information'!#REF! -> #REF! | S57: 9 BOQ Approval Date | W57: ='General Information'!#REF! -> #REF! | Z57: =#REF! -> #REF! | AB57: =#REF! -> #REF! | AD57: =#REF! -> #REF! | AE57: =#REF! -> #REF! | AF57: =#REF! -> #REF!
C58: =#REF! -> #REF! | E58: =IF(#REF!="","",#REF!) -> #REF! | F58: =IF(#REF!="","",#REF!) -> #REF! | G58: =IF(#REF!="","",#REF!) -> #REF! | H58: =IF(#REF!="","",#REF!) -> #REF! | I58: =IF(#REF!="","",#REF!) -> #REF! | J58: =IF(#REF!="","",#REF!) -> #REF! | K58: =IF(#REF!="","",#REF!) -> #REF! | L58: =IF(#REF!="","",#REF!) -> #REF! | M58: =IF(#REF!="","",#REF!) -> #REF! | N58: 5 Construction Plan Approval | Q58: ='General Information'!#REF! -> #REF! | S58: 10 No of Approved Version of BOQ | W58: ='General Information'!#REF! -> #REF! | Z58: =#REF! -> #REF! | AB58: =#REF! -> #REF! | AD58: =#REF! -> #REF! | AE58: =#REF! -> #REF! | AF58: =#REF! -> #REF!
...

Sheet SPI
C3: SPI Weekly Interval
D5: Week 1 14.Sep.2026 | E5: Week 2 21.Sep.2026 | F5: Week 3 28.Sep.2026 | G5: Week 4 05.Oct.2026 | H5: Week 5 012.Oct.2026
C6: Planned % | D6: 0.297 | E6: 0.31 | F6: 0.319 | G6: 0.325 | H6: =+'Weekly Progress Report'!M19 -> 0.333
C7: Earned % | D7: 0.309 | E7: 0.32 | F7: 0.329 | G7: 0.335 | H7: =+'Weekly Progress Report'!N19 -> 0.344 | L7: =+H7-G7 -> 0.009
C8: SPI | D8: 1.04 | E8: 1.03 | F8: 1.03 | G8: 1.03 | H8: =H7/H6 -> 1.03 | N8: =+G7-F7 -> 0.006
C31: Activity Name | D31: Start | E31: Finish | F31: Spreadsheet Field | G31: 46025 | H31: 46032 | I31: 46039 | J31: 46046 | K31: 46053 | L31: 46060 | M31: 46067 | N31: 46074 | O31: 46081 | P31: 46088 | Q31: 46095 | R31: 46102 | S31: 46109 | T31: 46116 | U31: 46123 | V31: 46130 | W31: 46137 | X31: 46144 | Y31: 46151 | Z31: 46158 | AA31: 46165 | AB31: 46172 | AC31: 46179 | AD31: 46186 | AE31: 46193 | AF31: 46200 | AG31: 46207 | AH31: 46214 | AI31: 46221 | AJ31: 46228 | AK31: 46235 | AL31: 46242 | AM31: 46249 | AN31: 46256 | AO31: 46263 | AP31: 46270 | AQ31: 46277 | AR31: 46284 | AS31: 46291 | AT31: 46298 | AU31: 46305 | AV31: 46312 | AW31: 46319 | AX31: 46326 | AY31: 46333 | AZ31: 46340 | BA31: 46347 | BB31: 46354 | BC31: 46361 | BD31: 46368 | BE31: 46375 | BF31: 46382 | BG31: 46389 | BH31: 46396 | BI31: 46403 | BJ31: 46410 | BK31: 46417 | BL31: 46424 | BM31: 46431 | BN31: 46438 | BO31: 46445 | BP31: 46452 | BQ31: 46459 | BR31: 46466 | BS31: 46473 | BT31: 46480 | BU31: 46487 | BV31: 46494 | BW31: 46501 | BX31: 46508 | BY31: 46515 | BZ31: 46522 | CA31: 46529 | CB31: 46536 | CC31: 46543 | CD31: 46550 | CE31: 46557 | CF31: 46564 | CG31: 46571 | CH31: 46578 | CI31: 46585 | CJ31: 46592 | CK31: 46599 | CL31: 46606 | CM31: 46613 | CN31: 46620 | CO31: 46627 | CP31: 46634 | CQ31: 46641 | CR31: 46648 | CS31: 46655 | CT31: 46662 | CU31: 46669 | CV31: 46676 | CW31: 46683 | CX31: 46690 | CY31: 46697 | CZ31: 46704 | DA31: 46711 | DB31: 46718
C32: ICKMO1-cost unite | D32: 46025 | E32: 46723 | F32: Budgeted Units | G32: 629778.8 | H32: 817900.7 | I32: 1117672.1 | J32: 1784116.5 | K32: 2205084.5 | L32: 3042911.7 | M32: 3538639.3 | N32: 2840366.4 | O32: 3077668.8 | P32: 2799539 | Q32: 2407878.9 | R32: 1910111.4 | S32: 2315821.6 | T32: 2136115.2 | U32: 1765470.3 | V32: 2035664.2 | W32: 2793013.9 | X32: 1763311.5 | Y32: 1890899.8 | Z32: 1102104.9 | AA32: 918553.47 | AB32: 1121640.6 | AC32: 817572.93 | AD32: 642466.71 | AE32: 1008995.6 | AF32: 1174931 | AG32: 1435794.4 | AH32: 2239774.9 | AI32: 2646690 | AJ32: 3094901 | AK32: 3129603.4 | AL32: 3592896.7 | AM32: 4072913.6 | AN32: 4283580 | AO32: 4325302.1 | AP32: 3073364.6 | AQ32: 3471431.7 | AR32: 1517990.5 | AS32: 2124434.9 | AT32: 2116641.5 | AU32: 2766161.8 | AV32: 3036723.7 | AW32: 2980679.1 | AX32: 3154463.8 | AY32: 3361260.2 | AZ32: 3092750.6 | BA32: 2820097.4 | BB32: 1936116.4 | BC32: 1689048.5 | BD32: 1631346.6 | BE32: 1526831.3 | BF32: 1100100.4 | BG32: 669938.63 | BH32: 595679.44 | BI32: 1867307 | BJ32: 2399894.4 | BK32: 1702100.4 | BL32: 4419281.2 | BM32: 5394379.9 | BN32: 4040128.2 | BO32: 5770854.6 | BP32: 5412649.6 | BQ32: 6058633.8 | BR32: 5925758.5 | BS32: 6146311.5 | BT32: 4098294 | BU32: 2791974.4 | BV32: 2393701.3 | BW32: 2013645.3 | BX32: 1392043.1 | BY32: 1109050.6 | BZ32: 1148278.6 | CA32: 1150798.1 | CB32: 917220.47 | CC32: 1953712.5 | CD32: 2600851.4 | CE32: 1922527.9 | CF32: 2010710.9 | CG32: 1876874.4 | CH32: 1711927.2 | CI32: 2346170.6 | CJ32: 1162975.6 | CK32: 1496899.5 | CL32: 2137249.3 | CM32: 1766195 | CN32: 576780.31 | CO32: 457950 | CP32: 429942.57 | CQ32: 203059.3 | CR32: 154448.87 | CS32: 70202.61 | CT32: 8712.77 | DA32: 19849113 | DB32: 39698226
G33: =+G32+F33 -> 629778.8 | H33: =+H32+G33 -> 1447679.5 | I33: =+I32+H33 -> 2565351.6 | J33: =+J32+I33 -> 4349468.1 | K33: =+K32+J33 -> 6554552.6 | L33: =+L32+K33 -> 9597464.3 | M33: =+M32+L33 -> 13136104 | N33: =+N32+M33 -> 15976470 | ... DB33: =+DB32+DA33 -> 2.6773158e+08
G34: =+G33/267731582 -> 0.0023522768 | H34: =+H33/267731582 -> 0.0054072048 | I34: =+I33/267731582 -> 0.0095818042 | J34: =+J33/267731582 -> 0.01624563 | K34: =+K33/267731582 -> 0.024481806 | L34: =+L33/267731582 -> 0.035847337 | M34: =+M33/267731582 -> 0.049064453 | N34: =+N33/267731582 -> 0.05967346 | ... DB34: =+DB33/267731582 -> 1

Sheet Weekly Progress Photos
C3: Weekly Progress Photos | J3: Date | K3: ='General Information'!E3 -> 46307

Sheet HSE
C3: MODON HSE Site Inspection Report
C4: Date | F4: =+'General Information'!E3 -> 46307 | M4: Inspected By | X4: MODON PM Name | AB4: Eng\Rakan
C5: Project ID. | F5: KH1-02-007 | M5: Report No. | T5: KHJ1-02-007-MAH-ST9-1-SUV-FIR-37-00
C6: Project Name: | F6: Development of infrastructure in Kharj Industrial City | M6: Contractor | T6: MOFARREH GROUP | Y6: Safety Performance | AB6: =IF(X29>0,3,IF(M29>6,AD133,IF(E29>0,2,1)*1)*1) -> 2 | AF6: =(((COUNTIF(M13:R25,"1")+COUNTIF(AD13:AI25,"1"))*AS13)+(COUNTIF(M13:R25,"2")+COUNTIF(AD13:AI25,"2"))*AS14+(COUNTIF(M13:R25,"3")+COUNTIF(AD13:AI25,"3"))*AS15)/((COUNT(M13:R25)+COUNT(AD13:AI25))*100) -> 0.93
C8: Inspections are a snapshot in time and refer only to the practices and documentation observed at the time of the Inspection. It remains the responsibility of the Consultant and Contractor to ensure that all aspects of Health & Safety are suitably managed.
C9: 1 | E9: Good Practice | I9: 2 | J9: Need Improvement | U9: 3 | V9: Fail (Life Threatening Activity) / Comliance with Plan & Procedures | Y9: N/A | Z9: Atcitty Not Applicable for this Site Inspection Report
C11: No. | D11: Topic | L11: Wt. | M11: HSE Compliance | T11: No. | U11: Topi+U11:AB15c | AC11: Wt. | AD11: HSE Compliance
C13: 1 | D13: Access and Egress - (General access to site, segregated from vehicles, / Overhead protection, while entering into the building /Adequate lighting provided when dark or overnight work) | L13: 0.05 | M13: 2 | T13: 14 | U13: Scaffolding - (Temp. Scaffolding Work-platform (All types) - qualified scaffolder / Inspection / Tagged / Safe Access/egress / PTW/Falsework & Formwork) | AC13: 0.05 | AD13: 1 | AQ13: 1 | AS13: 100 | AV13: 1
C14: 2 | D14: Traffic Management - (Loading/unloading/sheeting/temp. routes/speed/parking/competence) | L14: 0.02 | M14: 1 | T14: 15 | U14: Scaffolding - (Temp. Scaffolding Work-platform (All types) - qualified scaffolder / Inspection / Tagged / Safe Access/egress / PTW/Falsework & Formwork) | AC14: 0.04 | AD14: N/A | AQ14: 2 | AS14: 75 | AV14: 2
C15: 3 | D15: Site Signage - (Project Notice Board & General Signage) | L15: 0.02 | M15: 1 | T15: 16 | U15: Mobile Elevated Work platform (MEWP) - (PTW/competence requirements/conditions/inspections/tagged/training/Full-body harness) | AC15: 0.04 | AD15: N/A | AQ15: 3 | AS15: 0 | AV15: 3
C16: 4 | D16: PPE Compliance - (Use, storage, stock, handling & checks - Head, Foot, Eye, Hearing) | L16: 0.05 | M16: 1 | T16: 17 | U16: Excavation & Trenches - (PTW/Edge protection/buffer zone/Slope/Benching/Shoring/Geo-tech report/Atmospheric hazards/Acess&egress/Emergency management / MS&RA/H.E) | AC16: 0.03 | AD16: 2 | AV16: N/A
C17: 5 | D17: Housekeeping - (Material correctly stored/Rubbish cleaned & removed daily/slips & trips hazards) | L17: 0.03 | M17: 1 | T17: 18 | U17: Confined Space - (PTW/Training/competence/Emergency Management/MS & RA/Safe access/egress) | AC17: 0.05 | AD17: N/A
C18: 6 | D18: Storage of Materials - (Transporting, storage, training and use - Combustible / Flammable / Hazardous substances (COSHH) | M18: N/A | T18: 19 | U18: Fire Protection - (Flammable/Oxy. LPG /Combustible separated/FE's/Flashback arrestor/Sparks & slags/Smoking area/PTW/Generators/MS & RA/Emergency Management) | AD18: 1 | AM18: Red | AN18: Serious injury or death (immediately)
C19: 7 | D19: Site Waste Management - (Hazardous waste /Combustible waste / Human waste / Construction waste - asphalt, cable, timber, paving roof sheeting tiles, plastic & bricks) | L19: 0.03 | M19: 1 | T19: 20 | U19: Health & Welfare - (Adequate drinking water/shaded - eating & rest area/washing & sanitary facilities/Certified FA/FA Box & Stock/adequate toilets/Ambulance) | AD19: 2 | AM19: Yellow | AN19: Minor or near miss (3 days to comply)
C20: 8 | D20: Health Surveillance - (Expose to excessive noise/vibration/dust/silica/CO/cement/radiation/extreme weather condition) | L20: 0.03 | M20: 1 | T20: 21 | U20: Environmental Incident Measures - (Spill/ Leakage / Concrete wash / vehicle & eqpts. wash / waste disposal/Sewers and drains/emissions/Emergency Management/Training/site run-off water) | AC20: 0.05 | AD20: 2 | AM20: Green | AN20: No issues
C21: 9 | D21: Electrical Safety - (Electrical qualified /RCD/GFCI/Industrial Cocket/LOTO/Cable-overhung or buried/Cords in good condition/current inspection tag) | L21: 0.03 | M21: 1 | T21: 22 | U21: HSE Communications & Meetings - (Schedule HSE Meetings/Safety Committee meetings/Alerts / Lesson learned/Safety Bulletin contains latest HSE KPI) | AC21: 0.05 | AD21: 1
C22: 10 | D22: Tools & Equipment - (Includes, powered, hydraulic & pneumatic/Guards in place/Properly stored/RCD Protection/Earthed/Good condition & tagged) | L22: 0.03 | M22: 2 | T22: 23 | U22: HSE Plan & Associated Procedures - (Approved updated HSE Plan/ CEMP/HAZComm/Procedures/Standards/Project Safety Risk Register) | AC22: 0.03 | AD22: 1 | AM22: 26 points > 4 minors then is it’s a serious issue
C23: 11 | D23: Manual Handling - (Lifting/loading/pulling/pushing/twisting/awkward posture/repetitive task/frequent and prolong physical effort/Reasonable practicable use of mechanical aid) | L23: 0.03 | M23: 1 | T23: 24 | U23: Health, Safety & Environment Incident reporting - (Review of HSE Statistics, Reporting of Unsafe Act & Conditions/ Reporting of Near Miss incident/Reporting of FA cases/Record MT cases) | AC23: 0.03 | AD23: N/A
C24: 12 | D24: Vehicle and mobile equipment / Plant - (dumpers; excavators, cranes, piling rigs, grader, roller, loaders/condition/KSA License/certification) | L24: 0.03 | M24: 1 | T24: 25 | U24: HSE Awareness, Training & Competence - (Policy /Objective & targets/Information, training/Climatic condition awareness/Reponses in emergency situation/ Safety Behavior Observation) | AC24: 0.04 | AD24: 1
C25: 13 | D25: Lifting Operations & Rigging - (Lifting Plan/Lifting devices & gears/PTW/Condition/3rd party certification/bank-man/rigger/slingers/man-basket/inspection record/tagged) | L25: 0.03 | M25: 1 | T25: 26 | U25: Project Leadership Site Tours - (Provide evidence of proactive safety performance/Deficient discovered discussed/Positive feedback/Workers resolving safety issues) | AD25: 2
C27: Prepared by: | H27: Mohamed Adel | T27: Sent to MODON PM: | Y27: =AB4 -> Eng\Rakan
C28: Safety Results
C29: 1 | E29: =COUNTIF(M13:R26,"1")+COUNTIF(AC13:AH26,"1") -> 15 | J29: 2 | M29: =COUNTIF(M13:R26,"2")+COUNTIF(AC13:AH26,"2") -> 6 | V29: 3 | X29: =COUNTIF(M13:R26,"3")+COUNTIF(AC13:AH26,"3") -> 0

Sheet HSE-Stat
C3: WEEKLY SAFETY STATISTICS REPORT
C5: Category | D5: Item | F5: This Week | G5: This Month | H5: Year to Date | I5: Cumulative
C6: Reactive | D6: Total Hours Worked | F6: 32130 | G6: 32130 | H6: 1073075 | I6: 1073075
D7: Safe Hours Worked | F7: 32130 | G7: 32130 | H7: 1073075 | I7: 1073075
D8: LTI | F8: 0 | G8: 0 | H8: 0 | I8: 0
D9: MTC (Healed w/o Disability) | F9: 0 | G9: 0 | H9: 0 | I9: 0
D10: MTC (Healed w/ Disability) | F10: 0 | G10: 0 | H10: 0 | I10: 0
D11: Near Miss | F11: 0 | G11: 0 | H11: 2 | I11: 2
D12: First Aid Cases | F12: 0 | G12: 1 | H12: 6 | I12: 6
D13: Fatality | F13: 0 | G13: 0 | H13: 0 | I13: 0
D14: Fire Incident Cases | F14: 0 | G14: 0 | H14: 0 | I14: 0
D15: Vehicle Incident | F15: 0 | G15: 0 | H15: 0 | I15: 0
D16: Property Damages | F16: 0 | G16: 0 | H16: 3 | I16: 3
C17: Proactive | D17: Induction Training | F17: 23 | G17: 23 | H17: 1881 | I17: 1881
D18: No.of Internal Training | F18: 1 | G18: 1 | H18: 66 | I18: 66
D19: No.of Internal Audit | F19: 0 | G19: 0 | H19: 0 | I19: 0
D20: No. of Toolbox Talks | F20: 1 | G20: 1 | H20: 215 | I20: 215
D21: Safety Awards/Incentives | F21: 0 | G21: 0 | H21: 9 | I21: 9

Sheet Quality
B2: QC OBSERVATIONS CHECKLIST
BB4: ='[62]General Information'!C14 -> 45720
B6: Project No. | E6: KHJ1-02-007 | K6: OBS No. | O6: 44 | U6: Inspection Day: | X6: 04-October-2026 to 10-October-2026
B8: Project | E8: DEVELOPMENT OF INFRASTRUCTURE NETWORKS, AL KHARJ INDUSTRIAL CITY (MODON), RIYADH | O8: Contractor: Consultant: | U8: MOFFAREH ALHARBI & PARTNERS Egis Saudi Egnieering
B10: 4 | D10: Excellent | G10: Quality Management System is being practiced and applies to MODON System | Z10: 90 - 100 | AB10: QC Overall Score | AC10: =Q49 -> 0.91 | AN10: =SUM(Z10:Z13) -> 0 | AO10: 100 | AP10: 0.22883295
B11: 3 | D11: Good | G11: Evidence of compliance with plans and procedures. | Z11: 80 - 89 | AN11: =SUM(Y10:Y14) -> 0 | AO11: 89 | AP11: 0.20366133
B12: 2 | D12: Average | G12: Indication level of compliance with standards but there is room for improvement | Z12: 70 - 79 | AO12: 79 | AP12: 0.18077803
B13: 1 | D13: Improve | G13: Quality and Control is NOT being managed effectively. Needs Improvement | Z13: ≤ 69 | AO13: 69 | AP13: 0.15789474
B14: 0 | D14: N/A | G14: Item was not applicable or this item was not reviewed during the inspection. | Z14: Zero | AO14: 100 | AP14: 0.22883295
B16: No. | C16: Topic | K16: E (4) | L16: G (3) | M16: A (2) | N16: I (1) | O16: N/A (0) | Q16: No. | R16: Topic | Z16: E (4) | AA16: G (3) | AB16: A (2) | AC16: I (1) | AD16: N/A (0) | AO16: =SUM(AO10:AO15) -> 437
K17: 1 | L17: 0.89 | M17: 0.79 | N17: 0.69 | O17: 1 | Z17: 1 | AA17: 0.89 | AB17: 0.79 | AC17: 0.69 | AD17: 1 | AF17: =SUM(AF18:AG46)/COUNT(AF18:AG46) -> 0.91
B18: 1 | C18: Control of Access to Site/Office | L18: 1 | Q18: 30 | R18: QC of Excavation | AA18: 1 | AF18: =SUMPRODUCT($K$17:$O$17,K18:O18) -> 0.89 | AG18: =SUMPRODUCT($Z$17:$AD$17,Z18:AD18) -> 0.89 | AV18: Item Count | AW18: Score | AX18: Distributtion
B19: 2 | C19: Document Control Administration | L19: 1 | Q19: 31 | R19: QC of Roads/Round about | AA19: 1 | AF19: =SUMPRODUCT($K$17:$O$17,K19:O19) -> 0.89 | AG19: =SUMPRODUCT($Z$17:$AD$17,Z19:AD19) -> 0.89 | AX19: Overall | AY19: Relevant
B20: 3 | C20: Project Documents and Progress | L20: 1 | Q20: 32 | R20: QC of Interlock & Curbstone | AA20: 1 | AF20: =SUMPRODUCT($K$17:$O$17,K20:O20) -> 0.89 | AG20: =SUMPRODUCT($Z$17:$AD$17,Z20:AD20) -> 0.89 | AM20: 4 | AN20: =58 -> 58 | AO20: counts | AQ20: 4 | AR20: Excellent | AV20: =SUM(Z18:Z46,K18:K46) -> 1 | AW20: =AQ20*AV20 -> 4 | AX20: =AV20/$AV$25 -> 0.0172 | AY20: =AV20/SUM($AV$20:$AV$23) -> 0.0213
B21: 4 | C21: Contractor's Quality Plan/CM (Updated and Reviewed) | L21: 1 | Q21: 33 | R21: Layers/Backfilling Sampling | AA21: 1 | AF21: =SUMPRODUCT($K$17:$O$17,K21:O21) -> 0.89 | AG21: =SUMPRODUCT($Z$17:$AD$17,Z21:AD21) -> 0.89 | AM21: 3 | AN21: =58 -> 58 | AO21: counts | AQ21: 3 | AR21: Good | AV21: =SUM(L18:L46,AA18:AA46) -> 43 | AW21: =AQ21*AV21 -> 129 | AX21: =AV21/$AV$25 -> 0.7414 | AY21: =AV21/SUM($AV$20:$AV$23) -> 0.9149
B22: 5 | C22: MS Log and Paperwork | L22: 1 | Q22: 34 | R22: Pump Stations Units | AD22: 1 | AF22: =SUMPRODUCT($K$17:$O$17,K22:O22) -> 0.89 | AG22: =SUMPRODUCT($Z$17:$AD$17,Z22:AD22) -> 1 | AM22: 2 | AN22: =58 -> 58 | AO22: counts | AQ22: 2 | AR22: Average | AV22: =SUM(M18:M46,AB18:AB46) -> 3 | AW22: =AQ22*AV22 -> 6 | AX22: =AV22/$AV$25 -> 0.0517 | AY22: =AV22/SUM($AV$20:$AV$23) -> 0.0638 | BC22: NB: Insert 1, or 0 in the required cell only.
B23: 6 | C23: RFI, FIR, & MIR Procedure | L23: 1 | Q23: 35 | R23: Quality of Form Work | AA23: 1 | AF23: =SUMPRODUCT($K$17:$O$17,K23:O23) -> 0.89 | AG23: =SUMPRODUCT($Z$17:$AD$17,Z23:AD23) -> 0.89 | AM23: 1 | AN23: =58 -> 58 | AO23: counts | AQ23: 1 | AR23: Improve | AV23: =SUM(N18:N46,AC18:AC46) -> 0 | AW23: =AQ23*AV23 -> 0 | AX23: =AV23/$AV$25 -> 0 | AY23: =AV23/SUM($AV$20:$AV$23) -> 0
B24: 7 | C24: RFI, FIR, & MIR Inventory system | L24: 1 | Q24: 36 | R24: Design Change List | AD24: 1 | AF24: =SUMPRODUCT($K$17:$O$17,K24:O24) -> 0.89 | AG24: =SUMPRODUCT($Z$17:$AD$17,Z24:AD24) -> 1 | AM24: 0 | AN24: =58 -> 58 | AO24: counts | AQ24: 0 | AR24: N/A | AV24: =SUM(O18:O46,AD18:AD46) -> 11 | AW24: =AQ24*AV24 -> 0 | AX24: =AV24/$AV$25 -> 0.1897 | AY24: -
B25: 8 | C25: NCRs Control & Procedure | L25: 1 | Q25: 37 | R25: Quality of Concrete Placing | AA25: 1 | AF25: =SUMPRODUCT($K$17:$O$17,K25:O25) -> 0.89 | AG25: =SUMPRODUCT($Z$17:$AD$17,Z25:AD25) -> 0.89 | AR25: Total | AV25: =SUM(AV20:AV24) -> 58 | AW25: =SUM(AW20:AW24) -> 139 | AX25: =SUM(AX20:AX24) -> 1 | AY25: =SUM(AY20:AY24) -> 1
B26: 9 | C26: NCR Log | L26: 1 | Q26: 38 | R26: Concrete Surface Finishing | AA26: 1 | AF26: =SUMPRODUCT($K$17:$O$17,K26:O26) -> 0.89 | AG26: =SUMPRODUCT($Z$17:$AD$17,Z26:AD26) -> 0.89
B27: 10 | C27: MODON Standard* | L27: 1 | Q27: 39 | R27: Pedestals/Columns/Beams Alignment | AA27: 1 | AF27: =SUMPRODUCT($K$17:$O$17,K27:O27) -> 0.89 | AG27: =SUMPRODUCT($Z$17:$AD$17,Z27:AD27) -> 0.89 | AV27: Maz Score Available: | AW27: =SUM(AV20:AV23)*AQ20 -> 188 | AX27: <- Excludes N/A items
B28: 11 | C28: Project Risk Plan/Management* | L28: 1 | Q28: 40 | R28: Siporex Lifting & Unloading | AB28: 1 | AF28: =SUMPRODUCT($K$17:$O$17,K28:O28) -> 0.89 | AG28: =SUMPRODUCT($Z$17:$AD$17,Z28:AD28) -> 0.79
B29: 12 | C29: Monthly Quality Reports* | L29: 1 | Q29: 41 | R29: Siporex Quality Pre-installation | AD29: 1 | AF29: =SUMPRODUCT($K$17:$O$17,K29:O29) -> 0.89 | AG29: =SUMPRODUCT($Z$17:$AD$17,Z29:AD29) -> 1
B30: 13 | C30: ITP | K30: 1 | Q30: 42 | R30: Siporex Finishing Quality | AD30: 1 | AF30: =SUMPRODUCT($K$17:$O$17,K30:O30) -> 1 | AG30: =SUMPRODUCT($Z$17:$AD$17,Z30:AD30) -> 1 | AR30: Total Score | AW30: Percentage (%)
B31: 14 | C31: MODON Weekly Report | L31: 1 | Q31: 43 | R31: Roads / Parking Markings | AD31: 1 | AF31: =SUMPRODUCT($K$17:$O$17,K31:O31) -> 0.89 | AG31: =SUMPRODUCT($Z$17:$AD$17,Z31:AD31) -> 1 | AN31: =MAX(AN20:AN24) -> 58 | AR31: =AW25 -> 139 | AW31: =SUM(100/AR33*AR31) -> 73.94 | AY31: %
B32: 15 | C32: Design Change Official Paperwork* | M32: 1 | Q32: 44 | R32: QC of Finishing Outdoors | AD32: 1 | AF32: =SUMPRODUCT($K$17:$O$17,K32:O32) -> 0.79 | AG32: =SUMPRODUCT($Z$17:$AD$17,Z32:AD32) -> 1 | AR32: Max Score Available | BP32: 31
B33: 16 | C33: Design Change was Applied* | L33: 1 | Q33: 45 | R33: Quality of Finishing Indoors | AA33: 1 | AF33: =SUMPRODUCT($K$17:$O$17,K33:O33) -> 0.89 | AG33: =SUMPRODUCT($Z$17:$AD$17,Z33:AD33) -> 0.89 | AR33: =AW27 -> 188 | BP33: 32
B34: 17 | C34: Material List | L34: 1 | Q34: 46 | R34: Stairs Quality | AD34: 1 | AF34: =SUMPRODUCT($K$17:$O$17,K34:O34) -> 0.89 | AG34: =SUMPRODUCT($Z$17:$AD$17,Z34:AD34) -> 1 | BP34: 33
B35: 18 | C35: Pending Material Status | L35: 1 | Q35: 47 | R35: Tanks Method Statement Work | AD35: 1 | AF35: =SUMPRODUCT($K$17:$O$17,K35:O35) -> 0.89 | AG35: =SUMPRODUCT($Z$17:$AD$17,Z35:AD35) -> 1 | BP35: 34
B36: 19 | C36: Lifting Plan* | L36: 1 | Q36: 48 | R36: Electric Rooms | AD36: 1 | AF36: =SUMPRODUCT($K$17:$O$17,K36:O36) -> 0.89 | AG36: =SUMPRODUCT($Z$17:$AD$17,Z36:AD36) -> 1 | BP36: 35
B37: 20 | C37: DWG Log | L37: 1 | Q37: 49 | R37: QC of MCC/ATS Plant Units | AA37: 1 | AF37: =SUMPRODUCT($K$17:$O$17,K37:O37) -> 0.89 | AG37: =SUMPRODUCT($Z$17:$AD$17,Z37:AD37) -> 0.89 | BP37: 36
B38: 21 | C38: Invoice Status | M38: 1 | Q38: 50 | R38: Qualified Subcontractor | AA38: 1 | AF38: =SUMPRODUCT($K$17:$O$17,K38:O38) -> 0.79 | AG38: =SUMPRODUCT($Z$17:$AD$17,Z38:AD38) -> 0.89 | BP38: 37
B39: 22 | C39: Site Handover Letter | O39: 1 | Q39: 51 | R39: Scaffold/Ladders/Slope/Bridge Compliance | AA39: 1 | AF39: =SUMPRODUCT($K$17:$O$17,K39:O39) -> 1 | AG39: =SUMPRODUCT($Z$17:$AD$17,Z39:AD39) -> 0.89 | BP39: 38
B40: 23 | C40: Material Testing Results & Certification | L40: 1 | Q40: 52 | R40: Protection Applied to Completed Work | AA40: 1 | AF40: =SUMPRODUCT($K$17:$O$17,K40:O40) -> 0.89 | AG40: =SUMPRODUCT($Z$17:$AD$17,Z40:AD40) -> 0.89
B41: 24 | C41: As Build Drawings Status* | O41: 1 | Q41: 53 | R41: Storage Management in/out Control | AA41: 1 | AF41: =SUMPRODUCT($K$17:$O$17,K41:O41) -> 1 | AG41: =SUMPRODUCT($Z$17:$AD$17,Z41:AD41) -> 0.89
B42: 25 | C42: Calibrated Lab Tools & Equipment | L42: 1 | Q42: 54 | R42: Material Control | AA42: 1 | AF42: =SUMPRODUCT($K$17:$O$17,K42:O42) -> 0.89 | AG42: =SUMPRODUCT($Z$17:$AD$17,Z42:AD42) -> 0.89
B43: 26 | C43: Storage Inventory System | L43: 1 | Q43: 55 | R43: Manholes Storing and Quality | AA43: 1 | AF43: =SUMPRODUCT($K$17:$O$17,K43:O43) -> 0.89 | AG43: =SUMPRODUCT($Z$17:$AD$17,Z43:AD43) -> 0.89
B44: 27 | C44: Logistics Plan | L44: 1 | Q44: 56 | R44: Reinforced Steel Quality | AA44: 1 | AF44: =SUMPRODUCT($K$17:$O$17,K44:O44) -> 0.89 | AG44: =SUMPRODUCT($Z$17:$AD$17,Z44:AD44) -> 0.89
B45: 28 | C45: Project Progress Planview | L45: 1 | Q45: 57 | R45: Safety Overview | AA45: 1 | AF45: =SUMPRODUCT($K$17:$O$17,K45:O45) -> 0.89 | AG45: =SUMPRODUCT($Z$17:$AD$17,Z45:AD45) -> 0.89
B46: 29 | C46: Sufficient Number of QC Inspectors | L46: 1 | Q46: 58 | R46: Waste Management Control | AA46: 1 | AF46: =SUMPRODUCT($K$17:$O$17,K46:O46) -> 0.89 | AG46: =SUMPRODUCT($Z$17:$AD$17,Z46:AD46) -> 0.89
...

Sheet Quality-Stat
D3: Project ID: | E3: KHJ1-02-007 | G3: WEEKLY QUALITY STATISTICS REPORT (WQSR)
D4: Project Name: | E4: DEVELOPMENT OF INFRASTRUCTURE NETWORKS, AL KHARJ INDUSTRIAL CITY (MODON), RIYADH
C5: Contractor: MOFFAREH ALHARBI & PARTNERS | D5: For the Week of: | E5: 04-October-2026 to 10-October-2026
C6: Document Ref. Number | D6: QWR-0044
C7: The Following facts (provided as guideline) in figures indicate the current trends of Quality highlights improvement and areas of concerns as well towards overall site Quality aspects of this project.
C9: GENERAL | D9: Previous Week | E9: This Week | F9: Cumulative | G9: Brief Description/Comment
C10: Planned Project Progress | D10: 31.87 | E10: 0.6 | F10: 32.45 | G10: As Pre Revised Schedule
C11: Actual Project Progress | D11: 32.88 | E11: 0.6 | F11: 33.49
C12: QAC Leading Indicators | G12: Brief Description/Comment
C13: No. of Quality Induction conducted | D13: 1 | E13: =F13-D13 -> 0 | F13: 1
C14: No. of Quality Training Delivered* | D14: 10 | E14: 0 | F14: 10
C15: No. of Approved Field Inspection Report (FIR) | D15: 52983 | E15: 224 | F15: 53207
C16: No. of Rejected Field Inspection Report (FIR) | D16: 0 | E16: 29 | F16: 29
C17: No. of under review Field Inspection Report (FIR) | D17: 0 | E17: 31 | F17: 31
C18: No. of Approved Material Inspection Request (MIR) | D18: 206 | E18: 7 | F18: 213
C19: No. of Rejected Material Inspection Request (MIR) | D19: 0 | E19: 0 | F19: 0
C20: No. of Request For Information (RFI) - Open | D20: 1 | E20: 2 | F20: 3
C21: No. of Request For Information (RFI) - Closed | D21: 118 | E21: 3 | F21: 121
C22: No. of Approved Material Received Inspection Report (MRIR) | D22: 103 | E22: 0 | F22: 103
C23: No. of Rejected Material Received Inspection Report (MRIR) | D23: 0 | E23: 0 | F23: 0
C24: No. of Review/Approved Shop drawings | D24: 2031 | E24: 56 | F24: 2087
C25: No. of Rejected Shop drawings | D25: 0 | E25: 0 | F25: 0
... C31: No. of Non-Conformance Report (NCR) issued* | D31: 37 | E31: 0 | F31: 37
C32: Type & No. of Test performed* | D32: 2177 | E32: 93 | F32: 2270 | G32: Compaction-Soil Sampling-Borehole-Concrete Compressive Test
C33: Amount & No.of Penalties/Fines Applied* | D33: 7 | E33: 0 | F33: 7
C34: No. of Change/ Variation Request | D34: 0 | E34: =F34-D34 -> 0 | F34: 0
C35: No. of critical long lead iteams and status* | D35: 0 | E35: =F35-D35 -> 0 | F35: 0
C36: No. of Internal/External Audit Conducted | D36: 5 | E36: 0 | F36: 5
C38: Work Done this week
C39: E.g. 1 - Quality Toolbox Meeting for Borehole Geotechnical Investigation, Drilling and Sampling Activities. 2 - Quality inspections/Site walkthrough performed. 3 - Internal weekly MOM done.
C42: Name: Adil Ghafoor | G42: Approved By:
C43: Position: QA QC Manager | G43: Position:
C44: Signature: | G44: Signature:

Sheet Weekly Quality
A1: DEVELOPMENT OF INFRASTRUCTURE NETWORKS, AL KHARJ INDUSTRIAL CITY (MODON), RIYADH | AC1: DEVELOPMENT OF INFRASTRUCTURE NETWORKS, AL KHARJ INDUSTRIAL CITY (MODON), RIYADH
A2: The Contractor : MOFFAREH ALHARBI & PARTNERS | AC2: The Contractor : MOFFAREH ALHARBI & PARTNERS
A3: Report Number:KHJ1-02-007-MAH-TS9-1-QMS-QWR-0043-00 Contractors’ Submittal -27-September-2026 to 03-October-2026) | AC3: 04-October-2026 to 10-October-2026
B4: FIR Detail | L4: NCR Detail | T4: MAR Detail | AD4: Shop Drawing | AN4: ITP ( Inspection Test Plan) | AX4: MES ( Method statement)
C5: Received | F5: Code A | G5: Code B | H5: Code C/D | I5: UR | J5: KPI % | M5: Issued/Received | P5: Closed | Q5: OPEN | R5: KPI % | U5: Received | X5: Code A | Y5: Code B | Z5: Code C/D | AA5: UR | AB5: KPI % | AE5: Received | AH5: Code A | AI5: Code B | AJ5: Code C/D | AK5: UR | AL5: KPI % | AO5: Received | AR5: Code A | AS5: Code B | AT5: Code C/D | AU5: UR | AV5: KPI % | AY5: Received | BB5: Code A | BC5: Code B | BD5: Code C/D | BE5: UR | BF5: KPI %
C6: Previous | D6: Current | E6: Cumulative | M6: Previous | N6: Current | O6: Cumulative | U6: Previous | V6: Current | W6: Cumulative | AA6: UR | AE6: Previous | AF6: Current | AG6: Cumulative | AO6: Previous | AP6: Current | AQ6: Cumulative | AY6: Previous | AZ6: Current | BA6: Cumulative
B7: CIV | D7: 3 | F7: 0 | G7: 0 | H7: 0 | I7: 3 | L7: CIV | N7: 0 | P7: 0 | Q7: 0 | T7: CIV | V7: 0 | X7: 0 | Y7: 0 | Z7: 0 | AA7: 0 | AD7: CIV | AF7: 0 | AH7: 0 | AI7: 0 | AJ7: 0 | AK7: 0 | AN7: CIVIL | AP7: 0 | AR7: 0 | AS7: 0 | AT7: 0 | AU7: 0 | AX7: CIVIL | AZ7: 1 | BB7: 1 | BC7: 0 | BD7: 0 | BE7: 0
B8: Road | D8: 80 | F8: 15 | G8: 64 | H8: 1 | I8: 0 | L8: Electrical | N8: =O8-M8 -> 0 | P8: 0 | Q8: =O8-P8 -> 0 | T8: Electrical | V8: 0 | X8: 0 | Y8: 0 | Z8: 0 | AA8: 0 | AD8: Electrical | AF8: 6 | AH8: 4 | AI8: 0 | AJ8: 0 | AK8: 2 | AN8: MEP | AP8: 0 | AR8: 0 | AS8: 0 | AT8: 0 | AU8: 0 | AX8: MEP | AZ8: 0 | BB8: 0 | BC8: 0 | BD8: 0 | BE8: 1
B9: CBC | D9: 4 | F9: 2 | G9: 2 | H9: 0 | I9: 0 | L9: Mechanical | N9: 1 | P9: 0 | Q9: 1 | T9: Mechanical | V9: 0 | X9: 0 | Y9: 0 | Z9: 0 | AA9: 0 | AD9: Mechanical | AF9: 0 | AH9: 0 | AI9: 0 | AJ9: 0 | AK9: 0 | AN9: ELECTRICAL | AP9: 0 | AR9: 0 | AS9: 0 | AT9: 0 | AU9: 0 | AX9: ELECTRICAL | AZ9: 0 | BB9: 0 | BC9: 0 | BD9: 0 | BE9: 0
B10: MEC | D10: 0 | F10: 0 | G10: 0 | H10: 0 | I10: 0 | L10: Sewer | N10: 0 | P10: 0 | Q10: 0 | T10: Arc | V10: 0 | X10: 0 | Y10: 0 | Z10: 0 | AA10: 0 | AD10: General | AF10: 0 | AH10: 0 | AI10: 0 | AJ10: 0 | AK10: 0 | AN10: ROD | AP10: 0 | AR10: 0 | AS10: 0 | AT10: 0 | AU10: 0 | AX10: ARC | AZ10: 0 | BB10: 0 | BC10: 0 | BD10: 0 | BE10: 0
B11: Sewer | D11: 80 | F11: 0 | G11: 47 | H11: 19 | I11: 4 | L11: General | N11: 0 | P11: 0 | Q11: 0 | T11: IRI | V11: 0 | X11: 0 | Y11: 0 | Z11: 0 | AA11: 0 | AD11: Arch | AF11: 0 | AH11: 0 | AI11: 0 | AJ11: 0 | AK11: 0 | AN11: TEL | AP11: 0 | AR11: 0 | AS11: 0 | AT11: 0 | AU11: 0 | AX11: TEL | AZ11: 0 | BB11: 0 | BC11: 0 | BD11: 0 | BE11: 0
B12: Storm | D12: 44 | F12: 0 | G12: 39 | H12: 4 | I12: 1 | T12: LSC | V12: 0 | X12: 0 | Y12: 0 | Z12: 0 | AA12: 0 | AD12: ROAD | AF12: 1 | AH12: 1 | AI12: 0 | AJ12: 0 | AK12: 0 | AN12: Arc | AP12: 0 | AR12: 0 | AS12: 0 | AT12: 0 | AU12: 0
B13: Electrical | D13: 20 | F13: 7 | G13: 12 | H13: 0 | I13: 1 | AD13: SEW | AF13: 0 | AH13: 0 | AI13: 0 | AJ13: 0 | AK13: 0 | AN13: 0
B14: TEL | D14: 11 | F14: 3 | G14: 7 | H14: 1 | I14: 0 | AD14: TEL | AF14: 0 | AH14: 0 | AI14: 0 | AJ14: 0 | AK14: 0
B15: IRR | D15: 17 | F15: 1 | G15: 13 | H15: 3 | I15: 0 | AD15: ST | AF15: 20 | AH15: 0 | AI15: 20 | AJ15: 0 | AK15: 0
B16: Survey | D16: 0 | F16: 0 | G16: 0 | H16: 0 | I16: 0 | AD16: CBC | AF16: 0 | AH16: 0 | AI16: 0 | AJ16: 0 | AK16: 0
B17: POT | D17: 16 | F17: 0 | G17: 12 | H17: 1 | I17: 3 | AD17: LSC | AF17: 20 | AH17: 0 | AI17: 20 | AJ17: 0 | AK17: 0
AD18: IRR | AF18: 0 | AH18: 0 | AI18: 0 | AJ18: 0 | AK18: 0 | AM18: 81
AD19: POT | AF19: 0 | AH19: 0 | AI19: 0 | AJ19: 0 | AK19: 0
B20: TOTAL | D20: =SUM(D7:D19) -> 275 | F20: =SUM(F7:F19) -> 28 | G20: =SUM(G7:G19) -> 196 | H20: =SUM(H7:H19) -> 29 | I20: 31 | J20: 90 | L20: TOTAL | N20: 0 | P20: 0 | Q20: 0 | R20: 0 | T20: TOTAL | V20: 0 | X20: =SUM(X7:X15) -> 0 | Y20: 0 | Z20: =SUM(Z7:Z15) -> 0 | AA20: =SUM(AA7:AA15) -> 0 | AB20: 100 | AD20: MEP | AF20: 0 | AH20: 0 | AI20: 0 | AJ20: 0 | AK20: 0 | AN20: TOTAL | AP20: 0 | AR20: 0 | AS20: =SUM(AS7:AS15) -> 0 | AT20: =SUM(AT7:AT15) -> 0 | AU20: =SUM(AU7:AU15) -> 0 | AV20: 100 | AX20: TOTAL | AZ20: 1 | BB20: =SUM(BB7:BB15) -> 1 | BC20: =SUM(BC7:BC15) -> 0 | BD20: =SUM(BD7:BD15) -> 0 | BE20: 0 | BF20: 100
AD21: STR | AF21: 11 | AH21: 0 | AI21: 11 | AJ21: 0 | AK21: 0
AD22: TOTAL | AF22: 58 | AH22: 5 | AI22: 51 | AJ22: 0 | AK22: 2 | AL22: 100
B24: PQD (Prequalification Documents) | L24: SIR/SOR Detail | T24: MRIR | AD24: As built Drawing | AN24: MIR ( Material Receiving Inspection)
C25: Received | F25: Code A | G25: Code B | H25: Code C/D | I25: UR | J25: KPI % | M25: Issued/Received | P25: Closed | Q25: OPEN | R25: KPI % | U25: Received | X25: Code A | Y25: Code B | Z25: Code C/D | AA25: UR | AB25: KPI % | AE25: Received | AH25: Code A | AI25: Code B | AJ25: Code C/D | AK25: UR | AL25: KPI % | AO25: Received | AR25: Code A | AS25: Code B | AT25: Code C/D | AU25: UR | AV25: KPI %
C26: Previous | D26: Current | E26: Cumulative | M26: Previous | N26: Current | U26: Previous | V26: Current | W26: Cumulative | AE26: Previous | AF26: Current | AG26: Cumulative | AO26: Previous | AP26: Current | AQ26: Cumulative
B27: CIV | D27: 1 | F27: 0 | G27: 0 | H27: 1 | I27: 0 | L27: CIV | N27: 0 | P27: 0 | Q27: 0 | T27: CIV | V27: 0 | X27: 0 | Y27: 0 | Z27: 0 | AA27: 0 | AD27: CIV | AF27: 0 | AG27: 0 | AH27: 0 | AI27: 0 | AJ27: 0 | AK27: =AG27-AH27-AI27-AJ27 -> 0 | AN27: CIV/ROD | AP27: 2 | AR27: 2 | AS27: 0 | AT27: 0 | AU27: 0
B28: ARCH | D28: 1 | F28: 0 | G28: 0 | H28: 0 | I28: 1 | L28: ARCH | N28: 0 | P28: 0 | Q28: =O28-P28 -> 0 | T28: ARCH | V28: 0 | X28: 0 | Y28: 0 | Z28: 0 | AA28: 0 | AD28: ARCH | AF28: =AG28-AE28 -> 0 | AG28: 0 | AH28: 0 | AI28: 0 | AJ28: 0 | AK28: =AG28-AH28-AI28-AJ28 -> 0 | AN28: ARCH | AP28: =AQ28-AO28 -> 0 | AR28: 0 | AS28: 0 | AT28: 0 | AU28: =AQ28-AR28-AS28-AT28 -> 0
B29: Electrical | D29: 0 | F29: 0 | G29: 0 | H29: 0 | I29: 0 | L29: Electrical | N29: =O29-M29 -> 0 | P29: 0 | Q29: =O29-P29 -> 0 | T29: Electrical | V29: 0 | X29: 0 | Y29: 0 | Z29: 0 | AA29: 0 | AD29: Electrical | AF29: =AG29-AE29 -> 0 | AG29: 0 | AH29: 0 | AI29: 0 | AJ29: 0 | AK29: =AG29-AH29-AI29-AJ29 -> 0 | AN29: Electrical | AP29: 2 | AR29: 1 | AS29: 0 | AT29: 0 | AU29: 1
B30: Mechanical | D30: 0 | F30: 0 | G30: 0 | H30: 0 | I30: 0 | L30: Mechanical | N30: 0 | P30: 0 | Q30: 0 | T30: MEP | V30: 0 | X30: 0 | Y30: 0 | Z30: 0 | AA30: 0 | AD30: Mechanical | AF30: =AG30-AE30 -> 0 | AG30: 0 | AH30: 0 | AI30: 0 | AJ30: 0 | AK30: =AG30-AH30-AI30-AJ30 -> 0 | AN30: Mechanical | AP30: 4 | AR30: 4 | AS30: 0 | AT30: 0 | AU30: 0
B31: General | D31: 0 | F31: 0 | G31: 0 | H31: 0 | I31: 0 | L31: General | N31: 0 | P31: 0 | Q31: 0 | T31: Tel | V31: 0 | X31: 0 | Y31: 0 | Z31: 0 | AA31: 0 | AD31: General | AF31: =AG31-AE31 -> 0 | AG31: 0 | AH31: 0 | AI31: 0 | AJ31: 0 | AK31: =AG31-AH31-AI31-AJ31 -> 0 | AN31: Telecom | AP31: =AQ31-AO31 -> 0 | AR31: 0 | AS31: 0 | AT31: 0 | AU31: =AQ31-AR31-AS31-AT31 -> 0
T32: Storm | V32: 0 | X32: 0 | Y32: 0 | Z32: 0 | AA32: 0 | AN32: Storm | AP32: =AQ32-AO32 -> 0 | AR32: 0 | AS32: 0 | AT32: 0 | AU32: =AQ32-AR32-AS32-AT32 -> 0
T33: CBC | V33: 0 | X33: 0 | Y33: 0 | Z33: 0 | AA33: 0 | AN33: General | AP33: =AQ33-AO33 -> 0 | AR33: 0 | AS33: 0 | AT33: 0 | AU33: =AQ33-AR33-AS33-AT33 -> 0
T34: ROD | V34: 0 | X34: 9 | Y34: 0 | Z34: 0 | AA34: 0 | AN34: CBC | AP34: 0 | AR34: 0 | AS34: 0 | AT34: 0 | AU34: 0
B35: TOTAL | D35: =SUM(D26:D33) -> 2 | F35: =SUM(F26:F33) -> 0 | G35: =SUM(G26:G33) -> 0 | H35: =SUM(H26:H33) -> 1 | I35: =SUM(I26:I33) -> 1 | J35: 0 | T35: TOTAL | V35: =SUM(V26:V34) -> 0 | X35: 0 | Y35: =SUM(Y26:Y34) -> 0 | Z35: =SUM(Z26:Z34) -> 0 | AA35: 0 | AB35: 100 | AD35: TOTAL | AF35: =SUM(AF26:AF33) -> 0 | AH35: =SUM(AH26:AH33) -> 0 | AI35: =SUM(AI26:AI33) -> 0 | AJ35: =SUM(AJ26:AJ33) -> 0 | AK35: =SUM(AK26:AK33) -> 0 | AL35: 100 | AN35: LSC | AP35: =AQ35-AO35 -> 0 | AR35: 0 | AS35: 0 | AT35: 0 | AU35: =AQ35-AR35-AS35-AT35 -> 0
L36: TOTAL | N36: 0 | P36: =SUM(P27:P35) -> 0 | Q36: =SUM(Q27:Q35) -> 0 | R36: 100 | AN36: TOTAL | AP36: =SUM(AP27:AP35) -> 8 | AR36: 7 | AS36: =SUM(AS27:AS35) -> 0 | AT36: =SUM(AT27:AT35) -> 0 | AU36: 1 | AV36: 100

Sheet FIR Summary
C3: QC OBSERVATIONS CHECKLIST FIR Summary
C5: Serial # | D5: FIR # | E5: FIR Description | F5: Date | G5: Duration days | H5: Comments
C6: 1.Civil (CIV)
C8: 1 | D8: KHJ1-02-007-MAH-TS9-1-CIV-FIR-0096 | E8: Inspection for block masonry (CMU) Above the parapet between posts as per highlight in attached drawing Mosque (Mosque Area) | F8: 46295 | H8: UR-Under Review
C9: 2 | D9: KHJ1-02-007-MAH-TS9-1-CIV-FIR-0126 | E9: Inspection of Reinforcement Steel for Tie Beams Above the block masonry between posts as per highlight in attached drawing Mosque (Mosque Area). | F9: 46295 | H9: UR-Under Review
C10: 3 | D10: KHJ1-02-007-MAH-TS9-1-CIV-FIR-0137 | E10: Inspection of Concrete Pouring for Tie Beams Above the block masonry between posts as per highlight in attached drawing Mosque (Mosque Area). | F10: 46294 | H10: UR-Under Review
C11: 2.Road (ROD)
C12: 1 | D12: KHJ1-02-007-MAH-TS9-1-ROD-FIR-0849 | E12: Inspection for Sampling, Testing and Placement of 2nd Layer of Bituminous Base Course Left Side Remaining Area (5m) from Station 0+750 to 0+900 at Arterial Road - 01 Zone B. | F12: 46299 | H12: Accepted
C13: 2 | D13: KHJ1-02-007-MAH-TS9-1-ROD-FIR-0907 | E13: Inspection for Sampling, Testing and Placement of Bituminous Base Course (70mm) Station Station 0+062.5 to 0+275 at Local Road # 11 Zone A. | F13: 46299 | H13: Accepted
C14: 3 | D14: KHJ1-02-007-MAH-TS9-1-ROD-FIR-0910 | E14: Inspection for Sampling, Testing and Placement of Bituminous Base Course from Station 0+050 to 0+644 at Local Road - 25 Zone B. | F14: 46301 | H14: Accepted
C15: 4 | D15: KHJ1-02-007-MAH-TS9-1-ROD-FIR-0916 | E15: Inspection for Sampling, Testing and Placement of Bituminous Base Course Station 0+100 to 0+225 (70mm) at Local Road # 12 Zone A | F15: 46301 | H15: Accepted
C16: 5 | D16: KHJ1-02-007-MAH-TS9-1-ROD-FIR-0920 | E16: Inspection for Sampling, Testing and Placement of Bituminous Base Course from Station 0+025 to 0+100 at Local Road - 23 Zone B. | F16: 46301 | H16: Accepted
C17: 6 | D17: KHJ1-02-007-MAH-TS9-1-ROD-FIR-0925 | E17: Inspection for Installation of Curb Stone (K1A-187m) Median Right Side of Road from station 0+400 to 0+587 at Arterial Road # 01 Zone B. | F17: 46302 | H17: Accepted
C18: 7 | D18: KHJ1-02-007-MAH-TS9-1-ROD-FIR-0927 | E18: Core sampling Inspection for Bitumen Base course Station 0+062.5 to 0+275 (70mm) at Local Road # 11, 0+088 to 0+237 (70mm) at Local Road # 12 & 0+200 to 0+300 (150mm) (LHS) at Collector Road # 01 Zone A | F18: 46303 | H18: Accepted
C19: 8 | D19: KHJ1-02-007-MAH-TS9-1-ROD-FIR-0936 | E19: Inspection for Placement, Location, level and Compaction for 1st layer of Sub Grade from Station 0+550 to 0+625 at Local Road # 02 Zone B. | F19: 46303 | H19: Accepted
C20: 9 | D20: KHJ1-02-007-MAH-TS9-1-ROD-FIR-0937 | E20: Inspection for Placement, Location, level and Compaction for 1st layer of Sub Grade from Station 1+250 to 1+675 at Local Road # 02 Zone B. | F20: 46303 | H20: Accepted
C21: 10 | D21: KHJ1-02-007-MAH-TS9-1-ROD-FIR-0940 | E21: Inspection for Sampling, Testing and Placement of Bituminous Base Course Station 0+200 to 0+300 (150mm) (LHS) at Collector Road # 01 Zone A | F21: 46301 | H21: Accepted
C22: 11 | D22: KHJ1-02-007-MAH-TS9-1-ROD-FIR-0942 | E22: Inspection for Sampling, Testing and Placement of Bituminous Base Course Station 0+010 to 0+025 at Local Road # 13 Zone A. | F22: 46301 | H22: Accepted
C23: 12 | D23: KHJ1-02-007-MAH-TS9-1-ROD-FIR-0943 | E23: Inspection for Sampling, Testing and Placement of Bituminous Base Course Station 0+010 to 0+025 at Local Road # 14 Zone A. | F23: 46301 | H23: Accepted
... C93: 1 | D93: KHJ1-02-007-MAH-TS9-1-ROD-FIR-0957 | E93: Inspection for Placement, Location, level and Compaction of Aggregate Base Course(200mm) (A-1-a) from Station 0+010 to 0+075 at Local Road # 09 Zone A. | F93: 46303 | H93: Revised & Resubmit
C94: 3. Concrete Box Culvet (CBC)
C95: 1 | D95: KHJ1-02-007-MAH-TS9-1-CBC-FIR-0127 | E95: Inspection of Reinforcement for Base and Apron Slab Cast-in-Situ Part for Up stream and Down Stream at Culvert # 07 Local Road-24 Zone B. | F95: 46299 | H95: Accepted
C96: 2 | D96: KHJ1-02-007-MAH-TS9-1-CBC-FIR-0129 | E96: Inspection for Formwork and Concrete Pouring for Head Beam Cast-in-Situ Part for Up stream and Down Stream at Culvert # 04 Local Road-22 Zone B. | F96: 46300 | H96: Accepted
C98: 1 | D98: KHJ1-02-007-MAH-TS9-1-CBC-FIR-0128 | E98: Inspection for Formwork and Concrete Pouring for Top Slab and Vertical Walls Cast-in-Situ Part for Up stream and Down Stream at Culvert # 04 Local Road-22 Zone B. | F98: 46300 | H98: Accepted as Noted
C99: 2 | D99: KHJ1-02-007-MAH-TS9-1-CBC-FIR-0130 | E99: Inspection for Formwork and Concrete Pouring for Base and Apron Slab Cast-in-Situ Part for Up stream and Down Stream at Culvert # 05 Local Road-23 Zone B. | F99: 46300 | H99: Accepted as Noted
C100: 4.Mechanical(MEC)
C101: No FIR Submitted in Mechanical Decipline.
C102: 5.Sewer (SEW)
C103: 1 | D103: KHJ1-02-007-MAH-TS9-1-SEW-FIR-1634 | E103: Inspection for Excavation, Location, level and Compaction and Blinding Concrete Pouring for Sewer MH-2.32 at local road # 03 Zone-A. | F103: 46302 | H103: Accepted as Noted
C104: 2 | D104: KHJ1-02-007-MAH-TS9-1-SEW-FIR-1635 | E104: Inspection for Excavation, Location, level and Compaction and Blinding Concrete Pouring for Sewer MH-2.33 at local road # 03 Zone-A. | F104: 46302 | H104: Accepted as Noted
C105: 3 | D105: KHJ1-02-007-MAH-TS9-1-SEW-FIR-1636 | E105: Inspection for Excavation, Location, level and Compaction and Blinding Concrete Pouring for Sewer MH-2.31.1 at local road # 03 Zone-A. | F105: 46302 | H105: Accepted as Noted
C106: 4 | D106: KHJ1-02-007-MAH-TS9-1-SEW-FIR-1646 | E106: Sand Bedding and Installation of GRP Pipe (Dia200mm) ofSewer LinefromManhole MH-11to MH-12at localRoad #01inLabor Camp. | F106: 46302 | H106: Accepted as Noted
C107: 5 | D107: KHJ1-02-007-MAH-TS9-1-SEW-FIR-1649 | E107: Inspection for Excavation, Location, level and Compaction and Blinding Concrete Pouring for Sewer MH-2.29 at local road # 03 Zone-A. | F107: 46302 | H107: Accepted as Noted
C108: 6 | D108: KHJ1-02-007-MAH-TS9-1-SEW-FIR-1650 | E108: Inspection for Excavation, Location, level and Compaction and Blinding Concrete Pouring for Sewer MH-2.29.1 at local road # 03 Zone-A. | F108: 46302 | H108: Accepted as Noted
C109: 7 | D109: KHJ1-02-007-MAH-TS9-1-SEW-FIR-1651 | E109: Inspection for Excavation, Location, level and Compaction and Blinding Concrete Pouring for Sewer MH-2.30 at local road # 03 Zone-A. | F109: 46302 | H109: Accepted as Noted
C110: 8 | D110: KHJ1-02-007-MAH-TS9-1-SEW-FIR-1652 | E110: Inspection for Excavation, Location, level and Compaction and Blinding Concrete Pouring for Sewer MH-2.30.1 at local road # 03 Zone-A. | F110: 46302 | H110: Accepted as Noted
C111: 9 | D111: KHJ1-02-007-MAH-TS9-1-SEW-FIR-1653 | E111: Inspection for Blinding Concrete Pouring of Sewer MH-1 at labor camp road # 01 Zone A. | F111: 46302 | H111: Accepted as Noted
C112: 10 | D112: KHJ1-02-007-MAH-TS9-1-SEW-FIR-1654 | E112: Inspection for Blinding Concrete Pouring of Sewer MH-1-1, MH-1-2 & MH-1-3 at labor camp road # 01 Zone A. | F112: 46302 | H112: Accepted as Noted
C113: 11 | D113: KHJ1-02-007-MAH-TS9-1-SEW-FIR-1655 | E113: Inspection for Blinding Concrete Pouring of Sewer MH-1-4 & MH-1-5 at labor camp road # 01 Zone A. | F113: 46302 | H113: Accepted as Noted
C114: 12 | D114: KHJ1-02-007-MAH-TS9-1-SEW-FIR-1656 | E114: Inspection for Blinding Concrete Pouring of Sewer MH-1-6, MH-1-7 & MH-1-8 at labor camp road # 01 Zone A. | F114: 46302 | H114: Accepted as Noted
...

Sheet Procurement
C2: حالة المشتريات الرئيسية - مشروع الخرج
C3: اسم المشروع | D3: Parent Project ID | E3: القطاع | F3: مواد التوريدات | G3: المورد | H3: رقم التواصل مع المورد | I3: الموقف الحالي | J3: تاريخ بدء التوريد المجدول | K3: اجتماعات الموردين | L3: خارجي/ داخلي | M3: نسبة التوريد المحلي % | N3: نسبة التوريد الخارجي % | O3: اجمالي الكمية | P3: الكمية التي تم توريدها | Q3: وحدة القياس | R3: ملاحظات (حالة المادة - عوائق - تأخير - ظروف خارجية, التأخر بالدفع من المقاول أو المورد)
