Workbook
Name _Hlk191481195: MSA!$I$14
Name _Hlk191481195: 'Shop Dwgs'!$J$14
Name _Hlk192937198: MSA!$I$18
Name _Hlk192937198: 'Shop Dwgs'!$J$18
Name _Hlk193023968: 'Design Dwgs'!#REF!
Name _Hlk193195409: MSA!#REF!
Name _Hlk193195409: 'Shop Dwgs'!$J$22
Name _Hlk194749541: 'Design Dwgs'!#REF!
Name _Hlk195095287: 'Design Dwgs'!#REF!
Name _Hlk195180476: 'Design Dwgs'!#REF!
Name _Hlk195180491: 'Design Dwgs'!#REF!
Name _Hlk195180505: 'Design Dwgs'!#REF!
Name _Hlk195182086: 'Design Dwgs'!#REF!
Name _Hlk195182096: 'Design Dwgs'!#REF!
Name _Hlk195182805: 'Design Dwgs'!#REF!
Name _Hlk195186600: 'Design Dwgs'!#REF!
Name _Hlk195186642: 'Design Dwgs'!#REF!
Name _Hlk195605672: MSA!#REF!
Name _Hlk195605672: 'Shop Dwgs'!#REF!
Name _Hlk195605708: MSA!#REF!
Name _Hlk195605708: 'Shop Dwgs'!#REF!
Name _Hlk196649423: MSA!#REF!
Name _Hlk196649423: 'Shop Dwgs'!#REF!

Sheet % Summary
D2: P030 - (MLTX-02-003) - Playgrounds Initiative at (Qassim Oasis, Hail and Tabuk Industrial City) Technical/Engineering Submittals - Summary / Percentage
B4: ADV | H4: Egis / Modon
B5: Document Type / Trade | C5: Deadline for Trade | D5: Total Number of Documents | E5: Planned Submissions to date | F5: Actual Submissions to date | G5: Delayed Submissions | H5: Approved Code ( A&B ) | I5: Revise & Resubmit Code ( C ) | J5: Under Review Code ( UR ) | K5: Delayed Review (+3 >= 5 days) | L5: Under PMC Review / For Info. / Rejected / Withdrawn / Cancelled / Recalled Code ( D)
B6: Pre-Qualification | D6: =PQA!AC10 -> 55 | E6: N/A | F6: =SUM(H6:L6) -> 55 | G6: N/A | H6: =PQA!AC3+PQA!AC4 -> 47 | I6: =PQA!AC5 -> 5 | J6: =PQA!AC7 -> 3 | K6: =PQA!AC9 -> 0 | L6: =PQA!AC6 -> 0
D7: =D6/$D$6 -> 1 | E7: N/A | F7: =F6/$D$6 -> 1 | G7: N/A | H7: =H6/$D$6 -> 0.85454545 | I7: =I6/$D$6 -> 0.090909091 | J7: =J6/$D$6 -> 0.054545455 | K7: =K6/$D$6 -> 0 | L7: =L6/$D$6 -> 0
B8: Material Submittal | D8: =MS!AG10 -> 137 | E8: N/A | F8: =SUM(H8:L8) -> 137 | G8: N/A | H8: =MS!AG3+MS!AG4 -> 120 | I8: =MS!AG5 -> 6 | J8: =MS!AG7 -> 10 | K8: =MS!AG9 -> 1 | L8: =MS!AG6 -> 0
D9: =D8/$D$8 -> 1 | E9: N/A | F9: =F8/$D$8 -> 1 | G9: N/A | H9: =H8/$D$8 -> 0.87591241 | I9: =I8/$D$8 -> 0.04379562 | J9: =J8/$D$8 -> 0.072992701 | K9: =K8/$D$8 -> 0.0072992701 | L9: =L8/$D$8 -> 0
B10: Method Statement | D10: =MST!Y10 -> 22 | E10: N/A | F10: =SUM(H10:L10) -> 22 | G10: N/A | H10: =MST!Y3+MST!Y4 -> 22 | I10: =MST!Y5 -> 0 | J10: =MST!Y7 -> 0 | K10: =MST!Y9 -> 0 | L10: =MST!Y6 -> 0
D11: =D10/$D$10 -> 1 | E11: N/A | F11: =F10/$D$10 -> 1 | G11: N/A | H11: =H10/$D$10 -> 1 | I11: =I10/$D$10 -> 0 | J11: =J10/$D$10 -> 0 | K11: =K10/$D$10 -> 0 | L11: =L10/$D$10 -> 0
B12: Document Submittals Technical / General | D12: ='Doc. Submittals (Tech & Gen)'!AK10 -> 183 | E12: N/A | F12: =SUM(H12:L12) -> 183 | G12: N/A | H12: ='Doc. Submittals (Tech & Gen)'!AK3+'Doc. Submittals (Tech & Gen)'!AK4 -> 148 | I12: ='Doc. Submittals (Tech & Gen)'!AK5 -> 13 | J12: ='Doc. Submittals (Tech & Gen)'!AK7 -> 10 | K12: ='Doc. Submittals (Tech & Gen)'!AK9 -> 12 | L12: ='Doc. Submittals (Tech & Gen)'!AK6 -> 0
D13: =D12/$D$12 -> 1 | E13: N/A | F13: =F12/$D$12 -> 1 | G13: N/A | H13: =H12/$D$12 -> 0.80874317 | I13: =I12/$D$12 -> 0.071038251 | J13: =J12/$D$12 -> 0.054644809 | K13: =K12/$D$12 -> 0.06557377 | L13: =L12/$D$12 -> 0
B14: RFI | D14: =RFI!AB10 -> 34 | E14: N/A | F14: =SUM(H14:L14) -> 34 | G14: N/A | H14: =RFI!AB3+RFI!AB4 -> 30 | I14: =RFI!AB5 -> 3 | J14: =RFI!AB7 -> 0 | K14: =RFI!AB9 -> 1 | L14: =RFI!AB6 -> 0
D15: =D14/$D$14 -> 1 | E15: N/A | F15: =F14/$D$14 -> 1 | G15: N/A | H15: =H14/$D$14 -> 0.88235294 | I15: =I14/$D$14 -> 0.088235294 | J15: =J14/$D$14 -> 0 | K15: =K14/$D$14 -> 0.029411765 | L15: =L14/$D$14 -> 0
B16: Design Drawings | D16: ='Design Dwgs'!AD10 -> 0 | E16: N/A | F16: =SUM(H16:L16) -> 0 | G16: N/A | H16: ='Design Dwgs'!AD4+'Design Dwgs'!AD3 -> 0 | I16: ='Design Dwgs'!AD5 -> 0 | J16: ='Design Dwgs'!AD7 -> 0 | K16: ='Design Dwgs'!AD9 -> 0 | L16: ='Design Dwgs'!AD6 -> 0
D17: =D16/$D$16 -> #DIV/0! | E17: N/A | F17: =F16/$D$16 -> #DIV/0! | G17: N/A | H17: =H16/$D$16 -> #DIV/0! | I17: =I16/$D$16 -> #DIV/0! | J17: =J16/$D$16 -> #DIV/0! | K17: =K16/$D$16 -> #DIV/0! | L17: =L16/$D$16 -> #DIV/0!
B18: Shop Drawings | D18: ='Shop Dwgs'!AB10 -> 375 | E18: N/A | F18: =SUM(H18:L18) -> 375 | G18: N/A | H18: ='Shop Dwgs'!AB3+'Shop Dwgs'!AB4 -> 309 | I18: ='Shop Dwgs'!AB5 -> 20 | J18: ='Shop Dwgs'!AB7 -> 34 | K18: ='Shop Dwgs'!AB9 -> 12 | L18: ='Shop Dwgs'!AB6 -> 0
D19: =D18/$D$18 -> 1 | E19: N/A | F19: =F18/$D$18 -> 1 | G19: N/A | H19: =H18/$D$18 -> 0.824 | I19: =I18/$D$18 -> 0.053333333 | J19: =J18/$D$18 -> 0.090666667 | K19: =K18/$D$18 -> 0.032 | L19: =L18/$D$18 -> 0
B20: Material Source Approval (MSA) | D20: =MSA!AA10 -> 13 | E20: N/A | F20: =SUM(H20:L20) -> 13 | G20: N/A | H20: =MSA!AA3+MSA!AA4 -> 1 | I20: =MSA!AA5 -> 3 | J20: =MSA!AA7 -> 0 | K20: =MSA!AA9 -> 9 | L20: =MSA!AA6 -> 0
D21: =D20/$D$20 -> 1 | E21: N/A | F21: =F20/$D$20 -> 1 | G21: N/A | H21: =H20/$D$20 -> 0.076923077 | I21: =I20/$D$20 -> 0.23076923 | J21: =J20/$D$20 -> 0 | K21: =K20/$D$20 -> 0.69230769 | L21: =L20/$D$20 -> 0
B22: Total | D22: =D6+D8+D10+D12+D14+D16+D18+D20 -> 819 | E22: N/A | F22: =F6+F8+F10+F12+F14+F16+F18+F20 -> 819 | G22: N/A | H22: =H6+H8+H10+H12+H14+H16+H18+H20 -> 677 | I22: =I6+I8+I10+I12+I14+I16+I18+I20 -> 50 | J22: =J6+J8+J10+J12+J14+J16+J18+J20 -> 57 | K22: =K6+K8+K10+K12+K14+K16+K18+K20 -> 35 | L22: =L6+L8+L10+L12+L14+L16+L18+L20 -> 0
D23: =D22/$D$22 -> 1 | E23: N/A | F23: =F22/$D$22 -> 1 | G23: N/A | H23: =H22/D22 -> 0.82661783 | I23: =I22/D22 -> 0.061050061 | J23: =J22/D22 -> 0.06959707 | K23: =K22/F22 -> 0.042735043 | L23: =L22/F22 -> 0

Sheet PQA
AA3: Approved = A | AC3: =SUM(AC14:AC919) -> 5
G4: P030 - (MLTX-02-003) - Playgrounds Initiative at (Qassim Oasis , Hail and Tabuk Industrial City) | AA4: Approved with Comments = B | AC4: =SUM(AD14:AD919) -> 42
AA5: Revise & Resubmit = C | AC5: =SUM(AE14:AE919) -> 5
G6: Pre-Qualifications (PQA) - Submissions & Approvals | AA6: Under PMC Review / For Info. / Rejected / Cancelled / Recalled = D | AC6: =SUM(AF14:AF919) -> 0
AA7: Under Review = UR | AC7: =SUM(AG14:AG919) -> 3
AA8: Delayed with ADV | AC8: =COUNTIF(M14:M20,"Delayed") -> 0
AA9: Delayed with Egis | AC9: =COUNT(AH14:AH919) -> 0
AA10: Total Number of Submittals | AC10: =SUM(AC3:AC9) -> 55
L12: 1st Submittal - Rev-00 | Q12: 2nd Submittal - Rev-01 | U12: 3rd Submittal - Rev-02 | Y12: 4th Submittal - Rev-03 | AC12: =TODAY() -> 46306
B13: Transmittle # | C13: Location Area / Floor | D13: SI No. | E13: Transmittal Number | F13: Latest Rev.# | G13: ADV Reference Number | H13: Doc Type | I13: Description | J13: Discipline | K13: Site | L13: Actual Submission Date | M13: Delayed | N13: Date of Return Egis | O13: Duration with Egis | P13: Code | Q13: Actual Submission Date | R13: Date of Return Egis | S13: Duration with Egis | T13: Code | U13: Actual Submission Date | V13: Date of Return Egis | W13: Duration with Egis | X13: Code | Y13: Actual Submission Date | Z13: Date of Return Egis | AA13: Duration with Egis | AB13: Code | AC13: A | AD13: B | AE13: C | AF13: D | AG13: UR | AH13: Delayed with Egis | AI13: Remarks
D14: 1 | E14: MLTX-02-003-ADV-TS9-1-CVL-PQA-0001-00 | F14: 00 | G14: ADV-0001 | H14: PQA | I14: Pre-qualification of “PRO YARD AIRDOM” for supply and install of Air dome. | J14: CVL | K14: All | L14: 46085 | N14: 46088 | O14: =IF(L14="","",(IF(N14="",TODAY()-L14,N14-L14)+0)) & " Days " -> 3 Days | P14: C | AE14: 1 | AI14: Revise & Resubmit
D15: 2 | E15: MLTX-02-003-ADV-TS9-1-CVL-PQA-0002-00 | F15: 00 | G15: ADV-0002 | H15: PQA | I15: Pre-qualification by “Abdullah Abdin Ready-mix & Cement Products” | J15: CVL | K15: Tabuk | L15: 46105 | N15: 46130 | O15: =IF(L15="","",(IF(N15="",TODAY()-L15,N15-L15)+0)) & " Days " -> 25 Days | P15: B | AD15: 1 | AI15: Approved with Comments
D16: 3 | E16: MLTX-02-003-ADV-TS9-1-CVL-PQA-0003-00 | F16: 00 | G16: ADV-0003 | H16: PQA | I16: Pre-Qualification of Tabuk Engineering Laboratory for material testing | J16: CVL | K16: Tabuk | L16: 46105 | N16: 46107 | O16: =IF(L16="","",(IF(N16="",TODAY()-L16,N16-L16)+0)) & " Days " -> 2 Days | P16: C | AE16: 1 | AI16: Revise & Resubmit
D17: 4 | E17: MLTX-02-003-ADV-TS9-1-CVL-PQA-0004-00 | F17: 00 | G17: ADV-0004 | H17: PQA | I17: Pre-qualification of “Mohd Omar Jazzar Consulting Engineers Co.” for Third-Party Site and Laboratory Testing Services. | J17: CVL | K17: All | L17: 46116 | N17: 46118 | O17: =IF(L17="","",(IF(N17="",TODAY()-L17,N17-L17)+0)) & " Days " -> 2 Days | P17: B | AD17: 1 | AI17: Approved with Comments
D18: 5 | E18: MLTX-02-003-ADV-TS9-1-CVL-PQA-0005-00 | F18: 02 | G18: ADV-0005 | H18: PQA | I18: Pre-qualification of “Global Sport Gate - Doul” for Air Dome System. (Tabuk & Qasim) | J18: CVL | K18: Qassim & Tabuk | L18: 46116 | N18: 46144 | O18: =IF(L18="","",(IF(N18="",TODAY()-L18,N18-L18)+0)) & " Days " -> 28 Days | P18: C | Q18: 46160 | R18: 46160 | S18: =IF(Q18="","",(IF(R18="",TODAY()-Q18,R18-Q18)+0)) & " Days " -> 0 Days | T18: C | U18: 46176 | V18: 46177 | W18: =IF(U18="","",(IF(V18="",TODAY()-U18,V18-U18)+0)) & " Days " -> 1 Days | X18: B | AD18: 1 | AI18: Approved with Comments
D19: 6 | E19: MLTX-02-003-ADV-TS9-1-CVL-PQA-0006-00 | F19: 00 | G19: ADV-0006 | H19: PQA | I19: Pre-qualification of “MAPEI CONSTRUCTION CHEMICALS S.P.A.” for Repair and Finishing Works | J19: CVL | K19: All | L19: 46121 | N19: 46127 | O19: =IF(L19="","",(IF(N19="",TODAY()-L19,N19-L19)+0)) & " Days " -> 6 Days | P19: C | AE19: 1 | AI19: Revise & Resubmit
D20: 7 | E20: MLTX-02-003-ADV-TS9-1-CVL-PQA-0007-00 | F20: 00 | G20: ADV-0007 | H20: PQA | I20: Pre-qualification of “SACEP & Construct” for supply of Kerbstone, Interlock Paver and Wheel Stopper. | J20: CVL | K20: All | L20: 46131 | N20: 46133 | O20: =IF(L20="","",(IF(N20="",TODAY()-L20,N20-L20)+0)) & " Days " -> 2 Days | P20: B | AD20: 1 | AI20: Approved with Comments
D21: 8 | E21: MLTX-02-003-ADV-TS9-1-CVL-PQA-0008-00 | F21: 00 | G21: ADV-0008 | H21: PQA | I21: Pre-qualification of “OPAL United Factory for Concrete Products Co.” for supply of Kerbstone, Interlock Paver and Wheel Stopper. | J21: CVL | K21: Qassim & Hail | L21: 46131 | N21: 46145 | O21: =IF(L21="","",(IF(N21="",TODAY()-L21,N21-L21)+0)) & " Days " -> 14 Days | P21: B | AD21: 1 | AI21: Approved with Comments
D22: 9 | E22: MLTX-02-003-ADV-TS9-1-CVL-PQA-0009-00 | F22: 01 | G22: ADV-0009 | H22: PQA | I22: Pre-qualification of ASAS AL-MOHILEB CRUSHER for Backfilling Materials A1-a & Aggregate Base Course materials - Tabuk | J22: CVL | K22: Tabuk | L22: 46132 | N22: 46133 | O22: =IF(L22="","",(IF(N22="",TODAY()-L22,N22-L22)+0)) & " Days " -> 1 Days | P22: C | Q22: 46137 | R22: 46138 | S22: =IF(Q22="","",(IF(R22="",TODAY()-Q22,R22-Q22)+0)) & " Days " -> 1 Days | T22: B | AD22: 1 | AI22: Approved with Comments
D23: 10 | E23: MLTX-02-003-ADV-TS9-1-CVL-PQA-0010-00 | F23: 00 | G23: ADV-0010 | H23: PQA | I23: Pre-qualification of ASAS AL-MOHILEB Concrete batch plant for concrete ready mix for Tabuk project | J23: CVL | K23: Tabuk | L23: 46133 | N23: 46162 | O23: =IF(L23="","",(IF(N23="",TODAY()-L23,N23-L23)+0)) & " Days " -> 29 Days | P23: B | AD23: 1 | AI23: Approved with Comments
D24: 11 | E24: MLTX-02-003-ADV-TS9-1-CVL-PQA-0011-00 | F24: 00 | G24: ADV-0011 | H24: PQA | I24: Pre-qualification for Company Kharsana Tabuk Crusher (Abullah Abdin Industry Factory) for cement products for Backfilling Materials A1-a & Aggregate Base Course materials | J24: CVL | K24: Tabuk | L24: 46133 | N24: 46180 | O24: =IF(L24="","",(IF(N24="",TODAY()-L24,N24-L24)+0)) & " Days " -> 47 Days | P24: B | AD24: 1 | AI24: Approved with Comments
D25: 12 | E25: MLTX-02-003-ADV-TS9-1-CVL-PQA-0012-00 | F25: 02 | G25: ADV-0012 | H25: PQA | I25: Pre-qualification of Al-Omaier Trading & contracting. Co Crusher for Backfilling Materials A1-a & Aggregate Base Course materials | J25: CVL | K25: Hail | L25: 46138 | N25: 46145 | O25: =IF(L25="","",(IF(N25="",TODAY()-L25,N25-L25)+0)) & " Days " -> 7 Days | P25: C | Q25: 46151 | R25: 46151 | S25: =IF(Q25="","",(IF(R25="",TODAY()-Q25,R25-Q25)+0)) & " Days " -> 0 Days | T25: C | U25: 46153 | V25: 46153 | W25: =IF(U25="","",(IF(V25="",TODAY()-U25,V25-U25)+0)) & " Days " -> 0 Days | X25: B | AD25: 1 | AI25: Approved with Comments
D26: 13 | E26: MLTX-02-003-ADV-TS9-1-CVL-PQA-0013-00 | F26: 00 | G26: ADV-0013 | H26: PQA | I26: Pre-qualification of “Qassim Cement” for Portland Cement to be used in site for masonry and plaster works. | J26: CVL | K26: All | L26: 46146 | N26: 46152 | O26: =IF(L26="","",(IF(N26="",TODAY()-L26,N26-L26)+0)) & " Days " -> 6 Days | P26: A | AC26: 1 | AI26: Approved
D27: 14 | E27: MLTX-02-003-ADV-TS9-1-ARC-PQA-0014-00 | F27: 00 | G27: ADV-0014 | H27: PQA | I27: Pre-qualification of “Saudi Ceramic Company” for supply of Ceramic Tiles. | J27: ARC | K27: All | L27: 46147 | N27: 46152 | O27: =IF(L27="","",(IF(N27="",TODAY()-L27,N27-L27)+0)) & " Days " -> 5 Days | P27: B | AD27: 1 | AI27: Approved with Comments
D28: 15 | E28: MLTX-02-003-ADV-TS9-1-ARC-PQA-0015-00 | F28: 00 | G28: ADV-0015 | H28: PQA | I28: Pre-qualification of “Emad Elsafwah” for Supply of Marble & Granite. | J28: ARC | K28: All | L28: 46147 | N28: 46151 | O28: =IF(L28="","",(IF(N28="",TODAY()-L28,N28-L28)+0)) & " Days " -> 4 Days | P28: B | AD28: 1 | AI28: Approved with Comments
D29: 16 | E29: MLTX-02-003-ADV-TS9-1-CVL-PQA-0016-00 | F29: 00 | G29: ADV-0016 | H29: PQA | I29: Pre-qualification of Arabian Testing Evolution company Laboratory for 3rd party site and laboratory testing services | J29: CVL | K29: Tabuk | L29: 46151 | N29: 46158 | O29: =IF(L29="","",(IF(N29="",TODAY()-L29,N29-L29)+0)) & " Days " -> 7 Days | P29: B | AD29: 1 | AI29: Approved with Comments
D30: 17 | E30: MLTX-02-003-ADV-TS9-1-CVL-PQA-0017-00 | F30: 00 | G30: ADV-0017 | H30: PQA | I30: Pre-qualification of “ASAS Laboratory Company” for field and laboratory material testing (Hail). | J30: CVL | K30: Hail | L30: 46153 | N30: 46175 | O30: =IF(L30="","",(IF(N30="",TODAY()-L30,N30-L30)+0)) & " Days " -> 22 Days | P30: C | AE30: 1 | AI30: Revise & Resubmit
D31: 18 | E31: MLTX-02-003-ADV-TS9-1-CVL-PQA-0018-00 | F31: 00 | G31: ADV-0018 | H31: PQA | I31: Pre-qualification by RAWAI AL BASATIN COMPANY For Sports Fields Flooring & Landscape Construction works (Qassim, Hail and Tabuk) | J31: CVL | K31: All | L31: 46154 | N31: 46175 | O31: =IF(L31="","",(IF(N31="",TODAY()-L31,N31-L31)+0)) & " Days " -> 21 Days | P31: A | AC31: 1 | AI31: Approved
D32: 19 | E32: MLTX-02-003-ADV-TS9-1-CVL-PQA-0019-00 | F32: 00 | G32: ADV-0019 | H32: PQA | I32: Pre-qualification by GREEN YARD COMPANY for Sports Fields Flooring & Landscape works | J32: CVL | K32: All | L32: 46154 | N32: 46175 | O32: =IF(L32="","",(IF(N32="",TODAY()-L32,N32-L32)+0)) & " Days " -> 21 Days | P32: A | AC32: 1 | AI32: Approved
D33: 20 | E33: MLTX-02-003-ADV-TS9-1-ARC-PQA-0020-00 | F33: 00 | G33: ADV-0020 | H33: PQA | I33: Pre-qualification of ASAS AL-MOHILEB Concrete batch plant for supply of Kerbstone, Interlock, Wheel Stopper and CMU Block - (Tabuk Project ) | J33: ARC | K33: Tabuk | L33: 46155 | N33: 46162 | O33: =IF(L33="","",(IF(N33="",TODAY()-L33,N33-L33)+0)) & " Days " -> 7 Days | P33: B | AD33: 1 | AI33: Approved with Comments
D34: 21 | E34: MLTX-02-003-ADV-TS9-1-CVL-PQA-0021-00 | F34: 00 | G34: ADV-0021 | H34: PQA | I34: Pre-qualification FOR Arab Company for Laboratories and Soil (ACES) 3rd Party site and laboratory testing services Tabuk project | J34: CVL | K34: Tabuk | L34: 46161 | N34: 46162 | O34: =IF(L34="","",(IF(N34="",TODAY()-L34,N34-L34)+0)) & " Days " -> 1 Days | P34: B | AD34: 1 | AI34: Approved with Comments
D35: 22 | E35: MLTX-02-003-ADV-TS9-1-CVL-PQA-0022-00 | F35: 00 | G35: ADV-0022 | H35: PQA | I35: Pre-qualification Riyadh Geo-technique & Foundations Lab as a 3rd Party site and laboratory testing services Hail project | J35: CVL | K35: Hail | L35: 46161 | N35: 46161 | O35: =IF(L35="","",(IF(N35="",TODAY()-L35,N35-L35)+0)) & " Days " -> 0 Days | P35: B | AD35: 1 | AI35: Approved with Comments
D36: 23 | E36: MLTX-02-003-ADV-TS9-1-CVL-PQA-0023-00 | F36: 00 | G36: ADV-0023 | H36: PQA | I36: Pre-qualification of “Al Jammaz Hydrotek” for sports flooring and landscape work (Qassim Oasis, Hail and Tabuk Industrial City) | J36: CVL | K36: All | L36: 46167 | N36: 46177 | O36: =IF(L36="","",(IF(N36="",TODAY()-L36,N36-L36)+0)) & " Days " -> 10 Days | P36: B | AD36: 1 | AI36: Approved with Comments
D37: 24 | E37: MLTX-02-003-ADV-TS9-1-ARC-PQA-0024-00 | F37: 00 | G37: ADV-0024 | H37: PQA | I37: Pre-qualification by MALAEB ALASIMA CONTRACTING COMPANY For Sports Fields Flooring & Landscape Construction works | J37: ARC | K37: All | L37: 46176 | N37: 46180 | O37: =IF(L37="","",(IF(N37="",TODAY()-L37,N37-L37)+0)) & " Days " -> 4 Days | P37: A | AC37: 1 | AI37: Approved
D38: 25 | E38: MLTX-02-003-ADV-TS9-1-ARC-PQA-0025-00 | F38: 00 | G38: ADV-0025 | H38: PQA | I38: Pre-qualification by ARAB FARMER COMPANY For Agricultural Soil, Plants, Trees and shrubs works (Qassim-Hail-Tabuk) | J38: ARC | K38: All | L38: 46176 | N38: 46219 | O38: =IF(L38="","",(IF(N38="",TODAY()-L38,N38-L38)+0)) & " Days " -> 43 Days | P38: B | AD38: 1 | AI38: Approved with Comments
D39: 26 | E39: MLTX-02-003-ADV-TS9-1-CVL-PQA-0026-00 | F39: 00 | G39: ADV-0026 | H39: PQA | I39: Pre-qualification for Expert Future company for Asphalt Patch plant (Abdullah Abdin Factory for asphalt) for supplying asphalt - Tabuk project | J39: CVL | K39: Tabuk | L39: 46177 | N39: 46187 | O39: =IF(L39="","",(IF(N39="",TODAY()-L39,N39-L39)+0)) & " Days " -> 10 Days | P39: B | AD39: 1 | AI39: Approved with Comments
D40: 27 | E40: MLTX-02-003-ADV-TS9-1-CVL-PQA-0027-00 | F40: 01 | G40: ADV-0027 | H40: PQA | I40: Pre-qualification of “Alomaier Trading and Contracting Co.” for supply of Asphalt and Roads material. (HAIL) | J40: CVL | K40: Hail | L40: 46179 | N40: 46184 | O40: =IF(L40="","",(IF(N40="",TODAY()-L40,N40-L40)+0)) & " Days " -> 5 Days | P40: C | Q40: 46187 | R40: 46188 | S40: =IF(Q40="","",(IF(R40="",TODAY()-Q40,R40-Q40)+0)) & " Days " -> 1 Days | T40: A | AC40: 1 | AI40: Approved
D41: 28 | E41: MLTX-02-003-ADV-TS9-1-CVL-PQA-0028-00 | F41: 00 | G41: ADV-0028 | H41: PQA | I41: Pre-qualification Saudi Center for Insulations & Concrete repair (Seal-Tech) company for Insulations systems (water proofing-thermal insulation-Epoxies) & concrete repair | J41: CVL | K41: All | L41: 46181 | N41: 46186 | O41: =IF(L41="","",(IF(N41="",TODAY()-L41,N41-L41)+0)) & " Days " -> 5 Days | P41: B | AD41: 1 | AI41: Approved with Comments
D42: 29 | E42: MLTX-02-003-ADV-TS9-1-ARC-PQA-0029-00 | F42: 00 | G42: ADV-0029 | H42: PQA | I42: Pre-qualification by Saudi Floors COMPANY For Agricultural Soil, Plants, Trees and shrubs supplying & installation works (Qassim-Hail-Tabuk) | J42: ARC | K42: All | L42: 46183 | N42: 46187 | O42: =IF(L42="","",(IF(N42="",TODAY()-L42,N42-L42)+0)) & " Days " -> 4 Days | P42: B | AD42: 1 | AI42: Approved with Comments
D43: 30 | E43: MLTX-02-003-ADV-TS9-1-CVL-PQA-0030-00 | F43: 00 | G43: ADV-0030 | H43: PQA | I43: Pre-qualification for Fugro Suhaimi Company Limited Laboratory for 3rd party site and laboratory testing services (Tabuk) | J43: CVL | K43: Tabuk | L43: 46186 | N43: 46187 | O43: =IF(L43="","",(IF(N43="",TODAY()-L43,N43-L43)+0)) & " Days " -> 1 Days | P43: B | AD43: 1 | AI43: Approved with Comments
...

Sheet MS
AE3: Approved = A | AG3: =SUM(AG14:AG877) -> 5
G4: P030 - (MLTX-02-003) - Playgrounds Initiative at (Qassim Oasis , Hail and Tabuk Industrial City) | AE4: Approved with Comments = B | AG4: =SUM(AH14:AH877) -> 115
AE5: Revise & Resubmit = C | AG5: =SUM(AI14:AI877) -> 6
G6: Material Submittals (MS) - Submissions & Approvals | AE6: Under PMC Review / For Info. / Rejected / Cancelled / Recalled = D | AG6: =SUM(AJ14:AJ877) -> 0
AE7: Under Review = UR | AG7: =SUM(AK14:AK877) -> 10
AE8: Delayed with ADV | AG8: =COUNTIF(M14:M20,"Delayed") -> 0
AE9: Delayed with Egis | AG9: =SUM(AL14:AL877) -> 1
AE10: Total Number of Submittals | AG10: =SUM(AG3:AG9) -> 137
L12: 1st Submittal - Rev-00 | Q12: 2nd Submittal - Rev-01 | U12: 3rd Submittal - Rev-02 | Y12: 4th Submittal - Rev-03 | AC12: 5th Submittal - Rev-04 | AG12: =TODAY() -> 46306
B13: Transmittle # | C13: Location Area / Floor | D13: SI No. | E13: Transmittal Number | F13: Latest Rev.# | G13: ADV Reference Number | H13: Doc Type | I13: Description | J13: Discipline | K13: Site | L13: Actual Submission Date | M13: Delayed | N13: Date of Return Egis | O13: Duration with Egis | P13: Code | Q13: Actual Submission Date | R13: Date of Return Egis | S13: Duration with Egis | T13: Code | U13: Actual Submission Date | V13: Date of Return Egis | W13: Duration with Egis | X13: Code | Y13: Actual Submission Date | Z13: Date of Return Egis | AA13: Duration with Egis | AB13: Code | AC13: Actual Submission Date | AD13: Date of Return Egis | AE13: Duration with Egis | AF13: Code | AG13: A | AH13: B | AI13: C | AJ13: D | AK13: UR | AL13: Delayed with Egis | AM13: Remarks
D14: 1 | E14: MLTX-02-003-ADV-TS9-1-CVL-MS-0001-00 | F14: 00 | G14: ADV-0001 | H14: MS | I14: Material submittal for Ready Mix Concrete, Concrete Grade: C20 MPa SRC/OPC & C35 MPa SRC/OPC. | J14: CVL | K14: Qassim | L14: 46090 | N14: 46090 | O14: =IF(L14="","",(IF(N14="",TODAY()-L14,N14-L14)+0)) & " Days " -> 0 Days | P14: B | AH14: 1 | AM14: Approved with Comments
D15: 2 | E15: MLTX-02-003-ADV-TS9-1-CVL-MS-0002-00 | F15: 00 | G15: ADV-0002 | H15: MS | I15: Material submittal for Ready Mix Concrete, Concrete Grade: C20 MPa SRC/OPC & C35 MPa SRC/OPC. | J15: CVL | K15: Hail | L15: 46090 | N15: 46091 | O15: =IF(L15="","",(IF(N15="",TODAY()-L15,N15-L15)+0)) & " Days " -> 1 Days | P15: B | AH15: 1 | AM15: Approved with Comments
D16: 3 | E16: MLTX-02-003-ADV-TS9-1-CVL-MS-0003-00 | F16: 00 | G16: ADV-0003 | H16: MS | I16: Material submittal for Ready Mix Concrete, Concrete Grade: C20 MPa SRC/OPC & C35 MPa SRC/OPC. | J16: CVL | K16: Hail | L16: 46090 | N16: 46091 | O16: =IF(L16="","",(IF(N16="",TODAY()-L16,N16-L16)+0)) & " Days " -> 1 Days | P16: B | AH16: 1 | AM16: Approved with Comments
D17: 4 | E17: MLTX-02-003-ADV-TS9-1-CVL-MS-0004-00 | F17: 00 | G17: ADV-0004 | H17: MS | I17: Material submittal for “Hadded” Steel Reinforcing Bars ASTM A615 Grade 60 | J17: CVL | K17: All | L17: 46090 | N17: 46091 | O17: =IF(L17="","",(IF(N17="",TODAY()-L17,N17-L17)+0)) & " Days " -> 1 Days | P17: B | AH17: 1 | AM17: Approved with Comments
D18: 5 | E18: MLTX-02-003-ADV-TS9-1-CVL-MS-0005-00 | F18: 00 | G18: ADV-0005 | H18: MS | I18: Material submittal of “FOSROC” concrete repair materials. 1. RENDEROC FC 2. RENDEROC HS XTRA | J18: CVL | K18: All | L18: 46105 | N18: 46120 | O18: =IF(L18="","",(IF(N18="",TODAY()-L18,N18-L18)+0)) & " Days " -> 15 Days | P18: B | AH18: 1 | AM18: Approved with Comments
D19: 6 | E19: MLTX-02-003-ADV-TS9-1-CVL-MS-0006-00 | F19: 00 | G19: ADV-0006 | H19: MS | I19: Material submittal of “Sika” concrete repair materials. 1. SikaRep Fine 2. SikaRep | J19: CVL | K19: All | L19: 46105 | N19: 46121 | O19: =IF(L19="","",(IF(N19="",TODAY()-L19,N19-L19)+0)) & " Days " -> 16 Days | P19: B | AH19: 1 | AM19: Approved with Comments
D20: 7 | E20: MLTX-02-003-ADV-TS9-1-CVL-MS-0007-00 | F20: 00 | G20: ADV-0007 | H20: MS | I20: Material submittal for “Biflex TC” for termite control | J20: CVL | K20: All | L20: 46105 | N20: 46121 | O20: =IF(L20="","",(IF(N20="",TODAY()-L20,N20-L20)+0)) & " Days " -> 16 Days | P20: B | AH20: 1 | AM20: Approved with Comments
D21: 8 | E21: MLTX-02-003-ADV-TS9-1-CVL-MS-0008-00 | F21: 00 | G21: ADV-0008 | H21: MS | I21: Material submittal for “Al Ittefaq” Steel Reinforcing Bars ASTM A615 Grade 60 | J21: CVL | K21: All | L21: 46106 | N21: 46109 | O21: =IF(L21="","",(IF(N21="",TODAY()-L21,N21-L21)+0)) & " Days " -> 3 Days | P21: B | AH21: 1 | AM21: Approved with Comments
D22: 9 | E22: MLTX-02-003-ADV-TS9-1-CVL-MS-0009-00 | F22: 00 | G22: ADV-0009 | H22: MS | I22: Material submittal of “Poliane” Polyethylene Sheet 1. 250 micron under grade slab 2. 300 micron at roof waterproofing system | J22: CVL | K22: All | L22: 46106 | N22: 46109 | O22: =IF(L22="","",(IF(N22="",TODAY()-L22,N22-L22)+0)) & " Days " -> 3 Days | P22: B | AH22: 1 | AM22: Approved with Comments
D23: 10 | E23: MLTX-02-003-ADV-TS9-1-CVL-MS-0010-00 | F23: 00 | G23: ADV-0010 | H23: MS | I23: Material submittal of Readymix Concrete (Concrete Mix Design) for concrete grades: C20 SRC, C35 SRC/OPC. (TABUK) | J23: CVL | K23: Tabuk | L23: 46134 | N23: 46148 | O23: =IF(L23="","",(IF(N23="",TODAY()-L23,N23-L23)+0)) & " Days " -> 14 Days | P23: B | AH23: 1 | AM23: Approved with Comments
D24: 11 | E24: MLTX-02-003-ADV-TS9-1-CVL-MS-0011-00 | F24: 00 | G24: ADV-0011 | H24: MS | I24: Material submittal for “Autoclaved Aerated Panels” | J24: CVL | K24: All | L24: 46139 | N24: 46146 | O24: =IF(L24="","",(IF(N24="",TODAY()-L24,N24-L24)+0)) & " Days " -> 7 Days | P24: B | AH24: 1 | AM24: Approved with Comments
D25: 12 | E25: MLTX-02-003-ADV-TS9-1-MEC-MS-0012-00 | F25: 00 | G25: ADV-0012 | H25: MS | I25: Material submittal for AC UNITS | J25: MEC | K25: All | L25: 46147 | N25: 46148 | O25: =IF(L25="","",(IF(N25="",TODAY()-L25,N25-L25)+0)) & " Days " -> 1 Days | P25: B | AH25: 1 | AM25: Approved with Comments
... D32: 19 | E32: MLTX-02-003-ADV-TS9-1-MEC-MS-0019-00 | F32: 00 | G32: ADV-0019 | H32: MS | I32: MATERIAL SUBMITAL FOR HDPE PIPES AND FITTINGS | J32: MEC | K32: All | L32: 46148 | N32: 46153 | O32: =IF(L32="","",(IF(N32="",TODAY()-L32,N32-L32)+0)) & " Days " -> 5 Days | P32: B | AH32: 1 | AM32: Approved with Comments
D33: 20 | E33: MLTX-02-003-ADV-TS9-1-CVL-MS-0020-00 | F33: 00 | G33: ADV-0020 | H33: MS | I33: Material submittal for Backfilling Materials Class A-1-a (Hail) | J33: CVL | K33: Hail | L33: 46149 | N33: 46149 | O33: =IF(L33="","",(IF(N33="",TODAY()-L33,N33-L33)+0)) & " Days " -> 0 Days | P33: C | AI33: 1 | AM33: Revise & Resubmit
D34: 21 | E34: MLTX-02-003-ADV-TS9-1-ARC-MS-0021-00 | F34: 00 | G34: ADV-0021 | H34: MS | I34: Material submittal of “Mada Gypsum” for supply of gypsum board, metal framing and accessories. | J34: ARC | K34: All | L34: 46149 | N34: 46158 | O34: =IF(L34="","",(IF(N34="",TODAY()-L34,N34-L34)+0)) & " Days " -> 9 Days | P34: A | AG34: 1 | AM34: Approved
D35: 22 | E35: MLTX-02-003-ADV-TS9-1-ARC-MS-0022-00 | F35: 00 | G35: ADV-0022 | H35: MS | I35: Submittal of Qassim Cement “Finishing Cement” for use in site masonry and plastering works. | J35: ARC | K35: Qassim | L35: 46152 | N35: 46153 | O35: =IF(L35="","",(IF(N35="",TODAY()-L35,N35-L35)+0)) & " Days " -> 1 Days | P35: B | AH35: 1 | AM35: Approved with Comments
D36: 23 | E36: MLTX-02-003-ADV-TS9-1-ELE-MS-0023-00 | F36: 00 | G36: ADV-0023 | H36: MS | I36: Material submittal for “CABLE TRAY”. | J36: ELE | K36: All | L36: 46152 | N36: 46155 | O36: =IF(L36="","",(IF(N36="",TODAY()-L36,N36-L36)+0)) & " Days " -> 3 Days | P36: B | AH36: 1 | AM36: Approved with Comments
D37: 24 | E37: MLTX-02-003-ADV-TS9-1-ELE-MS-0024-00 | F37: 00 | G37: ADV-0024 | H37: MS | I37: Material submittal for “ EMT PIPES ,FITTINGS AND BOXES”. | J37: ELE | K37: All | L37: 46153 | N37: 46155 | O37: =IF(L37="","",(IF(N37="",TODAY()-L37,N37-L37)+0)) & " Days " -> 2 Days | P37: B | AH37: 1 | AM37: Approved with Comments
D38: 25 | E38: MLTX-02-003-ADV-TS9-1-ARC-MS-0025-00 | F38: 00 | G38: ADV-0025 | H38: MS | I38: Material Submittal for Thermal and Water Proofing Materials | J38: ARC | K38: All | L38: 46152 | N38: 46159 | O38: =IF(L38="","",(IF(N38="",TODAY()-L38,N38-L38)+0)) & " Days " -> 7 Days | P38: A | AG38: 1 | AM38: Approved
D39: 26 | E39: MLTX-02-003-ADV-TS9-1-ARC-MS-0026-00 | F39: 00 | G39: ADV-0026 | H39: MS | I39: Material Submittal for Waterproofing System Materials And Thermal Proofing | J39: ARC | K39: All | L39: 46152 | N39: 46153 | O39: =IF(L39="","",(IF(N39="",TODAY()-L39,N39-L39)+0)) & " Days " -> 1 Days | P39: A | AG39: 1 | AM39: Approved
D40: 27 | E40: MLTX-02-003-ADV-TS9-1-ARC-MS-0027-00 | F40: 00 | G40: ADV-0027 | H40: MS | I40: Material Submittal of “Saudi Ceramics” for supply of 300*300mm and 600*600 mm Ceramic Floor Tiles and 300*300mm Wall Ceramic Wall Tiles. | J40: ARC | K40: All | L40: 46152 | N40: 46153 | O40: =IF(L40="","",(IF(N40="",TODAY()-L40,N40-L40)+0)) & " Days " -> 1 Days | P40: B | AH40: 1 | AM40: Approved with Comments
D41: 28 | E41: MLTX-02-003-ADV-TS9-1-ARC-MS-0028-00 | F41: 00 | G41: ADV-0028 | H41: MS | I41: Material submittal of “Jazeera Paints” for epoxy floor paint, Internal/External Wall Acrylic Paints and Retroreflective Thermoplastic Road Paint. | J41: ARC | K41: All | L41: 46154 | N41: 46175 | O41: =IF(L41="","",(IF(N41="",TODAY()-L41,N41-L41)+0)) & " Days " -> 21 Days | P41: B | AH41: 1 | AM41: Approved with Comments
D42: 29 | E42: MLTX-02-003-ADV-TS9-1-ARC-MS-0029-00 | F42: 00 | G42: ADV-0029 | H42: MS | I42: Material submittal for Masonry Concrete Blocks | J42: ARC | K42: Qassim | L42: 46154 | N42: 46175 | O42: =IF(L42="","",(IF(N42="",TODAY()-L42,N42-L42)+0)) & " Days " -> 21 Days | P42: B | AH42: 1 | AM42: Approved with Comments
D43: 30 | E43: MLTX-02-003-ADV-TS9-1-ELE-MS-0030-00 | F43: 00 | G43: ADV-0030 | H43: MS | I43: Material submittal for LOW VOLTAGE CABLES AND WIRES | J43: ELE | K43: All | L43: 46154 | N43: 46155 | O43: =IF(L43="","",(IF(N43="",TODAY()-L43,N43-L43)+0)) & " Days " -> 1 Days | P43: B | AH43: 1 | AM43: Approved with Comments
D44: 31 | E44: MLTX-02-003-ADV-TS9-1-ARC-MS-0031-00 | F44: 00 | G44: ADV-0031 | H44: MS | I44: Material submittal for Masonry Concrete Blocks | J44: ARC | K44: Hail | L44: 46154 | N44: 46175 | O44: =IF(L44="","",(IF(N44="",TODAY()-L44,N44-L44)+0)) & " Days " -> 21 Days | P44: B | AH44: 1 | AM44: Approved with Comments
D45: 32 | E45: MLTX-02-003-ADV-TS9-1-ARC-MS-0032-00 | F45: 00 | G45: ADV-0032 | H45: MS | I45: Material submittal for Internal-External Signages / Traffic signs | J45: ARC | K45: All | L45: 46154 | N45: 46175 | O45: =IF(L45="","",(IF(N45="",TODAY()-L45,N45-L45)+0)) & " Days " -> 21 Days | P45: A | AG45: 1 | AM45: Approved
D46: 33 | E46: MLTX-02-003-ADV-TS9-1-ELE-MS-0033-00 | F46: 00 | G46: ADV-0033 | H46: MS | I46: Material Submittal for PVC CONDUIT AND FITTINGS | J46: ELE | K46: All | L46: 46155 | N46: 46163 | O46: =IF(L46="","",(IF(N46="",TODAY()-L46,N46-L46)+0)) & " Days " -> 8 Days | P46: B | AH46: 1 | AM46: Approved with Comments
D47: 34 | E47: MLTX-02-003-ADV-TS9-1-ARC-MS-0034-00 | F47: 00 | G47: ADV-0034 | H47: MS | I47: Material Submittal of Interlock Pavers (Hail, Qassim and Tabuk) Manufacturer: OPAL United Factory | J47: ARC | K47: All | L47: 46159 | N47: 46162 | O47: =IF(L47="","",(IF(N47="",TODAY()-L47,N47-L47)+0)) & " Days " -> 3 Days | P47: B | AH47: 1 | AM47: Approved with Comments
D48: 35 | E48: MLTX-02-003-ADV-TS9-1-MEC-MS-0035-00 | F48: 00 | G48: ADV-0035 | H48: MS | I48: Material Submittal for BOOSTER PUMP (Hail, Qassim and Tabuk) | J48: MEC | K48: All | L48: 46159 | N48: 46163 | O48: =IF(L48="","",(IF(N48="",TODAY()-L48,N48-L48)+0)) & " Days " -> 4 Days | P48: B | AH48: 1 | AM48: Approved with Comments
D49: 36 | E49: MLTX-02-003-ADV-TS9-1-CVL-MS-0036-00 | F49: 01 | G49: ADV-0036 | H49: MS | I49: Request for approval of Subgrade Material (Qassim) Supplier: Al-Sayigh Crusher | J49: CVL | K49: Qassim | L49: 46160 | N49: 46161 | O49: =IF(L49="","",(IF(N49="",TODAY()-L49,N49-L49)+0)) & " Days " -> 1 Days | P49: C | Q49: 46180 | R49: 46182 | S49: =IF(Q49="","",(IF(R49="",TODAY()-Q49,R49-Q49)+0)) & " Days " -> 2 Days | T49: B | AH49: 1 | AM49: Approved with Comments
...

Sheet MST
W3: Approved = A | Y3: =SUM(Y14:Y973) -> 0
G4: P030 - (MLTX-02-003) - Playgrounds Initiative at (Qassim Oasis , Hail and Tabuk Industrial City) | W4: Approved with Comments = B | Y4: =SUM(Z14:Z973) -> 22
W5: Revise & Resubmit = C | Y5: =SUM(AA14:AA9973) -> 0
G6: Method of Statement (MST) - Submissions & Approvals | W6: Under PMC Review / For Info. / Rejected / Cancelled / Recalled = D | Y6: =SUM(AB14:AB973) -> 0
W7: Under Review = UR | Y7: =SUM(AC14:AC973) -> 0
W8: Delayed with ADV | Y8: =COUNTIF(M14:M23,"Delayed") -> 0
W9: Delayed with Egis | Y9: =SUM(AD14:AD973) -> 0
W10: Total Number of Submittals | Y10: =SUM(Y3:Y9) -> 22
L12: 1st Submittal - Rev-00 | Q12: 2nd Submittal - Rev-01 | U12: 3rd Submittal - Rev-02 | Y12: =TODAY() -> 46306
B13: Transmittle # | C13: Location Area / Floor | D13: SI No. | E13: Transmittal Number | F13: Latest Rev.# | G13: ADV Reference Number | H13: Doc Type | I13: Description | J13: Discipline | K13: Planned Submission Date | L13: Actual Submission Date | M13: Delayed | N13: Date of Return Egis | O13: Duration with Egis | P13: Code | Q13: Actual Submission Date | R13: Date of Return Egis | S13: Duration with Egis | T13: Code | U13: Actual Submission Date | V13: Date of Return Egis | W13: Duration with Egis | X13: Code | Y13: A | Z13: B | AA13: C | AB13: D | AC13: UR | AD13: Delayed with Egis | AE13: Remarks
D14: 1 | E14: MLTX-02-003-ADV-TS9-1-CVL-MST-0001-00 | F14: 01 | G14: ADV-0001 | H14: MST | I14: Method of Statement for Excavation Works | J14: CVL | L14: 46090 | N14: 46098 | O14: =IF(L14="","",(IF(N14="",TODAY()-L14,N14-L14)+0)) & " Days " -> 8 Days | P14: C | Q14: 46104 | R14: 46107 | S14: =IF(Q14="","",(IF(R14="",TODAY()-Q14,R14-Q14)+0)) & " Days " -> 3 Days | T14: B | Z14: 1 | AE14: Approved with Comments
D15: 2 | E15: MLTX-02-003-ADV-TS9-1-CVL-MST-0002-00 | F15: 01 | G15: ADV-0002 | H15: MST | I15: Method of Statement for Backfilling Works | J15: CVL | L15: 46090 | N15: 46098 | O15: =IF(L15="","",(IF(N15="",TODAY()-L15,N15-L15)+0)) & " Days " -> 8 Days | P15: C | Q15: 46104 | R15: 46107 | S15: =IF(Q15="","",(IF(R15="",TODAY()-Q15,R15-Q15)+0)) & " Days " -> 3 Days | T15: B | Z15: 1 | AE15: Approved with Comments
D16: 3 | E16: MLTX-02-003-ADV-TS9-1-CVL-MST-0003-00 | F16: 01 | G16: ADV-0003 | H16: MST | I16: Method Statement for Anti-Termite Treatment | J16: CVL | L16: 46091 | N16: 46092 | O16: =IF(L16="","",(IF(N16="",TODAY()-L16,N16-L16)+0)) & " Days " -> 1 Days | P16: C | Q16: 46105 | R16: 46130 | S16: =IF(Q16="","",(IF(R16="",TODAY()-Q16,R16-Q16)+0)) & " Days " -> 25 Days | T16: B | Z16: 1 | AE16: Approved with Comments
D17: 4 | E17: MLTX-02-003-ADV-TS9-1-CVL-MST-0004-00 | F17: 00 | G17: ADV-0004 | H17: MST | I17: Method Statement for Cast-In-Situ Concrete Works | J17: CVL | L17: 46110 | N17: 46120 | O17: =IF(L17="","",(IF(N17="",TODAY()-L17,N17-L17)+0)) & " Days " -> 10 Days | P17: B | Z17: 1 | AE17: Approved with Comments
D18: 5 | E18: MLTX-02-003-ADV-TS9-1-CVL-MST-0005-00 | F18: 00 | G18: ADV-0005 | H18: MST | I18: Method Statement for Substructure Bituminous Damp Proof Coating | J18: CVL | L18: 46125 | N18: 46130 | O18: =IF(L18="","",(IF(N18="",TODAY()-L18,N18-L18)+0)) & " Days " -> 5 Days | P18: B | Z18: 1 | AE18: Approved with Comments
D19: 6 | E19: MLTX-02-003-ADV-TS9-1-ARC-MST-0006-00 | F19: 00 | G19: ADV-0006 | H19: MST | I19: Method Statement for Masonry Block Works | J19: ARC | L19: 46132 | N19: 46138 | O19: =IF(L19="","",(IF(N19="",TODAY()-L19,N19-L19)+0)) & " Days " -> 6 Days | P19: B | Z19: 1 | AE19: Approved with Comments
D20: 7 | E20: MLTX-02-003-ADV-TS9-1-ARC-MST-0007-00 | F20: 00 | G20: ADV-0007 | H20: MST | I20: MST for CURBSTONE & INTERLOCK PAVING WORKS | J20: ARC | L20: 46132 | N20: 46138 | O20: =IF(L20="","",(IF(N20="",TODAY()-L20,N20-L20)+0)) & " Days " -> 6 Days | P20: B | Z20: 1 | AE20: Approved with Comments
D21: 8 | E21: MLTX-02-003-ADV-TS9-1-CVL-MST-0008-00 | F21: 00 | G21: ADV-0008 | H21: MST | I21: Method Statement for Asphalt Paving Works | J21: CVL | L21: 46140 | N21: 46142 | O21: =IF(L21="","",(IF(N21="",TODAY()-L21,N21-L21)+0)) & " Days " -> 2 Days | P21: B | Z21: 1 | AE21: Approved with Comments
D22: 9 | E22: MLTX-02-003-ADV-TS9-1-CVL-MST-0009-00 | F22: 01 | G22: ADV-0009 | H22: MST | I22: Method Statement for Installation of Precast Concrete Manholes | J22: CVL | L22: 46142 | N22: 46142 | O22: =IF(L22="","",(IF(N22="",TODAY()-L22,N22-L22)+0)) & " Days " -> 0 Days | P22: C | Q22: 46144 | R22: 46149 | S22: =IF(Q22="","",(IF(R22="",TODAY()-Q22,R22-Q22)+0)) & " Days " -> 5 Days | T22: B | Z22: 1 | AE22: Approved with Comments
D23: 10 | E23: MLTX-02-003-ADV-TS9-1-ELE-MST-0010-00 | F23: 01 | G23: ADV-0010 | H23: MST | I23: Installation of LV, SMDB, DB's Switchgear | J23: ELE | L23: 46144 | N23: 46145 | O23: =IF(L23="","",(IF(N23="",TODAY()-L23,N23-L23)+0)) & " Days " -> 1 Days | P23: C | Q23: 46153 | R23: 46159 | S23: =IF(Q23="","",(IF(R23="",TODAY()-Q23,R23-Q23)+0)) & " Days " -> 6 Days | T23: B | Z23: 1 | AE23: Approved with Comments
D24: 11 | E24: MLTX-02-003-ADV-TS9-1-ELE-MST-0011-00 | F24: 01 | G24: ADV-0011 | H24: MST | I24: Installation of Earthing and Lightning Protection System | J24: ELE | L24: 46144 | N24: 46145 | O24: =IF(L24="","",(IF(N24="",TODAY()-L24,N24-L24)+0)) & " Days " -> 1 Days | P24: C | Q24: 46176 | R24: 46183 | S24: =IF(Q24="","",(IF(R24="",TODAY()-Q24,R24-Q24)+0)) & " Days " -> 7 Days | T24: B | Z24: 1 | AE24: Approved with Comments
D25: 12 | E25: MLTX-02-003-ADV-TS9-1-MEC-MST-0012-00 | F25: 00 | G25: ADV-0012 | H25: MST | I25: Installation of Drainage Piping Network | J25: MEC | L25: 46154 | N25: 46161 | O25: =IF(L25="","",(IF(N25="",TODAY()-L25,N25-L25)+0)) & " Days " -> 7 Days | P25: B | Z25: 1 | AE25: Approved with Comments
D26: 13 | E26: MLTX-02-003-ADV-TS9-1-CVL-MST-0013-00 | F26: 00 | G26: ADV-0013 | H26: MST | I26: Method Statement for Installation of Autoclaved Aerated Panels | J26: CVL | L26: 46161 | N26: 46174 | O26: =IF(L26="","",(IF(N26="",TODAY()-L26,N26-L26)+0)) & " Days " -> 13 Days | P26: B | Z26: 1 | AE26: Approved with Comments
D27: 14 | E27: MLTX-02-003-ADV-TS9-1-MEC-MST-0014-00 | F27: 00 | G27: ADV-0014 | H27: MST | I27: Installation of Water Supply Piping Network | J27: MEC | L27: 46175 | N27: 46179 | O27: =IF(L27="","",(IF(N27="",TODAY()-L27,N27-L27)+0)) & " Days " -> 4 Days | P27: B | Z27: 1 | AE27: Approved with Comments
D28: 15 | E28: MLTX-02-003-ADV-TS9-1-ELE-MST-0015-00 | F28: 00 | G28: ADV-0015 | H28: MST | I28: Installation of PVC conduits & Accessories | J28: ELE | L28: 46175 | N28: 46181 | O28: =IF(L28="","",(IF(N28="",TODAY()-L28,N28-L28)+0)) & " Days " -> 6 Days | P28: B | Z28: 1 | AE28: Approved with Comments
D29: 16 | E29: MLTX-02-003-ADV-TS9-1-ARC-MST-0016-00 | F29: 00 | G29: ADV-0016 | H29: MST | I29: Method Statement for Epoxy Paint for walls & floors | J29: ARC | L29: 46184 | N29: 46186 | O29: =IF(L29="","",(IF(N29="",TODAY()-L29,N29-L29)+0)) & " Days " -> 2 Days | P29: B | Z29: 1 | AE29: Approved with Comments
D30: 17 | E30: MLTX-02-003-ADV-TS9-1-CVL-MST-0017-00 | F30: 00 | G30: ADV-0017 | H30: MST | I30: Method Statement for Installation of Steel chain link fence & Gates | J30: CVL | L30: 46189 | N30: 46197 | O30: =IF(L30="","",(IF(N30="",TODAY()-L30,N30-L30)+0)) & " Days " -> 8 Days | P30: B | Z30: 1 | AE30: Approved with Comments
D31: 18 | E31: MLTX-02-003-ADV-TS9-1-CVL-MST-0018-00 | F31: 00 | G31: ADV-0018 | H31: MST | I31: Method Statement for Installation of Water Proofing Membrane | J31: CVL | L31: 46194 | N31: 46206 | O31: =IF(L31="","",(IF(N31="",TODAY()-L31,N31-L31)+0)) & " Days " -> 12 Days | P31: B | Z31: 1 | AE31: Approved with Comments
D32: 19 | E32: MLTX-02-003-ADV-TS9-1-CVL-MST-0019-00 | F32: 01 | G32: ADV-0019 | H32: MST | I32: Method Statement for Installation of woven & non-woven Geotextile | J32: CVL | L32: 46212 | N32: 46221 | O32: =IF(L32="","",(IF(N32="",TODAY()-L32,N32-L32)+0)) & " Days " -> 9 Days | P32: C | Q32: 46224 | R32: 46225 | S32: =IF(Q32="","",(IF(R32="",TODAY()-Q32,R32-Q32)+0)) & " Days " -> 1 Days | T32: B | Z32: 1 | AE32: Approved with Comments
D33: 20 | E33: MLTX-02-003-ADV-TS9-1-CVL-MST-0020-00 | F33: 00 | G33: ADV-0020 | H33: MST | I33: Method Statement for Plaster Work | J33: CVL | L33: 46233 | N33: 46237 | O33: =IF(L33="","",(IF(N33="",TODAY()-L33,N33-L33)+0)) & " Days " -> 4 Days | P33: B | Z33: 1 | AE33: Approved with Comments
D34: 21 | E34: MLTX-02-003-ADV-TS9-1-ARC-MST-0021-00 | F34: 00 | G34: ADV-0021 | H34: MST | I34: Method Statement for Installation of Gypsum Board Ceiling | J34: ARC | L34: 46270 | N34: 46277 | O34: =IF(L34="","",(IF(N34="",TODAY()-L34,N34-L34)+0)) & " Days " -> 7 Days | P34: B | Z34: 1 | AE34: Approved with Comments
D35: 22 | E35: MLTX-02-003-ADV-TS9-1-ARC-MST-0022-00 | F35: 00 | G35: ADV-0022 | H35: MST | I35: Method Statement for: Method Statement for Installation of Rubber Tartan Tiles | J35: ARC | L35: 46270 | N35: 46277 | O35: =IF(L35="","",(IF(N35="",TODAY()-L35,N35-L35)+0)) & " Days " -> 7 Days | P35: C | Q35: 46280 | S35: =IF(Q35="","",(IF(R35="",TODAY()-Q35,R35-Q35)+0)) & " Days " -> 26 Days | T35: B | Z35: 1 | AE35: Approved with Comments

Sheet Doc. Submittals  (Tech & Gen)
AI3: Approved = A | AK3: =SUM(AK14:AK829) -> 12
G4: P030 - (MLTX-02-003) - Playgrounds Initiative at (Qassim Oasis , Hail and Tabuk Industrial City) | AI4: Approved with Comments = B | AK4: =SUM(AL14:AL829) -> 136
AI5: Revise & Resubmit = C | AK5: =SUM(AM14:AM829) -> 13
G6: Technical Documents Submittals (DS) - Submissions & Approvals | AI6: Under PMC Review / For Info. / Rejected / Cancelled / Recalled = D | AK6: =SUM(AN14:AN829) -> 0
AI7: Under Review = UR | AK7: =SUM(AO14:AO829) -> 10
AI8: Delayed with ADV | AK8: =COUNTIF(M14:M20,"Delayed") -> 0
AI9: Delayed with Egis | AK9: =SUM(AP14:AP829) -> 12
AI10: Total Number of Submittals | AK10: =SUM(AK3:AK9) -> 183
L12: 1st Submittal - Rev-00 | Q12: 2nd Submittal - Rev-01 | U12: 3rd Submittal - Rev-02 | Y12: 4th Submittal - Rev-03 | AC12: 5th Submittal - Rev-04 | AG12: 6th Submittal - Rev-05 | AK12: =TODAY() -> 46306
B13: Transmittle # | C13: Location Area / Floor | D13: SI No. | E13: Transmittal Number | F13: Latest Rev.# | G13: ADV Reference Number | H13: Doc Type | I13: Description | J13: Discipline | K13: Planned Submission Date | L13: Actual Submission Date | M13: Delayed | N13: Date of Return Egis | O13: Duration with Egis | P13: Code | Q13: Actual Submission Date | R13: Date of Return Egis | S13: Duration with Egis | T13: Code | U13: Actual Submission Date | V13: Date of Return Egis | W13: Duration with Egis | X13: Code | Y13: Actual Submission Date | Z13: Date of Return Egis | AA13: Duration with Egis | AB13: Code | AC13: Actual Submission Date | AD13: Date of Return Egis | AE13: Duration with Egis | AF13: Code | AG13: Actual Submission Date | AH13: Date of Return Egis | AI13: Duration with Egis | AJ13: Code | AK13: A | AL13: B | AM13: C | AN13: D | AO13: UR | AP13: Delayed with Egis | AQ13: Remarks
D14: 1 | E14: MLTX-02-003-ADV-TS9-1-PRM-PLN-0001-00 | F14: 01 | G14: ADV-001 | H14: PRM | I14: Baseline Program Schedule – Qassim, Hail & Tabuk | J14: PLN | L14: 46081 | N14: 46085 | O14: =IF(L14="","",(IF(N14="",TODAY()-L14,N14-L14)+0)) & " Days " -> 4 Days | P14: C | Q14: 46085 | R14: 46086 | S14: =IF(Q14="","",(IF(R14="",TODAY()-Q14,R14-Q14)+0)) & " Days " -> 1 Days | T14: A | AK14: 1 | AQ14: Approved
D15: 2 | E15: MLTX-02-003-ADV-TS9-1-PRM-PQP-0002-00 | F15: 02 | G15: ADV-002 | H15: PRM | I15: Project Quality Plan – Qassim, Hail & Tabuk | J15: PQP | L15: 46093 | N15: 46093 | O15: =IF(L15="","",(IF(N15="",TODAY()-L15,N15-L15)+0)) & " Days " -> 0 Days | P15: C | Q15: 46121 | R15: 46126 | S15: =IF(Q15="","",(IF(R15="",TODAY()-Q15,R15-Q15)+0)) & " Days " -> 5 Days | T15: C | U15: 46165 | V15: 46180 | W15: =IF(U15="","",(IF(V15="",TODAY()-U15,V15-U15)+0)) & " Days " -> 15 Days | X15: B | AL15: 1 | AQ15: Approved with Comments
D16: 3 | E16: MLTX-02-003-ADV-TS9-1-PRM-ORG-0003-00 | F16: 00 | G16: ADV-003 | H16: PRM | I16: Organization Chart – Hail, Qassim & Tabuk | J16: ORG | L16: 46104 | N16: 46107 | O16: =IF(L16="","",(IF(N16="",TODAY()-L16,N16-L16)+0)) & " Days " -> 3 Days | P16: B | AL16: 1 | AQ16: Approved with Comments
D17: 4 | E17: MLTX-02-003-ADV-TS9-1-PRM-CUV-0004-00 | F17: 01 | G17: ADV-004 | H17: PRM | I17: Curriculum vitae (CV) - Abdelelaah Saad Alashry - QA/QC Manager | J17: CUV | L17: 46109 | N17: 46110 | O17: =IF(L17="","",(IF(N17="",TODAY()-L17,N17-L17)+0)) & " Days " -> 1 Days | P17: C | Q17: 46111 | R17: 46113 | S17: =IF(Q17="","",(IF(R17="",TODAY()-Q17,R17-Q17)+0)) & " Days " -> 2 Days | T17: C | AM17: 1 | AQ17: Revise & Resubmit
D18: 5 | E18: MLTX-02-003-ADV-TS9-1-PRM-CUV-0005-00 | F18: 01 | G18: ADV-005 | H18: PRM | I18: Curriculum vitae (CV) - Aatif Hussain - HSE Engineer | J18: CUV | L18: 46110 | N18: 46125 | O18: =IF(L18="","",(IF(N18="",TODAY()-L18,N18-L18)+0)) & " Days " -> 15 Days | P18: B | Q18: 46214 | S18: =IF(Q18="","",(IF(R18="",TODAY()-Q18,R18-Q18)+0)) & " Days " -> 92 Days | T18: UR | AP18: 1 | AQ18: Delayed with Egis
D19: 6 | E19: MLTX-02-003-ADV-TS9-1-PRM-CUV-0006-00 | F19: 01 | G19: ADV-006 | H19: PRM | I19: Curriculum vitae (CV) - Jaafar Gharaibeh - Civil Senior Engineer | J19: CUV | L19: 46111 | N19: 46112 | O19: =IF(L19="","",(IF(N19="",TODAY()-L19,N19-L19)+0)) & " Days " -> 1 Days | P19: C | Q19: 46114 | R19: 46116 | S19: =IF(Q19="","",(IF(R19="",TODAY()-Q19,R19-Q19)+0)) & " Days " -> 2 Days | T19: B | AL19: 1 | AQ19: Approved with Comments
D20: 7 | E20: MLTX-02-003-ADV-TS9-1-PRM-CUV-0007-00 | F20: 01 | G20: ADV-007 | H20: PRM | I20: Curriculum vitae (CV) - NAVEED UR REHMAN - Planning Engineer | J20: CUV | L20: 46111 | N20: 46112 | O20: =IF(L20="","",(IF(N20="",TODAY()-L20,N20-L20)+0)) & " Days " -> 1 Days | P20: C | Q20: 46113 | R20: 46120 | S20: =IF(Q20="","",(IF(R20="",TODAY()-Q20,R20-Q20)+0)) & " Days " -> 7 Days | T20: B | AL20: 1 | AQ20: Approved with Comments
D21: 8 | E21: MLTX-02-003-ADV-TS9-1-PRM-CUV-0008-00 | F21: 01 | G21: ADV-008 | H21: PRM | I21: Curriculum vitae (CV) – Abdelsalam Ali Mohamed Ahmed – Agricultural Engineer | J21: CUV | L21: 46111 | N21: 46112 | O21: =IF(L21="","",(IF(N21="",TODAY()-L21,N21-L21)+0)) & " Days " -> 1 Days | P21: C | Q21: 46116 | R21: 46116 | S21: =IF(Q21="","",(IF(R21="",TODAY()-Q21,R21-Q21)+0)) & " Days " -> 0 Days | T21: B | AL21: 1 | AQ21: Approved with Comments
D22: 9 | E22: MLTX-02-003-ADV-TS9-1-PRM-CUV-0009-00 | F22: 00 | G22: ADV-009 | H22: PRM | I22: Curriculum vitae (CV) – Hany Faris - Senior Electrical Engineer | J22: CUV | L22: 46111 | N22: 46113 | O22: =IF(L22="","",(IF(N22="",TODAY()-L22,N22-L22)+0)) & " Days " -> 2 Days | P22: B | AL22: 1 | AQ22: Approved with Comments
D23: 10 | E23: MLTX-02-003-ADV-TS9-1-PRM-CUV-0010-00 | F23: 01 | G23: ADV-010 | H23: PRM | I23: Curriculum vitae (CV) – Mohammad Saleem Ansari - Senior Mechanical Engineer (MEP) | J23: CUV | L23: 46111 | N23: 46111 | O23: =IF(L23="","",(IF(N23="",TODAY()-L23,N23-L23)+0)) & " Days " -> 0 Days | P23: C | Q23: 46114 | R23: 46120 | S23: =IF(Q23="","",(IF(R23="",TODAY()-Q23,R23-Q23)+0)) & " Days " -> 6 Days | T23: B | AL23: 1 | AQ23: Approved with Comments
D24: 11 | E24: MLTX-02-003-ADV-TS9-1-PRM-RPT-0011-00 | F24: 00 | G24: ADV-011 | H24: PRM | I24: GEOTECHNICAL INVESTIGATION REPORT FOR QASSIM INDUSTRIAL PROJECT (Order No.078) QASSIM, KINGDOM OF SAUDI ARABIA - Applus Arabia for Testing and Physical Analysis LTD. - QASSIM | J24: RPT | L24: 46112 | AL24: 1 | AQ24: For Information
D25: 12 | E25: MLTX-02-003-ADV-TS9-1-PRM-RPT-0012-00 | F25: 00 | G25: ADV-012 | H25: PRM | I25: GEOTECHNICAL INVESTIGATION REPORT FOR THE PROPOSED STADIUMS INITIATIVE AT TABUK Industrial City District, Tabuk, The Kingdom of Saudi Arabia - Applus Arabia for Testing and Physical Analysis. - TABUK | J25: RPT | L25: 46112 | AL25: 1 | AQ25: For Information
D26: 13 | E26: MLTX-02-003-ADV-TS9-1-PRM-RPT-0013-00 | F26: 00 | G26: ADV-013 | H26: PRM | I26: GEOTECHNICAL INVESTIGATION REPORT FOR THE PROPOSED PLAYGROUNDS INITIAIVE-HAIL INDUSTRIAL PROJECT (WORK ODER NO:074) MODON OASIS, HAIL, K.S.A - Appl us Arabia for Testing and Physical Analysis LTD - HAIL | J26: RPT | L26: 46112 | AL26: 1 | AQ26: For Information
D27: 14 | E27: MLTX-02-003-ADV-TS9-1-PRM-CUV-0014-00 | F27: 00 | G27: ADV-014 | H27: PRM | I27: Curriculum vitae (CV) – Ahmed Mohammed Emeish – Project Manager | J27: CUV | L27: 46114 | N27: 46117 | O27: =IF(L27="","",(IF(N27="",TODAY()-L27,N27-L27)+0)) & " Days " -> 3 Days | P27: B | AL27: 1 | AQ27: Approved with Comments
D28: 15 | E28: MLTX-02-003-ADV-TS9-1-PRM-CUV-0015-00 | F28: 00 | G28: ADV-015 | H28: PRM | I28: Curriculum vitae (CV) – Bilal Nabil Loutfi - Senior Land Surveyor Engineer | J28: CUV | L28: 46114 | N28: 46120 | O28: =IF(L28="","",(IF(N28="",TODAY()-L28,N28-L28)+0)) & " Days " -> 6 Days | P28: B | AL28: 1 | AQ28: Approved with Comments
D29: 16 | E29: MLTX-02-003-ADV-TS9-1-HSE-PLN-0016-00 | F29: 01 | G29: ADV-016 | H29: HSE | I29: Health & Safety Plan - Hail | J29: PLN | L29: 46116 | N29: 46131 | O29: =IF(L29="","",(IF(N29="",TODAY()-L29,N29-L29)+0)) & " Days " -> 15 Days | P29: A | Q29: 46141 | R29: 46176 | S29: =IF(Q29="","",(IF(R29="",TODAY()-Q29,R29-Q29)+0)) & " Days " -> 35 Days | T29: A | AK29: 1 | AQ29: Approved
D30: 17 | E30: MLTX-02-003-ADV-TS9-1-HSE-PLN-0017-00 | F30: 00 | G30: ADV-017 | H30: HSE | I30: Health & Safety Plan - Tabuk | J30: PLN | L30: 46116 | N30: 46118 | O30: =IF(L30="","",(IF(N30="",TODAY()-L30,N30-L30)+0)) & " Days " -> 2 Days | P30: B | AL30: 1 | AQ30: Approved with Comments
D31: 18 | E31: MLTX-02-003-ADV-TS9-1-HSE-PLN-0018-00 | F31: 01 | G31: ADV-018 | H31: HSE | I31: Health & Safety Plan - Qassim | J31: PLN | L31: 46116 | N31: 46133 | O31: =IF(L31="","",(IF(N31="",TODAY()-L31,N31-L31)+0)) & " Days " -> 17 Days | P31: C | Q31: 46141 | R31: 46153 | S31: =IF(Q31="","",(IF(R31="",TODAY()-Q31,R31-Q31)+0)) & " Days " -> 12 Days | T31: C | AM31: 1 | AQ31: Revise & Resubmit
D32: 19 | E32: MLTX-02-003-ADV-TS9-1-HSE-PLN-0019-00 | F32: 01 | G32: ADV-019 | H32: HSE | I32: ENVIRONMENTAL MANAGEMENT PLAN - Hail | J32: PLN | L32: 46116 | N32: 46127 | O32: =IF(L32="","",(IF(N32="",TODAY()-L32,N32-L32)+0)) & " Days " -> 11 Days | P32: A | Q32: 46154 | R32: 46177 | S32: =IF(Q32="","",(IF(R32="",TODAY()-Q32,R32-Q32)+0)) & " Days " -> 23 Days | T32: A | AK32: 1 | AQ32: Approved
D33: 20 | E33: MLTX-02-003-ADV-TS9-1-HSE-PLN-0020-00 | F33: 00 | G33: ADV-020 | H33: HSE | I33: ENVIRONMENTAL MANAGEMENT PLAN - Qassim | J33: PLN | L33: 46116 | N33: 46131 | O33: =IF(L33="","",(IF(N33="",TODAY()-L33,N33-L33)+0)) & " Days " -> 15 Days | P33: C | AM33: 1 | AQ33: Revise & Resubmit
D34: 21 | E34: MLTX-02-003-ADV-TS9-1-HSE-PLN-0021-00 | F34: 00 | G34: ADV-021 | H34: HSE | I34: ENVIRONMENTAL MANAGEMENT PLAN - Tabuk | J34: PLN | L34: 46116 | N34: 46118 | O34: =IF(L34="","",(IF(N34="",TODAY()-L34,N34-L34)+0)) & " Days " -> 2 Days | P34: B | AL34: 1 | AQ34: Approved with Comments
D35: 22 | E35: MLTX-02-003-ADV-TS9-1-HSE-PLN-0022-00 | F35: 01 | G35: ADV-022 | H35: HSE | I35: WASTE MANAGEMENT PLAN - Hail | J35: PLN | L35: 46116 | N35: 46127 | O35: =IF(L35="","",(IF(N35="",TODAY()-L35,N35-L35)+0)) & " Days " -> 11 Days | P35: B | Q35: 46207 | R35: 46253 | S35: =IF(Q35="","",(IF(R35="",TODAY()-Q35,R35-Q35)+0)) & " Days " -> 46 Days | T35: A | AK35: 1 | AQ35: Approved
D36: 23 | E36: MLTX-02-003-ADV-TS9-1-HSE-PLN-0023-00 | F36: 00 | G36: ADV-023 | H36: HSE | I36: WASTE MANAGEMENT PLAN - Qassim | J36: PLN | L36: 46116 | N36: 46131 | O36: =IF(L36="","",(IF(N36="",TODAY()-L36,N36-L36)+0)) & " Days " -> 15 Days | P36: B | AL36: 1 | AQ36: Approved with Comments
D37: 24 | E37: MLTX-02-003-ADV-TS9-1-HSE-PLN-0024-00 | F37: 00 | G37: ADV-024 | H37: HSE | I37: WASTE MANAGEMENT PLAN - Tabuk | J37: PLN | L37: 46116 | N37: 46118 | O37: =IF(L37="","",(IF(N37="",TODAY()-L37,N37-L37)+0)) & " Days " -> 2 Days | P37: B | AL37: 1 | AQ37: Approved with Comments
D38: 25 | E38: MLTX-02-003-ADV-TS9-1-HSE-PLN-0025-00 | F38: 01 | G38: ADV-025 | H38: HSE | I38: EMERGENCY PREPARDNESS & RESPONSE PLAN - Hail | J38: PLN | L38: 46117 | N38: 46127 | O38: =IF(L38="","",(IF(N38="",TODAY()-L38,N38-L38)+0)) & " Days " -> 10 Days | P38: B | Q38: 46207 | R38: 46253 | S38: =IF(Q38="","",(IF(R38="",TODAY()-Q38,R38-Q38)+0)) & " Days " -> 46 Days | T38: A | AK38: 1 | AQ38: Approved
D39: 26 | E39: MLTX-02-003-ADV-TS9-1-HSE-PLN-0026-00 | F39: 00 | G39: ADV-026 | H39: HSE | I39: EMERGENCY PREPARDNESS & RESPONSE PLAN – Qassim | J39: PLN | L39: 46117 | N39: 46131 | O39: =IF(L39="","",(IF(N39="",TODAY()-L39,N39-L39)+0)) & " Days " -> 14 Days | P39: B | AL39: 1 | AQ39: Approved with Comments
D40: 27 | E40: MLTX-02-003-ADV-TS9-1-HSE-PLN-0027-00 | F40: 00 | G40: ADV-027 | H40: HSE | I40: SITE SECURITY MANAGEMENT PLAN - Hail | J40: PLN | L40: 46117 | N40: 46134 | O40: =IF(L40="","",(IF(N40="",TODAY()-L40,N40-L40)+0)) & " Days " -> 17 Days | P40: B | AL40: 1 | AQ40: Approved with Comments
D41: 28 | E41: MLTX-02-003-ADV-TS9-1-HSE-PLN-0028-00 | F41: 00 | G41: ADV-028 | H41: HSE | I41: SITE SECURITY MANAGEMENT PLAN - Qassim | J41: PLN | L41: 46117 | N41: 46146 | O41: =IF(L41="","",(IF(N41="",TODAY()-L41,N41-L41)+0)) & " Days " -> 29 Days | P41: B | AL41: 1 | AQ41: Approved with Comments
D42: 29 | E42: MLTX-02-003-ADV-TS9-1-HSE-PLN-0029-00 | F42: 00 | G42: ADV-029 | H42: HSE | I42: SITE SECURITY MANAGEMENT PLAN - Tabuk | J42: PLN | L42: 46117 | N42: 46118 | O42: =IF(L42="","",(IF(N42="",TODAY()-L42,N42-L42)+0)) & " Days " -> 1 Days | P42: B | AL42: 1 | AQ42: Approved with Comments
D43: 30 | E43: MLTX-02-003-ADV-TS9-1-HSE-PRO-0030-00 | F43: 00 | G43: ADV-030 | H43: HSE | I43: PERMIT TO WORK PROCEDURE - Hail | J43: PRO | L43: 46117 | N43: 46127 | O43: =IF(L43="","",(IF(N43="",TODAY()-L43,N43-L43)+0)) & " Days " -> 10 Days | P43: B | AL43: 1 | AQ43: Approved with Comments
...

Sheet Design Dwgs
AB3: Approved = A | AD3: =SUM(AD14:AD874) -> 0
G4: P030 - (MLTX-02-003) - Playgrounds Initiative at (Qassim Oasis , Hail and Tabuk Industrial City) | AB4: Approved with Comments = B | AD4: =SUM(AE14:AE874) -> 0
AB5: Revise & Resubmit = C | AD5: =SUM(AF14:AF874) -> 0
G6: Design Drawings (DD) - Submissions & Approvals | AB6: Under PMC Review / For Info. / Rejected / Cancelled / Recalled = D | AD6: =SUM(AG14:AG874) -> 0
AB7: Under Review = UR | AD7: =SUM(AH14:AH874) -> 0
AB8: Delayed with ADV | AD8: =COUNTIF(N14:N19,"Delayed") -> 0
AB9: Delayed with Egis | AD9: =SUM(AI14:AI874) -> 0
AB10: Total Number of Submittals | AD10: =SUM(AD3:AD9) -> 0
M12: 1st Submittal - Rev-00 | R12: 2nd Submittal - Rev-01 | V12: 3rd Submittal - Rev-02 | Z12: 4rd Submittal - Rev-03 | AD12: =TODAY() -> 46306
B13: Transmittle # | C13: Location Area / Floor | D13: SI No. | E13: Transmittal Number | F13: Latest Rev.# | G13: ADV Reference Number | H13: Doc Type | I13: Drawing Number | J13: Drawing Description | K13: Discipline | L13: Site | M13: Actual Submission Date | N13: Delayed | O13: Date of Return Egis | P13: Duration with Egis | Q13: Code | R13: Actual Submission Date | S13: Date of Return Egis | T13: Duration with Egis | U13: Code | V13: Actual Submission Date | W13: Date of Return Egis | X13: Duration with Egis | Y13: Code | Z13: Actual Submission Date | AA13: Date of Return Egis | AB13: Duration with Egis | AC13: Code | AD13: A | AE13: B | AF13: C | AG13: D | AH13: UR | AI13: Delayed with Egis | AJ13: Remarks
D14: 1
D15: 2
D16: 3
D17: 4
D18: 5
D19: 6
D20: 7
D21: 8
D22: 9
D23: 10

Sheet RFI
Z3: Approved = A | AB3: =SUM(AB14:AB935) -> 0
G4: P030 - (MLTX-02-003) - Playgrounds Initiative at (Qassim Oasis , Hail and Tabuk Industrial City) | Z4: Approved with Comments = B | AB4: =SUM(AC14:AC935) -> 30
Z5: Revise & Resubmit = C | AB5: =SUM(AD14:AD935) -> 3
G6: Request for Information (RFI) - Submissions & Approvals | Z6: Under PMC Review / For Info. / Rejected / Cancelled / Recalled = D | AB6: =SUM(AE14:AE935) -> 0
Z7: Under Review = UR | AB7: =SUM(AF14:AF935) -> 0
Z8: Delayed with ADV | AB8: =COUNTIF(L14:L20,"Delayed") -> 0
Z9: Delayed with Egis | AB9: =SUM(AG14:AG935) -> 1
Z10: Total Number of Submittals | AB10: =SUM(AB3:AB9) -> 34
K12: 1st Submittal - Rev-00 | P12: 2nd Submittal - Rev-01 | T12: 3rd Submittal - Rev-02 | X12: 4th Submittal - Rev-03 | AB12: =TODAY() -> 46306
B13: Transmittle # | C13: Location Area / Floor | D13: SI No. | E13: Transmittal Number | F13: Latest Rev.# | G13: ADV Reference Number | H13: Doc Type | I13: Description / Subject | J13: Discipline | K13: Actual Submission Date | L13: Delayed | M13: Date of Return Egis | N13: Duration with Egis | O13: Code | P13: Actual Submission Date | Q13: Date of Return Egis | R13: Duration with Egis | S13: Code | T13: Actual Submission Date | U13: Date of Return Egis | V13: Duration with Egis | W13: Code | X13: Actual Submission Date | Y13: Date of Return Egis | Z13: Duration with Egis | AA13: Code | AB13: A | AC13: B | AD13: C | AE13: D | AF13: UR | AG13: Delayed with Egis | AH13: Remarks
D14: 1 | E14: MLTX-02-003-ADV-TS9-1-ARC-RFI-0001-00 | F14: 01 | G14: ADV-0001 | H14: RFI | I14: New Conflict After Revised Boundary - Hail | J14: ARC | K14: 46085 | M14: 46089 | N14: =IF(K14="","",(IF(M14="",TODAY()-K14,M14-K14)+0)) & " Days " -> 4 Days | O14: B | P14: 46112 | Q14: 46120 | R14: =IF(P14="","",(IF(Q14="",TODAY()-P14,Q14-P14)+0)) & " Days " -> 8 Days | S14: B | AC14: 1 | AH14: Approved with Comments
D15: 2 | E15: MLTX-02-003-ADV-TS9-1-ARC-RFI-0002-00 | F15: 00 | G15: ADV-0002 | H15: RFI | I15: Tabuk (Conflict with Under-Construction Building) | J15: ARC | K15: 46085 | M15: 46093 | N15: =IF(K15="","",(IF(M15="",TODAY()-K15,M15-K15)+0)) & " Days " -> 8 Days | O15: B | AC15: 1 | AH15: Approved with Comments
D16: 3 | E16: MLTX-02-003-ADV-TS9-1-STR-RFI-0003-00 | F16: 00 | G16: ADV-0003 | H16: RFI | I16: Pump Room STR Data Missing | J16: STR | K16: 46088 | M16: 46090 | N16: =IF(K16="","",(IF(M16="",TODAY()-K16,M16-K16)+0)) & " Days " -> 2 Days | O16: B | AC16: 1 | AH16: Approved with Comments
D17: 4 | E17: MLTX-02-003-ADV-TS9-1-MEC-RFI-0004-00 | F17: 00 | G17: ADV-0004 | H17: RFI | I17: Septic tank dimensions | J17: MEC | K17: 46090 | M17: 46093 | N17: =IF(K17="","",(IF(M17="",TODAY()-K17,M17-K17)+0)) & " Days " -> 3 Days | O17: B | AC17: 1 | AH17: Approved with Comments
D18: 5 | E18: MLTX-02-003-ADV-TS9-1-LSP-RFI-0005-00 | F18: 00 | G18: ADV-0005 | H18: RFI | I18: Tree Layout and Planting Details Clarification (BOQ Item 2.3.4) – Qassim, Hail & Tabuk | J18: LSP | K18: 46106 | M18: 46116 | N18: =IF(K18="","",(IF(M18="",TODAY()-K18,M18-K18)+0)) & " Days " -> 10 Days | O18: B | AC18: 1 | AH18: Approved with Comments
D19: 6 | E19: MLTX-02-003-ADV-TS9-1-LSP-RFI-0006-00 | F19: 00 | G19: ADV-0006 | H19: RFI | I19: Fertilizer Requirements and Soil Treatment Clarification – Qassim, Hail & Tabuk | J19: LSP | K19: 46106 | M19: 46114 | N19: =IF(K19="","",(IF(M19="",TODAY()-K19,M19-K19)+0)) & " Days " -> 8 Days | O19: B | AC19: 1 | AH19: Approved with Comments
D20: 7 | E20: MLTX-02-003-ADV-TS9-1-LSP-RFI-0007-00 | F20: 00 | G20: ADV-0007 | H20: RFI | I20: Clashes between existing light poles and sign bords with design of walk/Bike path – Qassim Project | J20: LSP | K20: 46132 | M20: 46134 | N20: =IF(K20="","",(IF(M20="",TODAY()-K20,M20-K20)+0)) & " Days " -> 2 Days | O20: B | AC20: 1 | AH20: Approved with Comments
D21: 8 | E21: MLTX-02-003-ADV-TS9-1-LSP-RFI-0008-00 | F21: 02 | G21: ADV-0008 | H21: RFI | I21: Missing Project Details and Specifications – Qassim, Hail and Tabuk | J21: LSP | K21: 46132 | M21: 46133 | N21: =IF(K21="","",(IF(M21="",TODAY()-K21,M21-K21)+0)) & " Days " -> 1 Days | O21: B | P21: 46139 | Q21: 46141 | R21: =IF(P21="","",(IF(Q21="",TODAY()-P21,Q21-P21)+0)) & " Days " -> 2 Days | S21: B | T21: 46183 | U21: 46215 | V21: =IF(T21="","",(IF(U21="",TODAY()-T21,U21-T21)+0)) & " Days " -> 32 Days | W21: B | AC21: 1 | AH21: Approved with Comments
D22: 9 | E22: MLTX-02-003-ADV-TS9-1-GEN-RFI-0009-00 | F22: 00 | G22: ADV-0009 | H22: RFI | I22: Request for As-Built Drawings – Underground Utilities (Qassim, Hail & Tabuk) | J22: GEN | K22: 46140 | M22: 46156 | N22: =IF(K22="","",(IF(M22="",TODAY()-K22,M22-K22)+0)) & " Days " -> 16 Days | O22: B | AC22: 1 | AH22: Approved with Comments
D23: 10 | E23: MLTX-02-003-ADV-TS9-1-ARC-RFI-0010-00 | F23: 01 | G23: ADV-0010 | H23: RFI | I23: Qassim Parking level | J23: ARC | K23: 46154 | M23: 46155 | N23: =IF(K23="","",(IF(M23="",TODAY()-K23,M23-K23)+0)) & " Days " -> 1 Days | O23: B | P23: 46161 | Q23: 46173 | R23: =IF(P23="","",(IF(Q23="",TODAY()-P23,Q23-P23)+0)) & " Days " -> 12 Days | S23: B | AC23: 1 | AH23: Approved with Comments
